2023-03-06 15:10:37.216 23 INFO alembic.runtime.migration [-] Context impl MySQLImpl.
2023-03-06 15:10:37.219 23 INFO alembic.runtime.migration [-] Will assume non-transactional DDL.
2023-03-06 15:10:37.268 23 INFO alembic.runtime.migration [-] Context impl MySQLImpl.
2023-03-06 15:10:37.269 23 INFO alembic.runtime.migration [-] Will assume non-transactional DDL.
2023-03-06 15:10:37.314 23 INFO alembic.runtime.migration [-] Running upgrade  -> 27e647c0fad4, Initial version.
2023-03-06 15:10:38.455 23 INFO alembic.runtime.migration [-] Running upgrade 27e647c0fad4 -> e25ffa003242, Initial no-op Yoga contract migration.
2023-03-06 15:10:38.469 23 INFO alembic.runtime.migration [-] Running upgrade 27e647c0fad4 -> 29e87d24a316, Initial no-op Yoga expand migration.
2023-03-06 15:10:46.804 7 INFO keystone.common.fernet_utils [-] Created a new temporary key: /etc/keystone/fernet-keys/0.tmp
2023-03-06 15:10:46.808 7 INFO keystone.common.fernet_utils [-] Become a valid new key: /etc/keystone/fernet-keys/0
2023-03-06 15:10:46.808 7 INFO keystone.common.fernet_utils [-] Starting key rotation with 1 key files: ['/etc/keystone/fernet-keys/0']
2023-03-06 15:10:46.809 7 INFO keystone.common.fernet_utils [-] Created a new temporary key: /etc/keystone/fernet-keys/0.tmp
2023-03-06 15:10:46.810 7 INFO keystone.common.fernet_utils [-] Current primary key is: 0
2023-03-06 15:10:46.811 7 INFO keystone.common.fernet_utils [-] Next primary key will be: 1
2023-03-06 15:10:46.811 7 INFO keystone.common.fernet_utils [-] Promoted key 0 to be the primary: 1
2023-03-06 15:10:46.812 7 INFO keystone.common.fernet_utils [-] Become a valid new key: /etc/keystone/fernet-keys/0
2023-03-06 15:11:06.570 32 INFO keystone.cmd.bootstrap [None req-d8fcd1d4-4145-42d9-9b10-a4fca3eb2965 - - - - - -] Created domain default
2023-03-06 15:11:06.707 32 INFO keystone.cmd.bootstrap [None req-d8fcd1d4-4145-42d9-9b10-a4fca3eb2965 - - - - - -] Created project admin
2023-03-06 15:11:07.430 32 INFO keystone.cmd.bootstrap [None req-d8fcd1d4-4145-42d9-9b10-a4fca3eb2965 - - - - - -] Created user admin
2023-03-06 15:11:07.450 32 INFO keystone.cmd.bootstrap [None req-d8fcd1d4-4145-42d9-9b10-a4fca3eb2965 - - - - - -] Created role reader
2023-03-06 15:11:07.467 32 INFO keystone.cmd.bootstrap [None req-d8fcd1d4-4145-42d9-9b10-a4fca3eb2965 - - - - - -] Created role member
2023-03-06 15:11:07.507 32 INFO keystone.cmd.bootstrap [None req-d8fcd1d4-4145-42d9-9b10-a4fca3eb2965 - - - - - -] Created implied role where 12bae7aa08cd44e2a12ec570bb84d2b1 implies 8dedecc9d54342d783797264204b7b82
2023-03-06 15:11:07.521 32 INFO keystone.cmd.bootstrap [None req-d8fcd1d4-4145-42d9-9b10-a4fca3eb2965 - - - - - -] Created role admin
2023-03-06 15:11:07.547 32 INFO keystone.cmd.bootstrap [None req-d8fcd1d4-4145-42d9-9b10-a4fca3eb2965 - - - - - -] Created implied role where b002447aeb2d418aaadc0bb6ea812af3 implies 12bae7aa08cd44e2a12ec570bb84d2b1
2023-03-06 15:11:07.565 32 INFO keystone.cmd.bootstrap [None req-d8fcd1d4-4145-42d9-9b10-a4fca3eb2965 - - - - - -] Granted role admin on project admin to user admin.
2023-03-06 15:11:07.574 32 INFO keystone.cmd.bootstrap [None req-d8fcd1d4-4145-42d9-9b10-a4fca3eb2965 - - - - - -] Granted role admin on the system to user admin.
2023-03-06 15:11:07.590 32 WARNING py.warnings [None req-d8fcd1d4-4145-42d9-9b10-a4fca3eb2965 - - - - - -] /var/lib/kolla/venv/lib/python3.9/site-packages/pycadf/identifier.py:71: UserWarning: Invalid uuid: RegionOne. To ensure interoperability, identifiers should be a valid uuid.
  warnings.warn(('Invalid uuid: %s. To ensure interoperability, '

2023-03-06 15:11:07.596 32 INFO keystone.cmd.bootstrap [None req-d8fcd1d4-4145-42d9-9b10-a4fca3eb2965 - - - - - -] Created region RegionOne
2023-03-06 15:11:07.643 32 INFO keystone.cmd.bootstrap [None req-d8fcd1d4-4145-42d9-9b10-a4fca3eb2965 - - - - - -] Created public endpoint http://169.16.1.165:5000
2023-03-06 15:11:07.660 32 INFO keystone.cmd.bootstrap [None req-d8fcd1d4-4145-42d9-9b10-a4fca3eb2965 - - - - - -] Created internal endpoint http://169.16.1.165:5000
2023-03-06 15:11:32.858 39 WARNING keystone.common.rbac_enforcer.enforcer [None req-e4c1d368-ba9e-41be-be49-9a51931bc633 b478287302c94ad1823fbd912fcdb7c9 - - all default -] Deprecated policy rules found. Use oslopolicy-policy-generator and oslopolicy-policy-upgrade to detect and resolve deprecated policies in your configuration.
2023-03-06 15:11:33.801 38 WARNING keystone.common.rbac_enforcer.enforcer [None req-8063da1d-c077-4594-8f62-34f3efc004f0 b478287302c94ad1823fbd912fcdb7c9 - - all default -] Deprecated policy rules found. Use oslopolicy-policy-generator and oslopolicy-policy-upgrade to detect and resolve deprecated policies in your configuration.
2023-03-06 15:11:41.910 37 WARNING keystone.common.rbac_enforcer.enforcer [None req-295a2a6b-c9b9-4164-b5ef-fda98086e8ca b478287302c94ad1823fbd912fcdb7c9 - - all default -] Deprecated policy rules found. Use oslopolicy-policy-generator and oslopolicy-policy-upgrade to detect and resolve deprecated policies in your configuration.
2023-03-06 15:13:02.037 39 ERROR keystone.server.flask.application [None req-c264a2d4-2f52-4795-a51e-ee3a091055da b478287302c94ad1823fbd912fcdb7c9 - - all default -] Could not find project: service.: keystone.exception.ProjectNotFound: Could not find project: service.
2023-03-06 15:13:02.037 39 ERROR keystone.server.flask.application Traceback (most recent call last):
2023-03-06 15:13:02.037 39 ERROR keystone.server.flask.application   File "/var/lib/kolla/venv/lib/python3.9/site-packages/flask/app.py", line 1820, in full_dispatch_request
2023-03-06 15:13:02.037 39 ERROR keystone.server.flask.application     rv = self.dispatch_request()
2023-03-06 15:13:02.037 39 ERROR keystone.server.flask.application   File "/var/lib/kolla/venv/lib/python3.9/site-packages/flask/app.py", line 1796, in dispatch_request
2023-03-06 15:13:02.037 39 ERROR keystone.server.flask.application     return self.ensure_sync(self.view_functions[rule.endpoint])(**view_args)
2023-03-06 15:13:02.037 39 ERROR keystone.server.flask.application   File "/var/lib/kolla/venv/lib/python3.9/site-packages/flask_restful/__init__.py", line 467, in wrapper
2023-03-06 15:13:02.037 39 ERROR keystone.server.flask.application     resp = resource(*args, **kwargs)
2023-03-06 15:13:02.037 39 ERROR keystone.server.flask.application   File "/var/lib/kolla/venv/lib/python3.9/site-packages/flask/views.py", line 107, in view
2023-03-06 15:13:02.037 39 ERROR keystone.server.flask.application     return current_app.ensure_sync(self.dispatch_request)(**kwargs)
2023-03-06 15:13:02.037 39 ERROR keystone.server.flask.application   File "/var/lib/kolla/venv/lib/python3.9/site-packages/flask_restful/__init__.py", line 582, in dispatch_request
2023-03-06 15:13:02.037 39 ERROR keystone.server.flask.application     resp = meth(*args, **kwargs)
2023-03-06 15:13:02.037 39 ERROR keystone.server.flask.application   File "/var/lib/kolla/venv/lib/python3.9/site-packages/keystone/api/projects.py", line 151, in get
2023-03-06 15:13:02.037 39 ERROR keystone.server.flask.application     return self._get_project(project_id)
2023-03-06 15:13:02.037 39 ERROR keystone.server.flask.application   File "/var/lib/kolla/venv/lib/python3.9/site-packages/keystone/api/projects.py", line 107, in _get_project
2023-03-06 15:13:02.037 39 ERROR keystone.server.flask.application     project = PROVIDERS.resource_api.get_project(project_id)
2023-03-06 15:13:02.037 39 ERROR keystone.server.flask.application   File "/var/lib/kolla/venv/lib/python3.9/site-packages/keystone/common/manager.py", line 115, in wrapped
2023-03-06 15:13:02.037 39 ERROR keystone.server.flask.application     __ret_val = __f(*args, **kwargs)
2023-03-06 15:13:02.037 39 ERROR keystone.server.flask.application   File "/var/lib/kolla/venv/lib/python3.9/site-packages/decorator.py", line 232, in fun
2023-03-06 15:13:02.037 39 ERROR keystone.server.flask.application     return caller(func, *(extras + args), **kw)
2023-03-06 15:13:02.037 39 ERROR keystone.server.flask.application   File "/var/lib/kolla/venv/lib/python3.9/site-packages/dogpile/cache/region.py", line 1577, in get_or_create_for_user_func
2023-03-06 15:13:02.037 39 ERROR keystone.server.flask.application     return self.get_or_create(
2023-03-06 15:13:02.037 39 ERROR keystone.server.flask.application   File "/var/lib/kolla/venv/lib/python3.9/site-packages/dogpile/cache/region.py", line 1042, in get_or_create
2023-03-06 15:13:02.037 39 ERROR keystone.server.flask.application     with Lock(
2023-03-06 15:13:02.037 39 ERROR keystone.server.flask.application   File "/var/lib/kolla/venv/lib/python3.9/site-packages/dogpile/lock.py", line 185, in __enter__
2023-03-06 15:13:02.037 39 ERROR keystone.server.flask.application     return self._enter()
2023-03-06 15:13:02.037 39 ERROR keystone.server.flask.application   File "/var/lib/kolla/venv/lib/python3.9/site-packages/dogpile/lock.py", line 94, in _enter
2023-03-06 15:13:02.037 39 ERROR keystone.server.flask.application     generated = self._enter_create(value, createdtime)
2023-03-06 15:13:02.037 39 ERROR keystone.server.flask.application   File "/var/lib/kolla/venv/lib/python3.9/site-packages/dogpile/lock.py", line 178, in _enter_create
2023-03-06 15:13:02.037 39 ERROR keystone.server.flask.application     return self.creator()
2023-03-06 15:13:02.037 39 ERROR keystone.server.flask.application   File "/var/lib/kolla/venv/lib/python3.9/site-packages/dogpile/cache/region.py", line 995, in gen_value
2023-03-06 15:13:02.037 39 ERROR keystone.server.flask.application     created_value = creator(
2023-03-06 15:13:02.037 39 ERROR keystone.server.flask.application   File "/var/lib/kolla/venv/lib/python3.9/site-packages/keystone/resource/core.py", line 903, in get_project
2023-03-06 15:13:02.037 39 ERROR keystone.server.flask.application     return self.driver.get_project(project_id)
2023-03-06 15:13:02.037 39 ERROR keystone.server.flask.application   File "/var/lib/kolla/venv/lib/python3.9/site-packages/keystone/resource/backends/sql.py", line 49, in get_project
2023-03-06 15:13:02.037 39 ERROR keystone.server.flask.application     return self._get_project(session, project_id).to_dict()
2023-03-06 15:13:02.037 39 ERROR keystone.server.flask.application   File "/var/lib/kolla/venv/lib/python3.9/site-packages/keystone/resource/backends/sql.py", line 44, in _get_project
2023-03-06 15:13:02.037 39 ERROR keystone.server.flask.application     raise exception.ProjectNotFound(project_id=project_id)
2023-03-06 15:13:02.037 39 ERROR keystone.server.flask.application keystone.exception.ProjectNotFound: Could not find project: service.
2023-03-06 15:13:02.037 39 ERROR keystone.server.flask.application 
2023-03-06 15:13:11.548 37 ERROR keystone.server.flask.application [None req-cc54321a-5df9-4e2b-b191-54245bea99e0 b478287302c94ad1823fbd912fcdb7c9 - - all default -] Could not find project: service.: keystone.exception.ProjectNotFound: Could not find project: service.
2023-03-06 15:13:11.548 37 ERROR keystone.server.flask.application Traceback (most recent call last):
2023-03-06 15:13:11.548 37 ERROR keystone.server.flask.application   File "/var/lib/kolla/venv/lib/python3.9/site-packages/flask/app.py", line 1820, in full_dispatch_request
2023-03-06 15:13:11.548 37 ERROR keystone.server.flask.application     rv = self.dispatch_request()
2023-03-06 15:13:11.548 37 ERROR keystone.server.flask.application   File "/var/lib/kolla/venv/lib/python3.9/site-packages/flask/app.py", line 1796, in dispatch_request
2023-03-06 15:13:11.548 37 ERROR keystone.server.flask.application     return self.ensure_sync(self.view_functions[rule.endpoint])(**view_args)
2023-03-06 15:13:11.548 37 ERROR keystone.server.flask.application   File "/var/lib/kolla/venv/lib/python3.9/site-packages/flask_restful/__init__.py", line 467, in wrapper
2023-03-06 15:13:11.548 37 ERROR keystone.server.flask.application     resp = resource(*args, **kwargs)
2023-03-06 15:13:11.548 37 ERROR keystone.server.flask.application   File "/var/lib/kolla/venv/lib/python3.9/site-packages/flask/views.py", line 107, in view
2023-03-06 15:13:11.548 37 ERROR keystone.server.flask.application     return current_app.ensure_sync(self.dispatch_request)(**kwargs)
2023-03-06 15:13:11.548 37 ERROR keystone.server.flask.application   File "/var/lib/kolla/venv/lib/python3.9/site-packages/flask_restful/__init__.py", line 582, in dispatch_request
2023-03-06 15:13:11.548 37 ERROR keystone.server.flask.application     resp = meth(*args, **kwargs)
2023-03-06 15:13:11.548 37 ERROR keystone.server.flask.application   File "/var/lib/kolla/venv/lib/python3.9/site-packages/keystone/api/projects.py", line 151, in get
2023-03-06 15:13:11.548 37 ERROR keystone.server.flask.application     return self._get_project(project_id)
2023-03-06 15:13:11.548 37 ERROR keystone.server.flask.application   File "/var/lib/kolla/venv/lib/python3.9/site-packages/keystone/api/projects.py", line 107, in _get_project
2023-03-06 15:13:11.548 37 ERROR keystone.server.flask.application     project = PROVIDERS.resource_api.get_project(project_id)
2023-03-06 15:13:11.548 37 ERROR keystone.server.flask.application   File "/var/lib/kolla/venv/lib/python3.9/site-packages/keystone/common/manager.py", line 115, in wrapped
2023-03-06 15:13:11.548 37 ERROR keystone.server.flask.application     __ret_val = __f(*args, **kwargs)
2023-03-06 15:13:11.548 37 ERROR keystone.server.flask.application   File "/var/lib/kolla/venv/lib/python3.9/site-packages/decorator.py", line 232, in fun
2023-03-06 15:13:11.548 37 ERROR keystone.server.flask.application     return caller(func, *(extras + args), **kw)
2023-03-06 15:13:11.548 37 ERROR keystone.server.flask.application   File "/var/lib/kolla/venv/lib/python3.9/site-packages/dogpile/cache/region.py", line 1577, in get_or_create_for_user_func
2023-03-06 15:13:11.548 37 ERROR keystone.server.flask.application     return self.get_or_create(
2023-03-06 15:13:11.548 37 ERROR keystone.server.flask.application   File "/var/lib/kolla/venv/lib/python3.9/site-packages/dogpile/cache/region.py", line 1042, in get_or_create
2023-03-06 15:13:11.548 37 ERROR keystone.server.flask.application     with Lock(
2023-03-06 15:13:11.548 37 ERROR keystone.server.flask.application   File "/var/lib/kolla/venv/lib/python3.9/site-packages/dogpile/lock.py", line 185, in __enter__
2023-03-06 15:13:11.548 37 ERROR keystone.server.flask.application     return self._enter()
2023-03-06 15:13:11.548 37 ERROR keystone.server.flask.application   File "/var/lib/kolla/venv/lib/python3.9/site-packages/dogpile/lock.py", line 94, in _enter
2023-03-06 15:13:11.548 37 ERROR keystone.server.flask.application     generated = self._enter_create(value, createdtime)
2023-03-06 15:13:11.548 37 ERROR keystone.server.flask.application   File "/var/lib/kolla/venv/lib/python3.9/site-packages/dogpile/lock.py", line 178, in _enter_create
2023-03-06 15:13:11.548 37 ERROR keystone.server.flask.application     return self.creator()
2023-03-06 15:13:11.548 37 ERROR keystone.server.flask.application   File "/var/lib/kolla/venv/lib/python3.9/site-packages/dogpile/cache/region.py", line 995, in gen_value
2023-03-06 15:13:11.548 37 ERROR keystone.server.flask.application     created_value = creator(
2023-03-06 15:13:11.548 37 ERROR keystone.server.flask.application   File "/var/lib/kolla/venv/lib/python3.9/site-packages/keystone/resource/core.py", line 903, in get_project
2023-03-06 15:13:11.548 37 ERROR keystone.server.flask.application     return self.driver.get_project(project_id)
2023-03-06 15:13:11.548 37 ERROR keystone.server.flask.application   File "/var/lib/kolla/venv/lib/python3.9/site-packages/keystone/resource/backends/sql.py", line 49, in get_project
2023-03-06 15:13:11.548 37 ERROR keystone.server.flask.application     return self._get_project(session, project_id).to_dict()
2023-03-06 15:13:11.548 37 ERROR keystone.server.flask.application   File "/var/lib/kolla/venv/lib/python3.9/site-packages/keystone/resource/backends/sql.py", line 44, in _get_project
2023-03-06 15:13:11.548 37 ERROR keystone.server.flask.application     raise exception.ProjectNotFound(project_id=project_id)
2023-03-06 15:13:11.548 37 ERROR keystone.server.flask.application keystone.exception.ProjectNotFound: Could not find project: service.
2023-03-06 15:13:11.548 37 ERROR keystone.server.flask.application 
2023-03-06 15:13:26.453 37 ERROR keystone.server.flask.application [None req-1c7d1b32-a64b-45c7-8303-997e6ed85f90 b478287302c94ad1823fbd912fcdb7c9 - - all default -] Could not find role: admin.: keystone.exception.RoleNotFound: Could not find role: admin.
2023-03-06 15:13:26.453 37 ERROR keystone.server.flask.application Traceback (most recent call last):
2023-03-06 15:13:26.453 37 ERROR keystone.server.flask.application   File "/var/lib/kolla/venv/lib/python3.9/site-packages/flask/app.py", line 1820, in full_dispatch_request
2023-03-06 15:13:26.453 37 ERROR keystone.server.flask.application     rv = self.dispatch_request()
2023-03-06 15:13:26.453 37 ERROR keystone.server.flask.application   File "/var/lib/kolla/venv/lib/python3.9/site-packages/flask/app.py", line 1796, in dispatch_request
2023-03-06 15:13:26.453 37 ERROR keystone.server.flask.application     return self.ensure_sync(self.view_functions[rule.endpoint])(**view_args)
2023-03-06 15:13:26.453 37 ERROR keystone.server.flask.application   File "/var/lib/kolla/venv/lib/python3.9/site-packages/flask_restful/__init__.py", line 467, in wrapper
2023-03-06 15:13:26.453 37 ERROR keystone.server.flask.application     resp = resource(*args, **kwargs)
2023-03-06 15:13:26.453 37 ERROR keystone.server.flask.application   File "/var/lib/kolla/venv/lib/python3.9/site-packages/flask/views.py", line 107, in view
2023-03-06 15:13:26.453 37 ERROR keystone.server.flask.application     return current_app.ensure_sync(self.dispatch_request)(**kwargs)
2023-03-06 15:13:26.453 37 ERROR keystone.server.flask.application   File "/var/lib/kolla/venv/lib/python3.9/site-packages/flask_restful/__init__.py", line 582, in dispatch_request
2023-03-06 15:13:26.453 37 ERROR keystone.server.flask.application     resp = meth(*args, **kwargs)
2023-03-06 15:13:26.453 37 ERROR keystone.server.flask.application   File "/var/lib/kolla/venv/lib/python3.9/site-packages/keystone/api/roles.py", line 50, in get
2023-03-06 15:13:26.453 37 ERROR keystone.server.flask.application     return self._get_role(role_id)
2023-03-06 15:13:26.453 37 ERROR keystone.server.flask.application   File "/var/lib/kolla/venv/lib/python3.9/site-packages/keystone/api/roles.py", line 70, in _get_role
2023-03-06 15:13:26.453 37 ERROR keystone.server.flask.application     ENFORCER.enforce_call(action='identity:get_role')
2023-03-06 15:13:26.453 37 ERROR keystone.server.flask.application   File "/var/lib/kolla/venv/lib/python3.9/site-packages/keystone/common/rbac_enforcer/enforcer.py", line 402, in enforce_call
2023-03-06 15:13:26.453 37 ERROR keystone.server.flask.application     policy_dict.update(cls._extract_member_target_data(
2023-03-06 15:13:26.453 37 ERROR keystone.server.flask.application   File "/var/lib/kolla/venv/lib/python3.9/site-packages/keystone/common/rbac_enforcer/enforcer.py", line 234, in _extract_member_target_data
2023-03-06 15:13:26.453 37 ERROR keystone.server.flask.application     member_name: func(flask.request.view_args[key])
2023-03-06 15:13:26.453 37 ERROR keystone.server.flask.application   File "/var/lib/kolla/venv/lib/python3.9/site-packages/keystone/common/manager.py", line 115, in wrapped
2023-03-06 15:13:26.453 37 ERROR keystone.server.flask.application     __ret_val = __f(*args, **kwargs)
2023-03-06 15:13:26.453 37 ERROR keystone.server.flask.application   File "/var/lib/kolla/venv/lib/python3.9/site-packages/decorator.py", line 232, in fun
2023-03-06 15:13:26.453 37 ERROR keystone.server.flask.application     return caller(func, *(extras + args), **kw)
2023-03-06 15:13:26.453 37 ERROR keystone.server.flask.application   File "/var/lib/kolla/venv/lib/python3.9/site-packages/dogpile/cache/region.py", line 1577, in get_or_create_for_user_func
2023-03-06 15:13:26.453 37 ERROR keystone.server.flask.application     return self.get_or_create(
2023-03-06 15:13:26.453 37 ERROR keystone.server.flask.application   File "/var/lib/kolla/venv/lib/python3.9/site-packages/dogpile/cache/region.py", line 1042, in get_or_create
2023-03-06 15:13:26.453 37 ERROR keystone.server.flask.application     with Lock(
2023-03-06 15:13:26.453 37 ERROR keystone.server.flask.application   File "/var/lib/kolla/venv/lib/python3.9/site-packages/dogpile/lock.py", line 185, in __enter__
2023-03-06 15:13:26.453 37 ERROR keystone.server.flask.application     return self._enter()
2023-03-06 15:13:26.453 37 ERROR keystone.server.flask.application   File "/var/lib/kolla/venv/lib/python3.9/site-packages/dogpile/lock.py", line 94, in _enter
2023-03-06 15:13:26.453 37 ERROR keystone.server.flask.application     generated = self._enter_create(value, createdtime)
2023-03-06 15:13:26.453 37 ERROR keystone.server.flask.application   File "/var/lib/kolla/venv/lib/python3.9/site-packages/dogpile/lock.py", line 178, in _enter_create
2023-03-06 15:13:26.453 37 ERROR keystone.server.flask.application     return self.creator()
2023-03-06 15:13:26.453 37 ERROR keystone.server.flask.application   File "/var/lib/kolla/venv/lib/python3.9/site-packages/dogpile/cache/region.py", line 995, in gen_value
2023-03-06 15:13:26.453 37 ERROR keystone.server.flask.application     created_value = creator(
2023-03-06 15:13:26.453 37 ERROR keystone.server.flask.application   File "/var/lib/kolla/venv/lib/python3.9/site-packages/keystone/assignment/core.py", line 1276, in get_role
2023-03-06 15:13:26.453 37 ERROR keystone.server.flask.application     return self.driver.get_role(role_id)
2023-03-06 15:13:26.453 37 ERROR keystone.server.flask.application   File "/var/lib/kolla/venv/lib/python3.9/site-packages/keystone/assignment/role_backends/sql.py", line 70, in get_role
2023-03-06 15:13:26.453 37 ERROR keystone.server.flask.application     return self._get_role(session, role_id).to_dict()
2023-03-06 15:13:26.453 37 ERROR keystone.server.flask.application   File "/var/lib/kolla/venv/lib/python3.9/site-packages/keystone/assignment/role_backends/sql.py", line 65, in _get_role
2023-03-06 15:13:26.453 37 ERROR keystone.server.flask.application     raise exception.RoleNotFound(role_id=role_id)
2023-03-06 15:13:26.453 37 ERROR keystone.server.flask.application keystone.exception.RoleNotFound: Could not find role: admin.
2023-03-06 15:13:26.453 37 ERROR keystone.server.flask.application 
2023-03-06 15:13:27.720 37 ERROR keystone.server.flask.application [None req-0388d887-f338-4129-b03e-acf9d72f9832 b478287302c94ad1823fbd912fcdb7c9 - - all default -] Could not find user: ironic.: keystone.exception.UserNotFound: Could not find user: ironic.
2023-03-06 15:13:27.720 37 ERROR keystone.server.flask.application Traceback (most recent call last):
2023-03-06 15:13:27.720 37 ERROR keystone.server.flask.application   File "/var/lib/kolla/venv/lib/python3.9/site-packages/flask/app.py", line 1820, in full_dispatch_request
2023-03-06 15:13:27.720 37 ERROR keystone.server.flask.application     rv = self.dispatch_request()
2023-03-06 15:13:27.720 37 ERROR keystone.server.flask.application   File "/var/lib/kolla/venv/lib/python3.9/site-packages/flask/app.py", line 1796, in dispatch_request
2023-03-06 15:13:27.720 37 ERROR keystone.server.flask.application     return self.ensure_sync(self.view_functions[rule.endpoint])(**view_args)
2023-03-06 15:13:27.720 37 ERROR keystone.server.flask.application   File "/var/lib/kolla/venv/lib/python3.9/site-packages/flask_restful/__init__.py", line 467, in wrapper
2023-03-06 15:13:27.720 37 ERROR keystone.server.flask.application     resp = resource(*args, **kwargs)
2023-03-06 15:13:27.720 37 ERROR keystone.server.flask.application   File "/var/lib/kolla/venv/lib/python3.9/site-packages/flask/views.py", line 107, in view
2023-03-06 15:13:27.720 37 ERROR keystone.server.flask.application     return current_app.ensure_sync(self.dispatch_request)(**kwargs)
2023-03-06 15:13:27.720 37 ERROR keystone.server.flask.application   File "/var/lib/kolla/venv/lib/python3.9/site-packages/flask_restful/__init__.py", line 582, in dispatch_request
2023-03-06 15:13:27.720 37 ERROR keystone.server.flask.application     resp = meth(*args, **kwargs)
2023-03-06 15:13:27.720 37 ERROR keystone.server.flask.application   File "/var/lib/kolla/venv/lib/python3.9/site-packages/keystone/api/users.py", line 182, in get
2023-03-06 15:13:27.720 37 ERROR keystone.server.flask.application     return self._get_user(user_id)
2023-03-06 15:13:27.720 37 ERROR keystone.server.flask.application   File "/var/lib/kolla/venv/lib/python3.9/site-packages/keystone/api/users.py", line 194, in _get_user
2023-03-06 15:13:27.720 37 ERROR keystone.server.flask.application     ref = PROVIDERS.identity_api.get_user(user_id)
2023-03-06 15:13:27.720 37 ERROR keystone.server.flask.application   File "/var/lib/kolla/venv/lib/python3.9/site-packages/keystone/common/manager.py", line 115, in wrapped
2023-03-06 15:13:27.720 37 ERROR keystone.server.flask.application     __ret_val = __f(*args, **kwargs)
2023-03-06 15:13:27.720 37 ERROR keystone.server.flask.application   File "/var/lib/kolla/venv/lib/python3.9/site-packages/keystone/identity/core.py", line 414, in wrapper
2023-03-06 15:13:27.720 37 ERROR keystone.server.flask.application     return f(self, *args, **kwargs)
2023-03-06 15:13:27.720 37 ERROR keystone.server.flask.application   File "/var/lib/kolla/venv/lib/python3.9/site-packages/keystone/identity/core.py", line 424, in wrapper
2023-03-06 15:13:27.720 37 ERROR keystone.server.flask.application     return f(self, *args, **kwargs)
2023-03-06 15:13:27.720 37 ERROR keystone.server.flask.application   File "/var/lib/kolla/venv/lib/python3.9/site-packages/decorator.py", line 232, in fun
2023-03-06 15:13:27.720 37 ERROR keystone.server.flask.application     return caller(func, *(extras + args), **kw)
2023-03-06 15:13:27.720 37 ERROR keystone.server.flask.application   File "/var/lib/kolla/venv/lib/python3.9/site-packages/dogpile/cache/region.py", line 1577, in get_or_create_for_user_func
2023-03-06 15:13:27.720 37 ERROR keystone.server.flask.application     return self.get_or_create(
2023-03-06 15:13:27.720 37 ERROR keystone.server.flask.application   File "/var/lib/kolla/venv/lib/python3.9/site-packages/dogpile/cache/region.py", line 1042, in get_or_create
2023-03-06 15:13:27.720 37 ERROR keystone.server.flask.application     with Lock(
2023-03-06 15:13:27.720 37 ERROR keystone.server.flask.application   File "/var/lib/kolla/venv/lib/python3.9/site-packages/dogpile/lock.py", line 185, in __enter__
2023-03-06 15:13:27.720 37 ERROR keystone.server.flask.application     return self._enter()
2023-03-06 15:13:27.720 37 ERROR keystone.server.flask.application   File "/var/lib/kolla/venv/lib/python3.9/site-packages/dogpile/lock.py", line 94, in _enter
2023-03-06 15:13:27.720 37 ERROR keystone.server.flask.application     generated = self._enter_create(value, createdtime)
2023-03-06 15:13:27.720 37 ERROR keystone.server.flask.application   File "/var/lib/kolla/venv/lib/python3.9/site-packages/dogpile/lock.py", line 178, in _enter_create
2023-03-06 15:13:27.720 37 ERROR keystone.server.flask.application     return self.creator()
2023-03-06 15:13:27.720 37 ERROR keystone.server.flask.application   File "/var/lib/kolla/venv/lib/python3.9/site-packages/dogpile/cache/region.py", line 995, in gen_value
2023-03-06 15:13:27.720 37 ERROR keystone.server.flask.application     created_value = creator(
2023-03-06 15:13:27.720 37 ERROR keystone.server.flask.application   File "/var/lib/kolla/venv/lib/python3.9/site-packages/keystone/identity/core.py", line 1011, in get_user
2023-03-06 15:13:27.720 37 ERROR keystone.server.flask.application     ref = driver.get_user(entity_id)
2023-03-06 15:13:27.720 37 ERROR keystone.server.flask.application   File "/var/lib/kolla/venv/lib/python3.9/site-packages/keystone/identity/backends/sql.py", line 200, in get_user
2023-03-06 15:13:27.720 37 ERROR keystone.server.flask.application     self._get_user(session, user_id).to_dict())
2023-03-06 15:13:27.720 37 ERROR keystone.server.flask.application   File "/var/lib/kolla/venv/lib/python3.9/site-packages/keystone/identity/backends/sql.py", line 194, in _get_user
2023-03-06 15:13:27.720 37 ERROR keystone.server.flask.application     raise exception.UserNotFound(user_id=user_id)
2023-03-06 15:13:27.720 37 ERROR keystone.server.flask.application keystone.exception.UserNotFound: Could not find user: ironic.
2023-03-06 15:13:27.720 37 ERROR keystone.server.flask.application 
2023-03-06 15:13:28.561 38 ERROR keystone.server.flask.application [None req-1fbb17e8-db88-437f-9799-c0c87130117d b478287302c94ad1823fbd912fcdb7c9 - - all default -] Could not find project: service.: keystone.exception.ProjectNotFound: Could not find project: service.
2023-03-06 15:13:28.561 38 ERROR keystone.server.flask.application Traceback (most recent call last):
2023-03-06 15:13:28.561 38 ERROR keystone.server.flask.application   File "/var/lib/kolla/venv/lib/python3.9/site-packages/flask/app.py", line 1820, in full_dispatch_request
2023-03-06 15:13:28.561 38 ERROR keystone.server.flask.application     rv = self.dispatch_request()
2023-03-06 15:13:28.561 38 ERROR keystone.server.flask.application   File "/var/lib/kolla/venv/lib/python3.9/site-packages/flask/app.py", line 1796, in dispatch_request
2023-03-06 15:13:28.561 38 ERROR keystone.server.flask.application     return self.ensure_sync(self.view_functions[rule.endpoint])(**view_args)
2023-03-06 15:13:28.561 38 ERROR keystone.server.flask.application   File "/var/lib/kolla/venv/lib/python3.9/site-packages/flask_restful/__init__.py", line 467, in wrapper
2023-03-06 15:13:28.561 38 ERROR keystone.server.flask.application     resp = resource(*args, **kwargs)
2023-03-06 15:13:28.561 38 ERROR keystone.server.flask.application   File "/var/lib/kolla/venv/lib/python3.9/site-packages/flask/views.py", line 107, in view
2023-03-06 15:13:28.561 38 ERROR keystone.server.flask.application     return current_app.ensure_sync(self.dispatch_request)(**kwargs)
2023-03-06 15:13:28.561 38 ERROR keystone.server.flask.application   File "/var/lib/kolla/venv/lib/python3.9/site-packages/flask_restful/__init__.py", line 582, in dispatch_request
2023-03-06 15:13:28.561 38 ERROR keystone.server.flask.application     resp = meth(*args, **kwargs)
2023-03-06 15:13:28.561 38 ERROR keystone.server.flask.application   File "/var/lib/kolla/venv/lib/python3.9/site-packages/keystone/api/projects.py", line 151, in get
2023-03-06 15:13:28.561 38 ERROR keystone.server.flask.application     return self._get_project(project_id)
2023-03-06 15:13:28.561 38 ERROR keystone.server.flask.application   File "/var/lib/kolla/venv/lib/python3.9/site-packages/keystone/api/projects.py", line 107, in _get_project
2023-03-06 15:13:28.561 38 ERROR keystone.server.flask.application     project = PROVIDERS.resource_api.get_project(project_id)
2023-03-06 15:13:28.561 38 ERROR keystone.server.flask.application   File "/var/lib/kolla/venv/lib/python3.9/site-packages/keystone/common/manager.py", line 115, in wrapped
2023-03-06 15:13:28.561 38 ERROR keystone.server.flask.application     __ret_val = __f(*args, **kwargs)
2023-03-06 15:13:28.561 38 ERROR keystone.server.flask.application   File "/var/lib/kolla/venv/lib/python3.9/site-packages/decorator.py", line 232, in fun
2023-03-06 15:13:28.561 38 ERROR keystone.server.flask.application     return caller(func, *(extras + args), **kw)
2023-03-06 15:13:28.561 38 ERROR keystone.server.flask.application   File "/var/lib/kolla/venv/lib/python3.9/site-packages/dogpile/cache/region.py", line 1577, in get_or_create_for_user_func
2023-03-06 15:13:28.561 38 ERROR keystone.server.flask.application     return self.get_or_create(
2023-03-06 15:13:28.561 38 ERROR keystone.server.flask.application   File "/var/lib/kolla/venv/lib/python3.9/site-packages/dogpile/cache/region.py", line 1042, in get_or_create
2023-03-06 15:13:28.561 38 ERROR keystone.server.flask.application     with Lock(
2023-03-06 15:13:28.561 38 ERROR keystone.server.flask.application   File "/var/lib/kolla/venv/lib/python3.9/site-packages/dogpile/lock.py", line 185, in __enter__
2023-03-06 15:13:28.561 38 ERROR keystone.server.flask.application     return self._enter()
2023-03-06 15:13:28.561 38 ERROR keystone.server.flask.application   File "/var/lib/kolla/venv/lib/python3.9/site-packages/dogpile/lock.py", line 94, in _enter
2023-03-06 15:13:28.561 38 ERROR keystone.server.flask.application     generated = self._enter_create(value, createdtime)
2023-03-06 15:13:28.561 38 ERROR keystone.server.flask.application   File "/var/lib/kolla/venv/lib/python3.9/site-packages/dogpile/lock.py", line 178, in _enter_create
2023-03-06 15:13:28.561 38 ERROR keystone.server.flask.application     return self.creator()
2023-03-06 15:13:28.561 38 ERROR keystone.server.flask.application   File "/var/lib/kolla/venv/lib/python3.9/site-packages/dogpile/cache/region.py", line 995, in gen_value
2023-03-06 15:13:28.561 38 ERROR keystone.server.flask.application     created_value = creator(
2023-03-06 15:13:28.561 38 ERROR keystone.server.flask.application   File "/var/lib/kolla/venv/lib/python3.9/site-packages/keystone/resource/core.py", line 903, in get_project
2023-03-06 15:13:28.561 38 ERROR keystone.server.flask.application     return self.driver.get_project(project_id)
2023-03-06 15:13:28.561 38 ERROR keystone.server.flask.application   File "/var/lib/kolla/venv/lib/python3.9/site-packages/keystone/resource/backends/sql.py", line 49, in get_project
2023-03-06 15:13:28.561 38 ERROR keystone.server.flask.application     return self._get_project(session, project_id).to_dict()
2023-03-06 15:13:28.561 38 ERROR keystone.server.flask.application   File "/var/lib/kolla/venv/lib/python3.9/site-packages/keystone/resource/backends/sql.py", line 44, in _get_project
2023-03-06 15:13:28.561 38 ERROR keystone.server.flask.application     raise exception.ProjectNotFound(project_id=project_id)
2023-03-06 15:13:28.561 38 ERROR keystone.server.flask.application keystone.exception.ProjectNotFound: Could not find project: service.
2023-03-06 15:13:28.561 38 ERROR keystone.server.flask.application 
2023-03-06 15:13:38.199 39 ERROR keystone.server.flask.application [None req-63fce94b-1545-427e-b9d2-282b0114ba86 b478287302c94ad1823fbd912fcdb7c9 - - all default -] Could not find role: admin.: keystone.exception.RoleNotFound: Could not find role: admin.
2023-03-06 15:13:38.199 39 ERROR keystone.server.flask.application Traceback (most recent call last):
2023-03-06 15:13:38.199 39 ERROR keystone.server.flask.application   File "/var/lib/kolla/venv/lib/python3.9/site-packages/flask/app.py", line 1820, in full_dispatch_request
2023-03-06 15:13:38.199 39 ERROR keystone.server.flask.application     rv = self.dispatch_request()
2023-03-06 15:13:38.199 39 ERROR keystone.server.flask.application   File "/var/lib/kolla/venv/lib/python3.9/site-packages/flask/app.py", line 1796, in dispatch_request
2023-03-06 15:13:38.199 39 ERROR keystone.server.flask.application     return self.ensure_sync(self.view_functions[rule.endpoint])(**view_args)
2023-03-06 15:13:38.199 39 ERROR keystone.server.flask.application   File "/var/lib/kolla/venv/lib/python3.9/site-packages/flask_restful/__init__.py", line 467, in wrapper
2023-03-06 15:13:38.199 39 ERROR keystone.server.flask.application     resp = resource(*args, **kwargs)
2023-03-06 15:13:38.199 39 ERROR keystone.server.flask.application   File "/var/lib/kolla/venv/lib/python3.9/site-packages/flask/views.py", line 107, in view
2023-03-06 15:13:38.199 39 ERROR keystone.server.flask.application     return current_app.ensure_sync(self.dispatch_request)(**kwargs)
2023-03-06 15:13:38.199 39 ERROR keystone.server.flask.application   File "/var/lib/kolla/venv/lib/python3.9/site-packages/flask_restful/__init__.py", line 582, in dispatch_request
2023-03-06 15:13:38.199 39 ERROR keystone.server.flask.application     resp = meth(*args, **kwargs)
2023-03-06 15:13:38.199 39 ERROR keystone.server.flask.application   File "/var/lib/kolla/venv/lib/python3.9/site-packages/keystone/api/roles.py", line 50, in get
2023-03-06 15:13:38.199 39 ERROR keystone.server.flask.application     return self._get_role(role_id)
2023-03-06 15:13:38.199 39 ERROR keystone.server.flask.application   File "/var/lib/kolla/venv/lib/python3.9/site-packages/keystone/api/roles.py", line 70, in _get_role
2023-03-06 15:13:38.199 39 ERROR keystone.server.flask.application     ENFORCER.enforce_call(action='identity:get_role')
2023-03-06 15:13:38.199 39 ERROR keystone.server.flask.application   File "/var/lib/kolla/venv/lib/python3.9/site-packages/keystone/common/rbac_enforcer/enforcer.py", line 402, in enforce_call
2023-03-06 15:13:38.199 39 ERROR keystone.server.flask.application     policy_dict.update(cls._extract_member_target_data(
2023-03-06 15:13:38.199 39 ERROR keystone.server.flask.application   File "/var/lib/kolla/venv/lib/python3.9/site-packages/keystone/common/rbac_enforcer/enforcer.py", line 234, in _extract_member_target_data
2023-03-06 15:13:38.199 39 ERROR keystone.server.flask.application     member_name: func(flask.request.view_args[key])
2023-03-06 15:13:38.199 39 ERROR keystone.server.flask.application   File "/var/lib/kolla/venv/lib/python3.9/site-packages/keystone/common/manager.py", line 115, in wrapped
2023-03-06 15:13:38.199 39 ERROR keystone.server.flask.application     __ret_val = __f(*args, **kwargs)
2023-03-06 15:13:38.199 39 ERROR keystone.server.flask.application   File "/var/lib/kolla/venv/lib/python3.9/site-packages/decorator.py", line 232, in fun
2023-03-06 15:13:38.199 39 ERROR keystone.server.flask.application     return caller(func, *(extras + args), **kw)
2023-03-06 15:13:38.199 39 ERROR keystone.server.flask.application   File "/var/lib/kolla/venv/lib/python3.9/site-packages/dogpile/cache/region.py", line 1577, in get_or_create_for_user_func
2023-03-06 15:13:38.199 39 ERROR keystone.server.flask.application     return self.get_or_create(
2023-03-06 15:13:38.199 39 ERROR keystone.server.flask.application   File "/var/lib/kolla/venv/lib/python3.9/site-packages/dogpile/cache/region.py", line 1042, in get_or_create
2023-03-06 15:13:38.199 39 ERROR keystone.server.flask.application     with Lock(
2023-03-06 15:13:38.199 39 ERROR keystone.server.flask.application   File "/var/lib/kolla/venv/lib/python3.9/site-packages/dogpile/lock.py", line 185, in __enter__
2023-03-06 15:13:38.199 39 ERROR keystone.server.flask.application     return self._enter()
2023-03-06 15:13:38.199 39 ERROR keystone.server.flask.application   File "/var/lib/kolla/venv/lib/python3.9/site-packages/dogpile/lock.py", line 94, in _enter
2023-03-06 15:13:38.199 39 ERROR keystone.server.flask.application     generated = self._enter_create(value, createdtime)
2023-03-06 15:13:38.199 39 ERROR keystone.server.flask.application   File "/var/lib/kolla/venv/lib/python3.9/site-packages/dogpile/lock.py", line 178, in _enter_create
2023-03-06 15:13:38.199 39 ERROR keystone.server.flask.application     return self.creator()
2023-03-06 15:13:38.199 39 ERROR keystone.server.flask.application   File "/var/lib/kolla/venv/lib/python3.9/site-packages/dogpile/cache/region.py", line 995, in gen_value
2023-03-06 15:13:38.199 39 ERROR keystone.server.flask.application     created_value = creator(
2023-03-06 15:13:38.199 39 ERROR keystone.server.flask.application   File "/var/lib/kolla/venv/lib/python3.9/site-packages/keystone/assignment/core.py", line 1276, in get_role
2023-03-06 15:13:38.199 39 ERROR keystone.server.flask.application     return self.driver.get_role(role_id)
2023-03-06 15:13:38.199 39 ERROR keystone.server.flask.application   File "/var/lib/kolla/venv/lib/python3.9/site-packages/keystone/assignment/role_backends/sql.py", line 70, in get_role
2023-03-06 15:13:38.199 39 ERROR keystone.server.flask.application     return self._get_role(session, role_id).to_dict()
2023-03-06 15:13:38.199 39 ERROR keystone.server.flask.application   File "/var/lib/kolla/venv/lib/python3.9/site-packages/keystone/assignment/role_backends/sql.py", line 65, in _get_role
2023-03-06 15:13:38.199 39 ERROR keystone.server.flask.application     raise exception.RoleNotFound(role_id=role_id)
2023-03-06 15:13:38.199 39 ERROR keystone.server.flask.application keystone.exception.RoleNotFound: Could not find role: admin.
2023-03-06 15:13:38.199 39 ERROR keystone.server.flask.application 
2023-03-06 15:13:39.784 39 ERROR keystone.server.flask.application [None req-a4d7a56e-92f3-4ea9-b9b3-876bae6c210d b478287302c94ad1823fbd912fcdb7c9 - - all default -] Could not find user: ironic-inspector.: keystone.exception.UserNotFound: Could not find user: ironic-inspector.
2023-03-06 15:13:39.784 39 ERROR keystone.server.flask.application Traceback (most recent call last):
2023-03-06 15:13:39.784 39 ERROR keystone.server.flask.application   File "/var/lib/kolla/venv/lib/python3.9/site-packages/flask/app.py", line 1820, in full_dispatch_request
2023-03-06 15:13:39.784 39 ERROR keystone.server.flask.application     rv = self.dispatch_request()
2023-03-06 15:13:39.784 39 ERROR keystone.server.flask.application   File "/var/lib/kolla/venv/lib/python3.9/site-packages/flask/app.py", line 1796, in dispatch_request
2023-03-06 15:13:39.784 39 ERROR keystone.server.flask.application     return self.ensure_sync(self.view_functions[rule.endpoint])(**view_args)
2023-03-06 15:13:39.784 39 ERROR keystone.server.flask.application   File "/var/lib/kolla/venv/lib/python3.9/site-packages/flask_restful/__init__.py", line 467, in wrapper
2023-03-06 15:13:39.784 39 ERROR keystone.server.flask.application     resp = resource(*args, **kwargs)
2023-03-06 15:13:39.784 39 ERROR keystone.server.flask.application   File "/var/lib/kolla/venv/lib/python3.9/site-packages/flask/views.py", line 107, in view
2023-03-06 15:13:39.784 39 ERROR keystone.server.flask.application     return current_app.ensure_sync(self.dispatch_request)(**kwargs)
2023-03-06 15:13:39.784 39 ERROR keystone.server.flask.application   File "/var/lib/kolla/venv/lib/python3.9/site-packages/flask_restful/__init__.py", line 582, in dispatch_request
2023-03-06 15:13:39.784 39 ERROR keystone.server.flask.application     resp = meth(*args, **kwargs)
2023-03-06 15:13:39.784 39 ERROR keystone.server.flask.application   File "/var/lib/kolla/venv/lib/python3.9/site-packages/keystone/api/users.py", line 182, in get
2023-03-06 15:13:39.784 39 ERROR keystone.server.flask.application     return self._get_user(user_id)
2023-03-06 15:13:39.784 39 ERROR keystone.server.flask.application   File "/var/lib/kolla/venv/lib/python3.9/site-packages/keystone/api/users.py", line 194, in _get_user
2023-03-06 15:13:39.784 39 ERROR keystone.server.flask.application     ref = PROVIDERS.identity_api.get_user(user_id)
2023-03-06 15:13:39.784 39 ERROR keystone.server.flask.application   File "/var/lib/kolla/venv/lib/python3.9/site-packages/keystone/common/manager.py", line 115, in wrapped
2023-03-06 15:13:39.784 39 ERROR keystone.server.flask.application     __ret_val = __f(*args, **kwargs)
2023-03-06 15:13:39.784 39 ERROR keystone.server.flask.application   File "/var/lib/kolla/venv/lib/python3.9/site-packages/keystone/identity/core.py", line 414, in wrapper
2023-03-06 15:13:39.784 39 ERROR keystone.server.flask.application     return f(self, *args, **kwargs)
2023-03-06 15:13:39.784 39 ERROR keystone.server.flask.application   File "/var/lib/kolla/venv/lib/python3.9/site-packages/keystone/identity/core.py", line 424, in wrapper
2023-03-06 15:13:39.784 39 ERROR keystone.server.flask.application     return f(self, *args, **kwargs)
2023-03-06 15:13:39.784 39 ERROR keystone.server.flask.application   File "/var/lib/kolla/venv/lib/python3.9/site-packages/decorator.py", line 232, in fun
2023-03-06 15:13:39.784 39 ERROR keystone.server.flask.application     return caller(func, *(extras + args), **kw)
2023-03-06 15:13:39.784 39 ERROR keystone.server.flask.application   File "/var/lib/kolla/venv/lib/python3.9/site-packages/dogpile/cache/region.py", line 1577, in get_or_create_for_user_func
2023-03-06 15:13:39.784 39 ERROR keystone.server.flask.application     return self.get_or_create(
2023-03-06 15:13:39.784 39 ERROR keystone.server.flask.application   File "/var/lib/kolla/venv/lib/python3.9/site-packages/dogpile/cache/region.py", line 1042, in get_or_create
2023-03-06 15:13:39.784 39 ERROR keystone.server.flask.application     with Lock(
2023-03-06 15:13:39.784 39 ERROR keystone.server.flask.application   File "/var/lib/kolla/venv/lib/python3.9/site-packages/dogpile/lock.py", line 185, in __enter__
2023-03-06 15:13:39.784 39 ERROR keystone.server.flask.application     return self._enter()
2023-03-06 15:13:39.784 39 ERROR keystone.server.flask.application   File "/var/lib/kolla/venv/lib/python3.9/site-packages/dogpile/lock.py", line 94, in _enter
2023-03-06 15:13:39.784 39 ERROR keystone.server.flask.application     generated = self._enter_create(value, createdtime)
2023-03-06 15:13:39.784 39 ERROR keystone.server.flask.application   File "/var/lib/kolla/venv/lib/python3.9/site-packages/dogpile/lock.py", line 178, in _enter_create
2023-03-06 15:13:39.784 39 ERROR keystone.server.flask.application     return self.creator()
2023-03-06 15:13:39.784 39 ERROR keystone.server.flask.application   File "/var/lib/kolla/venv/lib/python3.9/site-packages/dogpile/cache/region.py", line 995, in gen_value
2023-03-06 15:13:39.784 39 ERROR keystone.server.flask.application     created_value = creator(
2023-03-06 15:13:39.784 39 ERROR keystone.server.flask.application   File "/var/lib/kolla/venv/lib/python3.9/site-packages/keystone/identity/core.py", line 1011, in get_user
2023-03-06 15:13:39.784 39 ERROR keystone.server.flask.application     ref = driver.get_user(entity_id)
2023-03-06 15:13:39.784 39 ERROR keystone.server.flask.application   File "/var/lib/kolla/venv/lib/python3.9/site-packages/keystone/identity/backends/sql.py", line 200, in get_user
2023-03-06 15:13:39.784 39 ERROR keystone.server.flask.application     self._get_user(session, user_id).to_dict())
2023-03-06 15:13:39.784 39 ERROR keystone.server.flask.application   File "/var/lib/kolla/venv/lib/python3.9/site-packages/keystone/identity/backends/sql.py", line 194, in _get_user
2023-03-06 15:13:39.784 39 ERROR keystone.server.flask.application     raise exception.UserNotFound(user_id=user_id)
2023-03-06 15:13:39.784 39 ERROR keystone.server.flask.application keystone.exception.UserNotFound: Could not find user: ironic-inspector.
2023-03-06 15:13:39.784 39 ERROR keystone.server.flask.application 
2023-03-06 15:13:40.553 37 ERROR keystone.server.flask.application [None req-238ec4f0-48e7-432a-80f8-feeab21beb14 b478287302c94ad1823fbd912fcdb7c9 - - all default -] Could not find project: service.: keystone.exception.ProjectNotFound: Could not find project: service.
2023-03-06 15:13:40.553 37 ERROR keystone.server.flask.application Traceback (most recent call last):
2023-03-06 15:13:40.553 37 ERROR keystone.server.flask.application   File "/var/lib/kolla/venv/lib/python3.9/site-packages/flask/app.py", line 1820, in full_dispatch_request
2023-03-06 15:13:40.553 37 ERROR keystone.server.flask.application     rv = self.dispatch_request()
2023-03-06 15:13:40.553 37 ERROR keystone.server.flask.application   File "/var/lib/kolla/venv/lib/python3.9/site-packages/flask/app.py", line 1796, in dispatch_request
2023-03-06 15:13:40.553 37 ERROR keystone.server.flask.application     return self.ensure_sync(self.view_functions[rule.endpoint])(**view_args)
2023-03-06 15:13:40.553 37 ERROR keystone.server.flask.application   File "/var/lib/kolla/venv/lib/python3.9/site-packages/flask_restful/__init__.py", line 467, in wrapper
2023-03-06 15:13:40.553 37 ERROR keystone.server.flask.application     resp = resource(*args, **kwargs)
2023-03-06 15:13:40.553 37 ERROR keystone.server.flask.application   File "/var/lib/kolla/venv/lib/python3.9/site-packages/flask/views.py", line 107, in view
2023-03-06 15:13:40.553 37 ERROR keystone.server.flask.application     return current_app.ensure_sync(self.dispatch_request)(**kwargs)
2023-03-06 15:13:40.553 37 ERROR keystone.server.flask.application   File "/var/lib/kolla/venv/lib/python3.9/site-packages/flask_restful/__init__.py", line 582, in dispatch_request
2023-03-06 15:13:40.553 37 ERROR keystone.server.flask.application     resp = meth(*args, **kwargs)
2023-03-06 15:13:40.553 37 ERROR keystone.server.flask.application   File "/var/lib/kolla/venv/lib/python3.9/site-packages/keystone/api/projects.py", line 151, in get
2023-03-06 15:13:40.553 37 ERROR keystone.server.flask.application     return self._get_project(project_id)
2023-03-06 15:13:40.553 37 ERROR keystone.server.flask.application   File "/var/lib/kolla/venv/lib/python3.9/site-packages/keystone/api/projects.py", line 107, in _get_project
2023-03-06 15:13:40.553 37 ERROR keystone.server.flask.application     project = PROVIDERS.resource_api.get_project(project_id)
2023-03-06 15:13:40.553 37 ERROR keystone.server.flask.application   File "/var/lib/kolla/venv/lib/python3.9/site-packages/keystone/common/manager.py", line 115, in wrapped
2023-03-06 15:13:40.553 37 ERROR keystone.server.flask.application     __ret_val = __f(*args, **kwargs)
2023-03-06 15:13:40.553 37 ERROR keystone.server.flask.application   File "/var/lib/kolla/venv/lib/python3.9/site-packages/decorator.py", line 232, in fun
2023-03-06 15:13:40.553 37 ERROR keystone.server.flask.application     return caller(func, *(extras + args), **kw)
2023-03-06 15:13:40.553 37 ERROR keystone.server.flask.application   File "/var/lib/kolla/venv/lib/python3.9/site-packages/dogpile/cache/region.py", line 1577, in get_or_create_for_user_func
2023-03-06 15:13:40.553 37 ERROR keystone.server.flask.application     return self.get_or_create(
2023-03-06 15:13:40.553 37 ERROR keystone.server.flask.application   File "/var/lib/kolla/venv/lib/python3.9/site-packages/dogpile/cache/region.py", line 1042, in get_or_create
2023-03-06 15:13:40.553 37 ERROR keystone.server.flask.application     with Lock(
2023-03-06 15:13:40.553 37 ERROR keystone.server.flask.application   File "/var/lib/kolla/venv/lib/python3.9/site-packages/dogpile/lock.py", line 185, in __enter__
2023-03-06 15:13:40.553 37 ERROR keystone.server.flask.application     return self._enter()
2023-03-06 15:13:40.553 37 ERROR keystone.server.flask.application   File "/var/lib/kolla/venv/lib/python3.9/site-packages/dogpile/lock.py", line 94, in _enter
2023-03-06 15:13:40.553 37 ERROR keystone.server.flask.application     generated = self._enter_create(value, createdtime)
2023-03-06 15:13:40.553 37 ERROR keystone.server.flask.application   File "/var/lib/kolla/venv/lib/python3.9/site-packages/dogpile/lock.py", line 178, in _enter_create
2023-03-06 15:13:40.553 37 ERROR keystone.server.flask.application     return self.creator()
2023-03-06 15:13:40.553 37 ERROR keystone.server.flask.application   File "/var/lib/kolla/venv/lib/python3.9/site-packages/dogpile/cache/region.py", line 995, in gen_value
2023-03-06 15:13:40.553 37 ERROR keystone.server.flask.application     created_value = creator(
2023-03-06 15:13:40.553 37 ERROR keystone.server.flask.application   File "/var/lib/kolla/venv/lib/python3.9/site-packages/keystone/resource/core.py", line 903, in get_project
2023-03-06 15:13:40.553 37 ERROR keystone.server.flask.application     return self.driver.get_project(project_id)
2023-03-06 15:13:40.553 37 ERROR keystone.server.flask.application   File "/var/lib/kolla/venv/lib/python3.9/site-packages/keystone/resource/backends/sql.py", line 49, in get_project
2023-03-06 15:13:40.553 37 ERROR keystone.server.flask.application     return self._get_project(session, project_id).to_dict()
2023-03-06 15:13:40.553 37 ERROR keystone.server.flask.application   File "/var/lib/kolla/venv/lib/python3.9/site-packages/keystone/resource/backends/sql.py", line 44, in _get_project
2023-03-06 15:13:40.553 37 ERROR keystone.server.flask.application     raise exception.ProjectNotFound(project_id=project_id)
2023-03-06 15:13:40.553 37 ERROR keystone.server.flask.application keystone.exception.ProjectNotFound: Could not find project: service.
2023-03-06 15:13:40.553 37 ERROR keystone.server.flask.application 
2023-03-06 15:16:37.994 37 ERROR keystone.server.flask.application [None req-f98a152a-f9fe-43c9-a38f-a224b7dbeac5 b478287302c94ad1823fbd912fcdb7c9 - - all default -] Could not find project: service.: keystone.exception.ProjectNotFound: Could not find project: service.
2023-03-06 15:16:37.994 37 ERROR keystone.server.flask.application Traceback (most recent call last):
2023-03-06 15:16:37.994 37 ERROR keystone.server.flask.application   File "/var/lib/kolla/venv/lib/python3.9/site-packages/flask/app.py", line 1820, in full_dispatch_request
2023-03-06 15:16:37.994 37 ERROR keystone.server.flask.application     rv = self.dispatch_request()
2023-03-06 15:16:37.994 37 ERROR keystone.server.flask.application   File "/var/lib/kolla/venv/lib/python3.9/site-packages/flask/app.py", line 1796, in dispatch_request
2023-03-06 15:16:37.994 37 ERROR keystone.server.flask.application     return self.ensure_sync(self.view_functions[rule.endpoint])(**view_args)
2023-03-06 15:16:37.994 37 ERROR keystone.server.flask.application   File "/var/lib/kolla/venv/lib/python3.9/site-packages/flask_restful/__init__.py", line 467, in wrapper
2023-03-06 15:16:37.994 37 ERROR keystone.server.flask.application     resp = resource(*args, **kwargs)
2023-03-06 15:16:37.994 37 ERROR keystone.server.flask.application   File "/var/lib/kolla/venv/lib/python3.9/site-packages/flask/views.py", line 107, in view
2023-03-06 15:16:37.994 37 ERROR keystone.server.flask.application     return current_app.ensure_sync(self.dispatch_request)(**kwargs)
2023-03-06 15:16:37.994 37 ERROR keystone.server.flask.application   File "/var/lib/kolla/venv/lib/python3.9/site-packages/flask_restful/__init__.py", line 582, in dispatch_request
2023-03-06 15:16:37.994 37 ERROR keystone.server.flask.application     resp = meth(*args, **kwargs)
2023-03-06 15:16:37.994 37 ERROR keystone.server.flask.application   File "/var/lib/kolla/venv/lib/python3.9/site-packages/keystone/api/projects.py", line 151, in get
2023-03-06 15:16:37.994 37 ERROR keystone.server.flask.application     return self._get_project(project_id)
2023-03-06 15:16:37.994 37 ERROR keystone.server.flask.application   File "/var/lib/kolla/venv/lib/python3.9/site-packages/keystone/api/projects.py", line 107, in _get_project
2023-03-06 15:16:37.994 37 ERROR keystone.server.flask.application     project = PROVIDERS.resource_api.get_project(project_id)
2023-03-06 15:16:37.994 37 ERROR keystone.server.flask.application   File "/var/lib/kolla/venv/lib/python3.9/site-packages/keystone/common/manager.py", line 115, in wrapped
2023-03-06 15:16:37.994 37 ERROR keystone.server.flask.application     __ret_val = __f(*args, **kwargs)
2023-03-06 15:16:37.994 37 ERROR keystone.server.flask.application   File "/var/lib/kolla/venv/lib/python3.9/site-packages/decorator.py", line 232, in fun
2023-03-06 15:16:37.994 37 ERROR keystone.server.flask.application     return caller(func, *(extras + args), **kw)
2023-03-06 15:16:37.994 37 ERROR keystone.server.flask.application   File "/var/lib/kolla/venv/lib/python3.9/site-packages/dogpile/cache/region.py", line 1577, in get_or_create_for_user_func
2023-03-06 15:16:37.994 37 ERROR keystone.server.flask.application     return self.get_or_create(
2023-03-06 15:16:37.994 37 ERROR keystone.server.flask.application   File "/var/lib/kolla/venv/lib/python3.9/site-packages/dogpile/cache/region.py", line 1042, in get_or_create
2023-03-06 15:16:37.994 37 ERROR keystone.server.flask.application     with Lock(
2023-03-06 15:16:37.994 37 ERROR keystone.server.flask.application   File "/var/lib/kolla/venv/lib/python3.9/site-packages/dogpile/lock.py", line 185, in __enter__
2023-03-06 15:16:37.994 37 ERROR keystone.server.flask.application     return self._enter()
2023-03-06 15:16:37.994 37 ERROR keystone.server.flask.application   File "/var/lib/kolla/venv/lib/python3.9/site-packages/dogpile/lock.py", line 94, in _enter
2023-03-06 15:16:37.994 37 ERROR keystone.server.flask.application     generated = self._enter_create(value, createdtime)
2023-03-06 15:16:37.994 37 ERROR keystone.server.flask.application   File "/var/lib/kolla/venv/lib/python3.9/site-packages/dogpile/lock.py", line 178, in _enter_create
2023-03-06 15:16:37.994 37 ERROR keystone.server.flask.application     return self.creator()
2023-03-06 15:16:37.994 37 ERROR keystone.server.flask.application   File "/var/lib/kolla/venv/lib/python3.9/site-packages/dogpile/cache/region.py", line 995, in gen_value
2023-03-06 15:16:37.994 37 ERROR keystone.server.flask.application     created_value = creator(
2023-03-06 15:16:37.994 37 ERROR keystone.server.flask.application   File "/var/lib/kolla/venv/lib/python3.9/site-packages/keystone/resource/core.py", line 903, in get_project
2023-03-06 15:16:37.994 37 ERROR keystone.server.flask.application     return self.driver.get_project(project_id)
2023-03-06 15:16:37.994 37 ERROR keystone.server.flask.application   File "/var/lib/kolla/venv/lib/python3.9/site-packages/keystone/resource/backends/sql.py", line 49, in get_project
2023-03-06 15:16:37.994 37 ERROR keystone.server.flask.application     return self._get_project(session, project_id).to_dict()
2023-03-06 15:16:37.994 37 ERROR keystone.server.flask.application   File "/var/lib/kolla/venv/lib/python3.9/site-packages/keystone/resource/backends/sql.py", line 44, in _get_project
2023-03-06 15:16:37.994 37 ERROR keystone.server.flask.application     raise exception.ProjectNotFound(project_id=project_id)
2023-03-06 15:16:37.994 37 ERROR keystone.server.flask.application keystone.exception.ProjectNotFound: Could not find project: service.
2023-03-06 15:16:37.994 37 ERROR keystone.server.flask.application 
2023-03-06 15:16:53.486 39 ERROR keystone.server.flask.application [None req-48535bff-f823-4cf1-b660-c34af0ec7584 b478287302c94ad1823fbd912fcdb7c9 - - all default -] Could not find role: admin.: keystone.exception.RoleNotFound: Could not find role: admin.
2023-03-06 15:16:53.486 39 ERROR keystone.server.flask.application Traceback (most recent call last):
2023-03-06 15:16:53.486 39 ERROR keystone.server.flask.application   File "/var/lib/kolla/venv/lib/python3.9/site-packages/flask/app.py", line 1820, in full_dispatch_request
2023-03-06 15:16:53.486 39 ERROR keystone.server.flask.application     rv = self.dispatch_request()
2023-03-06 15:16:53.486 39 ERROR keystone.server.flask.application   File "/var/lib/kolla/venv/lib/python3.9/site-packages/flask/app.py", line 1796, in dispatch_request
2023-03-06 15:16:53.486 39 ERROR keystone.server.flask.application     return self.ensure_sync(self.view_functions[rule.endpoint])(**view_args)
2023-03-06 15:16:53.486 39 ERROR keystone.server.flask.application   File "/var/lib/kolla/venv/lib/python3.9/site-packages/flask_restful/__init__.py", line 467, in wrapper
2023-03-06 15:16:53.486 39 ERROR keystone.server.flask.application     resp = resource(*args, **kwargs)
2023-03-06 15:16:53.486 39 ERROR keystone.server.flask.application   File "/var/lib/kolla/venv/lib/python3.9/site-packages/flask/views.py", line 107, in view
2023-03-06 15:16:53.486 39 ERROR keystone.server.flask.application     return current_app.ensure_sync(self.dispatch_request)(**kwargs)
2023-03-06 15:16:53.486 39 ERROR keystone.server.flask.application   File "/var/lib/kolla/venv/lib/python3.9/site-packages/flask_restful/__init__.py", line 582, in dispatch_request
2023-03-06 15:16:53.486 39 ERROR keystone.server.flask.application     resp = meth(*args, **kwargs)
2023-03-06 15:16:53.486 39 ERROR keystone.server.flask.application   File "/var/lib/kolla/venv/lib/python3.9/site-packages/keystone/api/roles.py", line 50, in get
2023-03-06 15:16:53.486 39 ERROR keystone.server.flask.application     return self._get_role(role_id)
2023-03-06 15:16:53.486 39 ERROR keystone.server.flask.application   File "/var/lib/kolla/venv/lib/python3.9/site-packages/keystone/api/roles.py", line 70, in _get_role
2023-03-06 15:16:53.486 39 ERROR keystone.server.flask.application     ENFORCER.enforce_call(action='identity:get_role')
2023-03-06 15:16:53.486 39 ERROR keystone.server.flask.application   File "/var/lib/kolla/venv/lib/python3.9/site-packages/keystone/common/rbac_enforcer/enforcer.py", line 402, in enforce_call
2023-03-06 15:16:53.486 39 ERROR keystone.server.flask.application     policy_dict.update(cls._extract_member_target_data(
2023-03-06 15:16:53.486 39 ERROR keystone.server.flask.application   File "/var/lib/kolla/venv/lib/python3.9/site-packages/keystone/common/rbac_enforcer/enforcer.py", line 234, in _extract_member_target_data
2023-03-06 15:16:53.486 39 ERROR keystone.server.flask.application     member_name: func(flask.request.view_args[key])
2023-03-06 15:16:53.486 39 ERROR keystone.server.flask.application   File "/var/lib/kolla/venv/lib/python3.9/site-packages/keystone/common/manager.py", line 115, in wrapped
2023-03-06 15:16:53.486 39 ERROR keystone.server.flask.application     __ret_val = __f(*args, **kwargs)
2023-03-06 15:16:53.486 39 ERROR keystone.server.flask.application   File "/var/lib/kolla/venv/lib/python3.9/site-packages/decorator.py", line 232, in fun
2023-03-06 15:16:53.486 39 ERROR keystone.server.flask.application     return caller(func, *(extras + args), **kw)
2023-03-06 15:16:53.486 39 ERROR keystone.server.flask.application   File "/var/lib/kolla/venv/lib/python3.9/site-packages/dogpile/cache/region.py", line 1577, in get_or_create_for_user_func
2023-03-06 15:16:53.486 39 ERROR keystone.server.flask.application     return self.get_or_create(
2023-03-06 15:16:53.486 39 ERROR keystone.server.flask.application   File "/var/lib/kolla/venv/lib/python3.9/site-packages/dogpile/cache/region.py", line 1042, in get_or_create
2023-03-06 15:16:53.486 39 ERROR keystone.server.flask.application     with Lock(
2023-03-06 15:16:53.486 39 ERROR keystone.server.flask.application   File "/var/lib/kolla/venv/lib/python3.9/site-packages/dogpile/lock.py", line 185, in __enter__
2023-03-06 15:16:53.486 39 ERROR keystone.server.flask.application     return self._enter()
2023-03-06 15:16:53.486 39 ERROR keystone.server.flask.application   File "/var/lib/kolla/venv/lib/python3.9/site-packages/dogpile/lock.py", line 94, in _enter
2023-03-06 15:16:53.486 39 ERROR keystone.server.flask.application     generated = self._enter_create(value, createdtime)
2023-03-06 15:16:53.486 39 ERROR keystone.server.flask.application   File "/var/lib/kolla/venv/lib/python3.9/site-packages/dogpile/lock.py", line 178, in _enter_create
2023-03-06 15:16:53.486 39 ERROR keystone.server.flask.application     return self.creator()
2023-03-06 15:16:53.486 39 ERROR keystone.server.flask.application   File "/var/lib/kolla/venv/lib/python3.9/site-packages/dogpile/cache/region.py", line 995, in gen_value
2023-03-06 15:16:53.486 39 ERROR keystone.server.flask.application     created_value = creator(
2023-03-06 15:16:53.486 39 ERROR keystone.server.flask.application   File "/var/lib/kolla/venv/lib/python3.9/site-packages/keystone/assignment/core.py", line 1276, in get_role
2023-03-06 15:16:53.486 39 ERROR keystone.server.flask.application     return self.driver.get_role(role_id)
2023-03-06 15:16:53.486 39 ERROR keystone.server.flask.application   File "/var/lib/kolla/venv/lib/python3.9/site-packages/keystone/assignment/role_backends/sql.py", line 70, in get_role
2023-03-06 15:16:53.486 39 ERROR keystone.server.flask.application     return self._get_role(session, role_id).to_dict()
2023-03-06 15:16:53.486 39 ERROR keystone.server.flask.application   File "/var/lib/kolla/venv/lib/python3.9/site-packages/keystone/assignment/role_backends/sql.py", line 65, in _get_role
2023-03-06 15:16:53.486 39 ERROR keystone.server.flask.application     raise exception.RoleNotFound(role_id=role_id)
2023-03-06 15:16:53.486 39 ERROR keystone.server.flask.application keystone.exception.RoleNotFound: Could not find role: admin.
2023-03-06 15:16:53.486 39 ERROR keystone.server.flask.application 
2023-03-06 15:16:55.012 39 ERROR keystone.server.flask.application [None req-70fe8fb1-25a6-4b8c-b218-861c08633f0d b478287302c94ad1823fbd912fcdb7c9 - - all default -] Could not find user: neutron.: keystone.exception.UserNotFound: Could not find user: neutron.
2023-03-06 15:16:55.012 39 ERROR keystone.server.flask.application Traceback (most recent call last):
2023-03-06 15:16:55.012 39 ERROR keystone.server.flask.application   File "/var/lib/kolla/venv/lib/python3.9/site-packages/flask/app.py", line 1820, in full_dispatch_request
2023-03-06 15:16:55.012 39 ERROR keystone.server.flask.application     rv = self.dispatch_request()
2023-03-06 15:16:55.012 39 ERROR keystone.server.flask.application   File "/var/lib/kolla/venv/lib/python3.9/site-packages/flask/app.py", line 1796, in dispatch_request
2023-03-06 15:16:55.012 39 ERROR keystone.server.flask.application     return self.ensure_sync(self.view_functions[rule.endpoint])(**view_args)
2023-03-06 15:16:55.012 39 ERROR keystone.server.flask.application   File "/var/lib/kolla/venv/lib/python3.9/site-packages/flask_restful/__init__.py", line 467, in wrapper
2023-03-06 15:16:55.012 39 ERROR keystone.server.flask.application     resp = resource(*args, **kwargs)
2023-03-06 15:16:55.012 39 ERROR keystone.server.flask.application   File "/var/lib/kolla/venv/lib/python3.9/site-packages/flask/views.py", line 107, in view
2023-03-06 15:16:55.012 39 ERROR keystone.server.flask.application     return current_app.ensure_sync(self.dispatch_request)(**kwargs)
2023-03-06 15:16:55.012 39 ERROR keystone.server.flask.application   File "/var/lib/kolla/venv/lib/python3.9/site-packages/flask_restful/__init__.py", line 582, in dispatch_request
2023-03-06 15:16:55.012 39 ERROR keystone.server.flask.application     resp = meth(*args, **kwargs)
2023-03-06 15:16:55.012 39 ERROR keystone.server.flask.application   File "/var/lib/kolla/venv/lib/python3.9/site-packages/keystone/api/users.py", line 182, in get
2023-03-06 15:16:55.012 39 ERROR keystone.server.flask.application     return self._get_user(user_id)
2023-03-06 15:16:55.012 39 ERROR keystone.server.flask.application   File "/var/lib/kolla/venv/lib/python3.9/site-packages/keystone/api/users.py", line 194, in _get_user
2023-03-06 15:16:55.012 39 ERROR keystone.server.flask.application     ref = PROVIDERS.identity_api.get_user(user_id)
2023-03-06 15:16:55.012 39 ERROR keystone.server.flask.application   File "/var/lib/kolla/venv/lib/python3.9/site-packages/keystone/common/manager.py", line 115, in wrapped
2023-03-06 15:16:55.012 39 ERROR keystone.server.flask.application     __ret_val = __f(*args, **kwargs)
2023-03-06 15:16:55.012 39 ERROR keystone.server.flask.application   File "/var/lib/kolla/venv/lib/python3.9/site-packages/keystone/identity/core.py", line 414, in wrapper
2023-03-06 15:16:55.012 39 ERROR keystone.server.flask.application     return f(self, *args, **kwargs)
2023-03-06 15:16:55.012 39 ERROR keystone.server.flask.application   File "/var/lib/kolla/venv/lib/python3.9/site-packages/keystone/identity/core.py", line 424, in wrapper
2023-03-06 15:16:55.012 39 ERROR keystone.server.flask.application     return f(self, *args, **kwargs)
2023-03-06 15:16:55.012 39 ERROR keystone.server.flask.application   File "/var/lib/kolla/venv/lib/python3.9/site-packages/decorator.py", line 232, in fun
2023-03-06 15:16:55.012 39 ERROR keystone.server.flask.application     return caller(func, *(extras + args), **kw)
2023-03-06 15:16:55.012 39 ERROR keystone.server.flask.application   File "/var/lib/kolla/venv/lib/python3.9/site-packages/dogpile/cache/region.py", line 1577, in get_or_create_for_user_func
2023-03-06 15:16:55.012 39 ERROR keystone.server.flask.application     return self.get_or_create(
2023-03-06 15:16:55.012 39 ERROR keystone.server.flask.application   File "/var/lib/kolla/venv/lib/python3.9/site-packages/dogpile/cache/region.py", line 1042, in get_or_create
2023-03-06 15:16:55.012 39 ERROR keystone.server.flask.application     with Lock(
2023-03-06 15:16:55.012 39 ERROR keystone.server.flask.application   File "/var/lib/kolla/venv/lib/python3.9/site-packages/dogpile/lock.py", line 185, in __enter__
2023-03-06 15:16:55.012 39 ERROR keystone.server.flask.application     return self._enter()
2023-03-06 15:16:55.012 39 ERROR keystone.server.flask.application   File "/var/lib/kolla/venv/lib/python3.9/site-packages/dogpile/lock.py", line 94, in _enter
2023-03-06 15:16:55.012 39 ERROR keystone.server.flask.application     generated = self._enter_create(value, createdtime)
2023-03-06 15:16:55.012 39 ERROR keystone.server.flask.application   File "/var/lib/kolla/venv/lib/python3.9/site-packages/dogpile/lock.py", line 178, in _enter_create
2023-03-06 15:16:55.012 39 ERROR keystone.server.flask.application     return self.creator()
2023-03-06 15:16:55.012 39 ERROR keystone.server.flask.application   File "/var/lib/kolla/venv/lib/python3.9/site-packages/dogpile/cache/region.py", line 995, in gen_value
2023-03-06 15:16:55.012 39 ERROR keystone.server.flask.application     created_value = creator(
2023-03-06 15:16:55.012 39 ERROR keystone.server.flask.application   File "/var/lib/kolla/venv/lib/python3.9/site-packages/keystone/identity/core.py", line 1011, in get_user
2023-03-06 15:16:55.012 39 ERROR keystone.server.flask.application     ref = driver.get_user(entity_id)
2023-03-06 15:16:55.012 39 ERROR keystone.server.flask.application   File "/var/lib/kolla/venv/lib/python3.9/site-packages/keystone/identity/backends/sql.py", line 200, in get_user
2023-03-06 15:16:55.012 39 ERROR keystone.server.flask.application     self._get_user(session, user_id).to_dict())
2023-03-06 15:16:55.012 39 ERROR keystone.server.flask.application   File "/var/lib/kolla/venv/lib/python3.9/site-packages/keystone/identity/backends/sql.py", line 194, in _get_user
2023-03-06 15:16:55.012 39 ERROR keystone.server.flask.application     raise exception.UserNotFound(user_id=user_id)
2023-03-06 15:16:55.012 39 ERROR keystone.server.flask.application keystone.exception.UserNotFound: Could not find user: neutron.
2023-03-06 15:16:55.012 39 ERROR keystone.server.flask.application 
2023-03-06 15:16:56.013 38 ERROR keystone.server.flask.application [None req-1e15aebb-f243-47d7-9944-50afeb0eac84 b478287302c94ad1823fbd912fcdb7c9 - - all default -] Could not find project: service.: keystone.exception.ProjectNotFound: Could not find project: service.
2023-03-06 15:16:56.013 38 ERROR keystone.server.flask.application Traceback (most recent call last):
2023-03-06 15:16:56.013 38 ERROR keystone.server.flask.application   File "/var/lib/kolla/venv/lib/python3.9/site-packages/flask/app.py", line 1820, in full_dispatch_request
2023-03-06 15:16:56.013 38 ERROR keystone.server.flask.application     rv = self.dispatch_request()
2023-03-06 15:16:56.013 38 ERROR keystone.server.flask.application   File "/var/lib/kolla/venv/lib/python3.9/site-packages/flask/app.py", line 1796, in dispatch_request
2023-03-06 15:16:56.013 38 ERROR keystone.server.flask.application     return self.ensure_sync(self.view_functions[rule.endpoint])(**view_args)
2023-03-06 15:16:56.013 38 ERROR keystone.server.flask.application   File "/var/lib/kolla/venv/lib/python3.9/site-packages/flask_restful/__init__.py", line 467, in wrapper
2023-03-06 15:16:56.013 38 ERROR keystone.server.flask.application     resp = resource(*args, **kwargs)
2023-03-06 15:16:56.013 38 ERROR keystone.server.flask.application   File "/var/lib/kolla/venv/lib/python3.9/site-packages/flask/views.py", line 107, in view
2023-03-06 15:16:56.013 38 ERROR keystone.server.flask.application     return current_app.ensure_sync(self.dispatch_request)(**kwargs)
2023-03-06 15:16:56.013 38 ERROR keystone.server.flask.application   File "/var/lib/kolla/venv/lib/python3.9/site-packages/flask_restful/__init__.py", line 582, in dispatch_request
2023-03-06 15:16:56.013 38 ERROR keystone.server.flask.application     resp = meth(*args, **kwargs)
2023-03-06 15:16:56.013 38 ERROR keystone.server.flask.application   File "/var/lib/kolla/venv/lib/python3.9/site-packages/keystone/api/projects.py", line 151, in get
2023-03-06 15:16:56.013 38 ERROR keystone.server.flask.application     return self._get_project(project_id)
2023-03-06 15:16:56.013 38 ERROR keystone.server.flask.application   File "/var/lib/kolla/venv/lib/python3.9/site-packages/keystone/api/projects.py", line 107, in _get_project
2023-03-06 15:16:56.013 38 ERROR keystone.server.flask.application     project = PROVIDERS.resource_api.get_project(project_id)
2023-03-06 15:16:56.013 38 ERROR keystone.server.flask.application   File "/var/lib/kolla/venv/lib/python3.9/site-packages/keystone/common/manager.py", line 115, in wrapped
2023-03-06 15:16:56.013 38 ERROR keystone.server.flask.application     __ret_val = __f(*args, **kwargs)
2023-03-06 15:16:56.013 38 ERROR keystone.server.flask.application   File "/var/lib/kolla/venv/lib/python3.9/site-packages/decorator.py", line 232, in fun
2023-03-06 15:16:56.013 38 ERROR keystone.server.flask.application     return caller(func, *(extras + args), **kw)
2023-03-06 15:16:56.013 38 ERROR keystone.server.flask.application   File "/var/lib/kolla/venv/lib/python3.9/site-packages/dogpile/cache/region.py", line 1577, in get_or_create_for_user_func
2023-03-06 15:16:56.013 38 ERROR keystone.server.flask.application     return self.get_or_create(
2023-03-06 15:16:56.013 38 ERROR keystone.server.flask.application   File "/var/lib/kolla/venv/lib/python3.9/site-packages/dogpile/cache/region.py", line 1042, in get_or_create
2023-03-06 15:16:56.013 38 ERROR keystone.server.flask.application     with Lock(
2023-03-06 15:16:56.013 38 ERROR keystone.server.flask.application   File "/var/lib/kolla/venv/lib/python3.9/site-packages/dogpile/lock.py", line 185, in __enter__
2023-03-06 15:16:56.013 38 ERROR keystone.server.flask.application     return self._enter()
2023-03-06 15:16:56.013 38 ERROR keystone.server.flask.application   File "/var/lib/kolla/venv/lib/python3.9/site-packages/dogpile/lock.py", line 94, in _enter
2023-03-06 15:16:56.013 38 ERROR keystone.server.flask.application     generated = self._enter_create(value, createdtime)
2023-03-06 15:16:56.013 38 ERROR keystone.server.flask.application   File "/var/lib/kolla/venv/lib/python3.9/site-packages/dogpile/lock.py", line 178, in _enter_create
2023-03-06 15:16:56.013 38 ERROR keystone.server.flask.application     return self.creator()
2023-03-06 15:16:56.013 38 ERROR keystone.server.flask.application   File "/var/lib/kolla/venv/lib/python3.9/site-packages/dogpile/cache/region.py", line 995, in gen_value
2023-03-06 15:16:56.013 38 ERROR keystone.server.flask.application     created_value = creator(
2023-03-06 15:16:56.013 38 ERROR keystone.server.flask.application   File "/var/lib/kolla/venv/lib/python3.9/site-packages/keystone/resource/core.py", line 903, in get_project
2023-03-06 15:16:56.013 38 ERROR keystone.server.flask.application     return self.driver.get_project(project_id)
2023-03-06 15:16:56.013 38 ERROR keystone.server.flask.application   File "/var/lib/kolla/venv/lib/python3.9/site-packages/keystone/resource/backends/sql.py", line 49, in get_project
2023-03-06 15:16:56.013 38 ERROR keystone.server.flask.application     return self._get_project(session, project_id).to_dict()
2023-03-06 15:16:56.013 38 ERROR keystone.server.flask.application   File "/var/lib/kolla/venv/lib/python3.9/site-packages/keystone/resource/backends/sql.py", line 44, in _get_project
2023-03-06 15:16:56.013 38 ERROR keystone.server.flask.application     raise exception.ProjectNotFound(project_id=project_id)
2023-03-06 15:16:56.013 38 ERROR keystone.server.flask.application keystone.exception.ProjectNotFound: Could not find project: service.
2023-03-06 15:16:56.013 38 ERROR keystone.server.flask.application 
