2023-03-15 20:21:16.134 23 INFO alembic.runtime.migration [-] Context impl MySQLImpl.
2023-03-15 20:21:16.137 23 INFO alembic.runtime.migration [-] Will assume non-transactional DDL.
2023-03-15 20:21:16.189 23 INFO alembic.runtime.migration [-] Context impl MySQLImpl.
2023-03-15 20:21:16.190 23 INFO alembic.runtime.migration [-] Will assume non-transactional DDL.
2023-03-15 20:21:16.246 23 INFO alembic.runtime.migration [-] Running upgrade  -> 27e647c0fad4, Initial version.
2023-03-15 20:21:17.827 23 INFO alembic.runtime.migration [-] Running upgrade 27e647c0fad4 -> e25ffa003242, Initial no-op Yoga contract migration.
2023-03-15 20:21:17.841 23 INFO alembic.runtime.migration [-] Running upgrade 27e647c0fad4 -> 29e87d24a316, Initial no-op Yoga expand migration.
2023-03-15 20:21:27.127 7 INFO keystone.common.fernet_utils [-] Created a new temporary key: /etc/keystone/fernet-keys/0.tmp
2023-03-15 20:21:27.131 7 INFO keystone.common.fernet_utils [-] Become a valid new key: /etc/keystone/fernet-keys/0
2023-03-15 20:21:27.134 7 INFO keystone.common.fernet_utils [-] Starting key rotation with 1 key files: ['/etc/keystone/fernet-keys/0']
2023-03-15 20:21:27.135 7 INFO keystone.common.fernet_utils [-] Created a new temporary key: /etc/keystone/fernet-keys/0.tmp
2023-03-15 20:21:27.136 7 INFO keystone.common.fernet_utils [-] Current primary key is: 0
2023-03-15 20:21:27.137 7 INFO keystone.common.fernet_utils [-] Next primary key will be: 1
2023-03-15 20:21:27.137 7 INFO keystone.common.fernet_utils [-] Promoted key 0 to be the primary: 1
2023-03-15 20:21:27.138 7 INFO keystone.common.fernet_utils [-] Become a valid new key: /etc/keystone/fernet-keys/0
2023-03-15 20:21:47.590 33 INFO keystone.cmd.bootstrap [None req-5d51bd0d-ed65-4e83-a468-2d99665ba060 - - - - - -] Created domain default
2023-03-15 20:21:47.714 33 INFO keystone.cmd.bootstrap [None req-5d51bd0d-ed65-4e83-a468-2d99665ba060 - - - - - -] Created project admin
2023-03-15 20:21:48.454 33 INFO keystone.cmd.bootstrap [None req-5d51bd0d-ed65-4e83-a468-2d99665ba060 - - - - - -] Created user admin
2023-03-15 20:21:48.490 33 INFO keystone.cmd.bootstrap [None req-5d51bd0d-ed65-4e83-a468-2d99665ba060 - - - - - -] Created role reader
2023-03-15 20:21:48.513 33 INFO keystone.cmd.bootstrap [None req-5d51bd0d-ed65-4e83-a468-2d99665ba060 - - - - - -] Created role member
2023-03-15 20:21:48.557 33 INFO keystone.cmd.bootstrap [None req-5d51bd0d-ed65-4e83-a468-2d99665ba060 - - - - - -] Created implied role where 5a72dd81f4b14a16a7d6577b2e82f8fc implies b0e774bd05dd4694b1a15a32cb4a3730
2023-03-15 20:21:48.581 33 INFO keystone.cmd.bootstrap [None req-5d51bd0d-ed65-4e83-a468-2d99665ba060 - - - - - -] Created role admin
2023-03-15 20:21:48.646 33 INFO keystone.cmd.bootstrap [None req-5d51bd0d-ed65-4e83-a468-2d99665ba060 - - - - - -] Created implied role where 2c7941e1dd664acbae9a568d659d8664 implies 5a72dd81f4b14a16a7d6577b2e82f8fc
2023-03-15 20:21:48.683 33 INFO keystone.cmd.bootstrap [None req-5d51bd0d-ed65-4e83-a468-2d99665ba060 - - - - - -] Granted role admin on project admin to user admin.
2023-03-15 20:21:48.699 33 INFO keystone.cmd.bootstrap [None req-5d51bd0d-ed65-4e83-a468-2d99665ba060 - - - - - -] Granted role admin on the system to user admin.
2023-03-15 20:21:48.755 33 WARNING py.warnings [None req-5d51bd0d-ed65-4e83-a468-2d99665ba060 - - - - - -] /var/lib/kolla/venv/lib/python3.9/site-packages/pycadf/identifier.py:71: UserWarning: Invalid uuid: RegionOne. To ensure interoperability, identifiers should be a valid uuid.
  warnings.warn(('Invalid uuid: %s. To ensure interoperability, '

2023-03-15 20:21:48.768 33 INFO keystone.cmd.bootstrap [None req-5d51bd0d-ed65-4e83-a468-2d99665ba060 - - - - - -] Created region RegionOne
2023-03-15 20:21:48.849 33 INFO keystone.cmd.bootstrap [None req-5d51bd0d-ed65-4e83-a468-2d99665ba060 - - - - - -] Created public endpoint http://169.16.1.177:5000
2023-03-15 20:21:48.878 33 INFO keystone.cmd.bootstrap [None req-5d51bd0d-ed65-4e83-a468-2d99665ba060 - - - - - -] Created internal endpoint http://169.16.1.177:5000
2023-03-15 20:22:16.694 38 WARNING keystone.common.rbac_enforcer.enforcer [None req-a881caaf-0370-4067-9312-47bebadced58 20613e7b2f754801bc6f2aee280741a0 - - all default -] Deprecated policy rules found. Use oslopolicy-policy-generator and oslopolicy-policy-upgrade to detect and resolve deprecated policies in your configuration.
2023-03-15 20:22:17.392 40 WARNING keystone.common.rbac_enforcer.enforcer [None req-f32ed733-c577-406a-a9f8-44694e320e94 20613e7b2f754801bc6f2aee280741a0 - - all default -] Deprecated policy rules found. Use oslopolicy-policy-generator and oslopolicy-policy-upgrade to detect and resolve deprecated policies in your configuration.
2023-03-15 20:22:24.838 39 WARNING keystone.common.rbac_enforcer.enforcer [None req-edf33431-5d66-4a51-a65a-681114a3b273 20613e7b2f754801bc6f2aee280741a0 - - all default -] Deprecated policy rules found. Use oslopolicy-policy-generator and oslopolicy-policy-upgrade to detect and resolve deprecated policies in your configuration.
2023-03-15 20:23:52.045 38 ERROR keystone.server.flask.application [None req-29f1cd4e-026d-4417-9541-88749dfb3b5b 20613e7b2f754801bc6f2aee280741a0 - - all default -] Could not find project: service.: keystone.exception.ProjectNotFound: Could not find project: service.
2023-03-15 20:23:52.045 38 ERROR keystone.server.flask.application Traceback (most recent call last):
2023-03-15 20:23:52.045 38 ERROR keystone.server.flask.application   File "/var/lib/kolla/venv/lib/python3.9/site-packages/flask/app.py", line 1820, in full_dispatch_request
2023-03-15 20:23:52.045 38 ERROR keystone.server.flask.application     rv = self.dispatch_request()
2023-03-15 20:23:52.045 38 ERROR keystone.server.flask.application   File "/var/lib/kolla/venv/lib/python3.9/site-packages/flask/app.py", line 1796, in dispatch_request
2023-03-15 20:23:52.045 38 ERROR keystone.server.flask.application     return self.ensure_sync(self.view_functions[rule.endpoint])(**view_args)
2023-03-15 20:23:52.045 38 ERROR keystone.server.flask.application   File "/var/lib/kolla/venv/lib/python3.9/site-packages/flask_restful/__init__.py", line 467, in wrapper
2023-03-15 20:23:52.045 38 ERROR keystone.server.flask.application     resp = resource(*args, **kwargs)
2023-03-15 20:23:52.045 38 ERROR keystone.server.flask.application   File "/var/lib/kolla/venv/lib/python3.9/site-packages/flask/views.py", line 107, in view
2023-03-15 20:23:52.045 38 ERROR keystone.server.flask.application     return current_app.ensure_sync(self.dispatch_request)(**kwargs)
2023-03-15 20:23:52.045 38 ERROR keystone.server.flask.application   File "/var/lib/kolla/venv/lib/python3.9/site-packages/flask_restful/__init__.py", line 582, in dispatch_request
2023-03-15 20:23:52.045 38 ERROR keystone.server.flask.application     resp = meth(*args, **kwargs)
2023-03-15 20:23:52.045 38 ERROR keystone.server.flask.application   File "/var/lib/kolla/venv/lib/python3.9/site-packages/keystone/api/projects.py", line 151, in get
2023-03-15 20:23:52.045 38 ERROR keystone.server.flask.application     return self._get_project(project_id)
2023-03-15 20:23:52.045 38 ERROR keystone.server.flask.application   File "/var/lib/kolla/venv/lib/python3.9/site-packages/keystone/api/projects.py", line 107, in _get_project
2023-03-15 20:23:52.045 38 ERROR keystone.server.flask.application     project = PROVIDERS.resource_api.get_project(project_id)
2023-03-15 20:23:52.045 38 ERROR keystone.server.flask.application   File "/var/lib/kolla/venv/lib/python3.9/site-packages/keystone/common/manager.py", line 115, in wrapped
2023-03-15 20:23:52.045 38 ERROR keystone.server.flask.application     __ret_val = __f(*args, **kwargs)
2023-03-15 20:23:52.045 38 ERROR keystone.server.flask.application   File "/var/lib/kolla/venv/lib/python3.9/site-packages/decorator.py", line 232, in fun
2023-03-15 20:23:52.045 38 ERROR keystone.server.flask.application     return caller(func, *(extras + args), **kw)
2023-03-15 20:23:52.045 38 ERROR keystone.server.flask.application   File "/var/lib/kolla/venv/lib/python3.9/site-packages/dogpile/cache/region.py", line 1577, in get_or_create_for_user_func
2023-03-15 20:23:52.045 38 ERROR keystone.server.flask.application     return self.get_or_create(
2023-03-15 20:23:52.045 38 ERROR keystone.server.flask.application   File "/var/lib/kolla/venv/lib/python3.9/site-packages/dogpile/cache/region.py", line 1042, in get_or_create
2023-03-15 20:23:52.045 38 ERROR keystone.server.flask.application     with Lock(
2023-03-15 20:23:52.045 38 ERROR keystone.server.flask.application   File "/var/lib/kolla/venv/lib/python3.9/site-packages/dogpile/lock.py", line 185, in __enter__
2023-03-15 20:23:52.045 38 ERROR keystone.server.flask.application     return self._enter()
2023-03-15 20:23:52.045 38 ERROR keystone.server.flask.application   File "/var/lib/kolla/venv/lib/python3.9/site-packages/dogpile/lock.py", line 94, in _enter
2023-03-15 20:23:52.045 38 ERROR keystone.server.flask.application     generated = self._enter_create(value, createdtime)
2023-03-15 20:23:52.045 38 ERROR keystone.server.flask.application   File "/var/lib/kolla/venv/lib/python3.9/site-packages/dogpile/lock.py", line 178, in _enter_create
2023-03-15 20:23:52.045 38 ERROR keystone.server.flask.application     return self.creator()
2023-03-15 20:23:52.045 38 ERROR keystone.server.flask.application   File "/var/lib/kolla/venv/lib/python3.9/site-packages/dogpile/cache/region.py", line 995, in gen_value
2023-03-15 20:23:52.045 38 ERROR keystone.server.flask.application     created_value = creator(
2023-03-15 20:23:52.045 38 ERROR keystone.server.flask.application   File "/var/lib/kolla/venv/lib/python3.9/site-packages/keystone/resource/core.py", line 903, in get_project
2023-03-15 20:23:52.045 38 ERROR keystone.server.flask.application     return self.driver.get_project(project_id)
2023-03-15 20:23:52.045 38 ERROR keystone.server.flask.application   File "/var/lib/kolla/venv/lib/python3.9/site-packages/keystone/resource/backends/sql.py", line 49, in get_project
2023-03-15 20:23:52.045 38 ERROR keystone.server.flask.application     return self._get_project(session, project_id).to_dict()
2023-03-15 20:23:52.045 38 ERROR keystone.server.flask.application   File "/var/lib/kolla/venv/lib/python3.9/site-packages/keystone/resource/backends/sql.py", line 44, in _get_project
2023-03-15 20:23:52.045 38 ERROR keystone.server.flask.application     raise exception.ProjectNotFound(project_id=project_id)
2023-03-15 20:23:52.045 38 ERROR keystone.server.flask.application keystone.exception.ProjectNotFound: Could not find project: service.
2023-03-15 20:23:52.045 38 ERROR keystone.server.flask.application 
2023-03-15 20:24:02.099 39 ERROR keystone.server.flask.application [None req-5da8d69a-5c42-4ce7-9cd6-d622ea482512 20613e7b2f754801bc6f2aee280741a0 - - all default -] Could not find project: service.: keystone.exception.ProjectNotFound: Could not find project: service.
2023-03-15 20:24:02.099 39 ERROR keystone.server.flask.application Traceback (most recent call last):
2023-03-15 20:24:02.099 39 ERROR keystone.server.flask.application   File "/var/lib/kolla/venv/lib/python3.9/site-packages/flask/app.py", line 1820, in full_dispatch_request
2023-03-15 20:24:02.099 39 ERROR keystone.server.flask.application     rv = self.dispatch_request()
2023-03-15 20:24:02.099 39 ERROR keystone.server.flask.application   File "/var/lib/kolla/venv/lib/python3.9/site-packages/flask/app.py", line 1796, in dispatch_request
2023-03-15 20:24:02.099 39 ERROR keystone.server.flask.application     return self.ensure_sync(self.view_functions[rule.endpoint])(**view_args)
2023-03-15 20:24:02.099 39 ERROR keystone.server.flask.application   File "/var/lib/kolla/venv/lib/python3.9/site-packages/flask_restful/__init__.py", line 467, in wrapper
2023-03-15 20:24:02.099 39 ERROR keystone.server.flask.application     resp = resource(*args, **kwargs)
2023-03-15 20:24:02.099 39 ERROR keystone.server.flask.application   File "/var/lib/kolla/venv/lib/python3.9/site-packages/flask/views.py", line 107, in view
2023-03-15 20:24:02.099 39 ERROR keystone.server.flask.application     return current_app.ensure_sync(self.dispatch_request)(**kwargs)
2023-03-15 20:24:02.099 39 ERROR keystone.server.flask.application   File "/var/lib/kolla/venv/lib/python3.9/site-packages/flask_restful/__init__.py", line 582, in dispatch_request
2023-03-15 20:24:02.099 39 ERROR keystone.server.flask.application     resp = meth(*args, **kwargs)
2023-03-15 20:24:02.099 39 ERROR keystone.server.flask.application   File "/var/lib/kolla/venv/lib/python3.9/site-packages/keystone/api/projects.py", line 151, in get
2023-03-15 20:24:02.099 39 ERROR keystone.server.flask.application     return self._get_project(project_id)
2023-03-15 20:24:02.099 39 ERROR keystone.server.flask.application   File "/var/lib/kolla/venv/lib/python3.9/site-packages/keystone/api/projects.py", line 107, in _get_project
2023-03-15 20:24:02.099 39 ERROR keystone.server.flask.application     project = PROVIDERS.resource_api.get_project(project_id)
2023-03-15 20:24:02.099 39 ERROR keystone.server.flask.application   File "/var/lib/kolla/venv/lib/python3.9/site-packages/keystone/common/manager.py", line 115, in wrapped
2023-03-15 20:24:02.099 39 ERROR keystone.server.flask.application     __ret_val = __f(*args, **kwargs)
2023-03-15 20:24:02.099 39 ERROR keystone.server.flask.application   File "/var/lib/kolla/venv/lib/python3.9/site-packages/decorator.py", line 232, in fun
2023-03-15 20:24:02.099 39 ERROR keystone.server.flask.application     return caller(func, *(extras + args), **kw)
2023-03-15 20:24:02.099 39 ERROR keystone.server.flask.application   File "/var/lib/kolla/venv/lib/python3.9/site-packages/dogpile/cache/region.py", line 1577, in get_or_create_for_user_func
2023-03-15 20:24:02.099 39 ERROR keystone.server.flask.application     return self.get_or_create(
2023-03-15 20:24:02.099 39 ERROR keystone.server.flask.application   File "/var/lib/kolla/venv/lib/python3.9/site-packages/dogpile/cache/region.py", line 1042, in get_or_create
2023-03-15 20:24:02.099 39 ERROR keystone.server.flask.application     with Lock(
2023-03-15 20:24:02.099 39 ERROR keystone.server.flask.application   File "/var/lib/kolla/venv/lib/python3.9/site-packages/dogpile/lock.py", line 185, in __enter__
2023-03-15 20:24:02.099 39 ERROR keystone.server.flask.application     return self._enter()
2023-03-15 20:24:02.099 39 ERROR keystone.server.flask.application   File "/var/lib/kolla/venv/lib/python3.9/site-packages/dogpile/lock.py", line 94, in _enter
2023-03-15 20:24:02.099 39 ERROR keystone.server.flask.application     generated = self._enter_create(value, createdtime)
2023-03-15 20:24:02.099 39 ERROR keystone.server.flask.application   File "/var/lib/kolla/venv/lib/python3.9/site-packages/dogpile/lock.py", line 178, in _enter_create
2023-03-15 20:24:02.099 39 ERROR keystone.server.flask.application     return self.creator()
2023-03-15 20:24:02.099 39 ERROR keystone.server.flask.application   File "/var/lib/kolla/venv/lib/python3.9/site-packages/dogpile/cache/region.py", line 995, in gen_value
2023-03-15 20:24:02.099 39 ERROR keystone.server.flask.application     created_value = creator(
2023-03-15 20:24:02.099 39 ERROR keystone.server.flask.application   File "/var/lib/kolla/venv/lib/python3.9/site-packages/keystone/resource/core.py", line 903, in get_project
2023-03-15 20:24:02.099 39 ERROR keystone.server.flask.application     return self.driver.get_project(project_id)
2023-03-15 20:24:02.099 39 ERROR keystone.server.flask.application   File "/var/lib/kolla/venv/lib/python3.9/site-packages/keystone/resource/backends/sql.py", line 49, in get_project
2023-03-15 20:24:02.099 39 ERROR keystone.server.flask.application     return self._get_project(session, project_id).to_dict()
2023-03-15 20:24:02.099 39 ERROR keystone.server.flask.application   File "/var/lib/kolla/venv/lib/python3.9/site-packages/keystone/resource/backends/sql.py", line 44, in _get_project
2023-03-15 20:24:02.099 39 ERROR keystone.server.flask.application     raise exception.ProjectNotFound(project_id=project_id)
2023-03-15 20:24:02.099 39 ERROR keystone.server.flask.application keystone.exception.ProjectNotFound: Could not find project: service.
2023-03-15 20:24:02.099 39 ERROR keystone.server.flask.application 
2023-03-15 20:24:18.202 39 ERROR keystone.server.flask.application [None req-2358dfc8-d01d-4b0e-8186-d89295a01952 20613e7b2f754801bc6f2aee280741a0 - - all default -] Could not find role: admin.: keystone.exception.RoleNotFound: Could not find role: admin.
2023-03-15 20:24:18.202 39 ERROR keystone.server.flask.application Traceback (most recent call last):
2023-03-15 20:24:18.202 39 ERROR keystone.server.flask.application   File "/var/lib/kolla/venv/lib/python3.9/site-packages/flask/app.py", line 1820, in full_dispatch_request
2023-03-15 20:24:18.202 39 ERROR keystone.server.flask.application     rv = self.dispatch_request()
2023-03-15 20:24:18.202 39 ERROR keystone.server.flask.application   File "/var/lib/kolla/venv/lib/python3.9/site-packages/flask/app.py", line 1796, in dispatch_request
2023-03-15 20:24:18.202 39 ERROR keystone.server.flask.application     return self.ensure_sync(self.view_functions[rule.endpoint])(**view_args)
2023-03-15 20:24:18.202 39 ERROR keystone.server.flask.application   File "/var/lib/kolla/venv/lib/python3.9/site-packages/flask_restful/__init__.py", line 467, in wrapper
2023-03-15 20:24:18.202 39 ERROR keystone.server.flask.application     resp = resource(*args, **kwargs)
2023-03-15 20:24:18.202 39 ERROR keystone.server.flask.application   File "/var/lib/kolla/venv/lib/python3.9/site-packages/flask/views.py", line 107, in view
2023-03-15 20:24:18.202 39 ERROR keystone.server.flask.application     return current_app.ensure_sync(self.dispatch_request)(**kwargs)
2023-03-15 20:24:18.202 39 ERROR keystone.server.flask.application   File "/var/lib/kolla/venv/lib/python3.9/site-packages/flask_restful/__init__.py", line 582, in dispatch_request
2023-03-15 20:24:18.202 39 ERROR keystone.server.flask.application     resp = meth(*args, **kwargs)
2023-03-15 20:24:18.202 39 ERROR keystone.server.flask.application   File "/var/lib/kolla/venv/lib/python3.9/site-packages/keystone/api/roles.py", line 50, in get
2023-03-15 20:24:18.202 39 ERROR keystone.server.flask.application     return self._get_role(role_id)
2023-03-15 20:24:18.202 39 ERROR keystone.server.flask.application   File "/var/lib/kolla/venv/lib/python3.9/site-packages/keystone/api/roles.py", line 70, in _get_role
2023-03-15 20:24:18.202 39 ERROR keystone.server.flask.application     ENFORCER.enforce_call(action='identity:get_role')
2023-03-15 20:24:18.202 39 ERROR keystone.server.flask.application   File "/var/lib/kolla/venv/lib/python3.9/site-packages/keystone/common/rbac_enforcer/enforcer.py", line 402, in enforce_call
2023-03-15 20:24:18.202 39 ERROR keystone.server.flask.application     policy_dict.update(cls._extract_member_target_data(
2023-03-15 20:24:18.202 39 ERROR keystone.server.flask.application   File "/var/lib/kolla/venv/lib/python3.9/site-packages/keystone/common/rbac_enforcer/enforcer.py", line 234, in _extract_member_target_data
2023-03-15 20:24:18.202 39 ERROR keystone.server.flask.application     member_name: func(flask.request.view_args[key])
2023-03-15 20:24:18.202 39 ERROR keystone.server.flask.application   File "/var/lib/kolla/venv/lib/python3.9/site-packages/keystone/common/manager.py", line 115, in wrapped
2023-03-15 20:24:18.202 39 ERROR keystone.server.flask.application     __ret_val = __f(*args, **kwargs)
2023-03-15 20:24:18.202 39 ERROR keystone.server.flask.application   File "/var/lib/kolla/venv/lib/python3.9/site-packages/decorator.py", line 232, in fun
2023-03-15 20:24:18.202 39 ERROR keystone.server.flask.application     return caller(func, *(extras + args), **kw)
2023-03-15 20:24:18.202 39 ERROR keystone.server.flask.application   File "/var/lib/kolla/venv/lib/python3.9/site-packages/dogpile/cache/region.py", line 1577, in get_or_create_for_user_func
2023-03-15 20:24:18.202 39 ERROR keystone.server.flask.application     return self.get_or_create(
2023-03-15 20:24:18.202 39 ERROR keystone.server.flask.application   File "/var/lib/kolla/venv/lib/python3.9/site-packages/dogpile/cache/region.py", line 1042, in get_or_create
2023-03-15 20:24:18.202 39 ERROR keystone.server.flask.application     with Lock(
2023-03-15 20:24:18.202 39 ERROR keystone.server.flask.application   File "/var/lib/kolla/venv/lib/python3.9/site-packages/dogpile/lock.py", line 185, in __enter__
2023-03-15 20:24:18.202 39 ERROR keystone.server.flask.application     return self._enter()
2023-03-15 20:24:18.202 39 ERROR keystone.server.flask.application   File "/var/lib/kolla/venv/lib/python3.9/site-packages/dogpile/lock.py", line 94, in _enter
2023-03-15 20:24:18.202 39 ERROR keystone.server.flask.application     generated = self._enter_create(value, createdtime)
2023-03-15 20:24:18.202 39 ERROR keystone.server.flask.application   File "/var/lib/kolla/venv/lib/python3.9/site-packages/dogpile/lock.py", line 178, in _enter_create
2023-03-15 20:24:18.202 39 ERROR keystone.server.flask.application     return self.creator()
2023-03-15 20:24:18.202 39 ERROR keystone.server.flask.application   File "/var/lib/kolla/venv/lib/python3.9/site-packages/dogpile/cache/region.py", line 995, in gen_value
2023-03-15 20:24:18.202 39 ERROR keystone.server.flask.application     created_value = creator(
2023-03-15 20:24:18.202 39 ERROR keystone.server.flask.application   File "/var/lib/kolla/venv/lib/python3.9/site-packages/keystone/assignment/core.py", line 1276, in get_role
2023-03-15 20:24:18.202 39 ERROR keystone.server.flask.application     return self.driver.get_role(role_id)
2023-03-15 20:24:18.202 39 ERROR keystone.server.flask.application   File "/var/lib/kolla/venv/lib/python3.9/site-packages/keystone/assignment/role_backends/sql.py", line 70, in get_role
2023-03-15 20:24:18.202 39 ERROR keystone.server.flask.application     return self._get_role(session, role_id).to_dict()
2023-03-15 20:24:18.202 39 ERROR keystone.server.flask.application   File "/var/lib/kolla/venv/lib/python3.9/site-packages/keystone/assignment/role_backends/sql.py", line 65, in _get_role
2023-03-15 20:24:18.202 39 ERROR keystone.server.flask.application     raise exception.RoleNotFound(role_id=role_id)
2023-03-15 20:24:18.202 39 ERROR keystone.server.flask.application keystone.exception.RoleNotFound: Could not find role: admin.
2023-03-15 20:24:18.202 39 ERROR keystone.server.flask.application 
2023-03-15 20:24:19.447 39 ERROR keystone.server.flask.application [None req-21cea794-abf0-4e08-b9e2-ccf560cc791d 20613e7b2f754801bc6f2aee280741a0 - - all default -] Could not find user: ironic.: keystone.exception.UserNotFound: Could not find user: ironic.
2023-03-15 20:24:19.447 39 ERROR keystone.server.flask.application Traceback (most recent call last):
2023-03-15 20:24:19.447 39 ERROR keystone.server.flask.application   File "/var/lib/kolla/venv/lib/python3.9/site-packages/flask/app.py", line 1820, in full_dispatch_request
2023-03-15 20:24:19.447 39 ERROR keystone.server.flask.application     rv = self.dispatch_request()
2023-03-15 20:24:19.447 39 ERROR keystone.server.flask.application   File "/var/lib/kolla/venv/lib/python3.9/site-packages/flask/app.py", line 1796, in dispatch_request
2023-03-15 20:24:19.447 39 ERROR keystone.server.flask.application     return self.ensure_sync(self.view_functions[rule.endpoint])(**view_args)
2023-03-15 20:24:19.447 39 ERROR keystone.server.flask.application   File "/var/lib/kolla/venv/lib/python3.9/site-packages/flask_restful/__init__.py", line 467, in wrapper
2023-03-15 20:24:19.447 39 ERROR keystone.server.flask.application     resp = resource(*args, **kwargs)
2023-03-15 20:24:19.447 39 ERROR keystone.server.flask.application   File "/var/lib/kolla/venv/lib/python3.9/site-packages/flask/views.py", line 107, in view
2023-03-15 20:24:19.447 39 ERROR keystone.server.flask.application     return current_app.ensure_sync(self.dispatch_request)(**kwargs)
2023-03-15 20:24:19.447 39 ERROR keystone.server.flask.application   File "/var/lib/kolla/venv/lib/python3.9/site-packages/flask_restful/__init__.py", line 582, in dispatch_request
2023-03-15 20:24:19.447 39 ERROR keystone.server.flask.application     resp = meth(*args, **kwargs)
2023-03-15 20:24:19.447 39 ERROR keystone.server.flask.application   File "/var/lib/kolla/venv/lib/python3.9/site-packages/keystone/api/users.py", line 182, in get
2023-03-15 20:24:19.447 39 ERROR keystone.server.flask.application     return self._get_user(user_id)
2023-03-15 20:24:19.447 39 ERROR keystone.server.flask.application   File "/var/lib/kolla/venv/lib/python3.9/site-packages/keystone/api/users.py", line 194, in _get_user
2023-03-15 20:24:19.447 39 ERROR keystone.server.flask.application     ref = PROVIDERS.identity_api.get_user(user_id)
2023-03-15 20:24:19.447 39 ERROR keystone.server.flask.application   File "/var/lib/kolla/venv/lib/python3.9/site-packages/keystone/common/manager.py", line 115, in wrapped
2023-03-15 20:24:19.447 39 ERROR keystone.server.flask.application     __ret_val = __f(*args, **kwargs)
2023-03-15 20:24:19.447 39 ERROR keystone.server.flask.application   File "/var/lib/kolla/venv/lib/python3.9/site-packages/keystone/identity/core.py", line 414, in wrapper
2023-03-15 20:24:19.447 39 ERROR keystone.server.flask.application     return f(self, *args, **kwargs)
2023-03-15 20:24:19.447 39 ERROR keystone.server.flask.application   File "/var/lib/kolla/venv/lib/python3.9/site-packages/keystone/identity/core.py", line 424, in wrapper
2023-03-15 20:24:19.447 39 ERROR keystone.server.flask.application     return f(self, *args, **kwargs)
2023-03-15 20:24:19.447 39 ERROR keystone.server.flask.application   File "/var/lib/kolla/venv/lib/python3.9/site-packages/decorator.py", line 232, in fun
2023-03-15 20:24:19.447 39 ERROR keystone.server.flask.application     return caller(func, *(extras + args), **kw)
2023-03-15 20:24:19.447 39 ERROR keystone.server.flask.application   File "/var/lib/kolla/venv/lib/python3.9/site-packages/dogpile/cache/region.py", line 1577, in get_or_create_for_user_func
2023-03-15 20:24:19.447 39 ERROR keystone.server.flask.application     return self.get_or_create(
2023-03-15 20:24:19.447 39 ERROR keystone.server.flask.application   File "/var/lib/kolla/venv/lib/python3.9/site-packages/dogpile/cache/region.py", line 1042, in get_or_create
2023-03-15 20:24:19.447 39 ERROR keystone.server.flask.application     with Lock(
2023-03-15 20:24:19.447 39 ERROR keystone.server.flask.application   File "/var/lib/kolla/venv/lib/python3.9/site-packages/dogpile/lock.py", line 185, in __enter__
2023-03-15 20:24:19.447 39 ERROR keystone.server.flask.application     return self._enter()
2023-03-15 20:24:19.447 39 ERROR keystone.server.flask.application   File "/var/lib/kolla/venv/lib/python3.9/site-packages/dogpile/lock.py", line 94, in _enter
2023-03-15 20:24:19.447 39 ERROR keystone.server.flask.application     generated = self._enter_create(value, createdtime)
2023-03-15 20:24:19.447 39 ERROR keystone.server.flask.application   File "/var/lib/kolla/venv/lib/python3.9/site-packages/dogpile/lock.py", line 178, in _enter_create
2023-03-15 20:24:19.447 39 ERROR keystone.server.flask.application     return self.creator()
2023-03-15 20:24:19.447 39 ERROR keystone.server.flask.application   File "/var/lib/kolla/venv/lib/python3.9/site-packages/dogpile/cache/region.py", line 995, in gen_value
2023-03-15 20:24:19.447 39 ERROR keystone.server.flask.application     created_value = creator(
2023-03-15 20:24:19.447 39 ERROR keystone.server.flask.application   File "/var/lib/kolla/venv/lib/python3.9/site-packages/keystone/identity/core.py", line 1011, in get_user
2023-03-15 20:24:19.447 39 ERROR keystone.server.flask.application     ref = driver.get_user(entity_id)
2023-03-15 20:24:19.447 39 ERROR keystone.server.flask.application   File "/var/lib/kolla/venv/lib/python3.9/site-packages/keystone/identity/backends/sql.py", line 200, in get_user
2023-03-15 20:24:19.447 39 ERROR keystone.server.flask.application     self._get_user(session, user_id).to_dict())
2023-03-15 20:24:19.447 39 ERROR keystone.server.flask.application   File "/var/lib/kolla/venv/lib/python3.9/site-packages/keystone/identity/backends/sql.py", line 194, in _get_user
2023-03-15 20:24:19.447 39 ERROR keystone.server.flask.application     raise exception.UserNotFound(user_id=user_id)
2023-03-15 20:24:19.447 39 ERROR keystone.server.flask.application keystone.exception.UserNotFound: Could not find user: ironic.
2023-03-15 20:24:19.447 39 ERROR keystone.server.flask.application 
2023-03-15 20:24:20.355 40 ERROR keystone.server.flask.application [None req-51992b6c-0acb-4ba3-948e-0a4be2c83b90 20613e7b2f754801bc6f2aee280741a0 - - all default -] Could not find project: service.: keystone.exception.ProjectNotFound: Could not find project: service.
2023-03-15 20:24:20.355 40 ERROR keystone.server.flask.application Traceback (most recent call last):
2023-03-15 20:24:20.355 40 ERROR keystone.server.flask.application   File "/var/lib/kolla/venv/lib/python3.9/site-packages/flask/app.py", line 1820, in full_dispatch_request
2023-03-15 20:24:20.355 40 ERROR keystone.server.flask.application     rv = self.dispatch_request()
2023-03-15 20:24:20.355 40 ERROR keystone.server.flask.application   File "/var/lib/kolla/venv/lib/python3.9/site-packages/flask/app.py", line 1796, in dispatch_request
2023-03-15 20:24:20.355 40 ERROR keystone.server.flask.application     return self.ensure_sync(self.view_functions[rule.endpoint])(**view_args)
2023-03-15 20:24:20.355 40 ERROR keystone.server.flask.application   File "/var/lib/kolla/venv/lib/python3.9/site-packages/flask_restful/__init__.py", line 467, in wrapper
2023-03-15 20:24:20.355 40 ERROR keystone.server.flask.application     resp = resource(*args, **kwargs)
2023-03-15 20:24:20.355 40 ERROR keystone.server.flask.application   File "/var/lib/kolla/venv/lib/python3.9/site-packages/flask/views.py", line 107, in view
2023-03-15 20:24:20.355 40 ERROR keystone.server.flask.application     return current_app.ensure_sync(self.dispatch_request)(**kwargs)
2023-03-15 20:24:20.355 40 ERROR keystone.server.flask.application   File "/var/lib/kolla/venv/lib/python3.9/site-packages/flask_restful/__init__.py", line 582, in dispatch_request
2023-03-15 20:24:20.355 40 ERROR keystone.server.flask.application     resp = meth(*args, **kwargs)
2023-03-15 20:24:20.355 40 ERROR keystone.server.flask.application   File "/var/lib/kolla/venv/lib/python3.9/site-packages/keystone/api/projects.py", line 151, in get
2023-03-15 20:24:20.355 40 ERROR keystone.server.flask.application     return self._get_project(project_id)
2023-03-15 20:24:20.355 40 ERROR keystone.server.flask.application   File "/var/lib/kolla/venv/lib/python3.9/site-packages/keystone/api/projects.py", line 107, in _get_project
2023-03-15 20:24:20.355 40 ERROR keystone.server.flask.application     project = PROVIDERS.resource_api.get_project(project_id)
2023-03-15 20:24:20.355 40 ERROR keystone.server.flask.application   File "/var/lib/kolla/venv/lib/python3.9/site-packages/keystone/common/manager.py", line 115, in wrapped
2023-03-15 20:24:20.355 40 ERROR keystone.server.flask.application     __ret_val = __f(*args, **kwargs)
2023-03-15 20:24:20.355 40 ERROR keystone.server.flask.application   File "/var/lib/kolla/venv/lib/python3.9/site-packages/decorator.py", line 232, in fun
2023-03-15 20:24:20.355 40 ERROR keystone.server.flask.application     return caller(func, *(extras + args), **kw)
2023-03-15 20:24:20.355 40 ERROR keystone.server.flask.application   File "/var/lib/kolla/venv/lib/python3.9/site-packages/dogpile/cache/region.py", line 1577, in get_or_create_for_user_func
2023-03-15 20:24:20.355 40 ERROR keystone.server.flask.application     return self.get_or_create(
2023-03-15 20:24:20.355 40 ERROR keystone.server.flask.application   File "/var/lib/kolla/venv/lib/python3.9/site-packages/dogpile/cache/region.py", line 1042, in get_or_create
2023-03-15 20:24:20.355 40 ERROR keystone.server.flask.application     with Lock(
2023-03-15 20:24:20.355 40 ERROR keystone.server.flask.application   File "/var/lib/kolla/venv/lib/python3.9/site-packages/dogpile/lock.py", line 185, in __enter__
2023-03-15 20:24:20.355 40 ERROR keystone.server.flask.application     return self._enter()
2023-03-15 20:24:20.355 40 ERROR keystone.server.flask.application   File "/var/lib/kolla/venv/lib/python3.9/site-packages/dogpile/lock.py", line 94, in _enter
2023-03-15 20:24:20.355 40 ERROR keystone.server.flask.application     generated = self._enter_create(value, createdtime)
2023-03-15 20:24:20.355 40 ERROR keystone.server.flask.application   File "/var/lib/kolla/venv/lib/python3.9/site-packages/dogpile/lock.py", line 178, in _enter_create
2023-03-15 20:24:20.355 40 ERROR keystone.server.flask.application     return self.creator()
2023-03-15 20:24:20.355 40 ERROR keystone.server.flask.application   File "/var/lib/kolla/venv/lib/python3.9/site-packages/dogpile/cache/region.py", line 995, in gen_value
2023-03-15 20:24:20.355 40 ERROR keystone.server.flask.application     created_value = creator(
2023-03-15 20:24:20.355 40 ERROR keystone.server.flask.application   File "/var/lib/kolla/venv/lib/python3.9/site-packages/keystone/resource/core.py", line 903, in get_project
2023-03-15 20:24:20.355 40 ERROR keystone.server.flask.application     return self.driver.get_project(project_id)
2023-03-15 20:24:20.355 40 ERROR keystone.server.flask.application   File "/var/lib/kolla/venv/lib/python3.9/site-packages/keystone/resource/backends/sql.py", line 49, in get_project
2023-03-15 20:24:20.355 40 ERROR keystone.server.flask.application     return self._get_project(session, project_id).to_dict()
2023-03-15 20:24:20.355 40 ERROR keystone.server.flask.application   File "/var/lib/kolla/venv/lib/python3.9/site-packages/keystone/resource/backends/sql.py", line 44, in _get_project
2023-03-15 20:24:20.355 40 ERROR keystone.server.flask.application     raise exception.ProjectNotFound(project_id=project_id)
2023-03-15 20:24:20.355 40 ERROR keystone.server.flask.application keystone.exception.ProjectNotFound: Could not find project: service.
2023-03-15 20:24:20.355 40 ERROR keystone.server.flask.application 
2023-03-15 20:24:30.910 38 ERROR keystone.server.flask.application [None req-715f8f8b-7ef2-4e71-aae4-a29245e16472 20613e7b2f754801bc6f2aee280741a0 - - all default -] Could not find role: admin.: keystone.exception.RoleNotFound: Could not find role: admin.
2023-03-15 20:24:30.910 38 ERROR keystone.server.flask.application Traceback (most recent call last):
2023-03-15 20:24:30.910 38 ERROR keystone.server.flask.application   File "/var/lib/kolla/venv/lib/python3.9/site-packages/flask/app.py", line 1820, in full_dispatch_request
2023-03-15 20:24:30.910 38 ERROR keystone.server.flask.application     rv = self.dispatch_request()
2023-03-15 20:24:30.910 38 ERROR keystone.server.flask.application   File "/var/lib/kolla/venv/lib/python3.9/site-packages/flask/app.py", line 1796, in dispatch_request
2023-03-15 20:24:30.910 38 ERROR keystone.server.flask.application     return self.ensure_sync(self.view_functions[rule.endpoint])(**view_args)
2023-03-15 20:24:30.910 38 ERROR keystone.server.flask.application   File "/var/lib/kolla/venv/lib/python3.9/site-packages/flask_restful/__init__.py", line 467, in wrapper
2023-03-15 20:24:30.910 38 ERROR keystone.server.flask.application     resp = resource(*args, **kwargs)
2023-03-15 20:24:30.910 38 ERROR keystone.server.flask.application   File "/var/lib/kolla/venv/lib/python3.9/site-packages/flask/views.py", line 107, in view
2023-03-15 20:24:30.910 38 ERROR keystone.server.flask.application     return current_app.ensure_sync(self.dispatch_request)(**kwargs)
2023-03-15 20:24:30.910 38 ERROR keystone.server.flask.application   File "/var/lib/kolla/venv/lib/python3.9/site-packages/flask_restful/__init__.py", line 582, in dispatch_request
2023-03-15 20:24:30.910 38 ERROR keystone.server.flask.application     resp = meth(*args, **kwargs)
2023-03-15 20:24:30.910 38 ERROR keystone.server.flask.application   File "/var/lib/kolla/venv/lib/python3.9/site-packages/keystone/api/roles.py", line 50, in get
2023-03-15 20:24:30.910 38 ERROR keystone.server.flask.application     return self._get_role(role_id)
2023-03-15 20:24:30.910 38 ERROR keystone.server.flask.application   File "/var/lib/kolla/venv/lib/python3.9/site-packages/keystone/api/roles.py", line 70, in _get_role
2023-03-15 20:24:30.910 38 ERROR keystone.server.flask.application     ENFORCER.enforce_call(action='identity:get_role')
2023-03-15 20:24:30.910 38 ERROR keystone.server.flask.application   File "/var/lib/kolla/venv/lib/python3.9/site-packages/keystone/common/rbac_enforcer/enforcer.py", line 402, in enforce_call
2023-03-15 20:24:30.910 38 ERROR keystone.server.flask.application     policy_dict.update(cls._extract_member_target_data(
2023-03-15 20:24:30.910 38 ERROR keystone.server.flask.application   File "/var/lib/kolla/venv/lib/python3.9/site-packages/keystone/common/rbac_enforcer/enforcer.py", line 234, in _extract_member_target_data
2023-03-15 20:24:30.910 38 ERROR keystone.server.flask.application     member_name: func(flask.request.view_args[key])
2023-03-15 20:24:30.910 38 ERROR keystone.server.flask.application   File "/var/lib/kolla/venv/lib/python3.9/site-packages/keystone/common/manager.py", line 115, in wrapped
2023-03-15 20:24:30.910 38 ERROR keystone.server.flask.application     __ret_val = __f(*args, **kwargs)
2023-03-15 20:24:30.910 38 ERROR keystone.server.flask.application   File "/var/lib/kolla/venv/lib/python3.9/site-packages/decorator.py", line 232, in fun
2023-03-15 20:24:30.910 38 ERROR keystone.server.flask.application     return caller(func, *(extras + args), **kw)
2023-03-15 20:24:30.910 38 ERROR keystone.server.flask.application   File "/var/lib/kolla/venv/lib/python3.9/site-packages/dogpile/cache/region.py", line 1577, in get_or_create_for_user_func
2023-03-15 20:24:30.910 38 ERROR keystone.server.flask.application     return self.get_or_create(
2023-03-15 20:24:30.910 38 ERROR keystone.server.flask.application   File "/var/lib/kolla/venv/lib/python3.9/site-packages/dogpile/cache/region.py", line 1042, in get_or_create
2023-03-15 20:24:30.910 38 ERROR keystone.server.flask.application     with Lock(
2023-03-15 20:24:30.910 38 ERROR keystone.server.flask.application   File "/var/lib/kolla/venv/lib/python3.9/site-packages/dogpile/lock.py", line 185, in __enter__
2023-03-15 20:24:30.910 38 ERROR keystone.server.flask.application     return self._enter()
2023-03-15 20:24:30.910 38 ERROR keystone.server.flask.application   File "/var/lib/kolla/venv/lib/python3.9/site-packages/dogpile/lock.py", line 94, in _enter
2023-03-15 20:24:30.910 38 ERROR keystone.server.flask.application     generated = self._enter_create(value, createdtime)
2023-03-15 20:24:30.910 38 ERROR keystone.server.flask.application   File "/var/lib/kolla/venv/lib/python3.9/site-packages/dogpile/lock.py", line 178, in _enter_create
2023-03-15 20:24:30.910 38 ERROR keystone.server.flask.application     return self.creator()
2023-03-15 20:24:30.910 38 ERROR keystone.server.flask.application   File "/var/lib/kolla/venv/lib/python3.9/site-packages/dogpile/cache/region.py", line 995, in gen_value
2023-03-15 20:24:30.910 38 ERROR keystone.server.flask.application     created_value = creator(
2023-03-15 20:24:30.910 38 ERROR keystone.server.flask.application   File "/var/lib/kolla/venv/lib/python3.9/site-packages/keystone/assignment/core.py", line 1276, in get_role
2023-03-15 20:24:30.910 38 ERROR keystone.server.flask.application     return self.driver.get_role(role_id)
2023-03-15 20:24:30.910 38 ERROR keystone.server.flask.application   File "/var/lib/kolla/venv/lib/python3.9/site-packages/keystone/assignment/role_backends/sql.py", line 70, in get_role
2023-03-15 20:24:30.910 38 ERROR keystone.server.flask.application     return self._get_role(session, role_id).to_dict()
2023-03-15 20:24:30.910 38 ERROR keystone.server.flask.application   File "/var/lib/kolla/venv/lib/python3.9/site-packages/keystone/assignment/role_backends/sql.py", line 65, in _get_role
2023-03-15 20:24:30.910 38 ERROR keystone.server.flask.application     raise exception.RoleNotFound(role_id=role_id)
2023-03-15 20:24:30.910 38 ERROR keystone.server.flask.application keystone.exception.RoleNotFound: Could not find role: admin.
2023-03-15 20:24:30.910 38 ERROR keystone.server.flask.application 
2023-03-15 20:24:32.371 38 ERROR keystone.server.flask.application [None req-26cfbf6a-c3f7-4744-acaf-43c7873493fd 20613e7b2f754801bc6f2aee280741a0 - - all default -] Could not find user: ironic-inspector.: keystone.exception.UserNotFound: Could not find user: ironic-inspector.
2023-03-15 20:24:32.371 38 ERROR keystone.server.flask.application Traceback (most recent call last):
2023-03-15 20:24:32.371 38 ERROR keystone.server.flask.application   File "/var/lib/kolla/venv/lib/python3.9/site-packages/flask/app.py", line 1820, in full_dispatch_request
2023-03-15 20:24:32.371 38 ERROR keystone.server.flask.application     rv = self.dispatch_request()
2023-03-15 20:24:32.371 38 ERROR keystone.server.flask.application   File "/var/lib/kolla/venv/lib/python3.9/site-packages/flask/app.py", line 1796, in dispatch_request
2023-03-15 20:24:32.371 38 ERROR keystone.server.flask.application     return self.ensure_sync(self.view_functions[rule.endpoint])(**view_args)
2023-03-15 20:24:32.371 38 ERROR keystone.server.flask.application   File "/var/lib/kolla/venv/lib/python3.9/site-packages/flask_restful/__init__.py", line 467, in wrapper
2023-03-15 20:24:32.371 38 ERROR keystone.server.flask.application     resp = resource(*args, **kwargs)
2023-03-15 20:24:32.371 38 ERROR keystone.server.flask.application   File "/var/lib/kolla/venv/lib/python3.9/site-packages/flask/views.py", line 107, in view
2023-03-15 20:24:32.371 38 ERROR keystone.server.flask.application     return current_app.ensure_sync(self.dispatch_request)(**kwargs)
2023-03-15 20:24:32.371 38 ERROR keystone.server.flask.application   File "/var/lib/kolla/venv/lib/python3.9/site-packages/flask_restful/__init__.py", line 582, in dispatch_request
2023-03-15 20:24:32.371 38 ERROR keystone.server.flask.application     resp = meth(*args, **kwargs)
2023-03-15 20:24:32.371 38 ERROR keystone.server.flask.application   File "/var/lib/kolla/venv/lib/python3.9/site-packages/keystone/api/users.py", line 182, in get
2023-03-15 20:24:32.371 38 ERROR keystone.server.flask.application     return self._get_user(user_id)
2023-03-15 20:24:32.371 38 ERROR keystone.server.flask.application   File "/var/lib/kolla/venv/lib/python3.9/site-packages/keystone/api/users.py", line 194, in _get_user
2023-03-15 20:24:32.371 38 ERROR keystone.server.flask.application     ref = PROVIDERS.identity_api.get_user(user_id)
2023-03-15 20:24:32.371 38 ERROR keystone.server.flask.application   File "/var/lib/kolla/venv/lib/python3.9/site-packages/keystone/common/manager.py", line 115, in wrapped
2023-03-15 20:24:32.371 38 ERROR keystone.server.flask.application     __ret_val = __f(*args, **kwargs)
2023-03-15 20:24:32.371 38 ERROR keystone.server.flask.application   File "/var/lib/kolla/venv/lib/python3.9/site-packages/keystone/identity/core.py", line 414, in wrapper
2023-03-15 20:24:32.371 38 ERROR keystone.server.flask.application     return f(self, *args, **kwargs)
2023-03-15 20:24:32.371 38 ERROR keystone.server.flask.application   File "/var/lib/kolla/venv/lib/python3.9/site-packages/keystone/identity/core.py", line 424, in wrapper
2023-03-15 20:24:32.371 38 ERROR keystone.server.flask.application     return f(self, *args, **kwargs)
2023-03-15 20:24:32.371 38 ERROR keystone.server.flask.application   File "/var/lib/kolla/venv/lib/python3.9/site-packages/decorator.py", line 232, in fun
2023-03-15 20:24:32.371 38 ERROR keystone.server.flask.application     return caller(func, *(extras + args), **kw)
2023-03-15 20:24:32.371 38 ERROR keystone.server.flask.application   File "/var/lib/kolla/venv/lib/python3.9/site-packages/dogpile/cache/region.py", line 1577, in get_or_create_for_user_func
2023-03-15 20:24:32.371 38 ERROR keystone.server.flask.application     return self.get_or_create(
2023-03-15 20:24:32.371 38 ERROR keystone.server.flask.application   File "/var/lib/kolla/venv/lib/python3.9/site-packages/dogpile/cache/region.py", line 1042, in get_or_create
2023-03-15 20:24:32.371 38 ERROR keystone.server.flask.application     with Lock(
2023-03-15 20:24:32.371 38 ERROR keystone.server.flask.application   File "/var/lib/kolla/venv/lib/python3.9/site-packages/dogpile/lock.py", line 185, in __enter__
2023-03-15 20:24:32.371 38 ERROR keystone.server.flask.application     return self._enter()
2023-03-15 20:24:32.371 38 ERROR keystone.server.flask.application   File "/var/lib/kolla/venv/lib/python3.9/site-packages/dogpile/lock.py", line 94, in _enter
2023-03-15 20:24:32.371 38 ERROR keystone.server.flask.application     generated = self._enter_create(value, createdtime)
2023-03-15 20:24:32.371 38 ERROR keystone.server.flask.application   File "/var/lib/kolla/venv/lib/python3.9/site-packages/dogpile/lock.py", line 178, in _enter_create
2023-03-15 20:24:32.371 38 ERROR keystone.server.flask.application     return self.creator()
2023-03-15 20:24:32.371 38 ERROR keystone.server.flask.application   File "/var/lib/kolla/venv/lib/python3.9/site-packages/dogpile/cache/region.py", line 995, in gen_value
2023-03-15 20:24:32.371 38 ERROR keystone.server.flask.application     created_value = creator(
2023-03-15 20:24:32.371 38 ERROR keystone.server.flask.application   File "/var/lib/kolla/venv/lib/python3.9/site-packages/keystone/identity/core.py", line 1011, in get_user
2023-03-15 20:24:32.371 38 ERROR keystone.server.flask.application     ref = driver.get_user(entity_id)
2023-03-15 20:24:32.371 38 ERROR keystone.server.flask.application   File "/var/lib/kolla/venv/lib/python3.9/site-packages/keystone/identity/backends/sql.py", line 200, in get_user
2023-03-15 20:24:32.371 38 ERROR keystone.server.flask.application     self._get_user(session, user_id).to_dict())
2023-03-15 20:24:32.371 38 ERROR keystone.server.flask.application   File "/var/lib/kolla/venv/lib/python3.9/site-packages/keystone/identity/backends/sql.py", line 194, in _get_user
2023-03-15 20:24:32.371 38 ERROR keystone.server.flask.application     raise exception.UserNotFound(user_id=user_id)
2023-03-15 20:24:32.371 38 ERROR keystone.server.flask.application keystone.exception.UserNotFound: Could not find user: ironic-inspector.
2023-03-15 20:24:32.371 38 ERROR keystone.server.flask.application 
2023-03-15 20:24:33.218 39 ERROR keystone.server.flask.application [None req-1c8ccf63-4a1d-475c-8374-2c8df70b1b52 20613e7b2f754801bc6f2aee280741a0 - - all default -] Could not find project: service.: keystone.exception.ProjectNotFound: Could not find project: service.
2023-03-15 20:24:33.218 39 ERROR keystone.server.flask.application Traceback (most recent call last):
2023-03-15 20:24:33.218 39 ERROR keystone.server.flask.application   File "/var/lib/kolla/venv/lib/python3.9/site-packages/flask/app.py", line 1820, in full_dispatch_request
2023-03-15 20:24:33.218 39 ERROR keystone.server.flask.application     rv = self.dispatch_request()
2023-03-15 20:24:33.218 39 ERROR keystone.server.flask.application   File "/var/lib/kolla/venv/lib/python3.9/site-packages/flask/app.py", line 1796, in dispatch_request
2023-03-15 20:24:33.218 39 ERROR keystone.server.flask.application     return self.ensure_sync(self.view_functions[rule.endpoint])(**view_args)
2023-03-15 20:24:33.218 39 ERROR keystone.server.flask.application   File "/var/lib/kolla/venv/lib/python3.9/site-packages/flask_restful/__init__.py", line 467, in wrapper
2023-03-15 20:24:33.218 39 ERROR keystone.server.flask.application     resp = resource(*args, **kwargs)
2023-03-15 20:24:33.218 39 ERROR keystone.server.flask.application   File "/var/lib/kolla/venv/lib/python3.9/site-packages/flask/views.py", line 107, in view
2023-03-15 20:24:33.218 39 ERROR keystone.server.flask.application     return current_app.ensure_sync(self.dispatch_request)(**kwargs)
2023-03-15 20:24:33.218 39 ERROR keystone.server.flask.application   File "/var/lib/kolla/venv/lib/python3.9/site-packages/flask_restful/__init__.py", line 582, in dispatch_request
2023-03-15 20:24:33.218 39 ERROR keystone.server.flask.application     resp = meth(*args, **kwargs)
2023-03-15 20:24:33.218 39 ERROR keystone.server.flask.application   File "/var/lib/kolla/venv/lib/python3.9/site-packages/keystone/api/projects.py", line 151, in get
2023-03-15 20:24:33.218 39 ERROR keystone.server.flask.application     return self._get_project(project_id)
2023-03-15 20:24:33.218 39 ERROR keystone.server.flask.application   File "/var/lib/kolla/venv/lib/python3.9/site-packages/keystone/api/projects.py", line 107, in _get_project
2023-03-15 20:24:33.218 39 ERROR keystone.server.flask.application     project = PROVIDERS.resource_api.get_project(project_id)
2023-03-15 20:24:33.218 39 ERROR keystone.server.flask.application   File "/var/lib/kolla/venv/lib/python3.9/site-packages/keystone/common/manager.py", line 115, in wrapped
2023-03-15 20:24:33.218 39 ERROR keystone.server.flask.application     __ret_val = __f(*args, **kwargs)
2023-03-15 20:24:33.218 39 ERROR keystone.server.flask.application   File "/var/lib/kolla/venv/lib/python3.9/site-packages/decorator.py", line 232, in fun
2023-03-15 20:24:33.218 39 ERROR keystone.server.flask.application     return caller(func, *(extras + args), **kw)
2023-03-15 20:24:33.218 39 ERROR keystone.server.flask.application   File "/var/lib/kolla/venv/lib/python3.9/site-packages/dogpile/cache/region.py", line 1577, in get_or_create_for_user_func
2023-03-15 20:24:33.218 39 ERROR keystone.server.flask.application     return self.get_or_create(
2023-03-15 20:24:33.218 39 ERROR keystone.server.flask.application   File "/var/lib/kolla/venv/lib/python3.9/site-packages/dogpile/cache/region.py", line 1042, in get_or_create
2023-03-15 20:24:33.218 39 ERROR keystone.server.flask.application     with Lock(
2023-03-15 20:24:33.218 39 ERROR keystone.server.flask.application   File "/var/lib/kolla/venv/lib/python3.9/site-packages/dogpile/lock.py", line 185, in __enter__
2023-03-15 20:24:33.218 39 ERROR keystone.server.flask.application     return self._enter()
2023-03-15 20:24:33.218 39 ERROR keystone.server.flask.application   File "/var/lib/kolla/venv/lib/python3.9/site-packages/dogpile/lock.py", line 94, in _enter
2023-03-15 20:24:33.218 39 ERROR keystone.server.flask.application     generated = self._enter_create(value, createdtime)
2023-03-15 20:24:33.218 39 ERROR keystone.server.flask.application   File "/var/lib/kolla/venv/lib/python3.9/site-packages/dogpile/lock.py", line 178, in _enter_create
2023-03-15 20:24:33.218 39 ERROR keystone.server.flask.application     return self.creator()
2023-03-15 20:24:33.218 39 ERROR keystone.server.flask.application   File "/var/lib/kolla/venv/lib/python3.9/site-packages/dogpile/cache/region.py", line 995, in gen_value
2023-03-15 20:24:33.218 39 ERROR keystone.server.flask.application     created_value = creator(
2023-03-15 20:24:33.218 39 ERROR keystone.server.flask.application   File "/var/lib/kolla/venv/lib/python3.9/site-packages/keystone/resource/core.py", line 903, in get_project
2023-03-15 20:24:33.218 39 ERROR keystone.server.flask.application     return self.driver.get_project(project_id)
2023-03-15 20:24:33.218 39 ERROR keystone.server.flask.application   File "/var/lib/kolla/venv/lib/python3.9/site-packages/keystone/resource/backends/sql.py", line 49, in get_project
2023-03-15 20:24:33.218 39 ERROR keystone.server.flask.application     return self._get_project(session, project_id).to_dict()
2023-03-15 20:24:33.218 39 ERROR keystone.server.flask.application   File "/var/lib/kolla/venv/lib/python3.9/site-packages/keystone/resource/backends/sql.py", line 44, in _get_project
2023-03-15 20:24:33.218 39 ERROR keystone.server.flask.application     raise exception.ProjectNotFound(project_id=project_id)
2023-03-15 20:24:33.218 39 ERROR keystone.server.flask.application keystone.exception.ProjectNotFound: Could not find project: service.
2023-03-15 20:24:33.218 39 ERROR keystone.server.flask.application 
2023-03-15 20:27:41.398 38 ERROR keystone.server.flask.application [None req-440cdf2b-3f9e-460b-b948-c281d3a4b5d6 20613e7b2f754801bc6f2aee280741a0 - - all default -] Could not find project: service.: keystone.exception.ProjectNotFound: Could not find project: service.
2023-03-15 20:27:41.398 38 ERROR keystone.server.flask.application Traceback (most recent call last):
2023-03-15 20:27:41.398 38 ERROR keystone.server.flask.application   File "/var/lib/kolla/venv/lib/python3.9/site-packages/flask/app.py", line 1820, in full_dispatch_request
2023-03-15 20:27:41.398 38 ERROR keystone.server.flask.application     rv = self.dispatch_request()
2023-03-15 20:27:41.398 38 ERROR keystone.server.flask.application   File "/var/lib/kolla/venv/lib/python3.9/site-packages/flask/app.py", line 1796, in dispatch_request
2023-03-15 20:27:41.398 38 ERROR keystone.server.flask.application     return self.ensure_sync(self.view_functions[rule.endpoint])(**view_args)
2023-03-15 20:27:41.398 38 ERROR keystone.server.flask.application   File "/var/lib/kolla/venv/lib/python3.9/site-packages/flask_restful/__init__.py", line 467, in wrapper
2023-03-15 20:27:41.398 38 ERROR keystone.server.flask.application     resp = resource(*args, **kwargs)
2023-03-15 20:27:41.398 38 ERROR keystone.server.flask.application   File "/var/lib/kolla/venv/lib/python3.9/site-packages/flask/views.py", line 107, in view
2023-03-15 20:27:41.398 38 ERROR keystone.server.flask.application     return current_app.ensure_sync(self.dispatch_request)(**kwargs)
2023-03-15 20:27:41.398 38 ERROR keystone.server.flask.application   File "/var/lib/kolla/venv/lib/python3.9/site-packages/flask_restful/__init__.py", line 582, in dispatch_request
2023-03-15 20:27:41.398 38 ERROR keystone.server.flask.application     resp = meth(*args, **kwargs)
2023-03-15 20:27:41.398 38 ERROR keystone.server.flask.application   File "/var/lib/kolla/venv/lib/python3.9/site-packages/keystone/api/projects.py", line 151, in get
2023-03-15 20:27:41.398 38 ERROR keystone.server.flask.application     return self._get_project(project_id)
2023-03-15 20:27:41.398 38 ERROR keystone.server.flask.application   File "/var/lib/kolla/venv/lib/python3.9/site-packages/keystone/api/projects.py", line 107, in _get_project
2023-03-15 20:27:41.398 38 ERROR keystone.server.flask.application     project = PROVIDERS.resource_api.get_project(project_id)
2023-03-15 20:27:41.398 38 ERROR keystone.server.flask.application   File "/var/lib/kolla/venv/lib/python3.9/site-packages/keystone/common/manager.py", line 115, in wrapped
2023-03-15 20:27:41.398 38 ERROR keystone.server.flask.application     __ret_val = __f(*args, **kwargs)
2023-03-15 20:27:41.398 38 ERROR keystone.server.flask.application   File "/var/lib/kolla/venv/lib/python3.9/site-packages/decorator.py", line 232, in fun
2023-03-15 20:27:41.398 38 ERROR keystone.server.flask.application     return caller(func, *(extras + args), **kw)
2023-03-15 20:27:41.398 38 ERROR keystone.server.flask.application   File "/var/lib/kolla/venv/lib/python3.9/site-packages/dogpile/cache/region.py", line 1577, in get_or_create_for_user_func
2023-03-15 20:27:41.398 38 ERROR keystone.server.flask.application     return self.get_or_create(
2023-03-15 20:27:41.398 38 ERROR keystone.server.flask.application   File "/var/lib/kolla/venv/lib/python3.9/site-packages/dogpile/cache/region.py", line 1042, in get_or_create
2023-03-15 20:27:41.398 38 ERROR keystone.server.flask.application     with Lock(
2023-03-15 20:27:41.398 38 ERROR keystone.server.flask.application   File "/var/lib/kolla/venv/lib/python3.9/site-packages/dogpile/lock.py", line 185, in __enter__
2023-03-15 20:27:41.398 38 ERROR keystone.server.flask.application     return self._enter()
2023-03-15 20:27:41.398 38 ERROR keystone.server.flask.application   File "/var/lib/kolla/venv/lib/python3.9/site-packages/dogpile/lock.py", line 94, in _enter
2023-03-15 20:27:41.398 38 ERROR keystone.server.flask.application     generated = self._enter_create(value, createdtime)
2023-03-15 20:27:41.398 38 ERROR keystone.server.flask.application   File "/var/lib/kolla/venv/lib/python3.9/site-packages/dogpile/lock.py", line 178, in _enter_create
2023-03-15 20:27:41.398 38 ERROR keystone.server.flask.application     return self.creator()
2023-03-15 20:27:41.398 38 ERROR keystone.server.flask.application   File "/var/lib/kolla/venv/lib/python3.9/site-packages/dogpile/cache/region.py", line 995, in gen_value
2023-03-15 20:27:41.398 38 ERROR keystone.server.flask.application     created_value = creator(
2023-03-15 20:27:41.398 38 ERROR keystone.server.flask.application   File "/var/lib/kolla/venv/lib/python3.9/site-packages/keystone/resource/core.py", line 903, in get_project
2023-03-15 20:27:41.398 38 ERROR keystone.server.flask.application     return self.driver.get_project(project_id)
2023-03-15 20:27:41.398 38 ERROR keystone.server.flask.application   File "/var/lib/kolla/venv/lib/python3.9/site-packages/keystone/resource/backends/sql.py", line 49, in get_project
2023-03-15 20:27:41.398 38 ERROR keystone.server.flask.application     return self._get_project(session, project_id).to_dict()
2023-03-15 20:27:41.398 38 ERROR keystone.server.flask.application   File "/var/lib/kolla/venv/lib/python3.9/site-packages/keystone/resource/backends/sql.py", line 44, in _get_project
2023-03-15 20:27:41.398 38 ERROR keystone.server.flask.application     raise exception.ProjectNotFound(project_id=project_id)
2023-03-15 20:27:41.398 38 ERROR keystone.server.flask.application keystone.exception.ProjectNotFound: Could not find project: service.
2023-03-15 20:27:41.398 38 ERROR keystone.server.flask.application 
2023-03-15 20:27:56.958 38 ERROR keystone.server.flask.application [None req-838c8165-b3a0-4c1f-ab3a-1ad83abcd44e 20613e7b2f754801bc6f2aee280741a0 - - all default -] Could not find role: admin.: keystone.exception.RoleNotFound: Could not find role: admin.
2023-03-15 20:27:56.958 38 ERROR keystone.server.flask.application Traceback (most recent call last):
2023-03-15 20:27:56.958 38 ERROR keystone.server.flask.application   File "/var/lib/kolla/venv/lib/python3.9/site-packages/flask/app.py", line 1820, in full_dispatch_request
2023-03-15 20:27:56.958 38 ERROR keystone.server.flask.application     rv = self.dispatch_request()
2023-03-15 20:27:56.958 38 ERROR keystone.server.flask.application   File "/var/lib/kolla/venv/lib/python3.9/site-packages/flask/app.py", line 1796, in dispatch_request
2023-03-15 20:27:56.958 38 ERROR keystone.server.flask.application     return self.ensure_sync(self.view_functions[rule.endpoint])(**view_args)
2023-03-15 20:27:56.958 38 ERROR keystone.server.flask.application   File "/var/lib/kolla/venv/lib/python3.9/site-packages/flask_restful/__init__.py", line 467, in wrapper
2023-03-15 20:27:56.958 38 ERROR keystone.server.flask.application     resp = resource(*args, **kwargs)
2023-03-15 20:27:56.958 38 ERROR keystone.server.flask.application   File "/var/lib/kolla/venv/lib/python3.9/site-packages/flask/views.py", line 107, in view
2023-03-15 20:27:56.958 38 ERROR keystone.server.flask.application     return current_app.ensure_sync(self.dispatch_request)(**kwargs)
2023-03-15 20:27:56.958 38 ERROR keystone.server.flask.application   File "/var/lib/kolla/venv/lib/python3.9/site-packages/flask_restful/__init__.py", line 582, in dispatch_request
2023-03-15 20:27:56.958 38 ERROR keystone.server.flask.application     resp = meth(*args, **kwargs)
2023-03-15 20:27:56.958 38 ERROR keystone.server.flask.application   File "/var/lib/kolla/venv/lib/python3.9/site-packages/keystone/api/roles.py", line 50, in get
2023-03-15 20:27:56.958 38 ERROR keystone.server.flask.application     return self._get_role(role_id)
2023-03-15 20:27:56.958 38 ERROR keystone.server.flask.application   File "/var/lib/kolla/venv/lib/python3.9/site-packages/keystone/api/roles.py", line 70, in _get_role
2023-03-15 20:27:56.958 38 ERROR keystone.server.flask.application     ENFORCER.enforce_call(action='identity:get_role')
2023-03-15 20:27:56.958 38 ERROR keystone.server.flask.application   File "/var/lib/kolla/venv/lib/python3.9/site-packages/keystone/common/rbac_enforcer/enforcer.py", line 402, in enforce_call
2023-03-15 20:27:56.958 38 ERROR keystone.server.flask.application     policy_dict.update(cls._extract_member_target_data(
2023-03-15 20:27:56.958 38 ERROR keystone.server.flask.application   File "/var/lib/kolla/venv/lib/python3.9/site-packages/keystone/common/rbac_enforcer/enforcer.py", line 234, in _extract_member_target_data
2023-03-15 20:27:56.958 38 ERROR keystone.server.flask.application     member_name: func(flask.request.view_args[key])
2023-03-15 20:27:56.958 38 ERROR keystone.server.flask.application   File "/var/lib/kolla/venv/lib/python3.9/site-packages/keystone/common/manager.py", line 115, in wrapped
2023-03-15 20:27:56.958 38 ERROR keystone.server.flask.application     __ret_val = __f(*args, **kwargs)
2023-03-15 20:27:56.958 38 ERROR keystone.server.flask.application   File "/var/lib/kolla/venv/lib/python3.9/site-packages/decorator.py", line 232, in fun
2023-03-15 20:27:56.958 38 ERROR keystone.server.flask.application     return caller(func, *(extras + args), **kw)
2023-03-15 20:27:56.958 38 ERROR keystone.server.flask.application   File "/var/lib/kolla/venv/lib/python3.9/site-packages/dogpile/cache/region.py", line 1577, in get_or_create_for_user_func
2023-03-15 20:27:56.958 38 ERROR keystone.server.flask.application     return self.get_or_create(
2023-03-15 20:27:56.958 38 ERROR keystone.server.flask.application   File "/var/lib/kolla/venv/lib/python3.9/site-packages/dogpile/cache/region.py", line 1042, in get_or_create
2023-03-15 20:27:56.958 38 ERROR keystone.server.flask.application     with Lock(
2023-03-15 20:27:56.958 38 ERROR keystone.server.flask.application   File "/var/lib/kolla/venv/lib/python3.9/site-packages/dogpile/lock.py", line 185, in __enter__
2023-03-15 20:27:56.958 38 ERROR keystone.server.flask.application     return self._enter()
2023-03-15 20:27:56.958 38 ERROR keystone.server.flask.application   File "/var/lib/kolla/venv/lib/python3.9/site-packages/dogpile/lock.py", line 94, in _enter
2023-03-15 20:27:56.958 38 ERROR keystone.server.flask.application     generated = self._enter_create(value, createdtime)
2023-03-15 20:27:56.958 38 ERROR keystone.server.flask.application   File "/var/lib/kolla/venv/lib/python3.9/site-packages/dogpile/lock.py", line 178, in _enter_create
2023-03-15 20:27:56.958 38 ERROR keystone.server.flask.application     return self.creator()
2023-03-15 20:27:56.958 38 ERROR keystone.server.flask.application   File "/var/lib/kolla/venv/lib/python3.9/site-packages/dogpile/cache/region.py", line 995, in gen_value
2023-03-15 20:27:56.958 38 ERROR keystone.server.flask.application     created_value = creator(
2023-03-15 20:27:56.958 38 ERROR keystone.server.flask.application   File "/var/lib/kolla/venv/lib/python3.9/site-packages/keystone/assignment/core.py", line 1276, in get_role
2023-03-15 20:27:56.958 38 ERROR keystone.server.flask.application     return self.driver.get_role(role_id)
2023-03-15 20:27:56.958 38 ERROR keystone.server.flask.application   File "/var/lib/kolla/venv/lib/python3.9/site-packages/keystone/assignment/role_backends/sql.py", line 70, in get_role
2023-03-15 20:27:56.958 38 ERROR keystone.server.flask.application     return self._get_role(session, role_id).to_dict()
2023-03-15 20:27:56.958 38 ERROR keystone.server.flask.application   File "/var/lib/kolla/venv/lib/python3.9/site-packages/keystone/assignment/role_backends/sql.py", line 65, in _get_role
2023-03-15 20:27:56.958 38 ERROR keystone.server.flask.application     raise exception.RoleNotFound(role_id=role_id)
2023-03-15 20:27:56.958 38 ERROR keystone.server.flask.application keystone.exception.RoleNotFound: Could not find role: admin.
2023-03-15 20:27:56.958 38 ERROR keystone.server.flask.application 
2023-03-15 20:27:58.406 38 ERROR keystone.server.flask.application [None req-4e1cc918-a385-458e-b4ff-10098b7fff22 20613e7b2f754801bc6f2aee280741a0 - - all default -] Could not find user: neutron.: keystone.exception.UserNotFound: Could not find user: neutron.
2023-03-15 20:27:58.406 38 ERROR keystone.server.flask.application Traceback (most recent call last):
2023-03-15 20:27:58.406 38 ERROR keystone.server.flask.application   File "/var/lib/kolla/venv/lib/python3.9/site-packages/flask/app.py", line 1820, in full_dispatch_request
2023-03-15 20:27:58.406 38 ERROR keystone.server.flask.application     rv = self.dispatch_request()
2023-03-15 20:27:58.406 38 ERROR keystone.server.flask.application   File "/var/lib/kolla/venv/lib/python3.9/site-packages/flask/app.py", line 1796, in dispatch_request
2023-03-15 20:27:58.406 38 ERROR keystone.server.flask.application     return self.ensure_sync(self.view_functions[rule.endpoint])(**view_args)
2023-03-15 20:27:58.406 38 ERROR keystone.server.flask.application   File "/var/lib/kolla/venv/lib/python3.9/site-packages/flask_restful/__init__.py", line 467, in wrapper
2023-03-15 20:27:58.406 38 ERROR keystone.server.flask.application     resp = resource(*args, **kwargs)
2023-03-15 20:27:58.406 38 ERROR keystone.server.flask.application   File "/var/lib/kolla/venv/lib/python3.9/site-packages/flask/views.py", line 107, in view
2023-03-15 20:27:58.406 38 ERROR keystone.server.flask.application     return current_app.ensure_sync(self.dispatch_request)(**kwargs)
2023-03-15 20:27:58.406 38 ERROR keystone.server.flask.application   File "/var/lib/kolla/venv/lib/python3.9/site-packages/flask_restful/__init__.py", line 582, in dispatch_request
2023-03-15 20:27:58.406 38 ERROR keystone.server.flask.application     resp = meth(*args, **kwargs)
2023-03-15 20:27:58.406 38 ERROR keystone.server.flask.application   File "/var/lib/kolla/venv/lib/python3.9/site-packages/keystone/api/users.py", line 182, in get
2023-03-15 20:27:58.406 38 ERROR keystone.server.flask.application     return self._get_user(user_id)
2023-03-15 20:27:58.406 38 ERROR keystone.server.flask.application   File "/var/lib/kolla/venv/lib/python3.9/site-packages/keystone/api/users.py", line 194, in _get_user
2023-03-15 20:27:58.406 38 ERROR keystone.server.flask.application     ref = PROVIDERS.identity_api.get_user(user_id)
2023-03-15 20:27:58.406 38 ERROR keystone.server.flask.application   File "/var/lib/kolla/venv/lib/python3.9/site-packages/keystone/common/manager.py", line 115, in wrapped
2023-03-15 20:27:58.406 38 ERROR keystone.server.flask.application     __ret_val = __f(*args, **kwargs)
2023-03-15 20:27:58.406 38 ERROR keystone.server.flask.application   File "/var/lib/kolla/venv/lib/python3.9/site-packages/keystone/identity/core.py", line 414, in wrapper
2023-03-15 20:27:58.406 38 ERROR keystone.server.flask.application     return f(self, *args, **kwargs)
2023-03-15 20:27:58.406 38 ERROR keystone.server.flask.application   File "/var/lib/kolla/venv/lib/python3.9/site-packages/keystone/identity/core.py", line 424, in wrapper
2023-03-15 20:27:58.406 38 ERROR keystone.server.flask.application     return f(self, *args, **kwargs)
2023-03-15 20:27:58.406 38 ERROR keystone.server.flask.application   File "/var/lib/kolla/venv/lib/python3.9/site-packages/decorator.py", line 232, in fun
2023-03-15 20:27:58.406 38 ERROR keystone.server.flask.application     return caller(func, *(extras + args), **kw)
2023-03-15 20:27:58.406 38 ERROR keystone.server.flask.application   File "/var/lib/kolla/venv/lib/python3.9/site-packages/dogpile/cache/region.py", line 1577, in get_or_create_for_user_func
2023-03-15 20:27:58.406 38 ERROR keystone.server.flask.application     return self.get_or_create(
2023-03-15 20:27:58.406 38 ERROR keystone.server.flask.application   File "/var/lib/kolla/venv/lib/python3.9/site-packages/dogpile/cache/region.py", line 1042, in get_or_create
2023-03-15 20:27:58.406 38 ERROR keystone.server.flask.application     with Lock(
2023-03-15 20:27:58.406 38 ERROR keystone.server.flask.application   File "/var/lib/kolla/venv/lib/python3.9/site-packages/dogpile/lock.py", line 185, in __enter__
2023-03-15 20:27:58.406 38 ERROR keystone.server.flask.application     return self._enter()
2023-03-15 20:27:58.406 38 ERROR keystone.server.flask.application   File "/var/lib/kolla/venv/lib/python3.9/site-packages/dogpile/lock.py", line 94, in _enter
2023-03-15 20:27:58.406 38 ERROR keystone.server.flask.application     generated = self._enter_create(value, createdtime)
2023-03-15 20:27:58.406 38 ERROR keystone.server.flask.application   File "/var/lib/kolla/venv/lib/python3.9/site-packages/dogpile/lock.py", line 178, in _enter_create
2023-03-15 20:27:58.406 38 ERROR keystone.server.flask.application     return self.creator()
2023-03-15 20:27:58.406 38 ERROR keystone.server.flask.application   File "/var/lib/kolla/venv/lib/python3.9/site-packages/dogpile/cache/region.py", line 995, in gen_value
2023-03-15 20:27:58.406 38 ERROR keystone.server.flask.application     created_value = creator(
2023-03-15 20:27:58.406 38 ERROR keystone.server.flask.application   File "/var/lib/kolla/venv/lib/python3.9/site-packages/keystone/identity/core.py", line 1011, in get_user
2023-03-15 20:27:58.406 38 ERROR keystone.server.flask.application     ref = driver.get_user(entity_id)
2023-03-15 20:27:58.406 38 ERROR keystone.server.flask.application   File "/var/lib/kolla/venv/lib/python3.9/site-packages/keystone/identity/backends/sql.py", line 200, in get_user
2023-03-15 20:27:58.406 38 ERROR keystone.server.flask.application     self._get_user(session, user_id).to_dict())
2023-03-15 20:27:58.406 38 ERROR keystone.server.flask.application   File "/var/lib/kolla/venv/lib/python3.9/site-packages/keystone/identity/backends/sql.py", line 194, in _get_user
2023-03-15 20:27:58.406 38 ERROR keystone.server.flask.application     raise exception.UserNotFound(user_id=user_id)
2023-03-15 20:27:58.406 38 ERROR keystone.server.flask.application keystone.exception.UserNotFound: Could not find user: neutron.
2023-03-15 20:27:58.406 38 ERROR keystone.server.flask.application 
2023-03-15 20:27:59.268 40 ERROR keystone.server.flask.application [None req-69719b44-2dba-49cd-a39f-a864b5f4a14b 20613e7b2f754801bc6f2aee280741a0 - - all default -] Could not find project: service.: keystone.exception.ProjectNotFound: Could not find project: service.
2023-03-15 20:27:59.268 40 ERROR keystone.server.flask.application Traceback (most recent call last):
2023-03-15 20:27:59.268 40 ERROR keystone.server.flask.application   File "/var/lib/kolla/venv/lib/python3.9/site-packages/flask/app.py", line 1820, in full_dispatch_request
2023-03-15 20:27:59.268 40 ERROR keystone.server.flask.application     rv = self.dispatch_request()
2023-03-15 20:27:59.268 40 ERROR keystone.server.flask.application   File "/var/lib/kolla/venv/lib/python3.9/site-packages/flask/app.py", line 1796, in dispatch_request
2023-03-15 20:27:59.268 40 ERROR keystone.server.flask.application     return self.ensure_sync(self.view_functions[rule.endpoint])(**view_args)
2023-03-15 20:27:59.268 40 ERROR keystone.server.flask.application   File "/var/lib/kolla/venv/lib/python3.9/site-packages/flask_restful/__init__.py", line 467, in wrapper
2023-03-15 20:27:59.268 40 ERROR keystone.server.flask.application     resp = resource(*args, **kwargs)
2023-03-15 20:27:59.268 40 ERROR keystone.server.flask.application   File "/var/lib/kolla/venv/lib/python3.9/site-packages/flask/views.py", line 107, in view
2023-03-15 20:27:59.268 40 ERROR keystone.server.flask.application     return current_app.ensure_sync(self.dispatch_request)(**kwargs)
2023-03-15 20:27:59.268 40 ERROR keystone.server.flask.application   File "/var/lib/kolla/venv/lib/python3.9/site-packages/flask_restful/__init__.py", line 582, in dispatch_request
2023-03-15 20:27:59.268 40 ERROR keystone.server.flask.application     resp = meth(*args, **kwargs)
2023-03-15 20:27:59.268 40 ERROR keystone.server.flask.application   File "/var/lib/kolla/venv/lib/python3.9/site-packages/keystone/api/projects.py", line 151, in get
2023-03-15 20:27:59.268 40 ERROR keystone.server.flask.application     return self._get_project(project_id)
2023-03-15 20:27:59.268 40 ERROR keystone.server.flask.application   File "/var/lib/kolla/venv/lib/python3.9/site-packages/keystone/api/projects.py", line 107, in _get_project
2023-03-15 20:27:59.268 40 ERROR keystone.server.flask.application     project = PROVIDERS.resource_api.get_project(project_id)
2023-03-15 20:27:59.268 40 ERROR keystone.server.flask.application   File "/var/lib/kolla/venv/lib/python3.9/site-packages/keystone/common/manager.py", line 115, in wrapped
2023-03-15 20:27:59.268 40 ERROR keystone.server.flask.application     __ret_val = __f(*args, **kwargs)
2023-03-15 20:27:59.268 40 ERROR keystone.server.flask.application   File "/var/lib/kolla/venv/lib/python3.9/site-packages/decorator.py", line 232, in fun
2023-03-15 20:27:59.268 40 ERROR keystone.server.flask.application     return caller(func, *(extras + args), **kw)
2023-03-15 20:27:59.268 40 ERROR keystone.server.flask.application   File "/var/lib/kolla/venv/lib/python3.9/site-packages/dogpile/cache/region.py", line 1577, in get_or_create_for_user_func
2023-03-15 20:27:59.268 40 ERROR keystone.server.flask.application     return self.get_or_create(
2023-03-15 20:27:59.268 40 ERROR keystone.server.flask.application   File "/var/lib/kolla/venv/lib/python3.9/site-packages/dogpile/cache/region.py", line 1042, in get_or_create
2023-03-15 20:27:59.268 40 ERROR keystone.server.flask.application     with Lock(
2023-03-15 20:27:59.268 40 ERROR keystone.server.flask.application   File "/var/lib/kolla/venv/lib/python3.9/site-packages/dogpile/lock.py", line 185, in __enter__
2023-03-15 20:27:59.268 40 ERROR keystone.server.flask.application     return self._enter()
2023-03-15 20:27:59.268 40 ERROR keystone.server.flask.application   File "/var/lib/kolla/venv/lib/python3.9/site-packages/dogpile/lock.py", line 94, in _enter
2023-03-15 20:27:59.268 40 ERROR keystone.server.flask.application     generated = self._enter_create(value, createdtime)
2023-03-15 20:27:59.268 40 ERROR keystone.server.flask.application   File "/var/lib/kolla/venv/lib/python3.9/site-packages/dogpile/lock.py", line 178, in _enter_create
2023-03-15 20:27:59.268 40 ERROR keystone.server.flask.application     return self.creator()
2023-03-15 20:27:59.268 40 ERROR keystone.server.flask.application   File "/var/lib/kolla/venv/lib/python3.9/site-packages/dogpile/cache/region.py", line 995, in gen_value
2023-03-15 20:27:59.268 40 ERROR keystone.server.flask.application     created_value = creator(
2023-03-15 20:27:59.268 40 ERROR keystone.server.flask.application   File "/var/lib/kolla/venv/lib/python3.9/site-packages/keystone/resource/core.py", line 903, in get_project
2023-03-15 20:27:59.268 40 ERROR keystone.server.flask.application     return self.driver.get_project(project_id)
2023-03-15 20:27:59.268 40 ERROR keystone.server.flask.application   File "/var/lib/kolla/venv/lib/python3.9/site-packages/keystone/resource/backends/sql.py", line 49, in get_project
2023-03-15 20:27:59.268 40 ERROR keystone.server.flask.application     return self._get_project(session, project_id).to_dict()
2023-03-15 20:27:59.268 40 ERROR keystone.server.flask.application   File "/var/lib/kolla/venv/lib/python3.9/site-packages/keystone/resource/backends/sql.py", line 44, in _get_project
2023-03-15 20:27:59.268 40 ERROR keystone.server.flask.application     raise exception.ProjectNotFound(project_id=project_id)
2023-03-15 20:27:59.268 40 ERROR keystone.server.flask.application keystone.exception.ProjectNotFound: Could not find project: service.
2023-03-15 20:27:59.268 40 ERROR keystone.server.flask.application 
