2023-02-13 21:56:09.687704 2023-02-13 21:56:09.685 37 WARNING keystone.common.rbac_enforcer.enforcer [None req-8fe0aa00-a841-4601-9462-452620b7d424 f030e67c936f4531b915f6b82c685e84 - - all default -] Deprecated policy rules found. Use oslopolicy-policy-generator and oslopolicy-policy-upgrade to detect and resolve deprecated policies in your configuration.\x1b[00m
2023-02-13 21:56:10.110660 2023-02-13 21:56:10.109 38 WARNING keystone.common.rbac_enforcer.enforcer [None req-f12f12e9-0361-4e6d-a559-95c086288fc7 f030e67c936f4531b915f6b82c685e84 - - all default -] Deprecated policy rules found. Use oslopolicy-policy-generator and oslopolicy-policy-upgrade to detect and resolve deprecated policies in your configuration.\x1b[00m
2023-02-13 23:11:53.249143 2023-02-13 23:11:53.236 37 ERROR keystone.server.flask.application [None req-90c5435b-32bd-427f-b0ad-317a076cad52 f030e67c936f4531b915f6b82c685e84 - - all default -] Could not find project: service.: keystone.exception.ProjectNotFound: Could not find project: service.
2023-02-13 23:11:53.249222 2023-02-13 23:11:53.236 37 ERROR keystone.server.flask.application Traceback (most recent call last):
2023-02-13 23:11:53.249237 2023-02-13 23:11:53.236 37 ERROR keystone.server.flask.application   File "/var/lib/kolla/venv/lib/python3.9/site-packages/flask/app.py", line 1820, in full_dispatch_request
2023-02-13 23:11:53.249249 2023-02-13 23:11:53.236 37 ERROR keystone.server.flask.application     rv = self.dispatch_request()
2023-02-13 23:11:53.249260 2023-02-13 23:11:53.236 37 ERROR keystone.server.flask.application   File "/var/lib/kolla/venv/lib/python3.9/site-packages/flask/app.py", line 1796, in dispatch_request
2023-02-13 23:11:53.249272 2023-02-13 23:11:53.236 37 ERROR keystone.server.flask.application     return self.ensure_sync(self.view_functions[rule.endpoint])(**view_args)
2023-02-13 23:11:53.249283 2023-02-13 23:11:53.236 37 ERROR keystone.server.flask.application   File "/var/lib/kolla/venv/lib/python3.9/site-packages/flask_restful/__init__.py", line 467, in wrapper
2023-02-13 23:11:53.249294 2023-02-13 23:11:53.236 37 ERROR keystone.server.flask.application     resp = resource(*args, **kwargs)
2023-02-13 23:11:53.249305 2023-02-13 23:11:53.236 37 ERROR keystone.server.flask.application   File "/var/lib/kolla/venv/lib/python3.9/site-packages/flask/views.py", line 107, in view
2023-02-13 23:11:53.249316 2023-02-13 23:11:53.236 37 ERROR keystone.server.flask.application     return current_app.ensure_sync(self.dispatch_request)(**kwargs)
2023-02-13 23:11:53.249327 2023-02-13 23:11:53.236 37 ERROR keystone.server.flask.application   File "/var/lib/kolla/venv/lib/python3.9/site-packages/flask_restful/__init__.py", line 582, in dispatch_request
2023-02-13 23:11:53.249338 2023-02-13 23:11:53.236 37 ERROR keystone.server.flask.application     resp = meth(*args, **kwargs)
2023-02-13 23:11:53.249355 2023-02-13 23:11:53.236 37 ERROR keystone.server.flask.application   File "/var/lib/kolla/venv/lib/python3.9/site-packages/keystone/api/projects.py", line 151, in get
2023-02-13 23:11:53.249369 2023-02-13 23:11:53.236 37 ERROR keystone.server.flask.application     return self._get_project(project_id)
2023-02-13 23:11:53.249380 2023-02-13 23:11:53.236 37 ERROR keystone.server.flask.application   File "/var/lib/kolla/venv/lib/python3.9/site-packages/keystone/api/projects.py", line 107, in _get_project
2023-02-13 23:11:53.249392 2023-02-13 23:11:53.236 37 ERROR keystone.server.flask.application     project = PROVIDERS.resource_api.get_project(project_id)
2023-02-13 23:11:53.249403 2023-02-13 23:11:53.236 37 ERROR keystone.server.flask.application   File "/var/lib/kolla/venv/lib/python3.9/site-packages/keystone/common/manager.py", line 115, in wrapped
2023-02-13 23:11:53.249413 2023-02-13 23:11:53.236 37 ERROR keystone.server.flask.application     __ret_val = __f(*args, **kwargs)
2023-02-13 23:11:53.249424 2023-02-13 23:11:53.236 37 ERROR keystone.server.flask.application   File "/var/lib/kolla/venv/lib/python3.9/site-packages/decorator.py", line 232, in fun
2023-02-13 23:11:53.249435 2023-02-13 23:11:53.236 37 ERROR keystone.server.flask.application     return caller(func, *(extras + args), **kw)
2023-02-13 23:11:53.249489 2023-02-13 23:11:53.236 37 ERROR keystone.server.flask.application   File "/var/lib/kolla/venv/lib/python3.9/site-packages/dogpile/cache/region.py", line 1577, in get_or_create_for_user_func
2023-02-13 23:11:53.249506 2023-02-13 23:11:53.236 37 ERROR keystone.server.flask.application     return self.get_or_create(
2023-02-13 23:11:53.249517 2023-02-13 23:11:53.236 37 ERROR keystone.server.flask.application   File "/var/lib/kolla/venv/lib/python3.9/site-packages/dogpile/cache/region.py", line 1042, in get_or_create
2023-02-13 23:11:53.249529 2023-02-13 23:11:53.236 37 ERROR keystone.server.flask.application     with Lock(
2023-02-13 23:11:53.249539 2023-02-13 23:11:53.236 37 ERROR keystone.server.flask.application   File "/var/lib/kolla/venv/lib/python3.9/site-packages/dogpile/lock.py", line 185, in __enter__
2023-02-13 23:11:53.249582 2023-02-13 23:11:53.236 37 ERROR keystone.server.flask.application     return self._enter()
2023-02-13 23:11:53.249604 2023-02-13 23:11:53.236 37 ERROR keystone.server.flask.application   File "/var/lib/kolla/venv/lib/python3.9/site-packages/dogpile/lock.py", line 94, in _enter
2023-02-13 23:11:53.249625 2023-02-13 23:11:53.236 37 ERROR keystone.server.flask.application     generated = self._enter_create(value, createdtime)
2023-02-13 23:11:53.249643 2023-02-13 23:11:53.236 37 ERROR keystone.server.flask.application   File "/var/lib/kolla/venv/lib/python3.9/site-packages/dogpile/lock.py", line 178, in _enter_create
2023-02-13 23:11:53.249661 2023-02-13 23:11:53.236 37 ERROR keystone.server.flask.application     return self.creator()
2023-02-13 23:11:53.249675 2023-02-13 23:11:53.236 37 ERROR keystone.server.flask.application   File "/var/lib/kolla/venv/lib/python3.9/site-packages/dogpile/cache/region.py", line 995, in gen_value
2023-02-13 23:11:53.249687 2023-02-13 23:11:53.236 37 ERROR keystone.server.flask.application     created_value = creator(
2023-02-13 23:11:53.249697 2023-02-13 23:11:53.236 37 ERROR keystone.server.flask.application   File "/var/lib/kolla/venv/lib/python3.9/site-packages/keystone/resource/core.py", line 903, in get_project
2023-02-13 23:11:53.249708 2023-02-13 23:11:53.236 37 ERROR keystone.server.flask.application     return self.driver.get_project(project_id)
2023-02-13 23:11:53.249719 2023-02-13 23:11:53.236 37 ERROR keystone.server.flask.application   File "/var/lib/kolla/venv/lib/python3.9/site-packages/keystone/resource/backends/sql.py", line 49, in get_project
2023-02-13 23:11:53.249730 2023-02-13 23:11:53.236 37 ERROR keystone.server.flask.application     return self._get_project(session, project_id).to_dict()
2023-02-13 23:11:53.249741 2023-02-13 23:11:53.236 37 ERROR keystone.server.flask.application   File "/var/lib/kolla/venv/lib/python3.9/site-packages/keystone/resource/backends/sql.py", line 44, in _get_project
2023-02-13 23:11:53.249793 2023-02-13 23:11:53.236 37 ERROR keystone.server.flask.application     raise exception.ProjectNotFound(project_id=project_id)
2023-02-13 23:11:53.249809 2023-02-13 23:11:53.236 37 ERROR keystone.server.flask.application keystone.exception.ProjectNotFound: Could not find project: service.
2023-02-13 23:11:53.249821 2023-02-13 23:11:53.236 37 ERROR keystone.server.flask.application \x1b[00m
2023-02-13 23:12:03.164665 2023-02-13 23:12:03.159 37 ERROR keystone.server.flask.application [None req-65fd7370-272a-412c-bd98-b18ca15962a6 f030e67c936f4531b915f6b82c685e84 - - all default -] Could not find project: service.: keystone.exception.ProjectNotFound: Could not find project: service.
2023-02-13 23:12:03.164714 2023-02-13 23:12:03.159 37 ERROR keystone.server.flask.application Traceback (most recent call last):
2023-02-13 23:12:03.164726 2023-02-13 23:12:03.159 37 ERROR keystone.server.flask.application   File "/var/lib/kolla/venv/lib/python3.9/site-packages/flask/app.py", line 1820, in full_dispatch_request
2023-02-13 23:12:03.164737 2023-02-13 23:12:03.159 37 ERROR keystone.server.flask.application     rv = self.dispatch_request()
2023-02-13 23:12:03.164798 2023-02-13 23:12:03.159 37 ERROR keystone.server.flask.application   File "/var/lib/kolla/venv/lib/python3.9/site-packages/flask/app.py", line 1796, in dispatch_request
2023-02-13 23:12:03.164831 2023-02-13 23:12:03.159 37 ERROR keystone.server.flask.application     return self.ensure_sync(self.view_functions[rule.endpoint])(**view_args)
2023-02-13 23:12:03.164841 2023-02-13 23:12:03.159 37 ERROR keystone.server.flask.application   File "/var/lib/kolla/venv/lib/python3.9/site-packages/flask_restful/__init__.py", line 467, in wrapper
2023-02-13 23:12:03.164851 2023-02-13 23:12:03.159 37 ERROR keystone.server.flask.application     resp = resource(*args, **kwargs)
2023-02-13 23:12:03.164860 2023-02-13 23:12:03.159 37 ERROR keystone.server.flask.application   File "/var/lib/kolla/venv/lib/python3.9/site-packages/flask/views.py", line 107, in view
2023-02-13 23:12:03.164871 2023-02-13 23:12:03.159 37 ERROR keystone.server.flask.application     return current_app.ensure_sync(self.dispatch_request)(**kwargs)
2023-02-13 23:12:03.164880 2023-02-13 23:12:03.159 37 ERROR keystone.server.flask.application   File "/var/lib/kolla/venv/lib/python3.9/site-packages/flask_restful/__init__.py", line 582, in dispatch_request
2023-02-13 23:12:03.164890 2023-02-13 23:12:03.159 37 ERROR keystone.server.flask.application     resp = meth(*args, **kwargs)
2023-02-13 23:12:03.164900 2023-02-13 23:12:03.159 37 ERROR keystone.server.flask.application   File "/var/lib/kolla/venv/lib/python3.9/site-packages/keystone/api/projects.py", line 151, in get
2023-02-13 23:12:03.164910 2023-02-13 23:12:03.159 37 ERROR keystone.server.flask.application     return self._get_project(project_id)
2023-02-13 23:12:03.164920 2023-02-13 23:12:03.159 37 ERROR keystone.server.flask.application   File "/var/lib/kolla/venv/lib/python3.9/site-packages/keystone/api/projects.py", line 107, in _get_project
2023-02-13 23:12:03.164930 2023-02-13 23:12:03.159 37 ERROR keystone.server.flask.application     project = PROVIDERS.resource_api.get_project(project_id)
2023-02-13 23:12:03.164939 2023-02-13 23:12:03.159 37 ERROR keystone.server.flask.application   File "/var/lib/kolla/venv/lib/python3.9/site-packages/keystone/common/manager.py", line 115, in wrapped
2023-02-13 23:12:03.164949 2023-02-13 23:12:03.159 37 ERROR keystone.server.flask.application     __ret_val = __f(*args, **kwargs)
2023-02-13 23:12:03.164959 2023-02-13 23:12:03.159 37 ERROR keystone.server.flask.application   File "/var/lib/kolla/venv/lib/python3.9/site-packages/decorator.py", line 232, in fun
2023-02-13 23:12:03.164969 2023-02-13 23:12:03.159 37 ERROR keystone.server.flask.application     return caller(func, *(extras + args), **kw)
2023-02-13 23:12:03.164989 2023-02-13 23:12:03.159 37 ERROR keystone.server.flask.application   File "/var/lib/kolla/venv/lib/python3.9/site-packages/dogpile/cache/region.py", line 1577, in get_or_create_for_user_func
2023-02-13 23:12:03.165004 2023-02-13 23:12:03.159 37 ERROR keystone.server.flask.application     return self.get_or_create(
2023-02-13 23:12:03.165014 2023-02-13 23:12:03.159 37 ERROR keystone.server.flask.application   File "/var/lib/kolla/venv/lib/python3.9/site-packages/dogpile/cache/region.py", line 1042, in get_or_create
2023-02-13 23:12:03.165024 2023-02-13 23:12:03.159 37 ERROR keystone.server.flask.application     with Lock(
2023-02-13 23:12:03.165033 2023-02-13 23:12:03.159 37 ERROR keystone.server.flask.application   File "/var/lib/kolla/venv/lib/python3.9/site-packages/dogpile/lock.py", line 185, in __enter__
2023-02-13 23:12:03.165043 2023-02-13 23:12:03.159 37 ERROR keystone.server.flask.application     return self._enter()
2023-02-13 23:12:03.165052 2023-02-13 23:12:03.159 37 ERROR keystone.server.flask.application   File "/var/lib/kolla/venv/lib/python3.9/site-packages/dogpile/lock.py", line 94, in _enter
2023-02-13 23:12:03.165062 2023-02-13 23:12:03.159 37 ERROR keystone.server.flask.application     generated = self._enter_create(value, createdtime)
2023-02-13 23:12:03.165071 2023-02-13 23:12:03.159 37 ERROR keystone.server.flask.application   File "/var/lib/kolla/venv/lib/python3.9/site-packages/dogpile/lock.py", line 178, in _enter_create
2023-02-13 23:12:03.165094 2023-02-13 23:12:03.159 37 ERROR keystone.server.flask.application     return self.creator()
2023-02-13 23:12:03.165105 2023-02-13 23:12:03.159 37 ERROR keystone.server.flask.application   File "/var/lib/kolla/venv/lib/python3.9/site-packages/dogpile/cache/region.py", line 995, in gen_value
2023-02-13 23:12:03.165114 2023-02-13 23:12:03.159 37 ERROR keystone.server.flask.application     created_value = creator(
2023-02-13 23:12:03.165124 2023-02-13 23:12:03.159 37 ERROR keystone.server.flask.application   File "/var/lib/kolla/venv/lib/python3.9/site-packages/keystone/resource/core.py", line 903, in get_project
2023-02-13 23:12:03.165134 2023-02-13 23:12:03.159 37 ERROR keystone.server.flask.application     return self.driver.get_project(project_id)
2023-02-13 23:12:03.165143 2023-02-13 23:12:03.159 37 ERROR keystone.server.flask.application   File "/var/lib/kolla/venv/lib/python3.9/site-packages/keystone/resource/backends/sql.py", line 49, in get_project
2023-02-13 23:12:03.165153 2023-02-13 23:12:03.159 37 ERROR keystone.server.flask.application     return self._get_project(session, project_id).to_dict()
2023-02-13 23:12:03.165162 2023-02-13 23:12:03.159 37 ERROR keystone.server.flask.application   File "/var/lib/kolla/venv/lib/python3.9/site-packages/keystone/resource/backends/sql.py", line 44, in _get_project
2023-02-13 23:12:03.165172 2023-02-13 23:12:03.159 37 ERROR keystone.server.flask.application     raise exception.ProjectNotFound(project_id=project_id)
2023-02-13 23:12:03.165182 2023-02-13 23:12:03.159 37 ERROR keystone.server.flask.application keystone.exception.ProjectNotFound: Could not find project: service.
2023-02-13 23:12:03.165191 2023-02-13 23:12:03.159 37 ERROR keystone.server.flask.application \x1b[00m
2023-02-13 23:12:20.437991 2023-02-13 23:12:20.419 38 ERROR keystone.server.flask.application [None req-382a581e-c89e-4186-8fd7-3b723ea61fbc f030e67c936f4531b915f6b82c685e84 - - all default -] Could not find role: admin.: keystone.exception.RoleNotFound: Could not find role: admin.
2023-02-13 23:12:20.438061 2023-02-13 23:12:20.419 38 ERROR keystone.server.flask.application Traceback (most recent call last):
2023-02-13 23:12:20.438073 2023-02-13 23:12:20.419 38 ERROR keystone.server.flask.application   File "/var/lib/kolla/venv/lib/python3.9/site-packages/flask/app.py", line 1820, in full_dispatch_request
2023-02-13 23:12:20.438089 2023-02-13 23:12:20.419 38 ERROR keystone.server.flask.application     rv = self.dispatch_request()
2023-02-13 23:12:20.438099 2023-02-13 23:12:20.419 38 ERROR keystone.server.flask.application   File "/var/lib/kolla/venv/lib/python3.9/site-packages/flask/app.py", line 1796, in dispatch_request
2023-02-13 23:12:20.438110 2023-02-13 23:12:20.419 38 ERROR keystone.server.flask.application     return self.ensure_sync(self.view_functions[rule.endpoint])(**view_args)
2023-02-13 23:12:20.438120 2023-02-13 23:12:20.419 38 ERROR keystone.server.flask.application   File "/var/lib/kolla/venv/lib/python3.9/site-packages/flask_restful/__init__.py", line 467, in wrapper
2023-02-13 23:12:20.438130 2023-02-13 23:12:20.419 38 ERROR keystone.server.flask.application     resp = resource(*args, **kwargs)
2023-02-13 23:12:20.438150 2023-02-13 23:12:20.419 38 ERROR keystone.server.flask.application   File "/var/lib/kolla/venv/lib/python3.9/site-packages/flask/views.py", line 107, in view
2023-02-13 23:12:20.438164 2023-02-13 23:12:20.419 38 ERROR keystone.server.flask.application     return current_app.ensure_sync(self.dispatch_request)(**kwargs)
2023-02-13 23:12:20.438174 2023-02-13 23:12:20.419 38 ERROR keystone.server.flask.application   File "/var/lib/kolla/venv/lib/python3.9/site-packages/flask_restful/__init__.py", line 582, in dispatch_request
2023-02-13 23:12:20.438185 2023-02-13 23:12:20.419 38 ERROR keystone.server.flask.application     resp = meth(*args, **kwargs)
2023-02-13 23:12:20.438194 2023-02-13 23:12:20.419 38 ERROR keystone.server.flask.application   File "/var/lib/kolla/venv/lib/python3.9/site-packages/keystone/api/roles.py", line 50, in get
2023-02-13 23:12:20.438231 2023-02-13 23:12:20.419 38 ERROR keystone.server.flask.application     return self._get_role(role_id)
2023-02-13 23:12:20.438244 2023-02-13 23:12:20.419 38 ERROR keystone.server.flask.application   File "/var/lib/kolla/venv/lib/python3.9/site-packages/keystone/api/roles.py", line 70, in _get_role
2023-02-13 23:12:20.438255 2023-02-13 23:12:20.419 38 ERROR keystone.server.flask.application     ENFORCER.enforce_call(action='identity:get_role')
2023-02-13 23:12:20.438281 2023-02-13 23:12:20.419 38 ERROR keystone.server.flask.application   File "/var/lib/kolla/venv/lib/python3.9/site-packages/keystone/common/rbac_enforcer/enforcer.py", line 402, in enforce_call
2023-02-13 23:12:20.438295 2023-02-13 23:12:20.419 38 ERROR keystone.server.flask.application     policy_dict.update(cls._extract_member_target_data(
2023-02-13 23:12:20.438312 2023-02-13 23:12:20.419 38 ERROR keystone.server.flask.application   File "/var/lib/kolla/venv/lib/python3.9/site-packages/keystone/common/rbac_enforcer/enforcer.py", line 234, in _extract_member_target_data
2023-02-13 23:12:20.438326 2023-02-13 23:12:20.419 38 ERROR keystone.server.flask.application     member_name: func(flask.request.view_args[key])
2023-02-13 23:12:20.438336 2023-02-13 23:12:20.419 38 ERROR keystone.server.flask.application   File "/var/lib/kolla/venv/lib/python3.9/site-packages/keystone/common/manager.py", line 115, in wrapped
2023-02-13 23:12:20.438347 2023-02-13 23:12:20.419 38 ERROR keystone.server.flask.application     __ret_val = __f(*args, **kwargs)
2023-02-13 23:12:20.438356 2023-02-13 23:12:20.419 38 ERROR keystone.server.flask.application   File "/var/lib/kolla/venv/lib/python3.9/site-packages/decorator.py", line 232, in fun
2023-02-13 23:12:20.438367 2023-02-13 23:12:20.419 38 ERROR keystone.server.flask.application     return caller(func, *(extras + args), **kw)
2023-02-13 23:12:20.438376 2023-02-13 23:12:20.419 38 ERROR keystone.server.flask.application   File "/var/lib/kolla/venv/lib/python3.9/site-packages/dogpile/cache/region.py", line 1577, in get_or_create_for_user_func
2023-02-13 23:12:20.438387 2023-02-13 23:12:20.419 38 ERROR keystone.server.flask.application     return self.get_or_create(
2023-02-13 23:12:20.438397 2023-02-13 23:12:20.419 38 ERROR keystone.server.flask.application   File "/var/lib/kolla/venv/lib/python3.9/site-packages/dogpile/cache/region.py", line 1042, in get_or_create
2023-02-13 23:12:20.438422 2023-02-13 23:12:20.419 38 ERROR keystone.server.flask.application     with Lock(
2023-02-13 23:12:20.438433 2023-02-13 23:12:20.419 38 ERROR keystone.server.flask.application   File "/var/lib/kolla/venv/lib/python3.9/site-packages/dogpile/lock.py", line 185, in __enter__
2023-02-13 23:12:20.438443 2023-02-13 23:12:20.419 38 ERROR keystone.server.flask.application     return self._enter()
2023-02-13 23:12:20.438453 2023-02-13 23:12:20.419 38 ERROR keystone.server.flask.application   File "/var/lib/kolla/venv/lib/python3.9/site-packages/dogpile/lock.py", line 94, in _enter
2023-02-13 23:12:20.438463 2023-02-13 23:12:20.419 38 ERROR keystone.server.flask.application     generated = self._enter_create(value, createdtime)
2023-02-13 23:12:20.438473 2023-02-13 23:12:20.419 38 ERROR keystone.server.flask.application   File "/var/lib/kolla/venv/lib/python3.9/site-packages/dogpile/lock.py", line 178, in _enter_create
2023-02-13 23:12:20.438483 2023-02-13 23:12:20.419 38 ERROR keystone.server.flask.application     return self.creator()
2023-02-13 23:12:20.438493 2023-02-13 23:12:20.419 38 ERROR keystone.server.flask.application   File "/var/lib/kolla/venv/lib/python3.9/site-packages/dogpile/cache/region.py", line 995, in gen_value
2023-02-13 23:12:20.438503 2023-02-13 23:12:20.419 38 ERROR keystone.server.flask.application     created_value = creator(
2023-02-13 23:12:20.438513 2023-02-13 23:12:20.419 38 ERROR keystone.server.flask.application   File "/var/lib/kolla/venv/lib/python3.9/site-packages/keystone/assignment/core.py", line 1276, in get_role
2023-02-13 23:12:20.438617 2023-02-13 23:12:20.419 38 ERROR keystone.server.flask.application     return self.driver.get_role(role_id)
2023-02-13 23:12:20.438631 2023-02-13 23:12:20.419 38 ERROR keystone.server.flask.application   File "/var/lib/kolla/venv/lib/python3.9/site-packages/keystone/assignment/role_backends/sql.py", line 70, in get_role
2023-02-13 23:12:20.438642 2023-02-13 23:12:20.419 38 ERROR keystone.server.flask.application     return self._get_role(session, role_id).to_dict()
2023-02-13 23:12:20.438652 2023-02-13 23:12:20.419 38 ERROR keystone.server.flask.application   File "/var/lib/kolla/venv/lib/python3.9/site-packages/keystone/assignment/role_backends/sql.py", line 65, in _get_role
2023-02-13 23:12:20.438662 2023-02-13 23:12:20.419 38 ERROR keystone.server.flask.application     raise exception.RoleNotFound(role_id=role_id)
2023-02-13 23:12:20.438672 2023-02-13 23:12:20.419 38 ERROR keystone.server.flask.application keystone.exception.RoleNotFound: Could not find role: admin.
2023-02-13 23:12:20.438682 2023-02-13 23:12:20.419 38 ERROR keystone.server.flask.application \x1b[00m
2023-02-13 23:12:21.610269 2023-02-13 23:12:21.602 37 ERROR keystone.server.flask.application [None req-4741fcdd-6d22-4bf3-81c5-1426e8cb8a31 f030e67c936f4531b915f6b82c685e84 - - all default -] Could not find user: ironic.: keystone.exception.UserNotFound: Could not find user: ironic.
2023-02-13 23:12:21.610318 2023-02-13 23:12:21.602 37 ERROR keystone.server.flask.application Traceback (most recent call last):
2023-02-13 23:12:21.610329 2023-02-13 23:12:21.602 37 ERROR keystone.server.flask.application   File "/var/lib/kolla/venv/lib/python3.9/site-packages/flask/app.py", line 1820, in full_dispatch_request
2023-02-13 23:12:21.610340 2023-02-13 23:12:21.602 37 ERROR keystone.server.flask.application     rv = self.dispatch_request()
2023-02-13 23:12:21.610350 2023-02-13 23:12:21.602 37 ERROR keystone.server.flask.application   File "/var/lib/kolla/venv/lib/python3.9/site-packages/flask/app.py", line 1796, in dispatch_request
2023-02-13 23:12:21.610360 2023-02-13 23:12:21.602 37 ERROR keystone.server.flask.application     return self.ensure_sync(self.view_functions[rule.endpoint])(**view_args)
2023-02-13 23:12:21.610370 2023-02-13 23:12:21.602 37 ERROR keystone.server.flask.application   File "/var/lib/kolla/venv/lib/python3.9/site-packages/flask_restful/__init__.py", line 467, in wrapper
2023-02-13 23:12:21.610380 2023-02-13 23:12:21.602 37 ERROR keystone.server.flask.application     resp = resource(*args, **kwargs)
2023-02-13 23:12:21.610397 2023-02-13 23:12:21.602 37 ERROR keystone.server.flask.application   File "/var/lib/kolla/venv/lib/python3.9/site-packages/flask/views.py", line 107, in view
2023-02-13 23:12:21.610410 2023-02-13 23:12:21.602 37 ERROR keystone.server.flask.application     return current_app.ensure_sync(self.dispatch_request)(**kwargs)
2023-02-13 23:12:21.610420 2023-02-13 23:12:21.602 37 ERROR keystone.server.flask.application   File "/var/lib/kolla/venv/lib/python3.9/site-packages/flask_restful/__init__.py", line 582, in dispatch_request
2023-02-13 23:12:21.610431 2023-02-13 23:12:21.602 37 ERROR keystone.server.flask.application     resp = meth(*args, **kwargs)
2023-02-13 23:12:21.610440 2023-02-13 23:12:21.602 37 ERROR keystone.server.flask.application   File "/var/lib/kolla/venv/lib/python3.9/site-packages/keystone/api/users.py", line 182, in get
2023-02-13 23:12:21.610450 2023-02-13 23:12:21.602 37 ERROR keystone.server.flask.application     return self._get_user(user_id)
2023-02-13 23:12:21.610461 2023-02-13 23:12:21.602 37 ERROR keystone.server.flask.application   File "/var/lib/kolla/venv/lib/python3.9/site-packages/keystone/api/users.py", line 194, in _get_user
2023-02-13 23:12:21.610488 2023-02-13 23:12:21.602 37 ERROR keystone.server.flask.application     ref = PROVIDERS.identity_api.get_user(user_id)
2023-02-13 23:12:21.610498 2023-02-13 23:12:21.602 37 ERROR keystone.server.flask.application   File "/var/lib/kolla/venv/lib/python3.9/site-packages/keystone/common/manager.py", line 115, in wrapped
2023-02-13 23:12:21.610567 2023-02-13 23:12:21.602 37 ERROR keystone.server.flask.application     __ret_val = __f(*args, **kwargs)
2023-02-13 23:12:21.610580 2023-02-13 23:12:21.602 37 ERROR keystone.server.flask.application   File "/var/lib/kolla/venv/lib/python3.9/site-packages/keystone/identity/core.py", line 414, in wrapper
2023-02-13 23:12:21.610590 2023-02-13 23:12:21.602 37 ERROR keystone.server.flask.application     return f(self, *args, **kwargs)
2023-02-13 23:12:21.610600 2023-02-13 23:12:21.602 37 ERROR keystone.server.flask.application   File "/var/lib/kolla/venv/lib/python3.9/site-packages/keystone/identity/core.py", line 424, in wrapper
2023-02-13 23:12:21.610610 2023-02-13 23:12:21.602 37 ERROR keystone.server.flask.application     return f(self, *args, **kwargs)
2023-02-13 23:12:21.610619 2023-02-13 23:12:21.602 37 ERROR keystone.server.flask.application   File "/var/lib/kolla/venv/lib/python3.9/site-packages/decorator.py", line 232, in fun
2023-02-13 23:12:21.610629 2023-02-13 23:12:21.602 37 ERROR keystone.server.flask.application     return caller(func, *(extras + args), **kw)
2023-02-13 23:12:21.610639 2023-02-13 23:12:21.602 37 ERROR keystone.server.flask.application   File "/var/lib/kolla/venv/lib/python3.9/site-packages/dogpile/cache/region.py", line 1577, in get_or_create_for_user_func
2023-02-13 23:12:21.610649 2023-02-13 23:12:21.602 37 ERROR keystone.server.flask.application     return self.get_or_create(
2023-02-13 23:12:21.610659 2023-02-13 23:12:21.602 37 ERROR keystone.server.flask.application   File "/var/lib/kolla/venv/lib/python3.9/site-packages/dogpile/cache/region.py", line 1042, in get_or_create
2023-02-13 23:12:21.610670 2023-02-13 23:12:21.602 37 ERROR keystone.server.flask.application     with Lock(
2023-02-13 23:12:21.610679 2023-02-13 23:12:21.602 37 ERROR keystone.server.flask.application   File "/var/lib/kolla/venv/lib/python3.9/site-packages/dogpile/lock.py", line 185, in __enter__
2023-02-13 23:12:21.610689 2023-02-13 23:12:21.602 37 ERROR keystone.server.flask.application     return self._enter()
2023-02-13 23:12:21.610699 2023-02-13 23:12:21.602 37 ERROR keystone.server.flask.application   File "/var/lib/kolla/venv/lib/python3.9/site-packages/dogpile/lock.py", line 94, in _enter
2023-02-13 23:12:21.610709 2023-02-13 23:12:21.602 37 ERROR keystone.server.flask.application     generated = self._enter_create(value, createdtime)
2023-02-13 23:12:21.610719 2023-02-13 23:12:21.602 37 ERROR keystone.server.flask.application   File "/var/lib/kolla/venv/lib/python3.9/site-packages/dogpile/lock.py", line 178, in _enter_create
2023-02-13 23:12:21.610729 2023-02-13 23:12:21.602 37 ERROR keystone.server.flask.application     return self.creator()
2023-02-13 23:12:21.610738 2023-02-13 23:12:21.602 37 ERROR keystone.server.flask.application   File "/var/lib/kolla/venv/lib/python3.9/site-packages/dogpile/cache/region.py", line 995, in gen_value
2023-02-13 23:12:21.610781 2023-02-13 23:12:21.602 37 ERROR keystone.server.flask.application     created_value = creator(
2023-02-13 23:12:21.610797 2023-02-13 23:12:21.602 37 ERROR keystone.server.flask.application   File "/var/lib/kolla/venv/lib/python3.9/site-packages/keystone/identity/core.py", line 1011, in get_user
2023-02-13 23:12:21.610808 2023-02-13 23:12:21.602 37 ERROR keystone.server.flask.application     ref = driver.get_user(entity_id)
2023-02-13 23:12:21.610817 2023-02-13 23:12:21.602 37 ERROR keystone.server.flask.application   File "/var/lib/kolla/venv/lib/python3.9/site-packages/keystone/identity/backends/sql.py", line 200, in get_user
2023-02-13 23:12:21.610828 2023-02-13 23:12:21.602 37 ERROR keystone.server.flask.application     self._get_user(session, user_id).to_dict())
2023-02-13 23:12:21.610838 2023-02-13 23:12:21.602 37 ERROR keystone.server.flask.application   File "/var/lib/kolla/venv/lib/python3.9/site-packages/keystone/identity/backends/sql.py", line 194, in _get_user
2023-02-13 23:12:21.610848 2023-02-13 23:12:21.602 37 ERROR keystone.server.flask.application     raise exception.UserNotFound(user_id=user_id)
2023-02-13 23:12:21.610884 2023-02-13 23:12:21.602 37 ERROR keystone.server.flask.application keystone.exception.UserNotFound: Could not find user: ironic.
2023-02-13 23:12:21.610897 2023-02-13 23:12:21.602 37 ERROR keystone.server.flask.application \x1b[00m
2023-02-13 23:12:22.414315 2023-02-13 23:12:22.410 37 ERROR keystone.server.flask.application [None req-1005b6cd-5c38-4dd8-bd4c-16dbe968c62d f030e67c936f4531b915f6b82c685e84 - - all default -] Could not find project: service.: keystone.exception.ProjectNotFound: Could not find project: service.
2023-02-13 23:12:22.414361 2023-02-13 23:12:22.410 37 ERROR keystone.server.flask.application Traceback (most recent call last):
2023-02-13 23:12:22.414373 2023-02-13 23:12:22.410 37 ERROR keystone.server.flask.application   File "/var/lib/kolla/venv/lib/python3.9/site-packages/flask/app.py", line 1820, in full_dispatch_request
2023-02-13 23:12:22.414384 2023-02-13 23:12:22.410 37 ERROR keystone.server.flask.application     rv = self.dispatch_request()
2023-02-13 23:12:22.414394 2023-02-13 23:12:22.410 37 ERROR keystone.server.flask.application   File "/var/lib/kolla/venv/lib/python3.9/site-packages/flask/app.py", line 1796, in dispatch_request
2023-02-13 23:12:22.414404 2023-02-13 23:12:22.410 37 ERROR keystone.server.flask.application     return self.ensure_sync(self.view_functions[rule.endpoint])(**view_args)
2023-02-13 23:12:22.414417 2023-02-13 23:12:22.410 37 ERROR keystone.server.flask.application   File "/var/lib/kolla/venv/lib/python3.9/site-packages/flask_restful/__init__.py", line 467, in wrapper
2023-02-13 23:12:22.414439 2023-02-13 23:12:22.410 37 ERROR keystone.server.flask.application     resp = resource(*args, **kwargs)
2023-02-13 23:12:22.414450 2023-02-13 23:12:22.410 37 ERROR keystone.server.flask.application   File "/var/lib/kolla/venv/lib/python3.9/site-packages/flask/views.py", line 107, in view
2023-02-13 23:12:22.414460 2023-02-13 23:12:22.410 37 ERROR keystone.server.flask.application     return current_app.ensure_sync(self.dispatch_request)(**kwargs)
2023-02-13 23:12:22.414470 2023-02-13 23:12:22.410 37 ERROR keystone.server.flask.application   File "/var/lib/kolla/venv/lib/python3.9/site-packages/flask_restful/__init__.py", line 582, in dispatch_request
2023-02-13 23:12:22.414480 2023-02-13 23:12:22.410 37 ERROR keystone.server.flask.application     resp = meth(*args, **kwargs)
2023-02-13 23:12:22.414490 2023-02-13 23:12:22.410 37 ERROR keystone.server.flask.application   File "/var/lib/kolla/venv/lib/python3.9/site-packages/keystone/api/projects.py", line 151, in get
2023-02-13 23:12:22.414500 2023-02-13 23:12:22.410 37 ERROR keystone.server.flask.application     return self._get_project(project_id)
2023-02-13 23:12:22.414509 2023-02-13 23:12:22.410 37 ERROR keystone.server.flask.application   File "/var/lib/kolla/venv/lib/python3.9/site-packages/keystone/api/projects.py", line 107, in _get_project
2023-02-13 23:12:22.414519 2023-02-13 23:12:22.410 37 ERROR keystone.server.flask.application     project = PROVIDERS.resource_api.get_project(project_id)
2023-02-13 23:12:22.414556 2023-02-13 23:12:22.410 37 ERROR keystone.server.flask.application   File "/var/lib/kolla/venv/lib/python3.9/site-packages/keystone/common/manager.py", line 115, in wrapped
2023-02-13 23:12:22.414569 2023-02-13 23:12:22.410 37 ERROR keystone.server.flask.application     __ret_val = __f(*args, **kwargs)
2023-02-13 23:12:22.414579 2023-02-13 23:12:22.410 37 ERROR keystone.server.flask.application   File "/var/lib/kolla/venv/lib/python3.9/site-packages/decorator.py", line 232, in fun
2023-02-13 23:12:22.414589 2023-02-13 23:12:22.410 37 ERROR keystone.server.flask.application     return caller(func, *(extras + args), **kw)
2023-02-13 23:12:22.414598 2023-02-13 23:12:22.410 37 ERROR keystone.server.flask.application   File "/var/lib/kolla/venv/lib/python3.9/site-packages/dogpile/cache/region.py", line 1577, in get_or_create_for_user_func
2023-02-13 23:12:22.414609 2023-02-13 23:12:22.410 37 ERROR keystone.server.flask.application     return self.get_or_create(
2023-02-13 23:12:22.414653 2023-02-13 23:12:22.410 37 ERROR keystone.server.flask.application   File "/var/lib/kolla/venv/lib/python3.9/site-packages/dogpile/cache/region.py", line 1042, in get_or_create
2023-02-13 23:12:22.414667 2023-02-13 23:12:22.410 37 ERROR keystone.server.flask.application     with Lock(
2023-02-13 23:12:22.414676 2023-02-13 23:12:22.410 37 ERROR keystone.server.flask.application   File "/var/lib/kolla/venv/lib/python3.9/site-packages/dogpile/lock.py", line 185, in __enter__
2023-02-13 23:12:22.414686 2023-02-13 23:12:22.410 37 ERROR keystone.server.flask.application     return self._enter()
2023-02-13 23:12:22.414696 2023-02-13 23:12:22.410 37 ERROR keystone.server.flask.application   File "/var/lib/kolla/venv/lib/python3.9/site-packages/dogpile/lock.py", line 94, in _enter
2023-02-13 23:12:22.414706 2023-02-13 23:12:22.410 37 ERROR keystone.server.flask.application     generated = self._enter_create(value, createdtime)
2023-02-13 23:12:22.414716 2023-02-13 23:12:22.410 37 ERROR keystone.server.flask.application   File "/var/lib/kolla/venv/lib/python3.9/site-packages/dogpile/lock.py", line 178, in _enter_create
2023-02-13 23:12:22.414726 2023-02-13 23:12:22.410 37 ERROR keystone.server.flask.application     return self.creator()
2023-02-13 23:12:22.414736 2023-02-13 23:12:22.410 37 ERROR keystone.server.flask.application   File "/var/lib/kolla/venv/lib/python3.9/site-packages/dogpile/cache/region.py", line 995, in gen_value
2023-02-13 23:12:22.414770 2023-02-13 23:12:22.410 37 ERROR keystone.server.flask.application     created_value = creator(
2023-02-13 23:12:22.414800 2023-02-13 23:12:22.410 37 ERROR keystone.server.flask.application   File "/var/lib/kolla/venv/lib/python3.9/site-packages/keystone/resource/core.py", line 903, in get_project
2023-02-13 23:12:22.414811 2023-02-13 23:12:22.410 37 ERROR keystone.server.flask.application     return self.driver.get_project(project_id)
2023-02-13 23:12:22.414821 2023-02-13 23:12:22.410 37 ERROR keystone.server.flask.application   File "/var/lib/kolla/venv/lib/python3.9/site-packages/keystone/resource/backends/sql.py", line 49, in get_project
2023-02-13 23:12:22.414831 2023-02-13 23:12:22.410 37 ERROR keystone.server.flask.application     return self._get_project(session, project_id).to_dict()
2023-02-13 23:12:22.414841 2023-02-13 23:12:22.410 37 ERROR keystone.server.flask.application   File "/var/lib/kolla/venv/lib/python3.9/site-packages/keystone/resource/backends/sql.py", line 44, in _get_project
2023-02-13 23:12:22.414851 2023-02-13 23:12:22.410 37 ERROR keystone.server.flask.application     raise exception.ProjectNotFound(project_id=project_id)
2023-02-13 23:12:22.414862 2023-02-13 23:12:22.410 37 ERROR keystone.server.flask.application keystone.exception.ProjectNotFound: Could not find project: service.
2023-02-13 23:12:22.414871 2023-02-13 23:12:22.410 37 ERROR keystone.server.flask.application \x1b[00m
2023-02-13 23:12:32.611301 2023-02-13 23:12:32.605 38 ERROR keystone.server.flask.application [None req-e4ec8461-fb0e-427d-b8cb-2a044291f31c f030e67c936f4531b915f6b82c685e84 - - all default -] Could not find role: admin.: keystone.exception.RoleNotFound: Could not find role: admin.
2023-02-13 23:12:32.611436 2023-02-13 23:12:32.605 38 ERROR keystone.server.flask.application Traceback (most recent call last):
2023-02-13 23:12:32.611451 2023-02-13 23:12:32.605 38 ERROR keystone.server.flask.application   File "/var/lib/kolla/venv/lib/python3.9/site-packages/flask/app.py", line 1820, in full_dispatch_request
2023-02-13 23:12:32.611462 2023-02-13 23:12:32.605 38 ERROR keystone.server.flask.application     rv = self.dispatch_request()
2023-02-13 23:12:32.611473 2023-02-13 23:12:32.605 38 ERROR keystone.server.flask.application   File "/var/lib/kolla/venv/lib/python3.9/site-packages/flask/app.py", line 1796, in dispatch_request
2023-02-13 23:12:32.611483 2023-02-13 23:12:32.605 38 ERROR keystone.server.flask.application     return self.ensure_sync(self.view_functions[rule.endpoint])(**view_args)
2023-02-13 23:12:32.611556 2023-02-13 23:12:32.605 38 ERROR keystone.server.flask.application   File "/var/lib/kolla/venv/lib/python3.9/site-packages/flask_restful/__init__.py", line 467, in wrapper
2023-02-13 23:12:32.611572 2023-02-13 23:12:32.605 38 ERROR keystone.server.flask.application     resp = resource(*args, **kwargs)
2023-02-13 23:12:32.611591 2023-02-13 23:12:32.605 38 ERROR keystone.server.flask.application   File "/var/lib/kolla/venv/lib/python3.9/site-packages/flask/views.py", line 107, in view
2023-02-13 23:12:32.611605 2023-02-13 23:12:32.605 38 ERROR keystone.server.flask.application     return current_app.ensure_sync(self.dispatch_request)(**kwargs)
2023-02-13 23:12:32.611615 2023-02-13 23:12:32.605 38 ERROR keystone.server.flask.application   File "/var/lib/kolla/venv/lib/python3.9/site-packages/flask_restful/__init__.py", line 582, in dispatch_request
2023-02-13 23:12:32.611625 2023-02-13 23:12:32.605 38 ERROR keystone.server.flask.application     resp = meth(*args, **kwargs)
2023-02-13 23:12:32.611635 2023-02-13 23:12:32.605 38 ERROR keystone.server.flask.application   File "/var/lib/kolla/venv/lib/python3.9/site-packages/keystone/api/roles.py", line 50, in get
2023-02-13 23:12:32.611645 2023-02-13 23:12:32.605 38 ERROR keystone.server.flask.application     return self._get_role(role_id)
2023-02-13 23:12:32.611655 2023-02-13 23:12:32.605 38 ERROR keystone.server.flask.application   File "/var/lib/kolla/venv/lib/python3.9/site-packages/keystone/api/roles.py", line 70, in _get_role
2023-02-13 23:12:32.611664 2023-02-13 23:12:32.605 38 ERROR keystone.server.flask.application     ENFORCER.enforce_call(action='identity:get_role')
2023-02-13 23:12:32.611682 2023-02-13 23:12:32.605 38 ERROR keystone.server.flask.application   File "/var/lib/kolla/venv/lib/python3.9/site-packages/keystone/common/rbac_enforcer/enforcer.py", line 402, in enforce_call
2023-02-13 23:12:32.611696 2023-02-13 23:12:32.605 38 ERROR keystone.server.flask.application     policy_dict.update(cls._extract_member_target_data(
2023-02-13 23:12:32.611713 2023-02-13 23:12:32.605 38 ERROR keystone.server.flask.application   File "/var/lib/kolla/venv/lib/python3.9/site-packages/keystone/common/rbac_enforcer/enforcer.py", line 234, in _extract_member_target_data
2023-02-13 23:12:32.611727 2023-02-13 23:12:32.605 38 ERROR keystone.server.flask.application     member_name: func(flask.request.view_args[key])
2023-02-13 23:12:32.611737 2023-02-13 23:12:32.605 38 ERROR keystone.server.flask.application   File "/var/lib/kolla/venv/lib/python3.9/site-packages/keystone/common/manager.py", line 115, in wrapped
2023-02-13 23:12:32.611771 2023-02-13 23:12:32.605 38 ERROR keystone.server.flask.application     __ret_val = __f(*args, **kwargs)
2023-02-13 23:12:32.611786 2023-02-13 23:12:32.605 38 ERROR keystone.server.flask.application   File "/var/lib/kolla/venv/lib/python3.9/site-packages/decorator.py", line 232, in fun
2023-02-13 23:12:32.611797 2023-02-13 23:12:32.605 38 ERROR keystone.server.flask.application     return caller(func, *(extras + args), **kw)
2023-02-13 23:12:32.611807 2023-02-13 23:12:32.605 38 ERROR keystone.server.flask.application   File "/var/lib/kolla/venv/lib/python3.9/site-packages/dogpile/cache/region.py", line 1577, in get_or_create_for_user_func
2023-02-13 23:12:32.611817 2023-02-13 23:12:32.605 38 ERROR keystone.server.flask.application     return self.get_or_create(
2023-02-13 23:12:32.611827 2023-02-13 23:12:32.605 38 ERROR keystone.server.flask.application   File "/var/lib/kolla/venv/lib/python3.9/site-packages/dogpile/cache/region.py", line 1042, in get_or_create
2023-02-13 23:12:32.611837 2023-02-13 23:12:32.605 38 ERROR keystone.server.flask.application     with Lock(
2023-02-13 23:12:32.611847 2023-02-13 23:12:32.605 38 ERROR keystone.server.flask.application   File "/var/lib/kolla/venv/lib/python3.9/site-packages/dogpile/lock.py", line 185, in __enter__
2023-02-13 23:12:32.611858 2023-02-13 23:12:32.605 38 ERROR keystone.server.flask.application     return self._enter()
2023-02-13 23:12:32.611868 2023-02-13 23:12:32.605 38 ERROR keystone.server.flask.application   File "/var/lib/kolla/venv/lib/python3.9/site-packages/dogpile/lock.py", line 94, in _enter
2023-02-13 23:12:32.611917 2023-02-13 23:12:32.605 38 ERROR keystone.server.flask.application     generated = self._enter_create(value, createdtime)
2023-02-13 23:12:32.611931 2023-02-13 23:12:32.605 38 ERROR keystone.server.flask.application   File "/var/lib/kolla/venv/lib/python3.9/site-packages/dogpile/lock.py", line 178, in _enter_create
2023-02-13 23:12:32.611941 2023-02-13 23:12:32.605 38 ERROR keystone.server.flask.application     return self.creator()
2023-02-13 23:12:32.611951 2023-02-13 23:12:32.605 38 ERROR keystone.server.flask.application   File "/var/lib/kolla/venv/lib/python3.9/site-packages/dogpile/cache/region.py", line 995, in gen_value
2023-02-13 23:12:32.611961 2023-02-13 23:12:32.605 38 ERROR keystone.server.flask.application     created_value = creator(
2023-02-13 23:12:32.611971 2023-02-13 23:12:32.605 38 ERROR keystone.server.flask.application   File "/var/lib/kolla/venv/lib/python3.9/site-packages/keystone/assignment/core.py", line 1276, in get_role
2023-02-13 23:12:32.611981 2023-02-13 23:12:32.605 38 ERROR keystone.server.flask.application     return self.driver.get_role(role_id)
2023-02-13 23:12:32.611991 2023-02-13 23:12:32.605 38 ERROR keystone.server.flask.application   File "/var/lib/kolla/venv/lib/python3.9/site-packages/keystone/assignment/role_backends/sql.py", line 70, in get_role
2023-02-13 23:12:32.612002 2023-02-13 23:12:32.605 38 ERROR keystone.server.flask.application     return self._get_role(session, role_id).to_dict()
2023-02-13 23:12:32.612012 2023-02-13 23:12:32.605 38 ERROR keystone.server.flask.application   File "/var/lib/kolla/venv/lib/python3.9/site-packages/keystone/assignment/role_backends/sql.py", line 65, in _get_role
2023-02-13 23:12:32.612023 2023-02-13 23:12:32.605 38 ERROR keystone.server.flask.application     raise exception.RoleNotFound(role_id=role_id)
2023-02-13 23:12:32.612032 2023-02-13 23:12:32.605 38 ERROR keystone.server.flask.application keystone.exception.RoleNotFound: Could not find role: admin.
2023-02-13 23:12:32.612042 2023-02-13 23:12:32.605 38 ERROR keystone.server.flask.application \x1b[00m
2023-02-13 23:12:33.812096 2023-02-13 23:12:33.807 37 ERROR keystone.server.flask.application [None req-0816cf49-e37d-497a-aa27-1da24e379cfb f030e67c936f4531b915f6b82c685e84 - - all default -] Could not find user: ironic-inspector.: keystone.exception.UserNotFound: Could not find user: ironic-inspector.
2023-02-13 23:12:33.812158 2023-02-13 23:12:33.807 37 ERROR keystone.server.flask.application Traceback (most recent call last):
2023-02-13 23:12:33.812171 2023-02-13 23:12:33.807 37 ERROR keystone.server.flask.application   File "/var/lib/kolla/venv/lib/python3.9/site-packages/flask/app.py", line 1820, in full_dispatch_request
2023-02-13 23:12:33.812442 2023-02-13 23:12:33.807 37 ERROR keystone.server.flask.application     rv = self.dispatch_request()
2023-02-13 23:12:33.812464 2023-02-13 23:12:33.807 37 ERROR keystone.server.flask.application   File "/var/lib/kolla/venv/lib/python3.9/site-packages/flask/app.py", line 1796, in dispatch_request
2023-02-13 23:12:33.812476 2023-02-13 23:12:33.807 37 ERROR keystone.server.flask.application     return self.ensure_sync(self.view_functions[rule.endpoint])(**view_args)
2023-02-13 23:12:33.812488 2023-02-13 23:12:33.807 37 ERROR keystone.server.flask.application   File "/var/lib/kolla/venv/lib/python3.9/site-packages/flask_restful/__init__.py", line 467, in wrapper
2023-02-13 23:12:33.812499 2023-02-13 23:12:33.807 37 ERROR keystone.server.flask.application     resp = resource(*args, **kwargs)
2023-02-13 23:12:33.812525 2023-02-13 23:12:33.807 37 ERROR keystone.server.flask.application   File "/var/lib/kolla/venv/lib/python3.9/site-packages/flask/views.py", line 107, in view
2023-02-13 23:12:33.812574 2023-02-13 23:12:33.807 37 ERROR keystone.server.flask.application     return current_app.ensure_sync(self.dispatch_request)(**kwargs)
2023-02-13 23:12:33.812587 2023-02-13 23:12:33.807 37 ERROR keystone.server.flask.application   File "/var/lib/kolla/venv/lib/python3.9/site-packages/flask_restful/__init__.py", line 582, in dispatch_request
2023-02-13 23:12:33.812627 2023-02-13 23:12:33.807 37 ERROR keystone.server.flask.application     resp = meth(*args, **kwargs)
2023-02-13 23:12:33.812641 2023-02-13 23:12:33.807 37 ERROR keystone.server.flask.application   File "/var/lib/kolla/venv/lib/python3.9/site-packages/keystone/api/users.py", line 182, in get
2023-02-13 23:12:33.812653 2023-02-13 23:12:33.807 37 ERROR keystone.server.flask.application     return self._get_user(user_id)
2023-02-13 23:12:33.812664 2023-02-13 23:12:33.807 37 ERROR keystone.server.flask.application   File "/var/lib/kolla/venv/lib/python3.9/site-packages/keystone/api/users.py", line 194, in _get_user
2023-02-13 23:12:33.812676 2023-02-13 23:12:33.807 37 ERROR keystone.server.flask.application     ref = PROVIDERS.identity_api.get_user(user_id)
2023-02-13 23:12:33.812687 2023-02-13 23:12:33.807 37 ERROR keystone.server.flask.application   File "/var/lib/kolla/venv/lib/python3.9/site-packages/keystone/common/manager.py", line 115, in wrapped
2023-02-13 23:12:33.812699 2023-02-13 23:12:33.807 37 ERROR keystone.server.flask.application     __ret_val = __f(*args, **kwargs)
2023-02-13 23:12:33.812710 2023-02-13 23:12:33.807 37 ERROR keystone.server.flask.application   File "/var/lib/kolla/venv/lib/python3.9/site-packages/keystone/identity/core.py", line 414, in wrapper
2023-02-13 23:12:33.812722 2023-02-13 23:12:33.807 37 ERROR keystone.server.flask.application     return f(self, *args, **kwargs)
2023-02-13 23:12:33.812734 2023-02-13 23:12:33.807 37 ERROR keystone.server.flask.application   File "/var/lib/kolla/venv/lib/python3.9/site-packages/keystone/identity/core.py", line 424, in wrapper
2023-02-13 23:12:33.812769 2023-02-13 23:12:33.807 37 ERROR keystone.server.flask.application     return f(self, *args, **kwargs)
2023-02-13 23:12:33.812787 2023-02-13 23:12:33.807 37 ERROR keystone.server.flask.application   File "/var/lib/kolla/venv/lib/python3.9/site-packages/decorator.py", line 232, in fun
2023-02-13 23:12:33.812799 2023-02-13 23:12:33.807 37 ERROR keystone.server.flask.application     return caller(func, *(extras + args), **kw)
2023-02-13 23:12:33.812980 2023-02-13 23:12:33.807 37 ERROR keystone.server.flask.application   File "/var/lib/kolla/venv/lib/python3.9/site-packages/dogpile/cache/region.py", line 1577, in get_or_create_for_user_func
2023-02-13 23:12:33.813002 2023-02-13 23:12:33.807 37 ERROR keystone.server.flask.application     return self.get_or_create(
2023-02-13 23:12:33.813013 2023-02-13 23:12:33.807 37 ERROR keystone.server.flask.application   File "/var/lib/kolla/venv/lib/python3.9/site-packages/dogpile/cache/region.py", line 1042, in get_or_create
2023-02-13 23:12:33.813025 2023-02-13 23:12:33.807 37 ERROR keystone.server.flask.application     with Lock(
2023-02-13 23:12:33.813036 2023-02-13 23:12:33.807 37 ERROR keystone.server.flask.application   File "/var/lib/kolla/venv/lib/python3.9/site-packages/dogpile/lock.py", line 185, in __enter__
2023-02-13 23:12:33.813048 2023-02-13 23:12:33.807 37 ERROR keystone.server.flask.application     return self._enter()
2023-02-13 23:12:33.813059 2023-02-13 23:12:33.807 37 ERROR keystone.server.flask.application   File "/var/lib/kolla/venv/lib/python3.9/site-packages/dogpile/lock.py", line 94, in _enter
2023-02-13 23:12:33.813070 2023-02-13 23:12:33.807 37 ERROR keystone.server.flask.application     generated = self._enter_create(value, createdtime)
2023-02-13 23:12:33.813081 2023-02-13 23:12:33.807 37 ERROR keystone.server.flask.application   File "/var/lib/kolla/venv/lib/python3.9/site-packages/dogpile/lock.py", line 178, in _enter_create
2023-02-13 23:12:33.813093 2023-02-13 23:12:33.807 37 ERROR keystone.server.flask.application     return self.creator()
2023-02-13 23:12:33.813105 2023-02-13 23:12:33.807 37 ERROR keystone.server.flask.application   File "/var/lib/kolla/venv/lib/python3.9/site-packages/dogpile/cache/region.py", line 995, in gen_value
2023-02-13 23:12:33.813177 2023-02-13 23:12:33.807 37 ERROR keystone.server.flask.application     created_value = creator(
2023-02-13 23:12:33.813399 2023-02-13 23:12:33.807 37 ERROR keystone.server.flask.application   File "/var/lib/kolla/venv/lib/python3.9/site-packages/keystone/identity/core.py", line 1011, in get_user
2023-02-13 23:12:33.813420 2023-02-13 23:12:33.807 37 ERROR keystone.server.flask.application     ref = driver.get_user(entity_id)
2023-02-13 23:12:33.813432 2023-02-13 23:12:33.807 37 ERROR keystone.server.flask.application   File "/var/lib/kolla/venv/lib/python3.9/site-packages/keystone/identity/backends/sql.py", line 200, in get_user
2023-02-13 23:12:33.813444 2023-02-13 23:12:33.807 37 ERROR keystone.server.flask.application     self._get_user(session, user_id).to_dict())
2023-02-13 23:12:33.813455 2023-02-13 23:12:33.807 37 ERROR keystone.server.flask.application   File "/var/lib/kolla/venv/lib/python3.9/site-packages/keystone/identity/backends/sql.py", line 194, in _get_user
2023-02-13 23:12:33.813467 2023-02-13 23:12:33.807 37 ERROR keystone.server.flask.application     raise exception.UserNotFound(user_id=user_id)
2023-02-13 23:12:33.813478 2023-02-13 23:12:33.807 37 ERROR keystone.server.flask.application keystone.exception.UserNotFound: Could not find user: ironic-inspector.
2023-02-13 23:12:33.813490 2023-02-13 23:12:33.807 37 ERROR keystone.server.flask.application \x1b[00m
2023-02-13 23:12:34.759134 2023-02-13 23:12:34.755 37 ERROR keystone.server.flask.application [None req-652c6673-6575-4f2a-8f9a-541a25300cba f030e67c936f4531b915f6b82c685e84 - - all default -] Could not find project: service.: keystone.exception.ProjectNotFound: Could not find project: service.
2023-02-13 23:12:34.759179 2023-02-13 23:12:34.755 37 ERROR keystone.server.flask.application Traceback (most recent call last):
2023-02-13 23:12:34.759191 2023-02-13 23:12:34.755 37 ERROR keystone.server.flask.application   File "/var/lib/kolla/venv/lib/python3.9/site-packages/flask/app.py", line 1820, in full_dispatch_request
2023-02-13 23:12:34.759202 2023-02-13 23:12:34.755 37 ERROR keystone.server.flask.application     rv = self.dispatch_request()
2023-02-13 23:12:34.759212 2023-02-13 23:12:34.755 37 ERROR keystone.server.flask.application   File "/var/lib/kolla/venv/lib/python3.9/site-packages/flask/app.py", line 1796, in dispatch_request
2023-02-13 23:12:34.759222 2023-02-13 23:12:34.755 37 ERROR keystone.server.flask.application     return self.ensure_sync(self.view_functions[rule.endpoint])(**view_args)
2023-02-13 23:12:34.759232 2023-02-13 23:12:34.755 37 ERROR keystone.server.flask.application   File "/var/lib/kolla/venv/lib/python3.9/site-packages/flask_restful/__init__.py", line 467, in wrapper
2023-02-13 23:12:34.759242 2023-02-13 23:12:34.755 37 ERROR keystone.server.flask.application     resp = resource(*args, **kwargs)
2023-02-13 23:12:34.759251 2023-02-13 23:12:34.755 37 ERROR keystone.server.flask.application   File "/var/lib/kolla/venv/lib/python3.9/site-packages/flask/views.py", line 107, in view
2023-02-13 23:12:34.759262 2023-02-13 23:12:34.755 37 ERROR keystone.server.flask.application     return current_app.ensure_sync(self.dispatch_request)(**kwargs)
2023-02-13 23:12:34.759271 2023-02-13 23:12:34.755 37 ERROR keystone.server.flask.application   File "/var/lib/kolla/venv/lib/python3.9/site-packages/flask_restful/__init__.py", line 582, in dispatch_request
2023-02-13 23:12:34.759281 2023-02-13 23:12:34.755 37 ERROR keystone.server.flask.application     resp = meth(*args, **kwargs)
2023-02-13 23:12:34.759291 2023-02-13 23:12:34.755 37 ERROR keystone.server.flask.application   File "/var/lib/kolla/venv/lib/python3.9/site-packages/keystone/api/projects.py", line 151, in get
2023-02-13 23:12:34.759301 2023-02-13 23:12:34.755 37 ERROR keystone.server.flask.application     return self._get_project(project_id)
2023-02-13 23:12:34.759311 2023-02-13 23:12:34.755 37 ERROR keystone.server.flask.application   File "/var/lib/kolla/venv/lib/python3.9/site-packages/keystone/api/projects.py", line 107, in _get_project
2023-02-13 23:12:34.759321 2023-02-13 23:12:34.755 37 ERROR keystone.server.flask.application     project = PROVIDERS.resource_api.get_project(project_id)
2023-02-13 23:12:34.759348 2023-02-13 23:12:34.755 37 ERROR keystone.server.flask.application   File "/var/lib/kolla/venv/lib/python3.9/site-packages/keystone/common/manager.py", line 115, in wrapped
2023-02-13 23:12:34.759360 2023-02-13 23:12:34.755 37 ERROR keystone.server.flask.application     __ret_val = __f(*args, **kwargs)
2023-02-13 23:12:34.759370 2023-02-13 23:12:34.755 37 ERROR keystone.server.flask.application   File "/var/lib/kolla/venv/lib/python3.9/site-packages/decorator.py", line 232, in fun
2023-02-13 23:12:34.759380 2023-02-13 23:12:34.755 37 ERROR keystone.server.flask.application     return caller(func, *(extras + args), **kw)
2023-02-13 23:12:34.759403 2023-02-13 23:12:34.755 37 ERROR keystone.server.flask.application   File "/var/lib/kolla/venv/lib/python3.9/site-packages/dogpile/cache/region.py", line 1577, in get_or_create_for_user_func
2023-02-13 23:12:34.759427 2023-02-13 23:12:34.755 37 ERROR keystone.server.flask.application     return self.get_or_create(
2023-02-13 23:12:34.759437 2023-02-13 23:12:34.755 37 ERROR keystone.server.flask.application   File "/var/lib/kolla/venv/lib/python3.9/site-packages/dogpile/cache/region.py", line 1042, in get_or_create
2023-02-13 23:12:34.759448 2023-02-13 23:12:34.755 37 ERROR keystone.server.flask.application     with Lock(
2023-02-13 23:12:34.759458 2023-02-13 23:12:34.755 37 ERROR keystone.server.flask.application   File "/var/lib/kolla/venv/lib/python3.9/site-packages/dogpile/lock.py", line 185, in __enter__
2023-02-13 23:12:34.759468 2023-02-13 23:12:34.755 37 ERROR keystone.server.flask.application     return self._enter()
2023-02-13 23:12:34.759478 2023-02-13 23:12:34.755 37 ERROR keystone.server.flask.application   File "/var/lib/kolla/venv/lib/python3.9/site-packages/dogpile/lock.py", line 94, in _enter
2023-02-13 23:12:34.759488 2023-02-13 23:12:34.755 37 ERROR keystone.server.flask.application     generated = self._enter_create(value, createdtime)
2023-02-13 23:12:34.759498 2023-02-13 23:12:34.755 37 ERROR keystone.server.flask.application   File "/var/lib/kolla/venv/lib/python3.9/site-packages/dogpile/lock.py", line 178, in _enter_create
2023-02-13 23:12:34.759508 2023-02-13 23:12:34.755 37 ERROR keystone.server.flask.application     return self.creator()
2023-02-13 23:12:34.759518 2023-02-13 23:12:34.755 37 ERROR keystone.server.flask.application   File "/var/lib/kolla/venv/lib/python3.9/site-packages/dogpile/cache/region.py", line 995, in gen_value
2023-02-13 23:12:34.759527 2023-02-13 23:12:34.755 37 ERROR keystone.server.flask.application     created_value = creator(
2023-02-13 23:12:34.759555 2023-02-13 23:12:34.755 37 ERROR keystone.server.flask.application   File "/var/lib/kolla/venv/lib/python3.9/site-packages/keystone/resource/core.py", line 903, in get_project
2023-02-13 23:12:34.759569 2023-02-13 23:12:34.755 37 ERROR keystone.server.flask.application     return self.driver.get_project(project_id)
2023-02-13 23:12:34.759579 2023-02-13 23:12:34.755 37 ERROR keystone.server.flask.application   File "/var/lib/kolla/venv/lib/python3.9/site-packages/keystone/resource/backends/sql.py", line 49, in get_project
2023-02-13 23:12:34.759589 2023-02-13 23:12:34.755 37 ERROR keystone.server.flask.application     return self._get_project(session, project_id).to_dict()
2023-02-13 23:12:34.759598 2023-02-13 23:12:34.755 37 ERROR keystone.server.flask.application   File "/var/lib/kolla/venv/lib/python3.9/site-packages/keystone/resource/backends/sql.py", line 44, in _get_project
2023-02-13 23:12:34.759608 2023-02-13 23:12:34.755 37 ERROR keystone.server.flask.application     raise exception.ProjectNotFound(project_id=project_id)
2023-02-13 23:12:34.759618 2023-02-13 23:12:34.755 37 ERROR keystone.server.flask.application keystone.exception.ProjectNotFound: Could not find project: service.
2023-02-13 23:12:34.759628 2023-02-13 23:12:34.755 37 ERROR keystone.server.flask.application \x1b[00m
2023-02-13 23:15:51.581303 2023-02-13 23:15:51.578 37 WARNING py.warnings [None req-69f9c80e-41f1-4dc7-ab9e-c08a6ab74e62 f030e67c936f4531b915f6b82c685e84 de5ffdbf40fb4a31bba96ecd465d556c - - default default] /var/lib/kolla/venv/lib/python3.9/site-packages/oslo_policy/policy.py:1129: UserWarning: Policy "identity:create_user": "(role:admin and system_scope:all) or (role:admin and token.domain.id:%(target.user.domain_id)s)" failed scope check. The token used to make the request was project scoped but the policy requires ['system', 'domain'] scope. This behavior may change in the future where using the intended scope is required
2023-02-13 23:15:51.581455   warnings.warn(msg)
2023-02-13 23:15:51.581477 \x1b[00m
2023-02-13 23:15:56.457893 2023-02-13 23:15:56.453 38 ERROR keystone.server.flask.application [None req-44b429d8-8b82-4af0-96d7-4d5493bd7636 f030e67c936f4531b915f6b82c685e84 de5ffdbf40fb4a31bba96ecd465d556c - - default default] Could not find role: admin.: keystone.exception.RoleNotFound: Could not find role: admin.
2023-02-13 23:15:56.457949 2023-02-13 23:15:56.453 38 ERROR keystone.server.flask.application Traceback (most recent call last):
2023-02-13 23:15:56.457961 2023-02-13 23:15:56.453 38 ERROR keystone.server.flask.application   File "/var/lib/kolla/venv/lib/python3.9/site-packages/flask/app.py", line 1820, in full_dispatch_request
2023-02-13 23:15:56.457972 2023-02-13 23:15:56.453 38 ERROR keystone.server.flask.application     rv = self.dispatch_request()
2023-02-13 23:15:56.457982 2023-02-13 23:15:56.453 38 ERROR keystone.server.flask.application   File "/var/lib/kolla/venv/lib/python3.9/site-packages/flask/app.py", line 1796, in dispatch_request
2023-02-13 23:15:56.457993 2023-02-13 23:15:56.453 38 ERROR keystone.server.flask.application     return self.ensure_sync(self.view_functions[rule.endpoint])(**view_args)
2023-02-13 23:15:56.458003 2023-02-13 23:15:56.453 38 ERROR keystone.server.flask.application   File "/var/lib/kolla/venv/lib/python3.9/site-packages/flask_restful/__init__.py", line 467, in wrapper
2023-02-13 23:15:56.458014 2023-02-13 23:15:56.453 38 ERROR keystone.server.flask.application     resp = resource(*args, **kwargs)
2023-02-13 23:15:56.458033 2023-02-13 23:15:56.453 38 ERROR keystone.server.flask.application   File "/var/lib/kolla/venv/lib/python3.9/site-packages/flask/views.py", line 107, in view
2023-02-13 23:15:56.458047 2023-02-13 23:15:56.453 38 ERROR keystone.server.flask.application     return current_app.ensure_sync(self.dispatch_request)(**kwargs)
2023-02-13 23:15:56.458058 2023-02-13 23:15:56.453 38 ERROR keystone.server.flask.application   File "/var/lib/kolla/venv/lib/python3.9/site-packages/flask_restful/__init__.py", line 582, in dispatch_request
2023-02-13 23:15:56.458068 2023-02-13 23:15:56.453 38 ERROR keystone.server.flask.application     resp = meth(*args, **kwargs)
2023-02-13 23:15:56.458077 2023-02-13 23:15:56.453 38 ERROR keystone.server.flask.application   File "/var/lib/kolla/venv/lib/python3.9/site-packages/keystone/api/roles.py", line 50, in get
2023-02-13 23:15:56.458087 2023-02-13 23:15:56.453 38 ERROR keystone.server.flask.application     return self._get_role(role_id)
2023-02-13 23:15:56.458097 2023-02-13 23:15:56.453 38 ERROR keystone.server.flask.application   File "/var/lib/kolla/venv/lib/python3.9/site-packages/keystone/api/roles.py", line 70, in _get_role
2023-02-13 23:15:56.458107 2023-02-13 23:15:56.453 38 ERROR keystone.server.flask.application     ENFORCER.enforce_call(action='identity:get_role')
2023-02-13 23:15:56.458124 2023-02-13 23:15:56.453 38 ERROR keystone.server.flask.application   File "/var/lib/kolla/venv/lib/python3.9/site-packages/keystone/common/rbac_enforcer/enforcer.py", line 402, in enforce_call
2023-02-13 23:15:56.458137 2023-02-13 23:15:56.453 38 ERROR keystone.server.flask.application     policy_dict.update(cls._extract_member_target_data(
2023-02-13 23:15:56.458154 2023-02-13 23:15:56.453 38 ERROR keystone.server.flask.application   File "/var/lib/kolla/venv/lib/python3.9/site-packages/keystone/common/rbac_enforcer/enforcer.py", line 234, in _extract_member_target_data
2023-02-13 23:15:56.458193 2023-02-13 23:15:56.453 38 ERROR keystone.server.flask.application     member_name: func(flask.request.view_args[key])
2023-02-13 23:15:56.458206 2023-02-13 23:15:56.453 38 ERROR keystone.server.flask.application   File "/var/lib/kolla/venv/lib/python3.9/site-packages/keystone/common/manager.py", line 115, in wrapped
2023-02-13 23:15:56.458216 2023-02-13 23:15:56.453 38 ERROR keystone.server.flask.application     __ret_val = __f(*args, **kwargs)
2023-02-13 23:15:56.458226 2023-02-13 23:15:56.453 38 ERROR keystone.server.flask.application   File "/var/lib/kolla/venv/lib/python3.9/site-packages/decorator.py", line 232, in fun
2023-02-13 23:15:56.458237 2023-02-13 23:15:56.453 38 ERROR keystone.server.flask.application     return caller(func, *(extras + args), **kw)
2023-02-13 23:15:56.458246 2023-02-13 23:15:56.453 38 ERROR keystone.server.flask.application   File "/var/lib/kolla/venv/lib/python3.9/site-packages/dogpile/cache/region.py", line 1577, in get_or_create_for_user_func
2023-02-13 23:15:56.458257 2023-02-13 23:15:56.453 38 ERROR keystone.server.flask.application     return self.get_or_create(
2023-02-13 23:15:56.458266 2023-02-13 23:15:56.453 38 ERROR keystone.server.flask.application   File "/var/lib/kolla/venv/lib/python3.9/site-packages/dogpile/cache/region.py", line 1042, in get_or_create
2023-02-13 23:15:56.458277 2023-02-13 23:15:56.453 38 ERROR keystone.server.flask.application     with Lock(
2023-02-13 23:15:56.458287 2023-02-13 23:15:56.453 38 ERROR keystone.server.flask.application   File "/var/lib/kolla/venv/lib/python3.9/site-packages/dogpile/lock.py", line 185, in __enter__
2023-02-13 23:15:56.458297 2023-02-13 23:15:56.453 38 ERROR keystone.server.flask.application     return self._enter()
2023-02-13 23:15:56.458306 2023-02-13 23:15:56.453 38 ERROR keystone.server.flask.application   File "/var/lib/kolla/venv/lib/python3.9/site-packages/dogpile/lock.py", line 94, in _enter
2023-02-13 23:15:56.458316 2023-02-13 23:15:56.453 38 ERROR keystone.server.flask.application     generated = self._enter_create(value, createdtime)
2023-02-13 23:15:56.458326 2023-02-13 23:15:56.453 38 ERROR keystone.server.flask.application   File "/var/lib/kolla/venv/lib/python3.9/site-packages/dogpile/lock.py", line 178, in _enter_create
2023-02-13 23:15:56.458336 2023-02-13 23:15:56.453 38 ERROR keystone.server.flask.application     return self.creator()
2023-02-13 23:15:56.458346 2023-02-13 23:15:56.453 38 ERROR keystone.server.flask.application   File "/var/lib/kolla/venv/lib/python3.9/site-packages/dogpile/cache/region.py", line 995, in gen_value
2023-02-13 23:15:56.458356 2023-02-13 23:15:56.453 38 ERROR keystone.server.flask.application     created_value = creator(
2023-02-13 23:15:56.458366 2023-02-13 23:15:56.453 38 ERROR keystone.server.flask.application   File "/var/lib/kolla/venv/lib/python3.9/site-packages/keystone/assignment/core.py", line 1276, in get_role
2023-02-13 23:15:56.458376 2023-02-13 23:15:56.453 38 ERROR keystone.server.flask.application     return self.driver.get_role(role_id)
2023-02-13 23:15:56.458386 2023-02-13 23:15:56.453 38 ERROR keystone.server.flask.application   File "/var/lib/kolla/venv/lib/python3.9/site-packages/keystone/assignment/role_backends/sql.py", line 70, in get_role
2023-02-13 23:15:56.458396 2023-02-13 23:15:56.453 38 ERROR keystone.server.flask.application     return self._get_role(session, role_id).to_dict()
2023-02-13 23:15:56.458406 2023-02-13 23:15:56.453 38 ERROR keystone.server.flask.application   File "/var/lib/kolla/venv/lib/python3.9/site-packages/keystone/assignment/role_backends/sql.py", line 65, in _get_role
2023-02-13 23:15:56.458416 2023-02-13 23:15:56.453 38 ERROR keystone.server.flask.application     raise exception.RoleNotFound(role_id=role_id)
2023-02-13 23:15:56.458425 2023-02-13 23:15:56.453 38 ERROR keystone.server.flask.application keystone.exception.RoleNotFound: Could not find role: admin.
2023-02-13 23:15:56.458435 2023-02-13 23:15:56.453 38 ERROR keystone.server.flask.application \x1b[00m
2023-02-13 23:15:56.615609 2023-02-13 23:15:56.614 37 WARNING py.warnings [None req-2678b5cf-c40b-4c62-b161-0277ae90aae9 f030e67c936f4531b915f6b82c685e84 de5ffdbf40fb4a31bba96ecd465d556c - - default default] /var/lib/kolla/venv/lib/python3.9/site-packages/oslo_policy/policy.py:1129: UserWarning: Policy "identity:list_roles": "role:reader and system_scope:all" failed scope check. The token used to make the request was project scoped but the policy requires ['system'] scope. This behavior may change in the future where using the intended scope is required
2023-02-13 23:15:56.615709   warnings.warn(msg)
2023-02-13 23:15:56.615723 \x1b[00m
2023-02-13 23:15:56.882211 2023-02-13 23:15:56.873 38 ERROR keystone.server.flask.application [None req-dbd12a47-9198-4893-866c-3c99c5129f52 f030e67c936f4531b915f6b82c685e84 de5ffdbf40fb4a31bba96ecd465d556c - - default default] Could not find user: neutron.: keystone.exception.UserNotFound: Could not find user: neutron.
2023-02-13 23:15:56.882267 2023-02-13 23:15:56.873 38 ERROR keystone.server.flask.application Traceback (most recent call last):
2023-02-13 23:15:56.882290 2023-02-13 23:15:56.873 38 ERROR keystone.server.flask.application   File "/var/lib/kolla/venv/lib/python3.9/site-packages/flask/app.py", line 1820, in full_dispatch_request
2023-02-13 23:15:56.882305 2023-02-13 23:15:56.873 38 ERROR keystone.server.flask.application     rv = self.dispatch_request()
2023-02-13 23:15:56.882321 2023-02-13 23:15:56.873 38 ERROR keystone.server.flask.application   File "/var/lib/kolla/venv/lib/python3.9/site-packages/flask/app.py", line 1796, in dispatch_request
2023-02-13 23:15:56.882338 2023-02-13 23:15:56.873 38 ERROR keystone.server.flask.application     return self.ensure_sync(self.view_functions[rule.endpoint])(**view_args)
2023-02-13 23:15:56.882350 2023-02-13 23:15:56.873 38 ERROR keystone.server.flask.application   File "/var/lib/kolla/venv/lib/python3.9/site-packages/flask_restful/__init__.py", line 467, in wrapper
2023-02-13 23:15:56.882360 2023-02-13 23:15:56.873 38 ERROR keystone.server.flask.application     resp = resource(*args, **kwargs)
2023-02-13 23:15:56.882371 2023-02-13 23:15:56.873 38 ERROR keystone.server.flask.application   File "/var/lib/kolla/venv/lib/python3.9/site-packages/flask/views.py", line 107, in view
2023-02-13 23:15:56.882381 2023-02-13 23:15:56.873 38 ERROR keystone.server.flask.application     return current_app.ensure_sync(self.dispatch_request)(**kwargs)
2023-02-13 23:15:56.882391 2023-02-13 23:15:56.873 38 ERROR keystone.server.flask.application   File "/var/lib/kolla/venv/lib/python3.9/site-packages/flask_restful/__init__.py", line 582, in dispatch_request
2023-02-13 23:15:56.882405 2023-02-13 23:15:56.873 38 ERROR keystone.server.flask.application     resp = meth(*args, **kwargs)
2023-02-13 23:15:56.882425 2023-02-13 23:15:56.873 38 ERROR keystone.server.flask.application   File "/var/lib/kolla/venv/lib/python3.9/site-packages/keystone/api/users.py", line 182, in get
2023-02-13 23:15:56.882440 2023-02-13 23:15:56.873 38 ERROR keystone.server.flask.application     return self._get_user(user_id)
2023-02-13 23:15:56.882454 2023-02-13 23:15:56.873 38 ERROR keystone.server.flask.application   File "/var/lib/kolla/venv/lib/python3.9/site-packages/keystone/api/users.py", line 194, in _get_user
2023-02-13 23:15:56.882468 2023-02-13 23:15:56.873 38 ERROR keystone.server.flask.application     ref = PROVIDERS.identity_api.get_user(user_id)
2023-02-13 23:15:56.882482 2023-02-13 23:15:56.873 38 ERROR keystone.server.flask.application   File "/var/lib/kolla/venv/lib/python3.9/site-packages/keystone/common/manager.py", line 115, in wrapped
2023-02-13 23:15:56.882496 2023-02-13 23:15:56.873 38 ERROR keystone.server.flask.application     __ret_val = __f(*args, **kwargs)
2023-02-13 23:15:56.882542 2023-02-13 23:15:56.873 38 ERROR keystone.server.flask.application   File "/var/lib/kolla/venv/lib/python3.9/site-packages/keystone/identity/core.py", line 414, in wrapper
2023-02-13 23:15:56.882557 2023-02-13 23:15:56.873 38 ERROR keystone.server.flask.application     return f(self, *args, **kwargs)
2023-02-13 23:15:56.882585 2023-02-13 23:15:56.873 38 ERROR keystone.server.flask.application   File "/var/lib/kolla/venv/lib/python3.9/site-packages/keystone/identity/core.py", line 424, in wrapper
2023-02-13 23:15:56.882599 2023-02-13 23:15:56.873 38 ERROR keystone.server.flask.application     return f(self, *args, **kwargs)
2023-02-13 23:15:56.882619 2023-02-13 23:15:56.873 38 ERROR keystone.server.flask.application   File "/var/lib/kolla/venv/lib/python3.9/site-packages/decorator.py", line 232, in fun
2023-02-13 23:15:56.882640 2023-02-13 23:15:56.873 38 ERROR keystone.server.flask.application     return caller(func, *(extras + args), **kw)
2023-02-13 23:15:56.882661 2023-02-13 23:15:56.873 38 ERROR keystone.server.flask.application   File "/var/lib/kolla/venv/lib/python3.9/site-packages/dogpile/cache/region.py", line 1577, in get_or_create_for_user_func
2023-02-13 23:15:56.882680 2023-02-13 23:15:56.873 38 ERROR keystone.server.flask.application     return self.get_or_create(
2023-02-13 23:15:56.882694 2023-02-13 23:15:56.873 38 ERROR keystone.server.flask.application   File "/var/lib/kolla/venv/lib/python3.9/site-packages/dogpile/cache/region.py", line 1042, in get_or_create
2023-02-13 23:15:56.882710 2023-02-13 23:15:56.873 38 ERROR keystone.server.flask.application     with Lock(
2023-02-13 23:15:56.882729 2023-02-13 23:15:56.873 38 ERROR keystone.server.flask.application   File "/var/lib/kolla/venv/lib/python3.9/site-packages/dogpile/lock.py", line 185, in __enter__
2023-02-13 23:15:56.882782 2023-02-13 23:15:56.873 38 ERROR keystone.server.flask.application     return self._enter()
2023-02-13 23:15:56.882808 2023-02-13 23:15:56.873 38 ERROR keystone.server.flask.application   File "/var/lib/kolla/venv/lib/python3.9/site-packages/dogpile/lock.py", line 94, in _enter
2023-02-13 23:15:56.882830 2023-02-13 23:15:56.873 38 ERROR keystone.server.flask.application     generated = self._enter_create(value, createdtime)
2023-02-13 23:15:56.882850 2023-02-13 23:15:56.873 38 ERROR keystone.server.flask.application   File "/var/lib/kolla/venv/lib/python3.9/site-packages/dogpile/lock.py", line 178, in _enter_create
2023-02-13 23:15:56.882871 2023-02-13 23:15:56.873 38 ERROR keystone.server.flask.application     return self.creator()
2023-02-13 23:15:56.882888 2023-02-13 23:15:56.873 38 ERROR keystone.server.flask.application   File "/var/lib/kolla/venv/lib/python3.9/site-packages/dogpile/cache/region.py", line 995, in gen_value
2023-02-13 23:15:56.882907 2023-02-13 23:15:56.873 38 ERROR keystone.server.flask.application     created_value = creator(
2023-02-13 23:15:56.882926 2023-02-13 23:15:56.873 38 ERROR keystone.server.flask.application   File "/var/lib/kolla/venv/lib/python3.9/site-packages/keystone/identity/core.py", line 1011, in get_user
2023-02-13 23:15:56.882945 2023-02-13 23:15:56.873 38 ERROR keystone.server.flask.application     ref = driver.get_user(entity_id)
2023-02-13 23:15:56.882965 2023-02-13 23:15:56.873 38 ERROR keystone.server.flask.application   File "/var/lib/kolla/venv/lib/python3.9/site-packages/keystone/identity/backends/sql.py", line 200, in get_user
2023-02-13 23:15:56.882982 2023-02-13 23:15:56.873 38 ERROR keystone.server.flask.application     self._get_user(session, user_id).to_dict())
2023-02-13 23:15:56.883000 2023-02-13 23:15:56.873 38 ERROR keystone.server.flask.application   File "/var/lib/kolla/venv/lib/python3.9/site-packages/keystone/identity/backends/sql.py", line 194, in _get_user
2023-02-13 23:15:56.883022 2023-02-13 23:15:56.873 38 ERROR keystone.server.flask.application     raise exception.UserNotFound(user_id=user_id)
2023-02-13 23:15:56.883041 2023-02-13 23:15:56.873 38 ERROR keystone.server.flask.application keystone.exception.UserNotFound: Could not find user: neutron.
2023-02-13 23:15:56.883061 2023-02-13 23:15:56.873 38 ERROR keystone.server.flask.application \x1b[00m
2023-02-13 23:15:57.106846 2023-02-13 23:15:57.105 37 WARNING py.warnings [None req-f3da9b5a-3473-464f-9bc0-3aa3ae53515c f030e67c936f4531b915f6b82c685e84 de5ffdbf40fb4a31bba96ecd465d556c - - default default] /var/lib/kolla/venv/lib/python3.9/site-packages/oslo_policy/policy.py:1129: UserWarning: Policy "identity:list_users": "(role:reader and system_scope:all) or (role:reader and domain_id:%(target.domain_id)s)" failed scope check. The token used to make the request was project scoped but the policy requires ['system', 'domain'] scope. This behavior may change in the future where using the intended scope is required
2023-02-13 23:15:57.106922   warnings.warn(msg)
2023-02-13 23:15:57.106934 \x1b[00m
2023-02-13 23:15:57.404017 2023-02-13 23:15:57.397 38 ERROR keystone.server.flask.application [None req-0bd65061-23bf-4998-b15a-cf160497d9fb f030e67c936f4531b915f6b82c685e84 de5ffdbf40fb4a31bba96ecd465d556c - - default default] Could not find project: service.: keystone.exception.ProjectNotFound: Could not find project: service.
2023-02-13 23:15:57.404078 2023-02-13 23:15:57.397 38 ERROR keystone.server.flask.application Traceback (most recent call last):
2023-02-13 23:15:57.404090 2023-02-13 23:15:57.397 38 ERROR keystone.server.flask.application   File "/var/lib/kolla/venv/lib/python3.9/site-packages/flask/app.py", line 1820, in full_dispatch_request
2023-02-13 23:15:57.404101 2023-02-13 23:15:57.397 38 ERROR keystone.server.flask.application     rv = self.dispatch_request()
2023-02-13 23:15:57.404111 2023-02-13 23:15:57.397 38 ERROR keystone.server.flask.application   File "/var/lib/kolla/venv/lib/python3.9/site-packages/flask/app.py", line 1796, in dispatch_request
2023-02-13 23:15:57.404122 2023-02-13 23:15:57.397 38 ERROR keystone.server.flask.application     return self.ensure_sync(self.view_functions[rule.endpoint])(**view_args)
2023-02-13 23:15:57.404132 2023-02-13 23:15:57.397 38 ERROR keystone.server.flask.application   File "/var/lib/kolla/venv/lib/python3.9/site-packages/flask_restful/__init__.py", line 467, in wrapper
2023-02-13 23:15:57.404142 2023-02-13 23:15:57.397 38 ERROR keystone.server.flask.application     resp = resource(*args, **kwargs)
2023-02-13 23:15:57.404152 2023-02-13 23:15:57.397 38 ERROR keystone.server.flask.application   File "/var/lib/kolla/venv/lib/python3.9/site-packages/flask/views.py", line 107, in view
2023-02-13 23:15:57.404162 2023-02-13 23:15:57.397 38 ERROR keystone.server.flask.application     return current_app.ensure_sync(self.dispatch_request)(**kwargs)
2023-02-13 23:15:57.404172 2023-02-13 23:15:57.397 38 ERROR keystone.server.flask.application   File "/var/lib/kolla/venv/lib/python3.9/site-packages/flask_restful/__init__.py", line 582, in dispatch_request
2023-02-13 23:15:57.404182 2023-02-13 23:15:57.397 38 ERROR keystone.server.flask.application     resp = meth(*args, **kwargs)
2023-02-13 23:15:57.404192 2023-02-13 23:15:57.397 38 ERROR keystone.server.flask.application   File "/var/lib/kolla/venv/lib/python3.9/site-packages/keystone/api/projects.py", line 151, in get
2023-02-13 23:15:57.404202 2023-02-13 23:15:57.397 38 ERROR keystone.server.flask.application     return self._get_project(project_id)
2023-02-13 23:15:57.404212 2023-02-13 23:15:57.397 38 ERROR keystone.server.flask.application   File "/var/lib/kolla/venv/lib/python3.9/site-packages/keystone/api/projects.py", line 107, in _get_project
2023-02-13 23:15:57.404222 2023-02-13 23:15:57.397 38 ERROR keystone.server.flask.application     project = PROVIDERS.resource_api.get_project(project_id)
2023-02-13 23:15:57.404232 2023-02-13 23:15:57.397 38 ERROR keystone.server.flask.application   File "/var/lib/kolla/venv/lib/python3.9/site-packages/keystone/common/manager.py", line 115, in wrapped
2023-02-13 23:15:57.404241 2023-02-13 23:15:57.397 38 ERROR keystone.server.flask.application     __ret_val = __f(*args, **kwargs)
2023-02-13 23:15:57.404251 2023-02-13 23:15:57.397 38 ERROR keystone.server.flask.application   File "/var/lib/kolla/venv/lib/python3.9/site-packages/decorator.py", line 232, in fun
2023-02-13 23:15:57.404261 2023-02-13 23:15:57.397 38 ERROR keystone.server.flask.application     return caller(func, *(extras + args), **kw)
2023-02-13 23:15:57.404271 2023-02-13 23:15:57.397 38 ERROR keystone.server.flask.application   File "/var/lib/kolla/venv/lib/python3.9/site-packages/dogpile/cache/region.py", line 1577, in get_or_create_for_user_func
2023-02-13 23:15:57.404298 2023-02-13 23:15:57.397 38 ERROR keystone.server.flask.application     return self.get_or_create(
2023-02-13 23:15:57.404309 2023-02-13 23:15:57.397 38 ERROR keystone.server.flask.application   File "/var/lib/kolla/venv/lib/python3.9/site-packages/dogpile/cache/region.py", line 1042, in get_or_create
2023-02-13 23:15:57.404320 2023-02-13 23:15:57.397 38 ERROR keystone.server.flask.application     with Lock(
2023-02-13 23:15:57.404330 2023-02-13 23:15:57.397 38 ERROR keystone.server.flask.application   File "/var/lib/kolla/venv/lib/python3.9/site-packages/dogpile/lock.py", line 185, in __enter__
2023-02-13 23:15:57.404340 2023-02-13 23:15:57.397 38 ERROR keystone.server.flask.application     return self._enter()
2023-02-13 23:15:57.404350 2023-02-13 23:15:57.397 38 ERROR keystone.server.flask.application   File "/var/lib/kolla/venv/lib/python3.9/site-packages/dogpile/lock.py", line 94, in _enter
2023-02-13 23:15:57.404360 2023-02-13 23:15:57.397 38 ERROR keystone.server.flask.application     generated = self._enter_create(value, createdtime)
2023-02-13 23:15:57.404369 2023-02-13 23:15:57.397 38 ERROR keystone.server.flask.application   File "/var/lib/kolla/venv/lib/python3.9/site-packages/dogpile/lock.py", line 178, in _enter_create
2023-02-13 23:15:57.404379 2023-02-13 23:15:57.397 38 ERROR keystone.server.flask.application     return self.creator()
2023-02-13 23:15:57.404389 2023-02-13 23:15:57.397 38 ERROR keystone.server.flask.application   File "/var/lib/kolla/venv/lib/python3.9/site-packages/dogpile/cache/region.py", line 995, in gen_value
2023-02-13 23:15:57.404399 2023-02-13 23:15:57.397 38 ERROR keystone.server.flask.application     created_value = creator(
2023-02-13 23:15:57.404409 2023-02-13 23:15:57.397 38 ERROR keystone.server.flask.application   File "/var/lib/kolla/venv/lib/python3.9/site-packages/keystone/resource/core.py", line 903, in get_project
2023-02-13 23:15:57.404420 2023-02-13 23:15:57.397 38 ERROR keystone.server.flask.application     return self.driver.get_project(project_id)
2023-02-13 23:15:57.404434 2023-02-13 23:15:57.397 38 ERROR keystone.server.flask.application   File "/var/lib/kolla/venv/lib/python3.9/site-packages/keystone/resource/backends/sql.py", line 49, in get_project
2023-02-13 23:15:57.404445 2023-02-13 23:15:57.397 38 ERROR keystone.server.flask.application     return self._get_project(session, project_id).to_dict()
2023-02-13 23:15:57.404455 2023-02-13 23:15:57.397 38 ERROR keystone.server.flask.application   File "/var/lib/kolla/venv/lib/python3.9/site-packages/keystone/resource/backends/sql.py", line 44, in _get_project
2023-02-13 23:15:57.404465 2023-02-13 23:15:57.397 38 ERROR keystone.server.flask.application     raise exception.ProjectNotFound(project_id=project_id)
2023-02-13 23:15:57.404475 2023-02-13 23:15:57.397 38 ERROR keystone.server.flask.application keystone.exception.ProjectNotFound: Could not find project: service.
2023-02-13 23:15:57.404485 2023-02-13 23:15:57.397 38 ERROR keystone.server.flask.application \x1b[00m
2023-02-13 23:15:57.613950 2023-02-13 23:15:57.612 37 WARNING py.warnings [None req-b53557ba-c603-4460-9750-fe838246bd79 f030e67c936f4531b915f6b82c685e84 de5ffdbf40fb4a31bba96ecd465d556c - - default default] /var/lib/kolla/venv/lib/python3.9/site-packages/oslo_policy/policy.py:1129: UserWarning: Policy "identity:list_projects": "(role:reader and system_scope:all) or (role:reader and domain_id:%(target.domain_id)s)" failed scope check. The token used to make the request was project scoped but the policy requires ['system', 'domain'] scope. This behavior may change in the future where using the intended scope is required
2023-02-13 23:15:57.613989   warnings.warn(msg)
2023-02-13 23:15:57.613999 \x1b[00m
2023-02-13 23:15:57.905105 2023-02-13 23:15:57.902 38 WARNING py.warnings [None req-7795e410-9a4b-44c2-a01d-a3263fd73490 f030e67c936f4531b915f6b82c685e84 de5ffdbf40fb4a31bba96ecd465d556c - - default default] /var/lib/kolla/venv/lib/python3.9/site-packages/oslo_policy/policy.py:1129: UserWarning: Policy "identity:create_grant": "(role:admin and system_scope:all) or ((role:admin and domain_id:%(target.user.domain_id)s and domain_id:%(target.project.domain_id)s) or (role:admin and domain_id:%(target.user.domain_id)s and domain_id:%(target.domain.id)s) or (role:admin and domain_id:%(target.group.domain_id)s and domain_id:%(target.project.domain_id)s) or (role:admin and domain_id:%(target.group.domain_id)s and domain_id:%(target.domain.id)s)) and (domain_id:%(target.role.domain_id)s or None:%(target.role.domain_id)s)" failed scope check. The token used to make the request was project scoped but the policy requires ['system', 'domain'] scope. This behavior may change in the future where using the intended scope is required
2023-02-13 23:15:57.905188   warnings.warn(msg)
2023-02-13 23:15:57.905201 \x1b[00m
2023-02-13 23:16:02.057286 2023-02-13 23:16:02.056 38 WARNING py.warnings [None req-5473ade4-34d6-4b7f-94db-c729dcdb03a9 f030e67c936f4531b915f6b82c685e84 de5ffdbf40fb4a31bba96ecd465d556c - - default default] /var/lib/kolla/venv/lib/python3.9/site-packages/oslo_policy/policy.py:1129: UserWarning: Policy "identity:create_service": "role:admin and system_scope:all" failed scope check. The token used to make the request was project scoped but the policy requires ['system'] scope. This behavior may change in the future where using the intended scope is required
2023-02-13 23:16:02.057335   warnings.warn(msg)
2023-02-13 23:16:02.057346 \x1b[00m
2023-02-13 23:16:06.578106 2023-02-13 23:16:06.575 37 WARNING py.warnings [None req-81fc37da-6226-4467-95be-10c7fbc00c6b f030e67c936f4531b915f6b82c685e84 de5ffdbf40fb4a31bba96ecd465d556c - - default default] /var/lib/kolla/venv/lib/python3.9/site-packages/oslo_policy/policy.py:1129: UserWarning: Policy "identity:get_service": "role:reader and system_scope:all" failed scope check. The token used to make the request was project scoped but the policy requires ['system'] scope. This behavior may change in the future where using the intended scope is required
2023-02-13 23:16:06.578167   warnings.warn(msg)
2023-02-13 23:16:06.578179 \x1b[00m
2023-02-13 23:16:06.605708 2023-02-13 23:16:06.595 37 ERROR keystone.server.flask.application [None req-81fc37da-6226-4467-95be-10c7fbc00c6b f030e67c936f4531b915f6b82c685e84 de5ffdbf40fb4a31bba96ecd465d556c - - default default] Could not find service: network.: keystone.exception.ServiceNotFound: Could not find service: network.
2023-02-13 23:16:06.605835 2023-02-13 23:16:06.595 37 ERROR keystone.server.flask.application Traceback (most recent call last):
2023-02-13 23:16:06.605851 2023-02-13 23:16:06.595 37 ERROR keystone.server.flask.application   File "/var/lib/kolla/venv/lib/python3.9/site-packages/keystone/catalog/core.py", line 152, in get_service
2023-02-13 23:16:06.605862 2023-02-13 23:16:06.595 37 ERROR keystone.server.flask.application     return self.driver.get_service(service_id)
2023-02-13 23:16:06.605872 2023-02-13 23:16:06.595 37 ERROR keystone.server.flask.application   File "/var/lib/kolla/venv/lib/python3.9/site-packages/keystone/catalog/backends/sql.py", line 196, in get_service
2023-02-13 23:16:06.605883 2023-02-13 23:16:06.595 37 ERROR keystone.server.flask.application     return self._get_service(session, service_id).to_dict()
2023-02-13 23:16:06.605893 2023-02-13 23:16:06.595 37 ERROR keystone.server.flask.application   File "/var/lib/kolla/venv/lib/python3.9/site-packages/keystone/catalog/backends/sql.py", line 191, in _get_service
2023-02-13 23:16:06.605903 2023-02-13 23:16:06.595 37 ERROR keystone.server.flask.application     raise exception.ServiceNotFound(service_id=service_id)
2023-02-13 23:16:06.605913 2023-02-13 23:16:06.595 37 ERROR keystone.server.flask.application keystone.exception.ServiceNotFound: Could not find service: network.
2023-02-13 23:16:06.605924 2023-02-13 23:16:06.595 37 ERROR keystone.server.flask.application 
2023-02-13 23:16:06.605933 2023-02-13 23:16:06.595 37 ERROR keystone.server.flask.application During handling of the above exception, another exception occurred:
2023-02-13 23:16:06.605978 2023-02-13 23:16:06.595 37 ERROR keystone.server.flask.application 
2023-02-13 23:16:06.605991 2023-02-13 23:16:06.595 37 ERROR keystone.server.flask.application Traceback (most recent call last):
2023-02-13 23:16:06.606002 2023-02-13 23:16:06.595 37 ERROR keystone.server.flask.application   File "/var/lib/kolla/venv/lib/python3.9/site-packages/flask/app.py", line 1820, in full_dispatch_request
2023-02-13 23:16:06.606012 2023-02-13 23:16:06.595 37 ERROR keystone.server.flask.application     rv = self.dispatch_request()
2023-02-13 23:16:06.606022 2023-02-13 23:16:06.595 37 ERROR keystone.server.flask.application   File "/var/lib/kolla/venv/lib/python3.9/site-packages/flask/app.py", line 1796, in dispatch_request
2023-02-13 23:16:06.606032 2023-02-13 23:16:06.595 37 ERROR keystone.server.flask.application     return self.ensure_sync(self.view_functions[rule.endpoint])(**view_args)
2023-02-13 23:16:06.606042 2023-02-13 23:16:06.595 37 ERROR keystone.server.flask.application   File "/var/lib/kolla/venv/lib/python3.9/site-packages/flask_restful/__init__.py", line 467, in wrapper
2023-02-13 23:16:06.606052 2023-02-13 23:16:06.595 37 ERROR keystone.server.flask.application     resp = resource(*args, **kwargs)
2023-02-13 23:16:06.606082 2023-02-13 23:16:06.595 37 ERROR keystone.server.flask.application   File "/var/lib/kolla/venv/lib/python3.9/site-packages/flask/views.py", line 107, in view
2023-02-13 23:16:06.606097 2023-02-13 23:16:06.595 37 ERROR keystone.server.flask.application     return current_app.ensure_sync(self.dispatch_request)(**kwargs)
2023-02-13 23:16:06.606107 2023-02-13 23:16:06.595 37 ERROR keystone.server.flask.application   File "/var/lib/kolla/venv/lib/python3.9/site-packages/flask_restful/__init__.py", line 582, in dispatch_request
2023-02-13 23:16:06.606118 2023-02-13 23:16:06.595 37 ERROR keystone.server.flask.application     resp = meth(*args, **kwargs)
2023-02-13 23:16:06.606128 2023-02-13 23:16:06.595 37 ERROR keystone.server.flask.application   File "/var/lib/kolla/venv/lib/python3.9/site-packages/keystone/api/services.py", line 45, in get
2023-02-13 23:16:06.606138 2023-02-13 23:16:06.595 37 ERROR keystone.server.flask.application     return self._get_service(service_id)
2023-02-13 23:16:06.606148 2023-02-13 23:16:06.595 37 ERROR keystone.server.flask.application   File "/var/lib/kolla/venv/lib/python3.9/site-packages/keystone/api/services.py", line 34, in _get_service
2023-02-13 23:16:06.606159 2023-02-13 23:16:06.595 37 ERROR keystone.server.flask.application     return self.wrap_member(PROVIDERS.catalog_api.get_service(service_id))
2023-02-13 23:16:06.606169 2023-02-13 23:16:06.595 37 ERROR keystone.server.flask.application   File "/var/lib/kolla/venv/lib/python3.9/site-packages/keystone/common/manager.py", line 115, in wrapped
2023-02-13 23:16:06.606179 2023-02-13 23:16:06.595 37 ERROR keystone.server.flask.application     __ret_val = __f(*args, **kwargs)
2023-02-13 23:16:06.606189 2023-02-13 23:16:06.595 37 ERROR keystone.server.flask.application   File "/var/lib/kolla/venv/lib/python3.9/site-packages/decorator.py", line 232, in fun
2023-02-13 23:16:06.606199 2023-02-13 23:16:06.595 37 ERROR keystone.server.flask.application     return caller(func, *(extras + args), **kw)
2023-02-13 23:16:06.606218 2023-02-13 23:16:06.595 37 ERROR keystone.server.flask.application   File "/var/lib/kolla/venv/lib/python3.9/site-packages/dogpile/cache/region.py", line 1577, in get_or_create_for_user_func
2023-02-13 23:16:06.606232 2023-02-13 23:16:06.595 37 ERROR keystone.server.flask.application     return self.get_or_create(
2023-02-13 23:16:06.606243 2023-02-13 23:16:06.595 37 ERROR keystone.server.flask.application   File "/var/lib/kolla/venv/lib/python3.9/site-packages/dogpile/cache/region.py", line 1042, in get_or_create
2023-02-13 23:16:06.606253 2023-02-13 23:16:06.595 37 ERROR keystone.server.flask.application     with Lock(
2023-02-13 23:16:06.606263 2023-02-13 23:16:06.595 37 ERROR keystone.server.flask.application   File "/var/lib/kolla/venv/lib/python3.9/site-packages/dogpile/lock.py", line 185, in __enter__
2023-02-13 23:16:06.606297 2023-02-13 23:16:06.595 37 ERROR keystone.server.flask.application     return self._enter()
2023-02-13 23:16:06.606309 2023-02-13 23:16:06.595 37 ERROR keystone.server.flask.application   File "/var/lib/kolla/venv/lib/python3.9/site-packages/dogpile/lock.py", line 94, in _enter
2023-02-13 23:16:06.606320 2023-02-13 23:16:06.595 37 ERROR keystone.server.flask.application     generated = self._enter_create(value, createdtime)
2023-02-13 23:16:06.606330 2023-02-13 23:16:06.595 37 ERROR keystone.server.flask.application   File "/var/lib/kolla/venv/lib/python3.9/site-packages/dogpile/lock.py", line 178, in _enter_create
2023-02-13 23:16:06.606340 2023-02-13 23:16:06.595 37 ERROR keystone.server.flask.application     return self.creator()
2023-02-13 23:16:06.606350 2023-02-13 23:16:06.595 37 ERROR keystone.server.flask.application   File "/var/lib/kolla/venv/lib/python3.9/site-packages/dogpile/cache/region.py", line 995, in gen_value
2023-02-13 23:16:06.606360 2023-02-13 23:16:06.595 37 ERROR keystone.server.flask.application     created_value = creator(
2023-02-13 23:16:06.606370 2023-02-13 23:16:06.595 37 ERROR keystone.server.flask.application   File "/var/lib/kolla/venv/lib/python3.9/site-packages/keystone/catalog/core.py", line 154, in get_service
2023-02-13 23:16:06.606380 2023-02-13 23:16:06.595 37 ERROR keystone.server.flask.application     raise exception.ServiceNotFound(service_id=service_id)
2023-02-13 23:16:06.606390 2023-02-13 23:16:06.595 37 ERROR keystone.server.flask.application keystone.exception.ServiceNotFound: Could not find service: network.
2023-02-13 23:16:06.606400 2023-02-13 23:16:06.595 37 ERROR keystone.server.flask.application \x1b[00m
2023-02-13 23:16:06.790102 2023-02-13 23:16:06.788 38 WARNING py.warnings [None req-d30220bf-e9e0-41f9-8bc6-a8f9472b0b71 f030e67c936f4531b915f6b82c685e84 de5ffdbf40fb4a31bba96ecd465d556c - - default default] /var/lib/kolla/venv/lib/python3.9/site-packages/oslo_policy/policy.py:1129: UserWarning: Policy "identity:list_services": "role:reader and system_scope:all" failed scope check. The token used to make the request was project scoped but the policy requires ['system'] scope. This behavior may change in the future where using the intended scope is required
2023-02-13 23:16:06.790144   warnings.warn(msg)
2023-02-13 23:16:06.790155 \x1b[00m
2023-02-13 23:16:07.068427 2023-02-13 23:16:07.067 37 WARNING py.warnings [None req-faf6882d-c76e-4923-8905-93aea199fe5b f030e67c936f4531b915f6b82c685e84 de5ffdbf40fb4a31bba96ecd465d556c - - default default] /var/lib/kolla/venv/lib/python3.9/site-packages/oslo_policy/policy.py:1129: UserWarning: Policy "identity:list_services": "role:reader and system_scope:all" failed scope check. The token used to make the request was project scoped but the policy requires ['system'] scope. This behavior may change in the future where using the intended scope is required
2023-02-13 23:16:07.068471   warnings.warn(msg)
2023-02-13 23:16:07.068482 \x1b[00m
2023-02-13 23:16:07.318995 2023-02-13 23:16:07.317 38 WARNING py.warnings [None req-44835330-6342-4134-be74-f84d078462d3 f030e67c936f4531b915f6b82c685e84 de5ffdbf40fb4a31bba96ecd465d556c - - default default] /var/lib/kolla/venv/lib/python3.9/site-packages/oslo_policy/policy.py:1129: UserWarning: Policy "identity:create_endpoint": "role:admin and system_scope:all" failed scope check. The token used to make the request was project scoped but the policy requires ['system'] scope. This behavior may change in the future where using the intended scope is required
2023-02-13 23:16:07.319053   warnings.warn(msg)
2023-02-13 23:16:07.319064 \x1b[00m
2023-02-13 23:16:11.831950 2023-02-13 23:16:11.827 37 ERROR keystone.server.flask.application [None req-3679afde-d93c-4533-b4b5-f7c2dcc370d5 f030e67c936f4531b915f6b82c685e84 de5ffdbf40fb4a31bba96ecd465d556c - - default default] Could not find service: network.: keystone.exception.ServiceNotFound: Could not find service: network.
2023-02-13 23:16:11.832003 2023-02-13 23:16:11.827 37 ERROR keystone.server.flask.application Traceback (most recent call last):
2023-02-13 23:16:11.832044 2023-02-13 23:16:11.827 37 ERROR keystone.server.flask.application   File "/var/lib/kolla/venv/lib/python3.9/site-packages/keystone/catalog/core.py", line 152, in get_service
2023-02-13 23:16:11.832058 2023-02-13 23:16:11.827 37 ERROR keystone.server.flask.application     return self.driver.get_service(service_id)
2023-02-13 23:16:11.832068 2023-02-13 23:16:11.827 37 ERROR keystone.server.flask.application   File "/var/lib/kolla/venv/lib/python3.9/site-packages/keystone/catalog/backends/sql.py", line 196, in get_service
2023-02-13 23:16:11.832086 2023-02-13 23:16:11.827 37 ERROR keystone.server.flask.application     return self._get_service(session, service_id).to_dict()
2023-02-13 23:16:11.832099 2023-02-13 23:16:11.827 37 ERROR keystone.server.flask.application   File "/var/lib/kolla/venv/lib/python3.9/site-packages/keystone/catalog/backends/sql.py", line 191, in _get_service
2023-02-13 23:16:11.832109 2023-02-13 23:16:11.827 37 ERROR keystone.server.flask.application     raise exception.ServiceNotFound(service_id=service_id)
2023-02-13 23:16:11.832118 2023-02-13 23:16:11.827 37 ERROR keystone.server.flask.application keystone.exception.ServiceNotFound: Could not find service: network.
2023-02-13 23:16:11.832128 2023-02-13 23:16:11.827 37 ERROR keystone.server.flask.application 
2023-02-13 23:16:11.832138 2023-02-13 23:16:11.827 37 ERROR keystone.server.flask.application During handling of the above exception, another exception occurred:
2023-02-13 23:16:11.832147 2023-02-13 23:16:11.827 37 ERROR keystone.server.flask.application 
2023-02-13 23:16:11.832157 2023-02-13 23:16:11.827 37 ERROR keystone.server.flask.application Traceback (most recent call last):
2023-02-13 23:16:11.832166 2023-02-13 23:16:11.827 37 ERROR keystone.server.flask.application   File "/var/lib/kolla/venv/lib/python3.9/site-packages/flask/app.py", line 1820, in full_dispatch_request
2023-02-13 23:16:11.832176 2023-02-13 23:16:11.827 37 ERROR keystone.server.flask.application     rv = self.dispatch_request()
2023-02-13 23:16:11.832186 2023-02-13 23:16:11.827 37 ERROR keystone.server.flask.application   File "/var/lib/kolla/venv/lib/python3.9/site-packages/flask/app.py", line 1796, in dispatch_request
2023-02-13 23:16:11.832196 2023-02-13 23:16:11.827 37 ERROR keystone.server.flask.application     return self.ensure_sync(self.view_functions[rule.endpoint])(**view_args)
2023-02-13 23:16:11.832206 2023-02-13 23:16:11.827 37 ERROR keystone.server.flask.application   File "/var/lib/kolla/venv/lib/python3.9/site-packages/flask_restful/__init__.py", line 467, in wrapper
2023-02-13 23:16:11.832216 2023-02-13 23:16:11.827 37 ERROR keystone.server.flask.application     resp = resource(*args, **kwargs)
2023-02-13 23:16:11.832226 2023-02-13 23:16:11.827 37 ERROR keystone.server.flask.application   File "/var/lib/kolla/venv/lib/python3.9/site-packages/flask/views.py", line 107, in view
2023-02-13 23:16:11.832236 2023-02-13 23:16:11.827 37 ERROR keystone.server.flask.application     return current_app.ensure_sync(self.dispatch_request)(**kwargs)
2023-02-13 23:16:11.832245 2023-02-13 23:16:11.827 37 ERROR keystone.server.flask.application   File "/var/lib/kolla/venv/lib/python3.9/site-packages/flask_restful/__init__.py", line 582, in dispatch_request
2023-02-13 23:16:11.832255 2023-02-13 23:16:11.827 37 ERROR keystone.server.flask.application     resp = meth(*args, **kwargs)
2023-02-13 23:16:11.832265 2023-02-13 23:16:11.827 37 ERROR keystone.server.flask.application   File "/var/lib/kolla/venv/lib/python3.9/site-packages/keystone/api/services.py", line 45, in get
2023-02-13 23:16:11.832274 2023-02-13 23:16:11.827 37 ERROR keystone.server.flask.application     return self._get_service(service_id)
2023-02-13 23:16:11.832284 2023-02-13 23:16:11.827 37 ERROR keystone.server.flask.application   File "/var/lib/kolla/venv/lib/python3.9/site-packages/keystone/api/services.py", line 34, in _get_service
2023-02-13 23:16:11.832294 2023-02-13 23:16:11.827 37 ERROR keystone.server.flask.application     return self.wrap_member(PROVIDERS.catalog_api.get_service(service_id))
2023-02-13 23:16:11.832326 2023-02-13 23:16:11.827 37 ERROR keystone.server.flask.application   File "/var/lib/kolla/venv/lib/python3.9/site-packages/keystone/common/manager.py", line 115, in wrapped
2023-02-13 23:16:11.832339 2023-02-13 23:16:11.827 37 ERROR keystone.server.flask.application     __ret_val = __f(*args, **kwargs)
2023-02-13 23:16:11.832349 2023-02-13 23:16:11.827 37 ERROR keystone.server.flask.application   File "/var/lib/kolla/venv/lib/python3.9/site-packages/decorator.py", line 232, in fun
2023-02-13 23:16:11.832359 2023-02-13 23:16:11.827 37 ERROR keystone.server.flask.application     return caller(func, *(extras + args), **kw)
2023-02-13 23:16:11.832377 2023-02-13 23:16:11.827 37 ERROR keystone.server.flask.application   File "/var/lib/kolla/venv/lib/python3.9/site-packages/dogpile/cache/region.py", line 1577, in get_or_create_for_user_func
2023-02-13 23:16:11.832390 2023-02-13 23:16:11.827 37 ERROR keystone.server.flask.application     return self.get_or_create(
2023-02-13 23:16:11.832400 2023-02-13 23:16:11.827 37 ERROR keystone.server.flask.application   File "/var/lib/kolla/venv/lib/python3.9/site-packages/dogpile/cache/region.py", line 1042, in get_or_create
2023-02-13 23:16:11.832410 2023-02-13 23:16:11.827 37 ERROR keystone.server.flask.application     with Lock(
2023-02-13 23:16:11.832420 2023-02-13 23:16:11.827 37 ERROR keystone.server.flask.application   File "/var/lib/kolla/venv/lib/python3.9/site-packages/dogpile/lock.py", line 185, in __enter__
2023-02-13 23:16:11.832430 2023-02-13 23:16:11.827 37 ERROR keystone.server.flask.application     return self._enter()
2023-02-13 23:16:11.832439 2023-02-13 23:16:11.827 37 ERROR keystone.server.flask.application   File "/var/lib/kolla/venv/lib/python3.9/site-packages/dogpile/lock.py", line 94, in _enter
2023-02-13 23:16:11.832449 2023-02-13 23:16:11.827 37 ERROR keystone.server.flask.application     generated = self._enter_create(value, createdtime)
2023-02-13 23:16:11.832459 2023-02-13 23:16:11.827 37 ERROR keystone.server.flask.application   File "/var/lib/kolla/venv/lib/python3.9/site-packages/dogpile/lock.py", line 178, in _enter_create
2023-02-13 23:16:11.832469 2023-02-13 23:16:11.827 37 ERROR keystone.server.flask.application     return self.creator()
2023-02-13 23:16:11.832478 2023-02-13 23:16:11.827 37 ERROR keystone.server.flask.application   File "/var/lib/kolla/venv/lib/python3.9/site-packages/dogpile/cache/region.py", line 995, in gen_value
2023-02-13 23:16:11.832488 2023-02-13 23:16:11.827 37 ERROR keystone.server.flask.application     created_value = creator(
2023-02-13 23:16:11.832498 2023-02-13 23:16:11.827 37 ERROR keystone.server.flask.application   File "/var/lib/kolla/venv/lib/python3.9/site-packages/keystone/catalog/core.py", line 154, in get_service
2023-02-13 23:16:11.832510 2023-02-13 23:16:11.827 37 ERROR keystone.server.flask.application     raise exception.ServiceNotFound(service_id=service_id)
2023-02-13 23:16:11.832538 2023-02-13 23:16:11.827 37 ERROR keystone.server.flask.application keystone.exception.ServiceNotFound: Could not find service: network.
2023-02-13 23:16:11.832548 2023-02-13 23:16:11.827 37 ERROR keystone.server.flask.application \x1b[00m
2023-02-13 23:16:12.689985 2023-02-13 23:16:12.689 37 WARNING py.warnings [None req-68e2eae6-43ac-4fad-9c00-b69e71f004ec f030e67c936f4531b915f6b82c685e84 de5ffdbf40fb4a31bba96ecd465d556c - - default default] /var/lib/kolla/venv/lib/python3.9/site-packages/oslo_policy/policy.py:1129: UserWarning: Policy "identity:create_endpoint": "role:admin and system_scope:all" failed scope check. The token used to make the request was project scoped but the policy requires ['system'] scope. This behavior may change in the future where using the intended scope is required
2023-02-13 23:16:12.690036   warnings.warn(msg)
2023-02-13 23:16:12.690047 \x1b[00m
2023-02-13 23:16:17.207589 2023-02-13 23:16:17.206 38 WARNING py.warnings [None req-f57902f4-867e-410a-b0fc-34aad0f694b7 f030e67c936f4531b915f6b82c685e84 de5ffdbf40fb4a31bba96ecd465d556c - - default default] /var/lib/kolla/venv/lib/python3.9/site-packages/oslo_policy/policy.py:1129: UserWarning: Policy "identity:get_service": "role:reader and system_scope:all" failed scope check. The token used to make the request was project scoped but the policy requires ['system'] scope. This behavior may change in the future where using the intended scope is required
2023-02-13 23:16:17.207687   warnings.warn(msg)
2023-02-13 23:16:17.207702 \x1b[00m
2023-02-13 23:16:17.227561 2023-02-13 23:16:17.221 38 ERROR keystone.server.flask.application [None req-f57902f4-867e-410a-b0fc-34aad0f694b7 f030e67c936f4531b915f6b82c685e84 de5ffdbf40fb4a31bba96ecd465d556c - - default default] Could not find service: network.: keystone.exception.ServiceNotFound: Could not find service: network.
2023-02-13 23:16:17.227627 2023-02-13 23:16:17.221 38 ERROR keystone.server.flask.application Traceback (most recent call last):
2023-02-13 23:16:17.227640 2023-02-13 23:16:17.221 38 ERROR keystone.server.flask.application   File "/var/lib/kolla/venv/lib/python3.9/site-packages/keystone/catalog/core.py", line 152, in get_service
2023-02-13 23:16:17.227652 2023-02-13 23:16:17.221 38 ERROR keystone.server.flask.application     return self.driver.get_service(service_id)
2023-02-13 23:16:17.227663 2023-02-13 23:16:17.221 38 ERROR keystone.server.flask.application   File "/var/lib/kolla/venv/lib/python3.9/site-packages/keystone/catalog/backends/sql.py", line 196, in get_service
2023-02-13 23:16:17.227675 2023-02-13 23:16:17.221 38 ERROR keystone.server.flask.application     return self._get_service(session, service_id).to_dict()
2023-02-13 23:16:17.227686 2023-02-13 23:16:17.221 38 ERROR keystone.server.flask.application   File "/var/lib/kolla/venv/lib/python3.9/site-packages/keystone/catalog/backends/sql.py", line 191, in _get_service
2023-02-13 23:16:17.227698 2023-02-13 23:16:17.221 38 ERROR keystone.server.flask.application     raise exception.ServiceNotFound(service_id=service_id)
2023-02-13 23:16:17.227709 2023-02-13 23:16:17.221 38 ERROR keystone.server.flask.application keystone.exception.ServiceNotFound: Could not find service: network.
2023-02-13 23:16:17.227720 2023-02-13 23:16:17.221 38 ERROR keystone.server.flask.application 
2023-02-13 23:16:17.227731 2023-02-13 23:16:17.221 38 ERROR keystone.server.flask.application During handling of the above exception, another exception occurred:
2023-02-13 23:16:17.227742 2023-02-13 23:16:17.221 38 ERROR keystone.server.flask.application 
2023-02-13 23:16:17.227780 2023-02-13 23:16:17.221 38 ERROR keystone.server.flask.application Traceback (most recent call last):
2023-02-13 23:16:17.227795 2023-02-13 23:16:17.221 38 ERROR keystone.server.flask.application   File "/var/lib/kolla/venv/lib/python3.9/site-packages/flask/app.py", line 1820, in full_dispatch_request
2023-02-13 23:16:17.227807 2023-02-13 23:16:17.221 38 ERROR keystone.server.flask.application     rv = self.dispatch_request()
2023-02-13 23:16:17.227818 2023-02-13 23:16:17.221 38 ERROR keystone.server.flask.application   File "/var/lib/kolla/venv/lib/python3.9/site-packages/flask/app.py", line 1796, in dispatch_request
2023-02-13 23:16:17.227830 2023-02-13 23:16:17.221 38 ERROR keystone.server.flask.application     return self.ensure_sync(self.view_functions[rule.endpoint])(**view_args)
2023-02-13 23:16:17.227841 2023-02-13 23:16:17.221 38 ERROR keystone.server.flask.application   File "/var/lib/kolla/venv/lib/python3.9/site-packages/flask_restful/__init__.py", line 467, in wrapper
2023-02-13 23:16:17.227876 2023-02-13 23:16:17.221 38 ERROR keystone.server.flask.application     resp = resource(*args, **kwargs)
2023-02-13 23:16:17.227899 2023-02-13 23:16:17.221 38 ERROR keystone.server.flask.application   File "/var/lib/kolla/venv/lib/python3.9/site-packages/flask/views.py", line 107, in view
2023-02-13 23:16:17.227915 2023-02-13 23:16:17.221 38 ERROR keystone.server.flask.application     return current_app.ensure_sync(self.dispatch_request)(**kwargs)
2023-02-13 23:16:17.227961 2023-02-13 23:16:17.221 38 ERROR keystone.server.flask.application   File "/var/lib/kolla/venv/lib/python3.9/site-packages/flask_restful/__init__.py", line 582, in dispatch_request
2023-02-13 23:16:17.227975 2023-02-13 23:16:17.221 38 ERROR keystone.server.flask.application     resp = meth(*args, **kwargs)
2023-02-13 23:16:17.227986 2023-02-13 23:16:17.221 38 ERROR keystone.server.flask.application   File "/var/lib/kolla/venv/lib/python3.9/site-packages/keystone/api/services.py", line 45, in get
2023-02-13 23:16:17.227998 2023-02-13 23:16:17.221 38 ERROR keystone.server.flask.application     return self._get_service(service_id)
2023-02-13 23:16:17.228009 2023-02-13 23:16:17.221 38 ERROR keystone.server.flask.application   File "/var/lib/kolla/venv/lib/python3.9/site-packages/keystone/api/services.py", line 34, in _get_service
2023-02-13 23:16:17.228020 2023-02-13 23:16:17.221 38 ERROR keystone.server.flask.application     return self.wrap_member(PROVIDERS.catalog_api.get_service(service_id))
2023-02-13 23:16:17.228031 2023-02-13 23:16:17.221 38 ERROR keystone.server.flask.application   File "/var/lib/kolla/venv/lib/python3.9/site-packages/keystone/common/manager.py", line 115, in wrapped
2023-02-13 23:16:17.228043 2023-02-13 23:16:17.221 38 ERROR keystone.server.flask.application     __ret_val = __f(*args, **kwargs)
2023-02-13 23:16:17.228053 2023-02-13 23:16:17.221 38 ERROR keystone.server.flask.application   File "/var/lib/kolla/venv/lib/python3.9/site-packages/decorator.py", line 232, in fun
2023-02-13 23:16:17.228065 2023-02-13 23:16:17.221 38 ERROR keystone.server.flask.application     return caller(func, *(extras + args), **kw)
2023-02-13 23:16:17.228076 2023-02-13 23:16:17.221 38 ERROR keystone.server.flask.application   File "/var/lib/kolla/venv/lib/python3.9/site-packages/dogpile/cache/region.py", line 1577, in get_or_create_for_user_func
2023-02-13 23:16:17.228088 2023-02-13 23:16:17.221 38 ERROR keystone.server.flask.application     return self.get_or_create(
2023-02-13 23:16:17.228099 2023-02-13 23:16:17.221 38 ERROR keystone.server.flask.application   File "/var/lib/kolla/venv/lib/python3.9/site-packages/dogpile/cache/region.py", line 1042, in get_or_create
2023-02-13 23:16:17.228111 2023-02-13 23:16:17.221 38 ERROR keystone.server.flask.application     with Lock(
2023-02-13 23:16:17.228122 2023-02-13 23:16:17.221 38 ERROR keystone.server.flask.application   File "/var/lib/kolla/venv/lib/python3.9/site-packages/dogpile/lock.py", line 185, in __enter__
2023-02-13 23:16:17.228133 2023-02-13 23:16:17.221 38 ERROR keystone.server.flask.application     return self._enter()
2023-02-13 23:16:17.228144 2023-02-13 23:16:17.221 38 ERROR keystone.server.flask.application   File "/var/lib/kolla/venv/lib/python3.9/site-packages/dogpile/lock.py", line 94, in _enter
2023-02-13 23:16:17.228159 2023-02-13 23:16:17.221 38 ERROR keystone.server.flask.application     generated = self._enter_create(value, createdtime)
2023-02-13 23:16:17.228170 2023-02-13 23:16:17.221 38 ERROR keystone.server.flask.application   File "/var/lib/kolla/venv/lib/python3.9/site-packages/dogpile/lock.py", line 178, in _enter_create
2023-02-13 23:16:17.228186 2023-02-13 23:16:17.221 38 ERROR keystone.server.flask.application     return self.creator()
2023-02-13 23:16:17.228196 2023-02-13 23:16:17.221 38 ERROR keystone.server.flask.application   File "/var/lib/kolla/venv/lib/python3.9/site-packages/dogpile/cache/region.py", line 995, in gen_value
2023-02-13 23:16:17.228208 2023-02-13 23:16:17.221 38 ERROR keystone.server.flask.application     created_value = creator(
2023-02-13 23:16:17.228218 2023-02-13 23:16:17.221 38 ERROR keystone.server.flask.application   File "/var/lib/kolla/venv/lib/python3.9/site-packages/keystone/catalog/core.py", line 154, in get_service
2023-02-13 23:16:17.228230 2023-02-13 23:16:17.221 38 ERROR keystone.server.flask.application     raise exception.ServiceNotFound(service_id=service_id)
2023-02-13 23:16:17.228241 2023-02-13 23:16:17.221 38 ERROR keystone.server.flask.application keystone.exception.ServiceNotFound: Could not find service: network.
2023-02-13 23:16:17.228277 2023-02-13 23:16:17.221 38 ERROR keystone.server.flask.application \x1b[00m
