2023-03-01 14:06:46.306751 2023-03-01 14:06:46.304 33 WARNING keystone.common.rbac_enforcer.enforcer [None req-6513354b-f27c-44bb-8cb0-1ce06cf36e48 4948d33173d947e3973c5cf5740ec4cb - - all default -] Deprecated policy rules found. Use oslopolicy-policy-generator and oslopolicy-policy-upgrade to detect and resolve deprecated policies in your configuration.\x1b[00m
2023-03-01 14:06:47.194096 2023-03-01 14:06:47.192 35 WARNING keystone.common.rbac_enforcer.enforcer [None req-327906ce-de77-461b-bd46-222036d8f064 4948d33173d947e3973c5cf5740ec4cb - - all default -] Deprecated policy rules found. Use oslopolicy-policy-generator and oslopolicy-policy-upgrade to detect and resolve deprecated policies in your configuration.\x1b[00m
2023-03-01 14:06:54.673539 2023-03-01 14:06:54.670 34 WARNING keystone.common.rbac_enforcer.enforcer [None req-2e1c201c-46c8-47fe-b8a1-fc291454f539 4948d33173d947e3973c5cf5740ec4cb - - all default -] Deprecated policy rules found. Use oslopolicy-policy-generator and oslopolicy-policy-upgrade to detect and resolve deprecated policies in your configuration.\x1b[00m
2023-03-01 14:08:13.655193 2023-03-01 14:08:13.615 33 ERROR keystone.server.flask.application [None req-d576d6fe-79db-41e4-ac40-3c9bee383255 4948d33173d947e3973c5cf5740ec4cb - - all default -] Could not find project: service.: keystone.exception.ProjectNotFound: Could not find project: service.
2023-03-01 14:08:13.655243 2023-03-01 14:08:13.615 33 ERROR keystone.server.flask.application Traceback (most recent call last):
2023-03-01 14:08:13.655256 2023-03-01 14:08:13.615 33 ERROR keystone.server.flask.application   File "/var/lib/kolla/venv/lib/python3.9/site-packages/flask/app.py", line 1820, in full_dispatch_request
2023-03-01 14:08:13.655266 2023-03-01 14:08:13.615 33 ERROR keystone.server.flask.application     rv = self.dispatch_request()
2023-03-01 14:08:13.655275 2023-03-01 14:08:13.615 33 ERROR keystone.server.flask.application   File "/var/lib/kolla/venv/lib/python3.9/site-packages/flask/app.py", line 1796, in dispatch_request
2023-03-01 14:08:13.655285 2023-03-01 14:08:13.615 33 ERROR keystone.server.flask.application     return self.ensure_sync(self.view_functions[rule.endpoint])(**view_args)
2023-03-01 14:08:13.655294 2023-03-01 14:08:13.615 33 ERROR keystone.server.flask.application   File "/var/lib/kolla/venv/lib/python3.9/site-packages/flask_restful/__init__.py", line 467, in wrapper
2023-03-01 14:08:13.655304 2023-03-01 14:08:13.615 33 ERROR keystone.server.flask.application     resp = resource(*args, **kwargs)
2023-03-01 14:08:13.655319 2023-03-01 14:08:13.615 33 ERROR keystone.server.flask.application   File "/var/lib/kolla/venv/lib/python3.9/site-packages/flask/views.py", line 107, in view
2023-03-01 14:08:13.655331 2023-03-01 14:08:13.615 33 ERROR keystone.server.flask.application     return current_app.ensure_sync(self.dispatch_request)(**kwargs)
2023-03-01 14:08:13.655365 2023-03-01 14:08:13.615 33 ERROR keystone.server.flask.application   File "/var/lib/kolla/venv/lib/python3.9/site-packages/flask_restful/__init__.py", line 582, in dispatch_request
2023-03-01 14:08:13.655381 2023-03-01 14:08:13.615 33 ERROR keystone.server.flask.application     resp = meth(*args, **kwargs)
2023-03-01 14:08:13.655391 2023-03-01 14:08:13.615 33 ERROR keystone.server.flask.application   File "/var/lib/kolla/venv/lib/python3.9/site-packages/keystone/api/projects.py", line 151, in get
2023-03-01 14:08:13.655401 2023-03-01 14:08:13.615 33 ERROR keystone.server.flask.application     return self._get_project(project_id)
2023-03-01 14:08:13.655410 2023-03-01 14:08:13.615 33 ERROR keystone.server.flask.application   File "/var/lib/kolla/venv/lib/python3.9/site-packages/keystone/api/projects.py", line 107, in _get_project
2023-03-01 14:08:13.655420 2023-03-01 14:08:13.615 33 ERROR keystone.server.flask.application     project = PROVIDERS.resource_api.get_project(project_id)
2023-03-01 14:08:13.655429 2023-03-01 14:08:13.615 33 ERROR keystone.server.flask.application   File "/var/lib/kolla/venv/lib/python3.9/site-packages/keystone/common/manager.py", line 115, in wrapped
2023-03-01 14:08:13.655468 2023-03-01 14:08:13.615 33 ERROR keystone.server.flask.application     __ret_val = __f(*args, **kwargs)
2023-03-01 14:08:13.655480 2023-03-01 14:08:13.615 33 ERROR keystone.server.flask.application   File "/var/lib/kolla/venv/lib/python3.9/site-packages/decorator.py", line 232, in fun
2023-03-01 14:08:13.655490 2023-03-01 14:08:13.615 33 ERROR keystone.server.flask.application     return caller(func, *(extras + args), **kw)
2023-03-01 14:08:13.655500 2023-03-01 14:08:13.615 33 ERROR keystone.server.flask.application   File "/var/lib/kolla/venv/lib/python3.9/site-packages/dogpile/cache/region.py", line 1577, in get_or_create_for_user_func
2023-03-01 14:08:13.655510 2023-03-01 14:08:13.615 33 ERROR keystone.server.flask.application     return self.get_or_create(
2023-03-01 14:08:13.655519 2023-03-01 14:08:13.615 33 ERROR keystone.server.flask.application   File "/var/lib/kolla/venv/lib/python3.9/site-packages/dogpile/cache/region.py", line 1042, in get_or_create
2023-03-01 14:08:13.655529 2023-03-01 14:08:13.615 33 ERROR keystone.server.flask.application     with Lock(
2023-03-01 14:08:13.655538 2023-03-01 14:08:13.615 33 ERROR keystone.server.flask.application   File "/var/lib/kolla/venv/lib/python3.9/site-packages/dogpile/lock.py", line 185, in __enter__
2023-03-01 14:08:13.655547 2023-03-01 14:08:13.615 33 ERROR keystone.server.flask.application     return self._enter()
2023-03-01 14:08:13.655557 2023-03-01 14:08:13.615 33 ERROR keystone.server.flask.application   File "/var/lib/kolla/venv/lib/python3.9/site-packages/dogpile/lock.py", line 94, in _enter
2023-03-01 14:08:13.655566 2023-03-01 14:08:13.615 33 ERROR keystone.server.flask.application     generated = self._enter_create(value, createdtime)
2023-03-01 14:08:13.655575 2023-03-01 14:08:13.615 33 ERROR keystone.server.flask.application   File "/var/lib/kolla/venv/lib/python3.9/site-packages/dogpile/lock.py", line 178, in _enter_create
2023-03-01 14:08:13.655585 2023-03-01 14:08:13.615 33 ERROR keystone.server.flask.application     return self.creator()
2023-03-01 14:08:13.655594 2023-03-01 14:08:13.615 33 ERROR keystone.server.flask.application   File "/var/lib/kolla/venv/lib/python3.9/site-packages/dogpile/cache/region.py", line 995, in gen_value
2023-03-01 14:08:13.655603 2023-03-01 14:08:13.615 33 ERROR keystone.server.flask.application     created_value = creator(
2023-03-01 14:08:13.655612 2023-03-01 14:08:13.615 33 ERROR keystone.server.flask.application   File "/var/lib/kolla/venv/lib/python3.9/site-packages/keystone/resource/core.py", line 903, in get_project
2023-03-01 14:08:13.655622 2023-03-01 14:08:13.615 33 ERROR keystone.server.flask.application     return self.driver.get_project(project_id)
2023-03-01 14:08:13.655631 2023-03-01 14:08:13.615 33 ERROR keystone.server.flask.application   File "/var/lib/kolla/venv/lib/python3.9/site-packages/keystone/resource/backends/sql.py", line 49, in get_project
2023-03-01 14:08:13.655641 2023-03-01 14:08:13.615 33 ERROR keystone.server.flask.application     return self._get_project(session, project_id).to_dict()
2023-03-01 14:08:13.655650 2023-03-01 14:08:13.615 33 ERROR keystone.server.flask.application   File "/var/lib/kolla/venv/lib/python3.9/site-packages/keystone/resource/backends/sql.py", line 44, in _get_project
2023-03-01 14:08:13.655660 2023-03-01 14:08:13.615 33 ERROR keystone.server.flask.application     raise exception.ProjectNotFound(project_id=project_id)
2023-03-01 14:08:13.655669 2023-03-01 14:08:13.615 33 ERROR keystone.server.flask.application keystone.exception.ProjectNotFound: Could not find project: service.
2023-03-01 14:08:13.655678 2023-03-01 14:08:13.615 33 ERROR keystone.server.flask.application \x1b[00m
2023-03-01 14:08:22.794111 2023-03-01 14:08:22.780 35 ERROR keystone.server.flask.application [None req-5978ff45-0ca1-4876-944a-b173b05f1ec7 4948d33173d947e3973c5cf5740ec4cb - - all default -] Could not find project: service.: keystone.exception.ProjectNotFound: Could not find project: service.
2023-03-01 14:08:22.794195 2023-03-01 14:08:22.780 35 ERROR keystone.server.flask.application Traceback (most recent call last):
2023-03-01 14:08:22.794281 2023-03-01 14:08:22.780 35 ERROR keystone.server.flask.application   File "/var/lib/kolla/venv/lib/python3.9/site-packages/flask/app.py", line 1820, in full_dispatch_request
2023-03-01 14:08:22.794298 2023-03-01 14:08:22.780 35 ERROR keystone.server.flask.application     rv = self.dispatch_request()
2023-03-01 14:08:22.794312 2023-03-01 14:08:22.780 35 ERROR keystone.server.flask.application   File "/var/lib/kolla/venv/lib/python3.9/site-packages/flask/app.py", line 1796, in dispatch_request
2023-03-01 14:08:22.794327 2023-03-01 14:08:22.780 35 ERROR keystone.server.flask.application     return self.ensure_sync(self.view_functions[rule.endpoint])(**view_args)
2023-03-01 14:08:22.794382 2023-03-01 14:08:22.780 35 ERROR keystone.server.flask.application   File "/var/lib/kolla/venv/lib/python3.9/site-packages/flask_restful/__init__.py", line 467, in wrapper
2023-03-01 14:08:22.794407 2023-03-01 14:08:22.780 35 ERROR keystone.server.flask.application     resp = resource(*args, **kwargs)
2023-03-01 14:08:22.794449 2023-03-01 14:08:22.780 35 ERROR keystone.server.flask.application   File "/var/lib/kolla/venv/lib/python3.9/site-packages/flask/views.py", line 107, in view
2023-03-01 14:08:22.794467 2023-03-01 14:08:22.780 35 ERROR keystone.server.flask.application     return current_app.ensure_sync(self.dispatch_request)(**kwargs)
2023-03-01 14:08:22.794482 2023-03-01 14:08:22.780 35 ERROR keystone.server.flask.application   File "/var/lib/kolla/venv/lib/python3.9/site-packages/flask_restful/__init__.py", line 582, in dispatch_request
2023-03-01 14:08:22.794496 2023-03-01 14:08:22.780 35 ERROR keystone.server.flask.application     resp = meth(*args, **kwargs)
2023-03-01 14:08:22.794511 2023-03-01 14:08:22.780 35 ERROR keystone.server.flask.application   File "/var/lib/kolla/venv/lib/python3.9/site-packages/keystone/api/projects.py", line 151, in get
2023-03-01 14:08:22.794525 2023-03-01 14:08:22.780 35 ERROR keystone.server.flask.application     return self._get_project(project_id)
2023-03-01 14:08:22.794539 2023-03-01 14:08:22.780 35 ERROR keystone.server.flask.application   File "/var/lib/kolla/venv/lib/python3.9/site-packages/keystone/api/projects.py", line 107, in _get_project
2023-03-01 14:08:22.794554 2023-03-01 14:08:22.780 35 ERROR keystone.server.flask.application     project = PROVIDERS.resource_api.get_project(project_id)
2023-03-01 14:08:22.794568 2023-03-01 14:08:22.780 35 ERROR keystone.server.flask.application   File "/var/lib/kolla/venv/lib/python3.9/site-packages/keystone/common/manager.py", line 115, in wrapped
2023-03-01 14:08:22.794582 2023-03-01 14:08:22.780 35 ERROR keystone.server.flask.application     __ret_val = __f(*args, **kwargs)
2023-03-01 14:08:22.794596 2023-03-01 14:08:22.780 35 ERROR keystone.server.flask.application   File "/var/lib/kolla/venv/lib/python3.9/site-packages/decorator.py", line 232, in fun
2023-03-01 14:08:22.794610 2023-03-01 14:08:22.780 35 ERROR keystone.server.flask.application     return caller(func, *(extras + args), **kw)
2023-03-01 14:08:22.794625 2023-03-01 14:08:22.780 35 ERROR keystone.server.flask.application   File "/var/lib/kolla/venv/lib/python3.9/site-packages/dogpile/cache/region.py", line 1577, in get_or_create_for_user_func
2023-03-01 14:08:22.794639 2023-03-01 14:08:22.780 35 ERROR keystone.server.flask.application     return self.get_or_create(
2023-03-01 14:08:22.794653 2023-03-01 14:08:22.780 35 ERROR keystone.server.flask.application   File "/var/lib/kolla/venv/lib/python3.9/site-packages/dogpile/cache/region.py", line 1042, in get_or_create
2023-03-01 14:08:22.794668 2023-03-01 14:08:22.780 35 ERROR keystone.server.flask.application     with Lock(
2023-03-01 14:08:22.794682 2023-03-01 14:08:22.780 35 ERROR keystone.server.flask.application   File "/var/lib/kolla/venv/lib/python3.9/site-packages/dogpile/lock.py", line 185, in __enter__
2023-03-01 14:08:22.794698 2023-03-01 14:08:22.780 35 ERROR keystone.server.flask.application     return self._enter()
2023-03-01 14:08:22.794763 2023-03-01 14:08:22.780 35 ERROR keystone.server.flask.application   File "/var/lib/kolla/venv/lib/python3.9/site-packages/dogpile/lock.py", line 94, in _enter
2023-03-01 14:08:22.794782 2023-03-01 14:08:22.780 35 ERROR keystone.server.flask.application     generated = self._enter_create(value, createdtime)
2023-03-01 14:08:22.794797 2023-03-01 14:08:22.780 35 ERROR keystone.server.flask.application   File "/var/lib/kolla/venv/lib/python3.9/site-packages/dogpile/lock.py", line 178, in _enter_create
2023-03-01 14:08:22.794811 2023-03-01 14:08:22.780 35 ERROR keystone.server.flask.application     return self.creator()
2023-03-01 14:08:22.794825 2023-03-01 14:08:22.780 35 ERROR keystone.server.flask.application   File "/var/lib/kolla/venv/lib/python3.9/site-packages/dogpile/cache/region.py", line 995, in gen_value
2023-03-01 14:08:22.794840 2023-03-01 14:08:22.780 35 ERROR keystone.server.flask.application     created_value = creator(
2023-03-01 14:08:22.794853 2023-03-01 14:08:22.780 35 ERROR keystone.server.flask.application   File "/var/lib/kolla/venv/lib/python3.9/site-packages/keystone/resource/core.py", line 903, in get_project
2023-03-01 14:08:22.794868 2023-03-01 14:08:22.780 35 ERROR keystone.server.flask.application     return self.driver.get_project(project_id)
2023-03-01 14:08:22.794882 2023-03-01 14:08:22.780 35 ERROR keystone.server.flask.application   File "/var/lib/kolla/venv/lib/python3.9/site-packages/keystone/resource/backends/sql.py", line 49, in get_project
2023-03-01 14:08:22.794897 2023-03-01 14:08:22.780 35 ERROR keystone.server.flask.application     return self._get_project(session, project_id).to_dict()
2023-03-01 14:08:22.794911 2023-03-01 14:08:22.780 35 ERROR keystone.server.flask.application   File "/var/lib/kolla/venv/lib/python3.9/site-packages/keystone/resource/backends/sql.py", line 44, in _get_project
2023-03-01 14:08:22.794925 2023-03-01 14:08:22.780 35 ERROR keystone.server.flask.application     raise exception.ProjectNotFound(project_id=project_id)
2023-03-01 14:08:22.794939 2023-03-01 14:08:22.780 35 ERROR keystone.server.flask.application keystone.exception.ProjectNotFound: Could not find project: service.
2023-03-01 14:08:22.794954 2023-03-01 14:08:22.780 35 ERROR keystone.server.flask.application \x1b[00m
2023-03-01 14:08:37.419846 2023-03-01 14:08:37.413 35 ERROR keystone.server.flask.application [None req-c5712f00-bfa0-40c3-a2b4-a8590fdd73f7 4948d33173d947e3973c5cf5740ec4cb - - all default -] Could not find role: admin.: keystone.exception.RoleNotFound: Could not find role: admin.
2023-03-01 14:08:37.419895 2023-03-01 14:08:37.413 35 ERROR keystone.server.flask.application Traceback (most recent call last):
2023-03-01 14:08:37.419907 2023-03-01 14:08:37.413 35 ERROR keystone.server.flask.application   File "/var/lib/kolla/venv/lib/python3.9/site-packages/flask/app.py", line 1820, in full_dispatch_request
2023-03-01 14:08:37.419917 2023-03-01 14:08:37.413 35 ERROR keystone.server.flask.application     rv = self.dispatch_request()
2023-03-01 14:08:37.419927 2023-03-01 14:08:37.413 35 ERROR keystone.server.flask.application   File "/var/lib/kolla/venv/lib/python3.9/site-packages/flask/app.py", line 1796, in dispatch_request
2023-03-01 14:08:37.419936 2023-03-01 14:08:37.413 35 ERROR keystone.server.flask.application     return self.ensure_sync(self.view_functions[rule.endpoint])(**view_args)
2023-03-01 14:08:37.419956 2023-03-01 14:08:37.413 35 ERROR keystone.server.flask.application   File "/var/lib/kolla/venv/lib/python3.9/site-packages/flask_restful/__init__.py", line 467, in wrapper
2023-03-01 14:08:37.419965 2023-03-01 14:08:37.413 35 ERROR keystone.server.flask.application     resp = resource(*args, **kwargs)
2023-03-01 14:08:37.419981 2023-03-01 14:08:37.413 35 ERROR keystone.server.flask.application   File "/var/lib/kolla/venv/lib/python3.9/site-packages/flask/views.py", line 107, in view
2023-03-01 14:08:37.419993 2023-03-01 14:08:37.413 35 ERROR keystone.server.flask.application     return current_app.ensure_sync(self.dispatch_request)(**kwargs)
2023-03-01 14:08:37.420002 2023-03-01 14:08:37.413 35 ERROR keystone.server.flask.application   File "/var/lib/kolla/venv/lib/python3.9/site-packages/flask_restful/__init__.py", line 582, in dispatch_request
2023-03-01 14:08:37.420042 2023-03-01 14:08:37.413 35 ERROR keystone.server.flask.application     resp = meth(*args, **kwargs)
2023-03-01 14:08:37.420054 2023-03-01 14:08:37.413 35 ERROR keystone.server.flask.application   File "/var/lib/kolla/venv/lib/python3.9/site-packages/keystone/api/roles.py", line 50, in get
2023-03-01 14:08:37.420066 2023-03-01 14:08:37.413 35 ERROR keystone.server.flask.application     return self._get_role(role_id)
2023-03-01 14:08:37.420076 2023-03-01 14:08:37.413 35 ERROR keystone.server.flask.application   File "/var/lib/kolla/venv/lib/python3.9/site-packages/keystone/api/roles.py", line 70, in _get_role
2023-03-01 14:08:37.420085 2023-03-01 14:08:37.413 35 ERROR keystone.server.flask.application     ENFORCER.enforce_call(action='identity:get_role')
2023-03-01 14:08:37.420095 2023-03-01 14:08:37.413 35 ERROR keystone.server.flask.application   File "/var/lib/kolla/venv/lib/python3.9/site-packages/keystone/common/rbac_enforcer/enforcer.py", line 402, in enforce_call
2023-03-01 14:08:37.420104 2023-03-01 14:08:37.413 35 ERROR keystone.server.flask.application     policy_dict.update(cls._extract_member_target_data(
2023-03-01 14:08:37.420115 2023-03-01 14:08:37.413 35 ERROR keystone.server.flask.application   File "/var/lib/kolla/venv/lib/python3.9/site-packages/keystone/common/rbac_enforcer/enforcer.py", line 234, in _extract_member_target_data
2023-03-01 14:08:37.420125 2023-03-01 14:08:37.413 35 ERROR keystone.server.flask.application     member_name: func(flask.request.view_args[key])
2023-03-01 14:08:37.420134 2023-03-01 14:08:37.413 35 ERROR keystone.server.flask.application   File "/var/lib/kolla/venv/lib/python3.9/site-packages/keystone/common/manager.py", line 115, in wrapped
2023-03-01 14:08:37.420146 2023-03-01 14:08:37.413 35 ERROR keystone.server.flask.application     __ret_val = __f(*args, **kwargs)
2023-03-01 14:08:37.420156 2023-03-01 14:08:37.413 35 ERROR keystone.server.flask.application   File "/var/lib/kolla/venv/lib/python3.9/site-packages/decorator.py", line 232, in fun
2023-03-01 14:08:37.420165 2023-03-01 14:08:37.413 35 ERROR keystone.server.flask.application     return caller(func, *(extras + args), **kw)
2023-03-01 14:08:37.420174 2023-03-01 14:08:37.413 35 ERROR keystone.server.flask.application   File "/var/lib/kolla/venv/lib/python3.9/site-packages/dogpile/cache/region.py", line 1577, in get_or_create_for_user_func
2023-03-01 14:08:37.420184 2023-03-01 14:08:37.413 35 ERROR keystone.server.flask.application     return self.get_or_create(
2023-03-01 14:08:37.420193 2023-03-01 14:08:37.413 35 ERROR keystone.server.flask.application   File "/var/lib/kolla/venv/lib/python3.9/site-packages/dogpile/cache/region.py", line 1042, in get_or_create
2023-03-01 14:08:37.420211 2023-03-01 14:08:37.413 35 ERROR keystone.server.flask.application     with Lock(
2023-03-01 14:08:37.420220 2023-03-01 14:08:37.413 35 ERROR keystone.server.flask.application   File "/var/lib/kolla/venv/lib/python3.9/site-packages/dogpile/lock.py", line 185, in __enter__
2023-03-01 14:08:37.420229 2023-03-01 14:08:37.413 35 ERROR keystone.server.flask.application     return self._enter()
2023-03-01 14:08:37.420238 2023-03-01 14:08:37.413 35 ERROR keystone.server.flask.application   File "/var/lib/kolla/venv/lib/python3.9/site-packages/dogpile/lock.py", line 94, in _enter
2023-03-01 14:08:37.420248 2023-03-01 14:08:37.413 35 ERROR keystone.server.flask.application     generated = self._enter_create(value, createdtime)
2023-03-01 14:08:37.420257 2023-03-01 14:08:37.413 35 ERROR keystone.server.flask.application   File "/var/lib/kolla/venv/lib/python3.9/site-packages/dogpile/lock.py", line 178, in _enter_create
2023-03-01 14:08:37.420266 2023-03-01 14:08:37.413 35 ERROR keystone.server.flask.application     return self.creator()
2023-03-01 14:08:37.420275 2023-03-01 14:08:37.413 35 ERROR keystone.server.flask.application   File "/var/lib/kolla/venv/lib/python3.9/site-packages/dogpile/cache/region.py", line 995, in gen_value
2023-03-01 14:08:37.420302 2023-03-01 14:08:37.413 35 ERROR keystone.server.flask.application     created_value = creator(
2023-03-01 14:08:37.420314 2023-03-01 14:08:37.413 35 ERROR keystone.server.flask.application   File "/var/lib/kolla/venv/lib/python3.9/site-packages/keystone/assignment/core.py", line 1276, in get_role
2023-03-01 14:08:37.420323 2023-03-01 14:08:37.413 35 ERROR keystone.server.flask.application     return self.driver.get_role(role_id)
2023-03-01 14:08:37.420332 2023-03-01 14:08:37.413 35 ERROR keystone.server.flask.application   File "/var/lib/kolla/venv/lib/python3.9/site-packages/keystone/assignment/role_backends/sql.py", line 70, in get_role
2023-03-01 14:08:37.420365 2023-03-01 14:08:37.413 35 ERROR keystone.server.flask.application     return self._get_role(session, role_id).to_dict()
2023-03-01 14:08:37.420389 2023-03-01 14:08:37.413 35 ERROR keystone.server.flask.application   File "/var/lib/kolla/venv/lib/python3.9/site-packages/keystone/assignment/role_backends/sql.py", line 65, in _get_role
2023-03-01 14:08:37.420412 2023-03-01 14:08:37.413 35 ERROR keystone.server.flask.application     raise exception.RoleNotFound(role_id=role_id)
2023-03-01 14:08:37.420430 2023-03-01 14:08:37.413 35 ERROR keystone.server.flask.application keystone.exception.RoleNotFound: Could not find role: admin.
2023-03-01 14:08:37.420443 2023-03-01 14:08:37.413 35 ERROR keystone.server.flask.application \x1b[00m
2023-03-01 14:08:38.557845 2023-03-01 14:08:38.551 35 ERROR keystone.server.flask.application [None req-9d60cff6-bfdf-4cab-9fee-91b8c634372b 4948d33173d947e3973c5cf5740ec4cb - - all default -] Could not find user: ironic.: keystone.exception.UserNotFound: Could not find user: ironic.
2023-03-01 14:08:38.557888 2023-03-01 14:08:38.551 35 ERROR keystone.server.flask.application Traceback (most recent call last):
2023-03-01 14:08:38.557900 2023-03-01 14:08:38.551 35 ERROR keystone.server.flask.application   File "/var/lib/kolla/venv/lib/python3.9/site-packages/flask/app.py", line 1820, in full_dispatch_request
2023-03-01 14:08:38.557910 2023-03-01 14:08:38.551 35 ERROR keystone.server.flask.application     rv = self.dispatch_request()
2023-03-01 14:08:38.557920 2023-03-01 14:08:38.551 35 ERROR keystone.server.flask.application   File "/var/lib/kolla/venv/lib/python3.9/site-packages/flask/app.py", line 1796, in dispatch_request
2023-03-01 14:08:38.557930 2023-03-01 14:08:38.551 35 ERROR keystone.server.flask.application     return self.ensure_sync(self.view_functions[rule.endpoint])(**view_args)
2023-03-01 14:08:38.557963 2023-03-01 14:08:38.551 35 ERROR keystone.server.flask.application   File "/var/lib/kolla/venv/lib/python3.9/site-packages/flask_restful/__init__.py", line 467, in wrapper
2023-03-01 14:08:38.557973 2023-03-01 14:08:38.551 35 ERROR keystone.server.flask.application     resp = resource(*args, **kwargs)
2023-03-01 14:08:38.558013 2023-03-01 14:08:38.551 35 ERROR keystone.server.flask.application   File "/var/lib/kolla/venv/lib/python3.9/site-packages/flask/views.py", line 107, in view
2023-03-01 14:08:38.558023 2023-03-01 14:08:38.551 35 ERROR keystone.server.flask.application     return current_app.ensure_sync(self.dispatch_request)(**kwargs)
2023-03-01 14:08:38.558032 2023-03-01 14:08:38.551 35 ERROR keystone.server.flask.application   File "/var/lib/kolla/venv/lib/python3.9/site-packages/flask_restful/__init__.py", line 582, in dispatch_request
2023-03-01 14:08:38.558042 2023-03-01 14:08:38.551 35 ERROR keystone.server.flask.application     resp = meth(*args, **kwargs)
2023-03-01 14:08:38.558051 2023-03-01 14:08:38.551 35 ERROR keystone.server.flask.application   File "/var/lib/kolla/venv/lib/python3.9/site-packages/keystone/api/users.py", line 182, in get
2023-03-01 14:08:38.558060 2023-03-01 14:08:38.551 35 ERROR keystone.server.flask.application     return self._get_user(user_id)
2023-03-01 14:08:38.558070 2023-03-01 14:08:38.551 35 ERROR keystone.server.flask.application   File "/var/lib/kolla/venv/lib/python3.9/site-packages/keystone/api/users.py", line 194, in _get_user
2023-03-01 14:08:38.558111 2023-03-01 14:08:38.551 35 ERROR keystone.server.flask.application     ref = PROVIDERS.identity_api.get_user(user_id)
2023-03-01 14:08:38.558124 2023-03-01 14:08:38.551 35 ERROR keystone.server.flask.application   File "/var/lib/kolla/venv/lib/python3.9/site-packages/keystone/common/manager.py", line 115, in wrapped
2023-03-01 14:08:38.558133 2023-03-01 14:08:38.551 35 ERROR keystone.server.flask.application     __ret_val = __f(*args, **kwargs)
2023-03-01 14:08:38.558143 2023-03-01 14:08:38.551 35 ERROR keystone.server.flask.application   File "/var/lib/kolla/venv/lib/python3.9/site-packages/keystone/identity/core.py", line 414, in wrapper
2023-03-01 14:08:38.558152 2023-03-01 14:08:38.551 35 ERROR keystone.server.flask.application     return f(self, *args, **kwargs)
2023-03-01 14:08:38.558161 2023-03-01 14:08:38.551 35 ERROR keystone.server.flask.application   File "/var/lib/kolla/venv/lib/python3.9/site-packages/keystone/identity/core.py", line 424, in wrapper
2023-03-01 14:08:38.558171 2023-03-01 14:08:38.551 35 ERROR keystone.server.flask.application     return f(self, *args, **kwargs)
2023-03-01 14:08:38.558180 2023-03-01 14:08:38.551 35 ERROR keystone.server.flask.application   File "/var/lib/kolla/venv/lib/python3.9/site-packages/decorator.py", line 232, in fun
2023-03-01 14:08:38.558189 2023-03-01 14:08:38.551 35 ERROR keystone.server.flask.application     return caller(func, *(extras + args), **kw)
2023-03-01 14:08:38.558199 2023-03-01 14:08:38.551 35 ERROR keystone.server.flask.application   File "/var/lib/kolla/venv/lib/python3.9/site-packages/dogpile/cache/region.py", line 1577, in get_or_create_for_user_func
2023-03-01 14:08:38.558209 2023-03-01 14:08:38.551 35 ERROR keystone.server.flask.application     return self.get_or_create(
2023-03-01 14:08:38.558225 2023-03-01 14:08:38.551 35 ERROR keystone.server.flask.application   File "/var/lib/kolla/venv/lib/python3.9/site-packages/dogpile/cache/region.py", line 1042, in get_or_create
2023-03-01 14:08:38.558235 2023-03-01 14:08:38.551 35 ERROR keystone.server.flask.application     with Lock(
2023-03-01 14:08:38.558244 2023-03-01 14:08:38.551 35 ERROR keystone.server.flask.application   File "/var/lib/kolla/venv/lib/python3.9/site-packages/dogpile/lock.py", line 185, in __enter__
2023-03-01 14:08:38.558253 2023-03-01 14:08:38.551 35 ERROR keystone.server.flask.application     return self._enter()
2023-03-01 14:08:38.558262 2023-03-01 14:08:38.551 35 ERROR keystone.server.flask.application   File "/var/lib/kolla/venv/lib/python3.9/site-packages/dogpile/lock.py", line 94, in _enter
2023-03-01 14:08:38.558272 2023-03-01 14:08:38.551 35 ERROR keystone.server.flask.application     generated = self._enter_create(value, createdtime)
2023-03-01 14:08:38.558281 2023-03-01 14:08:38.551 35 ERROR keystone.server.flask.application   File "/var/lib/kolla/venv/lib/python3.9/site-packages/dogpile/lock.py", line 178, in _enter_create
2023-03-01 14:08:38.558291 2023-03-01 14:08:38.551 35 ERROR keystone.server.flask.application     return self.creator()
2023-03-01 14:08:38.558300 2023-03-01 14:08:38.551 35 ERROR keystone.server.flask.application   File "/var/lib/kolla/venv/lib/python3.9/site-packages/dogpile/cache/region.py", line 995, in gen_value
2023-03-01 14:08:38.558310 2023-03-01 14:08:38.551 35 ERROR keystone.server.flask.application     created_value = creator(
2023-03-01 14:08:38.558319 2023-03-01 14:08:38.551 35 ERROR keystone.server.flask.application   File "/var/lib/kolla/venv/lib/python3.9/site-packages/keystone/identity/core.py", line 1011, in get_user
2023-03-01 14:08:38.558329 2023-03-01 14:08:38.551 35 ERROR keystone.server.flask.application     ref = driver.get_user(entity_id)
2023-03-01 14:08:38.558338 2023-03-01 14:08:38.551 35 ERROR keystone.server.flask.application   File "/var/lib/kolla/venv/lib/python3.9/site-packages/keystone/identity/backends/sql.py", line 200, in get_user
2023-03-01 14:08:38.558408 2023-03-01 14:08:38.551 35 ERROR keystone.server.flask.application     self._get_user(session, user_id).to_dict())
2023-03-01 14:08:38.558442 2023-03-01 14:08:38.551 35 ERROR keystone.server.flask.application   File "/var/lib/kolla/venv/lib/python3.9/site-packages/keystone/identity/backends/sql.py", line 194, in _get_user
2023-03-01 14:08:38.558455 2023-03-01 14:08:38.551 35 ERROR keystone.server.flask.application     raise exception.UserNotFound(user_id=user_id)
2023-03-01 14:08:38.558464 2023-03-01 14:08:38.551 35 ERROR keystone.server.flask.application keystone.exception.UserNotFound: Could not find user: ironic.
2023-03-01 14:08:38.558474 2023-03-01 14:08:38.551 35 ERROR keystone.server.flask.application \x1b[00m
2023-03-01 14:08:39.505973 2023-03-01 14:08:39.493 34 ERROR keystone.server.flask.application [None req-06e93c78-830b-40ca-9093-d6dadbc7f831 4948d33173d947e3973c5cf5740ec4cb - - all default -] Could not find project: service.: keystone.exception.ProjectNotFound: Could not find project: service.
2023-03-01 14:08:39.506015 2023-03-01 14:08:39.493 34 ERROR keystone.server.flask.application Traceback (most recent call last):
2023-03-01 14:08:39.506027 2023-03-01 14:08:39.493 34 ERROR keystone.server.flask.application   File "/var/lib/kolla/venv/lib/python3.9/site-packages/flask/app.py", line 1820, in full_dispatch_request
2023-03-01 14:08:39.506037 2023-03-01 14:08:39.493 34 ERROR keystone.server.flask.application     rv = self.dispatch_request()
2023-03-01 14:08:39.506046 2023-03-01 14:08:39.493 34 ERROR keystone.server.flask.application   File "/var/lib/kolla/venv/lib/python3.9/site-packages/flask/app.py", line 1796, in dispatch_request
2023-03-01 14:08:39.506057 2023-03-01 14:08:39.493 34 ERROR keystone.server.flask.application     return self.ensure_sync(self.view_functions[rule.endpoint])(**view_args)
2023-03-01 14:08:39.506066 2023-03-01 14:08:39.493 34 ERROR keystone.server.flask.application   File "/var/lib/kolla/venv/lib/python3.9/site-packages/flask_restful/__init__.py", line 467, in wrapper
2023-03-01 14:08:39.506076 2023-03-01 14:08:39.493 34 ERROR keystone.server.flask.application     resp = resource(*args, **kwargs)
2023-03-01 14:08:39.506093 2023-03-01 14:08:39.493 34 ERROR keystone.server.flask.application   File "/var/lib/kolla/venv/lib/python3.9/site-packages/flask/views.py", line 107, in view
2023-03-01 14:08:39.506110 2023-03-01 14:08:39.493 34 ERROR keystone.server.flask.application     return current_app.ensure_sync(self.dispatch_request)(**kwargs)
2023-03-01 14:08:39.506121 2023-03-01 14:08:39.493 34 ERROR keystone.server.flask.application   File "/var/lib/kolla/venv/lib/python3.9/site-packages/flask_restful/__init__.py", line 582, in dispatch_request
2023-03-01 14:08:39.506131 2023-03-01 14:08:39.493 34 ERROR keystone.server.flask.application     resp = meth(*args, **kwargs)
2023-03-01 14:08:39.506141 2023-03-01 14:08:39.493 34 ERROR keystone.server.flask.application   File "/var/lib/kolla/venv/lib/python3.9/site-packages/keystone/api/projects.py", line 151, in get
2023-03-01 14:08:39.506150 2023-03-01 14:08:39.493 34 ERROR keystone.server.flask.application     return self._get_project(project_id)
2023-03-01 14:08:39.506160 2023-03-01 14:08:39.493 34 ERROR keystone.server.flask.application   File "/var/lib/kolla/venv/lib/python3.9/site-packages/keystone/api/projects.py", line 107, in _get_project
2023-03-01 14:08:39.506170 2023-03-01 14:08:39.493 34 ERROR keystone.server.flask.application     project = PROVIDERS.resource_api.get_project(project_id)
2023-03-01 14:08:39.506200 2023-03-01 14:08:39.493 34 ERROR keystone.server.flask.application   File "/var/lib/kolla/venv/lib/python3.9/site-packages/keystone/common/manager.py", line 115, in wrapped
2023-03-01 14:08:39.506252 2023-03-01 14:08:39.493 34 ERROR keystone.server.flask.application     __ret_val = __f(*args, **kwargs)
2023-03-01 14:08:39.506262 2023-03-01 14:08:39.493 34 ERROR keystone.server.flask.application   File "/var/lib/kolla/venv/lib/python3.9/site-packages/decorator.py", line 232, in fun
2023-03-01 14:08:39.506271 2023-03-01 14:08:39.493 34 ERROR keystone.server.flask.application     return caller(func, *(extras + args), **kw)
2023-03-01 14:08:39.506310 2023-03-01 14:08:39.493 34 ERROR keystone.server.flask.application   File "/var/lib/kolla/venv/lib/python3.9/site-packages/dogpile/cache/region.py", line 1577, in get_or_create_for_user_func
2023-03-01 14:08:39.506322 2023-03-01 14:08:39.493 34 ERROR keystone.server.flask.application     return self.get_or_create(
2023-03-01 14:08:39.506332 2023-03-01 14:08:39.493 34 ERROR keystone.server.flask.application   File "/var/lib/kolla/venv/lib/python3.9/site-packages/dogpile/cache/region.py", line 1042, in get_or_create
2023-03-01 14:08:39.506377 2023-03-01 14:08:39.493 34 ERROR keystone.server.flask.application     with Lock(
2023-03-01 14:08:39.506393 2023-03-01 14:08:39.493 34 ERROR keystone.server.flask.application   File "/var/lib/kolla/venv/lib/python3.9/site-packages/dogpile/lock.py", line 185, in __enter__
2023-03-01 14:08:39.506404 2023-03-01 14:08:39.493 34 ERROR keystone.server.flask.application     return self._enter()
2023-03-01 14:08:39.506413 2023-03-01 14:08:39.493 34 ERROR keystone.server.flask.application   File "/var/lib/kolla/venv/lib/python3.9/site-packages/dogpile/lock.py", line 94, in _enter
2023-03-01 14:08:39.506423 2023-03-01 14:08:39.493 34 ERROR keystone.server.flask.application     generated = self._enter_create(value, createdtime)
2023-03-01 14:08:39.506432 2023-03-01 14:08:39.493 34 ERROR keystone.server.flask.application   File "/var/lib/kolla/venv/lib/python3.9/site-packages/dogpile/lock.py", line 178, in _enter_create
2023-03-01 14:08:39.506442 2023-03-01 14:08:39.493 34 ERROR keystone.server.flask.application     return self.creator()
2023-03-01 14:08:39.506451 2023-03-01 14:08:39.493 34 ERROR keystone.server.flask.application   File "/var/lib/kolla/venv/lib/python3.9/site-packages/dogpile/cache/region.py", line 995, in gen_value
2023-03-01 14:08:39.506461 2023-03-01 14:08:39.493 34 ERROR keystone.server.flask.application     created_value = creator(
2023-03-01 14:08:39.506470 2023-03-01 14:08:39.493 34 ERROR keystone.server.flask.application   File "/var/lib/kolla/venv/lib/python3.9/site-packages/keystone/resource/core.py", line 903, in get_project
2023-03-01 14:08:39.506480 2023-03-01 14:08:39.493 34 ERROR keystone.server.flask.application     return self.driver.get_project(project_id)
2023-03-01 14:08:39.506489 2023-03-01 14:08:39.493 34 ERROR keystone.server.flask.application   File "/var/lib/kolla/venv/lib/python3.9/site-packages/keystone/resource/backends/sql.py", line 49, in get_project
2023-03-01 14:08:39.506499 2023-03-01 14:08:39.493 34 ERROR keystone.server.flask.application     return self._get_project(session, project_id).to_dict()
2023-03-01 14:08:39.506508 2023-03-01 14:08:39.493 34 ERROR keystone.server.flask.application   File "/var/lib/kolla/venv/lib/python3.9/site-packages/keystone/resource/backends/sql.py", line 44, in _get_project
2023-03-01 14:08:39.506518 2023-03-01 14:08:39.493 34 ERROR keystone.server.flask.application     raise exception.ProjectNotFound(project_id=project_id)
2023-03-01 14:08:39.506527 2023-03-01 14:08:39.493 34 ERROR keystone.server.flask.application keystone.exception.ProjectNotFound: Could not find project: service.
2023-03-01 14:08:39.506538 2023-03-01 14:08:39.493 34 ERROR keystone.server.flask.application \x1b[00m
2023-03-01 14:08:49.569818 2023-03-01 14:08:49.563 33 ERROR keystone.server.flask.application [None req-5d0ad248-99c5-4b94-a335-7add0e67d9b1 4948d33173d947e3973c5cf5740ec4cb - - all default -] Could not find role: admin.: keystone.exception.RoleNotFound: Could not find role: admin.
2023-03-01 14:08:49.569875 2023-03-01 14:08:49.563 33 ERROR keystone.server.flask.application Traceback (most recent call last):
2023-03-01 14:08:49.569900 2023-03-01 14:08:49.563 33 ERROR keystone.server.flask.application   File "/var/lib/kolla/venv/lib/python3.9/site-packages/flask/app.py", line 1820, in full_dispatch_request
2023-03-01 14:08:49.569922 2023-03-01 14:08:49.563 33 ERROR keystone.server.flask.application     rv = self.dispatch_request()
2023-03-01 14:08:49.569943 2023-03-01 14:08:49.563 33 ERROR keystone.server.flask.application   File "/var/lib/kolla/venv/lib/python3.9/site-packages/flask/app.py", line 1796, in dispatch_request
2023-03-01 14:08:49.569981 2023-03-01 14:08:49.563 33 ERROR keystone.server.flask.application     return self.ensure_sync(self.view_functions[rule.endpoint])(**view_args)
2023-03-01 14:08:49.570004 2023-03-01 14:08:49.563 33 ERROR keystone.server.flask.application   File "/var/lib/kolla/venv/lib/python3.9/site-packages/flask_restful/__init__.py", line 467, in wrapper
2023-03-01 14:08:49.570026 2023-03-01 14:08:49.563 33 ERROR keystone.server.flask.application     resp = resource(*args, **kwargs)
2023-03-01 14:08:49.570082 2023-03-01 14:08:49.563 33 ERROR keystone.server.flask.application   File "/var/lib/kolla/venv/lib/python3.9/site-packages/flask/views.py", line 107, in view
2023-03-01 14:08:49.570102 2023-03-01 14:08:49.563 33 ERROR keystone.server.flask.application     return current_app.ensure_sync(self.dispatch_request)(**kwargs)
2023-03-01 14:08:49.570112 2023-03-01 14:08:49.563 33 ERROR keystone.server.flask.application   File "/var/lib/kolla/venv/lib/python3.9/site-packages/flask_restful/__init__.py", line 582, in dispatch_request
2023-03-01 14:08:49.570121 2023-03-01 14:08:49.563 33 ERROR keystone.server.flask.application     resp = meth(*args, **kwargs)
2023-03-01 14:08:49.570130 2023-03-01 14:08:49.563 33 ERROR keystone.server.flask.application   File "/var/lib/kolla/venv/lib/python3.9/site-packages/keystone/api/roles.py", line 50, in get
2023-03-01 14:08:49.570140 2023-03-01 14:08:49.563 33 ERROR keystone.server.flask.application     return self._get_role(role_id)
2023-03-01 14:08:49.570149 2023-03-01 14:08:49.563 33 ERROR keystone.server.flask.application   File "/var/lib/kolla/venv/lib/python3.9/site-packages/keystone/api/roles.py", line 70, in _get_role
2023-03-01 14:08:49.570159 2023-03-01 14:08:49.563 33 ERROR keystone.server.flask.application     ENFORCER.enforce_call(action='identity:get_role')
2023-03-01 14:08:49.570169 2023-03-01 14:08:49.563 33 ERROR keystone.server.flask.application   File "/var/lib/kolla/venv/lib/python3.9/site-packages/keystone/common/rbac_enforcer/enforcer.py", line 402, in enforce_call
2023-03-01 14:08:49.570178 2023-03-01 14:08:49.563 33 ERROR keystone.server.flask.application     policy_dict.update(cls._extract_member_target_data(
2023-03-01 14:08:49.570194 2023-03-01 14:08:49.563 33 ERROR keystone.server.flask.application   File "/var/lib/kolla/venv/lib/python3.9/site-packages/keystone/common/rbac_enforcer/enforcer.py", line 234, in _extract_member_target_data
2023-03-01 14:08:49.570207 2023-03-01 14:08:49.563 33 ERROR keystone.server.flask.application     member_name: func(flask.request.view_args[key])
2023-03-01 14:08:49.570216 2023-03-01 14:08:49.563 33 ERROR keystone.server.flask.application   File "/var/lib/kolla/venv/lib/python3.9/site-packages/keystone/common/manager.py", line 115, in wrapped
2023-03-01 14:08:49.570226 2023-03-01 14:08:49.563 33 ERROR keystone.server.flask.application     __ret_val = __f(*args, **kwargs)
2023-03-01 14:08:49.570235 2023-03-01 14:08:49.563 33 ERROR keystone.server.flask.application   File "/var/lib/kolla/venv/lib/python3.9/site-packages/decorator.py", line 232, in fun
2023-03-01 14:08:49.570244 2023-03-01 14:08:49.563 33 ERROR keystone.server.flask.application     return caller(func, *(extras + args), **kw)
2023-03-01 14:08:49.570253 2023-03-01 14:08:49.563 33 ERROR keystone.server.flask.application   File "/var/lib/kolla/venv/lib/python3.9/site-packages/dogpile/cache/region.py", line 1577, in get_or_create_for_user_func
2023-03-01 14:08:49.570263 2023-03-01 14:08:49.563 33 ERROR keystone.server.flask.application     return self.get_or_create(
2023-03-01 14:08:49.570272 2023-03-01 14:08:49.563 33 ERROR keystone.server.flask.application   File "/var/lib/kolla/venv/lib/python3.9/site-packages/dogpile/cache/region.py", line 1042, in get_or_create
2023-03-01 14:08:49.570282 2023-03-01 14:08:49.563 33 ERROR keystone.server.flask.application     with Lock(
2023-03-01 14:08:49.570304 2023-03-01 14:08:49.563 33 ERROR keystone.server.flask.application   File "/var/lib/kolla/venv/lib/python3.9/site-packages/dogpile/lock.py", line 185, in __enter__
2023-03-01 14:08:49.570315 2023-03-01 14:08:49.563 33 ERROR keystone.server.flask.application     return self._enter()
2023-03-01 14:08:49.570324 2023-03-01 14:08:49.563 33 ERROR keystone.server.flask.application   File "/var/lib/kolla/venv/lib/python3.9/site-packages/dogpile/lock.py", line 94, in _enter
2023-03-01 14:08:49.570333 2023-03-01 14:08:49.563 33 ERROR keystone.server.flask.application     generated = self._enter_create(value, createdtime)
2023-03-01 14:08:49.570375 2023-03-01 14:08:49.563 33 ERROR keystone.server.flask.application   File "/var/lib/kolla/venv/lib/python3.9/site-packages/dogpile/lock.py", line 178, in _enter_create
2023-03-01 14:08:49.570391 2023-03-01 14:08:49.563 33 ERROR keystone.server.flask.application     return self.creator()
2023-03-01 14:08:49.570401 2023-03-01 14:08:49.563 33 ERROR keystone.server.flask.application   File "/var/lib/kolla/venv/lib/python3.9/site-packages/dogpile/cache/region.py", line 995, in gen_value
2023-03-01 14:08:49.570410 2023-03-01 14:08:49.563 33 ERROR keystone.server.flask.application     created_value = creator(
2023-03-01 14:08:49.570420 2023-03-01 14:08:49.563 33 ERROR keystone.server.flask.application   File "/var/lib/kolla/venv/lib/python3.9/site-packages/keystone/assignment/core.py", line 1276, in get_role
2023-03-01 14:08:49.570429 2023-03-01 14:08:49.563 33 ERROR keystone.server.flask.application     return self.driver.get_role(role_id)
2023-03-01 14:08:49.570441 2023-03-01 14:08:49.563 33 ERROR keystone.server.flask.application   File "/var/lib/kolla/venv/lib/python3.9/site-packages/keystone/assignment/role_backends/sql.py", line 70, in get_role
2023-03-01 14:08:49.570460 2023-03-01 14:08:49.563 33 ERROR keystone.server.flask.application     return self._get_role(session, role_id).to_dict()
2023-03-01 14:08:49.570479 2023-03-01 14:08:49.563 33 ERROR keystone.server.flask.application   File "/var/lib/kolla/venv/lib/python3.9/site-packages/keystone/assignment/role_backends/sql.py", line 65, in _get_role
2023-03-01 14:08:49.570499 2023-03-01 14:08:49.563 33 ERROR keystone.server.flask.application     raise exception.RoleNotFound(role_id=role_id)
2023-03-01 14:08:49.570518 2023-03-01 14:08:49.563 33 ERROR keystone.server.flask.application keystone.exception.RoleNotFound: Could not find role: admin.
2023-03-01 14:08:49.570536 2023-03-01 14:08:49.563 33 ERROR keystone.server.flask.application \x1b[00m
2023-03-01 14:08:50.828110 2023-03-01 14:08:50.821 33 ERROR keystone.server.flask.application [None req-809b8be1-d7e2-4da9-b687-ccb9e2669c2c 4948d33173d947e3973c5cf5740ec4cb - - all default -] Could not find user: ironic-inspector.: keystone.exception.UserNotFound: Could not find user: ironic-inspector.
2023-03-01 14:08:50.828168 2023-03-01 14:08:50.821 33 ERROR keystone.server.flask.application Traceback (most recent call last):
2023-03-01 14:08:50.828179 2023-03-01 14:08:50.821 33 ERROR keystone.server.flask.application   File "/var/lib/kolla/venv/lib/python3.9/site-packages/flask/app.py", line 1820, in full_dispatch_request
2023-03-01 14:08:50.828189 2023-03-01 14:08:50.821 33 ERROR keystone.server.flask.application     rv = self.dispatch_request()
2023-03-01 14:08:50.828198 2023-03-01 14:08:50.821 33 ERROR keystone.server.flask.application   File "/var/lib/kolla/venv/lib/python3.9/site-packages/flask/app.py", line 1796, in dispatch_request
2023-03-01 14:08:50.828208 2023-03-01 14:08:50.821 33 ERROR keystone.server.flask.application     return self.ensure_sync(self.view_functions[rule.endpoint])(**view_args)
2023-03-01 14:08:50.828218 2023-03-01 14:08:50.821 33 ERROR keystone.server.flask.application   File "/var/lib/kolla/venv/lib/python3.9/site-packages/flask_restful/__init__.py", line 467, in wrapper
2023-03-01 14:08:50.828227 2023-03-01 14:08:50.821 33 ERROR keystone.server.flask.application     resp = resource(*args, **kwargs)
2023-03-01 14:08:50.828237 2023-03-01 14:08:50.821 33 ERROR keystone.server.flask.application   File "/var/lib/kolla/venv/lib/python3.9/site-packages/flask/views.py", line 107, in view
2023-03-01 14:08:50.828262 2023-03-01 14:08:50.821 33 ERROR keystone.server.flask.application     return current_app.ensure_sync(self.dispatch_request)(**kwargs)
2023-03-01 14:08:50.828274 2023-03-01 14:08:50.821 33 ERROR keystone.server.flask.application   File "/var/lib/kolla/venv/lib/python3.9/site-packages/flask_restful/__init__.py", line 582, in dispatch_request
2023-03-01 14:08:50.828283 2023-03-01 14:08:50.821 33 ERROR keystone.server.flask.application     resp = meth(*args, **kwargs)
2023-03-01 14:08:50.828293 2023-03-01 14:08:50.821 33 ERROR keystone.server.flask.application   File "/var/lib/kolla/venv/lib/python3.9/site-packages/keystone/api/users.py", line 182, in get
2023-03-01 14:08:50.828302 2023-03-01 14:08:50.821 33 ERROR keystone.server.flask.application     return self._get_user(user_id)
2023-03-01 14:08:50.828312 2023-03-01 14:08:50.821 33 ERROR keystone.server.flask.application   File "/var/lib/kolla/venv/lib/python3.9/site-packages/keystone/api/users.py", line 194, in _get_user
2023-03-01 14:08:50.828322 2023-03-01 14:08:50.821 33 ERROR keystone.server.flask.application     ref = PROVIDERS.identity_api.get_user(user_id)
2023-03-01 14:08:50.828331 2023-03-01 14:08:50.821 33 ERROR keystone.server.flask.application   File "/var/lib/kolla/venv/lib/python3.9/site-packages/keystone/common/manager.py", line 115, in wrapped
2023-03-01 14:08:50.828521 2023-03-01 14:08:50.821 33 ERROR keystone.server.flask.application     __ret_val = __f(*args, **kwargs)
2023-03-01 14:08:50.828543 2023-03-01 14:08:50.821 33 ERROR keystone.server.flask.application   File "/var/lib/kolla/venv/lib/python3.9/site-packages/keystone/identity/core.py", line 414, in wrapper
2023-03-01 14:08:50.828553 2023-03-01 14:08:50.821 33 ERROR keystone.server.flask.application     return f(self, *args, **kwargs)
2023-03-01 14:08:50.828562 2023-03-01 14:08:50.821 33 ERROR keystone.server.flask.application   File "/var/lib/kolla/venv/lib/python3.9/site-packages/keystone/identity/core.py", line 424, in wrapper
2023-03-01 14:08:50.828572 2023-03-01 14:08:50.821 33 ERROR keystone.server.flask.application     return f(self, *args, **kwargs)
2023-03-01 14:08:50.828581 2023-03-01 14:08:50.821 33 ERROR keystone.server.flask.application   File "/var/lib/kolla/venv/lib/python3.9/site-packages/decorator.py", line 232, in fun
2023-03-01 14:08:50.828590 2023-03-01 14:08:50.821 33 ERROR keystone.server.flask.application     return caller(func, *(extras + args), **kw)
2023-03-01 14:08:50.828600 2023-03-01 14:08:50.821 33 ERROR keystone.server.flask.application   File "/var/lib/kolla/venv/lib/python3.9/site-packages/dogpile/cache/region.py", line 1577, in get_or_create_for_user_func
2023-03-01 14:08:50.828609 2023-03-01 14:08:50.821 33 ERROR keystone.server.flask.application     return self.get_or_create(
2023-03-01 14:08:50.828619 2023-03-01 14:08:50.821 33 ERROR keystone.server.flask.application   File "/var/lib/kolla/venv/lib/python3.9/site-packages/dogpile/cache/region.py", line 1042, in get_or_create
2023-03-01 14:08:50.828628 2023-03-01 14:08:50.821 33 ERROR keystone.server.flask.application     with Lock(
2023-03-01 14:08:50.828637 2023-03-01 14:08:50.821 33 ERROR keystone.server.flask.application   File "/var/lib/kolla/venv/lib/python3.9/site-packages/dogpile/lock.py", line 185, in __enter__
2023-03-01 14:08:50.828647 2023-03-01 14:08:50.821 33 ERROR keystone.server.flask.application     return self._enter()
2023-03-01 14:08:50.828656 2023-03-01 14:08:50.821 33 ERROR keystone.server.flask.application   File "/var/lib/kolla/venv/lib/python3.9/site-packages/dogpile/lock.py", line 94, in _enter
2023-03-01 14:08:50.828665 2023-03-01 14:08:50.821 33 ERROR keystone.server.flask.application     generated = self._enter_create(value, createdtime)
2023-03-01 14:08:50.828676 2023-03-01 14:08:50.821 33 ERROR keystone.server.flask.application   File "/var/lib/kolla/venv/lib/python3.9/site-packages/dogpile/lock.py", line 178, in _enter_create
2023-03-01 14:08:50.828721 2023-03-01 14:08:50.821 33 ERROR keystone.server.flask.application     return self.creator()
2023-03-01 14:08:50.828738 2023-03-01 14:08:50.821 33 ERROR keystone.server.flask.application   File "/var/lib/kolla/venv/lib/python3.9/site-packages/dogpile/cache/region.py", line 995, in gen_value
2023-03-01 14:08:50.828748 2023-03-01 14:08:50.821 33 ERROR keystone.server.flask.application     created_value = creator(
2023-03-01 14:08:50.828757 2023-03-01 14:08:50.821 33 ERROR keystone.server.flask.application   File "/var/lib/kolla/venv/lib/python3.9/site-packages/keystone/identity/core.py", line 1011, in get_user
2023-03-01 14:08:50.828767 2023-03-01 14:08:50.821 33 ERROR keystone.server.flask.application     ref = driver.get_user(entity_id)
2023-03-01 14:08:50.828776 2023-03-01 14:08:50.821 33 ERROR keystone.server.flask.application   File "/var/lib/kolla/venv/lib/python3.9/site-packages/keystone/identity/backends/sql.py", line 200, in get_user
2023-03-01 14:08:50.828786 2023-03-01 14:08:50.821 33 ERROR keystone.server.flask.application     self._get_user(session, user_id).to_dict())
2023-03-01 14:08:50.828795 2023-03-01 14:08:50.821 33 ERROR keystone.server.flask.application   File "/var/lib/kolla/venv/lib/python3.9/site-packages/keystone/identity/backends/sql.py", line 194, in _get_user
2023-03-01 14:08:50.828804 2023-03-01 14:08:50.821 33 ERROR keystone.server.flask.application     raise exception.UserNotFound(user_id=user_id)
2023-03-01 14:08:50.828814 2023-03-01 14:08:50.821 33 ERROR keystone.server.flask.application keystone.exception.UserNotFound: Could not find user: ironic-inspector.
2023-03-01 14:08:50.828823 2023-03-01 14:08:50.821 33 ERROR keystone.server.flask.application \x1b[00m
2023-03-01 14:08:51.670028 2023-03-01 14:08:51.666 35 ERROR keystone.server.flask.application [None req-80f6ff7b-d3a1-4b32-a899-9b9d73bad47e 4948d33173d947e3973c5cf5740ec4cb - - all default -] Could not find project: service.: keystone.exception.ProjectNotFound: Could not find project: service.
2023-03-01 14:08:51.670095 2023-03-01 14:08:51.666 35 ERROR keystone.server.flask.application Traceback (most recent call last):
2023-03-01 14:08:51.670107 2023-03-01 14:08:51.666 35 ERROR keystone.server.flask.application   File "/var/lib/kolla/venv/lib/python3.9/site-packages/flask/app.py", line 1820, in full_dispatch_request
2023-03-01 14:08:51.670117 2023-03-01 14:08:51.666 35 ERROR keystone.server.flask.application     rv = self.dispatch_request()
2023-03-01 14:08:51.670126 2023-03-01 14:08:51.666 35 ERROR keystone.server.flask.application   File "/var/lib/kolla/venv/lib/python3.9/site-packages/flask/app.py", line 1796, in dispatch_request
2023-03-01 14:08:51.670136 2023-03-01 14:08:51.666 35 ERROR keystone.server.flask.application     return self.ensure_sync(self.view_functions[rule.endpoint])(**view_args)
2023-03-01 14:08:51.670146 2023-03-01 14:08:51.666 35 ERROR keystone.server.flask.application   File "/var/lib/kolla/venv/lib/python3.9/site-packages/flask_restful/__init__.py", line 467, in wrapper
2023-03-01 14:08:51.670155 2023-03-01 14:08:51.666 35 ERROR keystone.server.flask.application     resp = resource(*args, **kwargs)
2023-03-01 14:08:51.670165 2023-03-01 14:08:51.666 35 ERROR keystone.server.flask.application   File "/var/lib/kolla/venv/lib/python3.9/site-packages/flask/views.py", line 107, in view
2023-03-01 14:08:51.670175 2023-03-01 14:08:51.666 35 ERROR keystone.server.flask.application     return current_app.ensure_sync(self.dispatch_request)(**kwargs)
2023-03-01 14:08:51.670184 2023-03-01 14:08:51.666 35 ERROR keystone.server.flask.application   File "/var/lib/kolla/venv/lib/python3.9/site-packages/flask_restful/__init__.py", line 582, in dispatch_request
2023-03-01 14:08:51.670194 2023-03-01 14:08:51.666 35 ERROR keystone.server.flask.application     resp = meth(*args, **kwargs)
2023-03-01 14:08:51.670203 2023-03-01 14:08:51.666 35 ERROR keystone.server.flask.application   File "/var/lib/kolla/venv/lib/python3.9/site-packages/keystone/api/projects.py", line 151, in get
2023-03-01 14:08:51.670230 2023-03-01 14:08:51.666 35 ERROR keystone.server.flask.application     return self._get_project(project_id)
2023-03-01 14:08:51.670241 2023-03-01 14:08:51.666 35 ERROR keystone.server.flask.application   File "/var/lib/kolla/venv/lib/python3.9/site-packages/keystone/api/projects.py", line 107, in _get_project
2023-03-01 14:08:51.670251 2023-03-01 14:08:51.666 35 ERROR keystone.server.flask.application     project = PROVIDERS.resource_api.get_project(project_id)
2023-03-01 14:08:51.670261 2023-03-01 14:08:51.666 35 ERROR keystone.server.flask.application   File "/var/lib/kolla/venv/lib/python3.9/site-packages/keystone/common/manager.py", line 115, in wrapped
2023-03-01 14:08:51.670271 2023-03-01 14:08:51.666 35 ERROR keystone.server.flask.application     __ret_val = __f(*args, **kwargs)
2023-03-01 14:08:51.670280 2023-03-01 14:08:51.666 35 ERROR keystone.server.flask.application   File "/var/lib/kolla/venv/lib/python3.9/site-packages/decorator.py", line 232, in fun
2023-03-01 14:08:51.670290 2023-03-01 14:08:51.666 35 ERROR keystone.server.flask.application     return caller(func, *(extras + args), **kw)
2023-03-01 14:08:51.670300 2023-03-01 14:08:51.666 35 ERROR keystone.server.flask.application   File "/var/lib/kolla/venv/lib/python3.9/site-packages/dogpile/cache/region.py", line 1577, in get_or_create_for_user_func
2023-03-01 14:08:51.670310 2023-03-01 14:08:51.666 35 ERROR keystone.server.flask.application     return self.get_or_create(
2023-03-01 14:08:51.670319 2023-03-01 14:08:51.666 35 ERROR keystone.server.flask.application   File "/var/lib/kolla/venv/lib/python3.9/site-packages/dogpile/cache/region.py", line 1042, in get_or_create
2023-03-01 14:08:51.670339 2023-03-01 14:08:51.666 35 ERROR keystone.server.flask.application     with Lock(
2023-03-01 14:08:51.670378 2023-03-01 14:08:51.666 35 ERROR keystone.server.flask.application   File "/var/lib/kolla/venv/lib/python3.9/site-packages/dogpile/lock.py", line 185, in __enter__
2023-03-01 14:08:51.670389 2023-03-01 14:08:51.666 35 ERROR keystone.server.flask.application     return self._enter()
2023-03-01 14:08:51.670398 2023-03-01 14:08:51.666 35 ERROR keystone.server.flask.application   File "/var/lib/kolla/venv/lib/python3.9/site-packages/dogpile/lock.py", line 94, in _enter
2023-03-01 14:08:51.670407 2023-03-01 14:08:51.666 35 ERROR keystone.server.flask.application     generated = self._enter_create(value, createdtime)
2023-03-01 14:08:51.670417 2023-03-01 14:08:51.666 35 ERROR keystone.server.flask.application   File "/var/lib/kolla/venv/lib/python3.9/site-packages/dogpile/lock.py", line 178, in _enter_create
2023-03-01 14:08:51.670426 2023-03-01 14:08:51.666 35 ERROR keystone.server.flask.application     return self.creator()
2023-03-01 14:08:51.670436 2023-03-01 14:08:51.666 35 ERROR keystone.server.flask.application   File "/var/lib/kolla/venv/lib/python3.9/site-packages/dogpile/cache/region.py", line 995, in gen_value
2023-03-01 14:08:51.670446 2023-03-01 14:08:51.666 35 ERROR keystone.server.flask.application     created_value = creator(
2023-03-01 14:08:51.670455 2023-03-01 14:08:51.666 35 ERROR keystone.server.flask.application   File "/var/lib/kolla/venv/lib/python3.9/site-packages/keystone/resource/core.py", line 903, in get_project
2023-03-01 14:08:51.670464 2023-03-01 14:08:51.666 35 ERROR keystone.server.flask.application     return self.driver.get_project(project_id)
2023-03-01 14:08:51.670474 2023-03-01 14:08:51.666 35 ERROR keystone.server.flask.application   File "/var/lib/kolla/venv/lib/python3.9/site-packages/keystone/resource/backends/sql.py", line 49, in get_project
2023-03-01 14:08:51.670483 2023-03-01 14:08:51.666 35 ERROR keystone.server.flask.application     return self._get_project(session, project_id).to_dict()
2023-03-01 14:08:51.670493 2023-03-01 14:08:51.666 35 ERROR keystone.server.flask.application   File "/var/lib/kolla/venv/lib/python3.9/site-packages/keystone/resource/backends/sql.py", line 44, in _get_project
2023-03-01 14:08:51.670502 2023-03-01 14:08:51.666 35 ERROR keystone.server.flask.application     raise exception.ProjectNotFound(project_id=project_id)
2023-03-01 14:08:51.670523 2023-03-01 14:08:51.666 35 ERROR keystone.server.flask.application keystone.exception.ProjectNotFound: Could not find project: service.
2023-03-01 14:08:51.670534 2023-03-01 14:08:51.666 35 ERROR keystone.server.flask.application \x1b[00m
2023-03-01 14:11:48.039549 2023-03-01 14:11:48.036 33 ERROR keystone.server.flask.application [None req-67ae3e1c-c826-41f2-9b30-4fd2ceaa4272 4948d33173d947e3973c5cf5740ec4cb - - all default -] Could not find project: service.: keystone.exception.ProjectNotFound: Could not find project: service.
2023-03-01 14:11:48.039615 2023-03-01 14:11:48.036 33 ERROR keystone.server.flask.application Traceback (most recent call last):
2023-03-01 14:11:48.039627 2023-03-01 14:11:48.036 33 ERROR keystone.server.flask.application   File "/var/lib/kolla/venv/lib/python3.9/site-packages/flask/app.py", line 1820, in full_dispatch_request
2023-03-01 14:11:48.039637 2023-03-01 14:11:48.036 33 ERROR keystone.server.flask.application     rv = self.dispatch_request()
2023-03-01 14:11:48.039646 2023-03-01 14:11:48.036 33 ERROR keystone.server.flask.application   File "/var/lib/kolla/venv/lib/python3.9/site-packages/flask/app.py", line 1796, in dispatch_request
2023-03-01 14:11:48.039656 2023-03-01 14:11:48.036 33 ERROR keystone.server.flask.application     return self.ensure_sync(self.view_functions[rule.endpoint])(**view_args)
2023-03-01 14:11:48.039702 2023-03-01 14:11:48.036 33 ERROR keystone.server.flask.application   File "/var/lib/kolla/venv/lib/python3.9/site-packages/flask_restful/__init__.py", line 467, in wrapper
2023-03-01 14:11:48.039725 2023-03-01 14:11:48.036 33 ERROR keystone.server.flask.application     resp = resource(*args, **kwargs)
2023-03-01 14:11:48.039738 2023-03-01 14:11:48.036 33 ERROR keystone.server.flask.application   File "/var/lib/kolla/venv/lib/python3.9/site-packages/flask/views.py", line 107, in view
2023-03-01 14:11:48.039748 2023-03-01 14:11:48.036 33 ERROR keystone.server.flask.application     return current_app.ensure_sync(self.dispatch_request)(**kwargs)
2023-03-01 14:11:48.039757 2023-03-01 14:11:48.036 33 ERROR keystone.server.flask.application   File "/var/lib/kolla/venv/lib/python3.9/site-packages/flask_restful/__init__.py", line 582, in dispatch_request
2023-03-01 14:11:48.039767 2023-03-01 14:11:48.036 33 ERROR keystone.server.flask.application     resp = meth(*args, **kwargs)
2023-03-01 14:11:48.039776 2023-03-01 14:11:48.036 33 ERROR keystone.server.flask.application   File "/var/lib/kolla/venv/lib/python3.9/site-packages/keystone/api/projects.py", line 151, in get
2023-03-01 14:11:48.039785 2023-03-01 14:11:48.036 33 ERROR keystone.server.flask.application     return self._get_project(project_id)
2023-03-01 14:11:48.039794 2023-03-01 14:11:48.036 33 ERROR keystone.server.flask.application   File "/var/lib/kolla/venv/lib/python3.9/site-packages/keystone/api/projects.py", line 107, in _get_project
2023-03-01 14:11:48.039803 2023-03-01 14:11:48.036 33 ERROR keystone.server.flask.application     project = PROVIDERS.resource_api.get_project(project_id)
2023-03-01 14:11:48.039812 2023-03-01 14:11:48.036 33 ERROR keystone.server.flask.application   File "/var/lib/kolla/venv/lib/python3.9/site-packages/keystone/common/manager.py", line 115, in wrapped
2023-03-01 14:11:48.039822 2023-03-01 14:11:48.036 33 ERROR keystone.server.flask.application     __ret_val = __f(*args, **kwargs)
2023-03-01 14:11:48.039831 2023-03-01 14:11:48.036 33 ERROR keystone.server.flask.application   File "/var/lib/kolla/venv/lib/python3.9/site-packages/decorator.py", line 232, in fun
2023-03-01 14:11:48.039840 2023-03-01 14:11:48.036 33 ERROR keystone.server.flask.application     return caller(func, *(extras + args), **kw)
2023-03-01 14:11:48.039850 2023-03-01 14:11:48.036 33 ERROR keystone.server.flask.application   File "/var/lib/kolla/venv/lib/python3.9/site-packages/dogpile/cache/region.py", line 1577, in get_or_create_for_user_func
2023-03-01 14:11:48.039859 2023-03-01 14:11:48.036 33 ERROR keystone.server.flask.application     return self.get_or_create(
2023-03-01 14:11:48.039897 2023-03-01 14:11:48.036 33 ERROR keystone.server.flask.application   File "/var/lib/kolla/venv/lib/python3.9/site-packages/dogpile/cache/region.py", line 1042, in get_or_create
2023-03-01 14:11:48.039908 2023-03-01 14:11:48.036 33 ERROR keystone.server.flask.application     with Lock(
2023-03-01 14:11:48.039918 2023-03-01 14:11:48.036 33 ERROR keystone.server.flask.application   File "/var/lib/kolla/venv/lib/python3.9/site-packages/dogpile/lock.py", line 185, in __enter__
2023-03-01 14:11:48.039927 2023-03-01 14:11:48.036 33 ERROR keystone.server.flask.application     return self._enter()
2023-03-01 14:11:48.039936 2023-03-01 14:11:48.036 33 ERROR keystone.server.flask.application   File "/var/lib/kolla/venv/lib/python3.9/site-packages/dogpile/lock.py", line 94, in _enter
2023-03-01 14:11:48.039945 2023-03-01 14:11:48.036 33 ERROR keystone.server.flask.application     generated = self._enter_create(value, createdtime)
2023-03-01 14:11:48.039954 2023-03-01 14:11:48.036 33 ERROR keystone.server.flask.application   File "/var/lib/kolla/venv/lib/python3.9/site-packages/dogpile/lock.py", line 178, in _enter_create
2023-03-01 14:11:48.039963 2023-03-01 14:11:48.036 33 ERROR keystone.server.flask.application     return self.creator()
2023-03-01 14:11:48.039972 2023-03-01 14:11:48.036 33 ERROR keystone.server.flask.application   File "/var/lib/kolla/venv/lib/python3.9/site-packages/dogpile/cache/region.py", line 995, in gen_value
2023-03-01 14:11:48.039982 2023-03-01 14:11:48.036 33 ERROR keystone.server.flask.application     created_value = creator(
2023-03-01 14:11:48.039990 2023-03-01 14:11:48.036 33 ERROR keystone.server.flask.application   File "/var/lib/kolla/venv/lib/python3.9/site-packages/keystone/resource/core.py", line 903, in get_project
2023-03-01 14:11:48.040000 2023-03-01 14:11:48.036 33 ERROR keystone.server.flask.application     return self.driver.get_project(project_id)
2023-03-01 14:11:48.040009 2023-03-01 14:11:48.036 33 ERROR keystone.server.flask.application   File "/var/lib/kolla/venv/lib/python3.9/site-packages/keystone/resource/backends/sql.py", line 49, in get_project
2023-03-01 14:11:48.040018 2023-03-01 14:11:48.036 33 ERROR keystone.server.flask.application     return self._get_project(session, project_id).to_dict()
2023-03-01 14:11:48.040027 2023-03-01 14:11:48.036 33 ERROR keystone.server.flask.application   File "/var/lib/kolla/venv/lib/python3.9/site-packages/keystone/resource/backends/sql.py", line 44, in _get_project
2023-03-01 14:11:48.040037 2023-03-01 14:11:48.036 33 ERROR keystone.server.flask.application     raise exception.ProjectNotFound(project_id=project_id)
2023-03-01 14:11:48.040046 2023-03-01 14:11:48.036 33 ERROR keystone.server.flask.application keystone.exception.ProjectNotFound: Could not find project: service.
2023-03-01 14:11:48.040055 2023-03-01 14:11:48.036 33 ERROR keystone.server.flask.application \x1b[00m
2023-03-01 14:12:03.577715 2023-03-01 14:12:03.570 34 ERROR keystone.server.flask.application [None req-e65384ef-5576-46b1-a8c8-6755952c62b6 4948d33173d947e3973c5cf5740ec4cb - - all default -] Could not find role: admin.: keystone.exception.RoleNotFound: Could not find role: admin.
2023-03-01 14:12:03.577762 2023-03-01 14:12:03.570 34 ERROR keystone.server.flask.application Traceback (most recent call last):
2023-03-01 14:12:03.577773 2023-03-01 14:12:03.570 34 ERROR keystone.server.flask.application   File "/var/lib/kolla/venv/lib/python3.9/site-packages/flask/app.py", line 1820, in full_dispatch_request
2023-03-01 14:12:03.577782 2023-03-01 14:12:03.570 34 ERROR keystone.server.flask.application     rv = self.dispatch_request()
2023-03-01 14:12:03.577791 2023-03-01 14:12:03.570 34 ERROR keystone.server.flask.application   File "/var/lib/kolla/venv/lib/python3.9/site-packages/flask/app.py", line 1796, in dispatch_request
2023-03-01 14:12:03.577801 2023-03-01 14:12:03.570 34 ERROR keystone.server.flask.application     return self.ensure_sync(self.view_functions[rule.endpoint])(**view_args)
2023-03-01 14:12:03.577810 2023-03-01 14:12:03.570 34 ERROR keystone.server.flask.application   File "/var/lib/kolla/venv/lib/python3.9/site-packages/flask_restful/__init__.py", line 467, in wrapper
2023-03-01 14:12:03.577835 2023-03-01 14:12:03.570 34 ERROR keystone.server.flask.application     resp = resource(*args, **kwargs)
2023-03-01 14:12:03.577846 2023-03-01 14:12:03.570 34 ERROR keystone.server.flask.application   File "/var/lib/kolla/venv/lib/python3.9/site-packages/flask/views.py", line 107, in view
2023-03-01 14:12:03.577856 2023-03-01 14:12:03.570 34 ERROR keystone.server.flask.application     return current_app.ensure_sync(self.dispatch_request)(**kwargs)
2023-03-01 14:12:03.577865 2023-03-01 14:12:03.570 34 ERROR keystone.server.flask.application   File "/var/lib/kolla/venv/lib/python3.9/site-packages/flask_restful/__init__.py", line 582, in dispatch_request
2023-03-01 14:12:03.577874 2023-03-01 14:12:03.570 34 ERROR keystone.server.flask.application     resp = meth(*args, **kwargs)
2023-03-01 14:12:03.577883 2023-03-01 14:12:03.570 34 ERROR keystone.server.flask.application   File "/var/lib/kolla/venv/lib/python3.9/site-packages/keystone/api/roles.py", line 50, in get
2023-03-01 14:12:03.577892 2023-03-01 14:12:03.570 34 ERROR keystone.server.flask.application     return self._get_role(role_id)
2023-03-01 14:12:03.577902 2023-03-01 14:12:03.570 34 ERROR keystone.server.flask.application   File "/var/lib/kolla/venv/lib/python3.9/site-packages/keystone/api/roles.py", line 70, in _get_role
2023-03-01 14:12:03.577911 2023-03-01 14:12:03.570 34 ERROR keystone.server.flask.application     ENFORCER.enforce_call(action='identity:get_role')
2023-03-01 14:12:03.578269 2023-03-01 14:12:03.570 34 ERROR keystone.server.flask.application   File "/var/lib/kolla/venv/lib/python3.9/site-packages/keystone/common/rbac_enforcer/enforcer.py", line 402, in enforce_call
2023-03-01 14:12:03.578292 2023-03-01 14:12:03.570 34 ERROR keystone.server.flask.application     policy_dict.update(cls._extract_member_target_data(
2023-03-01 14:12:03.578302 2023-03-01 14:12:03.570 34 ERROR keystone.server.flask.application   File "/var/lib/kolla/venv/lib/python3.9/site-packages/keystone/common/rbac_enforcer/enforcer.py", line 234, in _extract_member_target_data
2023-03-01 14:12:03.578312 2023-03-01 14:12:03.570 34 ERROR keystone.server.flask.application     member_name: func(flask.request.view_args[key])
2023-03-01 14:12:03.578322 2023-03-01 14:12:03.570 34 ERROR keystone.server.flask.application   File "/var/lib/kolla/venv/lib/python3.9/site-packages/keystone/common/manager.py", line 115, in wrapped
2023-03-01 14:12:03.578331 2023-03-01 14:12:03.570 34 ERROR keystone.server.flask.application     __ret_val = __f(*args, **kwargs)
2023-03-01 14:12:03.578360 2023-03-01 14:12:03.570 34 ERROR keystone.server.flask.application   File "/var/lib/kolla/venv/lib/python3.9/site-packages/decorator.py", line 232, in fun
2023-03-01 14:12:03.578392 2023-03-01 14:12:03.570 34 ERROR keystone.server.flask.application     return caller(func, *(extras + args), **kw)
2023-03-01 14:12:03.578404 2023-03-01 14:12:03.570 34 ERROR keystone.server.flask.application   File "/var/lib/kolla/venv/lib/python3.9/site-packages/dogpile/cache/region.py", line 1577, in get_or_create_for_user_func
2023-03-01 14:12:03.578414 2023-03-01 14:12:03.570 34 ERROR keystone.server.flask.application     return self.get_or_create(
2023-03-01 14:12:03.578423 2023-03-01 14:12:03.570 34 ERROR keystone.server.flask.application   File "/var/lib/kolla/venv/lib/python3.9/site-packages/dogpile/cache/region.py", line 1042, in get_or_create
2023-03-01 14:12:03.578433 2023-03-01 14:12:03.570 34 ERROR keystone.server.flask.application     with Lock(
2023-03-01 14:12:03.578442 2023-03-01 14:12:03.570 34 ERROR keystone.server.flask.application   File "/var/lib/kolla/venv/lib/python3.9/site-packages/dogpile/lock.py", line 185, in __enter__
2023-03-01 14:12:03.578452 2023-03-01 14:12:03.570 34 ERROR keystone.server.flask.application     return self._enter()
2023-03-01 14:12:03.578461 2023-03-01 14:12:03.570 34 ERROR keystone.server.flask.application   File "/var/lib/kolla/venv/lib/python3.9/site-packages/dogpile/lock.py", line 94, in _enter
2023-03-01 14:12:03.578487 2023-03-01 14:12:03.570 34 ERROR keystone.server.flask.application     generated = self._enter_create(value, createdtime)
2023-03-01 14:12:03.578498 2023-03-01 14:12:03.570 34 ERROR keystone.server.flask.application   File "/var/lib/kolla/venv/lib/python3.9/site-packages/dogpile/lock.py", line 178, in _enter_create
2023-03-01 14:12:03.578508 2023-03-01 14:12:03.570 34 ERROR keystone.server.flask.application     return self.creator()
2023-03-01 14:12:03.578517 2023-03-01 14:12:03.570 34 ERROR keystone.server.flask.application   File "/var/lib/kolla/venv/lib/python3.9/site-packages/dogpile/cache/region.py", line 995, in gen_value
2023-03-01 14:12:03.578527 2023-03-01 14:12:03.570 34 ERROR keystone.server.flask.application     created_value = creator(
2023-03-01 14:12:03.578536 2023-03-01 14:12:03.570 34 ERROR keystone.server.flask.application   File "/var/lib/kolla/venv/lib/python3.9/site-packages/keystone/assignment/core.py", line 1276, in get_role
2023-03-01 14:12:03.578546 2023-03-01 14:12:03.570 34 ERROR keystone.server.flask.application     return self.driver.get_role(role_id)
2023-03-01 14:12:03.578555 2023-03-01 14:12:03.570 34 ERROR keystone.server.flask.application   File "/var/lib/kolla/venv/lib/python3.9/site-packages/keystone/assignment/role_backends/sql.py", line 70, in get_role
2023-03-01 14:12:03.578565 2023-03-01 14:12:03.570 34 ERROR keystone.server.flask.application     return self._get_role(session, role_id).to_dict()
2023-03-01 14:12:03.578574 2023-03-01 14:12:03.570 34 ERROR keystone.server.flask.application   File "/var/lib/kolla/venv/lib/python3.9/site-packages/keystone/assignment/role_backends/sql.py", line 65, in _get_role
2023-03-01 14:12:03.578584 2023-03-01 14:12:03.570 34 ERROR keystone.server.flask.application     raise exception.RoleNotFound(role_id=role_id)
2023-03-01 14:12:03.578593 2023-03-01 14:12:03.570 34 ERROR keystone.server.flask.application keystone.exception.RoleNotFound: Could not find role: admin.
2023-03-01 14:12:03.578603 2023-03-01 14:12:03.570 34 ERROR keystone.server.flask.application \x1b[00m
2023-03-01 14:12:04.761995 2023-03-01 14:12:04.757 33 ERROR keystone.server.flask.application [None req-8ccc1b80-6a82-4ba1-b197-6287b43459e6 4948d33173d947e3973c5cf5740ec4cb - - all default -] Could not find user: neutron.: keystone.exception.UserNotFound: Could not find user: neutron.
2023-03-01 14:12:04.762055 2023-03-01 14:12:04.757 33 ERROR keystone.server.flask.application Traceback (most recent call last):
2023-03-01 14:12:04.762083 2023-03-01 14:12:04.757 33 ERROR keystone.server.flask.application   File "/var/lib/kolla/venv/lib/python3.9/site-packages/flask/app.py", line 1820, in full_dispatch_request
2023-03-01 14:12:04.762094 2023-03-01 14:12:04.757 33 ERROR keystone.server.flask.application     rv = self.dispatch_request()
2023-03-01 14:12:04.762104 2023-03-01 14:12:04.757 33 ERROR keystone.server.flask.application   File "/var/lib/kolla/venv/lib/python3.9/site-packages/flask/app.py", line 1796, in dispatch_request
2023-03-01 14:12:04.762115 2023-03-01 14:12:04.757 33 ERROR keystone.server.flask.application     return self.ensure_sync(self.view_functions[rule.endpoint])(**view_args)
2023-03-01 14:12:04.762126 2023-03-01 14:12:04.757 33 ERROR keystone.server.flask.application   File "/var/lib/kolla/venv/lib/python3.9/site-packages/flask_restful/__init__.py", line 467, in wrapper
2023-03-01 14:12:04.762136 2023-03-01 14:12:04.757 33 ERROR keystone.server.flask.application     resp = resource(*args, **kwargs)
2023-03-01 14:12:04.762146 2023-03-01 14:12:04.757 33 ERROR keystone.server.flask.application   File "/var/lib/kolla/venv/lib/python3.9/site-packages/flask/views.py", line 107, in view
2023-03-01 14:12:04.762157 2023-03-01 14:12:04.757 33 ERROR keystone.server.flask.application     return current_app.ensure_sync(self.dispatch_request)(**kwargs)
2023-03-01 14:12:04.762167 2023-03-01 14:12:04.757 33 ERROR keystone.server.flask.application   File "/var/lib/kolla/venv/lib/python3.9/site-packages/flask_restful/__init__.py", line 582, in dispatch_request
2023-03-01 14:12:04.762198 2023-03-01 14:12:04.757 33 ERROR keystone.server.flask.application     resp = meth(*args, **kwargs)
2023-03-01 14:12:04.762210 2023-03-01 14:12:04.757 33 ERROR keystone.server.flask.application   File "/var/lib/kolla/venv/lib/python3.9/site-packages/keystone/api/users.py", line 182, in get
2023-03-01 14:12:04.762220 2023-03-01 14:12:04.757 33 ERROR keystone.server.flask.application     return self._get_user(user_id)
2023-03-01 14:12:04.762230 2023-03-01 14:12:04.757 33 ERROR keystone.server.flask.application   File "/var/lib/kolla/venv/lib/python3.9/site-packages/keystone/api/users.py", line 194, in _get_user
2023-03-01 14:12:04.762240 2023-03-01 14:12:04.757 33 ERROR keystone.server.flask.application     ref = PROVIDERS.identity_api.get_user(user_id)
2023-03-01 14:12:04.762250 2023-03-01 14:12:04.757 33 ERROR keystone.server.flask.application   File "/var/lib/kolla/venv/lib/python3.9/site-packages/keystone/common/manager.py", line 115, in wrapped
2023-03-01 14:12:04.762260 2023-03-01 14:12:04.757 33 ERROR keystone.server.flask.application     __ret_val = __f(*args, **kwargs)
2023-03-01 14:12:04.762270 2023-03-01 14:12:04.757 33 ERROR keystone.server.flask.application   File "/var/lib/kolla/venv/lib/python3.9/site-packages/keystone/identity/core.py", line 414, in wrapper
2023-03-01 14:12:04.762280 2023-03-01 14:12:04.757 33 ERROR keystone.server.flask.application     return f(self, *args, **kwargs)
2023-03-01 14:12:04.762290 2023-03-01 14:12:04.757 33 ERROR keystone.server.flask.application   File "/var/lib/kolla/venv/lib/python3.9/site-packages/keystone/identity/core.py", line 424, in wrapper
2023-03-01 14:12:04.762300 2023-03-01 14:12:04.757 33 ERROR keystone.server.flask.application     return f(self, *args, **kwargs)
2023-03-01 14:12:04.762310 2023-03-01 14:12:04.757 33 ERROR keystone.server.flask.application   File "/var/lib/kolla/venv/lib/python3.9/site-packages/decorator.py", line 232, in fun
2023-03-01 14:12:04.762320 2023-03-01 14:12:04.757 33 ERROR keystone.server.flask.application     return caller(func, *(extras + args), **kw)
2023-03-01 14:12:04.762331 2023-03-01 14:12:04.757 33 ERROR keystone.server.flask.application   File "/var/lib/kolla/venv/lib/python3.9/site-packages/dogpile/cache/region.py", line 1577, in get_or_create_for_user_func
2023-03-01 14:12:04.762377 2023-03-01 14:12:04.757 33 ERROR keystone.server.flask.application     return self.get_or_create(
2023-03-01 14:12:04.762398 2023-03-01 14:12:04.757 33 ERROR keystone.server.flask.application   File "/var/lib/kolla/venv/lib/python3.9/site-packages/dogpile/cache/region.py", line 1042, in get_or_create
2023-03-01 14:12:04.762410 2023-03-01 14:12:04.757 33 ERROR keystone.server.flask.application     with Lock(
2023-03-01 14:12:04.762420 2023-03-01 14:12:04.757 33 ERROR keystone.server.flask.application   File "/var/lib/kolla/venv/lib/python3.9/site-packages/dogpile/lock.py", line 185, in __enter__
2023-03-01 14:12:04.762430 2023-03-01 14:12:04.757 33 ERROR keystone.server.flask.application     return self._enter()
2023-03-01 14:12:04.762440 2023-03-01 14:12:04.757 33 ERROR keystone.server.flask.application   File "/var/lib/kolla/venv/lib/python3.9/site-packages/dogpile/lock.py", line 94, in _enter
2023-03-01 14:12:04.762451 2023-03-01 14:12:04.757 33 ERROR keystone.server.flask.application     generated = self._enter_create(value, createdtime)
2023-03-01 14:12:04.762461 2023-03-01 14:12:04.757 33 ERROR keystone.server.flask.application   File "/var/lib/kolla/venv/lib/python3.9/site-packages/dogpile/lock.py", line 178, in _enter_create
2023-03-01 14:12:04.762471 2023-03-01 14:12:04.757 33 ERROR keystone.server.flask.application     return self.creator()
2023-03-01 14:12:04.762481 2023-03-01 14:12:04.757 33 ERROR keystone.server.flask.application   File "/var/lib/kolla/venv/lib/python3.9/site-packages/dogpile/cache/region.py", line 995, in gen_value
2023-03-01 14:12:04.762492 2023-03-01 14:12:04.757 33 ERROR keystone.server.flask.application     created_value = creator(
2023-03-01 14:12:04.762516 2023-03-01 14:12:04.757 33 ERROR keystone.server.flask.application   File "/var/lib/kolla/venv/lib/python3.9/site-packages/keystone/identity/core.py", line 1011, in get_user
2023-03-01 14:12:04.762527 2023-03-01 14:12:04.757 33 ERROR keystone.server.flask.application     ref = driver.get_user(entity_id)
2023-03-01 14:12:04.762538 2023-03-01 14:12:04.757 33 ERROR keystone.server.flask.application   File "/var/lib/kolla/venv/lib/python3.9/site-packages/keystone/identity/backends/sql.py", line 200, in get_user
2023-03-01 14:12:04.762548 2023-03-01 14:12:04.757 33 ERROR keystone.server.flask.application     self._get_user(session, user_id).to_dict())
2023-03-01 14:12:04.762558 2023-03-01 14:12:04.757 33 ERROR keystone.server.flask.application   File "/var/lib/kolla/venv/lib/python3.9/site-packages/keystone/identity/backends/sql.py", line 194, in _get_user
2023-03-01 14:12:04.762848 2023-03-01 14:12:04.757 33 ERROR keystone.server.flask.application     raise exception.UserNotFound(user_id=user_id)
2023-03-01 14:12:04.762866 2023-03-01 14:12:04.757 33 ERROR keystone.server.flask.application keystone.exception.UserNotFound: Could not find user: neutron.
2023-03-01 14:12:04.762876 2023-03-01 14:12:04.757 33 ERROR keystone.server.flask.application \x1b[00m
2023-03-01 14:12:05.583617 2023-03-01 14:12:05.580 34 ERROR keystone.server.flask.application [None req-ced8971b-4a80-4aea-8b40-e4b334c0b2c1 4948d33173d947e3973c5cf5740ec4cb - - all default -] Could not find project: service.: keystone.exception.ProjectNotFound: Could not find project: service.
2023-03-01 14:12:05.583708 2023-03-01 14:12:05.580 34 ERROR keystone.server.flask.application Traceback (most recent call last):
2023-03-01 14:12:05.583721 2023-03-01 14:12:05.580 34 ERROR keystone.server.flask.application   File "/var/lib/kolla/venv/lib/python3.9/site-packages/flask/app.py", line 1820, in full_dispatch_request
2023-03-01 14:12:05.583731 2023-03-01 14:12:05.580 34 ERROR keystone.server.flask.application     rv = self.dispatch_request()
2023-03-01 14:12:05.583740 2023-03-01 14:12:05.580 34 ERROR keystone.server.flask.application   File "/var/lib/kolla/venv/lib/python3.9/site-packages/flask/app.py", line 1796, in dispatch_request
2023-03-01 14:12:05.583750 2023-03-01 14:12:05.580 34 ERROR keystone.server.flask.application     return self.ensure_sync(self.view_functions[rule.endpoint])(**view_args)
2023-03-01 14:12:05.583759 2023-03-01 14:12:05.580 34 ERROR keystone.server.flask.application   File "/var/lib/kolla/venv/lib/python3.9/site-packages/flask_restful/__init__.py", line 467, in wrapper
2023-03-01 14:12:05.583768 2023-03-01 14:12:05.580 34 ERROR keystone.server.flask.application     resp = resource(*args, **kwargs)
2023-03-01 14:12:05.583777 2023-03-01 14:12:05.580 34 ERROR keystone.server.flask.application   File "/var/lib/kolla/venv/lib/python3.9/site-packages/flask/views.py", line 107, in view
2023-03-01 14:12:05.583787 2023-03-01 14:12:05.580 34 ERROR keystone.server.flask.application     return current_app.ensure_sync(self.dispatch_request)(**kwargs)
2023-03-01 14:12:05.583796 2023-03-01 14:12:05.580 34 ERROR keystone.server.flask.application   File "/var/lib/kolla/venv/lib/python3.9/site-packages/flask_restful/__init__.py", line 582, in dispatch_request
2023-03-01 14:12:05.583805 2023-03-01 14:12:05.580 34 ERROR keystone.server.flask.application     resp = meth(*args, **kwargs)
2023-03-01 14:12:05.583814 2023-03-01 14:12:05.580 34 ERROR keystone.server.flask.application   File "/var/lib/kolla/venv/lib/python3.9/site-packages/keystone/api/projects.py", line 151, in get
2023-03-01 14:12:05.583823 2023-03-01 14:12:05.580 34 ERROR keystone.server.flask.application     return self._get_project(project_id)
2023-03-01 14:12:05.583832 2023-03-01 14:12:05.580 34 ERROR keystone.server.flask.application   File "/var/lib/kolla/venv/lib/python3.9/site-packages/keystone/api/projects.py", line 107, in _get_project
2023-03-01 14:12:05.583841 2023-03-01 14:12:05.580 34 ERROR keystone.server.flask.application     project = PROVIDERS.resource_api.get_project(project_id)
2023-03-01 14:12:05.583866 2023-03-01 14:12:05.580 34 ERROR keystone.server.flask.application   File "/var/lib/kolla/venv/lib/python3.9/site-packages/keystone/common/manager.py", line 115, in wrapped
2023-03-01 14:12:05.583877 2023-03-01 14:12:05.580 34 ERROR keystone.server.flask.application     __ret_val = __f(*args, **kwargs)
2023-03-01 14:12:05.583886 2023-03-01 14:12:05.580 34 ERROR keystone.server.flask.application   File "/var/lib/kolla/venv/lib/python3.9/site-packages/decorator.py", line 232, in fun
2023-03-01 14:12:05.583896 2023-03-01 14:12:05.580 34 ERROR keystone.server.flask.application     return caller(func, *(extras + args), **kw)
2023-03-01 14:12:05.583905 2023-03-01 14:12:05.580 34 ERROR keystone.server.flask.application   File "/var/lib/kolla/venv/lib/python3.9/site-packages/dogpile/cache/region.py", line 1577, in get_or_create_for_user_func
2023-03-01 14:12:05.583921 2023-03-01 14:12:05.580 34 ERROR keystone.server.flask.application     return self.get_or_create(
2023-03-01 14:12:05.583930 2023-03-01 14:12:05.580 34 ERROR keystone.server.flask.application   File "/var/lib/kolla/venv/lib/python3.9/site-packages/dogpile/cache/region.py", line 1042, in get_or_create
2023-03-01 14:12:05.583942 2023-03-01 14:12:05.580 34 ERROR keystone.server.flask.application     with Lock(
2023-03-01 14:12:05.583951 2023-03-01 14:12:05.580 34 ERROR keystone.server.flask.application   File "/var/lib/kolla/venv/lib/python3.9/site-packages/dogpile/lock.py", line 185, in __enter__
2023-03-01 14:12:05.583960 2023-03-01 14:12:05.580 34 ERROR keystone.server.flask.application     return self._enter()
2023-03-01 14:12:05.583969 2023-03-01 14:12:05.580 34 ERROR keystone.server.flask.application   File "/var/lib/kolla/venv/lib/python3.9/site-packages/dogpile/lock.py", line 94, in _enter
2023-03-01 14:12:05.583978 2023-03-01 14:12:05.580 34 ERROR keystone.server.flask.application     generated = self._enter_create(value, createdtime)
2023-03-01 14:12:05.583991 2023-03-01 14:12:05.580 34 ERROR keystone.server.flask.application   File "/var/lib/kolla/venv/lib/python3.9/site-packages/dogpile/lock.py", line 178, in _enter_create
2023-03-01 14:12:05.584001 2023-03-01 14:12:05.580 34 ERROR keystone.server.flask.application     return self.creator()
2023-03-01 14:12:05.584010 2023-03-01 14:12:05.580 34 ERROR keystone.server.flask.application   File "/var/lib/kolla/venv/lib/python3.9/site-packages/dogpile/cache/region.py", line 995, in gen_value
2023-03-01 14:12:05.584019 2023-03-01 14:12:05.580 34 ERROR keystone.server.flask.application     created_value = creator(
2023-03-01 14:12:05.584028 2023-03-01 14:12:05.580 34 ERROR keystone.server.flask.application   File "/var/lib/kolla/venv/lib/python3.9/site-packages/keystone/resource/core.py", line 903, in get_project
2023-03-01 14:12:05.584037 2023-03-01 14:12:05.580 34 ERROR keystone.server.flask.application     return self.driver.get_project(project_id)
2023-03-01 14:12:05.584046 2023-03-01 14:12:05.580 34 ERROR keystone.server.flask.application   File "/var/lib/kolla/venv/lib/python3.9/site-packages/keystone/resource/backends/sql.py", line 49, in get_project
2023-03-01 14:12:05.584055 2023-03-01 14:12:05.580 34 ERROR keystone.server.flask.application     return self._get_project(session, project_id).to_dict()
2023-03-01 14:12:05.584064 2023-03-01 14:12:05.580 34 ERROR keystone.server.flask.application   File "/var/lib/kolla/venv/lib/python3.9/site-packages/keystone/resource/backends/sql.py", line 44, in _get_project
2023-03-01 14:12:05.584074 2023-03-01 14:12:05.580 34 ERROR keystone.server.flask.application     raise exception.ProjectNotFound(project_id=project_id)
2023-03-01 14:12:05.584083 2023-03-01 14:12:05.580 34 ERROR keystone.server.flask.application keystone.exception.ProjectNotFound: Could not find project: service.
2023-03-01 14:12:05.584092 2023-03-01 14:12:05.580 34 ERROR keystone.server.flask.application \x1b[00m
