2023-04-12 01:06:04.138 23 INFO alembic.runtime.migration [-] Context impl MySQLImpl.
2023-04-12 01:06:04.140 23 INFO alembic.runtime.migration [-] Will assume non-transactional DDL.
2023-04-12 01:06:04.199 23 INFO alembic.runtime.migration [-] Context impl MySQLImpl.
2023-04-12 01:06:04.199 23 INFO alembic.runtime.migration [-] Will assume non-transactional DDL.
2023-04-12 01:06:04.249 23 INFO alembic.runtime.migration [-] Running upgrade  -> 27e647c0fad4, Initial version.
2023-04-12 01:06:05.389 23 INFO alembic.runtime.migration [-] Running upgrade 27e647c0fad4 -> e25ffa003242, Initial no-op Yoga contract migration.
2023-04-12 01:06:05.413 23 INFO alembic.runtime.migration [-] Running upgrade 27e647c0fad4 -> 29e87d24a316, Initial no-op Yoga expand migration.
2023-04-12 01:06:13.911 7 INFO keystone.common.fernet_utils [-] Created a new temporary key: /etc/keystone/fernet-keys/0.tmp
2023-04-12 01:06:13.915 7 INFO keystone.common.fernet_utils [-] Become a valid new key: /etc/keystone/fernet-keys/0
2023-04-12 01:06:13.916 7 INFO keystone.common.fernet_utils [-] Starting key rotation with 1 key files: ['/etc/keystone/fernet-keys/0']
2023-04-12 01:06:13.917 7 INFO keystone.common.fernet_utils [-] Created a new temporary key: /etc/keystone/fernet-keys/0.tmp
2023-04-12 01:06:13.917 7 INFO keystone.common.fernet_utils [-] Current primary key is: 0
2023-04-12 01:06:13.918 7 INFO keystone.common.fernet_utils [-] Next primary key will be: 1
2023-04-12 01:06:13.918 7 INFO keystone.common.fernet_utils [-] Promoted key 0 to be the primary: 1
2023-04-12 01:06:13.919 7 INFO keystone.common.fernet_utils [-] Become a valid new key: /etc/keystone/fernet-keys/0
2023-04-12 01:06:32.037 32 INFO keystone.cmd.bootstrap [None req-798769cd-f25b-401d-850b-df73be32f444 - - - - - -] Created domain default
2023-04-12 01:06:32.107 32 INFO keystone.cmd.bootstrap [None req-798769cd-f25b-401d-850b-df73be32f444 - - - - - -] Created project admin
2023-04-12 01:06:32.710 32 INFO keystone.cmd.bootstrap [None req-798769cd-f25b-401d-850b-df73be32f444 - - - - - -] Created user admin
2023-04-12 01:06:32.742 32 INFO keystone.cmd.bootstrap [None req-798769cd-f25b-401d-850b-df73be32f444 - - - - - -] Created role reader
2023-04-12 01:06:32.776 32 INFO keystone.cmd.bootstrap [None req-798769cd-f25b-401d-850b-df73be32f444 - - - - - -] Created role member
2023-04-12 01:06:32.830 32 INFO keystone.cmd.bootstrap [None req-798769cd-f25b-401d-850b-df73be32f444 - - - - - -] Created implied role where 8b6113d23ed5489da0ae63dcf746dfa1 implies 8161b898c73c4a41895d88973d659041
2023-04-12 01:06:32.847 32 INFO keystone.cmd.bootstrap [None req-798769cd-f25b-401d-850b-df73be32f444 - - - - - -] Created role admin
2023-04-12 01:06:32.879 32 INFO keystone.cmd.bootstrap [None req-798769cd-f25b-401d-850b-df73be32f444 - - - - - -] Created implied role where 4301933a1298445f9a184b3b820b43b8 implies 8b6113d23ed5489da0ae63dcf746dfa1
2023-04-12 01:06:32.900 32 INFO keystone.cmd.bootstrap [None req-798769cd-f25b-401d-850b-df73be32f444 - - - - - -] Granted role admin on project admin to user admin.
2023-04-12 01:06:32.914 32 INFO keystone.cmd.bootstrap [None req-798769cd-f25b-401d-850b-df73be32f444 - - - - - -] Granted role admin on the system to user admin.
2023-04-12 01:06:32.935 32 WARNING py.warnings [None req-798769cd-f25b-401d-850b-df73be32f444 - - - - - -] /var/lib/kolla/venv/lib/python3.9/site-packages/pycadf/identifier.py:71: UserWarning: Invalid uuid: RegionOne. To ensure interoperability, identifiers should be a valid uuid.
  warnings.warn(('Invalid uuid: %s. To ensure interoperability, '

2023-04-12 01:06:32.943 32 INFO keystone.cmd.bootstrap [None req-798769cd-f25b-401d-850b-df73be32f444 - - - - - -] Created region RegionOne
2023-04-12 01:06:33.001 32 INFO keystone.cmd.bootstrap [None req-798769cd-f25b-401d-850b-df73be32f444 - - - - - -] Created public endpoint http://169.16.1.157:5000
2023-04-12 01:06:33.025 32 INFO keystone.cmd.bootstrap [None req-798769cd-f25b-401d-850b-df73be32f444 - - - - - -] Created internal endpoint http://169.16.1.157:5000
2023-04-12 01:06:58.068 39 WARNING keystone.common.rbac_enforcer.enforcer [None req-42c319e4-ecc0-4f6a-9ca8-6aa378af87b7 39f4879392a64163b67509866d91d639 - - all default -] Deprecated policy rules found. Use oslopolicy-policy-generator and oslopolicy-policy-upgrade to detect and resolve deprecated policies in your configuration.
2023-04-12 01:06:58.923 37 WARNING keystone.common.rbac_enforcer.enforcer [None req-e0927131-4cef-4d43-b0a6-989cdf7d6aee 39f4879392a64163b67509866d91d639 - - all default -] Deprecated policy rules found. Use oslopolicy-policy-generator and oslopolicy-policy-upgrade to detect and resolve deprecated policies in your configuration.
2023-04-12 01:07:06.172 38 WARNING keystone.common.rbac_enforcer.enforcer [None req-52cb57c8-5072-40e3-854b-6db3527fa4fa 39f4879392a64163b67509866d91d639 - - all default -] Deprecated policy rules found. Use oslopolicy-policy-generator and oslopolicy-policy-upgrade to detect and resolve deprecated policies in your configuration.
2023-04-12 01:08:24.305 38 ERROR keystone.server.flask.application [None req-41fd607c-4079-4676-9bf8-98b020888f2e 39f4879392a64163b67509866d91d639 - - all default -] Could not find project: service.: keystone.exception.ProjectNotFound: Could not find project: service.
2023-04-12 01:08:24.305 38 ERROR keystone.server.flask.application Traceback (most recent call last):
2023-04-12 01:08:24.305 38 ERROR keystone.server.flask.application   File "/var/lib/kolla/venv/lib/python3.9/site-packages/flask/app.py", line 1820, in full_dispatch_request
2023-04-12 01:08:24.305 38 ERROR keystone.server.flask.application     rv = self.dispatch_request()
2023-04-12 01:08:24.305 38 ERROR keystone.server.flask.application   File "/var/lib/kolla/venv/lib/python3.9/site-packages/flask/app.py", line 1796, in dispatch_request
2023-04-12 01:08:24.305 38 ERROR keystone.server.flask.application     return self.ensure_sync(self.view_functions[rule.endpoint])(**view_args)
2023-04-12 01:08:24.305 38 ERROR keystone.server.flask.application   File "/var/lib/kolla/venv/lib/python3.9/site-packages/flask_restful/__init__.py", line 467, in wrapper
2023-04-12 01:08:24.305 38 ERROR keystone.server.flask.application     resp = resource(*args, **kwargs)
2023-04-12 01:08:24.305 38 ERROR keystone.server.flask.application   File "/var/lib/kolla/venv/lib/python3.9/site-packages/flask/views.py", line 107, in view
2023-04-12 01:08:24.305 38 ERROR keystone.server.flask.application     return current_app.ensure_sync(self.dispatch_request)(**kwargs)
2023-04-12 01:08:24.305 38 ERROR keystone.server.flask.application   File "/var/lib/kolla/venv/lib/python3.9/site-packages/flask_restful/__init__.py", line 582, in dispatch_request
2023-04-12 01:08:24.305 38 ERROR keystone.server.flask.application     resp = meth(*args, **kwargs)
2023-04-12 01:08:24.305 38 ERROR keystone.server.flask.application   File "/var/lib/kolla/venv/lib/python3.9/site-packages/keystone/api/projects.py", line 151, in get
2023-04-12 01:08:24.305 38 ERROR keystone.server.flask.application     return self._get_project(project_id)
2023-04-12 01:08:24.305 38 ERROR keystone.server.flask.application   File "/var/lib/kolla/venv/lib/python3.9/site-packages/keystone/api/projects.py", line 107, in _get_project
2023-04-12 01:08:24.305 38 ERROR keystone.server.flask.application     project = PROVIDERS.resource_api.get_project(project_id)
2023-04-12 01:08:24.305 38 ERROR keystone.server.flask.application   File "/var/lib/kolla/venv/lib/python3.9/site-packages/keystone/common/manager.py", line 115, in wrapped
2023-04-12 01:08:24.305 38 ERROR keystone.server.flask.application     __ret_val = __f(*args, **kwargs)
2023-04-12 01:08:24.305 38 ERROR keystone.server.flask.application   File "/var/lib/kolla/venv/lib/python3.9/site-packages/decorator.py", line 232, in fun
2023-04-12 01:08:24.305 38 ERROR keystone.server.flask.application     return caller(func, *(extras + args), **kw)
2023-04-12 01:08:24.305 38 ERROR keystone.server.flask.application   File "/var/lib/kolla/venv/lib/python3.9/site-packages/dogpile/cache/region.py", line 1577, in get_or_create_for_user_func
2023-04-12 01:08:24.305 38 ERROR keystone.server.flask.application     return self.get_or_create(
2023-04-12 01:08:24.305 38 ERROR keystone.server.flask.application   File "/var/lib/kolla/venv/lib/python3.9/site-packages/dogpile/cache/region.py", line 1042, in get_or_create
2023-04-12 01:08:24.305 38 ERROR keystone.server.flask.application     with Lock(
2023-04-12 01:08:24.305 38 ERROR keystone.server.flask.application   File "/var/lib/kolla/venv/lib/python3.9/site-packages/dogpile/lock.py", line 185, in __enter__
2023-04-12 01:08:24.305 38 ERROR keystone.server.flask.application     return self._enter()
2023-04-12 01:08:24.305 38 ERROR keystone.server.flask.application   File "/var/lib/kolla/venv/lib/python3.9/site-packages/dogpile/lock.py", line 94, in _enter
2023-04-12 01:08:24.305 38 ERROR keystone.server.flask.application     generated = self._enter_create(value, createdtime)
2023-04-12 01:08:24.305 38 ERROR keystone.server.flask.application   File "/var/lib/kolla/venv/lib/python3.9/site-packages/dogpile/lock.py", line 178, in _enter_create
2023-04-12 01:08:24.305 38 ERROR keystone.server.flask.application     return self.creator()
2023-04-12 01:08:24.305 38 ERROR keystone.server.flask.application   File "/var/lib/kolla/venv/lib/python3.9/site-packages/dogpile/cache/region.py", line 995, in gen_value
2023-04-12 01:08:24.305 38 ERROR keystone.server.flask.application     created_value = creator(
2023-04-12 01:08:24.305 38 ERROR keystone.server.flask.application   File "/var/lib/kolla/venv/lib/python3.9/site-packages/keystone/resource/core.py", line 903, in get_project
2023-04-12 01:08:24.305 38 ERROR keystone.server.flask.application     return self.driver.get_project(project_id)
2023-04-12 01:08:24.305 38 ERROR keystone.server.flask.application   File "/var/lib/kolla/venv/lib/python3.9/site-packages/keystone/resource/backends/sql.py", line 49, in get_project
2023-04-12 01:08:24.305 38 ERROR keystone.server.flask.application     return self._get_project(session, project_id).to_dict()
2023-04-12 01:08:24.305 38 ERROR keystone.server.flask.application   File "/var/lib/kolla/venv/lib/python3.9/site-packages/keystone/resource/backends/sql.py", line 44, in _get_project
2023-04-12 01:08:24.305 38 ERROR keystone.server.flask.application     raise exception.ProjectNotFound(project_id=project_id)
2023-04-12 01:08:24.305 38 ERROR keystone.server.flask.application keystone.exception.ProjectNotFound: Could not find project: service.
2023-04-12 01:08:24.305 38 ERROR keystone.server.flask.application 
2023-04-12 01:08:32.675 37 ERROR keystone.server.flask.application [None req-d8ac1861-dc4b-4129-8c43-a8ec03ea40d9 39f4879392a64163b67509866d91d639 - - all default -] Could not find project: service.: keystone.exception.ProjectNotFound: Could not find project: service.
2023-04-12 01:08:32.675 37 ERROR keystone.server.flask.application Traceback (most recent call last):
2023-04-12 01:08:32.675 37 ERROR keystone.server.flask.application   File "/var/lib/kolla/venv/lib/python3.9/site-packages/flask/app.py", line 1820, in full_dispatch_request
2023-04-12 01:08:32.675 37 ERROR keystone.server.flask.application     rv = self.dispatch_request()
2023-04-12 01:08:32.675 37 ERROR keystone.server.flask.application   File "/var/lib/kolla/venv/lib/python3.9/site-packages/flask/app.py", line 1796, in dispatch_request
2023-04-12 01:08:32.675 37 ERROR keystone.server.flask.application     return self.ensure_sync(self.view_functions[rule.endpoint])(**view_args)
2023-04-12 01:08:32.675 37 ERROR keystone.server.flask.application   File "/var/lib/kolla/venv/lib/python3.9/site-packages/flask_restful/__init__.py", line 467, in wrapper
2023-04-12 01:08:32.675 37 ERROR keystone.server.flask.application     resp = resource(*args, **kwargs)
2023-04-12 01:08:32.675 37 ERROR keystone.server.flask.application   File "/var/lib/kolla/venv/lib/python3.9/site-packages/flask/views.py", line 107, in view
2023-04-12 01:08:32.675 37 ERROR keystone.server.flask.application     return current_app.ensure_sync(self.dispatch_request)(**kwargs)
2023-04-12 01:08:32.675 37 ERROR keystone.server.flask.application   File "/var/lib/kolla/venv/lib/python3.9/site-packages/flask_restful/__init__.py", line 582, in dispatch_request
2023-04-12 01:08:32.675 37 ERROR keystone.server.flask.application     resp = meth(*args, **kwargs)
2023-04-12 01:08:32.675 37 ERROR keystone.server.flask.application   File "/var/lib/kolla/venv/lib/python3.9/site-packages/keystone/api/projects.py", line 151, in get
2023-04-12 01:08:32.675 37 ERROR keystone.server.flask.application     return self._get_project(project_id)
2023-04-12 01:08:32.675 37 ERROR keystone.server.flask.application   File "/var/lib/kolla/venv/lib/python3.9/site-packages/keystone/api/projects.py", line 107, in _get_project
2023-04-12 01:08:32.675 37 ERROR keystone.server.flask.application     project = PROVIDERS.resource_api.get_project(project_id)
2023-04-12 01:08:32.675 37 ERROR keystone.server.flask.application   File "/var/lib/kolla/venv/lib/python3.9/site-packages/keystone/common/manager.py", line 115, in wrapped
2023-04-12 01:08:32.675 37 ERROR keystone.server.flask.application     __ret_val = __f(*args, **kwargs)
2023-04-12 01:08:32.675 37 ERROR keystone.server.flask.application   File "/var/lib/kolla/venv/lib/python3.9/site-packages/decorator.py", line 232, in fun
2023-04-12 01:08:32.675 37 ERROR keystone.server.flask.application     return caller(func, *(extras + args), **kw)
2023-04-12 01:08:32.675 37 ERROR keystone.server.flask.application   File "/var/lib/kolla/venv/lib/python3.9/site-packages/dogpile/cache/region.py", line 1577, in get_or_create_for_user_func
2023-04-12 01:08:32.675 37 ERROR keystone.server.flask.application     return self.get_or_create(
2023-04-12 01:08:32.675 37 ERROR keystone.server.flask.application   File "/var/lib/kolla/venv/lib/python3.9/site-packages/dogpile/cache/region.py", line 1042, in get_or_create
2023-04-12 01:08:32.675 37 ERROR keystone.server.flask.application     with Lock(
2023-04-12 01:08:32.675 37 ERROR keystone.server.flask.application   File "/var/lib/kolla/venv/lib/python3.9/site-packages/dogpile/lock.py", line 185, in __enter__
2023-04-12 01:08:32.675 37 ERROR keystone.server.flask.application     return self._enter()
2023-04-12 01:08:32.675 37 ERROR keystone.server.flask.application   File "/var/lib/kolla/venv/lib/python3.9/site-packages/dogpile/lock.py", line 94, in _enter
2023-04-12 01:08:32.675 37 ERROR keystone.server.flask.application     generated = self._enter_create(value, createdtime)
2023-04-12 01:08:32.675 37 ERROR keystone.server.flask.application   File "/var/lib/kolla/venv/lib/python3.9/site-packages/dogpile/lock.py", line 178, in _enter_create
2023-04-12 01:08:32.675 37 ERROR keystone.server.flask.application     return self.creator()
2023-04-12 01:08:32.675 37 ERROR keystone.server.flask.application   File "/var/lib/kolla/venv/lib/python3.9/site-packages/dogpile/cache/region.py", line 995, in gen_value
2023-04-12 01:08:32.675 37 ERROR keystone.server.flask.application     created_value = creator(
2023-04-12 01:08:32.675 37 ERROR keystone.server.flask.application   File "/var/lib/kolla/venv/lib/python3.9/site-packages/keystone/resource/core.py", line 903, in get_project
2023-04-12 01:08:32.675 37 ERROR keystone.server.flask.application     return self.driver.get_project(project_id)
2023-04-12 01:08:32.675 37 ERROR keystone.server.flask.application   File "/var/lib/kolla/venv/lib/python3.9/site-packages/keystone/resource/backends/sql.py", line 49, in get_project
2023-04-12 01:08:32.675 37 ERROR keystone.server.flask.application     return self._get_project(session, project_id).to_dict()
2023-04-12 01:08:32.675 37 ERROR keystone.server.flask.application   File "/var/lib/kolla/venv/lib/python3.9/site-packages/keystone/resource/backends/sql.py", line 44, in _get_project
2023-04-12 01:08:32.675 37 ERROR keystone.server.flask.application     raise exception.ProjectNotFound(project_id=project_id)
2023-04-12 01:08:32.675 37 ERROR keystone.server.flask.application keystone.exception.ProjectNotFound: Could not find project: service.
2023-04-12 01:08:32.675 37 ERROR keystone.server.flask.application 
2023-04-12 01:08:48.107 39 ERROR keystone.server.flask.application [None req-2236e871-f102-4d1e-9249-db557166cae2 39f4879392a64163b67509866d91d639 - - all default -] Could not find role: admin.: keystone.exception.RoleNotFound: Could not find role: admin.
2023-04-12 01:08:48.107 39 ERROR keystone.server.flask.application Traceback (most recent call last):
2023-04-12 01:08:48.107 39 ERROR keystone.server.flask.application   File "/var/lib/kolla/venv/lib/python3.9/site-packages/flask/app.py", line 1820, in full_dispatch_request
2023-04-12 01:08:48.107 39 ERROR keystone.server.flask.application     rv = self.dispatch_request()
2023-04-12 01:08:48.107 39 ERROR keystone.server.flask.application   File "/var/lib/kolla/venv/lib/python3.9/site-packages/flask/app.py", line 1796, in dispatch_request
2023-04-12 01:08:48.107 39 ERROR keystone.server.flask.application     return self.ensure_sync(self.view_functions[rule.endpoint])(**view_args)
2023-04-12 01:08:48.107 39 ERROR keystone.server.flask.application   File "/var/lib/kolla/venv/lib/python3.9/site-packages/flask_restful/__init__.py", line 467, in wrapper
2023-04-12 01:08:48.107 39 ERROR keystone.server.flask.application     resp = resource(*args, **kwargs)
2023-04-12 01:08:48.107 39 ERROR keystone.server.flask.application   File "/var/lib/kolla/venv/lib/python3.9/site-packages/flask/views.py", line 107, in view
2023-04-12 01:08:48.107 39 ERROR keystone.server.flask.application     return current_app.ensure_sync(self.dispatch_request)(**kwargs)
2023-04-12 01:08:48.107 39 ERROR keystone.server.flask.application   File "/var/lib/kolla/venv/lib/python3.9/site-packages/flask_restful/__init__.py", line 582, in dispatch_request
2023-04-12 01:08:48.107 39 ERROR keystone.server.flask.application     resp = meth(*args, **kwargs)
2023-04-12 01:08:48.107 39 ERROR keystone.server.flask.application   File "/var/lib/kolla/venv/lib/python3.9/site-packages/keystone/api/roles.py", line 50, in get
2023-04-12 01:08:48.107 39 ERROR keystone.server.flask.application     return self._get_role(role_id)
2023-04-12 01:08:48.107 39 ERROR keystone.server.flask.application   File "/var/lib/kolla/venv/lib/python3.9/site-packages/keystone/api/roles.py", line 70, in _get_role
2023-04-12 01:08:48.107 39 ERROR keystone.server.flask.application     ENFORCER.enforce_call(action='identity:get_role')
2023-04-12 01:08:48.107 39 ERROR keystone.server.flask.application   File "/var/lib/kolla/venv/lib/python3.9/site-packages/keystone/common/rbac_enforcer/enforcer.py", line 402, in enforce_call
2023-04-12 01:08:48.107 39 ERROR keystone.server.flask.application     policy_dict.update(cls._extract_member_target_data(
2023-04-12 01:08:48.107 39 ERROR keystone.server.flask.application   File "/var/lib/kolla/venv/lib/python3.9/site-packages/keystone/common/rbac_enforcer/enforcer.py", line 234, in _extract_member_target_data
2023-04-12 01:08:48.107 39 ERROR keystone.server.flask.application     member_name: func(flask.request.view_args[key])
2023-04-12 01:08:48.107 39 ERROR keystone.server.flask.application   File "/var/lib/kolla/venv/lib/python3.9/site-packages/keystone/common/manager.py", line 115, in wrapped
2023-04-12 01:08:48.107 39 ERROR keystone.server.flask.application     __ret_val = __f(*args, **kwargs)
2023-04-12 01:08:48.107 39 ERROR keystone.server.flask.application   File "/var/lib/kolla/venv/lib/python3.9/site-packages/decorator.py", line 232, in fun
2023-04-12 01:08:48.107 39 ERROR keystone.server.flask.application     return caller(func, *(extras + args), **kw)
2023-04-12 01:08:48.107 39 ERROR keystone.server.flask.application   File "/var/lib/kolla/venv/lib/python3.9/site-packages/dogpile/cache/region.py", line 1577, in get_or_create_for_user_func
2023-04-12 01:08:48.107 39 ERROR keystone.server.flask.application     return self.get_or_create(
2023-04-12 01:08:48.107 39 ERROR keystone.server.flask.application   File "/var/lib/kolla/venv/lib/python3.9/site-packages/dogpile/cache/region.py", line 1042, in get_or_create
2023-04-12 01:08:48.107 39 ERROR keystone.server.flask.application     with Lock(
2023-04-12 01:08:48.107 39 ERROR keystone.server.flask.application   File "/var/lib/kolla/venv/lib/python3.9/site-packages/dogpile/lock.py", line 185, in __enter__
2023-04-12 01:08:48.107 39 ERROR keystone.server.flask.application     return self._enter()
2023-04-12 01:08:48.107 39 ERROR keystone.server.flask.application   File "/var/lib/kolla/venv/lib/python3.9/site-packages/dogpile/lock.py", line 94, in _enter
2023-04-12 01:08:48.107 39 ERROR keystone.server.flask.application     generated = self._enter_create(value, createdtime)
2023-04-12 01:08:48.107 39 ERROR keystone.server.flask.application   File "/var/lib/kolla/venv/lib/python3.9/site-packages/dogpile/lock.py", line 178, in _enter_create
2023-04-12 01:08:48.107 39 ERROR keystone.server.flask.application     return self.creator()
2023-04-12 01:08:48.107 39 ERROR keystone.server.flask.application   File "/var/lib/kolla/venv/lib/python3.9/site-packages/dogpile/cache/region.py", line 995, in gen_value
2023-04-12 01:08:48.107 39 ERROR keystone.server.flask.application     created_value = creator(
2023-04-12 01:08:48.107 39 ERROR keystone.server.flask.application   File "/var/lib/kolla/venv/lib/python3.9/site-packages/keystone/assignment/core.py", line 1276, in get_role
2023-04-12 01:08:48.107 39 ERROR keystone.server.flask.application     return self.driver.get_role(role_id)
2023-04-12 01:08:48.107 39 ERROR keystone.server.flask.application   File "/var/lib/kolla/venv/lib/python3.9/site-packages/keystone/assignment/role_backends/sql.py", line 70, in get_role
2023-04-12 01:08:48.107 39 ERROR keystone.server.flask.application     return self._get_role(session, role_id).to_dict()
2023-04-12 01:08:48.107 39 ERROR keystone.server.flask.application   File "/var/lib/kolla/venv/lib/python3.9/site-packages/keystone/assignment/role_backends/sql.py", line 65, in _get_role
2023-04-12 01:08:48.107 39 ERROR keystone.server.flask.application     raise exception.RoleNotFound(role_id=role_id)
2023-04-12 01:08:48.107 39 ERROR keystone.server.flask.application keystone.exception.RoleNotFound: Could not find role: admin.
2023-04-12 01:08:48.107 39 ERROR keystone.server.flask.application 
2023-04-12 01:08:49.056 39 ERROR keystone.server.flask.application [None req-0f5d4cd9-0051-47f1-9b0e-8e3b1e4d9e74 39f4879392a64163b67509866d91d639 - - all default -] Could not find user: ironic.: keystone.exception.UserNotFound: Could not find user: ironic.
2023-04-12 01:08:49.056 39 ERROR keystone.server.flask.application Traceback (most recent call last):
2023-04-12 01:08:49.056 39 ERROR keystone.server.flask.application   File "/var/lib/kolla/venv/lib/python3.9/site-packages/flask/app.py", line 1820, in full_dispatch_request
2023-04-12 01:08:49.056 39 ERROR keystone.server.flask.application     rv = self.dispatch_request()
2023-04-12 01:08:49.056 39 ERROR keystone.server.flask.application   File "/var/lib/kolla/venv/lib/python3.9/site-packages/flask/app.py", line 1796, in dispatch_request
2023-04-12 01:08:49.056 39 ERROR keystone.server.flask.application     return self.ensure_sync(self.view_functions[rule.endpoint])(**view_args)
2023-04-12 01:08:49.056 39 ERROR keystone.server.flask.application   File "/var/lib/kolla/venv/lib/python3.9/site-packages/flask_restful/__init__.py", line 467, in wrapper
2023-04-12 01:08:49.056 39 ERROR keystone.server.flask.application     resp = resource(*args, **kwargs)
2023-04-12 01:08:49.056 39 ERROR keystone.server.flask.application   File "/var/lib/kolla/venv/lib/python3.9/site-packages/flask/views.py", line 107, in view
2023-04-12 01:08:49.056 39 ERROR keystone.server.flask.application     return current_app.ensure_sync(self.dispatch_request)(**kwargs)
2023-04-12 01:08:49.056 39 ERROR keystone.server.flask.application   File "/var/lib/kolla/venv/lib/python3.9/site-packages/flask_restful/__init__.py", line 582, in dispatch_request
2023-04-12 01:08:49.056 39 ERROR keystone.server.flask.application     resp = meth(*args, **kwargs)
2023-04-12 01:08:49.056 39 ERROR keystone.server.flask.application   File "/var/lib/kolla/venv/lib/python3.9/site-packages/keystone/api/users.py", line 182, in get
2023-04-12 01:08:49.056 39 ERROR keystone.server.flask.application     return self._get_user(user_id)
2023-04-12 01:08:49.056 39 ERROR keystone.server.flask.application   File "/var/lib/kolla/venv/lib/python3.9/site-packages/keystone/api/users.py", line 194, in _get_user
2023-04-12 01:08:49.056 39 ERROR keystone.server.flask.application     ref = PROVIDERS.identity_api.get_user(user_id)
2023-04-12 01:08:49.056 39 ERROR keystone.server.flask.application   File "/var/lib/kolla/venv/lib/python3.9/site-packages/keystone/common/manager.py", line 115, in wrapped
2023-04-12 01:08:49.056 39 ERROR keystone.server.flask.application     __ret_val = __f(*args, **kwargs)
2023-04-12 01:08:49.056 39 ERROR keystone.server.flask.application   File "/var/lib/kolla/venv/lib/python3.9/site-packages/keystone/identity/core.py", line 414, in wrapper
2023-04-12 01:08:49.056 39 ERROR keystone.server.flask.application     return f(self, *args, **kwargs)
2023-04-12 01:08:49.056 39 ERROR keystone.server.flask.application   File "/var/lib/kolla/venv/lib/python3.9/site-packages/keystone/identity/core.py", line 424, in wrapper
2023-04-12 01:08:49.056 39 ERROR keystone.server.flask.application     return f(self, *args, **kwargs)
2023-04-12 01:08:49.056 39 ERROR keystone.server.flask.application   File "/var/lib/kolla/venv/lib/python3.9/site-packages/decorator.py", line 232, in fun
2023-04-12 01:08:49.056 39 ERROR keystone.server.flask.application     return caller(func, *(extras + args), **kw)
2023-04-12 01:08:49.056 39 ERROR keystone.server.flask.application   File "/var/lib/kolla/venv/lib/python3.9/site-packages/dogpile/cache/region.py", line 1577, in get_or_create_for_user_func
2023-04-12 01:08:49.056 39 ERROR keystone.server.flask.application     return self.get_or_create(
2023-04-12 01:08:49.056 39 ERROR keystone.server.flask.application   File "/var/lib/kolla/venv/lib/python3.9/site-packages/dogpile/cache/region.py", line 1042, in get_or_create
2023-04-12 01:08:49.056 39 ERROR keystone.server.flask.application     with Lock(
2023-04-12 01:08:49.056 39 ERROR keystone.server.flask.application   File "/var/lib/kolla/venv/lib/python3.9/site-packages/dogpile/lock.py", line 185, in __enter__
2023-04-12 01:08:49.056 39 ERROR keystone.server.flask.application     return self._enter()
2023-04-12 01:08:49.056 39 ERROR keystone.server.flask.application   File "/var/lib/kolla/venv/lib/python3.9/site-packages/dogpile/lock.py", line 94, in _enter
2023-04-12 01:08:49.056 39 ERROR keystone.server.flask.application     generated = self._enter_create(value, createdtime)
2023-04-12 01:08:49.056 39 ERROR keystone.server.flask.application   File "/var/lib/kolla/venv/lib/python3.9/site-packages/dogpile/lock.py", line 178, in _enter_create
2023-04-12 01:08:49.056 39 ERROR keystone.server.flask.application     return self.creator()
2023-04-12 01:08:49.056 39 ERROR keystone.server.flask.application   File "/var/lib/kolla/venv/lib/python3.9/site-packages/dogpile/cache/region.py", line 995, in gen_value
2023-04-12 01:08:49.056 39 ERROR keystone.server.flask.application     created_value = creator(
2023-04-12 01:08:49.056 39 ERROR keystone.server.flask.application   File "/var/lib/kolla/venv/lib/python3.9/site-packages/keystone/identity/core.py", line 1011, in get_user
2023-04-12 01:08:49.056 39 ERROR keystone.server.flask.application     ref = driver.get_user(entity_id)
2023-04-12 01:08:49.056 39 ERROR keystone.server.flask.application   File "/var/lib/kolla/venv/lib/python3.9/site-packages/keystone/identity/backends/sql.py", line 200, in get_user
2023-04-12 01:08:49.056 39 ERROR keystone.server.flask.application     self._get_user(session, user_id).to_dict())
2023-04-12 01:08:49.056 39 ERROR keystone.server.flask.application   File "/var/lib/kolla/venv/lib/python3.9/site-packages/keystone/identity/backends/sql.py", line 194, in _get_user
2023-04-12 01:08:49.056 39 ERROR keystone.server.flask.application     raise exception.UserNotFound(user_id=user_id)
2023-04-12 01:08:49.056 39 ERROR keystone.server.flask.application keystone.exception.UserNotFound: Could not find user: ironic.
2023-04-12 01:08:49.056 39 ERROR keystone.server.flask.application 
2023-04-12 01:08:49.933 38 ERROR keystone.server.flask.application [None req-ec7068e8-05d0-4f33-8e26-8ee88759e859 39f4879392a64163b67509866d91d639 - - all default -] Could not find project: service.: keystone.exception.ProjectNotFound: Could not find project: service.
2023-04-12 01:08:49.933 38 ERROR keystone.server.flask.application Traceback (most recent call last):
2023-04-12 01:08:49.933 38 ERROR keystone.server.flask.application   File "/var/lib/kolla/venv/lib/python3.9/site-packages/flask/app.py", line 1820, in full_dispatch_request
2023-04-12 01:08:49.933 38 ERROR keystone.server.flask.application     rv = self.dispatch_request()
2023-04-12 01:08:49.933 38 ERROR keystone.server.flask.application   File "/var/lib/kolla/venv/lib/python3.9/site-packages/flask/app.py", line 1796, in dispatch_request
2023-04-12 01:08:49.933 38 ERROR keystone.server.flask.application     return self.ensure_sync(self.view_functions[rule.endpoint])(**view_args)
2023-04-12 01:08:49.933 38 ERROR keystone.server.flask.application   File "/var/lib/kolla/venv/lib/python3.9/site-packages/flask_restful/__init__.py", line 467, in wrapper
2023-04-12 01:08:49.933 38 ERROR keystone.server.flask.application     resp = resource(*args, **kwargs)
2023-04-12 01:08:49.933 38 ERROR keystone.server.flask.application   File "/var/lib/kolla/venv/lib/python3.9/site-packages/flask/views.py", line 107, in view
2023-04-12 01:08:49.933 38 ERROR keystone.server.flask.application     return current_app.ensure_sync(self.dispatch_request)(**kwargs)
2023-04-12 01:08:49.933 38 ERROR keystone.server.flask.application   File "/var/lib/kolla/venv/lib/python3.9/site-packages/flask_restful/__init__.py", line 582, in dispatch_request
2023-04-12 01:08:49.933 38 ERROR keystone.server.flask.application     resp = meth(*args, **kwargs)
2023-04-12 01:08:49.933 38 ERROR keystone.server.flask.application   File "/var/lib/kolla/venv/lib/python3.9/site-packages/keystone/api/projects.py", line 151, in get
2023-04-12 01:08:49.933 38 ERROR keystone.server.flask.application     return self._get_project(project_id)
2023-04-12 01:08:49.933 38 ERROR keystone.server.flask.application   File "/var/lib/kolla/venv/lib/python3.9/site-packages/keystone/api/projects.py", line 107, in _get_project
2023-04-12 01:08:49.933 38 ERROR keystone.server.flask.application     project = PROVIDERS.resource_api.get_project(project_id)
2023-04-12 01:08:49.933 38 ERROR keystone.server.flask.application   File "/var/lib/kolla/venv/lib/python3.9/site-packages/keystone/common/manager.py", line 115, in wrapped
2023-04-12 01:08:49.933 38 ERROR keystone.server.flask.application     __ret_val = __f(*args, **kwargs)
2023-04-12 01:08:49.933 38 ERROR keystone.server.flask.application   File "/var/lib/kolla/venv/lib/python3.9/site-packages/decorator.py", line 232, in fun
2023-04-12 01:08:49.933 38 ERROR keystone.server.flask.application     return caller(func, *(extras + args), **kw)
2023-04-12 01:08:49.933 38 ERROR keystone.server.flask.application   File "/var/lib/kolla/venv/lib/python3.9/site-packages/dogpile/cache/region.py", line 1577, in get_or_create_for_user_func
2023-04-12 01:08:49.933 38 ERROR keystone.server.flask.application     return self.get_or_create(
2023-04-12 01:08:49.933 38 ERROR keystone.server.flask.application   File "/var/lib/kolla/venv/lib/python3.9/site-packages/dogpile/cache/region.py", line 1042, in get_or_create
2023-04-12 01:08:49.933 38 ERROR keystone.server.flask.application     with Lock(
2023-04-12 01:08:49.933 38 ERROR keystone.server.flask.application   File "/var/lib/kolla/venv/lib/python3.9/site-packages/dogpile/lock.py", line 185, in __enter__
2023-04-12 01:08:49.933 38 ERROR keystone.server.flask.application     return self._enter()
2023-04-12 01:08:49.933 38 ERROR keystone.server.flask.application   File "/var/lib/kolla/venv/lib/python3.9/site-packages/dogpile/lock.py", line 94, in _enter
2023-04-12 01:08:49.933 38 ERROR keystone.server.flask.application     generated = self._enter_create(value, createdtime)
2023-04-12 01:08:49.933 38 ERROR keystone.server.flask.application   File "/var/lib/kolla/venv/lib/python3.9/site-packages/dogpile/lock.py", line 178, in _enter_create
2023-04-12 01:08:49.933 38 ERROR keystone.server.flask.application     return self.creator()
2023-04-12 01:08:49.933 38 ERROR keystone.server.flask.application   File "/var/lib/kolla/venv/lib/python3.9/site-packages/dogpile/cache/region.py", line 995, in gen_value
2023-04-12 01:08:49.933 38 ERROR keystone.server.flask.application     created_value = creator(
2023-04-12 01:08:49.933 38 ERROR keystone.server.flask.application   File "/var/lib/kolla/venv/lib/python3.9/site-packages/keystone/resource/core.py", line 903, in get_project
2023-04-12 01:08:49.933 38 ERROR keystone.server.flask.application     return self.driver.get_project(project_id)
2023-04-12 01:08:49.933 38 ERROR keystone.server.flask.application   File "/var/lib/kolla/venv/lib/python3.9/site-packages/keystone/resource/backends/sql.py", line 49, in get_project
2023-04-12 01:08:49.933 38 ERROR keystone.server.flask.application     return self._get_project(session, project_id).to_dict()
2023-04-12 01:08:49.933 38 ERROR keystone.server.flask.application   File "/var/lib/kolla/venv/lib/python3.9/site-packages/keystone/resource/backends/sql.py", line 44, in _get_project
2023-04-12 01:08:49.933 38 ERROR keystone.server.flask.application     raise exception.ProjectNotFound(project_id=project_id)
2023-04-12 01:08:49.933 38 ERROR keystone.server.flask.application keystone.exception.ProjectNotFound: Could not find project: service.
2023-04-12 01:08:49.933 38 ERROR keystone.server.flask.application 
2023-04-12 01:08:59.668 37 ERROR keystone.server.flask.application [None req-93f2950f-f453-4ec0-b782-1118a9d82e62 39f4879392a64163b67509866d91d639 - - all default -] Could not find role: admin.: keystone.exception.RoleNotFound: Could not find role: admin.
2023-04-12 01:08:59.668 37 ERROR keystone.server.flask.application Traceback (most recent call last):
2023-04-12 01:08:59.668 37 ERROR keystone.server.flask.application   File "/var/lib/kolla/venv/lib/python3.9/site-packages/flask/app.py", line 1820, in full_dispatch_request
2023-04-12 01:08:59.668 37 ERROR keystone.server.flask.application     rv = self.dispatch_request()
2023-04-12 01:08:59.668 37 ERROR keystone.server.flask.application   File "/var/lib/kolla/venv/lib/python3.9/site-packages/flask/app.py", line 1796, in dispatch_request
2023-04-12 01:08:59.668 37 ERROR keystone.server.flask.application     return self.ensure_sync(self.view_functions[rule.endpoint])(**view_args)
2023-04-12 01:08:59.668 37 ERROR keystone.server.flask.application   File "/var/lib/kolla/venv/lib/python3.9/site-packages/flask_restful/__init__.py", line 467, in wrapper
2023-04-12 01:08:59.668 37 ERROR keystone.server.flask.application     resp = resource(*args, **kwargs)
2023-04-12 01:08:59.668 37 ERROR keystone.server.flask.application   File "/var/lib/kolla/venv/lib/python3.9/site-packages/flask/views.py", line 107, in view
2023-04-12 01:08:59.668 37 ERROR keystone.server.flask.application     return current_app.ensure_sync(self.dispatch_request)(**kwargs)
2023-04-12 01:08:59.668 37 ERROR keystone.server.flask.application   File "/var/lib/kolla/venv/lib/python3.9/site-packages/flask_restful/__init__.py", line 582, in dispatch_request
2023-04-12 01:08:59.668 37 ERROR keystone.server.flask.application     resp = meth(*args, **kwargs)
2023-04-12 01:08:59.668 37 ERROR keystone.server.flask.application   File "/var/lib/kolla/venv/lib/python3.9/site-packages/keystone/api/roles.py", line 50, in get
2023-04-12 01:08:59.668 37 ERROR keystone.server.flask.application     return self._get_role(role_id)
2023-04-12 01:08:59.668 37 ERROR keystone.server.flask.application   File "/var/lib/kolla/venv/lib/python3.9/site-packages/keystone/api/roles.py", line 70, in _get_role
2023-04-12 01:08:59.668 37 ERROR keystone.server.flask.application     ENFORCER.enforce_call(action='identity:get_role')
2023-04-12 01:08:59.668 37 ERROR keystone.server.flask.application   File "/var/lib/kolla/venv/lib/python3.9/site-packages/keystone/common/rbac_enforcer/enforcer.py", line 402, in enforce_call
2023-04-12 01:08:59.668 37 ERROR keystone.server.flask.application     policy_dict.update(cls._extract_member_target_data(
2023-04-12 01:08:59.668 37 ERROR keystone.server.flask.application   File "/var/lib/kolla/venv/lib/python3.9/site-packages/keystone/common/rbac_enforcer/enforcer.py", line 234, in _extract_member_target_data
2023-04-12 01:08:59.668 37 ERROR keystone.server.flask.application     member_name: func(flask.request.view_args[key])
2023-04-12 01:08:59.668 37 ERROR keystone.server.flask.application   File "/var/lib/kolla/venv/lib/python3.9/site-packages/keystone/common/manager.py", line 115, in wrapped
2023-04-12 01:08:59.668 37 ERROR keystone.server.flask.application     __ret_val = __f(*args, **kwargs)
2023-04-12 01:08:59.668 37 ERROR keystone.server.flask.application   File "/var/lib/kolla/venv/lib/python3.9/site-packages/decorator.py", line 232, in fun
2023-04-12 01:08:59.668 37 ERROR keystone.server.flask.application     return caller(func, *(extras + args), **kw)
2023-04-12 01:08:59.668 37 ERROR keystone.server.flask.application   File "/var/lib/kolla/venv/lib/python3.9/site-packages/dogpile/cache/region.py", line 1577, in get_or_create_for_user_func
2023-04-12 01:08:59.668 37 ERROR keystone.server.flask.application     return self.get_or_create(
2023-04-12 01:08:59.668 37 ERROR keystone.server.flask.application   File "/var/lib/kolla/venv/lib/python3.9/site-packages/dogpile/cache/region.py", line 1042, in get_or_create
2023-04-12 01:08:59.668 37 ERROR keystone.server.flask.application     with Lock(
2023-04-12 01:08:59.668 37 ERROR keystone.server.flask.application   File "/var/lib/kolla/venv/lib/python3.9/site-packages/dogpile/lock.py", line 185, in __enter__
2023-04-12 01:08:59.668 37 ERROR keystone.server.flask.application     return self._enter()
2023-04-12 01:08:59.668 37 ERROR keystone.server.flask.application   File "/var/lib/kolla/venv/lib/python3.9/site-packages/dogpile/lock.py", line 94, in _enter
2023-04-12 01:08:59.668 37 ERROR keystone.server.flask.application     generated = self._enter_create(value, createdtime)
2023-04-12 01:08:59.668 37 ERROR keystone.server.flask.application   File "/var/lib/kolla/venv/lib/python3.9/site-packages/dogpile/lock.py", line 178, in _enter_create
2023-04-12 01:08:59.668 37 ERROR keystone.server.flask.application     return self.creator()
2023-04-12 01:08:59.668 37 ERROR keystone.server.flask.application   File "/var/lib/kolla/venv/lib/python3.9/site-packages/dogpile/cache/region.py", line 995, in gen_value
2023-04-12 01:08:59.668 37 ERROR keystone.server.flask.application     created_value = creator(
2023-04-12 01:08:59.668 37 ERROR keystone.server.flask.application   File "/var/lib/kolla/venv/lib/python3.9/site-packages/keystone/assignment/core.py", line 1276, in get_role
2023-04-12 01:08:59.668 37 ERROR keystone.server.flask.application     return self.driver.get_role(role_id)
2023-04-12 01:08:59.668 37 ERROR keystone.server.flask.application   File "/var/lib/kolla/venv/lib/python3.9/site-packages/keystone/assignment/role_backends/sql.py", line 70, in get_role
2023-04-12 01:08:59.668 37 ERROR keystone.server.flask.application     return self._get_role(session, role_id).to_dict()
2023-04-12 01:08:59.668 37 ERROR keystone.server.flask.application   File "/var/lib/kolla/venv/lib/python3.9/site-packages/keystone/assignment/role_backends/sql.py", line 65, in _get_role
2023-04-12 01:08:59.668 37 ERROR keystone.server.flask.application     raise exception.RoleNotFound(role_id=role_id)
2023-04-12 01:08:59.668 37 ERROR keystone.server.flask.application keystone.exception.RoleNotFound: Could not find role: admin.
2023-04-12 01:08:59.668 37 ERROR keystone.server.flask.application 
2023-04-12 01:09:00.721 37 ERROR keystone.server.flask.application [None req-94043bdd-66c6-41f5-93c4-3a2176e7afd8 39f4879392a64163b67509866d91d639 - - all default -] Could not find user: ironic-inspector.: keystone.exception.UserNotFound: Could not find user: ironic-inspector.
2023-04-12 01:09:00.721 37 ERROR keystone.server.flask.application Traceback (most recent call last):
2023-04-12 01:09:00.721 37 ERROR keystone.server.flask.application   File "/var/lib/kolla/venv/lib/python3.9/site-packages/flask/app.py", line 1820, in full_dispatch_request
2023-04-12 01:09:00.721 37 ERROR keystone.server.flask.application     rv = self.dispatch_request()
2023-04-12 01:09:00.721 37 ERROR keystone.server.flask.application   File "/var/lib/kolla/venv/lib/python3.9/site-packages/flask/app.py", line 1796, in dispatch_request
2023-04-12 01:09:00.721 37 ERROR keystone.server.flask.application     return self.ensure_sync(self.view_functions[rule.endpoint])(**view_args)
2023-04-12 01:09:00.721 37 ERROR keystone.server.flask.application   File "/var/lib/kolla/venv/lib/python3.9/site-packages/flask_restful/__init__.py", line 467, in wrapper
2023-04-12 01:09:00.721 37 ERROR keystone.server.flask.application     resp = resource(*args, **kwargs)
2023-04-12 01:09:00.721 37 ERROR keystone.server.flask.application   File "/var/lib/kolla/venv/lib/python3.9/site-packages/flask/views.py", line 107, in view
2023-04-12 01:09:00.721 37 ERROR keystone.server.flask.application     return current_app.ensure_sync(self.dispatch_request)(**kwargs)
2023-04-12 01:09:00.721 37 ERROR keystone.server.flask.application   File "/var/lib/kolla/venv/lib/python3.9/site-packages/flask_restful/__init__.py", line 582, in dispatch_request
2023-04-12 01:09:00.721 37 ERROR keystone.server.flask.application     resp = meth(*args, **kwargs)
2023-04-12 01:09:00.721 37 ERROR keystone.server.flask.application   File "/var/lib/kolla/venv/lib/python3.9/site-packages/keystone/api/users.py", line 182, in get
2023-04-12 01:09:00.721 37 ERROR keystone.server.flask.application     return self._get_user(user_id)
2023-04-12 01:09:00.721 37 ERROR keystone.server.flask.application   File "/var/lib/kolla/venv/lib/python3.9/site-packages/keystone/api/users.py", line 194, in _get_user
2023-04-12 01:09:00.721 37 ERROR keystone.server.flask.application     ref = PROVIDERS.identity_api.get_user(user_id)
2023-04-12 01:09:00.721 37 ERROR keystone.server.flask.application   File "/var/lib/kolla/venv/lib/python3.9/site-packages/keystone/common/manager.py", line 115, in wrapped
2023-04-12 01:09:00.721 37 ERROR keystone.server.flask.application     __ret_val = __f(*args, **kwargs)
2023-04-12 01:09:00.721 37 ERROR keystone.server.flask.application   File "/var/lib/kolla/venv/lib/python3.9/site-packages/keystone/identity/core.py", line 414, in wrapper
2023-04-12 01:09:00.721 37 ERROR keystone.server.flask.application     return f(self, *args, **kwargs)
2023-04-12 01:09:00.721 37 ERROR keystone.server.flask.application   File "/var/lib/kolla/venv/lib/python3.9/site-packages/keystone/identity/core.py", line 424, in wrapper
2023-04-12 01:09:00.721 37 ERROR keystone.server.flask.application     return f(self, *args, **kwargs)
2023-04-12 01:09:00.721 37 ERROR keystone.server.flask.application   File "/var/lib/kolla/venv/lib/python3.9/site-packages/decorator.py", line 232, in fun
2023-04-12 01:09:00.721 37 ERROR keystone.server.flask.application     return caller(func, *(extras + args), **kw)
2023-04-12 01:09:00.721 37 ERROR keystone.server.flask.application   File "/var/lib/kolla/venv/lib/python3.9/site-packages/dogpile/cache/region.py", line 1577, in get_or_create_for_user_func
2023-04-12 01:09:00.721 37 ERROR keystone.server.flask.application     return self.get_or_create(
2023-04-12 01:09:00.721 37 ERROR keystone.server.flask.application   File "/var/lib/kolla/venv/lib/python3.9/site-packages/dogpile/cache/region.py", line 1042, in get_or_create
2023-04-12 01:09:00.721 37 ERROR keystone.server.flask.application     with Lock(
2023-04-12 01:09:00.721 37 ERROR keystone.server.flask.application   File "/var/lib/kolla/venv/lib/python3.9/site-packages/dogpile/lock.py", line 185, in __enter__
2023-04-12 01:09:00.721 37 ERROR keystone.server.flask.application     return self._enter()
2023-04-12 01:09:00.721 37 ERROR keystone.server.flask.application   File "/var/lib/kolla/venv/lib/python3.9/site-packages/dogpile/lock.py", line 94, in _enter
2023-04-12 01:09:00.721 37 ERROR keystone.server.flask.application     generated = self._enter_create(value, createdtime)
2023-04-12 01:09:00.721 37 ERROR keystone.server.flask.application   File "/var/lib/kolla/venv/lib/python3.9/site-packages/dogpile/lock.py", line 178, in _enter_create
2023-04-12 01:09:00.721 37 ERROR keystone.server.flask.application     return self.creator()
2023-04-12 01:09:00.721 37 ERROR keystone.server.flask.application   File "/var/lib/kolla/venv/lib/python3.9/site-packages/dogpile/cache/region.py", line 995, in gen_value
2023-04-12 01:09:00.721 37 ERROR keystone.server.flask.application     created_value = creator(
2023-04-12 01:09:00.721 37 ERROR keystone.server.flask.application   File "/var/lib/kolla/venv/lib/python3.9/site-packages/keystone/identity/core.py", line 1011, in get_user
2023-04-12 01:09:00.721 37 ERROR keystone.server.flask.application     ref = driver.get_user(entity_id)
2023-04-12 01:09:00.721 37 ERROR keystone.server.flask.application   File "/var/lib/kolla/venv/lib/python3.9/site-packages/keystone/identity/backends/sql.py", line 200, in get_user
2023-04-12 01:09:00.721 37 ERROR keystone.server.flask.application     self._get_user(session, user_id).to_dict())
2023-04-12 01:09:00.721 37 ERROR keystone.server.flask.application   File "/var/lib/kolla/venv/lib/python3.9/site-packages/keystone/identity/backends/sql.py", line 194, in _get_user
2023-04-12 01:09:00.721 37 ERROR keystone.server.flask.application     raise exception.UserNotFound(user_id=user_id)
2023-04-12 01:09:00.721 37 ERROR keystone.server.flask.application keystone.exception.UserNotFound: Could not find user: ironic-inspector.
2023-04-12 01:09:00.721 37 ERROR keystone.server.flask.application 
2023-04-12 01:09:01.528 39 ERROR keystone.server.flask.application [None req-715a8122-e197-4074-bfe5-8296c6d60193 39f4879392a64163b67509866d91d639 - - all default -] Could not find project: service.: keystone.exception.ProjectNotFound: Could not find project: service.
2023-04-12 01:09:01.528 39 ERROR keystone.server.flask.application Traceback (most recent call last):
2023-04-12 01:09:01.528 39 ERROR keystone.server.flask.application   File "/var/lib/kolla/venv/lib/python3.9/site-packages/flask/app.py", line 1820, in full_dispatch_request
2023-04-12 01:09:01.528 39 ERROR keystone.server.flask.application     rv = self.dispatch_request()
2023-04-12 01:09:01.528 39 ERROR keystone.server.flask.application   File "/var/lib/kolla/venv/lib/python3.9/site-packages/flask/app.py", line 1796, in dispatch_request
2023-04-12 01:09:01.528 39 ERROR keystone.server.flask.application     return self.ensure_sync(self.view_functions[rule.endpoint])(**view_args)
2023-04-12 01:09:01.528 39 ERROR keystone.server.flask.application   File "/var/lib/kolla/venv/lib/python3.9/site-packages/flask_restful/__init__.py", line 467, in wrapper
2023-04-12 01:09:01.528 39 ERROR keystone.server.flask.application     resp = resource(*args, **kwargs)
2023-04-12 01:09:01.528 39 ERROR keystone.server.flask.application   File "/var/lib/kolla/venv/lib/python3.9/site-packages/flask/views.py", line 107, in view
2023-04-12 01:09:01.528 39 ERROR keystone.server.flask.application     return current_app.ensure_sync(self.dispatch_request)(**kwargs)
2023-04-12 01:09:01.528 39 ERROR keystone.server.flask.application   File "/var/lib/kolla/venv/lib/python3.9/site-packages/flask_restful/__init__.py", line 582, in dispatch_request
2023-04-12 01:09:01.528 39 ERROR keystone.server.flask.application     resp = meth(*args, **kwargs)
2023-04-12 01:09:01.528 39 ERROR keystone.server.flask.application   File "/var/lib/kolla/venv/lib/python3.9/site-packages/keystone/api/projects.py", line 151, in get
2023-04-12 01:09:01.528 39 ERROR keystone.server.flask.application     return self._get_project(project_id)
2023-04-12 01:09:01.528 39 ERROR keystone.server.flask.application   File "/var/lib/kolla/venv/lib/python3.9/site-packages/keystone/api/projects.py", line 107, in _get_project
2023-04-12 01:09:01.528 39 ERROR keystone.server.flask.application     project = PROVIDERS.resource_api.get_project(project_id)
2023-04-12 01:09:01.528 39 ERROR keystone.server.flask.application   File "/var/lib/kolla/venv/lib/python3.9/site-packages/keystone/common/manager.py", line 115, in wrapped
2023-04-12 01:09:01.528 39 ERROR keystone.server.flask.application     __ret_val = __f(*args, **kwargs)
2023-04-12 01:09:01.528 39 ERROR keystone.server.flask.application   File "/var/lib/kolla/venv/lib/python3.9/site-packages/decorator.py", line 232, in fun
2023-04-12 01:09:01.528 39 ERROR keystone.server.flask.application     return caller(func, *(extras + args), **kw)
2023-04-12 01:09:01.528 39 ERROR keystone.server.flask.application   File "/var/lib/kolla/venv/lib/python3.9/site-packages/dogpile/cache/region.py", line 1577, in get_or_create_for_user_func
2023-04-12 01:09:01.528 39 ERROR keystone.server.flask.application     return self.get_or_create(
2023-04-12 01:09:01.528 39 ERROR keystone.server.flask.application   File "/var/lib/kolla/venv/lib/python3.9/site-packages/dogpile/cache/region.py", line 1042, in get_or_create
2023-04-12 01:09:01.528 39 ERROR keystone.server.flask.application     with Lock(
2023-04-12 01:09:01.528 39 ERROR keystone.server.flask.application   File "/var/lib/kolla/venv/lib/python3.9/site-packages/dogpile/lock.py", line 185, in __enter__
2023-04-12 01:09:01.528 39 ERROR keystone.server.flask.application     return self._enter()
2023-04-12 01:09:01.528 39 ERROR keystone.server.flask.application   File "/var/lib/kolla/venv/lib/python3.9/site-packages/dogpile/lock.py", line 94, in _enter
2023-04-12 01:09:01.528 39 ERROR keystone.server.flask.application     generated = self._enter_create(value, createdtime)
2023-04-12 01:09:01.528 39 ERROR keystone.server.flask.application   File "/var/lib/kolla/venv/lib/python3.9/site-packages/dogpile/lock.py", line 178, in _enter_create
2023-04-12 01:09:01.528 39 ERROR keystone.server.flask.application     return self.creator()
2023-04-12 01:09:01.528 39 ERROR keystone.server.flask.application   File "/var/lib/kolla/venv/lib/python3.9/site-packages/dogpile/cache/region.py", line 995, in gen_value
2023-04-12 01:09:01.528 39 ERROR keystone.server.flask.application     created_value = creator(
2023-04-12 01:09:01.528 39 ERROR keystone.server.flask.application   File "/var/lib/kolla/venv/lib/python3.9/site-packages/keystone/resource/core.py", line 903, in get_project
2023-04-12 01:09:01.528 39 ERROR keystone.server.flask.application     return self.driver.get_project(project_id)
2023-04-12 01:09:01.528 39 ERROR keystone.server.flask.application   File "/var/lib/kolla/venv/lib/python3.9/site-packages/keystone/resource/backends/sql.py", line 49, in get_project
2023-04-12 01:09:01.528 39 ERROR keystone.server.flask.application     return self._get_project(session, project_id).to_dict()
2023-04-12 01:09:01.528 39 ERROR keystone.server.flask.application   File "/var/lib/kolla/venv/lib/python3.9/site-packages/keystone/resource/backends/sql.py", line 44, in _get_project
2023-04-12 01:09:01.528 39 ERROR keystone.server.flask.application     raise exception.ProjectNotFound(project_id=project_id)
2023-04-12 01:09:01.528 39 ERROR keystone.server.flask.application keystone.exception.ProjectNotFound: Could not find project: service.
2023-04-12 01:09:01.528 39 ERROR keystone.server.flask.application 
2023-04-12 01:11:47.730 37 ERROR keystone.server.flask.application [None req-9e94d7be-6629-4c35-ab32-1c997b6c8f3d 39f4879392a64163b67509866d91d639 - - all default -] Could not find project: service.: keystone.exception.ProjectNotFound: Could not find project: service.
2023-04-12 01:11:47.730 37 ERROR keystone.server.flask.application Traceback (most recent call last):
2023-04-12 01:11:47.730 37 ERROR keystone.server.flask.application   File "/var/lib/kolla/venv/lib/python3.9/site-packages/flask/app.py", line 1820, in full_dispatch_request
2023-04-12 01:11:47.730 37 ERROR keystone.server.flask.application     rv = self.dispatch_request()
2023-04-12 01:11:47.730 37 ERROR keystone.server.flask.application   File "/var/lib/kolla/venv/lib/python3.9/site-packages/flask/app.py", line 1796, in dispatch_request
2023-04-12 01:11:47.730 37 ERROR keystone.server.flask.application     return self.ensure_sync(self.view_functions[rule.endpoint])(**view_args)
2023-04-12 01:11:47.730 37 ERROR keystone.server.flask.application   File "/var/lib/kolla/venv/lib/python3.9/site-packages/flask_restful/__init__.py", line 467, in wrapper
2023-04-12 01:11:47.730 37 ERROR keystone.server.flask.application     resp = resource(*args, **kwargs)
2023-04-12 01:11:47.730 37 ERROR keystone.server.flask.application   File "/var/lib/kolla/venv/lib/python3.9/site-packages/flask/views.py", line 107, in view
2023-04-12 01:11:47.730 37 ERROR keystone.server.flask.application     return current_app.ensure_sync(self.dispatch_request)(**kwargs)
2023-04-12 01:11:47.730 37 ERROR keystone.server.flask.application   File "/var/lib/kolla/venv/lib/python3.9/site-packages/flask_restful/__init__.py", line 582, in dispatch_request
2023-04-12 01:11:47.730 37 ERROR keystone.server.flask.application     resp = meth(*args, **kwargs)
2023-04-12 01:11:47.730 37 ERROR keystone.server.flask.application   File "/var/lib/kolla/venv/lib/python3.9/site-packages/keystone/api/projects.py", line 151, in get
2023-04-12 01:11:47.730 37 ERROR keystone.server.flask.application     return self._get_project(project_id)
2023-04-12 01:11:47.730 37 ERROR keystone.server.flask.application   File "/var/lib/kolla/venv/lib/python3.9/site-packages/keystone/api/projects.py", line 107, in _get_project
2023-04-12 01:11:47.730 37 ERROR keystone.server.flask.application     project = PROVIDERS.resource_api.get_project(project_id)
2023-04-12 01:11:47.730 37 ERROR keystone.server.flask.application   File "/var/lib/kolla/venv/lib/python3.9/site-packages/keystone/common/manager.py", line 115, in wrapped
2023-04-12 01:11:47.730 37 ERROR keystone.server.flask.application     __ret_val = __f(*args, **kwargs)
2023-04-12 01:11:47.730 37 ERROR keystone.server.flask.application   File "/var/lib/kolla/venv/lib/python3.9/site-packages/decorator.py", line 232, in fun
2023-04-12 01:11:47.730 37 ERROR keystone.server.flask.application     return caller(func, *(extras + args), **kw)
2023-04-12 01:11:47.730 37 ERROR keystone.server.flask.application   File "/var/lib/kolla/venv/lib/python3.9/site-packages/dogpile/cache/region.py", line 1577, in get_or_create_for_user_func
2023-04-12 01:11:47.730 37 ERROR keystone.server.flask.application     return self.get_or_create(
2023-04-12 01:11:47.730 37 ERROR keystone.server.flask.application   File "/var/lib/kolla/venv/lib/python3.9/site-packages/dogpile/cache/region.py", line 1042, in get_or_create
2023-04-12 01:11:47.730 37 ERROR keystone.server.flask.application     with Lock(
2023-04-12 01:11:47.730 37 ERROR keystone.server.flask.application   File "/var/lib/kolla/venv/lib/python3.9/site-packages/dogpile/lock.py", line 185, in __enter__
2023-04-12 01:11:47.730 37 ERROR keystone.server.flask.application     return self._enter()
2023-04-12 01:11:47.730 37 ERROR keystone.server.flask.application   File "/var/lib/kolla/venv/lib/python3.9/site-packages/dogpile/lock.py", line 94, in _enter
2023-04-12 01:11:47.730 37 ERROR keystone.server.flask.application     generated = self._enter_create(value, createdtime)
2023-04-12 01:11:47.730 37 ERROR keystone.server.flask.application   File "/var/lib/kolla/venv/lib/python3.9/site-packages/dogpile/lock.py", line 178, in _enter_create
2023-04-12 01:11:47.730 37 ERROR keystone.server.flask.application     return self.creator()
2023-04-12 01:11:47.730 37 ERROR keystone.server.flask.application   File "/var/lib/kolla/venv/lib/python3.9/site-packages/dogpile/cache/region.py", line 995, in gen_value
2023-04-12 01:11:47.730 37 ERROR keystone.server.flask.application     created_value = creator(
2023-04-12 01:11:47.730 37 ERROR keystone.server.flask.application   File "/var/lib/kolla/venv/lib/python3.9/site-packages/keystone/resource/core.py", line 903, in get_project
2023-04-12 01:11:47.730 37 ERROR keystone.server.flask.application     return self.driver.get_project(project_id)
2023-04-12 01:11:47.730 37 ERROR keystone.server.flask.application   File "/var/lib/kolla/venv/lib/python3.9/site-packages/keystone/resource/backends/sql.py", line 49, in get_project
2023-04-12 01:11:47.730 37 ERROR keystone.server.flask.application     return self._get_project(session, project_id).to_dict()
2023-04-12 01:11:47.730 37 ERROR keystone.server.flask.application   File "/var/lib/kolla/venv/lib/python3.9/site-packages/keystone/resource/backends/sql.py", line 44, in _get_project
2023-04-12 01:11:47.730 37 ERROR keystone.server.flask.application     raise exception.ProjectNotFound(project_id=project_id)
2023-04-12 01:11:47.730 37 ERROR keystone.server.flask.application keystone.exception.ProjectNotFound: Could not find project: service.
2023-04-12 01:11:47.730 37 ERROR keystone.server.flask.application 
2023-04-12 01:12:04.012 38 ERROR keystone.server.flask.application [None req-754df1c6-2dcb-4b23-a2f4-a54fb8f6048a 39f4879392a64163b67509866d91d639 - - all default -] Could not find role: admin.: keystone.exception.RoleNotFound: Could not find role: admin.
2023-04-12 01:12:04.012 38 ERROR keystone.server.flask.application Traceback (most recent call last):
2023-04-12 01:12:04.012 38 ERROR keystone.server.flask.application   File "/var/lib/kolla/venv/lib/python3.9/site-packages/flask/app.py", line 1820, in full_dispatch_request
2023-04-12 01:12:04.012 38 ERROR keystone.server.flask.application     rv = self.dispatch_request()
2023-04-12 01:12:04.012 38 ERROR keystone.server.flask.application   File "/var/lib/kolla/venv/lib/python3.9/site-packages/flask/app.py", line 1796, in dispatch_request
2023-04-12 01:12:04.012 38 ERROR keystone.server.flask.application     return self.ensure_sync(self.view_functions[rule.endpoint])(**view_args)
2023-04-12 01:12:04.012 38 ERROR keystone.server.flask.application   File "/var/lib/kolla/venv/lib/python3.9/site-packages/flask_restful/__init__.py", line 467, in wrapper
2023-04-12 01:12:04.012 38 ERROR keystone.server.flask.application     resp = resource(*args, **kwargs)
2023-04-12 01:12:04.012 38 ERROR keystone.server.flask.application   File "/var/lib/kolla/venv/lib/python3.9/site-packages/flask/views.py", line 107, in view
2023-04-12 01:12:04.012 38 ERROR keystone.server.flask.application     return current_app.ensure_sync(self.dispatch_request)(**kwargs)
2023-04-12 01:12:04.012 38 ERROR keystone.server.flask.application   File "/var/lib/kolla/venv/lib/python3.9/site-packages/flask_restful/__init__.py", line 582, in dispatch_request
2023-04-12 01:12:04.012 38 ERROR keystone.server.flask.application     resp = meth(*args, **kwargs)
2023-04-12 01:12:04.012 38 ERROR keystone.server.flask.application   File "/var/lib/kolla/venv/lib/python3.9/site-packages/keystone/api/roles.py", line 50, in get
2023-04-12 01:12:04.012 38 ERROR keystone.server.flask.application     return self._get_role(role_id)
2023-04-12 01:12:04.012 38 ERROR keystone.server.flask.application   File "/var/lib/kolla/venv/lib/python3.9/site-packages/keystone/api/roles.py", line 70, in _get_role
2023-04-12 01:12:04.012 38 ERROR keystone.server.flask.application     ENFORCER.enforce_call(action='identity:get_role')
2023-04-12 01:12:04.012 38 ERROR keystone.server.flask.application   File "/var/lib/kolla/venv/lib/python3.9/site-packages/keystone/common/rbac_enforcer/enforcer.py", line 402, in enforce_call
2023-04-12 01:12:04.012 38 ERROR keystone.server.flask.application     policy_dict.update(cls._extract_member_target_data(
2023-04-12 01:12:04.012 38 ERROR keystone.server.flask.application   File "/var/lib/kolla/venv/lib/python3.9/site-packages/keystone/common/rbac_enforcer/enforcer.py", line 234, in _extract_member_target_data
2023-04-12 01:12:04.012 38 ERROR keystone.server.flask.application     member_name: func(flask.request.view_args[key])
2023-04-12 01:12:04.012 38 ERROR keystone.server.flask.application   File "/var/lib/kolla/venv/lib/python3.9/site-packages/keystone/common/manager.py", line 115, in wrapped
2023-04-12 01:12:04.012 38 ERROR keystone.server.flask.application     __ret_val = __f(*args, **kwargs)
2023-04-12 01:12:04.012 38 ERROR keystone.server.flask.application   File "/var/lib/kolla/venv/lib/python3.9/site-packages/decorator.py", line 232, in fun
2023-04-12 01:12:04.012 38 ERROR keystone.server.flask.application     return caller(func, *(extras + args), **kw)
2023-04-12 01:12:04.012 38 ERROR keystone.server.flask.application   File "/var/lib/kolla/venv/lib/python3.9/site-packages/dogpile/cache/region.py", line 1577, in get_or_create_for_user_func
2023-04-12 01:12:04.012 38 ERROR keystone.server.flask.application     return self.get_or_create(
2023-04-12 01:12:04.012 38 ERROR keystone.server.flask.application   File "/var/lib/kolla/venv/lib/python3.9/site-packages/dogpile/cache/region.py", line 1042, in get_or_create
2023-04-12 01:12:04.012 38 ERROR keystone.server.flask.application     with Lock(
2023-04-12 01:12:04.012 38 ERROR keystone.server.flask.application   File "/var/lib/kolla/venv/lib/python3.9/site-packages/dogpile/lock.py", line 185, in __enter__
2023-04-12 01:12:04.012 38 ERROR keystone.server.flask.application     return self._enter()
2023-04-12 01:12:04.012 38 ERROR keystone.server.flask.application   File "/var/lib/kolla/venv/lib/python3.9/site-packages/dogpile/lock.py", line 94, in _enter
2023-04-12 01:12:04.012 38 ERROR keystone.server.flask.application     generated = self._enter_create(value, createdtime)
2023-04-12 01:12:04.012 38 ERROR keystone.server.flask.application   File "/var/lib/kolla/venv/lib/python3.9/site-packages/dogpile/lock.py", line 178, in _enter_create
2023-04-12 01:12:04.012 38 ERROR keystone.server.flask.application     return self.creator()
2023-04-12 01:12:04.012 38 ERROR keystone.server.flask.application   File "/var/lib/kolla/venv/lib/python3.9/site-packages/dogpile/cache/region.py", line 995, in gen_value
2023-04-12 01:12:04.012 38 ERROR keystone.server.flask.application     created_value = creator(
2023-04-12 01:12:04.012 38 ERROR keystone.server.flask.application   File "/var/lib/kolla/venv/lib/python3.9/site-packages/keystone/assignment/core.py", line 1276, in get_role
2023-04-12 01:12:04.012 38 ERROR keystone.server.flask.application     return self.driver.get_role(role_id)
2023-04-12 01:12:04.012 38 ERROR keystone.server.flask.application   File "/var/lib/kolla/venv/lib/python3.9/site-packages/keystone/assignment/role_backends/sql.py", line 70, in get_role
2023-04-12 01:12:04.012 38 ERROR keystone.server.flask.application     return self._get_role(session, role_id).to_dict()
2023-04-12 01:12:04.012 38 ERROR keystone.server.flask.application   File "/var/lib/kolla/venv/lib/python3.9/site-packages/keystone/assignment/role_backends/sql.py", line 65, in _get_role
2023-04-12 01:12:04.012 38 ERROR keystone.server.flask.application     raise exception.RoleNotFound(role_id=role_id)
2023-04-12 01:12:04.012 38 ERROR keystone.server.flask.application keystone.exception.RoleNotFound: Could not find role: admin.
2023-04-12 01:12:04.012 38 ERROR keystone.server.flask.application 
2023-04-12 01:12:05.100 38 ERROR keystone.server.flask.application [None req-de93e12f-5012-4ae1-a844-8f68ad662c09 39f4879392a64163b67509866d91d639 - - all default -] Could not find user: neutron.: keystone.exception.UserNotFound: Could not find user: neutron.
2023-04-12 01:12:05.100 38 ERROR keystone.server.flask.application Traceback (most recent call last):
2023-04-12 01:12:05.100 38 ERROR keystone.server.flask.application   File "/var/lib/kolla/venv/lib/python3.9/site-packages/flask/app.py", line 1820, in full_dispatch_request
2023-04-12 01:12:05.100 38 ERROR keystone.server.flask.application     rv = self.dispatch_request()
2023-04-12 01:12:05.100 38 ERROR keystone.server.flask.application   File "/var/lib/kolla/venv/lib/python3.9/site-packages/flask/app.py", line 1796, in dispatch_request
2023-04-12 01:12:05.100 38 ERROR keystone.server.flask.application     return self.ensure_sync(self.view_functions[rule.endpoint])(**view_args)
2023-04-12 01:12:05.100 38 ERROR keystone.server.flask.application   File "/var/lib/kolla/venv/lib/python3.9/site-packages/flask_restful/__init__.py", line 467, in wrapper
2023-04-12 01:12:05.100 38 ERROR keystone.server.flask.application     resp = resource(*args, **kwargs)
2023-04-12 01:12:05.100 38 ERROR keystone.server.flask.application   File "/var/lib/kolla/venv/lib/python3.9/site-packages/flask/views.py", line 107, in view
2023-04-12 01:12:05.100 38 ERROR keystone.server.flask.application     return current_app.ensure_sync(self.dispatch_request)(**kwargs)
2023-04-12 01:12:05.100 38 ERROR keystone.server.flask.application   File "/var/lib/kolla/venv/lib/python3.9/site-packages/flask_restful/__init__.py", line 582, in dispatch_request
2023-04-12 01:12:05.100 38 ERROR keystone.server.flask.application     resp = meth(*args, **kwargs)
2023-04-12 01:12:05.100 38 ERROR keystone.server.flask.application   File "/var/lib/kolla/venv/lib/python3.9/site-packages/keystone/api/users.py", line 182, in get
2023-04-12 01:12:05.100 38 ERROR keystone.server.flask.application     return self._get_user(user_id)
2023-04-12 01:12:05.100 38 ERROR keystone.server.flask.application   File "/var/lib/kolla/venv/lib/python3.9/site-packages/keystone/api/users.py", line 194, in _get_user
2023-04-12 01:12:05.100 38 ERROR keystone.server.flask.application     ref = PROVIDERS.identity_api.get_user(user_id)
2023-04-12 01:12:05.100 38 ERROR keystone.server.flask.application   File "/var/lib/kolla/venv/lib/python3.9/site-packages/keystone/common/manager.py", line 115, in wrapped
2023-04-12 01:12:05.100 38 ERROR keystone.server.flask.application     __ret_val = __f(*args, **kwargs)
2023-04-12 01:12:05.100 38 ERROR keystone.server.flask.application   File "/var/lib/kolla/venv/lib/python3.9/site-packages/keystone/identity/core.py", line 414, in wrapper
2023-04-12 01:12:05.100 38 ERROR keystone.server.flask.application     return f(self, *args, **kwargs)
2023-04-12 01:12:05.100 38 ERROR keystone.server.flask.application   File "/var/lib/kolla/venv/lib/python3.9/site-packages/keystone/identity/core.py", line 424, in wrapper
2023-04-12 01:12:05.100 38 ERROR keystone.server.flask.application     return f(self, *args, **kwargs)
2023-04-12 01:12:05.100 38 ERROR keystone.server.flask.application   File "/var/lib/kolla/venv/lib/python3.9/site-packages/decorator.py", line 232, in fun
2023-04-12 01:12:05.100 38 ERROR keystone.server.flask.application     return caller(func, *(extras + args), **kw)
2023-04-12 01:12:05.100 38 ERROR keystone.server.flask.application   File "/var/lib/kolla/venv/lib/python3.9/site-packages/dogpile/cache/region.py", line 1577, in get_or_create_for_user_func
2023-04-12 01:12:05.100 38 ERROR keystone.server.flask.application     return self.get_or_create(
2023-04-12 01:12:05.100 38 ERROR keystone.server.flask.application   File "/var/lib/kolla/venv/lib/python3.9/site-packages/dogpile/cache/region.py", line 1042, in get_or_create
2023-04-12 01:12:05.100 38 ERROR keystone.server.flask.application     with Lock(
2023-04-12 01:12:05.100 38 ERROR keystone.server.flask.application   File "/var/lib/kolla/venv/lib/python3.9/site-packages/dogpile/lock.py", line 185, in __enter__
2023-04-12 01:12:05.100 38 ERROR keystone.server.flask.application     return self._enter()
2023-04-12 01:12:05.100 38 ERROR keystone.server.flask.application   File "/var/lib/kolla/venv/lib/python3.9/site-packages/dogpile/lock.py", line 94, in _enter
2023-04-12 01:12:05.100 38 ERROR keystone.server.flask.application     generated = self._enter_create(value, createdtime)
2023-04-12 01:12:05.100 38 ERROR keystone.server.flask.application   File "/var/lib/kolla/venv/lib/python3.9/site-packages/dogpile/lock.py", line 178, in _enter_create
2023-04-12 01:12:05.100 38 ERROR keystone.server.flask.application     return self.creator()
2023-04-12 01:12:05.100 38 ERROR keystone.server.flask.application   File "/var/lib/kolla/venv/lib/python3.9/site-packages/dogpile/cache/region.py", line 995, in gen_value
2023-04-12 01:12:05.100 38 ERROR keystone.server.flask.application     created_value = creator(
2023-04-12 01:12:05.100 38 ERROR keystone.server.flask.application   File "/var/lib/kolla/venv/lib/python3.9/site-packages/keystone/identity/core.py", line 1011, in get_user
2023-04-12 01:12:05.100 38 ERROR keystone.server.flask.application     ref = driver.get_user(entity_id)
2023-04-12 01:12:05.100 38 ERROR keystone.server.flask.application   File "/var/lib/kolla/venv/lib/python3.9/site-packages/keystone/identity/backends/sql.py", line 200, in get_user
2023-04-12 01:12:05.100 38 ERROR keystone.server.flask.application     self._get_user(session, user_id).to_dict())
2023-04-12 01:12:05.100 38 ERROR keystone.server.flask.application   File "/var/lib/kolla/venv/lib/python3.9/site-packages/keystone/identity/backends/sql.py", line 194, in _get_user
2023-04-12 01:12:05.100 38 ERROR keystone.server.flask.application     raise exception.UserNotFound(user_id=user_id)
2023-04-12 01:12:05.100 38 ERROR keystone.server.flask.application keystone.exception.UserNotFound: Could not find user: neutron.
2023-04-12 01:12:05.100 38 ERROR keystone.server.flask.application 
2023-04-12 01:12:05.981 39 ERROR keystone.server.flask.application [None req-7d2f20fb-c8ad-4a94-b6bf-458c21108f75 39f4879392a64163b67509866d91d639 - - all default -] Could not find project: service.: keystone.exception.ProjectNotFound: Could not find project: service.
2023-04-12 01:12:05.981 39 ERROR keystone.server.flask.application Traceback (most recent call last):
2023-04-12 01:12:05.981 39 ERROR keystone.server.flask.application   File "/var/lib/kolla/venv/lib/python3.9/site-packages/flask/app.py", line 1820, in full_dispatch_request
2023-04-12 01:12:05.981 39 ERROR keystone.server.flask.application     rv = self.dispatch_request()
2023-04-12 01:12:05.981 39 ERROR keystone.server.flask.application   File "/var/lib/kolla/venv/lib/python3.9/site-packages/flask/app.py", line 1796, in dispatch_request
2023-04-12 01:12:05.981 39 ERROR keystone.server.flask.application     return self.ensure_sync(self.view_functions[rule.endpoint])(**view_args)
2023-04-12 01:12:05.981 39 ERROR keystone.server.flask.application   File "/var/lib/kolla/venv/lib/python3.9/site-packages/flask_restful/__init__.py", line 467, in wrapper
2023-04-12 01:12:05.981 39 ERROR keystone.server.flask.application     resp = resource(*args, **kwargs)
2023-04-12 01:12:05.981 39 ERROR keystone.server.flask.application   File "/var/lib/kolla/venv/lib/python3.9/site-packages/flask/views.py", line 107, in view
2023-04-12 01:12:05.981 39 ERROR keystone.server.flask.application     return current_app.ensure_sync(self.dispatch_request)(**kwargs)
2023-04-12 01:12:05.981 39 ERROR keystone.server.flask.application   File "/var/lib/kolla/venv/lib/python3.9/site-packages/flask_restful/__init__.py", line 582, in dispatch_request
2023-04-12 01:12:05.981 39 ERROR keystone.server.flask.application     resp = meth(*args, **kwargs)
2023-04-12 01:12:05.981 39 ERROR keystone.server.flask.application   File "/var/lib/kolla/venv/lib/python3.9/site-packages/keystone/api/projects.py", line 151, in get
2023-04-12 01:12:05.981 39 ERROR keystone.server.flask.application     return self._get_project(project_id)
2023-04-12 01:12:05.981 39 ERROR keystone.server.flask.application   File "/var/lib/kolla/venv/lib/python3.9/site-packages/keystone/api/projects.py", line 107, in _get_project
2023-04-12 01:12:05.981 39 ERROR keystone.server.flask.application     project = PROVIDERS.resource_api.get_project(project_id)
2023-04-12 01:12:05.981 39 ERROR keystone.server.flask.application   File "/var/lib/kolla/venv/lib/python3.9/site-packages/keystone/common/manager.py", line 115, in wrapped
2023-04-12 01:12:05.981 39 ERROR keystone.server.flask.application     __ret_val = __f(*args, **kwargs)
2023-04-12 01:12:05.981 39 ERROR keystone.server.flask.application   File "/var/lib/kolla/venv/lib/python3.9/site-packages/decorator.py", line 232, in fun
2023-04-12 01:12:05.981 39 ERROR keystone.server.flask.application     return caller(func, *(extras + args), **kw)
2023-04-12 01:12:05.981 39 ERROR keystone.server.flask.application   File "/var/lib/kolla/venv/lib/python3.9/site-packages/dogpile/cache/region.py", line 1577, in get_or_create_for_user_func
2023-04-12 01:12:05.981 39 ERROR keystone.server.flask.application     return self.get_or_create(
2023-04-12 01:12:05.981 39 ERROR keystone.server.flask.application   File "/var/lib/kolla/venv/lib/python3.9/site-packages/dogpile/cache/region.py", line 1042, in get_or_create
2023-04-12 01:12:05.981 39 ERROR keystone.server.flask.application     with Lock(
2023-04-12 01:12:05.981 39 ERROR keystone.server.flask.application   File "/var/lib/kolla/venv/lib/python3.9/site-packages/dogpile/lock.py", line 185, in __enter__
2023-04-12 01:12:05.981 39 ERROR keystone.server.flask.application     return self._enter()
2023-04-12 01:12:05.981 39 ERROR keystone.server.flask.application   File "/var/lib/kolla/venv/lib/python3.9/site-packages/dogpile/lock.py", line 94, in _enter
2023-04-12 01:12:05.981 39 ERROR keystone.server.flask.application     generated = self._enter_create(value, createdtime)
2023-04-12 01:12:05.981 39 ERROR keystone.server.flask.application   File "/var/lib/kolla/venv/lib/python3.9/site-packages/dogpile/lock.py", line 178, in _enter_create
2023-04-12 01:12:05.981 39 ERROR keystone.server.flask.application     return self.creator()
2023-04-12 01:12:05.981 39 ERROR keystone.server.flask.application   File "/var/lib/kolla/venv/lib/python3.9/site-packages/dogpile/cache/region.py", line 995, in gen_value
2023-04-12 01:12:05.981 39 ERROR keystone.server.flask.application     created_value = creator(
2023-04-12 01:12:05.981 39 ERROR keystone.server.flask.application   File "/var/lib/kolla/venv/lib/python3.9/site-packages/keystone/resource/core.py", line 903, in get_project
2023-04-12 01:12:05.981 39 ERROR keystone.server.flask.application     return self.driver.get_project(project_id)
2023-04-12 01:12:05.981 39 ERROR keystone.server.flask.application   File "/var/lib/kolla/venv/lib/python3.9/site-packages/keystone/resource/backends/sql.py", line 49, in get_project
2023-04-12 01:12:05.981 39 ERROR keystone.server.flask.application     return self._get_project(session, project_id).to_dict()
2023-04-12 01:12:05.981 39 ERROR keystone.server.flask.application   File "/var/lib/kolla/venv/lib/python3.9/site-packages/keystone/resource/backends/sql.py", line 44, in _get_project
2023-04-12 01:12:05.981 39 ERROR keystone.server.flask.application     raise exception.ProjectNotFound(project_id=project_id)
2023-04-12 01:12:05.981 39 ERROR keystone.server.flask.application keystone.exception.ProjectNotFound: Could not find project: service.
2023-04-12 01:12:05.981 39 ERROR keystone.server.flask.application 
