2023-03-13 22:52:46.060 23 INFO alembic.runtime.migration [-] Context impl MySQLImpl.
2023-03-13 22:52:46.062 23 INFO alembic.runtime.migration [-] Will assume non-transactional DDL.
2023-03-13 22:52:46.102 23 INFO alembic.runtime.migration [-] Context impl MySQLImpl.
2023-03-13 22:52:46.102 23 INFO alembic.runtime.migration [-] Will assume non-transactional DDL.
2023-03-13 22:52:46.154 23 INFO alembic.runtime.migration [-] Running upgrade  -> 27e647c0fad4, Initial version.
2023-03-13 22:52:47.425 23 INFO alembic.runtime.migration [-] Running upgrade 27e647c0fad4 -> e25ffa003242, Initial no-op Yoga contract migration.
2023-03-13 22:52:47.430 23 INFO alembic.runtime.migration [-] Running upgrade 27e647c0fad4 -> 29e87d24a316, Initial no-op Yoga expand migration.
2023-03-13 22:52:56.280 7 INFO keystone.common.fernet_utils [-] Created a new temporary key: /etc/keystone/fernet-keys/0.tmp
2023-03-13 22:52:56.285 7 INFO keystone.common.fernet_utils [-] Become a valid new key: /etc/keystone/fernet-keys/0
2023-03-13 22:52:56.286 7 INFO keystone.common.fernet_utils [-] Starting key rotation with 1 key files: ['/etc/keystone/fernet-keys/0']
2023-03-13 22:52:56.286 7 INFO keystone.common.fernet_utils [-] Created a new temporary key: /etc/keystone/fernet-keys/0.tmp
2023-03-13 22:52:56.287 7 INFO keystone.common.fernet_utils [-] Current primary key is: 0
2023-03-13 22:52:56.288 7 INFO keystone.common.fernet_utils [-] Next primary key will be: 1
2023-03-13 22:52:56.289 7 INFO keystone.common.fernet_utils [-] Promoted key 0 to be the primary: 1
2023-03-13 22:52:56.289 7 INFO keystone.common.fernet_utils [-] Become a valid new key: /etc/keystone/fernet-keys/0
2023-03-13 22:53:17.546 32 INFO keystone.cmd.bootstrap [None req-8c32b274-9a66-41c3-bbca-17fad2a7f014 - - - - - -] Created domain default
2023-03-13 22:53:17.668 32 INFO keystone.cmd.bootstrap [None req-8c32b274-9a66-41c3-bbca-17fad2a7f014 - - - - - -] Created project admin
2023-03-13 22:53:18.460 32 INFO keystone.cmd.bootstrap [None req-8c32b274-9a66-41c3-bbca-17fad2a7f014 - - - - - -] Created user admin
2023-03-13 22:53:18.483 32 INFO keystone.cmd.bootstrap [None req-8c32b274-9a66-41c3-bbca-17fad2a7f014 - - - - - -] Created role reader
2023-03-13 22:53:18.502 32 INFO keystone.cmd.bootstrap [None req-8c32b274-9a66-41c3-bbca-17fad2a7f014 - - - - - -] Created role member
2023-03-13 22:53:18.537 32 INFO keystone.cmd.bootstrap [None req-8c32b274-9a66-41c3-bbca-17fad2a7f014 - - - - - -] Created implied role where 4962d8a17da3453eab927a88458639ee implies a2c2655f24a24b6faee38f7f8eff6c86
2023-03-13 22:53:18.559 32 INFO keystone.cmd.bootstrap [None req-8c32b274-9a66-41c3-bbca-17fad2a7f014 - - - - - -] Created role admin
2023-03-13 22:53:18.592 32 INFO keystone.cmd.bootstrap [None req-8c32b274-9a66-41c3-bbca-17fad2a7f014 - - - - - -] Created implied role where f22230d1706547ecb25d1859f1695d67 implies 4962d8a17da3453eab927a88458639ee
2023-03-13 22:53:18.613 32 INFO keystone.cmd.bootstrap [None req-8c32b274-9a66-41c3-bbca-17fad2a7f014 - - - - - -] Granted role admin on project admin to user admin.
2023-03-13 22:53:18.624 32 INFO keystone.cmd.bootstrap [None req-8c32b274-9a66-41c3-bbca-17fad2a7f014 - - - - - -] Granted role admin on the system to user admin.
2023-03-13 22:53:18.646 32 WARNING py.warnings [None req-8c32b274-9a66-41c3-bbca-17fad2a7f014 - - - - - -] /var/lib/kolla/venv/lib/python3.9/site-packages/pycadf/identifier.py:71: UserWarning: Invalid uuid: RegionOne. To ensure interoperability, identifiers should be a valid uuid.
  warnings.warn(('Invalid uuid: %s. To ensure interoperability, '

2023-03-13 22:53:18.654 32 INFO keystone.cmd.bootstrap [None req-8c32b274-9a66-41c3-bbca-17fad2a7f014 - - - - - -] Created region RegionOne
2023-03-13 22:53:18.711 32 INFO keystone.cmd.bootstrap [None req-8c32b274-9a66-41c3-bbca-17fad2a7f014 - - - - - -] Created public endpoint http://169.16.1.168:5000
2023-03-13 22:53:18.733 32 INFO keystone.cmd.bootstrap [None req-8c32b274-9a66-41c3-bbca-17fad2a7f014 - - - - - -] Created internal endpoint http://169.16.1.168:5000
2023-03-13 22:53:46.080 39 WARNING keystone.common.rbac_enforcer.enforcer [None req-4e317fc7-c9cd-4eba-8d53-b8be41e33240 28a3049e1dd74d85b768eaad8b970a99 - - all default -] Deprecated policy rules found. Use oslopolicy-policy-generator and oslopolicy-policy-upgrade to detect and resolve deprecated policies in your configuration.
2023-03-13 22:53:46.864 38 WARNING keystone.common.rbac_enforcer.enforcer [None req-c0417000-0088-4998-9dcb-a13cfeaa6d2e 28a3049e1dd74d85b768eaad8b970a99 - - all default -] Deprecated policy rules found. Use oslopolicy-policy-generator and oslopolicy-policy-upgrade to detect and resolve deprecated policies in your configuration.
2023-03-13 22:53:54.578 37 WARNING keystone.common.rbac_enforcer.enforcer [None req-aaa2e0bc-0ee0-467c-a9f9-b35ea56649df 28a3049e1dd74d85b768eaad8b970a99 - - all default -] Deprecated policy rules found. Use oslopolicy-policy-generator and oslopolicy-policy-upgrade to detect and resolve deprecated policies in your configuration.
2023-03-13 22:55:07.939 38 ERROR keystone.server.flask.application [None req-a099662a-e2a5-4946-b9f9-bea834e4288d 28a3049e1dd74d85b768eaad8b970a99 - - all default -] Could not find project: service.: keystone.exception.ProjectNotFound: Could not find project: service.
2023-03-13 22:55:07.939 38 ERROR keystone.server.flask.application Traceback (most recent call last):
2023-03-13 22:55:07.939 38 ERROR keystone.server.flask.application   File "/var/lib/kolla/venv/lib/python3.9/site-packages/flask/app.py", line 1820, in full_dispatch_request
2023-03-13 22:55:07.939 38 ERROR keystone.server.flask.application     rv = self.dispatch_request()
2023-03-13 22:55:07.939 38 ERROR keystone.server.flask.application   File "/var/lib/kolla/venv/lib/python3.9/site-packages/flask/app.py", line 1796, in dispatch_request
2023-03-13 22:55:07.939 38 ERROR keystone.server.flask.application     return self.ensure_sync(self.view_functions[rule.endpoint])(**view_args)
2023-03-13 22:55:07.939 38 ERROR keystone.server.flask.application   File "/var/lib/kolla/venv/lib/python3.9/site-packages/flask_restful/__init__.py", line 467, in wrapper
2023-03-13 22:55:07.939 38 ERROR keystone.server.flask.application     resp = resource(*args, **kwargs)
2023-03-13 22:55:07.939 38 ERROR keystone.server.flask.application   File "/var/lib/kolla/venv/lib/python3.9/site-packages/flask/views.py", line 107, in view
2023-03-13 22:55:07.939 38 ERROR keystone.server.flask.application     return current_app.ensure_sync(self.dispatch_request)(**kwargs)
2023-03-13 22:55:07.939 38 ERROR keystone.server.flask.application   File "/var/lib/kolla/venv/lib/python3.9/site-packages/flask_restful/__init__.py", line 582, in dispatch_request
2023-03-13 22:55:07.939 38 ERROR keystone.server.flask.application     resp = meth(*args, **kwargs)
2023-03-13 22:55:07.939 38 ERROR keystone.server.flask.application   File "/var/lib/kolla/venv/lib/python3.9/site-packages/keystone/api/projects.py", line 151, in get
2023-03-13 22:55:07.939 38 ERROR keystone.server.flask.application     return self._get_project(project_id)
2023-03-13 22:55:07.939 38 ERROR keystone.server.flask.application   File "/var/lib/kolla/venv/lib/python3.9/site-packages/keystone/api/projects.py", line 107, in _get_project
2023-03-13 22:55:07.939 38 ERROR keystone.server.flask.application     project = PROVIDERS.resource_api.get_project(project_id)
2023-03-13 22:55:07.939 38 ERROR keystone.server.flask.application   File "/var/lib/kolla/venv/lib/python3.9/site-packages/keystone/common/manager.py", line 115, in wrapped
2023-03-13 22:55:07.939 38 ERROR keystone.server.flask.application     __ret_val = __f(*args, **kwargs)
2023-03-13 22:55:07.939 38 ERROR keystone.server.flask.application   File "/var/lib/kolla/venv/lib/python3.9/site-packages/decorator.py", line 232, in fun
2023-03-13 22:55:07.939 38 ERROR keystone.server.flask.application     return caller(func, *(extras + args), **kw)
2023-03-13 22:55:07.939 38 ERROR keystone.server.flask.application   File "/var/lib/kolla/venv/lib/python3.9/site-packages/dogpile/cache/region.py", line 1577, in get_or_create_for_user_func
2023-03-13 22:55:07.939 38 ERROR keystone.server.flask.application     return self.get_or_create(
2023-03-13 22:55:07.939 38 ERROR keystone.server.flask.application   File "/var/lib/kolla/venv/lib/python3.9/site-packages/dogpile/cache/region.py", line 1042, in get_or_create
2023-03-13 22:55:07.939 38 ERROR keystone.server.flask.application     with Lock(
2023-03-13 22:55:07.939 38 ERROR keystone.server.flask.application   File "/var/lib/kolla/venv/lib/python3.9/site-packages/dogpile/lock.py", line 185, in __enter__
2023-03-13 22:55:07.939 38 ERROR keystone.server.flask.application     return self._enter()
2023-03-13 22:55:07.939 38 ERROR keystone.server.flask.application   File "/var/lib/kolla/venv/lib/python3.9/site-packages/dogpile/lock.py", line 94, in _enter
2023-03-13 22:55:07.939 38 ERROR keystone.server.flask.application     generated = self._enter_create(value, createdtime)
2023-03-13 22:55:07.939 38 ERROR keystone.server.flask.application   File "/var/lib/kolla/venv/lib/python3.9/site-packages/dogpile/lock.py", line 178, in _enter_create
2023-03-13 22:55:07.939 38 ERROR keystone.server.flask.application     return self.creator()
2023-03-13 22:55:07.939 38 ERROR keystone.server.flask.application   File "/var/lib/kolla/venv/lib/python3.9/site-packages/dogpile/cache/region.py", line 995, in gen_value
2023-03-13 22:55:07.939 38 ERROR keystone.server.flask.application     created_value = creator(
2023-03-13 22:55:07.939 38 ERROR keystone.server.flask.application   File "/var/lib/kolla/venv/lib/python3.9/site-packages/keystone/resource/core.py", line 903, in get_project
2023-03-13 22:55:07.939 38 ERROR keystone.server.flask.application     return self.driver.get_project(project_id)
2023-03-13 22:55:07.939 38 ERROR keystone.server.flask.application   File "/var/lib/kolla/venv/lib/python3.9/site-packages/keystone/resource/backends/sql.py", line 49, in get_project
2023-03-13 22:55:07.939 38 ERROR keystone.server.flask.application     return self._get_project(session, project_id).to_dict()
2023-03-13 22:55:07.939 38 ERROR keystone.server.flask.application   File "/var/lib/kolla/venv/lib/python3.9/site-packages/keystone/resource/backends/sql.py", line 44, in _get_project
2023-03-13 22:55:07.939 38 ERROR keystone.server.flask.application     raise exception.ProjectNotFound(project_id=project_id)
2023-03-13 22:55:07.939 38 ERROR keystone.server.flask.application keystone.exception.ProjectNotFound: Could not find project: service.
2023-03-13 22:55:07.939 38 ERROR keystone.server.flask.application 
2023-03-13 22:55:16.888 39 ERROR keystone.server.flask.application [None req-61979441-c75d-4f0c-96b8-db8d6271e43b 28a3049e1dd74d85b768eaad8b970a99 - - all default -] Could not find project: service.: keystone.exception.ProjectNotFound: Could not find project: service.
2023-03-13 22:55:16.888 39 ERROR keystone.server.flask.application Traceback (most recent call last):
2023-03-13 22:55:16.888 39 ERROR keystone.server.flask.application   File "/var/lib/kolla/venv/lib/python3.9/site-packages/flask/app.py", line 1820, in full_dispatch_request
2023-03-13 22:55:16.888 39 ERROR keystone.server.flask.application     rv = self.dispatch_request()
2023-03-13 22:55:16.888 39 ERROR keystone.server.flask.application   File "/var/lib/kolla/venv/lib/python3.9/site-packages/flask/app.py", line 1796, in dispatch_request
2023-03-13 22:55:16.888 39 ERROR keystone.server.flask.application     return self.ensure_sync(self.view_functions[rule.endpoint])(**view_args)
2023-03-13 22:55:16.888 39 ERROR keystone.server.flask.application   File "/var/lib/kolla/venv/lib/python3.9/site-packages/flask_restful/__init__.py", line 467, in wrapper
2023-03-13 22:55:16.888 39 ERROR keystone.server.flask.application     resp = resource(*args, **kwargs)
2023-03-13 22:55:16.888 39 ERROR keystone.server.flask.application   File "/var/lib/kolla/venv/lib/python3.9/site-packages/flask/views.py", line 107, in view
2023-03-13 22:55:16.888 39 ERROR keystone.server.flask.application     return current_app.ensure_sync(self.dispatch_request)(**kwargs)
2023-03-13 22:55:16.888 39 ERROR keystone.server.flask.application   File "/var/lib/kolla/venv/lib/python3.9/site-packages/flask_restful/__init__.py", line 582, in dispatch_request
2023-03-13 22:55:16.888 39 ERROR keystone.server.flask.application     resp = meth(*args, **kwargs)
2023-03-13 22:55:16.888 39 ERROR keystone.server.flask.application   File "/var/lib/kolla/venv/lib/python3.9/site-packages/keystone/api/projects.py", line 151, in get
2023-03-13 22:55:16.888 39 ERROR keystone.server.flask.application     return self._get_project(project_id)
2023-03-13 22:55:16.888 39 ERROR keystone.server.flask.application   File "/var/lib/kolla/venv/lib/python3.9/site-packages/keystone/api/projects.py", line 107, in _get_project
2023-03-13 22:55:16.888 39 ERROR keystone.server.flask.application     project = PROVIDERS.resource_api.get_project(project_id)
2023-03-13 22:55:16.888 39 ERROR keystone.server.flask.application   File "/var/lib/kolla/venv/lib/python3.9/site-packages/keystone/common/manager.py", line 115, in wrapped
2023-03-13 22:55:16.888 39 ERROR keystone.server.flask.application     __ret_val = __f(*args, **kwargs)
2023-03-13 22:55:16.888 39 ERROR keystone.server.flask.application   File "/var/lib/kolla/venv/lib/python3.9/site-packages/decorator.py", line 232, in fun
2023-03-13 22:55:16.888 39 ERROR keystone.server.flask.application     return caller(func, *(extras + args), **kw)
2023-03-13 22:55:16.888 39 ERROR keystone.server.flask.application   File "/var/lib/kolla/venv/lib/python3.9/site-packages/dogpile/cache/region.py", line 1577, in get_or_create_for_user_func
2023-03-13 22:55:16.888 39 ERROR keystone.server.flask.application     return self.get_or_create(
2023-03-13 22:55:16.888 39 ERROR keystone.server.flask.application   File "/var/lib/kolla/venv/lib/python3.9/site-packages/dogpile/cache/region.py", line 1042, in get_or_create
2023-03-13 22:55:16.888 39 ERROR keystone.server.flask.application     with Lock(
2023-03-13 22:55:16.888 39 ERROR keystone.server.flask.application   File "/var/lib/kolla/venv/lib/python3.9/site-packages/dogpile/lock.py", line 185, in __enter__
2023-03-13 22:55:16.888 39 ERROR keystone.server.flask.application     return self._enter()
2023-03-13 22:55:16.888 39 ERROR keystone.server.flask.application   File "/var/lib/kolla/venv/lib/python3.9/site-packages/dogpile/lock.py", line 94, in _enter
2023-03-13 22:55:16.888 39 ERROR keystone.server.flask.application     generated = self._enter_create(value, createdtime)
2023-03-13 22:55:16.888 39 ERROR keystone.server.flask.application   File "/var/lib/kolla/venv/lib/python3.9/site-packages/dogpile/lock.py", line 178, in _enter_create
2023-03-13 22:55:16.888 39 ERROR keystone.server.flask.application     return self.creator()
2023-03-13 22:55:16.888 39 ERROR keystone.server.flask.application   File "/var/lib/kolla/venv/lib/python3.9/site-packages/dogpile/cache/region.py", line 995, in gen_value
2023-03-13 22:55:16.888 39 ERROR keystone.server.flask.application     created_value = creator(
2023-03-13 22:55:16.888 39 ERROR keystone.server.flask.application   File "/var/lib/kolla/venv/lib/python3.9/site-packages/keystone/resource/core.py", line 903, in get_project
2023-03-13 22:55:16.888 39 ERROR keystone.server.flask.application     return self.driver.get_project(project_id)
2023-03-13 22:55:16.888 39 ERROR keystone.server.flask.application   File "/var/lib/kolla/venv/lib/python3.9/site-packages/keystone/resource/backends/sql.py", line 49, in get_project
2023-03-13 22:55:16.888 39 ERROR keystone.server.flask.application     return self._get_project(session, project_id).to_dict()
2023-03-13 22:55:16.888 39 ERROR keystone.server.flask.application   File "/var/lib/kolla/venv/lib/python3.9/site-packages/keystone/resource/backends/sql.py", line 44, in _get_project
2023-03-13 22:55:16.888 39 ERROR keystone.server.flask.application     raise exception.ProjectNotFound(project_id=project_id)
2023-03-13 22:55:16.888 39 ERROR keystone.server.flask.application keystone.exception.ProjectNotFound: Could not find project: service.
2023-03-13 22:55:16.888 39 ERROR keystone.server.flask.application 
2023-03-13 22:55:31.347 39 ERROR keystone.server.flask.application [None req-bf498596-f508-49f0-afc6-9437e41bb542 28a3049e1dd74d85b768eaad8b970a99 - - all default -] Could not find role: admin.: keystone.exception.RoleNotFound: Could not find role: admin.
2023-03-13 22:55:31.347 39 ERROR keystone.server.flask.application Traceback (most recent call last):
2023-03-13 22:55:31.347 39 ERROR keystone.server.flask.application   File "/var/lib/kolla/venv/lib/python3.9/site-packages/flask/app.py", line 1820, in full_dispatch_request
2023-03-13 22:55:31.347 39 ERROR keystone.server.flask.application     rv = self.dispatch_request()
2023-03-13 22:55:31.347 39 ERROR keystone.server.flask.application   File "/var/lib/kolla/venv/lib/python3.9/site-packages/flask/app.py", line 1796, in dispatch_request
2023-03-13 22:55:31.347 39 ERROR keystone.server.flask.application     return self.ensure_sync(self.view_functions[rule.endpoint])(**view_args)
2023-03-13 22:55:31.347 39 ERROR keystone.server.flask.application   File "/var/lib/kolla/venv/lib/python3.9/site-packages/flask_restful/__init__.py", line 467, in wrapper
2023-03-13 22:55:31.347 39 ERROR keystone.server.flask.application     resp = resource(*args, **kwargs)
2023-03-13 22:55:31.347 39 ERROR keystone.server.flask.application   File "/var/lib/kolla/venv/lib/python3.9/site-packages/flask/views.py", line 107, in view
2023-03-13 22:55:31.347 39 ERROR keystone.server.flask.application     return current_app.ensure_sync(self.dispatch_request)(**kwargs)
2023-03-13 22:55:31.347 39 ERROR keystone.server.flask.application   File "/var/lib/kolla/venv/lib/python3.9/site-packages/flask_restful/__init__.py", line 582, in dispatch_request
2023-03-13 22:55:31.347 39 ERROR keystone.server.flask.application     resp = meth(*args, **kwargs)
2023-03-13 22:55:31.347 39 ERROR keystone.server.flask.application   File "/var/lib/kolla/venv/lib/python3.9/site-packages/keystone/api/roles.py", line 50, in get
2023-03-13 22:55:31.347 39 ERROR keystone.server.flask.application     return self._get_role(role_id)
2023-03-13 22:55:31.347 39 ERROR keystone.server.flask.application   File "/var/lib/kolla/venv/lib/python3.9/site-packages/keystone/api/roles.py", line 70, in _get_role
2023-03-13 22:55:31.347 39 ERROR keystone.server.flask.application     ENFORCER.enforce_call(action='identity:get_role')
2023-03-13 22:55:31.347 39 ERROR keystone.server.flask.application   File "/var/lib/kolla/venv/lib/python3.9/site-packages/keystone/common/rbac_enforcer/enforcer.py", line 402, in enforce_call
2023-03-13 22:55:31.347 39 ERROR keystone.server.flask.application     policy_dict.update(cls._extract_member_target_data(
2023-03-13 22:55:31.347 39 ERROR keystone.server.flask.application   File "/var/lib/kolla/venv/lib/python3.9/site-packages/keystone/common/rbac_enforcer/enforcer.py", line 234, in _extract_member_target_data
2023-03-13 22:55:31.347 39 ERROR keystone.server.flask.application     member_name: func(flask.request.view_args[key])
2023-03-13 22:55:31.347 39 ERROR keystone.server.flask.application   File "/var/lib/kolla/venv/lib/python3.9/site-packages/keystone/common/manager.py", line 115, in wrapped
2023-03-13 22:55:31.347 39 ERROR keystone.server.flask.application     __ret_val = __f(*args, **kwargs)
2023-03-13 22:55:31.347 39 ERROR keystone.server.flask.application   File "/var/lib/kolla/venv/lib/python3.9/site-packages/decorator.py", line 232, in fun
2023-03-13 22:55:31.347 39 ERROR keystone.server.flask.application     return caller(func, *(extras + args), **kw)
2023-03-13 22:55:31.347 39 ERROR keystone.server.flask.application   File "/var/lib/kolla/venv/lib/python3.9/site-packages/dogpile/cache/region.py", line 1577, in get_or_create_for_user_func
2023-03-13 22:55:31.347 39 ERROR keystone.server.flask.application     return self.get_or_create(
2023-03-13 22:55:31.347 39 ERROR keystone.server.flask.application   File "/var/lib/kolla/venv/lib/python3.9/site-packages/dogpile/cache/region.py", line 1042, in get_or_create
2023-03-13 22:55:31.347 39 ERROR keystone.server.flask.application     with Lock(
2023-03-13 22:55:31.347 39 ERROR keystone.server.flask.application   File "/var/lib/kolla/venv/lib/python3.9/site-packages/dogpile/lock.py", line 185, in __enter__
2023-03-13 22:55:31.347 39 ERROR keystone.server.flask.application     return self._enter()
2023-03-13 22:55:31.347 39 ERROR keystone.server.flask.application   File "/var/lib/kolla/venv/lib/python3.9/site-packages/dogpile/lock.py", line 94, in _enter
2023-03-13 22:55:31.347 39 ERROR keystone.server.flask.application     generated = self._enter_create(value, createdtime)
2023-03-13 22:55:31.347 39 ERROR keystone.server.flask.application   File "/var/lib/kolla/venv/lib/python3.9/site-packages/dogpile/lock.py", line 178, in _enter_create
2023-03-13 22:55:31.347 39 ERROR keystone.server.flask.application     return self.creator()
2023-03-13 22:55:31.347 39 ERROR keystone.server.flask.application   File "/var/lib/kolla/venv/lib/python3.9/site-packages/dogpile/cache/region.py", line 995, in gen_value
2023-03-13 22:55:31.347 39 ERROR keystone.server.flask.application     created_value = creator(
2023-03-13 22:55:31.347 39 ERROR keystone.server.flask.application   File "/var/lib/kolla/venv/lib/python3.9/site-packages/keystone/assignment/core.py", line 1276, in get_role
2023-03-13 22:55:31.347 39 ERROR keystone.server.flask.application     return self.driver.get_role(role_id)
2023-03-13 22:55:31.347 39 ERROR keystone.server.flask.application   File "/var/lib/kolla/venv/lib/python3.9/site-packages/keystone/assignment/role_backends/sql.py", line 70, in get_role
2023-03-13 22:55:31.347 39 ERROR keystone.server.flask.application     return self._get_role(session, role_id).to_dict()
2023-03-13 22:55:31.347 39 ERROR keystone.server.flask.application   File "/var/lib/kolla/venv/lib/python3.9/site-packages/keystone/assignment/role_backends/sql.py", line 65, in _get_role
2023-03-13 22:55:31.347 39 ERROR keystone.server.flask.application     raise exception.RoleNotFound(role_id=role_id)
2023-03-13 22:55:31.347 39 ERROR keystone.server.flask.application keystone.exception.RoleNotFound: Could not find role: admin.
2023-03-13 22:55:31.347 39 ERROR keystone.server.flask.application 
2023-03-13 22:55:32.555 39 ERROR keystone.server.flask.application [None req-d48c033a-6ab0-45a4-bdc9-af2f105e54b8 28a3049e1dd74d85b768eaad8b970a99 - - all default -] Could not find user: ironic.: keystone.exception.UserNotFound: Could not find user: ironic.
2023-03-13 22:55:32.555 39 ERROR keystone.server.flask.application Traceback (most recent call last):
2023-03-13 22:55:32.555 39 ERROR keystone.server.flask.application   File "/var/lib/kolla/venv/lib/python3.9/site-packages/flask/app.py", line 1820, in full_dispatch_request
2023-03-13 22:55:32.555 39 ERROR keystone.server.flask.application     rv = self.dispatch_request()
2023-03-13 22:55:32.555 39 ERROR keystone.server.flask.application   File "/var/lib/kolla/venv/lib/python3.9/site-packages/flask/app.py", line 1796, in dispatch_request
2023-03-13 22:55:32.555 39 ERROR keystone.server.flask.application     return self.ensure_sync(self.view_functions[rule.endpoint])(**view_args)
2023-03-13 22:55:32.555 39 ERROR keystone.server.flask.application   File "/var/lib/kolla/venv/lib/python3.9/site-packages/flask_restful/__init__.py", line 467, in wrapper
2023-03-13 22:55:32.555 39 ERROR keystone.server.flask.application     resp = resource(*args, **kwargs)
2023-03-13 22:55:32.555 39 ERROR keystone.server.flask.application   File "/var/lib/kolla/venv/lib/python3.9/site-packages/flask/views.py", line 107, in view
2023-03-13 22:55:32.555 39 ERROR keystone.server.flask.application     return current_app.ensure_sync(self.dispatch_request)(**kwargs)
2023-03-13 22:55:32.555 39 ERROR keystone.server.flask.application   File "/var/lib/kolla/venv/lib/python3.9/site-packages/flask_restful/__init__.py", line 582, in dispatch_request
2023-03-13 22:55:32.555 39 ERROR keystone.server.flask.application     resp = meth(*args, **kwargs)
2023-03-13 22:55:32.555 39 ERROR keystone.server.flask.application   File "/var/lib/kolla/venv/lib/python3.9/site-packages/keystone/api/users.py", line 182, in get
2023-03-13 22:55:32.555 39 ERROR keystone.server.flask.application     return self._get_user(user_id)
2023-03-13 22:55:32.555 39 ERROR keystone.server.flask.application   File "/var/lib/kolla/venv/lib/python3.9/site-packages/keystone/api/users.py", line 194, in _get_user
2023-03-13 22:55:32.555 39 ERROR keystone.server.flask.application     ref = PROVIDERS.identity_api.get_user(user_id)
2023-03-13 22:55:32.555 39 ERROR keystone.server.flask.application   File "/var/lib/kolla/venv/lib/python3.9/site-packages/keystone/common/manager.py", line 115, in wrapped
2023-03-13 22:55:32.555 39 ERROR keystone.server.flask.application     __ret_val = __f(*args, **kwargs)
2023-03-13 22:55:32.555 39 ERROR keystone.server.flask.application   File "/var/lib/kolla/venv/lib/python3.9/site-packages/keystone/identity/core.py", line 414, in wrapper
2023-03-13 22:55:32.555 39 ERROR keystone.server.flask.application     return f(self, *args, **kwargs)
2023-03-13 22:55:32.555 39 ERROR keystone.server.flask.application   File "/var/lib/kolla/venv/lib/python3.9/site-packages/keystone/identity/core.py", line 424, in wrapper
2023-03-13 22:55:32.555 39 ERROR keystone.server.flask.application     return f(self, *args, **kwargs)
2023-03-13 22:55:32.555 39 ERROR keystone.server.flask.application   File "/var/lib/kolla/venv/lib/python3.9/site-packages/decorator.py", line 232, in fun
2023-03-13 22:55:32.555 39 ERROR keystone.server.flask.application     return caller(func, *(extras + args), **kw)
2023-03-13 22:55:32.555 39 ERROR keystone.server.flask.application   File "/var/lib/kolla/venv/lib/python3.9/site-packages/dogpile/cache/region.py", line 1577, in get_or_create_for_user_func
2023-03-13 22:55:32.555 39 ERROR keystone.server.flask.application     return self.get_or_create(
2023-03-13 22:55:32.555 39 ERROR keystone.server.flask.application   File "/var/lib/kolla/venv/lib/python3.9/site-packages/dogpile/cache/region.py", line 1042, in get_or_create
2023-03-13 22:55:32.555 39 ERROR keystone.server.flask.application     with Lock(
2023-03-13 22:55:32.555 39 ERROR keystone.server.flask.application   File "/var/lib/kolla/venv/lib/python3.9/site-packages/dogpile/lock.py", line 185, in __enter__
2023-03-13 22:55:32.555 39 ERROR keystone.server.flask.application     return self._enter()
2023-03-13 22:55:32.555 39 ERROR keystone.server.flask.application   File "/var/lib/kolla/venv/lib/python3.9/site-packages/dogpile/lock.py", line 94, in _enter
2023-03-13 22:55:32.555 39 ERROR keystone.server.flask.application     generated = self._enter_create(value, createdtime)
2023-03-13 22:55:32.555 39 ERROR keystone.server.flask.application   File "/var/lib/kolla/venv/lib/python3.9/site-packages/dogpile/lock.py", line 178, in _enter_create
2023-03-13 22:55:32.555 39 ERROR keystone.server.flask.application     return self.creator()
2023-03-13 22:55:32.555 39 ERROR keystone.server.flask.application   File "/var/lib/kolla/venv/lib/python3.9/site-packages/dogpile/cache/region.py", line 995, in gen_value
2023-03-13 22:55:32.555 39 ERROR keystone.server.flask.application     created_value = creator(
2023-03-13 22:55:32.555 39 ERROR keystone.server.flask.application   File "/var/lib/kolla/venv/lib/python3.9/site-packages/keystone/identity/core.py", line 1011, in get_user
2023-03-13 22:55:32.555 39 ERROR keystone.server.flask.application     ref = driver.get_user(entity_id)
2023-03-13 22:55:32.555 39 ERROR keystone.server.flask.application   File "/var/lib/kolla/venv/lib/python3.9/site-packages/keystone/identity/backends/sql.py", line 200, in get_user
2023-03-13 22:55:32.555 39 ERROR keystone.server.flask.application     self._get_user(session, user_id).to_dict())
2023-03-13 22:55:32.555 39 ERROR keystone.server.flask.application   File "/var/lib/kolla/venv/lib/python3.9/site-packages/keystone/identity/backends/sql.py", line 194, in _get_user
2023-03-13 22:55:32.555 39 ERROR keystone.server.flask.application     raise exception.UserNotFound(user_id=user_id)
2023-03-13 22:55:32.555 39 ERROR keystone.server.flask.application keystone.exception.UserNotFound: Could not find user: ironic.
2023-03-13 22:55:32.555 39 ERROR keystone.server.flask.application 
2023-03-13 22:55:33.342 37 ERROR keystone.server.flask.application [None req-8307cc98-f2ab-48b6-9dbc-e4c1b5c2707f 28a3049e1dd74d85b768eaad8b970a99 - - all default -] Could not find project: service.: keystone.exception.ProjectNotFound: Could not find project: service.
2023-03-13 22:55:33.342 37 ERROR keystone.server.flask.application Traceback (most recent call last):
2023-03-13 22:55:33.342 37 ERROR keystone.server.flask.application   File "/var/lib/kolla/venv/lib/python3.9/site-packages/flask/app.py", line 1820, in full_dispatch_request
2023-03-13 22:55:33.342 37 ERROR keystone.server.flask.application     rv = self.dispatch_request()
2023-03-13 22:55:33.342 37 ERROR keystone.server.flask.application   File "/var/lib/kolla/venv/lib/python3.9/site-packages/flask/app.py", line 1796, in dispatch_request
2023-03-13 22:55:33.342 37 ERROR keystone.server.flask.application     return self.ensure_sync(self.view_functions[rule.endpoint])(**view_args)
2023-03-13 22:55:33.342 37 ERROR keystone.server.flask.application   File "/var/lib/kolla/venv/lib/python3.9/site-packages/flask_restful/__init__.py", line 467, in wrapper
2023-03-13 22:55:33.342 37 ERROR keystone.server.flask.application     resp = resource(*args, **kwargs)
2023-03-13 22:55:33.342 37 ERROR keystone.server.flask.application   File "/var/lib/kolla/venv/lib/python3.9/site-packages/flask/views.py", line 107, in view
2023-03-13 22:55:33.342 37 ERROR keystone.server.flask.application     return current_app.ensure_sync(self.dispatch_request)(**kwargs)
2023-03-13 22:55:33.342 37 ERROR keystone.server.flask.application   File "/var/lib/kolla/venv/lib/python3.9/site-packages/flask_restful/__init__.py", line 582, in dispatch_request
2023-03-13 22:55:33.342 37 ERROR keystone.server.flask.application     resp = meth(*args, **kwargs)
2023-03-13 22:55:33.342 37 ERROR keystone.server.flask.application   File "/var/lib/kolla/venv/lib/python3.9/site-packages/keystone/api/projects.py", line 151, in get
2023-03-13 22:55:33.342 37 ERROR keystone.server.flask.application     return self._get_project(project_id)
2023-03-13 22:55:33.342 37 ERROR keystone.server.flask.application   File "/var/lib/kolla/venv/lib/python3.9/site-packages/keystone/api/projects.py", line 107, in _get_project
2023-03-13 22:55:33.342 37 ERROR keystone.server.flask.application     project = PROVIDERS.resource_api.get_project(project_id)
2023-03-13 22:55:33.342 37 ERROR keystone.server.flask.application   File "/var/lib/kolla/venv/lib/python3.9/site-packages/keystone/common/manager.py", line 115, in wrapped
2023-03-13 22:55:33.342 37 ERROR keystone.server.flask.application     __ret_val = __f(*args, **kwargs)
2023-03-13 22:55:33.342 37 ERROR keystone.server.flask.application   File "/var/lib/kolla/venv/lib/python3.9/site-packages/decorator.py", line 232, in fun
2023-03-13 22:55:33.342 37 ERROR keystone.server.flask.application     return caller(func, *(extras + args), **kw)
2023-03-13 22:55:33.342 37 ERROR keystone.server.flask.application   File "/var/lib/kolla/venv/lib/python3.9/site-packages/dogpile/cache/region.py", line 1577, in get_or_create_for_user_func
2023-03-13 22:55:33.342 37 ERROR keystone.server.flask.application     return self.get_or_create(
2023-03-13 22:55:33.342 37 ERROR keystone.server.flask.application   File "/var/lib/kolla/venv/lib/python3.9/site-packages/dogpile/cache/region.py", line 1042, in get_or_create
2023-03-13 22:55:33.342 37 ERROR keystone.server.flask.application     with Lock(
2023-03-13 22:55:33.342 37 ERROR keystone.server.flask.application   File "/var/lib/kolla/venv/lib/python3.9/site-packages/dogpile/lock.py", line 185, in __enter__
2023-03-13 22:55:33.342 37 ERROR keystone.server.flask.application     return self._enter()
2023-03-13 22:55:33.342 37 ERROR keystone.server.flask.application   File "/var/lib/kolla/venv/lib/python3.9/site-packages/dogpile/lock.py", line 94, in _enter
2023-03-13 22:55:33.342 37 ERROR keystone.server.flask.application     generated = self._enter_create(value, createdtime)
2023-03-13 22:55:33.342 37 ERROR keystone.server.flask.application   File "/var/lib/kolla/venv/lib/python3.9/site-packages/dogpile/lock.py", line 178, in _enter_create
2023-03-13 22:55:33.342 37 ERROR keystone.server.flask.application     return self.creator()
2023-03-13 22:55:33.342 37 ERROR keystone.server.flask.application   File "/var/lib/kolla/venv/lib/python3.9/site-packages/dogpile/cache/region.py", line 995, in gen_value
2023-03-13 22:55:33.342 37 ERROR keystone.server.flask.application     created_value = creator(
2023-03-13 22:55:33.342 37 ERROR keystone.server.flask.application   File "/var/lib/kolla/venv/lib/python3.9/site-packages/keystone/resource/core.py", line 903, in get_project
2023-03-13 22:55:33.342 37 ERROR keystone.server.flask.application     return self.driver.get_project(project_id)
2023-03-13 22:55:33.342 37 ERROR keystone.server.flask.application   File "/var/lib/kolla/venv/lib/python3.9/site-packages/keystone/resource/backends/sql.py", line 49, in get_project
2023-03-13 22:55:33.342 37 ERROR keystone.server.flask.application     return self._get_project(session, project_id).to_dict()
2023-03-13 22:55:33.342 37 ERROR keystone.server.flask.application   File "/var/lib/kolla/venv/lib/python3.9/site-packages/keystone/resource/backends/sql.py", line 44, in _get_project
2023-03-13 22:55:33.342 37 ERROR keystone.server.flask.application     raise exception.ProjectNotFound(project_id=project_id)
2023-03-13 22:55:33.342 37 ERROR keystone.server.flask.application keystone.exception.ProjectNotFound: Could not find project: service.
2023-03-13 22:55:33.342 37 ERROR keystone.server.flask.application 
2023-03-13 22:55:43.678 39 ERROR keystone.server.flask.application [None req-7442af63-666d-4966-802d-508839560e4b 28a3049e1dd74d85b768eaad8b970a99 - - all default -] Could not find role: admin.: keystone.exception.RoleNotFound: Could not find role: admin.
2023-03-13 22:55:43.678 39 ERROR keystone.server.flask.application Traceback (most recent call last):
2023-03-13 22:55:43.678 39 ERROR keystone.server.flask.application   File "/var/lib/kolla/venv/lib/python3.9/site-packages/flask/app.py", line 1820, in full_dispatch_request
2023-03-13 22:55:43.678 39 ERROR keystone.server.flask.application     rv = self.dispatch_request()
2023-03-13 22:55:43.678 39 ERROR keystone.server.flask.application   File "/var/lib/kolla/venv/lib/python3.9/site-packages/flask/app.py", line 1796, in dispatch_request
2023-03-13 22:55:43.678 39 ERROR keystone.server.flask.application     return self.ensure_sync(self.view_functions[rule.endpoint])(**view_args)
2023-03-13 22:55:43.678 39 ERROR keystone.server.flask.application   File "/var/lib/kolla/venv/lib/python3.9/site-packages/flask_restful/__init__.py", line 467, in wrapper
2023-03-13 22:55:43.678 39 ERROR keystone.server.flask.application     resp = resource(*args, **kwargs)
2023-03-13 22:55:43.678 39 ERROR keystone.server.flask.application   File "/var/lib/kolla/venv/lib/python3.9/site-packages/flask/views.py", line 107, in view
2023-03-13 22:55:43.678 39 ERROR keystone.server.flask.application     return current_app.ensure_sync(self.dispatch_request)(**kwargs)
2023-03-13 22:55:43.678 39 ERROR keystone.server.flask.application   File "/var/lib/kolla/venv/lib/python3.9/site-packages/flask_restful/__init__.py", line 582, in dispatch_request
2023-03-13 22:55:43.678 39 ERROR keystone.server.flask.application     resp = meth(*args, **kwargs)
2023-03-13 22:55:43.678 39 ERROR keystone.server.flask.application   File "/var/lib/kolla/venv/lib/python3.9/site-packages/keystone/api/roles.py", line 50, in get
2023-03-13 22:55:43.678 39 ERROR keystone.server.flask.application     return self._get_role(role_id)
2023-03-13 22:55:43.678 39 ERROR keystone.server.flask.application   File "/var/lib/kolla/venv/lib/python3.9/site-packages/keystone/api/roles.py", line 70, in _get_role
2023-03-13 22:55:43.678 39 ERROR keystone.server.flask.application     ENFORCER.enforce_call(action='identity:get_role')
2023-03-13 22:55:43.678 39 ERROR keystone.server.flask.application   File "/var/lib/kolla/venv/lib/python3.9/site-packages/keystone/common/rbac_enforcer/enforcer.py", line 402, in enforce_call
2023-03-13 22:55:43.678 39 ERROR keystone.server.flask.application     policy_dict.update(cls._extract_member_target_data(
2023-03-13 22:55:43.678 39 ERROR keystone.server.flask.application   File "/var/lib/kolla/venv/lib/python3.9/site-packages/keystone/common/rbac_enforcer/enforcer.py", line 234, in _extract_member_target_data
2023-03-13 22:55:43.678 39 ERROR keystone.server.flask.application     member_name: func(flask.request.view_args[key])
2023-03-13 22:55:43.678 39 ERROR keystone.server.flask.application   File "/var/lib/kolla/venv/lib/python3.9/site-packages/keystone/common/manager.py", line 115, in wrapped
2023-03-13 22:55:43.678 39 ERROR keystone.server.flask.application     __ret_val = __f(*args, **kwargs)
2023-03-13 22:55:43.678 39 ERROR keystone.server.flask.application   File "/var/lib/kolla/venv/lib/python3.9/site-packages/decorator.py", line 232, in fun
2023-03-13 22:55:43.678 39 ERROR keystone.server.flask.application     return caller(func, *(extras + args), **kw)
2023-03-13 22:55:43.678 39 ERROR keystone.server.flask.application   File "/var/lib/kolla/venv/lib/python3.9/site-packages/dogpile/cache/region.py", line 1577, in get_or_create_for_user_func
2023-03-13 22:55:43.678 39 ERROR keystone.server.flask.application     return self.get_or_create(
2023-03-13 22:55:43.678 39 ERROR keystone.server.flask.application   File "/var/lib/kolla/venv/lib/python3.9/site-packages/dogpile/cache/region.py", line 1042, in get_or_create
2023-03-13 22:55:43.678 39 ERROR keystone.server.flask.application     with Lock(
2023-03-13 22:55:43.678 39 ERROR keystone.server.flask.application   File "/var/lib/kolla/venv/lib/python3.9/site-packages/dogpile/lock.py", line 185, in __enter__
2023-03-13 22:55:43.678 39 ERROR keystone.server.flask.application     return self._enter()
2023-03-13 22:55:43.678 39 ERROR keystone.server.flask.application   File "/var/lib/kolla/venv/lib/python3.9/site-packages/dogpile/lock.py", line 94, in _enter
2023-03-13 22:55:43.678 39 ERROR keystone.server.flask.application     generated = self._enter_create(value, createdtime)
2023-03-13 22:55:43.678 39 ERROR keystone.server.flask.application   File "/var/lib/kolla/venv/lib/python3.9/site-packages/dogpile/lock.py", line 178, in _enter_create
2023-03-13 22:55:43.678 39 ERROR keystone.server.flask.application     return self.creator()
2023-03-13 22:55:43.678 39 ERROR keystone.server.flask.application   File "/var/lib/kolla/venv/lib/python3.9/site-packages/dogpile/cache/region.py", line 995, in gen_value
2023-03-13 22:55:43.678 39 ERROR keystone.server.flask.application     created_value = creator(
2023-03-13 22:55:43.678 39 ERROR keystone.server.flask.application   File "/var/lib/kolla/venv/lib/python3.9/site-packages/keystone/assignment/core.py", line 1276, in get_role
2023-03-13 22:55:43.678 39 ERROR keystone.server.flask.application     return self.driver.get_role(role_id)
2023-03-13 22:55:43.678 39 ERROR keystone.server.flask.application   File "/var/lib/kolla/venv/lib/python3.9/site-packages/keystone/assignment/role_backends/sql.py", line 70, in get_role
2023-03-13 22:55:43.678 39 ERROR keystone.server.flask.application     return self._get_role(session, role_id).to_dict()
2023-03-13 22:55:43.678 39 ERROR keystone.server.flask.application   File "/var/lib/kolla/venv/lib/python3.9/site-packages/keystone/assignment/role_backends/sql.py", line 65, in _get_role
2023-03-13 22:55:43.678 39 ERROR keystone.server.flask.application     raise exception.RoleNotFound(role_id=role_id)
2023-03-13 22:55:43.678 39 ERROR keystone.server.flask.application keystone.exception.RoleNotFound: Could not find role: admin.
2023-03-13 22:55:43.678 39 ERROR keystone.server.flask.application 
2023-03-13 22:55:44.684 39 ERROR keystone.server.flask.application [None req-254927ed-c71c-43dc-a39d-bc8518c8e407 28a3049e1dd74d85b768eaad8b970a99 - - all default -] Could not find user: ironic-inspector.: keystone.exception.UserNotFound: Could not find user: ironic-inspector.
2023-03-13 22:55:44.684 39 ERROR keystone.server.flask.application Traceback (most recent call last):
2023-03-13 22:55:44.684 39 ERROR keystone.server.flask.application   File "/var/lib/kolla/venv/lib/python3.9/site-packages/flask/app.py", line 1820, in full_dispatch_request
2023-03-13 22:55:44.684 39 ERROR keystone.server.flask.application     rv = self.dispatch_request()
2023-03-13 22:55:44.684 39 ERROR keystone.server.flask.application   File "/var/lib/kolla/venv/lib/python3.9/site-packages/flask/app.py", line 1796, in dispatch_request
2023-03-13 22:55:44.684 39 ERROR keystone.server.flask.application     return self.ensure_sync(self.view_functions[rule.endpoint])(**view_args)
2023-03-13 22:55:44.684 39 ERROR keystone.server.flask.application   File "/var/lib/kolla/venv/lib/python3.9/site-packages/flask_restful/__init__.py", line 467, in wrapper
2023-03-13 22:55:44.684 39 ERROR keystone.server.flask.application     resp = resource(*args, **kwargs)
2023-03-13 22:55:44.684 39 ERROR keystone.server.flask.application   File "/var/lib/kolla/venv/lib/python3.9/site-packages/flask/views.py", line 107, in view
2023-03-13 22:55:44.684 39 ERROR keystone.server.flask.application     return current_app.ensure_sync(self.dispatch_request)(**kwargs)
2023-03-13 22:55:44.684 39 ERROR keystone.server.flask.application   File "/var/lib/kolla/venv/lib/python3.9/site-packages/flask_restful/__init__.py", line 582, in dispatch_request
2023-03-13 22:55:44.684 39 ERROR keystone.server.flask.application     resp = meth(*args, **kwargs)
2023-03-13 22:55:44.684 39 ERROR keystone.server.flask.application   File "/var/lib/kolla/venv/lib/python3.9/site-packages/keystone/api/users.py", line 182, in get
2023-03-13 22:55:44.684 39 ERROR keystone.server.flask.application     return self._get_user(user_id)
2023-03-13 22:55:44.684 39 ERROR keystone.server.flask.application   File "/var/lib/kolla/venv/lib/python3.9/site-packages/keystone/api/users.py", line 194, in _get_user
2023-03-13 22:55:44.684 39 ERROR keystone.server.flask.application     ref = PROVIDERS.identity_api.get_user(user_id)
2023-03-13 22:55:44.684 39 ERROR keystone.server.flask.application   File "/var/lib/kolla/venv/lib/python3.9/site-packages/keystone/common/manager.py", line 115, in wrapped
2023-03-13 22:55:44.684 39 ERROR keystone.server.flask.application     __ret_val = __f(*args, **kwargs)
2023-03-13 22:55:44.684 39 ERROR keystone.server.flask.application   File "/var/lib/kolla/venv/lib/python3.9/site-packages/keystone/identity/core.py", line 414, in wrapper
2023-03-13 22:55:44.684 39 ERROR keystone.server.flask.application     return f(self, *args, **kwargs)
2023-03-13 22:55:44.684 39 ERROR keystone.server.flask.application   File "/var/lib/kolla/venv/lib/python3.9/site-packages/keystone/identity/core.py", line 424, in wrapper
2023-03-13 22:55:44.684 39 ERROR keystone.server.flask.application     return f(self, *args, **kwargs)
2023-03-13 22:55:44.684 39 ERROR keystone.server.flask.application   File "/var/lib/kolla/venv/lib/python3.9/site-packages/decorator.py", line 232, in fun
2023-03-13 22:55:44.684 39 ERROR keystone.server.flask.application     return caller(func, *(extras + args), **kw)
2023-03-13 22:55:44.684 39 ERROR keystone.server.flask.application   File "/var/lib/kolla/venv/lib/python3.9/site-packages/dogpile/cache/region.py", line 1577, in get_or_create_for_user_func
2023-03-13 22:55:44.684 39 ERROR keystone.server.flask.application     return self.get_or_create(
2023-03-13 22:55:44.684 39 ERROR keystone.server.flask.application   File "/var/lib/kolla/venv/lib/python3.9/site-packages/dogpile/cache/region.py", line 1042, in get_or_create
2023-03-13 22:55:44.684 39 ERROR keystone.server.flask.application     with Lock(
2023-03-13 22:55:44.684 39 ERROR keystone.server.flask.application   File "/var/lib/kolla/venv/lib/python3.9/site-packages/dogpile/lock.py", line 185, in __enter__
2023-03-13 22:55:44.684 39 ERROR keystone.server.flask.application     return self._enter()
2023-03-13 22:55:44.684 39 ERROR keystone.server.flask.application   File "/var/lib/kolla/venv/lib/python3.9/site-packages/dogpile/lock.py", line 94, in _enter
2023-03-13 22:55:44.684 39 ERROR keystone.server.flask.application     generated = self._enter_create(value, createdtime)
2023-03-13 22:55:44.684 39 ERROR keystone.server.flask.application   File "/var/lib/kolla/venv/lib/python3.9/site-packages/dogpile/lock.py", line 178, in _enter_create
2023-03-13 22:55:44.684 39 ERROR keystone.server.flask.application     return self.creator()
2023-03-13 22:55:44.684 39 ERROR keystone.server.flask.application   File "/var/lib/kolla/venv/lib/python3.9/site-packages/dogpile/cache/region.py", line 995, in gen_value
2023-03-13 22:55:44.684 39 ERROR keystone.server.flask.application     created_value = creator(
2023-03-13 22:55:44.684 39 ERROR keystone.server.flask.application   File "/var/lib/kolla/venv/lib/python3.9/site-packages/keystone/identity/core.py", line 1011, in get_user
2023-03-13 22:55:44.684 39 ERROR keystone.server.flask.application     ref = driver.get_user(entity_id)
2023-03-13 22:55:44.684 39 ERROR keystone.server.flask.application   File "/var/lib/kolla/venv/lib/python3.9/site-packages/keystone/identity/backends/sql.py", line 200, in get_user
2023-03-13 22:55:44.684 39 ERROR keystone.server.flask.application     self._get_user(session, user_id).to_dict())
2023-03-13 22:55:44.684 39 ERROR keystone.server.flask.application   File "/var/lib/kolla/venv/lib/python3.9/site-packages/keystone/identity/backends/sql.py", line 194, in _get_user
2023-03-13 22:55:44.684 39 ERROR keystone.server.flask.application     raise exception.UserNotFound(user_id=user_id)
2023-03-13 22:55:44.684 39 ERROR keystone.server.flask.application keystone.exception.UserNotFound: Could not find user: ironic-inspector.
2023-03-13 22:55:44.684 39 ERROR keystone.server.flask.application 
2023-03-13 22:55:45.407 37 ERROR keystone.server.flask.application [None req-88adfc1b-bc99-48db-8822-d912dc3499e6 28a3049e1dd74d85b768eaad8b970a99 - - all default -] Could not find project: service.: keystone.exception.ProjectNotFound: Could not find project: service.
2023-03-13 22:55:45.407 37 ERROR keystone.server.flask.application Traceback (most recent call last):
2023-03-13 22:55:45.407 37 ERROR keystone.server.flask.application   File "/var/lib/kolla/venv/lib/python3.9/site-packages/flask/app.py", line 1820, in full_dispatch_request
2023-03-13 22:55:45.407 37 ERROR keystone.server.flask.application     rv = self.dispatch_request()
2023-03-13 22:55:45.407 37 ERROR keystone.server.flask.application   File "/var/lib/kolla/venv/lib/python3.9/site-packages/flask/app.py", line 1796, in dispatch_request
2023-03-13 22:55:45.407 37 ERROR keystone.server.flask.application     return self.ensure_sync(self.view_functions[rule.endpoint])(**view_args)
2023-03-13 22:55:45.407 37 ERROR keystone.server.flask.application   File "/var/lib/kolla/venv/lib/python3.9/site-packages/flask_restful/__init__.py", line 467, in wrapper
2023-03-13 22:55:45.407 37 ERROR keystone.server.flask.application     resp = resource(*args, **kwargs)
2023-03-13 22:55:45.407 37 ERROR keystone.server.flask.application   File "/var/lib/kolla/venv/lib/python3.9/site-packages/flask/views.py", line 107, in view
2023-03-13 22:55:45.407 37 ERROR keystone.server.flask.application     return current_app.ensure_sync(self.dispatch_request)(**kwargs)
2023-03-13 22:55:45.407 37 ERROR keystone.server.flask.application   File "/var/lib/kolla/venv/lib/python3.9/site-packages/flask_restful/__init__.py", line 582, in dispatch_request
2023-03-13 22:55:45.407 37 ERROR keystone.server.flask.application     resp = meth(*args, **kwargs)
2023-03-13 22:55:45.407 37 ERROR keystone.server.flask.application   File "/var/lib/kolla/venv/lib/python3.9/site-packages/keystone/api/projects.py", line 151, in get
2023-03-13 22:55:45.407 37 ERROR keystone.server.flask.application     return self._get_project(project_id)
2023-03-13 22:55:45.407 37 ERROR keystone.server.flask.application   File "/var/lib/kolla/venv/lib/python3.9/site-packages/keystone/api/projects.py", line 107, in _get_project
2023-03-13 22:55:45.407 37 ERROR keystone.server.flask.application     project = PROVIDERS.resource_api.get_project(project_id)
2023-03-13 22:55:45.407 37 ERROR keystone.server.flask.application   File "/var/lib/kolla/venv/lib/python3.9/site-packages/keystone/common/manager.py", line 115, in wrapped
2023-03-13 22:55:45.407 37 ERROR keystone.server.flask.application     __ret_val = __f(*args, **kwargs)
2023-03-13 22:55:45.407 37 ERROR keystone.server.flask.application   File "/var/lib/kolla/venv/lib/python3.9/site-packages/decorator.py", line 232, in fun
2023-03-13 22:55:45.407 37 ERROR keystone.server.flask.application     return caller(func, *(extras + args), **kw)
2023-03-13 22:55:45.407 37 ERROR keystone.server.flask.application   File "/var/lib/kolla/venv/lib/python3.9/site-packages/dogpile/cache/region.py", line 1577, in get_or_create_for_user_func
2023-03-13 22:55:45.407 37 ERROR keystone.server.flask.application     return self.get_or_create(
2023-03-13 22:55:45.407 37 ERROR keystone.server.flask.application   File "/var/lib/kolla/venv/lib/python3.9/site-packages/dogpile/cache/region.py", line 1042, in get_or_create
2023-03-13 22:55:45.407 37 ERROR keystone.server.flask.application     with Lock(
2023-03-13 22:55:45.407 37 ERROR keystone.server.flask.application   File "/var/lib/kolla/venv/lib/python3.9/site-packages/dogpile/lock.py", line 185, in __enter__
2023-03-13 22:55:45.407 37 ERROR keystone.server.flask.application     return self._enter()
2023-03-13 22:55:45.407 37 ERROR keystone.server.flask.application   File "/var/lib/kolla/venv/lib/python3.9/site-packages/dogpile/lock.py", line 94, in _enter
2023-03-13 22:55:45.407 37 ERROR keystone.server.flask.application     generated = self._enter_create(value, createdtime)
2023-03-13 22:55:45.407 37 ERROR keystone.server.flask.application   File "/var/lib/kolla/venv/lib/python3.9/site-packages/dogpile/lock.py", line 178, in _enter_create
2023-03-13 22:55:45.407 37 ERROR keystone.server.flask.application     return self.creator()
2023-03-13 22:55:45.407 37 ERROR keystone.server.flask.application   File "/var/lib/kolla/venv/lib/python3.9/site-packages/dogpile/cache/region.py", line 995, in gen_value
2023-03-13 22:55:45.407 37 ERROR keystone.server.flask.application     created_value = creator(
2023-03-13 22:55:45.407 37 ERROR keystone.server.flask.application   File "/var/lib/kolla/venv/lib/python3.9/site-packages/keystone/resource/core.py", line 903, in get_project
2023-03-13 22:55:45.407 37 ERROR keystone.server.flask.application     return self.driver.get_project(project_id)
2023-03-13 22:55:45.407 37 ERROR keystone.server.flask.application   File "/var/lib/kolla/venv/lib/python3.9/site-packages/keystone/resource/backends/sql.py", line 49, in get_project
2023-03-13 22:55:45.407 37 ERROR keystone.server.flask.application     return self._get_project(session, project_id).to_dict()
2023-03-13 22:55:45.407 37 ERROR keystone.server.flask.application   File "/var/lib/kolla/venv/lib/python3.9/site-packages/keystone/resource/backends/sql.py", line 44, in _get_project
2023-03-13 22:55:45.407 37 ERROR keystone.server.flask.application     raise exception.ProjectNotFound(project_id=project_id)
2023-03-13 22:55:45.407 37 ERROR keystone.server.flask.application keystone.exception.ProjectNotFound: Could not find project: service.
2023-03-13 22:55:45.407 37 ERROR keystone.server.flask.application 
2023-03-13 22:58:34.189 37 ERROR keystone.server.flask.application [None req-3c5bb7f2-0e22-4667-8fd7-4e6da7091461 28a3049e1dd74d85b768eaad8b970a99 - - all default -] Could not find project: service.: keystone.exception.ProjectNotFound: Could not find project: service.
2023-03-13 22:58:34.189 37 ERROR keystone.server.flask.application Traceback (most recent call last):
2023-03-13 22:58:34.189 37 ERROR keystone.server.flask.application   File "/var/lib/kolla/venv/lib/python3.9/site-packages/flask/app.py", line 1820, in full_dispatch_request
2023-03-13 22:58:34.189 37 ERROR keystone.server.flask.application     rv = self.dispatch_request()
2023-03-13 22:58:34.189 37 ERROR keystone.server.flask.application   File "/var/lib/kolla/venv/lib/python3.9/site-packages/flask/app.py", line 1796, in dispatch_request
2023-03-13 22:58:34.189 37 ERROR keystone.server.flask.application     return self.ensure_sync(self.view_functions[rule.endpoint])(**view_args)
2023-03-13 22:58:34.189 37 ERROR keystone.server.flask.application   File "/var/lib/kolla/venv/lib/python3.9/site-packages/flask_restful/__init__.py", line 467, in wrapper
2023-03-13 22:58:34.189 37 ERROR keystone.server.flask.application     resp = resource(*args, **kwargs)
2023-03-13 22:58:34.189 37 ERROR keystone.server.flask.application   File "/var/lib/kolla/venv/lib/python3.9/site-packages/flask/views.py", line 107, in view
2023-03-13 22:58:34.189 37 ERROR keystone.server.flask.application     return current_app.ensure_sync(self.dispatch_request)(**kwargs)
2023-03-13 22:58:34.189 37 ERROR keystone.server.flask.application   File "/var/lib/kolla/venv/lib/python3.9/site-packages/flask_restful/__init__.py", line 582, in dispatch_request
2023-03-13 22:58:34.189 37 ERROR keystone.server.flask.application     resp = meth(*args, **kwargs)
2023-03-13 22:58:34.189 37 ERROR keystone.server.flask.application   File "/var/lib/kolla/venv/lib/python3.9/site-packages/keystone/api/projects.py", line 151, in get
2023-03-13 22:58:34.189 37 ERROR keystone.server.flask.application     return self._get_project(project_id)
2023-03-13 22:58:34.189 37 ERROR keystone.server.flask.application   File "/var/lib/kolla/venv/lib/python3.9/site-packages/keystone/api/projects.py", line 107, in _get_project
2023-03-13 22:58:34.189 37 ERROR keystone.server.flask.application     project = PROVIDERS.resource_api.get_project(project_id)
2023-03-13 22:58:34.189 37 ERROR keystone.server.flask.application   File "/var/lib/kolla/venv/lib/python3.9/site-packages/keystone/common/manager.py", line 115, in wrapped
2023-03-13 22:58:34.189 37 ERROR keystone.server.flask.application     __ret_val = __f(*args, **kwargs)
2023-03-13 22:58:34.189 37 ERROR keystone.server.flask.application   File "/var/lib/kolla/venv/lib/python3.9/site-packages/decorator.py", line 232, in fun
2023-03-13 22:58:34.189 37 ERROR keystone.server.flask.application     return caller(func, *(extras + args), **kw)
2023-03-13 22:58:34.189 37 ERROR keystone.server.flask.application   File "/var/lib/kolla/venv/lib/python3.9/site-packages/dogpile/cache/region.py", line 1577, in get_or_create_for_user_func
2023-03-13 22:58:34.189 37 ERROR keystone.server.flask.application     return self.get_or_create(
2023-03-13 22:58:34.189 37 ERROR keystone.server.flask.application   File "/var/lib/kolla/venv/lib/python3.9/site-packages/dogpile/cache/region.py", line 1042, in get_or_create
2023-03-13 22:58:34.189 37 ERROR keystone.server.flask.application     with Lock(
2023-03-13 22:58:34.189 37 ERROR keystone.server.flask.application   File "/var/lib/kolla/venv/lib/python3.9/site-packages/dogpile/lock.py", line 185, in __enter__
2023-03-13 22:58:34.189 37 ERROR keystone.server.flask.application     return self._enter()
2023-03-13 22:58:34.189 37 ERROR keystone.server.flask.application   File "/var/lib/kolla/venv/lib/python3.9/site-packages/dogpile/lock.py", line 94, in _enter
2023-03-13 22:58:34.189 37 ERROR keystone.server.flask.application     generated = self._enter_create(value, createdtime)
2023-03-13 22:58:34.189 37 ERROR keystone.server.flask.application   File "/var/lib/kolla/venv/lib/python3.9/site-packages/dogpile/lock.py", line 178, in _enter_create
2023-03-13 22:58:34.189 37 ERROR keystone.server.flask.application     return self.creator()
2023-03-13 22:58:34.189 37 ERROR keystone.server.flask.application   File "/var/lib/kolla/venv/lib/python3.9/site-packages/dogpile/cache/region.py", line 995, in gen_value
2023-03-13 22:58:34.189 37 ERROR keystone.server.flask.application     created_value = creator(
2023-03-13 22:58:34.189 37 ERROR keystone.server.flask.application   File "/var/lib/kolla/venv/lib/python3.9/site-packages/keystone/resource/core.py", line 903, in get_project
2023-03-13 22:58:34.189 37 ERROR keystone.server.flask.application     return self.driver.get_project(project_id)
2023-03-13 22:58:34.189 37 ERROR keystone.server.flask.application   File "/var/lib/kolla/venv/lib/python3.9/site-packages/keystone/resource/backends/sql.py", line 49, in get_project
2023-03-13 22:58:34.189 37 ERROR keystone.server.flask.application     return self._get_project(session, project_id).to_dict()
2023-03-13 22:58:34.189 37 ERROR keystone.server.flask.application   File "/var/lib/kolla/venv/lib/python3.9/site-packages/keystone/resource/backends/sql.py", line 44, in _get_project
2023-03-13 22:58:34.189 37 ERROR keystone.server.flask.application     raise exception.ProjectNotFound(project_id=project_id)
2023-03-13 22:58:34.189 37 ERROR keystone.server.flask.application keystone.exception.ProjectNotFound: Could not find project: service.
2023-03-13 22:58:34.189 37 ERROR keystone.server.flask.application 
2023-03-13 22:58:48.291 38 ERROR keystone.server.flask.application [None req-69998ece-3979-4382-89b1-c362a41cf7b1 28a3049e1dd74d85b768eaad8b970a99 - - all default -] Could not find role: admin.: keystone.exception.RoleNotFound: Could not find role: admin.
2023-03-13 22:58:48.291 38 ERROR keystone.server.flask.application Traceback (most recent call last):
2023-03-13 22:58:48.291 38 ERROR keystone.server.flask.application   File "/var/lib/kolla/venv/lib/python3.9/site-packages/flask/app.py", line 1820, in full_dispatch_request
2023-03-13 22:58:48.291 38 ERROR keystone.server.flask.application     rv = self.dispatch_request()
2023-03-13 22:58:48.291 38 ERROR keystone.server.flask.application   File "/var/lib/kolla/venv/lib/python3.9/site-packages/flask/app.py", line 1796, in dispatch_request
2023-03-13 22:58:48.291 38 ERROR keystone.server.flask.application     return self.ensure_sync(self.view_functions[rule.endpoint])(**view_args)
2023-03-13 22:58:48.291 38 ERROR keystone.server.flask.application   File "/var/lib/kolla/venv/lib/python3.9/site-packages/flask_restful/__init__.py", line 467, in wrapper
2023-03-13 22:58:48.291 38 ERROR keystone.server.flask.application     resp = resource(*args, **kwargs)
2023-03-13 22:58:48.291 38 ERROR keystone.server.flask.application   File "/var/lib/kolla/venv/lib/python3.9/site-packages/flask/views.py", line 107, in view
2023-03-13 22:58:48.291 38 ERROR keystone.server.flask.application     return current_app.ensure_sync(self.dispatch_request)(**kwargs)
2023-03-13 22:58:48.291 38 ERROR keystone.server.flask.application   File "/var/lib/kolla/venv/lib/python3.9/site-packages/flask_restful/__init__.py", line 582, in dispatch_request
2023-03-13 22:58:48.291 38 ERROR keystone.server.flask.application     resp = meth(*args, **kwargs)
2023-03-13 22:58:48.291 38 ERROR keystone.server.flask.application   File "/var/lib/kolla/venv/lib/python3.9/site-packages/keystone/api/roles.py", line 50, in get
2023-03-13 22:58:48.291 38 ERROR keystone.server.flask.application     return self._get_role(role_id)
2023-03-13 22:58:48.291 38 ERROR keystone.server.flask.application   File "/var/lib/kolla/venv/lib/python3.9/site-packages/keystone/api/roles.py", line 70, in _get_role
2023-03-13 22:58:48.291 38 ERROR keystone.server.flask.application     ENFORCER.enforce_call(action='identity:get_role')
2023-03-13 22:58:48.291 38 ERROR keystone.server.flask.application   File "/var/lib/kolla/venv/lib/python3.9/site-packages/keystone/common/rbac_enforcer/enforcer.py", line 402, in enforce_call
2023-03-13 22:58:48.291 38 ERROR keystone.server.flask.application     policy_dict.update(cls._extract_member_target_data(
2023-03-13 22:58:48.291 38 ERROR keystone.server.flask.application   File "/var/lib/kolla/venv/lib/python3.9/site-packages/keystone/common/rbac_enforcer/enforcer.py", line 234, in _extract_member_target_data
2023-03-13 22:58:48.291 38 ERROR keystone.server.flask.application     member_name: func(flask.request.view_args[key])
2023-03-13 22:58:48.291 38 ERROR keystone.server.flask.application   File "/var/lib/kolla/venv/lib/python3.9/site-packages/keystone/common/manager.py", line 115, in wrapped
2023-03-13 22:58:48.291 38 ERROR keystone.server.flask.application     __ret_val = __f(*args, **kwargs)
2023-03-13 22:58:48.291 38 ERROR keystone.server.flask.application   File "/var/lib/kolla/venv/lib/python3.9/site-packages/decorator.py", line 232, in fun
2023-03-13 22:58:48.291 38 ERROR keystone.server.flask.application     return caller(func, *(extras + args), **kw)
2023-03-13 22:58:48.291 38 ERROR keystone.server.flask.application   File "/var/lib/kolla/venv/lib/python3.9/site-packages/dogpile/cache/region.py", line 1577, in get_or_create_for_user_func
2023-03-13 22:58:48.291 38 ERROR keystone.server.flask.application     return self.get_or_create(
2023-03-13 22:58:48.291 38 ERROR keystone.server.flask.application   File "/var/lib/kolla/venv/lib/python3.9/site-packages/dogpile/cache/region.py", line 1042, in get_or_create
2023-03-13 22:58:48.291 38 ERROR keystone.server.flask.application     with Lock(
2023-03-13 22:58:48.291 38 ERROR keystone.server.flask.application   File "/var/lib/kolla/venv/lib/python3.9/site-packages/dogpile/lock.py", line 185, in __enter__
2023-03-13 22:58:48.291 38 ERROR keystone.server.flask.application     return self._enter()
2023-03-13 22:58:48.291 38 ERROR keystone.server.flask.application   File "/var/lib/kolla/venv/lib/python3.9/site-packages/dogpile/lock.py", line 94, in _enter
2023-03-13 22:58:48.291 38 ERROR keystone.server.flask.application     generated = self._enter_create(value, createdtime)
2023-03-13 22:58:48.291 38 ERROR keystone.server.flask.application   File "/var/lib/kolla/venv/lib/python3.9/site-packages/dogpile/lock.py", line 178, in _enter_create
2023-03-13 22:58:48.291 38 ERROR keystone.server.flask.application     return self.creator()
2023-03-13 22:58:48.291 38 ERROR keystone.server.flask.application   File "/var/lib/kolla/venv/lib/python3.9/site-packages/dogpile/cache/region.py", line 995, in gen_value
2023-03-13 22:58:48.291 38 ERROR keystone.server.flask.application     created_value = creator(
2023-03-13 22:58:48.291 38 ERROR keystone.server.flask.application   File "/var/lib/kolla/venv/lib/python3.9/site-packages/keystone/assignment/core.py", line 1276, in get_role
2023-03-13 22:58:48.291 38 ERROR keystone.server.flask.application     return self.driver.get_role(role_id)
2023-03-13 22:58:48.291 38 ERROR keystone.server.flask.application   File "/var/lib/kolla/venv/lib/python3.9/site-packages/keystone/assignment/role_backends/sql.py", line 70, in get_role
2023-03-13 22:58:48.291 38 ERROR keystone.server.flask.application     return self._get_role(session, role_id).to_dict()
2023-03-13 22:58:48.291 38 ERROR keystone.server.flask.application   File "/var/lib/kolla/venv/lib/python3.9/site-packages/keystone/assignment/role_backends/sql.py", line 65, in _get_role
2023-03-13 22:58:48.291 38 ERROR keystone.server.flask.application     raise exception.RoleNotFound(role_id=role_id)
2023-03-13 22:58:48.291 38 ERROR keystone.server.flask.application keystone.exception.RoleNotFound: Could not find role: admin.
2023-03-13 22:58:48.291 38 ERROR keystone.server.flask.application 
2023-03-13 22:58:49.340 38 ERROR keystone.server.flask.application [None req-602a246d-f67c-4417-9534-909a4d28cfbd 28a3049e1dd74d85b768eaad8b970a99 - - all default -] Could not find user: neutron.: keystone.exception.UserNotFound: Could not find user: neutron.
2023-03-13 22:58:49.340 38 ERROR keystone.server.flask.application Traceback (most recent call last):
2023-03-13 22:58:49.340 38 ERROR keystone.server.flask.application   File "/var/lib/kolla/venv/lib/python3.9/site-packages/flask/app.py", line 1820, in full_dispatch_request
2023-03-13 22:58:49.340 38 ERROR keystone.server.flask.application     rv = self.dispatch_request()
2023-03-13 22:58:49.340 38 ERROR keystone.server.flask.application   File "/var/lib/kolla/venv/lib/python3.9/site-packages/flask/app.py", line 1796, in dispatch_request
2023-03-13 22:58:49.340 38 ERROR keystone.server.flask.application     return self.ensure_sync(self.view_functions[rule.endpoint])(**view_args)
2023-03-13 22:58:49.340 38 ERROR keystone.server.flask.application   File "/var/lib/kolla/venv/lib/python3.9/site-packages/flask_restful/__init__.py", line 467, in wrapper
2023-03-13 22:58:49.340 38 ERROR keystone.server.flask.application     resp = resource(*args, **kwargs)
2023-03-13 22:58:49.340 38 ERROR keystone.server.flask.application   File "/var/lib/kolla/venv/lib/python3.9/site-packages/flask/views.py", line 107, in view
2023-03-13 22:58:49.340 38 ERROR keystone.server.flask.application     return current_app.ensure_sync(self.dispatch_request)(**kwargs)
2023-03-13 22:58:49.340 38 ERROR keystone.server.flask.application   File "/var/lib/kolla/venv/lib/python3.9/site-packages/flask_restful/__init__.py", line 582, in dispatch_request
2023-03-13 22:58:49.340 38 ERROR keystone.server.flask.application     resp = meth(*args, **kwargs)
2023-03-13 22:58:49.340 38 ERROR keystone.server.flask.application   File "/var/lib/kolla/venv/lib/python3.9/site-packages/keystone/api/users.py", line 182, in get
2023-03-13 22:58:49.340 38 ERROR keystone.server.flask.application     return self._get_user(user_id)
2023-03-13 22:58:49.340 38 ERROR keystone.server.flask.application   File "/var/lib/kolla/venv/lib/python3.9/site-packages/keystone/api/users.py", line 194, in _get_user
2023-03-13 22:58:49.340 38 ERROR keystone.server.flask.application     ref = PROVIDERS.identity_api.get_user(user_id)
2023-03-13 22:58:49.340 38 ERROR keystone.server.flask.application   File "/var/lib/kolla/venv/lib/python3.9/site-packages/keystone/common/manager.py", line 115, in wrapped
2023-03-13 22:58:49.340 38 ERROR keystone.server.flask.application     __ret_val = __f(*args, **kwargs)
2023-03-13 22:58:49.340 38 ERROR keystone.server.flask.application   File "/var/lib/kolla/venv/lib/python3.9/site-packages/keystone/identity/core.py", line 414, in wrapper
2023-03-13 22:58:49.340 38 ERROR keystone.server.flask.application     return f(self, *args, **kwargs)
2023-03-13 22:58:49.340 38 ERROR keystone.server.flask.application   File "/var/lib/kolla/venv/lib/python3.9/site-packages/keystone/identity/core.py", line 424, in wrapper
2023-03-13 22:58:49.340 38 ERROR keystone.server.flask.application     return f(self, *args, **kwargs)
2023-03-13 22:58:49.340 38 ERROR keystone.server.flask.application   File "/var/lib/kolla/venv/lib/python3.9/site-packages/decorator.py", line 232, in fun
2023-03-13 22:58:49.340 38 ERROR keystone.server.flask.application     return caller(func, *(extras + args), **kw)
2023-03-13 22:58:49.340 38 ERROR keystone.server.flask.application   File "/var/lib/kolla/venv/lib/python3.9/site-packages/dogpile/cache/region.py", line 1577, in get_or_create_for_user_func
2023-03-13 22:58:49.340 38 ERROR keystone.server.flask.application     return self.get_or_create(
2023-03-13 22:58:49.340 38 ERROR keystone.server.flask.application   File "/var/lib/kolla/venv/lib/python3.9/site-packages/dogpile/cache/region.py", line 1042, in get_or_create
2023-03-13 22:58:49.340 38 ERROR keystone.server.flask.application     with Lock(
2023-03-13 22:58:49.340 38 ERROR keystone.server.flask.application   File "/var/lib/kolla/venv/lib/python3.9/site-packages/dogpile/lock.py", line 185, in __enter__
2023-03-13 22:58:49.340 38 ERROR keystone.server.flask.application     return self._enter()
2023-03-13 22:58:49.340 38 ERROR keystone.server.flask.application   File "/var/lib/kolla/venv/lib/python3.9/site-packages/dogpile/lock.py", line 94, in _enter
2023-03-13 22:58:49.340 38 ERROR keystone.server.flask.application     generated = self._enter_create(value, createdtime)
2023-03-13 22:58:49.340 38 ERROR keystone.server.flask.application   File "/var/lib/kolla/venv/lib/python3.9/site-packages/dogpile/lock.py", line 178, in _enter_create
2023-03-13 22:58:49.340 38 ERROR keystone.server.flask.application     return self.creator()
2023-03-13 22:58:49.340 38 ERROR keystone.server.flask.application   File "/var/lib/kolla/venv/lib/python3.9/site-packages/dogpile/cache/region.py", line 995, in gen_value
2023-03-13 22:58:49.340 38 ERROR keystone.server.flask.application     created_value = creator(
2023-03-13 22:58:49.340 38 ERROR keystone.server.flask.application   File "/var/lib/kolla/venv/lib/python3.9/site-packages/keystone/identity/core.py", line 1011, in get_user
2023-03-13 22:58:49.340 38 ERROR keystone.server.flask.application     ref = driver.get_user(entity_id)
2023-03-13 22:58:49.340 38 ERROR keystone.server.flask.application   File "/var/lib/kolla/venv/lib/python3.9/site-packages/keystone/identity/backends/sql.py", line 200, in get_user
2023-03-13 22:58:49.340 38 ERROR keystone.server.flask.application     self._get_user(session, user_id).to_dict())
2023-03-13 22:58:49.340 38 ERROR keystone.server.flask.application   File "/var/lib/kolla/venv/lib/python3.9/site-packages/keystone/identity/backends/sql.py", line 194, in _get_user
2023-03-13 22:58:49.340 38 ERROR keystone.server.flask.application     raise exception.UserNotFound(user_id=user_id)
2023-03-13 22:58:49.340 38 ERROR keystone.server.flask.application keystone.exception.UserNotFound: Could not find user: neutron.
2023-03-13 22:58:49.340 38 ERROR keystone.server.flask.application 
2023-03-13 22:58:50.037 39 ERROR keystone.server.flask.application [None req-4b32f913-40bf-4eb9-818a-7c72870f8168 28a3049e1dd74d85b768eaad8b970a99 - - all default -] Could not find project: service.: keystone.exception.ProjectNotFound: Could not find project: service.
2023-03-13 22:58:50.037 39 ERROR keystone.server.flask.application Traceback (most recent call last):
2023-03-13 22:58:50.037 39 ERROR keystone.server.flask.application   File "/var/lib/kolla/venv/lib/python3.9/site-packages/flask/app.py", line 1820, in full_dispatch_request
2023-03-13 22:58:50.037 39 ERROR keystone.server.flask.application     rv = self.dispatch_request()
2023-03-13 22:58:50.037 39 ERROR keystone.server.flask.application   File "/var/lib/kolla/venv/lib/python3.9/site-packages/flask/app.py", line 1796, in dispatch_request
2023-03-13 22:58:50.037 39 ERROR keystone.server.flask.application     return self.ensure_sync(self.view_functions[rule.endpoint])(**view_args)
2023-03-13 22:58:50.037 39 ERROR keystone.server.flask.application   File "/var/lib/kolla/venv/lib/python3.9/site-packages/flask_restful/__init__.py", line 467, in wrapper
2023-03-13 22:58:50.037 39 ERROR keystone.server.flask.application     resp = resource(*args, **kwargs)
2023-03-13 22:58:50.037 39 ERROR keystone.server.flask.application   File "/var/lib/kolla/venv/lib/python3.9/site-packages/flask/views.py", line 107, in view
2023-03-13 22:58:50.037 39 ERROR keystone.server.flask.application     return current_app.ensure_sync(self.dispatch_request)(**kwargs)
2023-03-13 22:58:50.037 39 ERROR keystone.server.flask.application   File "/var/lib/kolla/venv/lib/python3.9/site-packages/flask_restful/__init__.py", line 582, in dispatch_request
2023-03-13 22:58:50.037 39 ERROR keystone.server.flask.application     resp = meth(*args, **kwargs)
2023-03-13 22:58:50.037 39 ERROR keystone.server.flask.application   File "/var/lib/kolla/venv/lib/python3.9/site-packages/keystone/api/projects.py", line 151, in get
2023-03-13 22:58:50.037 39 ERROR keystone.server.flask.application     return self._get_project(project_id)
2023-03-13 22:58:50.037 39 ERROR keystone.server.flask.application   File "/var/lib/kolla/venv/lib/python3.9/site-packages/keystone/api/projects.py", line 107, in _get_project
2023-03-13 22:58:50.037 39 ERROR keystone.server.flask.application     project = PROVIDERS.resource_api.get_project(project_id)
2023-03-13 22:58:50.037 39 ERROR keystone.server.flask.application   File "/var/lib/kolla/venv/lib/python3.9/site-packages/keystone/common/manager.py", line 115, in wrapped
2023-03-13 22:58:50.037 39 ERROR keystone.server.flask.application     __ret_val = __f(*args, **kwargs)
2023-03-13 22:58:50.037 39 ERROR keystone.server.flask.application   File "/var/lib/kolla/venv/lib/python3.9/site-packages/decorator.py", line 232, in fun
2023-03-13 22:58:50.037 39 ERROR keystone.server.flask.application     return caller(func, *(extras + args), **kw)
2023-03-13 22:58:50.037 39 ERROR keystone.server.flask.application   File "/var/lib/kolla/venv/lib/python3.9/site-packages/dogpile/cache/region.py", line 1577, in get_or_create_for_user_func
2023-03-13 22:58:50.037 39 ERROR keystone.server.flask.application     return self.get_or_create(
2023-03-13 22:58:50.037 39 ERROR keystone.server.flask.application   File "/var/lib/kolla/venv/lib/python3.9/site-packages/dogpile/cache/region.py", line 1042, in get_or_create
2023-03-13 22:58:50.037 39 ERROR keystone.server.flask.application     with Lock(
2023-03-13 22:58:50.037 39 ERROR keystone.server.flask.application   File "/var/lib/kolla/venv/lib/python3.9/site-packages/dogpile/lock.py", line 185, in __enter__
2023-03-13 22:58:50.037 39 ERROR keystone.server.flask.application     return self._enter()
2023-03-13 22:58:50.037 39 ERROR keystone.server.flask.application   File "/var/lib/kolla/venv/lib/python3.9/site-packages/dogpile/lock.py", line 94, in _enter
2023-03-13 22:58:50.037 39 ERROR keystone.server.flask.application     generated = self._enter_create(value, createdtime)
2023-03-13 22:58:50.037 39 ERROR keystone.server.flask.application   File "/var/lib/kolla/venv/lib/python3.9/site-packages/dogpile/lock.py", line 178, in _enter_create
2023-03-13 22:58:50.037 39 ERROR keystone.server.flask.application     return self.creator()
2023-03-13 22:58:50.037 39 ERROR keystone.server.flask.application   File "/var/lib/kolla/venv/lib/python3.9/site-packages/dogpile/cache/region.py", line 995, in gen_value
2023-03-13 22:58:50.037 39 ERROR keystone.server.flask.application     created_value = creator(
2023-03-13 22:58:50.037 39 ERROR keystone.server.flask.application   File "/var/lib/kolla/venv/lib/python3.9/site-packages/keystone/resource/core.py", line 903, in get_project
2023-03-13 22:58:50.037 39 ERROR keystone.server.flask.application     return self.driver.get_project(project_id)
2023-03-13 22:58:50.037 39 ERROR keystone.server.flask.application   File "/var/lib/kolla/venv/lib/python3.9/site-packages/keystone/resource/backends/sql.py", line 49, in get_project
2023-03-13 22:58:50.037 39 ERROR keystone.server.flask.application     return self._get_project(session, project_id).to_dict()
2023-03-13 22:58:50.037 39 ERROR keystone.server.flask.application   File "/var/lib/kolla/venv/lib/python3.9/site-packages/keystone/resource/backends/sql.py", line 44, in _get_project
2023-03-13 22:58:50.037 39 ERROR keystone.server.flask.application     raise exception.ProjectNotFound(project_id=project_id)
2023-03-13 22:58:50.037 39 ERROR keystone.server.flask.application keystone.exception.ProjectNotFound: Could not find project: service.
2023-03-13 22:58:50.037 39 ERROR keystone.server.flask.application 
2023-03-13 23:51:56.252 37 WARNING py.warnings [None req-0e25d38b-136d-47df-a80c-80d29d3bd3db 28a3049e1dd74d85b768eaad8b970a99 654f00c3143e44fab98eda602783c92c - - default default] /var/lib/kolla/venv/lib/python3.9/site-packages/oslo_policy/policy.py:1129: UserWarning: Policy "identity:list_domains": "role:reader and system_scope:all" failed scope check. The token used to make the request was project scoped but the policy requires ['system'] scope. This behavior may change in the future where using the intended scope is required
  warnings.warn(msg)

2023-03-13 23:51:56.562 39 WARNING py.warnings [None req-c42161f3-0600-4f9e-93c3-c34636b20198 28a3049e1dd74d85b768eaad8b970a99 654f00c3143e44fab98eda602783c92c - - default default] /var/lib/kolla/venv/lib/python3.9/site-packages/oslo_policy/policy.py:1129: UserWarning: Policy "identity:create_project": "(role:admin and system_scope:all) or (role:admin and domain_id:%(target.project.domain_id)s)" failed scope check. The token used to make the request was project scoped but the policy requires ['system', 'domain'] scope. This behavior may change in the future where using the intended scope is required
  warnings.warn(msg)

2023-03-13 23:51:56.846 38 WARNING py.warnings [None req-5d9ef43a-be8a-4640-bd96-5c9797d4e03c 28a3049e1dd74d85b768eaad8b970a99 654f00c3143e44fab98eda602783c92c - - default default] /var/lib/kolla/venv/lib/python3.9/site-packages/oslo_policy/policy.py:1129: UserWarning: Policy "identity:create_user": "(role:admin and system_scope:all) or (role:admin and token.domain.id:%(target.user.domain_id)s)" failed scope check. The token used to make the request was project scoped but the policy requires ['system', 'domain'] scope. This behavior may change in the future where using the intended scope is required
  warnings.warn(msg)

2023-03-13 23:51:57.694 37 WARNING py.warnings [None req-fd3c67d9-459d-4f8d-a2d5-e6581bc3d461 28a3049e1dd74d85b768eaad8b970a99 654f00c3143e44fab98eda602783c92c - - default default] /var/lib/kolla/venv/lib/python3.9/site-packages/oslo_policy/policy.py:1129: UserWarning: Policy "identity:list_roles": "role:reader and system_scope:all" failed scope check. The token used to make the request was project scoped but the policy requires ['system'] scope. This behavior may change in the future where using the intended scope is required
  warnings.warn(msg)

2023-03-13 23:51:58.073 39 WARNING py.warnings [None req-c55578ca-855f-42ac-a683-d3d4e772ac3b 28a3049e1dd74d85b768eaad8b970a99 654f00c3143e44fab98eda602783c92c - - default default] /var/lib/kolla/venv/lib/python3.9/site-packages/oslo_policy/policy.py:1129: UserWarning: Policy "identity:create_grant": "(role:admin and system_scope:all) or ((role:admin and domain_id:%(target.user.domain_id)s and domain_id:%(target.project.domain_id)s) or (role:admin and domain_id:%(target.user.domain_id)s and domain_id:%(target.domain.id)s) or (role:admin and domain_id:%(target.group.domain_id)s and domain_id:%(target.project.domain_id)s) or (role:admin and domain_id:%(target.group.domain_id)s and domain_id:%(target.domain.id)s)) and (domain_id:%(target.role.domain_id)s or None:%(target.role.domain_id)s)" failed scope check. The token used to make the request was project scoped but the policy requires ['system', 'domain'] scope. This behavior may change in the future where using the intended scope is required
  warnings.warn(msg)

2023-03-13 23:51:59.315 38 WARNING py.warnings [None req-cfa3bcd4-91d6-424e-9b4c-bb24741db30a 28a3049e1dd74d85b768eaad8b970a99 654f00c3143e44fab98eda602783c92c - - default default] /var/lib/kolla/venv/lib/python3.9/site-packages/oslo_policy/policy.py:1129: UserWarning: Policy "identity:create_project": "(role:admin and system_scope:all) or (role:admin and domain_id:%(target.project.domain_id)s)" failed scope check. The token used to make the request was project scoped but the policy requires ['system', 'domain'] scope. This behavior may change in the future where using the intended scope is required
  warnings.warn(msg)

2023-03-13 23:51:59.747 37 WARNING py.warnings [None req-87612947-8130-4568-afb4-9f5bffb4ea67 28a3049e1dd74d85b768eaad8b970a99 654f00c3143e44fab98eda602783c92c - - default default] /var/lib/kolla/venv/lib/python3.9/site-packages/oslo_policy/policy.py:1129: UserWarning: Policy "identity:create_user": "(role:admin and system_scope:all) or (role:admin and token.domain.id:%(target.user.domain_id)s)" failed scope check. The token used to make the request was project scoped but the policy requires ['system', 'domain'] scope. This behavior may change in the future where using the intended scope is required
  warnings.warn(msg)

2023-03-13 23:52:00.690 39 WARNING py.warnings [None req-a697f7ff-5eb3-4edf-9d83-255d33208b0a 28a3049e1dd74d85b768eaad8b970a99 654f00c3143e44fab98eda602783c92c - - default default] /var/lib/kolla/venv/lib/python3.9/site-packages/oslo_policy/policy.py:1129: UserWarning: Policy "identity:list_roles": "role:reader and system_scope:all" failed scope check. The token used to make the request was project scoped but the policy requires ['system'] scope. This behavior may change in the future where using the intended scope is required
  warnings.warn(msg)

2023-03-13 23:52:00.979 38 WARNING py.warnings [None req-13988278-ec42-4529-b832-23d213ee2ad0 28a3049e1dd74d85b768eaad8b970a99 654f00c3143e44fab98eda602783c92c - - default default] /var/lib/kolla/venv/lib/python3.9/site-packages/oslo_policy/policy.py:1129: UserWarning: Policy "identity:create_grant": "(role:admin and system_scope:all) or ((role:admin and domain_id:%(target.user.domain_id)s and domain_id:%(target.project.domain_id)s) or (role:admin and domain_id:%(target.user.domain_id)s and domain_id:%(target.domain.id)s) or (role:admin and domain_id:%(target.group.domain_id)s and domain_id:%(target.project.domain_id)s) or (role:admin and domain_id:%(target.group.domain_id)s and domain_id:%(target.domain.id)s)) and (domain_id:%(target.role.domain_id)s or None:%(target.role.domain_id)s)" failed scope check. The token used to make the request was project scoped but the policy requires ['system', 'domain'] scope. This behavior may change in the future where using the intended scope is required
  warnings.warn(msg)

2023-03-13 23:52:03.878 38 WARNING py.warnings [None req-b0fa83a4-4ff8-4811-b7b5-c36c344eab3c 28a3049e1dd74d85b768eaad8b970a99 654f00c3143e44fab98eda602783c92c - - default default] /var/lib/kolla/venv/lib/python3.9/site-packages/oslo_policy/policy.py:1129: UserWarning: Policy "identity:create_system_grant_for_user": "role:admin and system_scope:all" failed scope check. The token used to make the request was project scoped but the policy requires ['system'] scope. This behavior may change in the future where using the intended scope is required
  warnings.warn(msg)

