2023-03-01 17:27:19.117 24 INFO alembic.runtime.migration [-] Context impl MySQLImpl.
2023-03-01 17:27:19.121 24 INFO alembic.runtime.migration [-] Will assume non-transactional DDL.
2023-03-01 17:27:19.158 24 INFO alembic.runtime.migration [-] Context impl MySQLImpl.
2023-03-01 17:27:19.159 24 INFO alembic.runtime.migration [-] Will assume non-transactional DDL.
2023-03-01 17:27:19.199 24 INFO alembic.runtime.migration [-] Running upgrade  -> 27e647c0fad4, Initial version.
2023-03-01 17:27:20.310 24 INFO alembic.runtime.migration [-] Running upgrade 27e647c0fad4 -> e25ffa003242, Initial no-op Yoga contract migration.
2023-03-01 17:27:20.315 24 INFO alembic.runtime.migration [-] Running upgrade 27e647c0fad4 -> 29e87d24a316, Initial no-op Yoga expand migration.
2023-03-01 17:27:28.876 7 INFO keystone.common.fernet_utils [-] Created a new temporary key: /etc/keystone/fernet-keys/0.tmp
2023-03-01 17:27:28.880 7 INFO keystone.common.fernet_utils [-] Become a valid new key: /etc/keystone/fernet-keys/0
2023-03-01 17:27:28.881 7 INFO keystone.common.fernet_utils [-] Starting key rotation with 1 key files: ['/etc/keystone/fernet-keys/0']
2023-03-01 17:27:28.882 7 INFO keystone.common.fernet_utils [-] Created a new temporary key: /etc/keystone/fernet-keys/0.tmp
2023-03-01 17:27:28.882 7 INFO keystone.common.fernet_utils [-] Current primary key is: 0
2023-03-01 17:27:28.883 7 INFO keystone.common.fernet_utils [-] Next primary key will be: 1
2023-03-01 17:27:28.883 7 INFO keystone.common.fernet_utils [-] Promoted key 0 to be the primary: 1
2023-03-01 17:27:28.884 7 INFO keystone.common.fernet_utils [-] Become a valid new key: /etc/keystone/fernet-keys/0
2023-03-01 17:27:47.036 32 INFO keystone.cmd.bootstrap [None req-f03a9439-72bd-48f9-9a64-24f75e2adc4d - - - - - -] Created domain default
2023-03-01 17:27:47.110 32 INFO keystone.cmd.bootstrap [None req-f03a9439-72bd-48f9-9a64-24f75e2adc4d - - - - - -] Created project admin
2023-03-01 17:27:47.729 32 INFO keystone.cmd.bootstrap [None req-f03a9439-72bd-48f9-9a64-24f75e2adc4d - - - - - -] Created user admin
2023-03-01 17:27:47.750 32 INFO keystone.cmd.bootstrap [None req-f03a9439-72bd-48f9-9a64-24f75e2adc4d - - - - - -] Created role reader
2023-03-01 17:27:47.767 32 INFO keystone.cmd.bootstrap [None req-f03a9439-72bd-48f9-9a64-24f75e2adc4d - - - - - -] Created role member
2023-03-01 17:27:47.806 32 INFO keystone.cmd.bootstrap [None req-f03a9439-72bd-48f9-9a64-24f75e2adc4d - - - - - -] Created implied role where e5860794c07940719579e20306d4589e implies ca4f8233481744979954aabc5300bb57
2023-03-01 17:27:47.823 32 INFO keystone.cmd.bootstrap [None req-f03a9439-72bd-48f9-9a64-24f75e2adc4d - - - - - -] Created role admin
2023-03-01 17:27:47.853 32 INFO keystone.cmd.bootstrap [None req-f03a9439-72bd-48f9-9a64-24f75e2adc4d - - - - - -] Created implied role where afc0f69ac2954b2d828e519a56e2b307 implies e5860794c07940719579e20306d4589e
2023-03-01 17:27:47.871 32 INFO keystone.cmd.bootstrap [None req-f03a9439-72bd-48f9-9a64-24f75e2adc4d - - - - - -] Granted role admin on project admin to user admin.
2023-03-01 17:27:47.881 32 INFO keystone.cmd.bootstrap [None req-f03a9439-72bd-48f9-9a64-24f75e2adc4d - - - - - -] Granted role admin on the system to user admin.
2023-03-01 17:27:47.902 32 WARNING py.warnings [None req-f03a9439-72bd-48f9-9a64-24f75e2adc4d - - - - - -] /var/lib/kolla/venv/lib/python3.9/site-packages/pycadf/identifier.py:71: UserWarning: Invalid uuid: RegionOne. To ensure interoperability, identifiers should be a valid uuid.
  warnings.warn(('Invalid uuid: %s. To ensure interoperability, '

2023-03-01 17:27:47.911 32 INFO keystone.cmd.bootstrap [None req-f03a9439-72bd-48f9-9a64-24f75e2adc4d - - - - - -] Created region RegionOne
2023-03-01 17:27:47.980 32 INFO keystone.cmd.bootstrap [None req-f03a9439-72bd-48f9-9a64-24f75e2adc4d - - - - - -] Created public endpoint http://169.16.1.170:5000
2023-03-01 17:27:48.000 32 INFO keystone.cmd.bootstrap [None req-f03a9439-72bd-48f9-9a64-24f75e2adc4d - - - - - -] Created internal endpoint http://169.16.1.170:5000
2023-03-01 17:28:12.786 39 WARNING keystone.common.rbac_enforcer.enforcer [None req-122df2ea-35d3-4f61-bf44-e27fa9820728 11e59edeaab843dd8ac2a0622768a80f - - all default -] Deprecated policy rules found. Use oslopolicy-policy-generator and oslopolicy-policy-upgrade to detect and resolve deprecated policies in your configuration.
2023-03-01 17:28:13.568 38 WARNING keystone.common.rbac_enforcer.enforcer [None req-400e1259-f44c-4ca2-a950-70f1b9cecb98 11e59edeaab843dd8ac2a0622768a80f - - all default -] Deprecated policy rules found. Use oslopolicy-policy-generator and oslopolicy-policy-upgrade to detect and resolve deprecated policies in your configuration.
2023-03-01 17:28:20.328 37 WARNING keystone.common.rbac_enforcer.enforcer [None req-9b497621-1587-4a32-a72e-de3c08f64e81 11e59edeaab843dd8ac2a0622768a80f - - all default -] Deprecated policy rules found. Use oslopolicy-policy-generator and oslopolicy-policy-upgrade to detect and resolve deprecated policies in your configuration.
2023-03-01 17:29:37.567 39 ERROR keystone.server.flask.application [None req-95419dea-3e61-4f82-aa83-82d86b0e201e 11e59edeaab843dd8ac2a0622768a80f - - all default -] Could not find project: service.: keystone.exception.ProjectNotFound: Could not find project: service.
2023-03-01 17:29:37.567 39 ERROR keystone.server.flask.application Traceback (most recent call last):
2023-03-01 17:29:37.567 39 ERROR keystone.server.flask.application   File "/var/lib/kolla/venv/lib/python3.9/site-packages/flask/app.py", line 1820, in full_dispatch_request
2023-03-01 17:29:37.567 39 ERROR keystone.server.flask.application     rv = self.dispatch_request()
2023-03-01 17:29:37.567 39 ERROR keystone.server.flask.application   File "/var/lib/kolla/venv/lib/python3.9/site-packages/flask/app.py", line 1796, in dispatch_request
2023-03-01 17:29:37.567 39 ERROR keystone.server.flask.application     return self.ensure_sync(self.view_functions[rule.endpoint])(**view_args)
2023-03-01 17:29:37.567 39 ERROR keystone.server.flask.application   File "/var/lib/kolla/venv/lib/python3.9/site-packages/flask_restful/__init__.py", line 467, in wrapper
2023-03-01 17:29:37.567 39 ERROR keystone.server.flask.application     resp = resource(*args, **kwargs)
2023-03-01 17:29:37.567 39 ERROR keystone.server.flask.application   File "/var/lib/kolla/venv/lib/python3.9/site-packages/flask/views.py", line 107, in view
2023-03-01 17:29:37.567 39 ERROR keystone.server.flask.application     return current_app.ensure_sync(self.dispatch_request)(**kwargs)
2023-03-01 17:29:37.567 39 ERROR keystone.server.flask.application   File "/var/lib/kolla/venv/lib/python3.9/site-packages/flask_restful/__init__.py", line 582, in dispatch_request
2023-03-01 17:29:37.567 39 ERROR keystone.server.flask.application     resp = meth(*args, **kwargs)
2023-03-01 17:29:37.567 39 ERROR keystone.server.flask.application   File "/var/lib/kolla/venv/lib/python3.9/site-packages/keystone/api/projects.py", line 151, in get
2023-03-01 17:29:37.567 39 ERROR keystone.server.flask.application     return self._get_project(project_id)
2023-03-01 17:29:37.567 39 ERROR keystone.server.flask.application   File "/var/lib/kolla/venv/lib/python3.9/site-packages/keystone/api/projects.py", line 107, in _get_project
2023-03-01 17:29:37.567 39 ERROR keystone.server.flask.application     project = PROVIDERS.resource_api.get_project(project_id)
2023-03-01 17:29:37.567 39 ERROR keystone.server.flask.application   File "/var/lib/kolla/venv/lib/python3.9/site-packages/keystone/common/manager.py", line 115, in wrapped
2023-03-01 17:29:37.567 39 ERROR keystone.server.flask.application     __ret_val = __f(*args, **kwargs)
2023-03-01 17:29:37.567 39 ERROR keystone.server.flask.application   File "/var/lib/kolla/venv/lib/python3.9/site-packages/decorator.py", line 232, in fun
2023-03-01 17:29:37.567 39 ERROR keystone.server.flask.application     return caller(func, *(extras + args), **kw)
2023-03-01 17:29:37.567 39 ERROR keystone.server.flask.application   File "/var/lib/kolla/venv/lib/python3.9/site-packages/dogpile/cache/region.py", line 1577, in get_or_create_for_user_func
2023-03-01 17:29:37.567 39 ERROR keystone.server.flask.application     return self.get_or_create(
2023-03-01 17:29:37.567 39 ERROR keystone.server.flask.application   File "/var/lib/kolla/venv/lib/python3.9/site-packages/dogpile/cache/region.py", line 1042, in get_or_create
2023-03-01 17:29:37.567 39 ERROR keystone.server.flask.application     with Lock(
2023-03-01 17:29:37.567 39 ERROR keystone.server.flask.application   File "/var/lib/kolla/venv/lib/python3.9/site-packages/dogpile/lock.py", line 185, in __enter__
2023-03-01 17:29:37.567 39 ERROR keystone.server.flask.application     return self._enter()
2023-03-01 17:29:37.567 39 ERROR keystone.server.flask.application   File "/var/lib/kolla/venv/lib/python3.9/site-packages/dogpile/lock.py", line 94, in _enter
2023-03-01 17:29:37.567 39 ERROR keystone.server.flask.application     generated = self._enter_create(value, createdtime)
2023-03-01 17:29:37.567 39 ERROR keystone.server.flask.application   File "/var/lib/kolla/venv/lib/python3.9/site-packages/dogpile/lock.py", line 178, in _enter_create
2023-03-01 17:29:37.567 39 ERROR keystone.server.flask.application     return self.creator()
2023-03-01 17:29:37.567 39 ERROR keystone.server.flask.application   File "/var/lib/kolla/venv/lib/python3.9/site-packages/dogpile/cache/region.py", line 995, in gen_value
2023-03-01 17:29:37.567 39 ERROR keystone.server.flask.application     created_value = creator(
2023-03-01 17:29:37.567 39 ERROR keystone.server.flask.application   File "/var/lib/kolla/venv/lib/python3.9/site-packages/keystone/resource/core.py", line 903, in get_project
2023-03-01 17:29:37.567 39 ERROR keystone.server.flask.application     return self.driver.get_project(project_id)
2023-03-01 17:29:37.567 39 ERROR keystone.server.flask.application   File "/var/lib/kolla/venv/lib/python3.9/site-packages/keystone/resource/backends/sql.py", line 49, in get_project
2023-03-01 17:29:37.567 39 ERROR keystone.server.flask.application     return self._get_project(session, project_id).to_dict()
2023-03-01 17:29:37.567 39 ERROR keystone.server.flask.application   File "/var/lib/kolla/venv/lib/python3.9/site-packages/keystone/resource/backends/sql.py", line 44, in _get_project
2023-03-01 17:29:37.567 39 ERROR keystone.server.flask.application     raise exception.ProjectNotFound(project_id=project_id)
2023-03-01 17:29:37.567 39 ERROR keystone.server.flask.application keystone.exception.ProjectNotFound: Could not find project: service.
2023-03-01 17:29:37.567 39 ERROR keystone.server.flask.application 
2023-03-01 17:29:47.578 37 ERROR keystone.server.flask.application [None req-5409909e-7677-4298-aa7d-5faa94829b1c 11e59edeaab843dd8ac2a0622768a80f - - all default -] Could not find project: service.: keystone.exception.ProjectNotFound: Could not find project: service.
2023-03-01 17:29:47.578 37 ERROR keystone.server.flask.application Traceback (most recent call last):
2023-03-01 17:29:47.578 37 ERROR keystone.server.flask.application   File "/var/lib/kolla/venv/lib/python3.9/site-packages/flask/app.py", line 1820, in full_dispatch_request
2023-03-01 17:29:47.578 37 ERROR keystone.server.flask.application     rv = self.dispatch_request()
2023-03-01 17:29:47.578 37 ERROR keystone.server.flask.application   File "/var/lib/kolla/venv/lib/python3.9/site-packages/flask/app.py", line 1796, in dispatch_request
2023-03-01 17:29:47.578 37 ERROR keystone.server.flask.application     return self.ensure_sync(self.view_functions[rule.endpoint])(**view_args)
2023-03-01 17:29:47.578 37 ERROR keystone.server.flask.application   File "/var/lib/kolla/venv/lib/python3.9/site-packages/flask_restful/__init__.py", line 467, in wrapper
2023-03-01 17:29:47.578 37 ERROR keystone.server.flask.application     resp = resource(*args, **kwargs)
2023-03-01 17:29:47.578 37 ERROR keystone.server.flask.application   File "/var/lib/kolla/venv/lib/python3.9/site-packages/flask/views.py", line 107, in view
2023-03-01 17:29:47.578 37 ERROR keystone.server.flask.application     return current_app.ensure_sync(self.dispatch_request)(**kwargs)
2023-03-01 17:29:47.578 37 ERROR keystone.server.flask.application   File "/var/lib/kolla/venv/lib/python3.9/site-packages/flask_restful/__init__.py", line 582, in dispatch_request
2023-03-01 17:29:47.578 37 ERROR keystone.server.flask.application     resp = meth(*args, **kwargs)
2023-03-01 17:29:47.578 37 ERROR keystone.server.flask.application   File "/var/lib/kolla/venv/lib/python3.9/site-packages/keystone/api/projects.py", line 151, in get
2023-03-01 17:29:47.578 37 ERROR keystone.server.flask.application     return self._get_project(project_id)
2023-03-01 17:29:47.578 37 ERROR keystone.server.flask.application   File "/var/lib/kolla/venv/lib/python3.9/site-packages/keystone/api/projects.py", line 107, in _get_project
2023-03-01 17:29:47.578 37 ERROR keystone.server.flask.application     project = PROVIDERS.resource_api.get_project(project_id)
2023-03-01 17:29:47.578 37 ERROR keystone.server.flask.application   File "/var/lib/kolla/venv/lib/python3.9/site-packages/keystone/common/manager.py", line 115, in wrapped
2023-03-01 17:29:47.578 37 ERROR keystone.server.flask.application     __ret_val = __f(*args, **kwargs)
2023-03-01 17:29:47.578 37 ERROR keystone.server.flask.application   File "/var/lib/kolla/venv/lib/python3.9/site-packages/decorator.py", line 232, in fun
2023-03-01 17:29:47.578 37 ERROR keystone.server.flask.application     return caller(func, *(extras + args), **kw)
2023-03-01 17:29:47.578 37 ERROR keystone.server.flask.application   File "/var/lib/kolla/venv/lib/python3.9/site-packages/dogpile/cache/region.py", line 1577, in get_or_create_for_user_func
2023-03-01 17:29:47.578 37 ERROR keystone.server.flask.application     return self.get_or_create(
2023-03-01 17:29:47.578 37 ERROR keystone.server.flask.application   File "/var/lib/kolla/venv/lib/python3.9/site-packages/dogpile/cache/region.py", line 1042, in get_or_create
2023-03-01 17:29:47.578 37 ERROR keystone.server.flask.application     with Lock(
2023-03-01 17:29:47.578 37 ERROR keystone.server.flask.application   File "/var/lib/kolla/venv/lib/python3.9/site-packages/dogpile/lock.py", line 185, in __enter__
2023-03-01 17:29:47.578 37 ERROR keystone.server.flask.application     return self._enter()
2023-03-01 17:29:47.578 37 ERROR keystone.server.flask.application   File "/var/lib/kolla/venv/lib/python3.9/site-packages/dogpile/lock.py", line 94, in _enter
2023-03-01 17:29:47.578 37 ERROR keystone.server.flask.application     generated = self._enter_create(value, createdtime)
2023-03-01 17:29:47.578 37 ERROR keystone.server.flask.application   File "/var/lib/kolla/venv/lib/python3.9/site-packages/dogpile/lock.py", line 178, in _enter_create
2023-03-01 17:29:47.578 37 ERROR keystone.server.flask.application     return self.creator()
2023-03-01 17:29:47.578 37 ERROR keystone.server.flask.application   File "/var/lib/kolla/venv/lib/python3.9/site-packages/dogpile/cache/region.py", line 995, in gen_value
2023-03-01 17:29:47.578 37 ERROR keystone.server.flask.application     created_value = creator(
2023-03-01 17:29:47.578 37 ERROR keystone.server.flask.application   File "/var/lib/kolla/venv/lib/python3.9/site-packages/keystone/resource/core.py", line 903, in get_project
2023-03-01 17:29:47.578 37 ERROR keystone.server.flask.application     return self.driver.get_project(project_id)
2023-03-01 17:29:47.578 37 ERROR keystone.server.flask.application   File "/var/lib/kolla/venv/lib/python3.9/site-packages/keystone/resource/backends/sql.py", line 49, in get_project
2023-03-01 17:29:47.578 37 ERROR keystone.server.flask.application     return self._get_project(session, project_id).to_dict()
2023-03-01 17:29:47.578 37 ERROR keystone.server.flask.application   File "/var/lib/kolla/venv/lib/python3.9/site-packages/keystone/resource/backends/sql.py", line 44, in _get_project
2023-03-01 17:29:47.578 37 ERROR keystone.server.flask.application     raise exception.ProjectNotFound(project_id=project_id)
2023-03-01 17:29:47.578 37 ERROR keystone.server.flask.application keystone.exception.ProjectNotFound: Could not find project: service.
2023-03-01 17:29:47.578 37 ERROR keystone.server.flask.application 
2023-03-01 17:30:03.046 37 ERROR keystone.server.flask.application [None req-5d4abcf1-a6c8-4e09-a4ad-412c78481902 11e59edeaab843dd8ac2a0622768a80f - - all default -] Could not find role: admin.: keystone.exception.RoleNotFound: Could not find role: admin.
2023-03-01 17:30:03.046 37 ERROR keystone.server.flask.application Traceback (most recent call last):
2023-03-01 17:30:03.046 37 ERROR keystone.server.flask.application   File "/var/lib/kolla/venv/lib/python3.9/site-packages/flask/app.py", line 1820, in full_dispatch_request
2023-03-01 17:30:03.046 37 ERROR keystone.server.flask.application     rv = self.dispatch_request()
2023-03-01 17:30:03.046 37 ERROR keystone.server.flask.application   File "/var/lib/kolla/venv/lib/python3.9/site-packages/flask/app.py", line 1796, in dispatch_request
2023-03-01 17:30:03.046 37 ERROR keystone.server.flask.application     return self.ensure_sync(self.view_functions[rule.endpoint])(**view_args)
2023-03-01 17:30:03.046 37 ERROR keystone.server.flask.application   File "/var/lib/kolla/venv/lib/python3.9/site-packages/flask_restful/__init__.py", line 467, in wrapper
2023-03-01 17:30:03.046 37 ERROR keystone.server.flask.application     resp = resource(*args, **kwargs)
2023-03-01 17:30:03.046 37 ERROR keystone.server.flask.application   File "/var/lib/kolla/venv/lib/python3.9/site-packages/flask/views.py", line 107, in view
2023-03-01 17:30:03.046 37 ERROR keystone.server.flask.application     return current_app.ensure_sync(self.dispatch_request)(**kwargs)
2023-03-01 17:30:03.046 37 ERROR keystone.server.flask.application   File "/var/lib/kolla/venv/lib/python3.9/site-packages/flask_restful/__init__.py", line 582, in dispatch_request
2023-03-01 17:30:03.046 37 ERROR keystone.server.flask.application     resp = meth(*args, **kwargs)
2023-03-01 17:30:03.046 37 ERROR keystone.server.flask.application   File "/var/lib/kolla/venv/lib/python3.9/site-packages/keystone/api/roles.py", line 50, in get
2023-03-01 17:30:03.046 37 ERROR keystone.server.flask.application     return self._get_role(role_id)
2023-03-01 17:30:03.046 37 ERROR keystone.server.flask.application   File "/var/lib/kolla/venv/lib/python3.9/site-packages/keystone/api/roles.py", line 70, in _get_role
2023-03-01 17:30:03.046 37 ERROR keystone.server.flask.application     ENFORCER.enforce_call(action='identity:get_role')
2023-03-01 17:30:03.046 37 ERROR keystone.server.flask.application   File "/var/lib/kolla/venv/lib/python3.9/site-packages/keystone/common/rbac_enforcer/enforcer.py", line 402, in enforce_call
2023-03-01 17:30:03.046 37 ERROR keystone.server.flask.application     policy_dict.update(cls._extract_member_target_data(
2023-03-01 17:30:03.046 37 ERROR keystone.server.flask.application   File "/var/lib/kolla/venv/lib/python3.9/site-packages/keystone/common/rbac_enforcer/enforcer.py", line 234, in _extract_member_target_data
2023-03-01 17:30:03.046 37 ERROR keystone.server.flask.application     member_name: func(flask.request.view_args[key])
2023-03-01 17:30:03.046 37 ERROR keystone.server.flask.application   File "/var/lib/kolla/venv/lib/python3.9/site-packages/keystone/common/manager.py", line 115, in wrapped
2023-03-01 17:30:03.046 37 ERROR keystone.server.flask.application     __ret_val = __f(*args, **kwargs)
2023-03-01 17:30:03.046 37 ERROR keystone.server.flask.application   File "/var/lib/kolla/venv/lib/python3.9/site-packages/decorator.py", line 232, in fun
2023-03-01 17:30:03.046 37 ERROR keystone.server.flask.application     return caller(func, *(extras + args), **kw)
2023-03-01 17:30:03.046 37 ERROR keystone.server.flask.application   File "/var/lib/kolla/venv/lib/python3.9/site-packages/dogpile/cache/region.py", line 1577, in get_or_create_for_user_func
2023-03-01 17:30:03.046 37 ERROR keystone.server.flask.application     return self.get_or_create(
2023-03-01 17:30:03.046 37 ERROR keystone.server.flask.application   File "/var/lib/kolla/venv/lib/python3.9/site-packages/dogpile/cache/region.py", line 1042, in get_or_create
2023-03-01 17:30:03.046 37 ERROR keystone.server.flask.application     with Lock(
2023-03-01 17:30:03.046 37 ERROR keystone.server.flask.application   File "/var/lib/kolla/venv/lib/python3.9/site-packages/dogpile/lock.py", line 185, in __enter__
2023-03-01 17:30:03.046 37 ERROR keystone.server.flask.application     return self._enter()
2023-03-01 17:30:03.046 37 ERROR keystone.server.flask.application   File "/var/lib/kolla/venv/lib/python3.9/site-packages/dogpile/lock.py", line 94, in _enter
2023-03-01 17:30:03.046 37 ERROR keystone.server.flask.application     generated = self._enter_create(value, createdtime)
2023-03-01 17:30:03.046 37 ERROR keystone.server.flask.application   File "/var/lib/kolla/venv/lib/python3.9/site-packages/dogpile/lock.py", line 178, in _enter_create
2023-03-01 17:30:03.046 37 ERROR keystone.server.flask.application     return self.creator()
2023-03-01 17:30:03.046 37 ERROR keystone.server.flask.application   File "/var/lib/kolla/venv/lib/python3.9/site-packages/dogpile/cache/region.py", line 995, in gen_value
2023-03-01 17:30:03.046 37 ERROR keystone.server.flask.application     created_value = creator(
2023-03-01 17:30:03.046 37 ERROR keystone.server.flask.application   File "/var/lib/kolla/venv/lib/python3.9/site-packages/keystone/assignment/core.py", line 1276, in get_role
2023-03-01 17:30:03.046 37 ERROR keystone.server.flask.application     return self.driver.get_role(role_id)
2023-03-01 17:30:03.046 37 ERROR keystone.server.flask.application   File "/var/lib/kolla/venv/lib/python3.9/site-packages/keystone/assignment/role_backends/sql.py", line 70, in get_role
2023-03-01 17:30:03.046 37 ERROR keystone.server.flask.application     return self._get_role(session, role_id).to_dict()
2023-03-01 17:30:03.046 37 ERROR keystone.server.flask.application   File "/var/lib/kolla/venv/lib/python3.9/site-packages/keystone/assignment/role_backends/sql.py", line 65, in _get_role
2023-03-01 17:30:03.046 37 ERROR keystone.server.flask.application     raise exception.RoleNotFound(role_id=role_id)
2023-03-01 17:30:03.046 37 ERROR keystone.server.flask.application keystone.exception.RoleNotFound: Could not find role: admin.
2023-03-01 17:30:03.046 37 ERROR keystone.server.flask.application 
2023-03-01 17:30:04.256 37 ERROR keystone.server.flask.application [None req-ebda3953-5fe6-40e3-a76c-9c11ea42db67 11e59edeaab843dd8ac2a0622768a80f - - all default -] Could not find user: ironic.: keystone.exception.UserNotFound: Could not find user: ironic.
2023-03-01 17:30:04.256 37 ERROR keystone.server.flask.application Traceback (most recent call last):
2023-03-01 17:30:04.256 37 ERROR keystone.server.flask.application   File "/var/lib/kolla/venv/lib/python3.9/site-packages/flask/app.py", line 1820, in full_dispatch_request
2023-03-01 17:30:04.256 37 ERROR keystone.server.flask.application     rv = self.dispatch_request()
2023-03-01 17:30:04.256 37 ERROR keystone.server.flask.application   File "/var/lib/kolla/venv/lib/python3.9/site-packages/flask/app.py", line 1796, in dispatch_request
2023-03-01 17:30:04.256 37 ERROR keystone.server.flask.application     return self.ensure_sync(self.view_functions[rule.endpoint])(**view_args)
2023-03-01 17:30:04.256 37 ERROR keystone.server.flask.application   File "/var/lib/kolla/venv/lib/python3.9/site-packages/flask_restful/__init__.py", line 467, in wrapper
2023-03-01 17:30:04.256 37 ERROR keystone.server.flask.application     resp = resource(*args, **kwargs)
2023-03-01 17:30:04.256 37 ERROR keystone.server.flask.application   File "/var/lib/kolla/venv/lib/python3.9/site-packages/flask/views.py", line 107, in view
2023-03-01 17:30:04.256 37 ERROR keystone.server.flask.application     return current_app.ensure_sync(self.dispatch_request)(**kwargs)
2023-03-01 17:30:04.256 37 ERROR keystone.server.flask.application   File "/var/lib/kolla/venv/lib/python3.9/site-packages/flask_restful/__init__.py", line 582, in dispatch_request
2023-03-01 17:30:04.256 37 ERROR keystone.server.flask.application     resp = meth(*args, **kwargs)
2023-03-01 17:30:04.256 37 ERROR keystone.server.flask.application   File "/var/lib/kolla/venv/lib/python3.9/site-packages/keystone/api/users.py", line 182, in get
2023-03-01 17:30:04.256 37 ERROR keystone.server.flask.application     return self._get_user(user_id)
2023-03-01 17:30:04.256 37 ERROR keystone.server.flask.application   File "/var/lib/kolla/venv/lib/python3.9/site-packages/keystone/api/users.py", line 194, in _get_user
2023-03-01 17:30:04.256 37 ERROR keystone.server.flask.application     ref = PROVIDERS.identity_api.get_user(user_id)
2023-03-01 17:30:04.256 37 ERROR keystone.server.flask.application   File "/var/lib/kolla/venv/lib/python3.9/site-packages/keystone/common/manager.py", line 115, in wrapped
2023-03-01 17:30:04.256 37 ERROR keystone.server.flask.application     __ret_val = __f(*args, **kwargs)
2023-03-01 17:30:04.256 37 ERROR keystone.server.flask.application   File "/var/lib/kolla/venv/lib/python3.9/site-packages/keystone/identity/core.py", line 414, in wrapper
2023-03-01 17:30:04.256 37 ERROR keystone.server.flask.application     return f(self, *args, **kwargs)
2023-03-01 17:30:04.256 37 ERROR keystone.server.flask.application   File "/var/lib/kolla/venv/lib/python3.9/site-packages/keystone/identity/core.py", line 424, in wrapper
2023-03-01 17:30:04.256 37 ERROR keystone.server.flask.application     return f(self, *args, **kwargs)
2023-03-01 17:30:04.256 37 ERROR keystone.server.flask.application   File "/var/lib/kolla/venv/lib/python3.9/site-packages/decorator.py", line 232, in fun
2023-03-01 17:30:04.256 37 ERROR keystone.server.flask.application     return caller(func, *(extras + args), **kw)
2023-03-01 17:30:04.256 37 ERROR keystone.server.flask.application   File "/var/lib/kolla/venv/lib/python3.9/site-packages/dogpile/cache/region.py", line 1577, in get_or_create_for_user_func
2023-03-01 17:30:04.256 37 ERROR keystone.server.flask.application     return self.get_or_create(
2023-03-01 17:30:04.256 37 ERROR keystone.server.flask.application   File "/var/lib/kolla/venv/lib/python3.9/site-packages/dogpile/cache/region.py", line 1042, in get_or_create
2023-03-01 17:30:04.256 37 ERROR keystone.server.flask.application     with Lock(
2023-03-01 17:30:04.256 37 ERROR keystone.server.flask.application   File "/var/lib/kolla/venv/lib/python3.9/site-packages/dogpile/lock.py", line 185, in __enter__
2023-03-01 17:30:04.256 37 ERROR keystone.server.flask.application     return self._enter()
2023-03-01 17:30:04.256 37 ERROR keystone.server.flask.application   File "/var/lib/kolla/venv/lib/python3.9/site-packages/dogpile/lock.py", line 94, in _enter
2023-03-01 17:30:04.256 37 ERROR keystone.server.flask.application     generated = self._enter_create(value, createdtime)
2023-03-01 17:30:04.256 37 ERROR keystone.server.flask.application   File "/var/lib/kolla/venv/lib/python3.9/site-packages/dogpile/lock.py", line 178, in _enter_create
2023-03-01 17:30:04.256 37 ERROR keystone.server.flask.application     return self.creator()
2023-03-01 17:30:04.256 37 ERROR keystone.server.flask.application   File "/var/lib/kolla/venv/lib/python3.9/site-packages/dogpile/cache/region.py", line 995, in gen_value
2023-03-01 17:30:04.256 37 ERROR keystone.server.flask.application     created_value = creator(
2023-03-01 17:30:04.256 37 ERROR keystone.server.flask.application   File "/var/lib/kolla/venv/lib/python3.9/site-packages/keystone/identity/core.py", line 1011, in get_user
2023-03-01 17:30:04.256 37 ERROR keystone.server.flask.application     ref = driver.get_user(entity_id)
2023-03-01 17:30:04.256 37 ERROR keystone.server.flask.application   File "/var/lib/kolla/venv/lib/python3.9/site-packages/keystone/identity/backends/sql.py", line 200, in get_user
2023-03-01 17:30:04.256 37 ERROR keystone.server.flask.application     self._get_user(session, user_id).to_dict())
2023-03-01 17:30:04.256 37 ERROR keystone.server.flask.application   File "/var/lib/kolla/venv/lib/python3.9/site-packages/keystone/identity/backends/sql.py", line 194, in _get_user
2023-03-01 17:30:04.256 37 ERROR keystone.server.flask.application     raise exception.UserNotFound(user_id=user_id)
2023-03-01 17:30:04.256 37 ERROR keystone.server.flask.application keystone.exception.UserNotFound: Could not find user: ironic.
2023-03-01 17:30:04.256 37 ERROR keystone.server.flask.application 
2023-03-01 17:30:05.135 38 ERROR keystone.server.flask.application [None req-4d589af2-8f58-4047-953b-ed0e05a4aafd 11e59edeaab843dd8ac2a0622768a80f - - all default -] Could not find project: service.: keystone.exception.ProjectNotFound: Could not find project: service.
2023-03-01 17:30:05.135 38 ERROR keystone.server.flask.application Traceback (most recent call last):
2023-03-01 17:30:05.135 38 ERROR keystone.server.flask.application   File "/var/lib/kolla/venv/lib/python3.9/site-packages/flask/app.py", line 1820, in full_dispatch_request
2023-03-01 17:30:05.135 38 ERROR keystone.server.flask.application     rv = self.dispatch_request()
2023-03-01 17:30:05.135 38 ERROR keystone.server.flask.application   File "/var/lib/kolla/venv/lib/python3.9/site-packages/flask/app.py", line 1796, in dispatch_request
2023-03-01 17:30:05.135 38 ERROR keystone.server.flask.application     return self.ensure_sync(self.view_functions[rule.endpoint])(**view_args)
2023-03-01 17:30:05.135 38 ERROR keystone.server.flask.application   File "/var/lib/kolla/venv/lib/python3.9/site-packages/flask_restful/__init__.py", line 467, in wrapper
2023-03-01 17:30:05.135 38 ERROR keystone.server.flask.application     resp = resource(*args, **kwargs)
2023-03-01 17:30:05.135 38 ERROR keystone.server.flask.application   File "/var/lib/kolla/venv/lib/python3.9/site-packages/flask/views.py", line 107, in view
2023-03-01 17:30:05.135 38 ERROR keystone.server.flask.application     return current_app.ensure_sync(self.dispatch_request)(**kwargs)
2023-03-01 17:30:05.135 38 ERROR keystone.server.flask.application   File "/var/lib/kolla/venv/lib/python3.9/site-packages/flask_restful/__init__.py", line 582, in dispatch_request
2023-03-01 17:30:05.135 38 ERROR keystone.server.flask.application     resp = meth(*args, **kwargs)
2023-03-01 17:30:05.135 38 ERROR keystone.server.flask.application   File "/var/lib/kolla/venv/lib/python3.9/site-packages/keystone/api/projects.py", line 151, in get
2023-03-01 17:30:05.135 38 ERROR keystone.server.flask.application     return self._get_project(project_id)
2023-03-01 17:30:05.135 38 ERROR keystone.server.flask.application   File "/var/lib/kolla/venv/lib/python3.9/site-packages/keystone/api/projects.py", line 107, in _get_project
2023-03-01 17:30:05.135 38 ERROR keystone.server.flask.application     project = PROVIDERS.resource_api.get_project(project_id)
2023-03-01 17:30:05.135 38 ERROR keystone.server.flask.application   File "/var/lib/kolla/venv/lib/python3.9/site-packages/keystone/common/manager.py", line 115, in wrapped
2023-03-01 17:30:05.135 38 ERROR keystone.server.flask.application     __ret_val = __f(*args, **kwargs)
2023-03-01 17:30:05.135 38 ERROR keystone.server.flask.application   File "/var/lib/kolla/venv/lib/python3.9/site-packages/decorator.py", line 232, in fun
2023-03-01 17:30:05.135 38 ERROR keystone.server.flask.application     return caller(func, *(extras + args), **kw)
2023-03-01 17:30:05.135 38 ERROR keystone.server.flask.application   File "/var/lib/kolla/venv/lib/python3.9/site-packages/dogpile/cache/region.py", line 1577, in get_or_create_for_user_func
2023-03-01 17:30:05.135 38 ERROR keystone.server.flask.application     return self.get_or_create(
2023-03-01 17:30:05.135 38 ERROR keystone.server.flask.application   File "/var/lib/kolla/venv/lib/python3.9/site-packages/dogpile/cache/region.py", line 1042, in get_or_create
2023-03-01 17:30:05.135 38 ERROR keystone.server.flask.application     with Lock(
2023-03-01 17:30:05.135 38 ERROR keystone.server.flask.application   File "/var/lib/kolla/venv/lib/python3.9/site-packages/dogpile/lock.py", line 185, in __enter__
2023-03-01 17:30:05.135 38 ERROR keystone.server.flask.application     return self._enter()
2023-03-01 17:30:05.135 38 ERROR keystone.server.flask.application   File "/var/lib/kolla/venv/lib/python3.9/site-packages/dogpile/lock.py", line 94, in _enter
2023-03-01 17:30:05.135 38 ERROR keystone.server.flask.application     generated = self._enter_create(value, createdtime)
2023-03-01 17:30:05.135 38 ERROR keystone.server.flask.application   File "/var/lib/kolla/venv/lib/python3.9/site-packages/dogpile/lock.py", line 178, in _enter_create
2023-03-01 17:30:05.135 38 ERROR keystone.server.flask.application     return self.creator()
2023-03-01 17:30:05.135 38 ERROR keystone.server.flask.application   File "/var/lib/kolla/venv/lib/python3.9/site-packages/dogpile/cache/region.py", line 995, in gen_value
2023-03-01 17:30:05.135 38 ERROR keystone.server.flask.application     created_value = creator(
2023-03-01 17:30:05.135 38 ERROR keystone.server.flask.application   File "/var/lib/kolla/venv/lib/python3.9/site-packages/keystone/resource/core.py", line 903, in get_project
2023-03-01 17:30:05.135 38 ERROR keystone.server.flask.application     return self.driver.get_project(project_id)
2023-03-01 17:30:05.135 38 ERROR keystone.server.flask.application   File "/var/lib/kolla/venv/lib/python3.9/site-packages/keystone/resource/backends/sql.py", line 49, in get_project
2023-03-01 17:30:05.135 38 ERROR keystone.server.flask.application     return self._get_project(session, project_id).to_dict()
2023-03-01 17:30:05.135 38 ERROR keystone.server.flask.application   File "/var/lib/kolla/venv/lib/python3.9/site-packages/keystone/resource/backends/sql.py", line 44, in _get_project
2023-03-01 17:30:05.135 38 ERROR keystone.server.flask.application     raise exception.ProjectNotFound(project_id=project_id)
2023-03-01 17:30:05.135 38 ERROR keystone.server.flask.application keystone.exception.ProjectNotFound: Could not find project: service.
2023-03-01 17:30:05.135 38 ERROR keystone.server.flask.application 
2023-03-01 17:30:14.943 39 ERROR keystone.server.flask.application [None req-dbf4e9ce-d2ab-4d90-9eea-2ae2f81b88a7 11e59edeaab843dd8ac2a0622768a80f - - all default -] Could not find role: admin.: keystone.exception.RoleNotFound: Could not find role: admin.
2023-03-01 17:30:14.943 39 ERROR keystone.server.flask.application Traceback (most recent call last):
2023-03-01 17:30:14.943 39 ERROR keystone.server.flask.application   File "/var/lib/kolla/venv/lib/python3.9/site-packages/flask/app.py", line 1820, in full_dispatch_request
2023-03-01 17:30:14.943 39 ERROR keystone.server.flask.application     rv = self.dispatch_request()
2023-03-01 17:30:14.943 39 ERROR keystone.server.flask.application   File "/var/lib/kolla/venv/lib/python3.9/site-packages/flask/app.py", line 1796, in dispatch_request
2023-03-01 17:30:14.943 39 ERROR keystone.server.flask.application     return self.ensure_sync(self.view_functions[rule.endpoint])(**view_args)
2023-03-01 17:30:14.943 39 ERROR keystone.server.flask.application   File "/var/lib/kolla/venv/lib/python3.9/site-packages/flask_restful/__init__.py", line 467, in wrapper
2023-03-01 17:30:14.943 39 ERROR keystone.server.flask.application     resp = resource(*args, **kwargs)
2023-03-01 17:30:14.943 39 ERROR keystone.server.flask.application   File "/var/lib/kolla/venv/lib/python3.9/site-packages/flask/views.py", line 107, in view
2023-03-01 17:30:14.943 39 ERROR keystone.server.flask.application     return current_app.ensure_sync(self.dispatch_request)(**kwargs)
2023-03-01 17:30:14.943 39 ERROR keystone.server.flask.application   File "/var/lib/kolla/venv/lib/python3.9/site-packages/flask_restful/__init__.py", line 582, in dispatch_request
2023-03-01 17:30:14.943 39 ERROR keystone.server.flask.application     resp = meth(*args, **kwargs)
2023-03-01 17:30:14.943 39 ERROR keystone.server.flask.application   File "/var/lib/kolla/venv/lib/python3.9/site-packages/keystone/api/roles.py", line 50, in get
2023-03-01 17:30:14.943 39 ERROR keystone.server.flask.application     return self._get_role(role_id)
2023-03-01 17:30:14.943 39 ERROR keystone.server.flask.application   File "/var/lib/kolla/venv/lib/python3.9/site-packages/keystone/api/roles.py", line 70, in _get_role
2023-03-01 17:30:14.943 39 ERROR keystone.server.flask.application     ENFORCER.enforce_call(action='identity:get_role')
2023-03-01 17:30:14.943 39 ERROR keystone.server.flask.application   File "/var/lib/kolla/venv/lib/python3.9/site-packages/keystone/common/rbac_enforcer/enforcer.py", line 402, in enforce_call
2023-03-01 17:30:14.943 39 ERROR keystone.server.flask.application     policy_dict.update(cls._extract_member_target_data(
2023-03-01 17:30:14.943 39 ERROR keystone.server.flask.application   File "/var/lib/kolla/venv/lib/python3.9/site-packages/keystone/common/rbac_enforcer/enforcer.py", line 234, in _extract_member_target_data
2023-03-01 17:30:14.943 39 ERROR keystone.server.flask.application     member_name: func(flask.request.view_args[key])
2023-03-01 17:30:14.943 39 ERROR keystone.server.flask.application   File "/var/lib/kolla/venv/lib/python3.9/site-packages/keystone/common/manager.py", line 115, in wrapped
2023-03-01 17:30:14.943 39 ERROR keystone.server.flask.application     __ret_val = __f(*args, **kwargs)
2023-03-01 17:30:14.943 39 ERROR keystone.server.flask.application   File "/var/lib/kolla/venv/lib/python3.9/site-packages/decorator.py", line 232, in fun
2023-03-01 17:30:14.943 39 ERROR keystone.server.flask.application     return caller(func, *(extras + args), **kw)
2023-03-01 17:30:14.943 39 ERROR keystone.server.flask.application   File "/var/lib/kolla/venv/lib/python3.9/site-packages/dogpile/cache/region.py", line 1577, in get_or_create_for_user_func
2023-03-01 17:30:14.943 39 ERROR keystone.server.flask.application     return self.get_or_create(
2023-03-01 17:30:14.943 39 ERROR keystone.server.flask.application   File "/var/lib/kolla/venv/lib/python3.9/site-packages/dogpile/cache/region.py", line 1042, in get_or_create
2023-03-01 17:30:14.943 39 ERROR keystone.server.flask.application     with Lock(
2023-03-01 17:30:14.943 39 ERROR keystone.server.flask.application   File "/var/lib/kolla/venv/lib/python3.9/site-packages/dogpile/lock.py", line 185, in __enter__
2023-03-01 17:30:14.943 39 ERROR keystone.server.flask.application     return self._enter()
2023-03-01 17:30:14.943 39 ERROR keystone.server.flask.application   File "/var/lib/kolla/venv/lib/python3.9/site-packages/dogpile/lock.py", line 94, in _enter
2023-03-01 17:30:14.943 39 ERROR keystone.server.flask.application     generated = self._enter_create(value, createdtime)
2023-03-01 17:30:14.943 39 ERROR keystone.server.flask.application   File "/var/lib/kolla/venv/lib/python3.9/site-packages/dogpile/lock.py", line 178, in _enter_create
2023-03-01 17:30:14.943 39 ERROR keystone.server.flask.application     return self.creator()
2023-03-01 17:30:14.943 39 ERROR keystone.server.flask.application   File "/var/lib/kolla/venv/lib/python3.9/site-packages/dogpile/cache/region.py", line 995, in gen_value
2023-03-01 17:30:14.943 39 ERROR keystone.server.flask.application     created_value = creator(
2023-03-01 17:30:14.943 39 ERROR keystone.server.flask.application   File "/var/lib/kolla/venv/lib/python3.9/site-packages/keystone/assignment/core.py", line 1276, in get_role
2023-03-01 17:30:14.943 39 ERROR keystone.server.flask.application     return self.driver.get_role(role_id)
2023-03-01 17:30:14.943 39 ERROR keystone.server.flask.application   File "/var/lib/kolla/venv/lib/python3.9/site-packages/keystone/assignment/role_backends/sql.py", line 70, in get_role
2023-03-01 17:30:14.943 39 ERROR keystone.server.flask.application     return self._get_role(session, role_id).to_dict()
2023-03-01 17:30:14.943 39 ERROR keystone.server.flask.application   File "/var/lib/kolla/venv/lib/python3.9/site-packages/keystone/assignment/role_backends/sql.py", line 65, in _get_role
2023-03-01 17:30:14.943 39 ERROR keystone.server.flask.application     raise exception.RoleNotFound(role_id=role_id)
2023-03-01 17:30:14.943 39 ERROR keystone.server.flask.application keystone.exception.RoleNotFound: Could not find role: admin.
2023-03-01 17:30:14.943 39 ERROR keystone.server.flask.application 
2023-03-01 17:30:16.085 39 ERROR keystone.server.flask.application [None req-065b02ea-acd1-4e87-a71e-a854ce6e62d9 11e59edeaab843dd8ac2a0622768a80f - - all default -] Could not find user: ironic-inspector.: keystone.exception.UserNotFound: Could not find user: ironic-inspector.
2023-03-01 17:30:16.085 39 ERROR keystone.server.flask.application Traceback (most recent call last):
2023-03-01 17:30:16.085 39 ERROR keystone.server.flask.application   File "/var/lib/kolla/venv/lib/python3.9/site-packages/flask/app.py", line 1820, in full_dispatch_request
2023-03-01 17:30:16.085 39 ERROR keystone.server.flask.application     rv = self.dispatch_request()
2023-03-01 17:30:16.085 39 ERROR keystone.server.flask.application   File "/var/lib/kolla/venv/lib/python3.9/site-packages/flask/app.py", line 1796, in dispatch_request
2023-03-01 17:30:16.085 39 ERROR keystone.server.flask.application     return self.ensure_sync(self.view_functions[rule.endpoint])(**view_args)
2023-03-01 17:30:16.085 39 ERROR keystone.server.flask.application   File "/var/lib/kolla/venv/lib/python3.9/site-packages/flask_restful/__init__.py", line 467, in wrapper
2023-03-01 17:30:16.085 39 ERROR keystone.server.flask.application     resp = resource(*args, **kwargs)
2023-03-01 17:30:16.085 39 ERROR keystone.server.flask.application   File "/var/lib/kolla/venv/lib/python3.9/site-packages/flask/views.py", line 107, in view
2023-03-01 17:30:16.085 39 ERROR keystone.server.flask.application     return current_app.ensure_sync(self.dispatch_request)(**kwargs)
2023-03-01 17:30:16.085 39 ERROR keystone.server.flask.application   File "/var/lib/kolla/venv/lib/python3.9/site-packages/flask_restful/__init__.py", line 582, in dispatch_request
2023-03-01 17:30:16.085 39 ERROR keystone.server.flask.application     resp = meth(*args, **kwargs)
2023-03-01 17:30:16.085 39 ERROR keystone.server.flask.application   File "/var/lib/kolla/venv/lib/python3.9/site-packages/keystone/api/users.py", line 182, in get
2023-03-01 17:30:16.085 39 ERROR keystone.server.flask.application     return self._get_user(user_id)
2023-03-01 17:30:16.085 39 ERROR keystone.server.flask.application   File "/var/lib/kolla/venv/lib/python3.9/site-packages/keystone/api/users.py", line 194, in _get_user
2023-03-01 17:30:16.085 39 ERROR keystone.server.flask.application     ref = PROVIDERS.identity_api.get_user(user_id)
2023-03-01 17:30:16.085 39 ERROR keystone.server.flask.application   File "/var/lib/kolla/venv/lib/python3.9/site-packages/keystone/common/manager.py", line 115, in wrapped
2023-03-01 17:30:16.085 39 ERROR keystone.server.flask.application     __ret_val = __f(*args, **kwargs)
2023-03-01 17:30:16.085 39 ERROR keystone.server.flask.application   File "/var/lib/kolla/venv/lib/python3.9/site-packages/keystone/identity/core.py", line 414, in wrapper
2023-03-01 17:30:16.085 39 ERROR keystone.server.flask.application     return f(self, *args, **kwargs)
2023-03-01 17:30:16.085 39 ERROR keystone.server.flask.application   File "/var/lib/kolla/venv/lib/python3.9/site-packages/keystone/identity/core.py", line 424, in wrapper
2023-03-01 17:30:16.085 39 ERROR keystone.server.flask.application     return f(self, *args, **kwargs)
2023-03-01 17:30:16.085 39 ERROR keystone.server.flask.application   File "/var/lib/kolla/venv/lib/python3.9/site-packages/decorator.py", line 232, in fun
2023-03-01 17:30:16.085 39 ERROR keystone.server.flask.application     return caller(func, *(extras + args), **kw)
2023-03-01 17:30:16.085 39 ERROR keystone.server.flask.application   File "/var/lib/kolla/venv/lib/python3.9/site-packages/dogpile/cache/region.py", line 1577, in get_or_create_for_user_func
2023-03-01 17:30:16.085 39 ERROR keystone.server.flask.application     return self.get_or_create(
2023-03-01 17:30:16.085 39 ERROR keystone.server.flask.application   File "/var/lib/kolla/venv/lib/python3.9/site-packages/dogpile/cache/region.py", line 1042, in get_or_create
2023-03-01 17:30:16.085 39 ERROR keystone.server.flask.application     with Lock(
2023-03-01 17:30:16.085 39 ERROR keystone.server.flask.application   File "/var/lib/kolla/venv/lib/python3.9/site-packages/dogpile/lock.py", line 185, in __enter__
2023-03-01 17:30:16.085 39 ERROR keystone.server.flask.application     return self._enter()
2023-03-01 17:30:16.085 39 ERROR keystone.server.flask.application   File "/var/lib/kolla/venv/lib/python3.9/site-packages/dogpile/lock.py", line 94, in _enter
2023-03-01 17:30:16.085 39 ERROR keystone.server.flask.application     generated = self._enter_create(value, createdtime)
2023-03-01 17:30:16.085 39 ERROR keystone.server.flask.application   File "/var/lib/kolla/venv/lib/python3.9/site-packages/dogpile/lock.py", line 178, in _enter_create
2023-03-01 17:30:16.085 39 ERROR keystone.server.flask.application     return self.creator()
2023-03-01 17:30:16.085 39 ERROR keystone.server.flask.application   File "/var/lib/kolla/venv/lib/python3.9/site-packages/dogpile/cache/region.py", line 995, in gen_value
2023-03-01 17:30:16.085 39 ERROR keystone.server.flask.application     created_value = creator(
2023-03-01 17:30:16.085 39 ERROR keystone.server.flask.application   File "/var/lib/kolla/venv/lib/python3.9/site-packages/keystone/identity/core.py", line 1011, in get_user
2023-03-01 17:30:16.085 39 ERROR keystone.server.flask.application     ref = driver.get_user(entity_id)
2023-03-01 17:30:16.085 39 ERROR keystone.server.flask.application   File "/var/lib/kolla/venv/lib/python3.9/site-packages/keystone/identity/backends/sql.py", line 200, in get_user
2023-03-01 17:30:16.085 39 ERROR keystone.server.flask.application     self._get_user(session, user_id).to_dict())
2023-03-01 17:30:16.085 39 ERROR keystone.server.flask.application   File "/var/lib/kolla/venv/lib/python3.9/site-packages/keystone/identity/backends/sql.py", line 194, in _get_user
2023-03-01 17:30:16.085 39 ERROR keystone.server.flask.application     raise exception.UserNotFound(user_id=user_id)
2023-03-01 17:30:16.085 39 ERROR keystone.server.flask.application keystone.exception.UserNotFound: Could not find user: ironic-inspector.
2023-03-01 17:30:16.085 39 ERROR keystone.server.flask.application 
2023-03-01 17:30:16.950 37 ERROR keystone.server.flask.application [None req-97d8509f-c92a-49c3-b041-d914418c8ff9 11e59edeaab843dd8ac2a0622768a80f - - all default -] Could not find project: service.: keystone.exception.ProjectNotFound: Could not find project: service.
2023-03-01 17:30:16.950 37 ERROR keystone.server.flask.application Traceback (most recent call last):
2023-03-01 17:30:16.950 37 ERROR keystone.server.flask.application   File "/var/lib/kolla/venv/lib/python3.9/site-packages/flask/app.py", line 1820, in full_dispatch_request
2023-03-01 17:30:16.950 37 ERROR keystone.server.flask.application     rv = self.dispatch_request()
2023-03-01 17:30:16.950 37 ERROR keystone.server.flask.application   File "/var/lib/kolla/venv/lib/python3.9/site-packages/flask/app.py", line 1796, in dispatch_request
2023-03-01 17:30:16.950 37 ERROR keystone.server.flask.application     return self.ensure_sync(self.view_functions[rule.endpoint])(**view_args)
2023-03-01 17:30:16.950 37 ERROR keystone.server.flask.application   File "/var/lib/kolla/venv/lib/python3.9/site-packages/flask_restful/__init__.py", line 467, in wrapper
2023-03-01 17:30:16.950 37 ERROR keystone.server.flask.application     resp = resource(*args, **kwargs)
2023-03-01 17:30:16.950 37 ERROR keystone.server.flask.application   File "/var/lib/kolla/venv/lib/python3.9/site-packages/flask/views.py", line 107, in view
2023-03-01 17:30:16.950 37 ERROR keystone.server.flask.application     return current_app.ensure_sync(self.dispatch_request)(**kwargs)
2023-03-01 17:30:16.950 37 ERROR keystone.server.flask.application   File "/var/lib/kolla/venv/lib/python3.9/site-packages/flask_restful/__init__.py", line 582, in dispatch_request
2023-03-01 17:30:16.950 37 ERROR keystone.server.flask.application     resp = meth(*args, **kwargs)
2023-03-01 17:30:16.950 37 ERROR keystone.server.flask.application   File "/var/lib/kolla/venv/lib/python3.9/site-packages/keystone/api/projects.py", line 151, in get
2023-03-01 17:30:16.950 37 ERROR keystone.server.flask.application     return self._get_project(project_id)
2023-03-01 17:30:16.950 37 ERROR keystone.server.flask.application   File "/var/lib/kolla/venv/lib/python3.9/site-packages/keystone/api/projects.py", line 107, in _get_project
2023-03-01 17:30:16.950 37 ERROR keystone.server.flask.application     project = PROVIDERS.resource_api.get_project(project_id)
2023-03-01 17:30:16.950 37 ERROR keystone.server.flask.application   File "/var/lib/kolla/venv/lib/python3.9/site-packages/keystone/common/manager.py", line 115, in wrapped
2023-03-01 17:30:16.950 37 ERROR keystone.server.flask.application     __ret_val = __f(*args, **kwargs)
2023-03-01 17:30:16.950 37 ERROR keystone.server.flask.application   File "/var/lib/kolla/venv/lib/python3.9/site-packages/decorator.py", line 232, in fun
2023-03-01 17:30:16.950 37 ERROR keystone.server.flask.application     return caller(func, *(extras + args), **kw)
2023-03-01 17:30:16.950 37 ERROR keystone.server.flask.application   File "/var/lib/kolla/venv/lib/python3.9/site-packages/dogpile/cache/region.py", line 1577, in get_or_create_for_user_func
2023-03-01 17:30:16.950 37 ERROR keystone.server.flask.application     return self.get_or_create(
2023-03-01 17:30:16.950 37 ERROR keystone.server.flask.application   File "/var/lib/kolla/venv/lib/python3.9/site-packages/dogpile/cache/region.py", line 1042, in get_or_create
2023-03-01 17:30:16.950 37 ERROR keystone.server.flask.application     with Lock(
2023-03-01 17:30:16.950 37 ERROR keystone.server.flask.application   File "/var/lib/kolla/venv/lib/python3.9/site-packages/dogpile/lock.py", line 185, in __enter__
2023-03-01 17:30:16.950 37 ERROR keystone.server.flask.application     return self._enter()
2023-03-01 17:30:16.950 37 ERROR keystone.server.flask.application   File "/var/lib/kolla/venv/lib/python3.9/site-packages/dogpile/lock.py", line 94, in _enter
2023-03-01 17:30:16.950 37 ERROR keystone.server.flask.application     generated = self._enter_create(value, createdtime)
2023-03-01 17:30:16.950 37 ERROR keystone.server.flask.application   File "/var/lib/kolla/venv/lib/python3.9/site-packages/dogpile/lock.py", line 178, in _enter_create
2023-03-01 17:30:16.950 37 ERROR keystone.server.flask.application     return self.creator()
2023-03-01 17:30:16.950 37 ERROR keystone.server.flask.application   File "/var/lib/kolla/venv/lib/python3.9/site-packages/dogpile/cache/region.py", line 995, in gen_value
2023-03-01 17:30:16.950 37 ERROR keystone.server.flask.application     created_value = creator(
2023-03-01 17:30:16.950 37 ERROR keystone.server.flask.application   File "/var/lib/kolla/venv/lib/python3.9/site-packages/keystone/resource/core.py", line 903, in get_project
2023-03-01 17:30:16.950 37 ERROR keystone.server.flask.application     return self.driver.get_project(project_id)
2023-03-01 17:30:16.950 37 ERROR keystone.server.flask.application   File "/var/lib/kolla/venv/lib/python3.9/site-packages/keystone/resource/backends/sql.py", line 49, in get_project
2023-03-01 17:30:16.950 37 ERROR keystone.server.flask.application     return self._get_project(session, project_id).to_dict()
2023-03-01 17:30:16.950 37 ERROR keystone.server.flask.application   File "/var/lib/kolla/venv/lib/python3.9/site-packages/keystone/resource/backends/sql.py", line 44, in _get_project
2023-03-01 17:30:16.950 37 ERROR keystone.server.flask.application     raise exception.ProjectNotFound(project_id=project_id)
2023-03-01 17:30:16.950 37 ERROR keystone.server.flask.application keystone.exception.ProjectNotFound: Could not find project: service.
2023-03-01 17:30:16.950 37 ERROR keystone.server.flask.application 
2023-03-01 17:33:37.871 39 ERROR keystone.server.flask.application [None req-b240fd4c-157f-4965-a503-0ce60bc6d489 11e59edeaab843dd8ac2a0622768a80f - - all default -] Could not find project: service.: keystone.exception.ProjectNotFound: Could not find project: service.
2023-03-01 17:33:37.871 39 ERROR keystone.server.flask.application Traceback (most recent call last):
2023-03-01 17:33:37.871 39 ERROR keystone.server.flask.application   File "/var/lib/kolla/venv/lib/python3.9/site-packages/flask/app.py", line 1820, in full_dispatch_request
2023-03-01 17:33:37.871 39 ERROR keystone.server.flask.application     rv = self.dispatch_request()
2023-03-01 17:33:37.871 39 ERROR keystone.server.flask.application   File "/var/lib/kolla/venv/lib/python3.9/site-packages/flask/app.py", line 1796, in dispatch_request
2023-03-01 17:33:37.871 39 ERROR keystone.server.flask.application     return self.ensure_sync(self.view_functions[rule.endpoint])(**view_args)
2023-03-01 17:33:37.871 39 ERROR keystone.server.flask.application   File "/var/lib/kolla/venv/lib/python3.9/site-packages/flask_restful/__init__.py", line 467, in wrapper
2023-03-01 17:33:37.871 39 ERROR keystone.server.flask.application     resp = resource(*args, **kwargs)
2023-03-01 17:33:37.871 39 ERROR keystone.server.flask.application   File "/var/lib/kolla/venv/lib/python3.9/site-packages/flask/views.py", line 107, in view
2023-03-01 17:33:37.871 39 ERROR keystone.server.flask.application     return current_app.ensure_sync(self.dispatch_request)(**kwargs)
2023-03-01 17:33:37.871 39 ERROR keystone.server.flask.application   File "/var/lib/kolla/venv/lib/python3.9/site-packages/flask_restful/__init__.py", line 582, in dispatch_request
2023-03-01 17:33:37.871 39 ERROR keystone.server.flask.application     resp = meth(*args, **kwargs)
2023-03-01 17:33:37.871 39 ERROR keystone.server.flask.application   File "/var/lib/kolla/venv/lib/python3.9/site-packages/keystone/api/projects.py", line 151, in get
2023-03-01 17:33:37.871 39 ERROR keystone.server.flask.application     return self._get_project(project_id)
2023-03-01 17:33:37.871 39 ERROR keystone.server.flask.application   File "/var/lib/kolla/venv/lib/python3.9/site-packages/keystone/api/projects.py", line 107, in _get_project
2023-03-01 17:33:37.871 39 ERROR keystone.server.flask.application     project = PROVIDERS.resource_api.get_project(project_id)
2023-03-01 17:33:37.871 39 ERROR keystone.server.flask.application   File "/var/lib/kolla/venv/lib/python3.9/site-packages/keystone/common/manager.py", line 115, in wrapped
2023-03-01 17:33:37.871 39 ERROR keystone.server.flask.application     __ret_val = __f(*args, **kwargs)
2023-03-01 17:33:37.871 39 ERROR keystone.server.flask.application   File "/var/lib/kolla/venv/lib/python3.9/site-packages/decorator.py", line 232, in fun
2023-03-01 17:33:37.871 39 ERROR keystone.server.flask.application     return caller(func, *(extras + args), **kw)
2023-03-01 17:33:37.871 39 ERROR keystone.server.flask.application   File "/var/lib/kolla/venv/lib/python3.9/site-packages/dogpile/cache/region.py", line 1577, in get_or_create_for_user_func
2023-03-01 17:33:37.871 39 ERROR keystone.server.flask.application     return self.get_or_create(
2023-03-01 17:33:37.871 39 ERROR keystone.server.flask.application   File "/var/lib/kolla/venv/lib/python3.9/site-packages/dogpile/cache/region.py", line 1042, in get_or_create
2023-03-01 17:33:37.871 39 ERROR keystone.server.flask.application     with Lock(
2023-03-01 17:33:37.871 39 ERROR keystone.server.flask.application   File "/var/lib/kolla/venv/lib/python3.9/site-packages/dogpile/lock.py", line 185, in __enter__
2023-03-01 17:33:37.871 39 ERROR keystone.server.flask.application     return self._enter()
2023-03-01 17:33:37.871 39 ERROR keystone.server.flask.application   File "/var/lib/kolla/venv/lib/python3.9/site-packages/dogpile/lock.py", line 94, in _enter
2023-03-01 17:33:37.871 39 ERROR keystone.server.flask.application     generated = self._enter_create(value, createdtime)
2023-03-01 17:33:37.871 39 ERROR keystone.server.flask.application   File "/var/lib/kolla/venv/lib/python3.9/site-packages/dogpile/lock.py", line 178, in _enter_create
2023-03-01 17:33:37.871 39 ERROR keystone.server.flask.application     return self.creator()
2023-03-01 17:33:37.871 39 ERROR keystone.server.flask.application   File "/var/lib/kolla/venv/lib/python3.9/site-packages/dogpile/cache/region.py", line 995, in gen_value
2023-03-01 17:33:37.871 39 ERROR keystone.server.flask.application     created_value = creator(
2023-03-01 17:33:37.871 39 ERROR keystone.server.flask.application   File "/var/lib/kolla/venv/lib/python3.9/site-packages/keystone/resource/core.py", line 903, in get_project
2023-03-01 17:33:37.871 39 ERROR keystone.server.flask.application     return self.driver.get_project(project_id)
2023-03-01 17:33:37.871 39 ERROR keystone.server.flask.application   File "/var/lib/kolla/venv/lib/python3.9/site-packages/keystone/resource/backends/sql.py", line 49, in get_project
2023-03-01 17:33:37.871 39 ERROR keystone.server.flask.application     return self._get_project(session, project_id).to_dict()
2023-03-01 17:33:37.871 39 ERROR keystone.server.flask.application   File "/var/lib/kolla/venv/lib/python3.9/site-packages/keystone/resource/backends/sql.py", line 44, in _get_project
2023-03-01 17:33:37.871 39 ERROR keystone.server.flask.application     raise exception.ProjectNotFound(project_id=project_id)
2023-03-01 17:33:37.871 39 ERROR keystone.server.flask.application keystone.exception.ProjectNotFound: Could not find project: service.
2023-03-01 17:33:37.871 39 ERROR keystone.server.flask.application 
2023-03-01 17:33:54.244 37 ERROR keystone.server.flask.application [None req-014d5a4e-8768-4929-aa0d-22a491c8ed89 11e59edeaab843dd8ac2a0622768a80f - - all default -] Could not find role: admin.: keystone.exception.RoleNotFound: Could not find role: admin.
2023-03-01 17:33:54.244 37 ERROR keystone.server.flask.application Traceback (most recent call last):
2023-03-01 17:33:54.244 37 ERROR keystone.server.flask.application   File "/var/lib/kolla/venv/lib/python3.9/site-packages/flask/app.py", line 1820, in full_dispatch_request
2023-03-01 17:33:54.244 37 ERROR keystone.server.flask.application     rv = self.dispatch_request()
2023-03-01 17:33:54.244 37 ERROR keystone.server.flask.application   File "/var/lib/kolla/venv/lib/python3.9/site-packages/flask/app.py", line 1796, in dispatch_request
2023-03-01 17:33:54.244 37 ERROR keystone.server.flask.application     return self.ensure_sync(self.view_functions[rule.endpoint])(**view_args)
2023-03-01 17:33:54.244 37 ERROR keystone.server.flask.application   File "/var/lib/kolla/venv/lib/python3.9/site-packages/flask_restful/__init__.py", line 467, in wrapper
2023-03-01 17:33:54.244 37 ERROR keystone.server.flask.application     resp = resource(*args, **kwargs)
2023-03-01 17:33:54.244 37 ERROR keystone.server.flask.application   File "/var/lib/kolla/venv/lib/python3.9/site-packages/flask/views.py", line 107, in view
2023-03-01 17:33:54.244 37 ERROR keystone.server.flask.application     return current_app.ensure_sync(self.dispatch_request)(**kwargs)
2023-03-01 17:33:54.244 37 ERROR keystone.server.flask.application   File "/var/lib/kolla/venv/lib/python3.9/site-packages/flask_restful/__init__.py", line 582, in dispatch_request
2023-03-01 17:33:54.244 37 ERROR keystone.server.flask.application     resp = meth(*args, **kwargs)
2023-03-01 17:33:54.244 37 ERROR keystone.server.flask.application   File "/var/lib/kolla/venv/lib/python3.9/site-packages/keystone/api/roles.py", line 50, in get
2023-03-01 17:33:54.244 37 ERROR keystone.server.flask.application     return self._get_role(role_id)
2023-03-01 17:33:54.244 37 ERROR keystone.server.flask.application   File "/var/lib/kolla/venv/lib/python3.9/site-packages/keystone/api/roles.py", line 70, in _get_role
2023-03-01 17:33:54.244 37 ERROR keystone.server.flask.application     ENFORCER.enforce_call(action='identity:get_role')
2023-03-01 17:33:54.244 37 ERROR keystone.server.flask.application   File "/var/lib/kolla/venv/lib/python3.9/site-packages/keystone/common/rbac_enforcer/enforcer.py", line 402, in enforce_call
2023-03-01 17:33:54.244 37 ERROR keystone.server.flask.application     policy_dict.update(cls._extract_member_target_data(
2023-03-01 17:33:54.244 37 ERROR keystone.server.flask.application   File "/var/lib/kolla/venv/lib/python3.9/site-packages/keystone/common/rbac_enforcer/enforcer.py", line 234, in _extract_member_target_data
2023-03-01 17:33:54.244 37 ERROR keystone.server.flask.application     member_name: func(flask.request.view_args[key])
2023-03-01 17:33:54.244 37 ERROR keystone.server.flask.application   File "/var/lib/kolla/venv/lib/python3.9/site-packages/keystone/common/manager.py", line 115, in wrapped
2023-03-01 17:33:54.244 37 ERROR keystone.server.flask.application     __ret_val = __f(*args, **kwargs)
2023-03-01 17:33:54.244 37 ERROR keystone.server.flask.application   File "/var/lib/kolla/venv/lib/python3.9/site-packages/decorator.py", line 232, in fun
2023-03-01 17:33:54.244 37 ERROR keystone.server.flask.application     return caller(func, *(extras + args), **kw)
2023-03-01 17:33:54.244 37 ERROR keystone.server.flask.application   File "/var/lib/kolla/venv/lib/python3.9/site-packages/dogpile/cache/region.py", line 1577, in get_or_create_for_user_func
2023-03-01 17:33:54.244 37 ERROR keystone.server.flask.application     return self.get_or_create(
2023-03-01 17:33:54.244 37 ERROR keystone.server.flask.application   File "/var/lib/kolla/venv/lib/python3.9/site-packages/dogpile/cache/region.py", line 1042, in get_or_create
2023-03-01 17:33:54.244 37 ERROR keystone.server.flask.application     with Lock(
2023-03-01 17:33:54.244 37 ERROR keystone.server.flask.application   File "/var/lib/kolla/venv/lib/python3.9/site-packages/dogpile/lock.py", line 185, in __enter__
2023-03-01 17:33:54.244 37 ERROR keystone.server.flask.application     return self._enter()
2023-03-01 17:33:54.244 37 ERROR keystone.server.flask.application   File "/var/lib/kolla/venv/lib/python3.9/site-packages/dogpile/lock.py", line 94, in _enter
2023-03-01 17:33:54.244 37 ERROR keystone.server.flask.application     generated = self._enter_create(value, createdtime)
2023-03-01 17:33:54.244 37 ERROR keystone.server.flask.application   File "/var/lib/kolla/venv/lib/python3.9/site-packages/dogpile/lock.py", line 178, in _enter_create
2023-03-01 17:33:54.244 37 ERROR keystone.server.flask.application     return self.creator()
2023-03-01 17:33:54.244 37 ERROR keystone.server.flask.application   File "/var/lib/kolla/venv/lib/python3.9/site-packages/dogpile/cache/region.py", line 995, in gen_value
2023-03-01 17:33:54.244 37 ERROR keystone.server.flask.application     created_value = creator(
2023-03-01 17:33:54.244 37 ERROR keystone.server.flask.application   File "/var/lib/kolla/venv/lib/python3.9/site-packages/keystone/assignment/core.py", line 1276, in get_role
2023-03-01 17:33:54.244 37 ERROR keystone.server.flask.application     return self.driver.get_role(role_id)
2023-03-01 17:33:54.244 37 ERROR keystone.server.flask.application   File "/var/lib/kolla/venv/lib/python3.9/site-packages/keystone/assignment/role_backends/sql.py", line 70, in get_role
2023-03-01 17:33:54.244 37 ERROR keystone.server.flask.application     return self._get_role(session, role_id).to_dict()
2023-03-01 17:33:54.244 37 ERROR keystone.server.flask.application   File "/var/lib/kolla/venv/lib/python3.9/site-packages/keystone/assignment/role_backends/sql.py", line 65, in _get_role
2023-03-01 17:33:54.244 37 ERROR keystone.server.flask.application     raise exception.RoleNotFound(role_id=role_id)
2023-03-01 17:33:54.244 37 ERROR keystone.server.flask.application keystone.exception.RoleNotFound: Could not find role: admin.
2023-03-01 17:33:54.244 37 ERROR keystone.server.flask.application 
2023-03-01 17:33:55.504 37 ERROR keystone.server.flask.application [None req-43442cf4-3226-4089-88cb-c5ed7f5356a9 11e59edeaab843dd8ac2a0622768a80f - - all default -] Could not find user: neutron.: keystone.exception.UserNotFound: Could not find user: neutron.
2023-03-01 17:33:55.504 37 ERROR keystone.server.flask.application Traceback (most recent call last):
2023-03-01 17:33:55.504 37 ERROR keystone.server.flask.application   File "/var/lib/kolla/venv/lib/python3.9/site-packages/flask/app.py", line 1820, in full_dispatch_request
2023-03-01 17:33:55.504 37 ERROR keystone.server.flask.application     rv = self.dispatch_request()
2023-03-01 17:33:55.504 37 ERROR keystone.server.flask.application   File "/var/lib/kolla/venv/lib/python3.9/site-packages/flask/app.py", line 1796, in dispatch_request
2023-03-01 17:33:55.504 37 ERROR keystone.server.flask.application     return self.ensure_sync(self.view_functions[rule.endpoint])(**view_args)
2023-03-01 17:33:55.504 37 ERROR keystone.server.flask.application   File "/var/lib/kolla/venv/lib/python3.9/site-packages/flask_restful/__init__.py", line 467, in wrapper
2023-03-01 17:33:55.504 37 ERROR keystone.server.flask.application     resp = resource(*args, **kwargs)
2023-03-01 17:33:55.504 37 ERROR keystone.server.flask.application   File "/var/lib/kolla/venv/lib/python3.9/site-packages/flask/views.py", line 107, in view
2023-03-01 17:33:55.504 37 ERROR keystone.server.flask.application     return current_app.ensure_sync(self.dispatch_request)(**kwargs)
2023-03-01 17:33:55.504 37 ERROR keystone.server.flask.application   File "/var/lib/kolla/venv/lib/python3.9/site-packages/flask_restful/__init__.py", line 582, in dispatch_request
2023-03-01 17:33:55.504 37 ERROR keystone.server.flask.application     resp = meth(*args, **kwargs)
2023-03-01 17:33:55.504 37 ERROR keystone.server.flask.application   File "/var/lib/kolla/venv/lib/python3.9/site-packages/keystone/api/users.py", line 182, in get
2023-03-01 17:33:55.504 37 ERROR keystone.server.flask.application     return self._get_user(user_id)
2023-03-01 17:33:55.504 37 ERROR keystone.server.flask.application   File "/var/lib/kolla/venv/lib/python3.9/site-packages/keystone/api/users.py", line 194, in _get_user
2023-03-01 17:33:55.504 37 ERROR keystone.server.flask.application     ref = PROVIDERS.identity_api.get_user(user_id)
2023-03-01 17:33:55.504 37 ERROR keystone.server.flask.application   File "/var/lib/kolla/venv/lib/python3.9/site-packages/keystone/common/manager.py", line 115, in wrapped
2023-03-01 17:33:55.504 37 ERROR keystone.server.flask.application     __ret_val = __f(*args, **kwargs)
2023-03-01 17:33:55.504 37 ERROR keystone.server.flask.application   File "/var/lib/kolla/venv/lib/python3.9/site-packages/keystone/identity/core.py", line 414, in wrapper
2023-03-01 17:33:55.504 37 ERROR keystone.server.flask.application     return f(self, *args, **kwargs)
2023-03-01 17:33:55.504 37 ERROR keystone.server.flask.application   File "/var/lib/kolla/venv/lib/python3.9/site-packages/keystone/identity/core.py", line 424, in wrapper
2023-03-01 17:33:55.504 37 ERROR keystone.server.flask.application     return f(self, *args, **kwargs)
2023-03-01 17:33:55.504 37 ERROR keystone.server.flask.application   File "/var/lib/kolla/venv/lib/python3.9/site-packages/decorator.py", line 232, in fun
2023-03-01 17:33:55.504 37 ERROR keystone.server.flask.application     return caller(func, *(extras + args), **kw)
2023-03-01 17:33:55.504 37 ERROR keystone.server.flask.application   File "/var/lib/kolla/venv/lib/python3.9/site-packages/dogpile/cache/region.py", line 1577, in get_or_create_for_user_func
2023-03-01 17:33:55.504 37 ERROR keystone.server.flask.application     return self.get_or_create(
2023-03-01 17:33:55.504 37 ERROR keystone.server.flask.application   File "/var/lib/kolla/venv/lib/python3.9/site-packages/dogpile/cache/region.py", line 1042, in get_or_create
2023-03-01 17:33:55.504 37 ERROR keystone.server.flask.application     with Lock(
2023-03-01 17:33:55.504 37 ERROR keystone.server.flask.application   File "/var/lib/kolla/venv/lib/python3.9/site-packages/dogpile/lock.py", line 185, in __enter__
2023-03-01 17:33:55.504 37 ERROR keystone.server.flask.application     return self._enter()
2023-03-01 17:33:55.504 37 ERROR keystone.server.flask.application   File "/var/lib/kolla/venv/lib/python3.9/site-packages/dogpile/lock.py", line 94, in _enter
2023-03-01 17:33:55.504 37 ERROR keystone.server.flask.application     generated = self._enter_create(value, createdtime)
2023-03-01 17:33:55.504 37 ERROR keystone.server.flask.application   File "/var/lib/kolla/venv/lib/python3.9/site-packages/dogpile/lock.py", line 178, in _enter_create
2023-03-01 17:33:55.504 37 ERROR keystone.server.flask.application     return self.creator()
2023-03-01 17:33:55.504 37 ERROR keystone.server.flask.application   File "/var/lib/kolla/venv/lib/python3.9/site-packages/dogpile/cache/region.py", line 995, in gen_value
2023-03-01 17:33:55.504 37 ERROR keystone.server.flask.application     created_value = creator(
2023-03-01 17:33:55.504 37 ERROR keystone.server.flask.application   File "/var/lib/kolla/venv/lib/python3.9/site-packages/keystone/identity/core.py", line 1011, in get_user
2023-03-01 17:33:55.504 37 ERROR keystone.server.flask.application     ref = driver.get_user(entity_id)
2023-03-01 17:33:55.504 37 ERROR keystone.server.flask.application   File "/var/lib/kolla/venv/lib/python3.9/site-packages/keystone/identity/backends/sql.py", line 200, in get_user
2023-03-01 17:33:55.504 37 ERROR keystone.server.flask.application     self._get_user(session, user_id).to_dict())
2023-03-01 17:33:55.504 37 ERROR keystone.server.flask.application   File "/var/lib/kolla/venv/lib/python3.9/site-packages/keystone/identity/backends/sql.py", line 194, in _get_user
2023-03-01 17:33:55.504 37 ERROR keystone.server.flask.application     raise exception.UserNotFound(user_id=user_id)
2023-03-01 17:33:55.504 37 ERROR keystone.server.flask.application keystone.exception.UserNotFound: Could not find user: neutron.
2023-03-01 17:33:55.504 37 ERROR keystone.server.flask.application 
2023-03-01 17:33:56.378 37 ERROR keystone.server.flask.application [None req-b91b09a7-f6f4-4f16-9c17-e1cd244c7b8f 11e59edeaab843dd8ac2a0622768a80f - - all default -] Could not find project: service.: keystone.exception.ProjectNotFound: Could not find project: service.
2023-03-01 17:33:56.378 37 ERROR keystone.server.flask.application Traceback (most recent call last):
2023-03-01 17:33:56.378 37 ERROR keystone.server.flask.application   File "/var/lib/kolla/venv/lib/python3.9/site-packages/flask/app.py", line 1820, in full_dispatch_request
2023-03-01 17:33:56.378 37 ERROR keystone.server.flask.application     rv = self.dispatch_request()
2023-03-01 17:33:56.378 37 ERROR keystone.server.flask.application   File "/var/lib/kolla/venv/lib/python3.9/site-packages/flask/app.py", line 1796, in dispatch_request
2023-03-01 17:33:56.378 37 ERROR keystone.server.flask.application     return self.ensure_sync(self.view_functions[rule.endpoint])(**view_args)
2023-03-01 17:33:56.378 37 ERROR keystone.server.flask.application   File "/var/lib/kolla/venv/lib/python3.9/site-packages/flask_restful/__init__.py", line 467, in wrapper
2023-03-01 17:33:56.378 37 ERROR keystone.server.flask.application     resp = resource(*args, **kwargs)
2023-03-01 17:33:56.378 37 ERROR keystone.server.flask.application   File "/var/lib/kolla/venv/lib/python3.9/site-packages/flask/views.py", line 107, in view
2023-03-01 17:33:56.378 37 ERROR keystone.server.flask.application     return current_app.ensure_sync(self.dispatch_request)(**kwargs)
2023-03-01 17:33:56.378 37 ERROR keystone.server.flask.application   File "/var/lib/kolla/venv/lib/python3.9/site-packages/flask_restful/__init__.py", line 582, in dispatch_request
2023-03-01 17:33:56.378 37 ERROR keystone.server.flask.application     resp = meth(*args, **kwargs)
2023-03-01 17:33:56.378 37 ERROR keystone.server.flask.application   File "/var/lib/kolla/venv/lib/python3.9/site-packages/keystone/api/projects.py", line 151, in get
2023-03-01 17:33:56.378 37 ERROR keystone.server.flask.application     return self._get_project(project_id)
2023-03-01 17:33:56.378 37 ERROR keystone.server.flask.application   File "/var/lib/kolla/venv/lib/python3.9/site-packages/keystone/api/projects.py", line 107, in _get_project
2023-03-01 17:33:56.378 37 ERROR keystone.server.flask.application     project = PROVIDERS.resource_api.get_project(project_id)
2023-03-01 17:33:56.378 37 ERROR keystone.server.flask.application   File "/var/lib/kolla/venv/lib/python3.9/site-packages/keystone/common/manager.py", line 115, in wrapped
2023-03-01 17:33:56.378 37 ERROR keystone.server.flask.application     __ret_val = __f(*args, **kwargs)
2023-03-01 17:33:56.378 37 ERROR keystone.server.flask.application   File "/var/lib/kolla/venv/lib/python3.9/site-packages/decorator.py", line 232, in fun
2023-03-01 17:33:56.378 37 ERROR keystone.server.flask.application     return caller(func, *(extras + args), **kw)
2023-03-01 17:33:56.378 37 ERROR keystone.server.flask.application   File "/var/lib/kolla/venv/lib/python3.9/site-packages/dogpile/cache/region.py", line 1577, in get_or_create_for_user_func
2023-03-01 17:33:56.378 37 ERROR keystone.server.flask.application     return self.get_or_create(
2023-03-01 17:33:56.378 37 ERROR keystone.server.flask.application   File "/var/lib/kolla/venv/lib/python3.9/site-packages/dogpile/cache/region.py", line 1042, in get_or_create
2023-03-01 17:33:56.378 37 ERROR keystone.server.flask.application     with Lock(
2023-03-01 17:33:56.378 37 ERROR keystone.server.flask.application   File "/var/lib/kolla/venv/lib/python3.9/site-packages/dogpile/lock.py", line 185, in __enter__
2023-03-01 17:33:56.378 37 ERROR keystone.server.flask.application     return self._enter()
2023-03-01 17:33:56.378 37 ERROR keystone.server.flask.application   File "/var/lib/kolla/venv/lib/python3.9/site-packages/dogpile/lock.py", line 94, in _enter
2023-03-01 17:33:56.378 37 ERROR keystone.server.flask.application     generated = self._enter_create(value, createdtime)
2023-03-01 17:33:56.378 37 ERROR keystone.server.flask.application   File "/var/lib/kolla/venv/lib/python3.9/site-packages/dogpile/lock.py", line 178, in _enter_create
2023-03-01 17:33:56.378 37 ERROR keystone.server.flask.application     return self.creator()
2023-03-01 17:33:56.378 37 ERROR keystone.server.flask.application   File "/var/lib/kolla/venv/lib/python3.9/site-packages/dogpile/cache/region.py", line 995, in gen_value
2023-03-01 17:33:56.378 37 ERROR keystone.server.flask.application     created_value = creator(
2023-03-01 17:33:56.378 37 ERROR keystone.server.flask.application   File "/var/lib/kolla/venv/lib/python3.9/site-packages/keystone/resource/core.py", line 903, in get_project
2023-03-01 17:33:56.378 37 ERROR keystone.server.flask.application     return self.driver.get_project(project_id)
2023-03-01 17:33:56.378 37 ERROR keystone.server.flask.application   File "/var/lib/kolla/venv/lib/python3.9/site-packages/keystone/resource/backends/sql.py", line 49, in get_project
2023-03-01 17:33:56.378 37 ERROR keystone.server.flask.application     return self._get_project(session, project_id).to_dict()
2023-03-01 17:33:56.378 37 ERROR keystone.server.flask.application   File "/var/lib/kolla/venv/lib/python3.9/site-packages/keystone/resource/backends/sql.py", line 44, in _get_project
2023-03-01 17:33:56.378 37 ERROR keystone.server.flask.application     raise exception.ProjectNotFound(project_id=project_id)
2023-03-01 17:33:56.378 37 ERROR keystone.server.flask.application keystone.exception.ProjectNotFound: Could not find project: service.
2023-03-01 17:33:56.378 37 ERROR keystone.server.flask.application 
