2023-03-15 19:29:18.078 23 INFO alembic.runtime.migration [-] Context impl MySQLImpl.
2023-03-15 19:29:18.081 23 INFO alembic.runtime.migration [-] Will assume non-transactional DDL.
2023-03-15 19:29:18.133 23 INFO alembic.runtime.migration [-] Context impl MySQLImpl.
2023-03-15 19:29:18.134 23 INFO alembic.runtime.migration [-] Will assume non-transactional DDL.
2023-03-15 19:29:18.196 23 INFO alembic.runtime.migration [-] Running upgrade  -> 27e647c0fad4, Initial version.
2023-03-15 19:29:19.493 23 INFO alembic.runtime.migration [-] Running upgrade 27e647c0fad4 -> e25ffa003242, Initial no-op Yoga contract migration.
2023-03-15 19:29:19.498 23 INFO alembic.runtime.migration [-] Running upgrade 27e647c0fad4 -> 29e87d24a316, Initial no-op Yoga expand migration.
2023-03-15 19:29:28.566 8 INFO keystone.common.fernet_utils [-] Created a new temporary key: /etc/keystone/fernet-keys/0.tmp
2023-03-15 19:29:28.572 8 INFO keystone.common.fernet_utils [-] Become a valid new key: /etc/keystone/fernet-keys/0
2023-03-15 19:29:28.573 8 INFO keystone.common.fernet_utils [-] Starting key rotation with 1 key files: ['/etc/keystone/fernet-keys/0']
2023-03-15 19:29:28.574 8 INFO keystone.common.fernet_utils [-] Created a new temporary key: /etc/keystone/fernet-keys/0.tmp
2023-03-15 19:29:28.574 8 INFO keystone.common.fernet_utils [-] Current primary key is: 0
2023-03-15 19:29:28.576 8 INFO keystone.common.fernet_utils [-] Next primary key will be: 1
2023-03-15 19:29:28.576 8 INFO keystone.common.fernet_utils [-] Promoted key 0 to be the primary: 1
2023-03-15 19:29:28.577 8 INFO keystone.common.fernet_utils [-] Become a valid new key: /etc/keystone/fernet-keys/0
2023-03-15 19:29:49.116 32 INFO keystone.cmd.bootstrap [None req-6c52df6d-1829-41e4-916b-15744aa8b623 - - - - - -] Created domain default
2023-03-15 19:29:49.203 32 INFO keystone.cmd.bootstrap [None req-6c52df6d-1829-41e4-916b-15744aa8b623 - - - - - -] Created project admin
2023-03-15 19:29:49.845 32 INFO keystone.cmd.bootstrap [None req-6c52df6d-1829-41e4-916b-15744aa8b623 - - - - - -] Created user admin
2023-03-15 19:29:49.876 32 INFO keystone.cmd.bootstrap [None req-6c52df6d-1829-41e4-916b-15744aa8b623 - - - - - -] Created role reader
2023-03-15 19:29:49.898 32 INFO keystone.cmd.bootstrap [None req-6c52df6d-1829-41e4-916b-15744aa8b623 - - - - - -] Created role member
2023-03-15 19:29:49.959 32 INFO keystone.cmd.bootstrap [None req-6c52df6d-1829-41e4-916b-15744aa8b623 - - - - - -] Created implied role where 853d9c0946fa42f18f29b9c628397d7d implies 67bd13c8bec0471a902205ce70b83c70
2023-03-15 19:29:49.986 32 INFO keystone.cmd.bootstrap [None req-6c52df6d-1829-41e4-916b-15744aa8b623 - - - - - -] Created role admin
2023-03-15 19:29:50.027 32 INFO keystone.cmd.bootstrap [None req-6c52df6d-1829-41e4-916b-15744aa8b623 - - - - - -] Created implied role where e8ee66f07e5141f6b04107553ad4b03a implies 853d9c0946fa42f18f29b9c628397d7d
2023-03-15 19:29:50.064 32 INFO keystone.cmd.bootstrap [None req-6c52df6d-1829-41e4-916b-15744aa8b623 - - - - - -] Granted role admin on project admin to user admin.
2023-03-15 19:29:50.082 32 INFO keystone.cmd.bootstrap [None req-6c52df6d-1829-41e4-916b-15744aa8b623 - - - - - -] Granted role admin on the system to user admin.
2023-03-15 19:29:50.124 32 WARNING py.warnings [None req-6c52df6d-1829-41e4-916b-15744aa8b623 - - - - - -] /var/lib/kolla/venv/lib/python3.9/site-packages/pycadf/identifier.py:71: UserWarning: Invalid uuid: RegionOne. To ensure interoperability, identifiers should be a valid uuid.
  warnings.warn(('Invalid uuid: %s. To ensure interoperability, '

2023-03-15 19:29:50.137 32 INFO keystone.cmd.bootstrap [None req-6c52df6d-1829-41e4-916b-15744aa8b623 - - - - - -] Created region RegionOne
2023-03-15 19:29:50.223 32 INFO keystone.cmd.bootstrap [None req-6c52df6d-1829-41e4-916b-15744aa8b623 - - - - - -] Created public endpoint http://169.16.1.161:5000
2023-03-15 19:29:50.250 32 INFO keystone.cmd.bootstrap [None req-6c52df6d-1829-41e4-916b-15744aa8b623 - - - - - -] Created internal endpoint http://169.16.1.161:5000
2023-03-15 19:30:17.789 39 WARNING keystone.common.rbac_enforcer.enforcer [None req-fc6529c2-ba2b-456f-9ebf-cb06301c4906 e67c66414fb4476e9016e0f5a05aeb1a - - all default -] Deprecated policy rules found. Use oslopolicy-policy-generator and oslopolicy-policy-upgrade to detect and resolve deprecated policies in your configuration.
2023-03-15 19:30:18.779 37 WARNING keystone.common.rbac_enforcer.enforcer [None req-b1d2f843-dec7-4d50-8c5e-53ad2a37f9e5 e67c66414fb4476e9016e0f5a05aeb1a - - all default -] Deprecated policy rules found. Use oslopolicy-policy-generator and oslopolicy-policy-upgrade to detect and resolve deprecated policies in your configuration.
2023-03-15 19:30:27.978 38 WARNING keystone.common.rbac_enforcer.enforcer [None req-6cb7cf79-6ef7-408c-a5ed-a6141eb73efb e67c66414fb4476e9016e0f5a05aeb1a - - all default -] Deprecated policy rules found. Use oslopolicy-policy-generator and oslopolicy-policy-upgrade to detect and resolve deprecated policies in your configuration.
2023-03-15 19:31:56.563 39 ERROR keystone.server.flask.application [None req-956fd7e3-98fe-4d37-8aab-e30c2d62495e e67c66414fb4476e9016e0f5a05aeb1a - - all default -] Could not find project: service.: keystone.exception.ProjectNotFound: Could not find project: service.
2023-03-15 19:31:56.563 39 ERROR keystone.server.flask.application Traceback (most recent call last):
2023-03-15 19:31:56.563 39 ERROR keystone.server.flask.application   File "/var/lib/kolla/venv/lib/python3.9/site-packages/flask/app.py", line 1820, in full_dispatch_request
2023-03-15 19:31:56.563 39 ERROR keystone.server.flask.application     rv = self.dispatch_request()
2023-03-15 19:31:56.563 39 ERROR keystone.server.flask.application   File "/var/lib/kolla/venv/lib/python3.9/site-packages/flask/app.py", line 1796, in dispatch_request
2023-03-15 19:31:56.563 39 ERROR keystone.server.flask.application     return self.ensure_sync(self.view_functions[rule.endpoint])(**view_args)
2023-03-15 19:31:56.563 39 ERROR keystone.server.flask.application   File "/var/lib/kolla/venv/lib/python3.9/site-packages/flask_restful/__init__.py", line 467, in wrapper
2023-03-15 19:31:56.563 39 ERROR keystone.server.flask.application     resp = resource(*args, **kwargs)
2023-03-15 19:31:56.563 39 ERROR keystone.server.flask.application   File "/var/lib/kolla/venv/lib/python3.9/site-packages/flask/views.py", line 107, in view
2023-03-15 19:31:56.563 39 ERROR keystone.server.flask.application     return current_app.ensure_sync(self.dispatch_request)(**kwargs)
2023-03-15 19:31:56.563 39 ERROR keystone.server.flask.application   File "/var/lib/kolla/venv/lib/python3.9/site-packages/flask_restful/__init__.py", line 582, in dispatch_request
2023-03-15 19:31:56.563 39 ERROR keystone.server.flask.application     resp = meth(*args, **kwargs)
2023-03-15 19:31:56.563 39 ERROR keystone.server.flask.application   File "/var/lib/kolla/venv/lib/python3.9/site-packages/keystone/api/projects.py", line 151, in get
2023-03-15 19:31:56.563 39 ERROR keystone.server.flask.application     return self._get_project(project_id)
2023-03-15 19:31:56.563 39 ERROR keystone.server.flask.application   File "/var/lib/kolla/venv/lib/python3.9/site-packages/keystone/api/projects.py", line 107, in _get_project
2023-03-15 19:31:56.563 39 ERROR keystone.server.flask.application     project = PROVIDERS.resource_api.get_project(project_id)
2023-03-15 19:31:56.563 39 ERROR keystone.server.flask.application   File "/var/lib/kolla/venv/lib/python3.9/site-packages/keystone/common/manager.py", line 115, in wrapped
2023-03-15 19:31:56.563 39 ERROR keystone.server.flask.application     __ret_val = __f(*args, **kwargs)
2023-03-15 19:31:56.563 39 ERROR keystone.server.flask.application   File "/var/lib/kolla/venv/lib/python3.9/site-packages/decorator.py", line 232, in fun
2023-03-15 19:31:56.563 39 ERROR keystone.server.flask.application     return caller(func, *(extras + args), **kw)
2023-03-15 19:31:56.563 39 ERROR keystone.server.flask.application   File "/var/lib/kolla/venv/lib/python3.9/site-packages/dogpile/cache/region.py", line 1577, in get_or_create_for_user_func
2023-03-15 19:31:56.563 39 ERROR keystone.server.flask.application     return self.get_or_create(
2023-03-15 19:31:56.563 39 ERROR keystone.server.flask.application   File "/var/lib/kolla/venv/lib/python3.9/site-packages/dogpile/cache/region.py", line 1042, in get_or_create
2023-03-15 19:31:56.563 39 ERROR keystone.server.flask.application     with Lock(
2023-03-15 19:31:56.563 39 ERROR keystone.server.flask.application   File "/var/lib/kolla/venv/lib/python3.9/site-packages/dogpile/lock.py", line 185, in __enter__
2023-03-15 19:31:56.563 39 ERROR keystone.server.flask.application     return self._enter()
2023-03-15 19:31:56.563 39 ERROR keystone.server.flask.application   File "/var/lib/kolla/venv/lib/python3.9/site-packages/dogpile/lock.py", line 94, in _enter
2023-03-15 19:31:56.563 39 ERROR keystone.server.flask.application     generated = self._enter_create(value, createdtime)
2023-03-15 19:31:56.563 39 ERROR keystone.server.flask.application   File "/var/lib/kolla/venv/lib/python3.9/site-packages/dogpile/lock.py", line 178, in _enter_create
2023-03-15 19:31:56.563 39 ERROR keystone.server.flask.application     return self.creator()
2023-03-15 19:31:56.563 39 ERROR keystone.server.flask.application   File "/var/lib/kolla/venv/lib/python3.9/site-packages/dogpile/cache/region.py", line 995, in gen_value
2023-03-15 19:31:56.563 39 ERROR keystone.server.flask.application     created_value = creator(
2023-03-15 19:31:56.563 39 ERROR keystone.server.flask.application   File "/var/lib/kolla/venv/lib/python3.9/site-packages/keystone/resource/core.py", line 903, in get_project
2023-03-15 19:31:56.563 39 ERROR keystone.server.flask.application     return self.driver.get_project(project_id)
2023-03-15 19:31:56.563 39 ERROR keystone.server.flask.application   File "/var/lib/kolla/venv/lib/python3.9/site-packages/keystone/resource/backends/sql.py", line 49, in get_project
2023-03-15 19:31:56.563 39 ERROR keystone.server.flask.application     return self._get_project(session, project_id).to_dict()
2023-03-15 19:31:56.563 39 ERROR keystone.server.flask.application   File "/var/lib/kolla/venv/lib/python3.9/site-packages/keystone/resource/backends/sql.py", line 44, in _get_project
2023-03-15 19:31:56.563 39 ERROR keystone.server.flask.application     raise exception.ProjectNotFound(project_id=project_id)
2023-03-15 19:31:56.563 39 ERROR keystone.server.flask.application keystone.exception.ProjectNotFound: Could not find project: service.
2023-03-15 19:31:56.563 39 ERROR keystone.server.flask.application 
2023-03-15 19:32:06.572 38 ERROR keystone.server.flask.application [None req-7655fbbe-1298-4e42-ba42-45f6eaca9bbe e67c66414fb4476e9016e0f5a05aeb1a - - all default -] Could not find project: service.: keystone.exception.ProjectNotFound: Could not find project: service.
2023-03-15 19:32:06.572 38 ERROR keystone.server.flask.application Traceback (most recent call last):
2023-03-15 19:32:06.572 38 ERROR keystone.server.flask.application   File "/var/lib/kolla/venv/lib/python3.9/site-packages/flask/app.py", line 1820, in full_dispatch_request
2023-03-15 19:32:06.572 38 ERROR keystone.server.flask.application     rv = self.dispatch_request()
2023-03-15 19:32:06.572 38 ERROR keystone.server.flask.application   File "/var/lib/kolla/venv/lib/python3.9/site-packages/flask/app.py", line 1796, in dispatch_request
2023-03-15 19:32:06.572 38 ERROR keystone.server.flask.application     return self.ensure_sync(self.view_functions[rule.endpoint])(**view_args)
2023-03-15 19:32:06.572 38 ERROR keystone.server.flask.application   File "/var/lib/kolla/venv/lib/python3.9/site-packages/flask_restful/__init__.py", line 467, in wrapper
2023-03-15 19:32:06.572 38 ERROR keystone.server.flask.application     resp = resource(*args, **kwargs)
2023-03-15 19:32:06.572 38 ERROR keystone.server.flask.application   File "/var/lib/kolla/venv/lib/python3.9/site-packages/flask/views.py", line 107, in view
2023-03-15 19:32:06.572 38 ERROR keystone.server.flask.application     return current_app.ensure_sync(self.dispatch_request)(**kwargs)
2023-03-15 19:32:06.572 38 ERROR keystone.server.flask.application   File "/var/lib/kolla/venv/lib/python3.9/site-packages/flask_restful/__init__.py", line 582, in dispatch_request
2023-03-15 19:32:06.572 38 ERROR keystone.server.flask.application     resp = meth(*args, **kwargs)
2023-03-15 19:32:06.572 38 ERROR keystone.server.flask.application   File "/var/lib/kolla/venv/lib/python3.9/site-packages/keystone/api/projects.py", line 151, in get
2023-03-15 19:32:06.572 38 ERROR keystone.server.flask.application     return self._get_project(project_id)
2023-03-15 19:32:06.572 38 ERROR keystone.server.flask.application   File "/var/lib/kolla/venv/lib/python3.9/site-packages/keystone/api/projects.py", line 107, in _get_project
2023-03-15 19:32:06.572 38 ERROR keystone.server.flask.application     project = PROVIDERS.resource_api.get_project(project_id)
2023-03-15 19:32:06.572 38 ERROR keystone.server.flask.application   File "/var/lib/kolla/venv/lib/python3.9/site-packages/keystone/common/manager.py", line 115, in wrapped
2023-03-15 19:32:06.572 38 ERROR keystone.server.flask.application     __ret_val = __f(*args, **kwargs)
2023-03-15 19:32:06.572 38 ERROR keystone.server.flask.application   File "/var/lib/kolla/venv/lib/python3.9/site-packages/decorator.py", line 232, in fun
2023-03-15 19:32:06.572 38 ERROR keystone.server.flask.application     return caller(func, *(extras + args), **kw)
2023-03-15 19:32:06.572 38 ERROR keystone.server.flask.application   File "/var/lib/kolla/venv/lib/python3.9/site-packages/dogpile/cache/region.py", line 1577, in get_or_create_for_user_func
2023-03-15 19:32:06.572 38 ERROR keystone.server.flask.application     return self.get_or_create(
2023-03-15 19:32:06.572 38 ERROR keystone.server.flask.application   File "/var/lib/kolla/venv/lib/python3.9/site-packages/dogpile/cache/region.py", line 1042, in get_or_create
2023-03-15 19:32:06.572 38 ERROR keystone.server.flask.application     with Lock(
2023-03-15 19:32:06.572 38 ERROR keystone.server.flask.application   File "/var/lib/kolla/venv/lib/python3.9/site-packages/dogpile/lock.py", line 185, in __enter__
2023-03-15 19:32:06.572 38 ERROR keystone.server.flask.application     return self._enter()
2023-03-15 19:32:06.572 38 ERROR keystone.server.flask.application   File "/var/lib/kolla/venv/lib/python3.9/site-packages/dogpile/lock.py", line 94, in _enter
2023-03-15 19:32:06.572 38 ERROR keystone.server.flask.application     generated = self._enter_create(value, createdtime)
2023-03-15 19:32:06.572 38 ERROR keystone.server.flask.application   File "/var/lib/kolla/venv/lib/python3.9/site-packages/dogpile/lock.py", line 178, in _enter_create
2023-03-15 19:32:06.572 38 ERROR keystone.server.flask.application     return self.creator()
2023-03-15 19:32:06.572 38 ERROR keystone.server.flask.application   File "/var/lib/kolla/venv/lib/python3.9/site-packages/dogpile/cache/region.py", line 995, in gen_value
2023-03-15 19:32:06.572 38 ERROR keystone.server.flask.application     created_value = creator(
2023-03-15 19:32:06.572 38 ERROR keystone.server.flask.application   File "/var/lib/kolla/venv/lib/python3.9/site-packages/keystone/resource/core.py", line 903, in get_project
2023-03-15 19:32:06.572 38 ERROR keystone.server.flask.application     return self.driver.get_project(project_id)
2023-03-15 19:32:06.572 38 ERROR keystone.server.flask.application   File "/var/lib/kolla/venv/lib/python3.9/site-packages/keystone/resource/backends/sql.py", line 49, in get_project
2023-03-15 19:32:06.572 38 ERROR keystone.server.flask.application     return self._get_project(session, project_id).to_dict()
2023-03-15 19:32:06.572 38 ERROR keystone.server.flask.application   File "/var/lib/kolla/venv/lib/python3.9/site-packages/keystone/resource/backends/sql.py", line 44, in _get_project
2023-03-15 19:32:06.572 38 ERROR keystone.server.flask.application     raise exception.ProjectNotFound(project_id=project_id)
2023-03-15 19:32:06.572 38 ERROR keystone.server.flask.application keystone.exception.ProjectNotFound: Could not find project: service.
2023-03-15 19:32:06.572 38 ERROR keystone.server.flask.application 
2023-03-15 19:32:23.445 38 ERROR keystone.server.flask.application [None req-ecc1b637-15d1-4efc-aeb1-b721946466e7 e67c66414fb4476e9016e0f5a05aeb1a - - all default -] Could not find role: admin.: keystone.exception.RoleNotFound: Could not find role: admin.
2023-03-15 19:32:23.445 38 ERROR keystone.server.flask.application Traceback (most recent call last):
2023-03-15 19:32:23.445 38 ERROR keystone.server.flask.application   File "/var/lib/kolla/venv/lib/python3.9/site-packages/flask/app.py", line 1820, in full_dispatch_request
2023-03-15 19:32:23.445 38 ERROR keystone.server.flask.application     rv = self.dispatch_request()
2023-03-15 19:32:23.445 38 ERROR keystone.server.flask.application   File "/var/lib/kolla/venv/lib/python3.9/site-packages/flask/app.py", line 1796, in dispatch_request
2023-03-15 19:32:23.445 38 ERROR keystone.server.flask.application     return self.ensure_sync(self.view_functions[rule.endpoint])(**view_args)
2023-03-15 19:32:23.445 38 ERROR keystone.server.flask.application   File "/var/lib/kolla/venv/lib/python3.9/site-packages/flask_restful/__init__.py", line 467, in wrapper
2023-03-15 19:32:23.445 38 ERROR keystone.server.flask.application     resp = resource(*args, **kwargs)
2023-03-15 19:32:23.445 38 ERROR keystone.server.flask.application   File "/var/lib/kolla/venv/lib/python3.9/site-packages/flask/views.py", line 107, in view
2023-03-15 19:32:23.445 38 ERROR keystone.server.flask.application     return current_app.ensure_sync(self.dispatch_request)(**kwargs)
2023-03-15 19:32:23.445 38 ERROR keystone.server.flask.application   File "/var/lib/kolla/venv/lib/python3.9/site-packages/flask_restful/__init__.py", line 582, in dispatch_request
2023-03-15 19:32:23.445 38 ERROR keystone.server.flask.application     resp = meth(*args, **kwargs)
2023-03-15 19:32:23.445 38 ERROR keystone.server.flask.application   File "/var/lib/kolla/venv/lib/python3.9/site-packages/keystone/api/roles.py", line 50, in get
2023-03-15 19:32:23.445 38 ERROR keystone.server.flask.application     return self._get_role(role_id)
2023-03-15 19:32:23.445 38 ERROR keystone.server.flask.application   File "/var/lib/kolla/venv/lib/python3.9/site-packages/keystone/api/roles.py", line 70, in _get_role
2023-03-15 19:32:23.445 38 ERROR keystone.server.flask.application     ENFORCER.enforce_call(action='identity:get_role')
2023-03-15 19:32:23.445 38 ERROR keystone.server.flask.application   File "/var/lib/kolla/venv/lib/python3.9/site-packages/keystone/common/rbac_enforcer/enforcer.py", line 402, in enforce_call
2023-03-15 19:32:23.445 38 ERROR keystone.server.flask.application     policy_dict.update(cls._extract_member_target_data(
2023-03-15 19:32:23.445 38 ERROR keystone.server.flask.application   File "/var/lib/kolla/venv/lib/python3.9/site-packages/keystone/common/rbac_enforcer/enforcer.py", line 234, in _extract_member_target_data
2023-03-15 19:32:23.445 38 ERROR keystone.server.flask.application     member_name: func(flask.request.view_args[key])
2023-03-15 19:32:23.445 38 ERROR keystone.server.flask.application   File "/var/lib/kolla/venv/lib/python3.9/site-packages/keystone/common/manager.py", line 115, in wrapped
2023-03-15 19:32:23.445 38 ERROR keystone.server.flask.application     __ret_val = __f(*args, **kwargs)
2023-03-15 19:32:23.445 38 ERROR keystone.server.flask.application   File "/var/lib/kolla/venv/lib/python3.9/site-packages/decorator.py", line 232, in fun
2023-03-15 19:32:23.445 38 ERROR keystone.server.flask.application     return caller(func, *(extras + args), **kw)
2023-03-15 19:32:23.445 38 ERROR keystone.server.flask.application   File "/var/lib/kolla/venv/lib/python3.9/site-packages/dogpile/cache/region.py", line 1577, in get_or_create_for_user_func
2023-03-15 19:32:23.445 38 ERROR keystone.server.flask.application     return self.get_or_create(
2023-03-15 19:32:23.445 38 ERROR keystone.server.flask.application   File "/var/lib/kolla/venv/lib/python3.9/site-packages/dogpile/cache/region.py", line 1042, in get_or_create
2023-03-15 19:32:23.445 38 ERROR keystone.server.flask.application     with Lock(
2023-03-15 19:32:23.445 38 ERROR keystone.server.flask.application   File "/var/lib/kolla/venv/lib/python3.9/site-packages/dogpile/lock.py", line 185, in __enter__
2023-03-15 19:32:23.445 38 ERROR keystone.server.flask.application     return self._enter()
2023-03-15 19:32:23.445 38 ERROR keystone.server.flask.application   File "/var/lib/kolla/venv/lib/python3.9/site-packages/dogpile/lock.py", line 94, in _enter
2023-03-15 19:32:23.445 38 ERROR keystone.server.flask.application     generated = self._enter_create(value, createdtime)
2023-03-15 19:32:23.445 38 ERROR keystone.server.flask.application   File "/var/lib/kolla/venv/lib/python3.9/site-packages/dogpile/lock.py", line 178, in _enter_create
2023-03-15 19:32:23.445 38 ERROR keystone.server.flask.application     return self.creator()
2023-03-15 19:32:23.445 38 ERROR keystone.server.flask.application   File "/var/lib/kolla/venv/lib/python3.9/site-packages/dogpile/cache/region.py", line 995, in gen_value
2023-03-15 19:32:23.445 38 ERROR keystone.server.flask.application     created_value = creator(
2023-03-15 19:32:23.445 38 ERROR keystone.server.flask.application   File "/var/lib/kolla/venv/lib/python3.9/site-packages/keystone/assignment/core.py", line 1276, in get_role
2023-03-15 19:32:23.445 38 ERROR keystone.server.flask.application     return self.driver.get_role(role_id)
2023-03-15 19:32:23.445 38 ERROR keystone.server.flask.application   File "/var/lib/kolla/venv/lib/python3.9/site-packages/keystone/assignment/role_backends/sql.py", line 70, in get_role
2023-03-15 19:32:23.445 38 ERROR keystone.server.flask.application     return self._get_role(session, role_id).to_dict()
2023-03-15 19:32:23.445 38 ERROR keystone.server.flask.application   File "/var/lib/kolla/venv/lib/python3.9/site-packages/keystone/assignment/role_backends/sql.py", line 65, in _get_role
2023-03-15 19:32:23.445 38 ERROR keystone.server.flask.application     raise exception.RoleNotFound(role_id=role_id)
2023-03-15 19:32:23.445 38 ERROR keystone.server.flask.application keystone.exception.RoleNotFound: Could not find role: admin.
2023-03-15 19:32:23.445 38 ERROR keystone.server.flask.application 
2023-03-15 19:32:25.026 38 ERROR keystone.server.flask.application [None req-5cfc25cf-4d84-4e4a-9e2d-1b8f9dbec1fd e67c66414fb4476e9016e0f5a05aeb1a - - all default -] Could not find user: ironic.: keystone.exception.UserNotFound: Could not find user: ironic.
2023-03-15 19:32:25.026 38 ERROR keystone.server.flask.application Traceback (most recent call last):
2023-03-15 19:32:25.026 38 ERROR keystone.server.flask.application   File "/var/lib/kolla/venv/lib/python3.9/site-packages/flask/app.py", line 1820, in full_dispatch_request
2023-03-15 19:32:25.026 38 ERROR keystone.server.flask.application     rv = self.dispatch_request()
2023-03-15 19:32:25.026 38 ERROR keystone.server.flask.application   File "/var/lib/kolla/venv/lib/python3.9/site-packages/flask/app.py", line 1796, in dispatch_request
2023-03-15 19:32:25.026 38 ERROR keystone.server.flask.application     return self.ensure_sync(self.view_functions[rule.endpoint])(**view_args)
2023-03-15 19:32:25.026 38 ERROR keystone.server.flask.application   File "/var/lib/kolla/venv/lib/python3.9/site-packages/flask_restful/__init__.py", line 467, in wrapper
2023-03-15 19:32:25.026 38 ERROR keystone.server.flask.application     resp = resource(*args, **kwargs)
2023-03-15 19:32:25.026 38 ERROR keystone.server.flask.application   File "/var/lib/kolla/venv/lib/python3.9/site-packages/flask/views.py", line 107, in view
2023-03-15 19:32:25.026 38 ERROR keystone.server.flask.application     return current_app.ensure_sync(self.dispatch_request)(**kwargs)
2023-03-15 19:32:25.026 38 ERROR keystone.server.flask.application   File "/var/lib/kolla/venv/lib/python3.9/site-packages/flask_restful/__init__.py", line 582, in dispatch_request
2023-03-15 19:32:25.026 38 ERROR keystone.server.flask.application     resp = meth(*args, **kwargs)
2023-03-15 19:32:25.026 38 ERROR keystone.server.flask.application   File "/var/lib/kolla/venv/lib/python3.9/site-packages/keystone/api/users.py", line 182, in get
2023-03-15 19:32:25.026 38 ERROR keystone.server.flask.application     return self._get_user(user_id)
2023-03-15 19:32:25.026 38 ERROR keystone.server.flask.application   File "/var/lib/kolla/venv/lib/python3.9/site-packages/keystone/api/users.py", line 194, in _get_user
2023-03-15 19:32:25.026 38 ERROR keystone.server.flask.application     ref = PROVIDERS.identity_api.get_user(user_id)
2023-03-15 19:32:25.026 38 ERROR keystone.server.flask.application   File "/var/lib/kolla/venv/lib/python3.9/site-packages/keystone/common/manager.py", line 115, in wrapped
2023-03-15 19:32:25.026 38 ERROR keystone.server.flask.application     __ret_val = __f(*args, **kwargs)
2023-03-15 19:32:25.026 38 ERROR keystone.server.flask.application   File "/var/lib/kolla/venv/lib/python3.9/site-packages/keystone/identity/core.py", line 414, in wrapper
2023-03-15 19:32:25.026 38 ERROR keystone.server.flask.application     return f(self, *args, **kwargs)
2023-03-15 19:32:25.026 38 ERROR keystone.server.flask.application   File "/var/lib/kolla/venv/lib/python3.9/site-packages/keystone/identity/core.py", line 424, in wrapper
2023-03-15 19:32:25.026 38 ERROR keystone.server.flask.application     return f(self, *args, **kwargs)
2023-03-15 19:32:25.026 38 ERROR keystone.server.flask.application   File "/var/lib/kolla/venv/lib/python3.9/site-packages/decorator.py", line 232, in fun
2023-03-15 19:32:25.026 38 ERROR keystone.server.flask.application     return caller(func, *(extras + args), **kw)
2023-03-15 19:32:25.026 38 ERROR keystone.server.flask.application   File "/var/lib/kolla/venv/lib/python3.9/site-packages/dogpile/cache/region.py", line 1577, in get_or_create_for_user_func
2023-03-15 19:32:25.026 38 ERROR keystone.server.flask.application     return self.get_or_create(
2023-03-15 19:32:25.026 38 ERROR keystone.server.flask.application   File "/var/lib/kolla/venv/lib/python3.9/site-packages/dogpile/cache/region.py", line 1042, in get_or_create
2023-03-15 19:32:25.026 38 ERROR keystone.server.flask.application     with Lock(
2023-03-15 19:32:25.026 38 ERROR keystone.server.flask.application   File "/var/lib/kolla/venv/lib/python3.9/site-packages/dogpile/lock.py", line 185, in __enter__
2023-03-15 19:32:25.026 38 ERROR keystone.server.flask.application     return self._enter()
2023-03-15 19:32:25.026 38 ERROR keystone.server.flask.application   File "/var/lib/kolla/venv/lib/python3.9/site-packages/dogpile/lock.py", line 94, in _enter
2023-03-15 19:32:25.026 38 ERROR keystone.server.flask.application     generated = self._enter_create(value, createdtime)
2023-03-15 19:32:25.026 38 ERROR keystone.server.flask.application   File "/var/lib/kolla/venv/lib/python3.9/site-packages/dogpile/lock.py", line 178, in _enter_create
2023-03-15 19:32:25.026 38 ERROR keystone.server.flask.application     return self.creator()
2023-03-15 19:32:25.026 38 ERROR keystone.server.flask.application   File "/var/lib/kolla/venv/lib/python3.9/site-packages/dogpile/cache/region.py", line 995, in gen_value
2023-03-15 19:32:25.026 38 ERROR keystone.server.flask.application     created_value = creator(
2023-03-15 19:32:25.026 38 ERROR keystone.server.flask.application   File "/var/lib/kolla/venv/lib/python3.9/site-packages/keystone/identity/core.py", line 1011, in get_user
2023-03-15 19:32:25.026 38 ERROR keystone.server.flask.application     ref = driver.get_user(entity_id)
2023-03-15 19:32:25.026 38 ERROR keystone.server.flask.application   File "/var/lib/kolla/venv/lib/python3.9/site-packages/keystone/identity/backends/sql.py", line 200, in get_user
2023-03-15 19:32:25.026 38 ERROR keystone.server.flask.application     self._get_user(session, user_id).to_dict())
2023-03-15 19:32:25.026 38 ERROR keystone.server.flask.application   File "/var/lib/kolla/venv/lib/python3.9/site-packages/keystone/identity/backends/sql.py", line 194, in _get_user
2023-03-15 19:32:25.026 38 ERROR keystone.server.flask.application     raise exception.UserNotFound(user_id=user_id)
2023-03-15 19:32:25.026 38 ERROR keystone.server.flask.application keystone.exception.UserNotFound: Could not find user: ironic.
2023-03-15 19:32:25.026 38 ERROR keystone.server.flask.application 
2023-03-15 19:32:25.858 37 ERROR keystone.server.flask.application [None req-5c016441-902e-4208-8ca1-30ee5efcccc3 e67c66414fb4476e9016e0f5a05aeb1a - - all default -] Could not find project: service.: keystone.exception.ProjectNotFound: Could not find project: service.
2023-03-15 19:32:25.858 37 ERROR keystone.server.flask.application Traceback (most recent call last):
2023-03-15 19:32:25.858 37 ERROR keystone.server.flask.application   File "/var/lib/kolla/venv/lib/python3.9/site-packages/flask/app.py", line 1820, in full_dispatch_request
2023-03-15 19:32:25.858 37 ERROR keystone.server.flask.application     rv = self.dispatch_request()
2023-03-15 19:32:25.858 37 ERROR keystone.server.flask.application   File "/var/lib/kolla/venv/lib/python3.9/site-packages/flask/app.py", line 1796, in dispatch_request
2023-03-15 19:32:25.858 37 ERROR keystone.server.flask.application     return self.ensure_sync(self.view_functions[rule.endpoint])(**view_args)
2023-03-15 19:32:25.858 37 ERROR keystone.server.flask.application   File "/var/lib/kolla/venv/lib/python3.9/site-packages/flask_restful/__init__.py", line 467, in wrapper
2023-03-15 19:32:25.858 37 ERROR keystone.server.flask.application     resp = resource(*args, **kwargs)
2023-03-15 19:32:25.858 37 ERROR keystone.server.flask.application   File "/var/lib/kolla/venv/lib/python3.9/site-packages/flask/views.py", line 107, in view
2023-03-15 19:32:25.858 37 ERROR keystone.server.flask.application     return current_app.ensure_sync(self.dispatch_request)(**kwargs)
2023-03-15 19:32:25.858 37 ERROR keystone.server.flask.application   File "/var/lib/kolla/venv/lib/python3.9/site-packages/flask_restful/__init__.py", line 582, in dispatch_request
2023-03-15 19:32:25.858 37 ERROR keystone.server.flask.application     resp = meth(*args, **kwargs)
2023-03-15 19:32:25.858 37 ERROR keystone.server.flask.application   File "/var/lib/kolla/venv/lib/python3.9/site-packages/keystone/api/projects.py", line 151, in get
2023-03-15 19:32:25.858 37 ERROR keystone.server.flask.application     return self._get_project(project_id)
2023-03-15 19:32:25.858 37 ERROR keystone.server.flask.application   File "/var/lib/kolla/venv/lib/python3.9/site-packages/keystone/api/projects.py", line 107, in _get_project
2023-03-15 19:32:25.858 37 ERROR keystone.server.flask.application     project = PROVIDERS.resource_api.get_project(project_id)
2023-03-15 19:32:25.858 37 ERROR keystone.server.flask.application   File "/var/lib/kolla/venv/lib/python3.9/site-packages/keystone/common/manager.py", line 115, in wrapped
2023-03-15 19:32:25.858 37 ERROR keystone.server.flask.application     __ret_val = __f(*args, **kwargs)
2023-03-15 19:32:25.858 37 ERROR keystone.server.flask.application   File "/var/lib/kolla/venv/lib/python3.9/site-packages/decorator.py", line 232, in fun
2023-03-15 19:32:25.858 37 ERROR keystone.server.flask.application     return caller(func, *(extras + args), **kw)
2023-03-15 19:32:25.858 37 ERROR keystone.server.flask.application   File "/var/lib/kolla/venv/lib/python3.9/site-packages/dogpile/cache/region.py", line 1577, in get_or_create_for_user_func
2023-03-15 19:32:25.858 37 ERROR keystone.server.flask.application     return self.get_or_create(
2023-03-15 19:32:25.858 37 ERROR keystone.server.flask.application   File "/var/lib/kolla/venv/lib/python3.9/site-packages/dogpile/cache/region.py", line 1042, in get_or_create
2023-03-15 19:32:25.858 37 ERROR keystone.server.flask.application     with Lock(
2023-03-15 19:32:25.858 37 ERROR keystone.server.flask.application   File "/var/lib/kolla/venv/lib/python3.9/site-packages/dogpile/lock.py", line 185, in __enter__
2023-03-15 19:32:25.858 37 ERROR keystone.server.flask.application     return self._enter()
2023-03-15 19:32:25.858 37 ERROR keystone.server.flask.application   File "/var/lib/kolla/venv/lib/python3.9/site-packages/dogpile/lock.py", line 94, in _enter
2023-03-15 19:32:25.858 37 ERROR keystone.server.flask.application     generated = self._enter_create(value, createdtime)
2023-03-15 19:32:25.858 37 ERROR keystone.server.flask.application   File "/var/lib/kolla/venv/lib/python3.9/site-packages/dogpile/lock.py", line 178, in _enter_create
2023-03-15 19:32:25.858 37 ERROR keystone.server.flask.application     return self.creator()
2023-03-15 19:32:25.858 37 ERROR keystone.server.flask.application   File "/var/lib/kolla/venv/lib/python3.9/site-packages/dogpile/cache/region.py", line 995, in gen_value
2023-03-15 19:32:25.858 37 ERROR keystone.server.flask.application     created_value = creator(
2023-03-15 19:32:25.858 37 ERROR keystone.server.flask.application   File "/var/lib/kolla/venv/lib/python3.9/site-packages/keystone/resource/core.py", line 903, in get_project
2023-03-15 19:32:25.858 37 ERROR keystone.server.flask.application     return self.driver.get_project(project_id)
2023-03-15 19:32:25.858 37 ERROR keystone.server.flask.application   File "/var/lib/kolla/venv/lib/python3.9/site-packages/keystone/resource/backends/sql.py", line 49, in get_project
2023-03-15 19:32:25.858 37 ERROR keystone.server.flask.application     return self._get_project(session, project_id).to_dict()
2023-03-15 19:32:25.858 37 ERROR keystone.server.flask.application   File "/var/lib/kolla/venv/lib/python3.9/site-packages/keystone/resource/backends/sql.py", line 44, in _get_project
2023-03-15 19:32:25.858 37 ERROR keystone.server.flask.application     raise exception.ProjectNotFound(project_id=project_id)
2023-03-15 19:32:25.858 37 ERROR keystone.server.flask.application keystone.exception.ProjectNotFound: Could not find project: service.
2023-03-15 19:32:25.858 37 ERROR keystone.server.flask.application 
2023-03-15 19:32:36.630 39 ERROR keystone.server.flask.application [None req-49d65742-7231-4364-88c5-03b6ceb25c1b e67c66414fb4476e9016e0f5a05aeb1a - - all default -] Could not find role: admin.: keystone.exception.RoleNotFound: Could not find role: admin.
2023-03-15 19:32:36.630 39 ERROR keystone.server.flask.application Traceback (most recent call last):
2023-03-15 19:32:36.630 39 ERROR keystone.server.flask.application   File "/var/lib/kolla/venv/lib/python3.9/site-packages/flask/app.py", line 1820, in full_dispatch_request
2023-03-15 19:32:36.630 39 ERROR keystone.server.flask.application     rv = self.dispatch_request()
2023-03-15 19:32:36.630 39 ERROR keystone.server.flask.application   File "/var/lib/kolla/venv/lib/python3.9/site-packages/flask/app.py", line 1796, in dispatch_request
2023-03-15 19:32:36.630 39 ERROR keystone.server.flask.application     return self.ensure_sync(self.view_functions[rule.endpoint])(**view_args)
2023-03-15 19:32:36.630 39 ERROR keystone.server.flask.application   File "/var/lib/kolla/venv/lib/python3.9/site-packages/flask_restful/__init__.py", line 467, in wrapper
2023-03-15 19:32:36.630 39 ERROR keystone.server.flask.application     resp = resource(*args, **kwargs)
2023-03-15 19:32:36.630 39 ERROR keystone.server.flask.application   File "/var/lib/kolla/venv/lib/python3.9/site-packages/flask/views.py", line 107, in view
2023-03-15 19:32:36.630 39 ERROR keystone.server.flask.application     return current_app.ensure_sync(self.dispatch_request)(**kwargs)
2023-03-15 19:32:36.630 39 ERROR keystone.server.flask.application   File "/var/lib/kolla/venv/lib/python3.9/site-packages/flask_restful/__init__.py", line 582, in dispatch_request
2023-03-15 19:32:36.630 39 ERROR keystone.server.flask.application     resp = meth(*args, **kwargs)
2023-03-15 19:32:36.630 39 ERROR keystone.server.flask.application   File "/var/lib/kolla/venv/lib/python3.9/site-packages/keystone/api/roles.py", line 50, in get
2023-03-15 19:32:36.630 39 ERROR keystone.server.flask.application     return self._get_role(role_id)
2023-03-15 19:32:36.630 39 ERROR keystone.server.flask.application   File "/var/lib/kolla/venv/lib/python3.9/site-packages/keystone/api/roles.py", line 70, in _get_role
2023-03-15 19:32:36.630 39 ERROR keystone.server.flask.application     ENFORCER.enforce_call(action='identity:get_role')
2023-03-15 19:32:36.630 39 ERROR keystone.server.flask.application   File "/var/lib/kolla/venv/lib/python3.9/site-packages/keystone/common/rbac_enforcer/enforcer.py", line 402, in enforce_call
2023-03-15 19:32:36.630 39 ERROR keystone.server.flask.application     policy_dict.update(cls._extract_member_target_data(
2023-03-15 19:32:36.630 39 ERROR keystone.server.flask.application   File "/var/lib/kolla/venv/lib/python3.9/site-packages/keystone/common/rbac_enforcer/enforcer.py", line 234, in _extract_member_target_data
2023-03-15 19:32:36.630 39 ERROR keystone.server.flask.application     member_name: func(flask.request.view_args[key])
2023-03-15 19:32:36.630 39 ERROR keystone.server.flask.application   File "/var/lib/kolla/venv/lib/python3.9/site-packages/keystone/common/manager.py", line 115, in wrapped
2023-03-15 19:32:36.630 39 ERROR keystone.server.flask.application     __ret_val = __f(*args, **kwargs)
2023-03-15 19:32:36.630 39 ERROR keystone.server.flask.application   File "/var/lib/kolla/venv/lib/python3.9/site-packages/decorator.py", line 232, in fun
2023-03-15 19:32:36.630 39 ERROR keystone.server.flask.application     return caller(func, *(extras + args), **kw)
2023-03-15 19:32:36.630 39 ERROR keystone.server.flask.application   File "/var/lib/kolla/venv/lib/python3.9/site-packages/dogpile/cache/region.py", line 1577, in get_or_create_for_user_func
2023-03-15 19:32:36.630 39 ERROR keystone.server.flask.application     return self.get_or_create(
2023-03-15 19:32:36.630 39 ERROR keystone.server.flask.application   File "/var/lib/kolla/venv/lib/python3.9/site-packages/dogpile/cache/region.py", line 1042, in get_or_create
2023-03-15 19:32:36.630 39 ERROR keystone.server.flask.application     with Lock(
2023-03-15 19:32:36.630 39 ERROR keystone.server.flask.application   File "/var/lib/kolla/venv/lib/python3.9/site-packages/dogpile/lock.py", line 185, in __enter__
2023-03-15 19:32:36.630 39 ERROR keystone.server.flask.application     return self._enter()
2023-03-15 19:32:36.630 39 ERROR keystone.server.flask.application   File "/var/lib/kolla/venv/lib/python3.9/site-packages/dogpile/lock.py", line 94, in _enter
2023-03-15 19:32:36.630 39 ERROR keystone.server.flask.application     generated = self._enter_create(value, createdtime)
2023-03-15 19:32:36.630 39 ERROR keystone.server.flask.application   File "/var/lib/kolla/venv/lib/python3.9/site-packages/dogpile/lock.py", line 178, in _enter_create
2023-03-15 19:32:36.630 39 ERROR keystone.server.flask.application     return self.creator()
2023-03-15 19:32:36.630 39 ERROR keystone.server.flask.application   File "/var/lib/kolla/venv/lib/python3.9/site-packages/dogpile/cache/region.py", line 995, in gen_value
2023-03-15 19:32:36.630 39 ERROR keystone.server.flask.application     created_value = creator(
2023-03-15 19:32:36.630 39 ERROR keystone.server.flask.application   File "/var/lib/kolla/venv/lib/python3.9/site-packages/keystone/assignment/core.py", line 1276, in get_role
2023-03-15 19:32:36.630 39 ERROR keystone.server.flask.application     return self.driver.get_role(role_id)
2023-03-15 19:32:36.630 39 ERROR keystone.server.flask.application   File "/var/lib/kolla/venv/lib/python3.9/site-packages/keystone/assignment/role_backends/sql.py", line 70, in get_role
2023-03-15 19:32:36.630 39 ERROR keystone.server.flask.application     return self._get_role(session, role_id).to_dict()
2023-03-15 19:32:36.630 39 ERROR keystone.server.flask.application   File "/var/lib/kolla/venv/lib/python3.9/site-packages/keystone/assignment/role_backends/sql.py", line 65, in _get_role
2023-03-15 19:32:36.630 39 ERROR keystone.server.flask.application     raise exception.RoleNotFound(role_id=role_id)
2023-03-15 19:32:36.630 39 ERROR keystone.server.flask.application keystone.exception.RoleNotFound: Could not find role: admin.
2023-03-15 19:32:36.630 39 ERROR keystone.server.flask.application 
2023-03-15 19:32:37.880 39 ERROR keystone.server.flask.application [None req-58339a9e-bbae-4ad8-a996-605996f7a718 e67c66414fb4476e9016e0f5a05aeb1a - - all default -] Could not find user: ironic-inspector.: keystone.exception.UserNotFound: Could not find user: ironic-inspector.
2023-03-15 19:32:37.880 39 ERROR keystone.server.flask.application Traceback (most recent call last):
2023-03-15 19:32:37.880 39 ERROR keystone.server.flask.application   File "/var/lib/kolla/venv/lib/python3.9/site-packages/flask/app.py", line 1820, in full_dispatch_request
2023-03-15 19:32:37.880 39 ERROR keystone.server.flask.application     rv = self.dispatch_request()
2023-03-15 19:32:37.880 39 ERROR keystone.server.flask.application   File "/var/lib/kolla/venv/lib/python3.9/site-packages/flask/app.py", line 1796, in dispatch_request
2023-03-15 19:32:37.880 39 ERROR keystone.server.flask.application     return self.ensure_sync(self.view_functions[rule.endpoint])(**view_args)
2023-03-15 19:32:37.880 39 ERROR keystone.server.flask.application   File "/var/lib/kolla/venv/lib/python3.9/site-packages/flask_restful/__init__.py", line 467, in wrapper
2023-03-15 19:32:37.880 39 ERROR keystone.server.flask.application     resp = resource(*args, **kwargs)
2023-03-15 19:32:37.880 39 ERROR keystone.server.flask.application   File "/var/lib/kolla/venv/lib/python3.9/site-packages/flask/views.py", line 107, in view
2023-03-15 19:32:37.880 39 ERROR keystone.server.flask.application     return current_app.ensure_sync(self.dispatch_request)(**kwargs)
2023-03-15 19:32:37.880 39 ERROR keystone.server.flask.application   File "/var/lib/kolla/venv/lib/python3.9/site-packages/flask_restful/__init__.py", line 582, in dispatch_request
2023-03-15 19:32:37.880 39 ERROR keystone.server.flask.application     resp = meth(*args, **kwargs)
2023-03-15 19:32:37.880 39 ERROR keystone.server.flask.application   File "/var/lib/kolla/venv/lib/python3.9/site-packages/keystone/api/users.py", line 182, in get
2023-03-15 19:32:37.880 39 ERROR keystone.server.flask.application     return self._get_user(user_id)
2023-03-15 19:32:37.880 39 ERROR keystone.server.flask.application   File "/var/lib/kolla/venv/lib/python3.9/site-packages/keystone/api/users.py", line 194, in _get_user
2023-03-15 19:32:37.880 39 ERROR keystone.server.flask.application     ref = PROVIDERS.identity_api.get_user(user_id)
2023-03-15 19:32:37.880 39 ERROR keystone.server.flask.application   File "/var/lib/kolla/venv/lib/python3.9/site-packages/keystone/common/manager.py", line 115, in wrapped
2023-03-15 19:32:37.880 39 ERROR keystone.server.flask.application     __ret_val = __f(*args, **kwargs)
2023-03-15 19:32:37.880 39 ERROR keystone.server.flask.application   File "/var/lib/kolla/venv/lib/python3.9/site-packages/keystone/identity/core.py", line 414, in wrapper
2023-03-15 19:32:37.880 39 ERROR keystone.server.flask.application     return f(self, *args, **kwargs)
2023-03-15 19:32:37.880 39 ERROR keystone.server.flask.application   File "/var/lib/kolla/venv/lib/python3.9/site-packages/keystone/identity/core.py", line 424, in wrapper
2023-03-15 19:32:37.880 39 ERROR keystone.server.flask.application     return f(self, *args, **kwargs)
2023-03-15 19:32:37.880 39 ERROR keystone.server.flask.application   File "/var/lib/kolla/venv/lib/python3.9/site-packages/decorator.py", line 232, in fun
2023-03-15 19:32:37.880 39 ERROR keystone.server.flask.application     return caller(func, *(extras + args), **kw)
2023-03-15 19:32:37.880 39 ERROR keystone.server.flask.application   File "/var/lib/kolla/venv/lib/python3.9/site-packages/dogpile/cache/region.py", line 1577, in get_or_create_for_user_func
2023-03-15 19:32:37.880 39 ERROR keystone.server.flask.application     return self.get_or_create(
2023-03-15 19:32:37.880 39 ERROR keystone.server.flask.application   File "/var/lib/kolla/venv/lib/python3.9/site-packages/dogpile/cache/region.py", line 1042, in get_or_create
2023-03-15 19:32:37.880 39 ERROR keystone.server.flask.application     with Lock(
2023-03-15 19:32:37.880 39 ERROR keystone.server.flask.application   File "/var/lib/kolla/venv/lib/python3.9/site-packages/dogpile/lock.py", line 185, in __enter__
2023-03-15 19:32:37.880 39 ERROR keystone.server.flask.application     return self._enter()
2023-03-15 19:32:37.880 39 ERROR keystone.server.flask.application   File "/var/lib/kolla/venv/lib/python3.9/site-packages/dogpile/lock.py", line 94, in _enter
2023-03-15 19:32:37.880 39 ERROR keystone.server.flask.application     generated = self._enter_create(value, createdtime)
2023-03-15 19:32:37.880 39 ERROR keystone.server.flask.application   File "/var/lib/kolla/venv/lib/python3.9/site-packages/dogpile/lock.py", line 178, in _enter_create
2023-03-15 19:32:37.880 39 ERROR keystone.server.flask.application     return self.creator()
2023-03-15 19:32:37.880 39 ERROR keystone.server.flask.application   File "/var/lib/kolla/venv/lib/python3.9/site-packages/dogpile/cache/region.py", line 995, in gen_value
2023-03-15 19:32:37.880 39 ERROR keystone.server.flask.application     created_value = creator(
2023-03-15 19:32:37.880 39 ERROR keystone.server.flask.application   File "/var/lib/kolla/venv/lib/python3.9/site-packages/keystone/identity/core.py", line 1011, in get_user
2023-03-15 19:32:37.880 39 ERROR keystone.server.flask.application     ref = driver.get_user(entity_id)
2023-03-15 19:32:37.880 39 ERROR keystone.server.flask.application   File "/var/lib/kolla/venv/lib/python3.9/site-packages/keystone/identity/backends/sql.py", line 200, in get_user
2023-03-15 19:32:37.880 39 ERROR keystone.server.flask.application     self._get_user(session, user_id).to_dict())
2023-03-15 19:32:37.880 39 ERROR keystone.server.flask.application   File "/var/lib/kolla/venv/lib/python3.9/site-packages/keystone/identity/backends/sql.py", line 194, in _get_user
2023-03-15 19:32:37.880 39 ERROR keystone.server.flask.application     raise exception.UserNotFound(user_id=user_id)
2023-03-15 19:32:37.880 39 ERROR keystone.server.flask.application keystone.exception.UserNotFound: Could not find user: ironic-inspector.
2023-03-15 19:32:37.880 39 ERROR keystone.server.flask.application 
2023-03-15 19:32:38.751 38 ERROR keystone.server.flask.application [None req-fc6803bb-5834-4f56-a29b-ddc39b1be76e e67c66414fb4476e9016e0f5a05aeb1a - - all default -] Could not find project: service.: keystone.exception.ProjectNotFound: Could not find project: service.
2023-03-15 19:32:38.751 38 ERROR keystone.server.flask.application Traceback (most recent call last):
2023-03-15 19:32:38.751 38 ERROR keystone.server.flask.application   File "/var/lib/kolla/venv/lib/python3.9/site-packages/flask/app.py", line 1820, in full_dispatch_request
2023-03-15 19:32:38.751 38 ERROR keystone.server.flask.application     rv = self.dispatch_request()
2023-03-15 19:32:38.751 38 ERROR keystone.server.flask.application   File "/var/lib/kolla/venv/lib/python3.9/site-packages/flask/app.py", line 1796, in dispatch_request
2023-03-15 19:32:38.751 38 ERROR keystone.server.flask.application     return self.ensure_sync(self.view_functions[rule.endpoint])(**view_args)
2023-03-15 19:32:38.751 38 ERROR keystone.server.flask.application   File "/var/lib/kolla/venv/lib/python3.9/site-packages/flask_restful/__init__.py", line 467, in wrapper
2023-03-15 19:32:38.751 38 ERROR keystone.server.flask.application     resp = resource(*args, **kwargs)
2023-03-15 19:32:38.751 38 ERROR keystone.server.flask.application   File "/var/lib/kolla/venv/lib/python3.9/site-packages/flask/views.py", line 107, in view
2023-03-15 19:32:38.751 38 ERROR keystone.server.flask.application     return current_app.ensure_sync(self.dispatch_request)(**kwargs)
2023-03-15 19:32:38.751 38 ERROR keystone.server.flask.application   File "/var/lib/kolla/venv/lib/python3.9/site-packages/flask_restful/__init__.py", line 582, in dispatch_request
2023-03-15 19:32:38.751 38 ERROR keystone.server.flask.application     resp = meth(*args, **kwargs)
2023-03-15 19:32:38.751 38 ERROR keystone.server.flask.application   File "/var/lib/kolla/venv/lib/python3.9/site-packages/keystone/api/projects.py", line 151, in get
2023-03-15 19:32:38.751 38 ERROR keystone.server.flask.application     return self._get_project(project_id)
2023-03-15 19:32:38.751 38 ERROR keystone.server.flask.application   File "/var/lib/kolla/venv/lib/python3.9/site-packages/keystone/api/projects.py", line 107, in _get_project
2023-03-15 19:32:38.751 38 ERROR keystone.server.flask.application     project = PROVIDERS.resource_api.get_project(project_id)
2023-03-15 19:32:38.751 38 ERROR keystone.server.flask.application   File "/var/lib/kolla/venv/lib/python3.9/site-packages/keystone/common/manager.py", line 115, in wrapped
2023-03-15 19:32:38.751 38 ERROR keystone.server.flask.application     __ret_val = __f(*args, **kwargs)
2023-03-15 19:32:38.751 38 ERROR keystone.server.flask.application   File "/var/lib/kolla/venv/lib/python3.9/site-packages/decorator.py", line 232, in fun
2023-03-15 19:32:38.751 38 ERROR keystone.server.flask.application     return caller(func, *(extras + args), **kw)
2023-03-15 19:32:38.751 38 ERROR keystone.server.flask.application   File "/var/lib/kolla/venv/lib/python3.9/site-packages/dogpile/cache/region.py", line 1577, in get_or_create_for_user_func
2023-03-15 19:32:38.751 38 ERROR keystone.server.flask.application     return self.get_or_create(
2023-03-15 19:32:38.751 38 ERROR keystone.server.flask.application   File "/var/lib/kolla/venv/lib/python3.9/site-packages/dogpile/cache/region.py", line 1042, in get_or_create
2023-03-15 19:32:38.751 38 ERROR keystone.server.flask.application     with Lock(
2023-03-15 19:32:38.751 38 ERROR keystone.server.flask.application   File "/var/lib/kolla/venv/lib/python3.9/site-packages/dogpile/lock.py", line 185, in __enter__
2023-03-15 19:32:38.751 38 ERROR keystone.server.flask.application     return self._enter()
2023-03-15 19:32:38.751 38 ERROR keystone.server.flask.application   File "/var/lib/kolla/venv/lib/python3.9/site-packages/dogpile/lock.py", line 94, in _enter
2023-03-15 19:32:38.751 38 ERROR keystone.server.flask.application     generated = self._enter_create(value, createdtime)
2023-03-15 19:32:38.751 38 ERROR keystone.server.flask.application   File "/var/lib/kolla/venv/lib/python3.9/site-packages/dogpile/lock.py", line 178, in _enter_create
2023-03-15 19:32:38.751 38 ERROR keystone.server.flask.application     return self.creator()
2023-03-15 19:32:38.751 38 ERROR keystone.server.flask.application   File "/var/lib/kolla/venv/lib/python3.9/site-packages/dogpile/cache/region.py", line 995, in gen_value
2023-03-15 19:32:38.751 38 ERROR keystone.server.flask.application     created_value = creator(
2023-03-15 19:32:38.751 38 ERROR keystone.server.flask.application   File "/var/lib/kolla/venv/lib/python3.9/site-packages/keystone/resource/core.py", line 903, in get_project
2023-03-15 19:32:38.751 38 ERROR keystone.server.flask.application     return self.driver.get_project(project_id)
2023-03-15 19:32:38.751 38 ERROR keystone.server.flask.application   File "/var/lib/kolla/venv/lib/python3.9/site-packages/keystone/resource/backends/sql.py", line 49, in get_project
2023-03-15 19:32:38.751 38 ERROR keystone.server.flask.application     return self._get_project(session, project_id).to_dict()
2023-03-15 19:32:38.751 38 ERROR keystone.server.flask.application   File "/var/lib/kolla/venv/lib/python3.9/site-packages/keystone/resource/backends/sql.py", line 44, in _get_project
2023-03-15 19:32:38.751 38 ERROR keystone.server.flask.application     raise exception.ProjectNotFound(project_id=project_id)
2023-03-15 19:32:38.751 38 ERROR keystone.server.flask.application keystone.exception.ProjectNotFound: Could not find project: service.
2023-03-15 19:32:38.751 38 ERROR keystone.server.flask.application 
2023-03-15 19:35:42.797 38 ERROR keystone.server.flask.application [None req-c161b91a-8de7-4dc9-bfa6-14f8094787bc e67c66414fb4476e9016e0f5a05aeb1a - - all default -] Could not find project: service.: keystone.exception.ProjectNotFound: Could not find project: service.
2023-03-15 19:35:42.797 38 ERROR keystone.server.flask.application Traceback (most recent call last):
2023-03-15 19:35:42.797 38 ERROR keystone.server.flask.application   File "/var/lib/kolla/venv/lib/python3.9/site-packages/flask/app.py", line 1820, in full_dispatch_request
2023-03-15 19:35:42.797 38 ERROR keystone.server.flask.application     rv = self.dispatch_request()
2023-03-15 19:35:42.797 38 ERROR keystone.server.flask.application   File "/var/lib/kolla/venv/lib/python3.9/site-packages/flask/app.py", line 1796, in dispatch_request
2023-03-15 19:35:42.797 38 ERROR keystone.server.flask.application     return self.ensure_sync(self.view_functions[rule.endpoint])(**view_args)
2023-03-15 19:35:42.797 38 ERROR keystone.server.flask.application   File "/var/lib/kolla/venv/lib/python3.9/site-packages/flask_restful/__init__.py", line 467, in wrapper
2023-03-15 19:35:42.797 38 ERROR keystone.server.flask.application     resp = resource(*args, **kwargs)
2023-03-15 19:35:42.797 38 ERROR keystone.server.flask.application   File "/var/lib/kolla/venv/lib/python3.9/site-packages/flask/views.py", line 107, in view
2023-03-15 19:35:42.797 38 ERROR keystone.server.flask.application     return current_app.ensure_sync(self.dispatch_request)(**kwargs)
2023-03-15 19:35:42.797 38 ERROR keystone.server.flask.application   File "/var/lib/kolla/venv/lib/python3.9/site-packages/flask_restful/__init__.py", line 582, in dispatch_request
2023-03-15 19:35:42.797 38 ERROR keystone.server.flask.application     resp = meth(*args, **kwargs)
2023-03-15 19:35:42.797 38 ERROR keystone.server.flask.application   File "/var/lib/kolla/venv/lib/python3.9/site-packages/keystone/api/projects.py", line 151, in get
2023-03-15 19:35:42.797 38 ERROR keystone.server.flask.application     return self._get_project(project_id)
2023-03-15 19:35:42.797 38 ERROR keystone.server.flask.application   File "/var/lib/kolla/venv/lib/python3.9/site-packages/keystone/api/projects.py", line 107, in _get_project
2023-03-15 19:35:42.797 38 ERROR keystone.server.flask.application     project = PROVIDERS.resource_api.get_project(project_id)
2023-03-15 19:35:42.797 38 ERROR keystone.server.flask.application   File "/var/lib/kolla/venv/lib/python3.9/site-packages/keystone/common/manager.py", line 115, in wrapped
2023-03-15 19:35:42.797 38 ERROR keystone.server.flask.application     __ret_val = __f(*args, **kwargs)
2023-03-15 19:35:42.797 38 ERROR keystone.server.flask.application   File "/var/lib/kolla/venv/lib/python3.9/site-packages/decorator.py", line 232, in fun
2023-03-15 19:35:42.797 38 ERROR keystone.server.flask.application     return caller(func, *(extras + args), **kw)
2023-03-15 19:35:42.797 38 ERROR keystone.server.flask.application   File "/var/lib/kolla/venv/lib/python3.9/site-packages/dogpile/cache/region.py", line 1577, in get_or_create_for_user_func
2023-03-15 19:35:42.797 38 ERROR keystone.server.flask.application     return self.get_or_create(
2023-03-15 19:35:42.797 38 ERROR keystone.server.flask.application   File "/var/lib/kolla/venv/lib/python3.9/site-packages/dogpile/cache/region.py", line 1042, in get_or_create
2023-03-15 19:35:42.797 38 ERROR keystone.server.flask.application     with Lock(
2023-03-15 19:35:42.797 38 ERROR keystone.server.flask.application   File "/var/lib/kolla/venv/lib/python3.9/site-packages/dogpile/lock.py", line 185, in __enter__
2023-03-15 19:35:42.797 38 ERROR keystone.server.flask.application     return self._enter()
2023-03-15 19:35:42.797 38 ERROR keystone.server.flask.application   File "/var/lib/kolla/venv/lib/python3.9/site-packages/dogpile/lock.py", line 94, in _enter
2023-03-15 19:35:42.797 38 ERROR keystone.server.flask.application     generated = self._enter_create(value, createdtime)
2023-03-15 19:35:42.797 38 ERROR keystone.server.flask.application   File "/var/lib/kolla/venv/lib/python3.9/site-packages/dogpile/lock.py", line 178, in _enter_create
2023-03-15 19:35:42.797 38 ERROR keystone.server.flask.application     return self.creator()
2023-03-15 19:35:42.797 38 ERROR keystone.server.flask.application   File "/var/lib/kolla/venv/lib/python3.9/site-packages/dogpile/cache/region.py", line 995, in gen_value
2023-03-15 19:35:42.797 38 ERROR keystone.server.flask.application     created_value = creator(
2023-03-15 19:35:42.797 38 ERROR keystone.server.flask.application   File "/var/lib/kolla/venv/lib/python3.9/site-packages/keystone/resource/core.py", line 903, in get_project
2023-03-15 19:35:42.797 38 ERROR keystone.server.flask.application     return self.driver.get_project(project_id)
2023-03-15 19:35:42.797 38 ERROR keystone.server.flask.application   File "/var/lib/kolla/venv/lib/python3.9/site-packages/keystone/resource/backends/sql.py", line 49, in get_project
2023-03-15 19:35:42.797 38 ERROR keystone.server.flask.application     return self._get_project(session, project_id).to_dict()
2023-03-15 19:35:42.797 38 ERROR keystone.server.flask.application   File "/var/lib/kolla/venv/lib/python3.9/site-packages/keystone/resource/backends/sql.py", line 44, in _get_project
2023-03-15 19:35:42.797 38 ERROR keystone.server.flask.application     raise exception.ProjectNotFound(project_id=project_id)
2023-03-15 19:35:42.797 38 ERROR keystone.server.flask.application keystone.exception.ProjectNotFound: Could not find project: service.
2023-03-15 19:35:42.797 38 ERROR keystone.server.flask.application 
2023-03-15 19:35:59.829 37 ERROR keystone.server.flask.application [None req-fc1289ea-3f85-4bf4-8d08-2449d78a9aa0 e67c66414fb4476e9016e0f5a05aeb1a - - all default -] Could not find role: admin.: keystone.exception.RoleNotFound: Could not find role: admin.
2023-03-15 19:35:59.829 37 ERROR keystone.server.flask.application Traceback (most recent call last):
2023-03-15 19:35:59.829 37 ERROR keystone.server.flask.application   File "/var/lib/kolla/venv/lib/python3.9/site-packages/flask/app.py", line 1820, in full_dispatch_request
2023-03-15 19:35:59.829 37 ERROR keystone.server.flask.application     rv = self.dispatch_request()
2023-03-15 19:35:59.829 37 ERROR keystone.server.flask.application   File "/var/lib/kolla/venv/lib/python3.9/site-packages/flask/app.py", line 1796, in dispatch_request
2023-03-15 19:35:59.829 37 ERROR keystone.server.flask.application     return self.ensure_sync(self.view_functions[rule.endpoint])(**view_args)
2023-03-15 19:35:59.829 37 ERROR keystone.server.flask.application   File "/var/lib/kolla/venv/lib/python3.9/site-packages/flask_restful/__init__.py", line 467, in wrapper
2023-03-15 19:35:59.829 37 ERROR keystone.server.flask.application     resp = resource(*args, **kwargs)
2023-03-15 19:35:59.829 37 ERROR keystone.server.flask.application   File "/var/lib/kolla/venv/lib/python3.9/site-packages/flask/views.py", line 107, in view
2023-03-15 19:35:59.829 37 ERROR keystone.server.flask.application     return current_app.ensure_sync(self.dispatch_request)(**kwargs)
2023-03-15 19:35:59.829 37 ERROR keystone.server.flask.application   File "/var/lib/kolla/venv/lib/python3.9/site-packages/flask_restful/__init__.py", line 582, in dispatch_request
2023-03-15 19:35:59.829 37 ERROR keystone.server.flask.application     resp = meth(*args, **kwargs)
2023-03-15 19:35:59.829 37 ERROR keystone.server.flask.application   File "/var/lib/kolla/venv/lib/python3.9/site-packages/keystone/api/roles.py", line 50, in get
2023-03-15 19:35:59.829 37 ERROR keystone.server.flask.application     return self._get_role(role_id)
2023-03-15 19:35:59.829 37 ERROR keystone.server.flask.application   File "/var/lib/kolla/venv/lib/python3.9/site-packages/keystone/api/roles.py", line 70, in _get_role
2023-03-15 19:35:59.829 37 ERROR keystone.server.flask.application     ENFORCER.enforce_call(action='identity:get_role')
2023-03-15 19:35:59.829 37 ERROR keystone.server.flask.application   File "/var/lib/kolla/venv/lib/python3.9/site-packages/keystone/common/rbac_enforcer/enforcer.py", line 402, in enforce_call
2023-03-15 19:35:59.829 37 ERROR keystone.server.flask.application     policy_dict.update(cls._extract_member_target_data(
2023-03-15 19:35:59.829 37 ERROR keystone.server.flask.application   File "/var/lib/kolla/venv/lib/python3.9/site-packages/keystone/common/rbac_enforcer/enforcer.py", line 234, in _extract_member_target_data
2023-03-15 19:35:59.829 37 ERROR keystone.server.flask.application     member_name: func(flask.request.view_args[key])
2023-03-15 19:35:59.829 37 ERROR keystone.server.flask.application   File "/var/lib/kolla/venv/lib/python3.9/site-packages/keystone/common/manager.py", line 115, in wrapped
2023-03-15 19:35:59.829 37 ERROR keystone.server.flask.application     __ret_val = __f(*args, **kwargs)
2023-03-15 19:35:59.829 37 ERROR keystone.server.flask.application   File "/var/lib/kolla/venv/lib/python3.9/site-packages/decorator.py", line 232, in fun
2023-03-15 19:35:59.829 37 ERROR keystone.server.flask.application     return caller(func, *(extras + args), **kw)
2023-03-15 19:35:59.829 37 ERROR keystone.server.flask.application   File "/var/lib/kolla/venv/lib/python3.9/site-packages/dogpile/cache/region.py", line 1577, in get_or_create_for_user_func
2023-03-15 19:35:59.829 37 ERROR keystone.server.flask.application     return self.get_or_create(
2023-03-15 19:35:59.829 37 ERROR keystone.server.flask.application   File "/var/lib/kolla/venv/lib/python3.9/site-packages/dogpile/cache/region.py", line 1042, in get_or_create
2023-03-15 19:35:59.829 37 ERROR keystone.server.flask.application     with Lock(
2023-03-15 19:35:59.829 37 ERROR keystone.server.flask.application   File "/var/lib/kolla/venv/lib/python3.9/site-packages/dogpile/lock.py", line 185, in __enter__
2023-03-15 19:35:59.829 37 ERROR keystone.server.flask.application     return self._enter()
2023-03-15 19:35:59.829 37 ERROR keystone.server.flask.application   File "/var/lib/kolla/venv/lib/python3.9/site-packages/dogpile/lock.py", line 94, in _enter
2023-03-15 19:35:59.829 37 ERROR keystone.server.flask.application     generated = self._enter_create(value, createdtime)
2023-03-15 19:35:59.829 37 ERROR keystone.server.flask.application   File "/var/lib/kolla/venv/lib/python3.9/site-packages/dogpile/lock.py", line 178, in _enter_create
2023-03-15 19:35:59.829 37 ERROR keystone.server.flask.application     return self.creator()
2023-03-15 19:35:59.829 37 ERROR keystone.server.flask.application   File "/var/lib/kolla/venv/lib/python3.9/site-packages/dogpile/cache/region.py", line 995, in gen_value
2023-03-15 19:35:59.829 37 ERROR keystone.server.flask.application     created_value = creator(
2023-03-15 19:35:59.829 37 ERROR keystone.server.flask.application   File "/var/lib/kolla/venv/lib/python3.9/site-packages/keystone/assignment/core.py", line 1276, in get_role
2023-03-15 19:35:59.829 37 ERROR keystone.server.flask.application     return self.driver.get_role(role_id)
2023-03-15 19:35:59.829 37 ERROR keystone.server.flask.application   File "/var/lib/kolla/venv/lib/python3.9/site-packages/keystone/assignment/role_backends/sql.py", line 70, in get_role
2023-03-15 19:35:59.829 37 ERROR keystone.server.flask.application     return self._get_role(session, role_id).to_dict()
2023-03-15 19:35:59.829 37 ERROR keystone.server.flask.application   File "/var/lib/kolla/venv/lib/python3.9/site-packages/keystone/assignment/role_backends/sql.py", line 65, in _get_role
2023-03-15 19:35:59.829 37 ERROR keystone.server.flask.application     raise exception.RoleNotFound(role_id=role_id)
2023-03-15 19:35:59.829 37 ERROR keystone.server.flask.application keystone.exception.RoleNotFound: Could not find role: admin.
2023-03-15 19:35:59.829 37 ERROR keystone.server.flask.application 
2023-03-15 19:36:01.255 38 ERROR keystone.server.flask.application [None req-ccb533e1-f48e-4fab-8e95-dcf660abad1c e67c66414fb4476e9016e0f5a05aeb1a - - all default -] Could not find user: neutron.: keystone.exception.UserNotFound: Could not find user: neutron.
2023-03-15 19:36:01.255 38 ERROR keystone.server.flask.application Traceback (most recent call last):
2023-03-15 19:36:01.255 38 ERROR keystone.server.flask.application   File "/var/lib/kolla/venv/lib/python3.9/site-packages/flask/app.py", line 1820, in full_dispatch_request
2023-03-15 19:36:01.255 38 ERROR keystone.server.flask.application     rv = self.dispatch_request()
2023-03-15 19:36:01.255 38 ERROR keystone.server.flask.application   File "/var/lib/kolla/venv/lib/python3.9/site-packages/flask/app.py", line 1796, in dispatch_request
2023-03-15 19:36:01.255 38 ERROR keystone.server.flask.application     return self.ensure_sync(self.view_functions[rule.endpoint])(**view_args)
2023-03-15 19:36:01.255 38 ERROR keystone.server.flask.application   File "/var/lib/kolla/venv/lib/python3.9/site-packages/flask_restful/__init__.py", line 467, in wrapper
2023-03-15 19:36:01.255 38 ERROR keystone.server.flask.application     resp = resource(*args, **kwargs)
2023-03-15 19:36:01.255 38 ERROR keystone.server.flask.application   File "/var/lib/kolla/venv/lib/python3.9/site-packages/flask/views.py", line 107, in view
2023-03-15 19:36:01.255 38 ERROR keystone.server.flask.application     return current_app.ensure_sync(self.dispatch_request)(**kwargs)
2023-03-15 19:36:01.255 38 ERROR keystone.server.flask.application   File "/var/lib/kolla/venv/lib/python3.9/site-packages/flask_restful/__init__.py", line 582, in dispatch_request
2023-03-15 19:36:01.255 38 ERROR keystone.server.flask.application     resp = meth(*args, **kwargs)
2023-03-15 19:36:01.255 38 ERROR keystone.server.flask.application   File "/var/lib/kolla/venv/lib/python3.9/site-packages/keystone/api/users.py", line 182, in get
2023-03-15 19:36:01.255 38 ERROR keystone.server.flask.application     return self._get_user(user_id)
2023-03-15 19:36:01.255 38 ERROR keystone.server.flask.application   File "/var/lib/kolla/venv/lib/python3.9/site-packages/keystone/api/users.py", line 194, in _get_user
2023-03-15 19:36:01.255 38 ERROR keystone.server.flask.application     ref = PROVIDERS.identity_api.get_user(user_id)
2023-03-15 19:36:01.255 38 ERROR keystone.server.flask.application   File "/var/lib/kolla/venv/lib/python3.9/site-packages/keystone/common/manager.py", line 115, in wrapped
2023-03-15 19:36:01.255 38 ERROR keystone.server.flask.application     __ret_val = __f(*args, **kwargs)
2023-03-15 19:36:01.255 38 ERROR keystone.server.flask.application   File "/var/lib/kolla/venv/lib/python3.9/site-packages/keystone/identity/core.py", line 414, in wrapper
2023-03-15 19:36:01.255 38 ERROR keystone.server.flask.application     return f(self, *args, **kwargs)
2023-03-15 19:36:01.255 38 ERROR keystone.server.flask.application   File "/var/lib/kolla/venv/lib/python3.9/site-packages/keystone/identity/core.py", line 424, in wrapper
2023-03-15 19:36:01.255 38 ERROR keystone.server.flask.application     return f(self, *args, **kwargs)
2023-03-15 19:36:01.255 38 ERROR keystone.server.flask.application   File "/var/lib/kolla/venv/lib/python3.9/site-packages/decorator.py", line 232, in fun
2023-03-15 19:36:01.255 38 ERROR keystone.server.flask.application     return caller(func, *(extras + args), **kw)
2023-03-15 19:36:01.255 38 ERROR keystone.server.flask.application   File "/var/lib/kolla/venv/lib/python3.9/site-packages/dogpile/cache/region.py", line 1577, in get_or_create_for_user_func
2023-03-15 19:36:01.255 38 ERROR keystone.server.flask.application     return self.get_or_create(
2023-03-15 19:36:01.255 38 ERROR keystone.server.flask.application   File "/var/lib/kolla/venv/lib/python3.9/site-packages/dogpile/cache/region.py", line 1042, in get_or_create
2023-03-15 19:36:01.255 38 ERROR keystone.server.flask.application     with Lock(
2023-03-15 19:36:01.255 38 ERROR keystone.server.flask.application   File "/var/lib/kolla/venv/lib/python3.9/site-packages/dogpile/lock.py", line 185, in __enter__
2023-03-15 19:36:01.255 38 ERROR keystone.server.flask.application     return self._enter()
2023-03-15 19:36:01.255 38 ERROR keystone.server.flask.application   File "/var/lib/kolla/venv/lib/python3.9/site-packages/dogpile/lock.py", line 94, in _enter
2023-03-15 19:36:01.255 38 ERROR keystone.server.flask.application     generated = self._enter_create(value, createdtime)
2023-03-15 19:36:01.255 38 ERROR keystone.server.flask.application   File "/var/lib/kolla/venv/lib/python3.9/site-packages/dogpile/lock.py", line 178, in _enter_create
2023-03-15 19:36:01.255 38 ERROR keystone.server.flask.application     return self.creator()
2023-03-15 19:36:01.255 38 ERROR keystone.server.flask.application   File "/var/lib/kolla/venv/lib/python3.9/site-packages/dogpile/cache/region.py", line 995, in gen_value
2023-03-15 19:36:01.255 38 ERROR keystone.server.flask.application     created_value = creator(
2023-03-15 19:36:01.255 38 ERROR keystone.server.flask.application   File "/var/lib/kolla/venv/lib/python3.9/site-packages/keystone/identity/core.py", line 1011, in get_user
2023-03-15 19:36:01.255 38 ERROR keystone.server.flask.application     ref = driver.get_user(entity_id)
2023-03-15 19:36:01.255 38 ERROR keystone.server.flask.application   File "/var/lib/kolla/venv/lib/python3.9/site-packages/keystone/identity/backends/sql.py", line 200, in get_user
2023-03-15 19:36:01.255 38 ERROR keystone.server.flask.application     self._get_user(session, user_id).to_dict())
2023-03-15 19:36:01.255 38 ERROR keystone.server.flask.application   File "/var/lib/kolla/venv/lib/python3.9/site-packages/keystone/identity/backends/sql.py", line 194, in _get_user
2023-03-15 19:36:01.255 38 ERROR keystone.server.flask.application     raise exception.UserNotFound(user_id=user_id)
2023-03-15 19:36:01.255 38 ERROR keystone.server.flask.application keystone.exception.UserNotFound: Could not find user: neutron.
2023-03-15 19:36:01.255 38 ERROR keystone.server.flask.application 
2023-03-15 19:36:02.303 39 ERROR keystone.server.flask.application [None req-f7363229-df94-4424-9e0e-13f00c027aa5 e67c66414fb4476e9016e0f5a05aeb1a - - all default -] Could not find project: service.: keystone.exception.ProjectNotFound: Could not find project: service.
2023-03-15 19:36:02.303 39 ERROR keystone.server.flask.application Traceback (most recent call last):
2023-03-15 19:36:02.303 39 ERROR keystone.server.flask.application   File "/var/lib/kolla/venv/lib/python3.9/site-packages/flask/app.py", line 1820, in full_dispatch_request
2023-03-15 19:36:02.303 39 ERROR keystone.server.flask.application     rv = self.dispatch_request()
2023-03-15 19:36:02.303 39 ERROR keystone.server.flask.application   File "/var/lib/kolla/venv/lib/python3.9/site-packages/flask/app.py", line 1796, in dispatch_request
2023-03-15 19:36:02.303 39 ERROR keystone.server.flask.application     return self.ensure_sync(self.view_functions[rule.endpoint])(**view_args)
2023-03-15 19:36:02.303 39 ERROR keystone.server.flask.application   File "/var/lib/kolla/venv/lib/python3.9/site-packages/flask_restful/__init__.py", line 467, in wrapper
2023-03-15 19:36:02.303 39 ERROR keystone.server.flask.application     resp = resource(*args, **kwargs)
2023-03-15 19:36:02.303 39 ERROR keystone.server.flask.application   File "/var/lib/kolla/venv/lib/python3.9/site-packages/flask/views.py", line 107, in view
2023-03-15 19:36:02.303 39 ERROR keystone.server.flask.application     return current_app.ensure_sync(self.dispatch_request)(**kwargs)
2023-03-15 19:36:02.303 39 ERROR keystone.server.flask.application   File "/var/lib/kolla/venv/lib/python3.9/site-packages/flask_restful/__init__.py", line 582, in dispatch_request
2023-03-15 19:36:02.303 39 ERROR keystone.server.flask.application     resp = meth(*args, **kwargs)
2023-03-15 19:36:02.303 39 ERROR keystone.server.flask.application   File "/var/lib/kolla/venv/lib/python3.9/site-packages/keystone/api/projects.py", line 151, in get
2023-03-15 19:36:02.303 39 ERROR keystone.server.flask.application     return self._get_project(project_id)
2023-03-15 19:36:02.303 39 ERROR keystone.server.flask.application   File "/var/lib/kolla/venv/lib/python3.9/site-packages/keystone/api/projects.py", line 107, in _get_project
2023-03-15 19:36:02.303 39 ERROR keystone.server.flask.application     project = PROVIDERS.resource_api.get_project(project_id)
2023-03-15 19:36:02.303 39 ERROR keystone.server.flask.application   File "/var/lib/kolla/venv/lib/python3.9/site-packages/keystone/common/manager.py", line 115, in wrapped
2023-03-15 19:36:02.303 39 ERROR keystone.server.flask.application     __ret_val = __f(*args, **kwargs)
2023-03-15 19:36:02.303 39 ERROR keystone.server.flask.application   File "/var/lib/kolla/venv/lib/python3.9/site-packages/decorator.py", line 232, in fun
2023-03-15 19:36:02.303 39 ERROR keystone.server.flask.application     return caller(func, *(extras + args), **kw)
2023-03-15 19:36:02.303 39 ERROR keystone.server.flask.application   File "/var/lib/kolla/venv/lib/python3.9/site-packages/dogpile/cache/region.py", line 1577, in get_or_create_for_user_func
2023-03-15 19:36:02.303 39 ERROR keystone.server.flask.application     return self.get_or_create(
2023-03-15 19:36:02.303 39 ERROR keystone.server.flask.application   File "/var/lib/kolla/venv/lib/python3.9/site-packages/dogpile/cache/region.py", line 1042, in get_or_create
2023-03-15 19:36:02.303 39 ERROR keystone.server.flask.application     with Lock(
2023-03-15 19:36:02.303 39 ERROR keystone.server.flask.application   File "/var/lib/kolla/venv/lib/python3.9/site-packages/dogpile/lock.py", line 185, in __enter__
2023-03-15 19:36:02.303 39 ERROR keystone.server.flask.application     return self._enter()
2023-03-15 19:36:02.303 39 ERROR keystone.server.flask.application   File "/var/lib/kolla/venv/lib/python3.9/site-packages/dogpile/lock.py", line 94, in _enter
2023-03-15 19:36:02.303 39 ERROR keystone.server.flask.application     generated = self._enter_create(value, createdtime)
2023-03-15 19:36:02.303 39 ERROR keystone.server.flask.application   File "/var/lib/kolla/venv/lib/python3.9/site-packages/dogpile/lock.py", line 178, in _enter_create
2023-03-15 19:36:02.303 39 ERROR keystone.server.flask.application     return self.creator()
2023-03-15 19:36:02.303 39 ERROR keystone.server.flask.application   File "/var/lib/kolla/venv/lib/python3.9/site-packages/dogpile/cache/region.py", line 995, in gen_value
2023-03-15 19:36:02.303 39 ERROR keystone.server.flask.application     created_value = creator(
2023-03-15 19:36:02.303 39 ERROR keystone.server.flask.application   File "/var/lib/kolla/venv/lib/python3.9/site-packages/keystone/resource/core.py", line 903, in get_project
2023-03-15 19:36:02.303 39 ERROR keystone.server.flask.application     return self.driver.get_project(project_id)
2023-03-15 19:36:02.303 39 ERROR keystone.server.flask.application   File "/var/lib/kolla/venv/lib/python3.9/site-packages/keystone/resource/backends/sql.py", line 49, in get_project
2023-03-15 19:36:02.303 39 ERROR keystone.server.flask.application     return self._get_project(session, project_id).to_dict()
2023-03-15 19:36:02.303 39 ERROR keystone.server.flask.application   File "/var/lib/kolla/venv/lib/python3.9/site-packages/keystone/resource/backends/sql.py", line 44, in _get_project
2023-03-15 19:36:02.303 39 ERROR keystone.server.flask.application     raise exception.ProjectNotFound(project_id=project_id)
2023-03-15 19:36:02.303 39 ERROR keystone.server.flask.application keystone.exception.ProjectNotFound: Could not find project: service.
2023-03-15 19:36:02.303 39 ERROR keystone.server.flask.application 
