2023-03-15 20:54:21.242 23 INFO alembic.runtime.migration [-] Context impl MySQLImpl.
2023-03-15 20:54:21.244 23 INFO alembic.runtime.migration [-] Will assume non-transactional DDL.
2023-03-15 20:54:21.282 23 INFO alembic.runtime.migration [-] Context impl MySQLImpl.
2023-03-15 20:54:21.283 23 INFO alembic.runtime.migration [-] Will assume non-transactional DDL.
2023-03-15 20:54:21.329 23 INFO alembic.runtime.migration [-] Running upgrade  -> 27e647c0fad4, Initial version.
2023-03-15 20:54:22.848 23 INFO alembic.runtime.migration [-] Running upgrade 27e647c0fad4 -> e25ffa003242, Initial no-op Yoga contract migration.
2023-03-15 20:54:22.860 23 INFO alembic.runtime.migration [-] Running upgrade 27e647c0fad4 -> 29e87d24a316, Initial no-op Yoga expand migration.
2023-03-15 20:54:31.598 7 INFO keystone.common.fernet_utils [-] Created a new temporary key: /etc/keystone/fernet-keys/0.tmp
2023-03-15 20:54:31.603 7 INFO keystone.common.fernet_utils [-] Become a valid new key: /etc/keystone/fernet-keys/0
2023-03-15 20:54:31.604 7 INFO keystone.common.fernet_utils [-] Starting key rotation with 1 key files: ['/etc/keystone/fernet-keys/0']
2023-03-15 20:54:31.605 7 INFO keystone.common.fernet_utils [-] Created a new temporary key: /etc/keystone/fernet-keys/0.tmp
2023-03-15 20:54:31.605 7 INFO keystone.common.fernet_utils [-] Current primary key is: 0
2023-03-15 20:54:31.606 7 INFO keystone.common.fernet_utils [-] Next primary key will be: 1
2023-03-15 20:54:31.607 7 INFO keystone.common.fernet_utils [-] Promoted key 0 to be the primary: 1
2023-03-15 20:54:31.607 7 INFO keystone.common.fernet_utils [-] Become a valid new key: /etc/keystone/fernet-keys/0
2023-03-15 20:54:51.559 32 INFO keystone.cmd.bootstrap [None req-53917226-66f6-4bbb-b996-075b68b947c9 - - - - - -] Created domain default
2023-03-15 20:54:51.656 32 INFO keystone.cmd.bootstrap [None req-53917226-66f6-4bbb-b996-075b68b947c9 - - - - - -] Created project admin
2023-03-15 20:54:52.454 32 INFO keystone.cmd.bootstrap [None req-53917226-66f6-4bbb-b996-075b68b947c9 - - - - - -] Created user admin
2023-03-15 20:54:52.497 32 INFO keystone.cmd.bootstrap [None req-53917226-66f6-4bbb-b996-075b68b947c9 - - - - - -] Created role reader
2023-03-15 20:54:52.524 32 INFO keystone.cmd.bootstrap [None req-53917226-66f6-4bbb-b996-075b68b947c9 - - - - - -] Created role member
2023-03-15 20:54:52.586 32 INFO keystone.cmd.bootstrap [None req-53917226-66f6-4bbb-b996-075b68b947c9 - - - - - -] Created implied role where b3a6ced392fe4727a5f07ed06193a4ca implies 0fe777b274c14b10af38815beb5ac511
2023-03-15 20:54:52.614 32 INFO keystone.cmd.bootstrap [None req-53917226-66f6-4bbb-b996-075b68b947c9 - - - - - -] Created role admin
2023-03-15 20:54:52.659 32 INFO keystone.cmd.bootstrap [None req-53917226-66f6-4bbb-b996-075b68b947c9 - - - - - -] Created implied role where 0a4328efd7994ecdada2b10810520b8b implies b3a6ced392fe4727a5f07ed06193a4ca
2023-03-15 20:54:52.689 32 INFO keystone.cmd.bootstrap [None req-53917226-66f6-4bbb-b996-075b68b947c9 - - - - - -] Granted role admin on project admin to user admin.
2023-03-15 20:54:52.704 32 INFO keystone.cmd.bootstrap [None req-53917226-66f6-4bbb-b996-075b68b947c9 - - - - - -] Granted role admin on the system to user admin.
2023-03-15 20:54:52.731 32 WARNING py.warnings [None req-53917226-66f6-4bbb-b996-075b68b947c9 - - - - - -] /var/lib/kolla/venv/lib/python3.9/site-packages/pycadf/identifier.py:71: UserWarning: Invalid uuid: RegionOne. To ensure interoperability, identifiers should be a valid uuid.
  warnings.warn(('Invalid uuid: %s. To ensure interoperability, '

2023-03-15 20:54:52.743 32 INFO keystone.cmd.bootstrap [None req-53917226-66f6-4bbb-b996-075b68b947c9 - - - - - -] Created region RegionOne
2023-03-15 20:54:52.802 32 INFO keystone.cmd.bootstrap [None req-53917226-66f6-4bbb-b996-075b68b947c9 - - - - - -] Created public endpoint http://169.16.1.146:5000
2023-03-15 20:54:52.818 32 INFO keystone.cmd.bootstrap [None req-53917226-66f6-4bbb-b996-075b68b947c9 - - - - - -] Created internal endpoint http://169.16.1.146:5000
2023-03-15 20:55:19.751 39 WARNING keystone.common.rbac_enforcer.enforcer [None req-bbf38911-841c-41e4-9f35-4c14a208dc83 85b537ff22d246d29b67535eecf74526 - - all default -] Deprecated policy rules found. Use oslopolicy-policy-generator and oslopolicy-policy-upgrade to detect and resolve deprecated policies in your configuration.
2023-03-15 20:55:20.726 38 WARNING keystone.common.rbac_enforcer.enforcer [None req-0770571b-0ce6-4a57-8e4e-7680d492b3e5 85b537ff22d246d29b67535eecf74526 - - all default -] Deprecated policy rules found. Use oslopolicy-policy-generator and oslopolicy-policy-upgrade to detect and resolve deprecated policies in your configuration.
2023-03-15 20:55:29.006 37 WARNING keystone.common.rbac_enforcer.enforcer [None req-380df00c-eb7e-43e6-865a-49eff3939d29 85b537ff22d246d29b67535eecf74526 - - all default -] Deprecated policy rules found. Use oslopolicy-policy-generator and oslopolicy-policy-upgrade to detect and resolve deprecated policies in your configuration.
2023-03-15 20:56:49.656 39 ERROR keystone.server.flask.application [None req-2109a2d4-7fcf-47c1-823e-46754325bdea 85b537ff22d246d29b67535eecf74526 - - all default -] Could not find project: service.: keystone.exception.ProjectNotFound: Could not find project: service.
2023-03-15 20:56:49.656 39 ERROR keystone.server.flask.application Traceback (most recent call last):
2023-03-15 20:56:49.656 39 ERROR keystone.server.flask.application   File "/var/lib/kolla/venv/lib/python3.9/site-packages/flask/app.py", line 1820, in full_dispatch_request
2023-03-15 20:56:49.656 39 ERROR keystone.server.flask.application     rv = self.dispatch_request()
2023-03-15 20:56:49.656 39 ERROR keystone.server.flask.application   File "/var/lib/kolla/venv/lib/python3.9/site-packages/flask/app.py", line 1796, in dispatch_request
2023-03-15 20:56:49.656 39 ERROR keystone.server.flask.application     return self.ensure_sync(self.view_functions[rule.endpoint])(**view_args)
2023-03-15 20:56:49.656 39 ERROR keystone.server.flask.application   File "/var/lib/kolla/venv/lib/python3.9/site-packages/flask_restful/__init__.py", line 467, in wrapper
2023-03-15 20:56:49.656 39 ERROR keystone.server.flask.application     resp = resource(*args, **kwargs)
2023-03-15 20:56:49.656 39 ERROR keystone.server.flask.application   File "/var/lib/kolla/venv/lib/python3.9/site-packages/flask/views.py", line 107, in view
2023-03-15 20:56:49.656 39 ERROR keystone.server.flask.application     return current_app.ensure_sync(self.dispatch_request)(**kwargs)
2023-03-15 20:56:49.656 39 ERROR keystone.server.flask.application   File "/var/lib/kolla/venv/lib/python3.9/site-packages/flask_restful/__init__.py", line 582, in dispatch_request
2023-03-15 20:56:49.656 39 ERROR keystone.server.flask.application     resp = meth(*args, **kwargs)
2023-03-15 20:56:49.656 39 ERROR keystone.server.flask.application   File "/var/lib/kolla/venv/lib/python3.9/site-packages/keystone/api/projects.py", line 151, in get
2023-03-15 20:56:49.656 39 ERROR keystone.server.flask.application     return self._get_project(project_id)
2023-03-15 20:56:49.656 39 ERROR keystone.server.flask.application   File "/var/lib/kolla/venv/lib/python3.9/site-packages/keystone/api/projects.py", line 107, in _get_project
2023-03-15 20:56:49.656 39 ERROR keystone.server.flask.application     project = PROVIDERS.resource_api.get_project(project_id)
2023-03-15 20:56:49.656 39 ERROR keystone.server.flask.application   File "/var/lib/kolla/venv/lib/python3.9/site-packages/keystone/common/manager.py", line 115, in wrapped
2023-03-15 20:56:49.656 39 ERROR keystone.server.flask.application     __ret_val = __f(*args, **kwargs)
2023-03-15 20:56:49.656 39 ERROR keystone.server.flask.application   File "/var/lib/kolla/venv/lib/python3.9/site-packages/decorator.py", line 232, in fun
2023-03-15 20:56:49.656 39 ERROR keystone.server.flask.application     return caller(func, *(extras + args), **kw)
2023-03-15 20:56:49.656 39 ERROR keystone.server.flask.application   File "/var/lib/kolla/venv/lib/python3.9/site-packages/dogpile/cache/region.py", line 1577, in get_or_create_for_user_func
2023-03-15 20:56:49.656 39 ERROR keystone.server.flask.application     return self.get_or_create(
2023-03-15 20:56:49.656 39 ERROR keystone.server.flask.application   File "/var/lib/kolla/venv/lib/python3.9/site-packages/dogpile/cache/region.py", line 1042, in get_or_create
2023-03-15 20:56:49.656 39 ERROR keystone.server.flask.application     with Lock(
2023-03-15 20:56:49.656 39 ERROR keystone.server.flask.application   File "/var/lib/kolla/venv/lib/python3.9/site-packages/dogpile/lock.py", line 185, in __enter__
2023-03-15 20:56:49.656 39 ERROR keystone.server.flask.application     return self._enter()
2023-03-15 20:56:49.656 39 ERROR keystone.server.flask.application   File "/var/lib/kolla/venv/lib/python3.9/site-packages/dogpile/lock.py", line 94, in _enter
2023-03-15 20:56:49.656 39 ERROR keystone.server.flask.application     generated = self._enter_create(value, createdtime)
2023-03-15 20:56:49.656 39 ERROR keystone.server.flask.application   File "/var/lib/kolla/venv/lib/python3.9/site-packages/dogpile/lock.py", line 178, in _enter_create
2023-03-15 20:56:49.656 39 ERROR keystone.server.flask.application     return self.creator()
2023-03-15 20:56:49.656 39 ERROR keystone.server.flask.application   File "/var/lib/kolla/venv/lib/python3.9/site-packages/dogpile/cache/region.py", line 995, in gen_value
2023-03-15 20:56:49.656 39 ERROR keystone.server.flask.application     created_value = creator(
2023-03-15 20:56:49.656 39 ERROR keystone.server.flask.application   File "/var/lib/kolla/venv/lib/python3.9/site-packages/keystone/resource/core.py", line 903, in get_project
2023-03-15 20:56:49.656 39 ERROR keystone.server.flask.application     return self.driver.get_project(project_id)
2023-03-15 20:56:49.656 39 ERROR keystone.server.flask.application   File "/var/lib/kolla/venv/lib/python3.9/site-packages/keystone/resource/backends/sql.py", line 49, in get_project
2023-03-15 20:56:49.656 39 ERROR keystone.server.flask.application     return self._get_project(session, project_id).to_dict()
2023-03-15 20:56:49.656 39 ERROR keystone.server.flask.application   File "/var/lib/kolla/venv/lib/python3.9/site-packages/keystone/resource/backends/sql.py", line 44, in _get_project
2023-03-15 20:56:49.656 39 ERROR keystone.server.flask.application     raise exception.ProjectNotFound(project_id=project_id)
2023-03-15 20:56:49.656 39 ERROR keystone.server.flask.application keystone.exception.ProjectNotFound: Could not find project: service.
2023-03-15 20:56:49.656 39 ERROR keystone.server.flask.application 
2023-03-15 20:56:58.686 37 ERROR keystone.server.flask.application [None req-a5be3f79-9ce0-4792-b6cc-2ed09aac0380 85b537ff22d246d29b67535eecf74526 - - all default -] Could not find project: service.: keystone.exception.ProjectNotFound: Could not find project: service.
2023-03-15 20:56:58.686 37 ERROR keystone.server.flask.application Traceback (most recent call last):
2023-03-15 20:56:58.686 37 ERROR keystone.server.flask.application   File "/var/lib/kolla/venv/lib/python3.9/site-packages/flask/app.py", line 1820, in full_dispatch_request
2023-03-15 20:56:58.686 37 ERROR keystone.server.flask.application     rv = self.dispatch_request()
2023-03-15 20:56:58.686 37 ERROR keystone.server.flask.application   File "/var/lib/kolla/venv/lib/python3.9/site-packages/flask/app.py", line 1796, in dispatch_request
2023-03-15 20:56:58.686 37 ERROR keystone.server.flask.application     return self.ensure_sync(self.view_functions[rule.endpoint])(**view_args)
2023-03-15 20:56:58.686 37 ERROR keystone.server.flask.application   File "/var/lib/kolla/venv/lib/python3.9/site-packages/flask_restful/__init__.py", line 467, in wrapper
2023-03-15 20:56:58.686 37 ERROR keystone.server.flask.application     resp = resource(*args, **kwargs)
2023-03-15 20:56:58.686 37 ERROR keystone.server.flask.application   File "/var/lib/kolla/venv/lib/python3.9/site-packages/flask/views.py", line 107, in view
2023-03-15 20:56:58.686 37 ERROR keystone.server.flask.application     return current_app.ensure_sync(self.dispatch_request)(**kwargs)
2023-03-15 20:56:58.686 37 ERROR keystone.server.flask.application   File "/var/lib/kolla/venv/lib/python3.9/site-packages/flask_restful/__init__.py", line 582, in dispatch_request
2023-03-15 20:56:58.686 37 ERROR keystone.server.flask.application     resp = meth(*args, **kwargs)
2023-03-15 20:56:58.686 37 ERROR keystone.server.flask.application   File "/var/lib/kolla/venv/lib/python3.9/site-packages/keystone/api/projects.py", line 151, in get
2023-03-15 20:56:58.686 37 ERROR keystone.server.flask.application     return self._get_project(project_id)
2023-03-15 20:56:58.686 37 ERROR keystone.server.flask.application   File "/var/lib/kolla/venv/lib/python3.9/site-packages/keystone/api/projects.py", line 107, in _get_project
2023-03-15 20:56:58.686 37 ERROR keystone.server.flask.application     project = PROVIDERS.resource_api.get_project(project_id)
2023-03-15 20:56:58.686 37 ERROR keystone.server.flask.application   File "/var/lib/kolla/venv/lib/python3.9/site-packages/keystone/common/manager.py", line 115, in wrapped
2023-03-15 20:56:58.686 37 ERROR keystone.server.flask.application     __ret_val = __f(*args, **kwargs)
2023-03-15 20:56:58.686 37 ERROR keystone.server.flask.application   File "/var/lib/kolla/venv/lib/python3.9/site-packages/decorator.py", line 232, in fun
2023-03-15 20:56:58.686 37 ERROR keystone.server.flask.application     return caller(func, *(extras + args), **kw)
2023-03-15 20:56:58.686 37 ERROR keystone.server.flask.application   File "/var/lib/kolla/venv/lib/python3.9/site-packages/dogpile/cache/region.py", line 1577, in get_or_create_for_user_func
2023-03-15 20:56:58.686 37 ERROR keystone.server.flask.application     return self.get_or_create(
2023-03-15 20:56:58.686 37 ERROR keystone.server.flask.application   File "/var/lib/kolla/venv/lib/python3.9/site-packages/dogpile/cache/region.py", line 1042, in get_or_create
2023-03-15 20:56:58.686 37 ERROR keystone.server.flask.application     with Lock(
2023-03-15 20:56:58.686 37 ERROR keystone.server.flask.application   File "/var/lib/kolla/venv/lib/python3.9/site-packages/dogpile/lock.py", line 185, in __enter__
2023-03-15 20:56:58.686 37 ERROR keystone.server.flask.application     return self._enter()
2023-03-15 20:56:58.686 37 ERROR keystone.server.flask.application   File "/var/lib/kolla/venv/lib/python3.9/site-packages/dogpile/lock.py", line 94, in _enter
2023-03-15 20:56:58.686 37 ERROR keystone.server.flask.application     generated = self._enter_create(value, createdtime)
2023-03-15 20:56:58.686 37 ERROR keystone.server.flask.application   File "/var/lib/kolla/venv/lib/python3.9/site-packages/dogpile/lock.py", line 178, in _enter_create
2023-03-15 20:56:58.686 37 ERROR keystone.server.flask.application     return self.creator()
2023-03-15 20:56:58.686 37 ERROR keystone.server.flask.application   File "/var/lib/kolla/venv/lib/python3.9/site-packages/dogpile/cache/region.py", line 995, in gen_value
2023-03-15 20:56:58.686 37 ERROR keystone.server.flask.application     created_value = creator(
2023-03-15 20:56:58.686 37 ERROR keystone.server.flask.application   File "/var/lib/kolla/venv/lib/python3.9/site-packages/keystone/resource/core.py", line 903, in get_project
2023-03-15 20:56:58.686 37 ERROR keystone.server.flask.application     return self.driver.get_project(project_id)
2023-03-15 20:56:58.686 37 ERROR keystone.server.flask.application   File "/var/lib/kolla/venv/lib/python3.9/site-packages/keystone/resource/backends/sql.py", line 49, in get_project
2023-03-15 20:56:58.686 37 ERROR keystone.server.flask.application     return self._get_project(session, project_id).to_dict()
2023-03-15 20:56:58.686 37 ERROR keystone.server.flask.application   File "/var/lib/kolla/venv/lib/python3.9/site-packages/keystone/resource/backends/sql.py", line 44, in _get_project
2023-03-15 20:56:58.686 37 ERROR keystone.server.flask.application     raise exception.ProjectNotFound(project_id=project_id)
2023-03-15 20:56:58.686 37 ERROR keystone.server.flask.application keystone.exception.ProjectNotFound: Could not find project: service.
2023-03-15 20:56:58.686 37 ERROR keystone.server.flask.application 
2023-03-15 20:57:14.910 37 ERROR keystone.server.flask.application [None req-cd6d93f7-faf1-4215-800d-bb950728f306 85b537ff22d246d29b67535eecf74526 - - all default -] Could not find role: admin.: keystone.exception.RoleNotFound: Could not find role: admin.
2023-03-15 20:57:14.910 37 ERROR keystone.server.flask.application Traceback (most recent call last):
2023-03-15 20:57:14.910 37 ERROR keystone.server.flask.application   File "/var/lib/kolla/venv/lib/python3.9/site-packages/flask/app.py", line 1820, in full_dispatch_request
2023-03-15 20:57:14.910 37 ERROR keystone.server.flask.application     rv = self.dispatch_request()
2023-03-15 20:57:14.910 37 ERROR keystone.server.flask.application   File "/var/lib/kolla/venv/lib/python3.9/site-packages/flask/app.py", line 1796, in dispatch_request
2023-03-15 20:57:14.910 37 ERROR keystone.server.flask.application     return self.ensure_sync(self.view_functions[rule.endpoint])(**view_args)
2023-03-15 20:57:14.910 37 ERROR keystone.server.flask.application   File "/var/lib/kolla/venv/lib/python3.9/site-packages/flask_restful/__init__.py", line 467, in wrapper
2023-03-15 20:57:14.910 37 ERROR keystone.server.flask.application     resp = resource(*args, **kwargs)
2023-03-15 20:57:14.910 37 ERROR keystone.server.flask.application   File "/var/lib/kolla/venv/lib/python3.9/site-packages/flask/views.py", line 107, in view
2023-03-15 20:57:14.910 37 ERROR keystone.server.flask.application     return current_app.ensure_sync(self.dispatch_request)(**kwargs)
2023-03-15 20:57:14.910 37 ERROR keystone.server.flask.application   File "/var/lib/kolla/venv/lib/python3.9/site-packages/flask_restful/__init__.py", line 582, in dispatch_request
2023-03-15 20:57:14.910 37 ERROR keystone.server.flask.application     resp = meth(*args, **kwargs)
2023-03-15 20:57:14.910 37 ERROR keystone.server.flask.application   File "/var/lib/kolla/venv/lib/python3.9/site-packages/keystone/api/roles.py", line 50, in get
2023-03-15 20:57:14.910 37 ERROR keystone.server.flask.application     return self._get_role(role_id)
2023-03-15 20:57:14.910 37 ERROR keystone.server.flask.application   File "/var/lib/kolla/venv/lib/python3.9/site-packages/keystone/api/roles.py", line 70, in _get_role
2023-03-15 20:57:14.910 37 ERROR keystone.server.flask.application     ENFORCER.enforce_call(action='identity:get_role')
2023-03-15 20:57:14.910 37 ERROR keystone.server.flask.application   File "/var/lib/kolla/venv/lib/python3.9/site-packages/keystone/common/rbac_enforcer/enforcer.py", line 402, in enforce_call
2023-03-15 20:57:14.910 37 ERROR keystone.server.flask.application     policy_dict.update(cls._extract_member_target_data(
2023-03-15 20:57:14.910 37 ERROR keystone.server.flask.application   File "/var/lib/kolla/venv/lib/python3.9/site-packages/keystone/common/rbac_enforcer/enforcer.py", line 234, in _extract_member_target_data
2023-03-15 20:57:14.910 37 ERROR keystone.server.flask.application     member_name: func(flask.request.view_args[key])
2023-03-15 20:57:14.910 37 ERROR keystone.server.flask.application   File "/var/lib/kolla/venv/lib/python3.9/site-packages/keystone/common/manager.py", line 115, in wrapped
2023-03-15 20:57:14.910 37 ERROR keystone.server.flask.application     __ret_val = __f(*args, **kwargs)
2023-03-15 20:57:14.910 37 ERROR keystone.server.flask.application   File "/var/lib/kolla/venv/lib/python3.9/site-packages/decorator.py", line 232, in fun
2023-03-15 20:57:14.910 37 ERROR keystone.server.flask.application     return caller(func, *(extras + args), **kw)
2023-03-15 20:57:14.910 37 ERROR keystone.server.flask.application   File "/var/lib/kolla/venv/lib/python3.9/site-packages/dogpile/cache/region.py", line 1577, in get_or_create_for_user_func
2023-03-15 20:57:14.910 37 ERROR keystone.server.flask.application     return self.get_or_create(
2023-03-15 20:57:14.910 37 ERROR keystone.server.flask.application   File "/var/lib/kolla/venv/lib/python3.9/site-packages/dogpile/cache/region.py", line 1042, in get_or_create
2023-03-15 20:57:14.910 37 ERROR keystone.server.flask.application     with Lock(
2023-03-15 20:57:14.910 37 ERROR keystone.server.flask.application   File "/var/lib/kolla/venv/lib/python3.9/site-packages/dogpile/lock.py", line 185, in __enter__
2023-03-15 20:57:14.910 37 ERROR keystone.server.flask.application     return self._enter()
2023-03-15 20:57:14.910 37 ERROR keystone.server.flask.application   File "/var/lib/kolla/venv/lib/python3.9/site-packages/dogpile/lock.py", line 94, in _enter
2023-03-15 20:57:14.910 37 ERROR keystone.server.flask.application     generated = self._enter_create(value, createdtime)
2023-03-15 20:57:14.910 37 ERROR keystone.server.flask.application   File "/var/lib/kolla/venv/lib/python3.9/site-packages/dogpile/lock.py", line 178, in _enter_create
2023-03-15 20:57:14.910 37 ERROR keystone.server.flask.application     return self.creator()
2023-03-15 20:57:14.910 37 ERROR keystone.server.flask.application   File "/var/lib/kolla/venv/lib/python3.9/site-packages/dogpile/cache/region.py", line 995, in gen_value
2023-03-15 20:57:14.910 37 ERROR keystone.server.flask.application     created_value = creator(
2023-03-15 20:57:14.910 37 ERROR keystone.server.flask.application   File "/var/lib/kolla/venv/lib/python3.9/site-packages/keystone/assignment/core.py", line 1276, in get_role
2023-03-15 20:57:14.910 37 ERROR keystone.server.flask.application     return self.driver.get_role(role_id)
2023-03-15 20:57:14.910 37 ERROR keystone.server.flask.application   File "/var/lib/kolla/venv/lib/python3.9/site-packages/keystone/assignment/role_backends/sql.py", line 70, in get_role
2023-03-15 20:57:14.910 37 ERROR keystone.server.flask.application     return self._get_role(session, role_id).to_dict()
2023-03-15 20:57:14.910 37 ERROR keystone.server.flask.application   File "/var/lib/kolla/venv/lib/python3.9/site-packages/keystone/assignment/role_backends/sql.py", line 65, in _get_role
2023-03-15 20:57:14.910 37 ERROR keystone.server.flask.application     raise exception.RoleNotFound(role_id=role_id)
2023-03-15 20:57:14.910 37 ERROR keystone.server.flask.application keystone.exception.RoleNotFound: Could not find role: admin.
2023-03-15 20:57:14.910 37 ERROR keystone.server.flask.application 
2023-03-15 20:57:16.345 37 ERROR keystone.server.flask.application [None req-eefec697-d925-4d1b-8816-05d9b89352a8 85b537ff22d246d29b67535eecf74526 - - all default -] Could not find user: ironic.: keystone.exception.UserNotFound: Could not find user: ironic.
2023-03-15 20:57:16.345 37 ERROR keystone.server.flask.application Traceback (most recent call last):
2023-03-15 20:57:16.345 37 ERROR keystone.server.flask.application   File "/var/lib/kolla/venv/lib/python3.9/site-packages/flask/app.py", line 1820, in full_dispatch_request
2023-03-15 20:57:16.345 37 ERROR keystone.server.flask.application     rv = self.dispatch_request()
2023-03-15 20:57:16.345 37 ERROR keystone.server.flask.application   File "/var/lib/kolla/venv/lib/python3.9/site-packages/flask/app.py", line 1796, in dispatch_request
2023-03-15 20:57:16.345 37 ERROR keystone.server.flask.application     return self.ensure_sync(self.view_functions[rule.endpoint])(**view_args)
2023-03-15 20:57:16.345 37 ERROR keystone.server.flask.application   File "/var/lib/kolla/venv/lib/python3.9/site-packages/flask_restful/__init__.py", line 467, in wrapper
2023-03-15 20:57:16.345 37 ERROR keystone.server.flask.application     resp = resource(*args, **kwargs)
2023-03-15 20:57:16.345 37 ERROR keystone.server.flask.application   File "/var/lib/kolla/venv/lib/python3.9/site-packages/flask/views.py", line 107, in view
2023-03-15 20:57:16.345 37 ERROR keystone.server.flask.application     return current_app.ensure_sync(self.dispatch_request)(**kwargs)
2023-03-15 20:57:16.345 37 ERROR keystone.server.flask.application   File "/var/lib/kolla/venv/lib/python3.9/site-packages/flask_restful/__init__.py", line 582, in dispatch_request
2023-03-15 20:57:16.345 37 ERROR keystone.server.flask.application     resp = meth(*args, **kwargs)
2023-03-15 20:57:16.345 37 ERROR keystone.server.flask.application   File "/var/lib/kolla/venv/lib/python3.9/site-packages/keystone/api/users.py", line 182, in get
2023-03-15 20:57:16.345 37 ERROR keystone.server.flask.application     return self._get_user(user_id)
2023-03-15 20:57:16.345 37 ERROR keystone.server.flask.application   File "/var/lib/kolla/venv/lib/python3.9/site-packages/keystone/api/users.py", line 194, in _get_user
2023-03-15 20:57:16.345 37 ERROR keystone.server.flask.application     ref = PROVIDERS.identity_api.get_user(user_id)
2023-03-15 20:57:16.345 37 ERROR keystone.server.flask.application   File "/var/lib/kolla/venv/lib/python3.9/site-packages/keystone/common/manager.py", line 115, in wrapped
2023-03-15 20:57:16.345 37 ERROR keystone.server.flask.application     __ret_val = __f(*args, **kwargs)
2023-03-15 20:57:16.345 37 ERROR keystone.server.flask.application   File "/var/lib/kolla/venv/lib/python3.9/site-packages/keystone/identity/core.py", line 414, in wrapper
2023-03-15 20:57:16.345 37 ERROR keystone.server.flask.application     return f(self, *args, **kwargs)
2023-03-15 20:57:16.345 37 ERROR keystone.server.flask.application   File "/var/lib/kolla/venv/lib/python3.9/site-packages/keystone/identity/core.py", line 424, in wrapper
2023-03-15 20:57:16.345 37 ERROR keystone.server.flask.application     return f(self, *args, **kwargs)
2023-03-15 20:57:16.345 37 ERROR keystone.server.flask.application   File "/var/lib/kolla/venv/lib/python3.9/site-packages/decorator.py", line 232, in fun
2023-03-15 20:57:16.345 37 ERROR keystone.server.flask.application     return caller(func, *(extras + args), **kw)
2023-03-15 20:57:16.345 37 ERROR keystone.server.flask.application   File "/var/lib/kolla/venv/lib/python3.9/site-packages/dogpile/cache/region.py", line 1577, in get_or_create_for_user_func
2023-03-15 20:57:16.345 37 ERROR keystone.server.flask.application     return self.get_or_create(
2023-03-15 20:57:16.345 37 ERROR keystone.server.flask.application   File "/var/lib/kolla/venv/lib/python3.9/site-packages/dogpile/cache/region.py", line 1042, in get_or_create
2023-03-15 20:57:16.345 37 ERROR keystone.server.flask.application     with Lock(
2023-03-15 20:57:16.345 37 ERROR keystone.server.flask.application   File "/var/lib/kolla/venv/lib/python3.9/site-packages/dogpile/lock.py", line 185, in __enter__
2023-03-15 20:57:16.345 37 ERROR keystone.server.flask.application     return self._enter()
2023-03-15 20:57:16.345 37 ERROR keystone.server.flask.application   File "/var/lib/kolla/venv/lib/python3.9/site-packages/dogpile/lock.py", line 94, in _enter
2023-03-15 20:57:16.345 37 ERROR keystone.server.flask.application     generated = self._enter_create(value, createdtime)
2023-03-15 20:57:16.345 37 ERROR keystone.server.flask.application   File "/var/lib/kolla/venv/lib/python3.9/site-packages/dogpile/lock.py", line 178, in _enter_create
2023-03-15 20:57:16.345 37 ERROR keystone.server.flask.application     return self.creator()
2023-03-15 20:57:16.345 37 ERROR keystone.server.flask.application   File "/var/lib/kolla/venv/lib/python3.9/site-packages/dogpile/cache/region.py", line 995, in gen_value
2023-03-15 20:57:16.345 37 ERROR keystone.server.flask.application     created_value = creator(
2023-03-15 20:57:16.345 37 ERROR keystone.server.flask.application   File "/var/lib/kolla/venv/lib/python3.9/site-packages/keystone/identity/core.py", line 1011, in get_user
2023-03-15 20:57:16.345 37 ERROR keystone.server.flask.application     ref = driver.get_user(entity_id)
2023-03-15 20:57:16.345 37 ERROR keystone.server.flask.application   File "/var/lib/kolla/venv/lib/python3.9/site-packages/keystone/identity/backends/sql.py", line 200, in get_user
2023-03-15 20:57:16.345 37 ERROR keystone.server.flask.application     self._get_user(session, user_id).to_dict())
2023-03-15 20:57:16.345 37 ERROR keystone.server.flask.application   File "/var/lib/kolla/venv/lib/python3.9/site-packages/keystone/identity/backends/sql.py", line 194, in _get_user
2023-03-15 20:57:16.345 37 ERROR keystone.server.flask.application     raise exception.UserNotFound(user_id=user_id)
2023-03-15 20:57:16.345 37 ERROR keystone.server.flask.application keystone.exception.UserNotFound: Could not find user: ironic.
2023-03-15 20:57:16.345 37 ERROR keystone.server.flask.application 
2023-03-15 20:57:17.234 38 ERROR keystone.server.flask.application [None req-487eb4c0-084c-4e66-a266-4a1eb1d4e02b 85b537ff22d246d29b67535eecf74526 - - all default -] Could not find project: service.: keystone.exception.ProjectNotFound: Could not find project: service.
2023-03-15 20:57:17.234 38 ERROR keystone.server.flask.application Traceback (most recent call last):
2023-03-15 20:57:17.234 38 ERROR keystone.server.flask.application   File "/var/lib/kolla/venv/lib/python3.9/site-packages/flask/app.py", line 1820, in full_dispatch_request
2023-03-15 20:57:17.234 38 ERROR keystone.server.flask.application     rv = self.dispatch_request()
2023-03-15 20:57:17.234 38 ERROR keystone.server.flask.application   File "/var/lib/kolla/venv/lib/python3.9/site-packages/flask/app.py", line 1796, in dispatch_request
2023-03-15 20:57:17.234 38 ERROR keystone.server.flask.application     return self.ensure_sync(self.view_functions[rule.endpoint])(**view_args)
2023-03-15 20:57:17.234 38 ERROR keystone.server.flask.application   File "/var/lib/kolla/venv/lib/python3.9/site-packages/flask_restful/__init__.py", line 467, in wrapper
2023-03-15 20:57:17.234 38 ERROR keystone.server.flask.application     resp = resource(*args, **kwargs)
2023-03-15 20:57:17.234 38 ERROR keystone.server.flask.application   File "/var/lib/kolla/venv/lib/python3.9/site-packages/flask/views.py", line 107, in view
2023-03-15 20:57:17.234 38 ERROR keystone.server.flask.application     return current_app.ensure_sync(self.dispatch_request)(**kwargs)
2023-03-15 20:57:17.234 38 ERROR keystone.server.flask.application   File "/var/lib/kolla/venv/lib/python3.9/site-packages/flask_restful/__init__.py", line 582, in dispatch_request
2023-03-15 20:57:17.234 38 ERROR keystone.server.flask.application     resp = meth(*args, **kwargs)
2023-03-15 20:57:17.234 38 ERROR keystone.server.flask.application   File "/var/lib/kolla/venv/lib/python3.9/site-packages/keystone/api/projects.py", line 151, in get
2023-03-15 20:57:17.234 38 ERROR keystone.server.flask.application     return self._get_project(project_id)
2023-03-15 20:57:17.234 38 ERROR keystone.server.flask.application   File "/var/lib/kolla/venv/lib/python3.9/site-packages/keystone/api/projects.py", line 107, in _get_project
2023-03-15 20:57:17.234 38 ERROR keystone.server.flask.application     project = PROVIDERS.resource_api.get_project(project_id)
2023-03-15 20:57:17.234 38 ERROR keystone.server.flask.application   File "/var/lib/kolla/venv/lib/python3.9/site-packages/keystone/common/manager.py", line 115, in wrapped
2023-03-15 20:57:17.234 38 ERROR keystone.server.flask.application     __ret_val = __f(*args, **kwargs)
2023-03-15 20:57:17.234 38 ERROR keystone.server.flask.application   File "/var/lib/kolla/venv/lib/python3.9/site-packages/decorator.py", line 232, in fun
2023-03-15 20:57:17.234 38 ERROR keystone.server.flask.application     return caller(func, *(extras + args), **kw)
2023-03-15 20:57:17.234 38 ERROR keystone.server.flask.application   File "/var/lib/kolla/venv/lib/python3.9/site-packages/dogpile/cache/region.py", line 1577, in get_or_create_for_user_func
2023-03-15 20:57:17.234 38 ERROR keystone.server.flask.application     return self.get_or_create(
2023-03-15 20:57:17.234 38 ERROR keystone.server.flask.application   File "/var/lib/kolla/venv/lib/python3.9/site-packages/dogpile/cache/region.py", line 1042, in get_or_create
2023-03-15 20:57:17.234 38 ERROR keystone.server.flask.application     with Lock(
2023-03-15 20:57:17.234 38 ERROR keystone.server.flask.application   File "/var/lib/kolla/venv/lib/python3.9/site-packages/dogpile/lock.py", line 185, in __enter__
2023-03-15 20:57:17.234 38 ERROR keystone.server.flask.application     return self._enter()
2023-03-15 20:57:17.234 38 ERROR keystone.server.flask.application   File "/var/lib/kolla/venv/lib/python3.9/site-packages/dogpile/lock.py", line 94, in _enter
2023-03-15 20:57:17.234 38 ERROR keystone.server.flask.application     generated = self._enter_create(value, createdtime)
2023-03-15 20:57:17.234 38 ERROR keystone.server.flask.application   File "/var/lib/kolla/venv/lib/python3.9/site-packages/dogpile/lock.py", line 178, in _enter_create
2023-03-15 20:57:17.234 38 ERROR keystone.server.flask.application     return self.creator()
2023-03-15 20:57:17.234 38 ERROR keystone.server.flask.application   File "/var/lib/kolla/venv/lib/python3.9/site-packages/dogpile/cache/region.py", line 995, in gen_value
2023-03-15 20:57:17.234 38 ERROR keystone.server.flask.application     created_value = creator(
2023-03-15 20:57:17.234 38 ERROR keystone.server.flask.application   File "/var/lib/kolla/venv/lib/python3.9/site-packages/keystone/resource/core.py", line 903, in get_project
2023-03-15 20:57:17.234 38 ERROR keystone.server.flask.application     return self.driver.get_project(project_id)
2023-03-15 20:57:17.234 38 ERROR keystone.server.flask.application   File "/var/lib/kolla/venv/lib/python3.9/site-packages/keystone/resource/backends/sql.py", line 49, in get_project
2023-03-15 20:57:17.234 38 ERROR keystone.server.flask.application     return self._get_project(session, project_id).to_dict()
2023-03-15 20:57:17.234 38 ERROR keystone.server.flask.application   File "/var/lib/kolla/venv/lib/python3.9/site-packages/keystone/resource/backends/sql.py", line 44, in _get_project
2023-03-15 20:57:17.234 38 ERROR keystone.server.flask.application     raise exception.ProjectNotFound(project_id=project_id)
2023-03-15 20:57:17.234 38 ERROR keystone.server.flask.application keystone.exception.ProjectNotFound: Could not find project: service.
2023-03-15 20:57:17.234 38 ERROR keystone.server.flask.application 
2023-03-15 20:57:26.753 39 ERROR keystone.server.flask.application [None req-339803a7-95e3-4d08-a93d-628cd5d611eb 85b537ff22d246d29b67535eecf74526 - - all default -] Could not find role: admin.: keystone.exception.RoleNotFound: Could not find role: admin.
2023-03-15 20:57:26.753 39 ERROR keystone.server.flask.application Traceback (most recent call last):
2023-03-15 20:57:26.753 39 ERROR keystone.server.flask.application   File "/var/lib/kolla/venv/lib/python3.9/site-packages/flask/app.py", line 1820, in full_dispatch_request
2023-03-15 20:57:26.753 39 ERROR keystone.server.flask.application     rv = self.dispatch_request()
2023-03-15 20:57:26.753 39 ERROR keystone.server.flask.application   File "/var/lib/kolla/venv/lib/python3.9/site-packages/flask/app.py", line 1796, in dispatch_request
2023-03-15 20:57:26.753 39 ERROR keystone.server.flask.application     return self.ensure_sync(self.view_functions[rule.endpoint])(**view_args)
2023-03-15 20:57:26.753 39 ERROR keystone.server.flask.application   File "/var/lib/kolla/venv/lib/python3.9/site-packages/flask_restful/__init__.py", line 467, in wrapper
2023-03-15 20:57:26.753 39 ERROR keystone.server.flask.application     resp = resource(*args, **kwargs)
2023-03-15 20:57:26.753 39 ERROR keystone.server.flask.application   File "/var/lib/kolla/venv/lib/python3.9/site-packages/flask/views.py", line 107, in view
2023-03-15 20:57:26.753 39 ERROR keystone.server.flask.application     return current_app.ensure_sync(self.dispatch_request)(**kwargs)
2023-03-15 20:57:26.753 39 ERROR keystone.server.flask.application   File "/var/lib/kolla/venv/lib/python3.9/site-packages/flask_restful/__init__.py", line 582, in dispatch_request
2023-03-15 20:57:26.753 39 ERROR keystone.server.flask.application     resp = meth(*args, **kwargs)
2023-03-15 20:57:26.753 39 ERROR keystone.server.flask.application   File "/var/lib/kolla/venv/lib/python3.9/site-packages/keystone/api/roles.py", line 50, in get
2023-03-15 20:57:26.753 39 ERROR keystone.server.flask.application     return self._get_role(role_id)
2023-03-15 20:57:26.753 39 ERROR keystone.server.flask.application   File "/var/lib/kolla/venv/lib/python3.9/site-packages/keystone/api/roles.py", line 70, in _get_role
2023-03-15 20:57:26.753 39 ERROR keystone.server.flask.application     ENFORCER.enforce_call(action='identity:get_role')
2023-03-15 20:57:26.753 39 ERROR keystone.server.flask.application   File "/var/lib/kolla/venv/lib/python3.9/site-packages/keystone/common/rbac_enforcer/enforcer.py", line 402, in enforce_call
2023-03-15 20:57:26.753 39 ERROR keystone.server.flask.application     policy_dict.update(cls._extract_member_target_data(
2023-03-15 20:57:26.753 39 ERROR keystone.server.flask.application   File "/var/lib/kolla/venv/lib/python3.9/site-packages/keystone/common/rbac_enforcer/enforcer.py", line 234, in _extract_member_target_data
2023-03-15 20:57:26.753 39 ERROR keystone.server.flask.application     member_name: func(flask.request.view_args[key])
2023-03-15 20:57:26.753 39 ERROR keystone.server.flask.application   File "/var/lib/kolla/venv/lib/python3.9/site-packages/keystone/common/manager.py", line 115, in wrapped
2023-03-15 20:57:26.753 39 ERROR keystone.server.flask.application     __ret_val = __f(*args, **kwargs)
2023-03-15 20:57:26.753 39 ERROR keystone.server.flask.application   File "/var/lib/kolla/venv/lib/python3.9/site-packages/decorator.py", line 232, in fun
2023-03-15 20:57:26.753 39 ERROR keystone.server.flask.application     return caller(func, *(extras + args), **kw)
2023-03-15 20:57:26.753 39 ERROR keystone.server.flask.application   File "/var/lib/kolla/venv/lib/python3.9/site-packages/dogpile/cache/region.py", line 1577, in get_or_create_for_user_func
2023-03-15 20:57:26.753 39 ERROR keystone.server.flask.application     return self.get_or_create(
2023-03-15 20:57:26.753 39 ERROR keystone.server.flask.application   File "/var/lib/kolla/venv/lib/python3.9/site-packages/dogpile/cache/region.py", line 1042, in get_or_create
2023-03-15 20:57:26.753 39 ERROR keystone.server.flask.application     with Lock(
2023-03-15 20:57:26.753 39 ERROR keystone.server.flask.application   File "/var/lib/kolla/venv/lib/python3.9/site-packages/dogpile/lock.py", line 185, in __enter__
2023-03-15 20:57:26.753 39 ERROR keystone.server.flask.application     return self._enter()
2023-03-15 20:57:26.753 39 ERROR keystone.server.flask.application   File "/var/lib/kolla/venv/lib/python3.9/site-packages/dogpile/lock.py", line 94, in _enter
2023-03-15 20:57:26.753 39 ERROR keystone.server.flask.application     generated = self._enter_create(value, createdtime)
2023-03-15 20:57:26.753 39 ERROR keystone.server.flask.application   File "/var/lib/kolla/venv/lib/python3.9/site-packages/dogpile/lock.py", line 178, in _enter_create
2023-03-15 20:57:26.753 39 ERROR keystone.server.flask.application     return self.creator()
2023-03-15 20:57:26.753 39 ERROR keystone.server.flask.application   File "/var/lib/kolla/venv/lib/python3.9/site-packages/dogpile/cache/region.py", line 995, in gen_value
2023-03-15 20:57:26.753 39 ERROR keystone.server.flask.application     created_value = creator(
2023-03-15 20:57:26.753 39 ERROR keystone.server.flask.application   File "/var/lib/kolla/venv/lib/python3.9/site-packages/keystone/assignment/core.py", line 1276, in get_role
2023-03-15 20:57:26.753 39 ERROR keystone.server.flask.application     return self.driver.get_role(role_id)
2023-03-15 20:57:26.753 39 ERROR keystone.server.flask.application   File "/var/lib/kolla/venv/lib/python3.9/site-packages/keystone/assignment/role_backends/sql.py", line 70, in get_role
2023-03-15 20:57:26.753 39 ERROR keystone.server.flask.application     return self._get_role(session, role_id).to_dict()
2023-03-15 20:57:26.753 39 ERROR keystone.server.flask.application   File "/var/lib/kolla/venv/lib/python3.9/site-packages/keystone/assignment/role_backends/sql.py", line 65, in _get_role
2023-03-15 20:57:26.753 39 ERROR keystone.server.flask.application     raise exception.RoleNotFound(role_id=role_id)
2023-03-15 20:57:26.753 39 ERROR keystone.server.flask.application keystone.exception.RoleNotFound: Could not find role: admin.
2023-03-15 20:57:26.753 39 ERROR keystone.server.flask.application 
2023-03-15 20:57:27.909 39 ERROR keystone.server.flask.application [None req-ab0cd265-3f99-41bf-81ed-f1807ac7d5e7 85b537ff22d246d29b67535eecf74526 - - all default -] Could not find user: ironic-inspector.: keystone.exception.UserNotFound: Could not find user: ironic-inspector.
2023-03-15 20:57:27.909 39 ERROR keystone.server.flask.application Traceback (most recent call last):
2023-03-15 20:57:27.909 39 ERROR keystone.server.flask.application   File "/var/lib/kolla/venv/lib/python3.9/site-packages/flask/app.py", line 1820, in full_dispatch_request
2023-03-15 20:57:27.909 39 ERROR keystone.server.flask.application     rv = self.dispatch_request()
2023-03-15 20:57:27.909 39 ERROR keystone.server.flask.application   File "/var/lib/kolla/venv/lib/python3.9/site-packages/flask/app.py", line 1796, in dispatch_request
2023-03-15 20:57:27.909 39 ERROR keystone.server.flask.application     return self.ensure_sync(self.view_functions[rule.endpoint])(**view_args)
2023-03-15 20:57:27.909 39 ERROR keystone.server.flask.application   File "/var/lib/kolla/venv/lib/python3.9/site-packages/flask_restful/__init__.py", line 467, in wrapper
2023-03-15 20:57:27.909 39 ERROR keystone.server.flask.application     resp = resource(*args, **kwargs)
2023-03-15 20:57:27.909 39 ERROR keystone.server.flask.application   File "/var/lib/kolla/venv/lib/python3.9/site-packages/flask/views.py", line 107, in view
2023-03-15 20:57:27.909 39 ERROR keystone.server.flask.application     return current_app.ensure_sync(self.dispatch_request)(**kwargs)
2023-03-15 20:57:27.909 39 ERROR keystone.server.flask.application   File "/var/lib/kolla/venv/lib/python3.9/site-packages/flask_restful/__init__.py", line 582, in dispatch_request
2023-03-15 20:57:27.909 39 ERROR keystone.server.flask.application     resp = meth(*args, **kwargs)
2023-03-15 20:57:27.909 39 ERROR keystone.server.flask.application   File "/var/lib/kolla/venv/lib/python3.9/site-packages/keystone/api/users.py", line 182, in get
2023-03-15 20:57:27.909 39 ERROR keystone.server.flask.application     return self._get_user(user_id)
2023-03-15 20:57:27.909 39 ERROR keystone.server.flask.application   File "/var/lib/kolla/venv/lib/python3.9/site-packages/keystone/api/users.py", line 194, in _get_user
2023-03-15 20:57:27.909 39 ERROR keystone.server.flask.application     ref = PROVIDERS.identity_api.get_user(user_id)
2023-03-15 20:57:27.909 39 ERROR keystone.server.flask.application   File "/var/lib/kolla/venv/lib/python3.9/site-packages/keystone/common/manager.py", line 115, in wrapped
2023-03-15 20:57:27.909 39 ERROR keystone.server.flask.application     __ret_val = __f(*args, **kwargs)
2023-03-15 20:57:27.909 39 ERROR keystone.server.flask.application   File "/var/lib/kolla/venv/lib/python3.9/site-packages/keystone/identity/core.py", line 414, in wrapper
2023-03-15 20:57:27.909 39 ERROR keystone.server.flask.application     return f(self, *args, **kwargs)
2023-03-15 20:57:27.909 39 ERROR keystone.server.flask.application   File "/var/lib/kolla/venv/lib/python3.9/site-packages/keystone/identity/core.py", line 424, in wrapper
2023-03-15 20:57:27.909 39 ERROR keystone.server.flask.application     return f(self, *args, **kwargs)
2023-03-15 20:57:27.909 39 ERROR keystone.server.flask.application   File "/var/lib/kolla/venv/lib/python3.9/site-packages/decorator.py", line 232, in fun
2023-03-15 20:57:27.909 39 ERROR keystone.server.flask.application     return caller(func, *(extras + args), **kw)
2023-03-15 20:57:27.909 39 ERROR keystone.server.flask.application   File "/var/lib/kolla/venv/lib/python3.9/site-packages/dogpile/cache/region.py", line 1577, in get_or_create_for_user_func
2023-03-15 20:57:27.909 39 ERROR keystone.server.flask.application     return self.get_or_create(
2023-03-15 20:57:27.909 39 ERROR keystone.server.flask.application   File "/var/lib/kolla/venv/lib/python3.9/site-packages/dogpile/cache/region.py", line 1042, in get_or_create
2023-03-15 20:57:27.909 39 ERROR keystone.server.flask.application     with Lock(
2023-03-15 20:57:27.909 39 ERROR keystone.server.flask.application   File "/var/lib/kolla/venv/lib/python3.9/site-packages/dogpile/lock.py", line 185, in __enter__
2023-03-15 20:57:27.909 39 ERROR keystone.server.flask.application     return self._enter()
2023-03-15 20:57:27.909 39 ERROR keystone.server.flask.application   File "/var/lib/kolla/venv/lib/python3.9/site-packages/dogpile/lock.py", line 94, in _enter
2023-03-15 20:57:27.909 39 ERROR keystone.server.flask.application     generated = self._enter_create(value, createdtime)
2023-03-15 20:57:27.909 39 ERROR keystone.server.flask.application   File "/var/lib/kolla/venv/lib/python3.9/site-packages/dogpile/lock.py", line 178, in _enter_create
2023-03-15 20:57:27.909 39 ERROR keystone.server.flask.application     return self.creator()
2023-03-15 20:57:27.909 39 ERROR keystone.server.flask.application   File "/var/lib/kolla/venv/lib/python3.9/site-packages/dogpile/cache/region.py", line 995, in gen_value
2023-03-15 20:57:27.909 39 ERROR keystone.server.flask.application     created_value = creator(
2023-03-15 20:57:27.909 39 ERROR keystone.server.flask.application   File "/var/lib/kolla/venv/lib/python3.9/site-packages/keystone/identity/core.py", line 1011, in get_user
2023-03-15 20:57:27.909 39 ERROR keystone.server.flask.application     ref = driver.get_user(entity_id)
2023-03-15 20:57:27.909 39 ERROR keystone.server.flask.application   File "/var/lib/kolla/venv/lib/python3.9/site-packages/keystone/identity/backends/sql.py", line 200, in get_user
2023-03-15 20:57:27.909 39 ERROR keystone.server.flask.application     self._get_user(session, user_id).to_dict())
2023-03-15 20:57:27.909 39 ERROR keystone.server.flask.application   File "/var/lib/kolla/venv/lib/python3.9/site-packages/keystone/identity/backends/sql.py", line 194, in _get_user
2023-03-15 20:57:27.909 39 ERROR keystone.server.flask.application     raise exception.UserNotFound(user_id=user_id)
2023-03-15 20:57:27.909 39 ERROR keystone.server.flask.application keystone.exception.UserNotFound: Could not find user: ironic-inspector.
2023-03-15 20:57:27.909 39 ERROR keystone.server.flask.application 
2023-03-15 20:57:28.647 37 ERROR keystone.server.flask.application [None req-29f40e19-aa8a-4529-a125-6a420b4bb3e3 85b537ff22d246d29b67535eecf74526 - - all default -] Could not find project: service.: keystone.exception.ProjectNotFound: Could not find project: service.
2023-03-15 20:57:28.647 37 ERROR keystone.server.flask.application Traceback (most recent call last):
2023-03-15 20:57:28.647 37 ERROR keystone.server.flask.application   File "/var/lib/kolla/venv/lib/python3.9/site-packages/flask/app.py", line 1820, in full_dispatch_request
2023-03-15 20:57:28.647 37 ERROR keystone.server.flask.application     rv = self.dispatch_request()
2023-03-15 20:57:28.647 37 ERROR keystone.server.flask.application   File "/var/lib/kolla/venv/lib/python3.9/site-packages/flask/app.py", line 1796, in dispatch_request
2023-03-15 20:57:28.647 37 ERROR keystone.server.flask.application     return self.ensure_sync(self.view_functions[rule.endpoint])(**view_args)
2023-03-15 20:57:28.647 37 ERROR keystone.server.flask.application   File "/var/lib/kolla/venv/lib/python3.9/site-packages/flask_restful/__init__.py", line 467, in wrapper
2023-03-15 20:57:28.647 37 ERROR keystone.server.flask.application     resp = resource(*args, **kwargs)
2023-03-15 20:57:28.647 37 ERROR keystone.server.flask.application   File "/var/lib/kolla/venv/lib/python3.9/site-packages/flask/views.py", line 107, in view
2023-03-15 20:57:28.647 37 ERROR keystone.server.flask.application     return current_app.ensure_sync(self.dispatch_request)(**kwargs)
2023-03-15 20:57:28.647 37 ERROR keystone.server.flask.application   File "/var/lib/kolla/venv/lib/python3.9/site-packages/flask_restful/__init__.py", line 582, in dispatch_request
2023-03-15 20:57:28.647 37 ERROR keystone.server.flask.application     resp = meth(*args, **kwargs)
2023-03-15 20:57:28.647 37 ERROR keystone.server.flask.application   File "/var/lib/kolla/venv/lib/python3.9/site-packages/keystone/api/projects.py", line 151, in get
2023-03-15 20:57:28.647 37 ERROR keystone.server.flask.application     return self._get_project(project_id)
2023-03-15 20:57:28.647 37 ERROR keystone.server.flask.application   File "/var/lib/kolla/venv/lib/python3.9/site-packages/keystone/api/projects.py", line 107, in _get_project
2023-03-15 20:57:28.647 37 ERROR keystone.server.flask.application     project = PROVIDERS.resource_api.get_project(project_id)
2023-03-15 20:57:28.647 37 ERROR keystone.server.flask.application   File "/var/lib/kolla/venv/lib/python3.9/site-packages/keystone/common/manager.py", line 115, in wrapped
2023-03-15 20:57:28.647 37 ERROR keystone.server.flask.application     __ret_val = __f(*args, **kwargs)
2023-03-15 20:57:28.647 37 ERROR keystone.server.flask.application   File "/var/lib/kolla/venv/lib/python3.9/site-packages/decorator.py", line 232, in fun
2023-03-15 20:57:28.647 37 ERROR keystone.server.flask.application     return caller(func, *(extras + args), **kw)
2023-03-15 20:57:28.647 37 ERROR keystone.server.flask.application   File "/var/lib/kolla/venv/lib/python3.9/site-packages/dogpile/cache/region.py", line 1577, in get_or_create_for_user_func
2023-03-15 20:57:28.647 37 ERROR keystone.server.flask.application     return self.get_or_create(
2023-03-15 20:57:28.647 37 ERROR keystone.server.flask.application   File "/var/lib/kolla/venv/lib/python3.9/site-packages/dogpile/cache/region.py", line 1042, in get_or_create
2023-03-15 20:57:28.647 37 ERROR keystone.server.flask.application     with Lock(
2023-03-15 20:57:28.647 37 ERROR keystone.server.flask.application   File "/var/lib/kolla/venv/lib/python3.9/site-packages/dogpile/lock.py", line 185, in __enter__
2023-03-15 20:57:28.647 37 ERROR keystone.server.flask.application     return self._enter()
2023-03-15 20:57:28.647 37 ERROR keystone.server.flask.application   File "/var/lib/kolla/venv/lib/python3.9/site-packages/dogpile/lock.py", line 94, in _enter
2023-03-15 20:57:28.647 37 ERROR keystone.server.flask.application     generated = self._enter_create(value, createdtime)
2023-03-15 20:57:28.647 37 ERROR keystone.server.flask.application   File "/var/lib/kolla/venv/lib/python3.9/site-packages/dogpile/lock.py", line 178, in _enter_create
2023-03-15 20:57:28.647 37 ERROR keystone.server.flask.application     return self.creator()
2023-03-15 20:57:28.647 37 ERROR keystone.server.flask.application   File "/var/lib/kolla/venv/lib/python3.9/site-packages/dogpile/cache/region.py", line 995, in gen_value
2023-03-15 20:57:28.647 37 ERROR keystone.server.flask.application     created_value = creator(
2023-03-15 20:57:28.647 37 ERROR keystone.server.flask.application   File "/var/lib/kolla/venv/lib/python3.9/site-packages/keystone/resource/core.py", line 903, in get_project
2023-03-15 20:57:28.647 37 ERROR keystone.server.flask.application     return self.driver.get_project(project_id)
2023-03-15 20:57:28.647 37 ERROR keystone.server.flask.application   File "/var/lib/kolla/venv/lib/python3.9/site-packages/keystone/resource/backends/sql.py", line 49, in get_project
2023-03-15 20:57:28.647 37 ERROR keystone.server.flask.application     return self._get_project(session, project_id).to_dict()
2023-03-15 20:57:28.647 37 ERROR keystone.server.flask.application   File "/var/lib/kolla/venv/lib/python3.9/site-packages/keystone/resource/backends/sql.py", line 44, in _get_project
2023-03-15 20:57:28.647 37 ERROR keystone.server.flask.application     raise exception.ProjectNotFound(project_id=project_id)
2023-03-15 20:57:28.647 37 ERROR keystone.server.flask.application keystone.exception.ProjectNotFound: Could not find project: service.
2023-03-15 20:57:28.647 37 ERROR keystone.server.flask.application 
2023-03-15 21:00:22.874 38 ERROR keystone.server.flask.application [None req-4300e109-8d46-4a6c-baf5-bce6c631080e 85b537ff22d246d29b67535eecf74526 - - all default -] Could not find project: service.: keystone.exception.ProjectNotFound: Could not find project: service.
2023-03-15 21:00:22.874 38 ERROR keystone.server.flask.application Traceback (most recent call last):
2023-03-15 21:00:22.874 38 ERROR keystone.server.flask.application   File "/var/lib/kolla/venv/lib/python3.9/site-packages/flask/app.py", line 1820, in full_dispatch_request
2023-03-15 21:00:22.874 38 ERROR keystone.server.flask.application     rv = self.dispatch_request()
2023-03-15 21:00:22.874 38 ERROR keystone.server.flask.application   File "/var/lib/kolla/venv/lib/python3.9/site-packages/flask/app.py", line 1796, in dispatch_request
2023-03-15 21:00:22.874 38 ERROR keystone.server.flask.application     return self.ensure_sync(self.view_functions[rule.endpoint])(**view_args)
2023-03-15 21:00:22.874 38 ERROR keystone.server.flask.application   File "/var/lib/kolla/venv/lib/python3.9/site-packages/flask_restful/__init__.py", line 467, in wrapper
2023-03-15 21:00:22.874 38 ERROR keystone.server.flask.application     resp = resource(*args, **kwargs)
2023-03-15 21:00:22.874 38 ERROR keystone.server.flask.application   File "/var/lib/kolla/venv/lib/python3.9/site-packages/flask/views.py", line 107, in view
2023-03-15 21:00:22.874 38 ERROR keystone.server.flask.application     return current_app.ensure_sync(self.dispatch_request)(**kwargs)
2023-03-15 21:00:22.874 38 ERROR keystone.server.flask.application   File "/var/lib/kolla/venv/lib/python3.9/site-packages/flask_restful/__init__.py", line 582, in dispatch_request
2023-03-15 21:00:22.874 38 ERROR keystone.server.flask.application     resp = meth(*args, **kwargs)
2023-03-15 21:00:22.874 38 ERROR keystone.server.flask.application   File "/var/lib/kolla/venv/lib/python3.9/site-packages/keystone/api/projects.py", line 151, in get
2023-03-15 21:00:22.874 38 ERROR keystone.server.flask.application     return self._get_project(project_id)
2023-03-15 21:00:22.874 38 ERROR keystone.server.flask.application   File "/var/lib/kolla/venv/lib/python3.9/site-packages/keystone/api/projects.py", line 107, in _get_project
2023-03-15 21:00:22.874 38 ERROR keystone.server.flask.application     project = PROVIDERS.resource_api.get_project(project_id)
2023-03-15 21:00:22.874 38 ERROR keystone.server.flask.application   File "/var/lib/kolla/venv/lib/python3.9/site-packages/keystone/common/manager.py", line 115, in wrapped
2023-03-15 21:00:22.874 38 ERROR keystone.server.flask.application     __ret_val = __f(*args, **kwargs)
2023-03-15 21:00:22.874 38 ERROR keystone.server.flask.application   File "/var/lib/kolla/venv/lib/python3.9/site-packages/decorator.py", line 232, in fun
2023-03-15 21:00:22.874 38 ERROR keystone.server.flask.application     return caller(func, *(extras + args), **kw)
2023-03-15 21:00:22.874 38 ERROR keystone.server.flask.application   File "/var/lib/kolla/venv/lib/python3.9/site-packages/dogpile/cache/region.py", line 1577, in get_or_create_for_user_func
2023-03-15 21:00:22.874 38 ERROR keystone.server.flask.application     return self.get_or_create(
2023-03-15 21:00:22.874 38 ERROR keystone.server.flask.application   File "/var/lib/kolla/venv/lib/python3.9/site-packages/dogpile/cache/region.py", line 1042, in get_or_create
2023-03-15 21:00:22.874 38 ERROR keystone.server.flask.application     with Lock(
2023-03-15 21:00:22.874 38 ERROR keystone.server.flask.application   File "/var/lib/kolla/venv/lib/python3.9/site-packages/dogpile/lock.py", line 185, in __enter__
2023-03-15 21:00:22.874 38 ERROR keystone.server.flask.application     return self._enter()
2023-03-15 21:00:22.874 38 ERROR keystone.server.flask.application   File "/var/lib/kolla/venv/lib/python3.9/site-packages/dogpile/lock.py", line 94, in _enter
2023-03-15 21:00:22.874 38 ERROR keystone.server.flask.application     generated = self._enter_create(value, createdtime)
2023-03-15 21:00:22.874 38 ERROR keystone.server.flask.application   File "/var/lib/kolla/venv/lib/python3.9/site-packages/dogpile/lock.py", line 178, in _enter_create
2023-03-15 21:00:22.874 38 ERROR keystone.server.flask.application     return self.creator()
2023-03-15 21:00:22.874 38 ERROR keystone.server.flask.application   File "/var/lib/kolla/venv/lib/python3.9/site-packages/dogpile/cache/region.py", line 995, in gen_value
2023-03-15 21:00:22.874 38 ERROR keystone.server.flask.application     created_value = creator(
2023-03-15 21:00:22.874 38 ERROR keystone.server.flask.application   File "/var/lib/kolla/venv/lib/python3.9/site-packages/keystone/resource/core.py", line 903, in get_project
2023-03-15 21:00:22.874 38 ERROR keystone.server.flask.application     return self.driver.get_project(project_id)
2023-03-15 21:00:22.874 38 ERROR keystone.server.flask.application   File "/var/lib/kolla/venv/lib/python3.9/site-packages/keystone/resource/backends/sql.py", line 49, in get_project
2023-03-15 21:00:22.874 38 ERROR keystone.server.flask.application     return self._get_project(session, project_id).to_dict()
2023-03-15 21:00:22.874 38 ERROR keystone.server.flask.application   File "/var/lib/kolla/venv/lib/python3.9/site-packages/keystone/resource/backends/sql.py", line 44, in _get_project
2023-03-15 21:00:22.874 38 ERROR keystone.server.flask.application     raise exception.ProjectNotFound(project_id=project_id)
2023-03-15 21:00:22.874 38 ERROR keystone.server.flask.application keystone.exception.ProjectNotFound: Could not find project: service.
2023-03-15 21:00:22.874 38 ERROR keystone.server.flask.application 
2023-03-15 21:00:38.542 37 ERROR keystone.server.flask.application [None req-9b8cbcf0-1c0d-4320-9f1c-ae49383e4d18 85b537ff22d246d29b67535eecf74526 - - all default -] Could not find role: admin.: keystone.exception.RoleNotFound: Could not find role: admin.
2023-03-15 21:00:38.542 37 ERROR keystone.server.flask.application Traceback (most recent call last):
2023-03-15 21:00:38.542 37 ERROR keystone.server.flask.application   File "/var/lib/kolla/venv/lib/python3.9/site-packages/flask/app.py", line 1820, in full_dispatch_request
2023-03-15 21:00:38.542 37 ERROR keystone.server.flask.application     rv = self.dispatch_request()
2023-03-15 21:00:38.542 37 ERROR keystone.server.flask.application   File "/var/lib/kolla/venv/lib/python3.9/site-packages/flask/app.py", line 1796, in dispatch_request
2023-03-15 21:00:38.542 37 ERROR keystone.server.flask.application     return self.ensure_sync(self.view_functions[rule.endpoint])(**view_args)
2023-03-15 21:00:38.542 37 ERROR keystone.server.flask.application   File "/var/lib/kolla/venv/lib/python3.9/site-packages/flask_restful/__init__.py", line 467, in wrapper
2023-03-15 21:00:38.542 37 ERROR keystone.server.flask.application     resp = resource(*args, **kwargs)
2023-03-15 21:00:38.542 37 ERROR keystone.server.flask.application   File "/var/lib/kolla/venv/lib/python3.9/site-packages/flask/views.py", line 107, in view
2023-03-15 21:00:38.542 37 ERROR keystone.server.flask.application     return current_app.ensure_sync(self.dispatch_request)(**kwargs)
2023-03-15 21:00:38.542 37 ERROR keystone.server.flask.application   File "/var/lib/kolla/venv/lib/python3.9/site-packages/flask_restful/__init__.py", line 582, in dispatch_request
2023-03-15 21:00:38.542 37 ERROR keystone.server.flask.application     resp = meth(*args, **kwargs)
2023-03-15 21:00:38.542 37 ERROR keystone.server.flask.application   File "/var/lib/kolla/venv/lib/python3.9/site-packages/keystone/api/roles.py", line 50, in get
2023-03-15 21:00:38.542 37 ERROR keystone.server.flask.application     return self._get_role(role_id)
2023-03-15 21:00:38.542 37 ERROR keystone.server.flask.application   File "/var/lib/kolla/venv/lib/python3.9/site-packages/keystone/api/roles.py", line 70, in _get_role
2023-03-15 21:00:38.542 37 ERROR keystone.server.flask.application     ENFORCER.enforce_call(action='identity:get_role')
2023-03-15 21:00:38.542 37 ERROR keystone.server.flask.application   File "/var/lib/kolla/venv/lib/python3.9/site-packages/keystone/common/rbac_enforcer/enforcer.py", line 402, in enforce_call
2023-03-15 21:00:38.542 37 ERROR keystone.server.flask.application     policy_dict.update(cls._extract_member_target_data(
2023-03-15 21:00:38.542 37 ERROR keystone.server.flask.application   File "/var/lib/kolla/venv/lib/python3.9/site-packages/keystone/common/rbac_enforcer/enforcer.py", line 234, in _extract_member_target_data
2023-03-15 21:00:38.542 37 ERROR keystone.server.flask.application     member_name: func(flask.request.view_args[key])
2023-03-15 21:00:38.542 37 ERROR keystone.server.flask.application   File "/var/lib/kolla/venv/lib/python3.9/site-packages/keystone/common/manager.py", line 115, in wrapped
2023-03-15 21:00:38.542 37 ERROR keystone.server.flask.application     __ret_val = __f(*args, **kwargs)
2023-03-15 21:00:38.542 37 ERROR keystone.server.flask.application   File "/var/lib/kolla/venv/lib/python3.9/site-packages/decorator.py", line 232, in fun
2023-03-15 21:00:38.542 37 ERROR keystone.server.flask.application     return caller(func, *(extras + args), **kw)
2023-03-15 21:00:38.542 37 ERROR keystone.server.flask.application   File "/var/lib/kolla/venv/lib/python3.9/site-packages/dogpile/cache/region.py", line 1577, in get_or_create_for_user_func
2023-03-15 21:00:38.542 37 ERROR keystone.server.flask.application     return self.get_or_create(
2023-03-15 21:00:38.542 37 ERROR keystone.server.flask.application   File "/var/lib/kolla/venv/lib/python3.9/site-packages/dogpile/cache/region.py", line 1042, in get_or_create
2023-03-15 21:00:38.542 37 ERROR keystone.server.flask.application     with Lock(
2023-03-15 21:00:38.542 37 ERROR keystone.server.flask.application   File "/var/lib/kolla/venv/lib/python3.9/site-packages/dogpile/lock.py", line 185, in __enter__
2023-03-15 21:00:38.542 37 ERROR keystone.server.flask.application     return self._enter()
2023-03-15 21:00:38.542 37 ERROR keystone.server.flask.application   File "/var/lib/kolla/venv/lib/python3.9/site-packages/dogpile/lock.py", line 94, in _enter
2023-03-15 21:00:38.542 37 ERROR keystone.server.flask.application     generated = self._enter_create(value, createdtime)
2023-03-15 21:00:38.542 37 ERROR keystone.server.flask.application   File "/var/lib/kolla/venv/lib/python3.9/site-packages/dogpile/lock.py", line 178, in _enter_create
2023-03-15 21:00:38.542 37 ERROR keystone.server.flask.application     return self.creator()
2023-03-15 21:00:38.542 37 ERROR keystone.server.flask.application   File "/var/lib/kolla/venv/lib/python3.9/site-packages/dogpile/cache/region.py", line 995, in gen_value
2023-03-15 21:00:38.542 37 ERROR keystone.server.flask.application     created_value = creator(
2023-03-15 21:00:38.542 37 ERROR keystone.server.flask.application   File "/var/lib/kolla/venv/lib/python3.9/site-packages/keystone/assignment/core.py", line 1276, in get_role
2023-03-15 21:00:38.542 37 ERROR keystone.server.flask.application     return self.driver.get_role(role_id)
2023-03-15 21:00:38.542 37 ERROR keystone.server.flask.application   File "/var/lib/kolla/venv/lib/python3.9/site-packages/keystone/assignment/role_backends/sql.py", line 70, in get_role
2023-03-15 21:00:38.542 37 ERROR keystone.server.flask.application     return self._get_role(session, role_id).to_dict()
2023-03-15 21:00:38.542 37 ERROR keystone.server.flask.application   File "/var/lib/kolla/venv/lib/python3.9/site-packages/keystone/assignment/role_backends/sql.py", line 65, in _get_role
2023-03-15 21:00:38.542 37 ERROR keystone.server.flask.application     raise exception.RoleNotFound(role_id=role_id)
2023-03-15 21:00:38.542 37 ERROR keystone.server.flask.application keystone.exception.RoleNotFound: Could not find role: admin.
2023-03-15 21:00:38.542 37 ERROR keystone.server.flask.application 
2023-03-15 21:00:39.626 37 ERROR keystone.server.flask.application [None req-6c1a7c22-5f49-4535-a5e8-5e24a2024c9b 85b537ff22d246d29b67535eecf74526 - - all default -] Could not find user: neutron.: keystone.exception.UserNotFound: Could not find user: neutron.
2023-03-15 21:00:39.626 37 ERROR keystone.server.flask.application Traceback (most recent call last):
2023-03-15 21:00:39.626 37 ERROR keystone.server.flask.application   File "/var/lib/kolla/venv/lib/python3.9/site-packages/flask/app.py", line 1820, in full_dispatch_request
2023-03-15 21:00:39.626 37 ERROR keystone.server.flask.application     rv = self.dispatch_request()
2023-03-15 21:00:39.626 37 ERROR keystone.server.flask.application   File "/var/lib/kolla/venv/lib/python3.9/site-packages/flask/app.py", line 1796, in dispatch_request
2023-03-15 21:00:39.626 37 ERROR keystone.server.flask.application     return self.ensure_sync(self.view_functions[rule.endpoint])(**view_args)
2023-03-15 21:00:39.626 37 ERROR keystone.server.flask.application   File "/var/lib/kolla/venv/lib/python3.9/site-packages/flask_restful/__init__.py", line 467, in wrapper
2023-03-15 21:00:39.626 37 ERROR keystone.server.flask.application     resp = resource(*args, **kwargs)
2023-03-15 21:00:39.626 37 ERROR keystone.server.flask.application   File "/var/lib/kolla/venv/lib/python3.9/site-packages/flask/views.py", line 107, in view
2023-03-15 21:00:39.626 37 ERROR keystone.server.flask.application     return current_app.ensure_sync(self.dispatch_request)(**kwargs)
2023-03-15 21:00:39.626 37 ERROR keystone.server.flask.application   File "/var/lib/kolla/venv/lib/python3.9/site-packages/flask_restful/__init__.py", line 582, in dispatch_request
2023-03-15 21:00:39.626 37 ERROR keystone.server.flask.application     resp = meth(*args, **kwargs)
2023-03-15 21:00:39.626 37 ERROR keystone.server.flask.application   File "/var/lib/kolla/venv/lib/python3.9/site-packages/keystone/api/users.py", line 182, in get
2023-03-15 21:00:39.626 37 ERROR keystone.server.flask.application     return self._get_user(user_id)
2023-03-15 21:00:39.626 37 ERROR keystone.server.flask.application   File "/var/lib/kolla/venv/lib/python3.9/site-packages/keystone/api/users.py", line 194, in _get_user
2023-03-15 21:00:39.626 37 ERROR keystone.server.flask.application     ref = PROVIDERS.identity_api.get_user(user_id)
2023-03-15 21:00:39.626 37 ERROR keystone.server.flask.application   File "/var/lib/kolla/venv/lib/python3.9/site-packages/keystone/common/manager.py", line 115, in wrapped
2023-03-15 21:00:39.626 37 ERROR keystone.server.flask.application     __ret_val = __f(*args, **kwargs)
2023-03-15 21:00:39.626 37 ERROR keystone.server.flask.application   File "/var/lib/kolla/venv/lib/python3.9/site-packages/keystone/identity/core.py", line 414, in wrapper
2023-03-15 21:00:39.626 37 ERROR keystone.server.flask.application     return f(self, *args, **kwargs)
2023-03-15 21:00:39.626 37 ERROR keystone.server.flask.application   File "/var/lib/kolla/venv/lib/python3.9/site-packages/keystone/identity/core.py", line 424, in wrapper
2023-03-15 21:00:39.626 37 ERROR keystone.server.flask.application     return f(self, *args, **kwargs)
2023-03-15 21:00:39.626 37 ERROR keystone.server.flask.application   File "/var/lib/kolla/venv/lib/python3.9/site-packages/decorator.py", line 232, in fun
2023-03-15 21:00:39.626 37 ERROR keystone.server.flask.application     return caller(func, *(extras + args), **kw)
2023-03-15 21:00:39.626 37 ERROR keystone.server.flask.application   File "/var/lib/kolla/venv/lib/python3.9/site-packages/dogpile/cache/region.py", line 1577, in get_or_create_for_user_func
2023-03-15 21:00:39.626 37 ERROR keystone.server.flask.application     return self.get_or_create(
2023-03-15 21:00:39.626 37 ERROR keystone.server.flask.application   File "/var/lib/kolla/venv/lib/python3.9/site-packages/dogpile/cache/region.py", line 1042, in get_or_create
2023-03-15 21:00:39.626 37 ERROR keystone.server.flask.application     with Lock(
2023-03-15 21:00:39.626 37 ERROR keystone.server.flask.application   File "/var/lib/kolla/venv/lib/python3.9/site-packages/dogpile/lock.py", line 185, in __enter__
2023-03-15 21:00:39.626 37 ERROR keystone.server.flask.application     return self._enter()
2023-03-15 21:00:39.626 37 ERROR keystone.server.flask.application   File "/var/lib/kolla/venv/lib/python3.9/site-packages/dogpile/lock.py", line 94, in _enter
2023-03-15 21:00:39.626 37 ERROR keystone.server.flask.application     generated = self._enter_create(value, createdtime)
2023-03-15 21:00:39.626 37 ERROR keystone.server.flask.application   File "/var/lib/kolla/venv/lib/python3.9/site-packages/dogpile/lock.py", line 178, in _enter_create
2023-03-15 21:00:39.626 37 ERROR keystone.server.flask.application     return self.creator()
2023-03-15 21:00:39.626 37 ERROR keystone.server.flask.application   File "/var/lib/kolla/venv/lib/python3.9/site-packages/dogpile/cache/region.py", line 995, in gen_value
2023-03-15 21:00:39.626 37 ERROR keystone.server.flask.application     created_value = creator(
2023-03-15 21:00:39.626 37 ERROR keystone.server.flask.application   File "/var/lib/kolla/venv/lib/python3.9/site-packages/keystone/identity/core.py", line 1011, in get_user
2023-03-15 21:00:39.626 37 ERROR keystone.server.flask.application     ref = driver.get_user(entity_id)
2023-03-15 21:00:39.626 37 ERROR keystone.server.flask.application   File "/var/lib/kolla/venv/lib/python3.9/site-packages/keystone/identity/backends/sql.py", line 200, in get_user
2023-03-15 21:00:39.626 37 ERROR keystone.server.flask.application     self._get_user(session, user_id).to_dict())
2023-03-15 21:00:39.626 37 ERROR keystone.server.flask.application   File "/var/lib/kolla/venv/lib/python3.9/site-packages/keystone/identity/backends/sql.py", line 194, in _get_user
2023-03-15 21:00:39.626 37 ERROR keystone.server.flask.application     raise exception.UserNotFound(user_id=user_id)
2023-03-15 21:00:39.626 37 ERROR keystone.server.flask.application keystone.exception.UserNotFound: Could not find user: neutron.
2023-03-15 21:00:39.626 37 ERROR keystone.server.flask.application 
2023-03-15 21:00:40.399 39 ERROR keystone.server.flask.application [None req-d3134296-69d6-4805-b20b-9341563960b2 85b537ff22d246d29b67535eecf74526 - - all default -] Could not find project: service.: keystone.exception.ProjectNotFound: Could not find project: service.
2023-03-15 21:00:40.399 39 ERROR keystone.server.flask.application Traceback (most recent call last):
2023-03-15 21:00:40.399 39 ERROR keystone.server.flask.application   File "/var/lib/kolla/venv/lib/python3.9/site-packages/flask/app.py", line 1820, in full_dispatch_request
2023-03-15 21:00:40.399 39 ERROR keystone.server.flask.application     rv = self.dispatch_request()
2023-03-15 21:00:40.399 39 ERROR keystone.server.flask.application   File "/var/lib/kolla/venv/lib/python3.9/site-packages/flask/app.py", line 1796, in dispatch_request
2023-03-15 21:00:40.399 39 ERROR keystone.server.flask.application     return self.ensure_sync(self.view_functions[rule.endpoint])(**view_args)
2023-03-15 21:00:40.399 39 ERROR keystone.server.flask.application   File "/var/lib/kolla/venv/lib/python3.9/site-packages/flask_restful/__init__.py", line 467, in wrapper
2023-03-15 21:00:40.399 39 ERROR keystone.server.flask.application     resp = resource(*args, **kwargs)
2023-03-15 21:00:40.399 39 ERROR keystone.server.flask.application   File "/var/lib/kolla/venv/lib/python3.9/site-packages/flask/views.py", line 107, in view
2023-03-15 21:00:40.399 39 ERROR keystone.server.flask.application     return current_app.ensure_sync(self.dispatch_request)(**kwargs)
2023-03-15 21:00:40.399 39 ERROR keystone.server.flask.application   File "/var/lib/kolla/venv/lib/python3.9/site-packages/flask_restful/__init__.py", line 582, in dispatch_request
2023-03-15 21:00:40.399 39 ERROR keystone.server.flask.application     resp = meth(*args, **kwargs)
2023-03-15 21:00:40.399 39 ERROR keystone.server.flask.application   File "/var/lib/kolla/venv/lib/python3.9/site-packages/keystone/api/projects.py", line 151, in get
2023-03-15 21:00:40.399 39 ERROR keystone.server.flask.application     return self._get_project(project_id)
2023-03-15 21:00:40.399 39 ERROR keystone.server.flask.application   File "/var/lib/kolla/venv/lib/python3.9/site-packages/keystone/api/projects.py", line 107, in _get_project
2023-03-15 21:00:40.399 39 ERROR keystone.server.flask.application     project = PROVIDERS.resource_api.get_project(project_id)
2023-03-15 21:00:40.399 39 ERROR keystone.server.flask.application   File "/var/lib/kolla/venv/lib/python3.9/site-packages/keystone/common/manager.py", line 115, in wrapped
2023-03-15 21:00:40.399 39 ERROR keystone.server.flask.application     __ret_val = __f(*args, **kwargs)
2023-03-15 21:00:40.399 39 ERROR keystone.server.flask.application   File "/var/lib/kolla/venv/lib/python3.9/site-packages/decorator.py", line 232, in fun
2023-03-15 21:00:40.399 39 ERROR keystone.server.flask.application     return caller(func, *(extras + args), **kw)
2023-03-15 21:00:40.399 39 ERROR keystone.server.flask.application   File "/var/lib/kolla/venv/lib/python3.9/site-packages/dogpile/cache/region.py", line 1577, in get_or_create_for_user_func
2023-03-15 21:00:40.399 39 ERROR keystone.server.flask.application     return self.get_or_create(
2023-03-15 21:00:40.399 39 ERROR keystone.server.flask.application   File "/var/lib/kolla/venv/lib/python3.9/site-packages/dogpile/cache/region.py", line 1042, in get_or_create
2023-03-15 21:00:40.399 39 ERROR keystone.server.flask.application     with Lock(
2023-03-15 21:00:40.399 39 ERROR keystone.server.flask.application   File "/var/lib/kolla/venv/lib/python3.9/site-packages/dogpile/lock.py", line 185, in __enter__
2023-03-15 21:00:40.399 39 ERROR keystone.server.flask.application     return self._enter()
2023-03-15 21:00:40.399 39 ERROR keystone.server.flask.application   File "/var/lib/kolla/venv/lib/python3.9/site-packages/dogpile/lock.py", line 94, in _enter
2023-03-15 21:00:40.399 39 ERROR keystone.server.flask.application     generated = self._enter_create(value, createdtime)
2023-03-15 21:00:40.399 39 ERROR keystone.server.flask.application   File "/var/lib/kolla/venv/lib/python3.9/site-packages/dogpile/lock.py", line 178, in _enter_create
2023-03-15 21:00:40.399 39 ERROR keystone.server.flask.application     return self.creator()
2023-03-15 21:00:40.399 39 ERROR keystone.server.flask.application   File "/var/lib/kolla/venv/lib/python3.9/site-packages/dogpile/cache/region.py", line 995, in gen_value
2023-03-15 21:00:40.399 39 ERROR keystone.server.flask.application     created_value = creator(
2023-03-15 21:00:40.399 39 ERROR keystone.server.flask.application   File "/var/lib/kolla/venv/lib/python3.9/site-packages/keystone/resource/core.py", line 903, in get_project
2023-03-15 21:00:40.399 39 ERROR keystone.server.flask.application     return self.driver.get_project(project_id)
2023-03-15 21:00:40.399 39 ERROR keystone.server.flask.application   File "/var/lib/kolla/venv/lib/python3.9/site-packages/keystone/resource/backends/sql.py", line 49, in get_project
2023-03-15 21:00:40.399 39 ERROR keystone.server.flask.application     return self._get_project(session, project_id).to_dict()
2023-03-15 21:00:40.399 39 ERROR keystone.server.flask.application   File "/var/lib/kolla/venv/lib/python3.9/site-packages/keystone/resource/backends/sql.py", line 44, in _get_project
2023-03-15 21:00:40.399 39 ERROR keystone.server.flask.application     raise exception.ProjectNotFound(project_id=project_id)
2023-03-15 21:00:40.399 39 ERROR keystone.server.flask.application keystone.exception.ProjectNotFound: Could not find project: service.
2023-03-15 21:00:40.399 39 ERROR keystone.server.flask.application 
2023-03-16 11:45:45.371 37 WARNING py.warnings [None req-519d56c5-9981-46d0-97d2-27131950d2a0 85b537ff22d246d29b67535eecf74526 0b9bd6ed02d24d17a7e0bc0ae7e0345e - - default default] /var/lib/kolla/venv/lib/python3.9/site-packages/oslo_policy/policy.py:1129: UserWarning: Policy "identity:list_domains": "role:reader and system_scope:all" failed scope check. The token used to make the request was project scoped but the policy requires ['system'] scope. This behavior may change in the future where using the intended scope is required
  warnings.warn(msg)

2023-03-16 11:45:45.602 38 WARNING py.warnings [None req-793a809b-b872-4ae4-9b1c-5343e1dd2bee 85b537ff22d246d29b67535eecf74526 0b9bd6ed02d24d17a7e0bc0ae7e0345e - - default default] /var/lib/kolla/venv/lib/python3.9/site-packages/oslo_policy/policy.py:1129: UserWarning: Policy "identity:create_project": "(role:admin and system_scope:all) or (role:admin and domain_id:%(target.project.domain_id)s)" failed scope check. The token used to make the request was project scoped but the policy requires ['system', 'domain'] scope. This behavior may change in the future where using the intended scope is required
  warnings.warn(msg)

2023-03-16 11:45:45.894 39 WARNING py.warnings [None req-945dc496-26d4-4dfe-b271-69e25776e7ae 85b537ff22d246d29b67535eecf74526 0b9bd6ed02d24d17a7e0bc0ae7e0345e - - default default] /var/lib/kolla/venv/lib/python3.9/site-packages/oslo_policy/policy.py:1129: UserWarning: Policy "identity:create_user": "(role:admin and system_scope:all) or (role:admin and token.domain.id:%(target.user.domain_id)s)" failed scope check. The token used to make the request was project scoped but the policy requires ['system', 'domain'] scope. This behavior may change in the future where using the intended scope is required
  warnings.warn(msg)

2023-03-16 11:45:46.662 37 WARNING py.warnings [None req-9bf96e99-e0c9-4e90-816d-8330f465ddf7 85b537ff22d246d29b67535eecf74526 0b9bd6ed02d24d17a7e0bc0ae7e0345e - - default default] /var/lib/kolla/venv/lib/python3.9/site-packages/oslo_policy/policy.py:1129: UserWarning: Policy "identity:list_roles": "role:reader and system_scope:all" failed scope check. The token used to make the request was project scoped but the policy requires ['system'] scope. This behavior may change in the future where using the intended scope is required
  warnings.warn(msg)

2023-03-16 11:45:46.980 38 WARNING py.warnings [None req-7b0b6af4-19be-4d3b-b33b-eaeb604cefac 85b537ff22d246d29b67535eecf74526 0b9bd6ed02d24d17a7e0bc0ae7e0345e - - default default] /var/lib/kolla/venv/lib/python3.9/site-packages/oslo_policy/policy.py:1129: UserWarning: Policy "identity:create_grant": "(role:admin and system_scope:all) or ((role:admin and domain_id:%(target.user.domain_id)s and domain_id:%(target.project.domain_id)s) or (role:admin and domain_id:%(target.user.domain_id)s and domain_id:%(target.domain.id)s) or (role:admin and domain_id:%(target.group.domain_id)s and domain_id:%(target.project.domain_id)s) or (role:admin and domain_id:%(target.group.domain_id)s and domain_id:%(target.domain.id)s)) and (domain_id:%(target.role.domain_id)s or None:%(target.role.domain_id)s)" failed scope check. The token used to make the request was project scoped but the policy requires ['system', 'domain'] scope. This behavior may change in the future where using the intended scope is required
  warnings.warn(msg)

2023-03-16 11:45:48.050 37 WARNING py.warnings [None req-2e37418c-77a2-411e-a552-d4cf2cc5be3f 85b537ff22d246d29b67535eecf74526 0b9bd6ed02d24d17a7e0bc0ae7e0345e - - default default] /var/lib/kolla/venv/lib/python3.9/site-packages/oslo_policy/policy.py:1129: UserWarning: Policy "identity:create_project": "(role:admin and system_scope:all) or (role:admin and domain_id:%(target.project.domain_id)s)" failed scope check. The token used to make the request was project scoped but the policy requires ['system', 'domain'] scope. This behavior may change in the future where using the intended scope is required
  warnings.warn(msg)

2023-03-16 11:45:48.478 38 WARNING py.warnings [None req-22f4a163-d839-4d99-aebd-bfb57ce36818 85b537ff22d246d29b67535eecf74526 0b9bd6ed02d24d17a7e0bc0ae7e0345e - - default default] /var/lib/kolla/venv/lib/python3.9/site-packages/oslo_policy/policy.py:1129: UserWarning: Policy "identity:create_user": "(role:admin and system_scope:all) or (role:admin and token.domain.id:%(target.user.domain_id)s)" failed scope check. The token used to make the request was project scoped but the policy requires ['system', 'domain'] scope. This behavior may change in the future where using the intended scope is required
  warnings.warn(msg)

2023-03-16 11:45:49.424 39 WARNING py.warnings [None req-1695ed09-7dd9-455d-b52f-d6d20207318d 85b537ff22d246d29b67535eecf74526 0b9bd6ed02d24d17a7e0bc0ae7e0345e - - default default] /var/lib/kolla/venv/lib/python3.9/site-packages/oslo_policy/policy.py:1129: UserWarning: Policy "identity:list_roles": "role:reader and system_scope:all" failed scope check. The token used to make the request was project scoped but the policy requires ['system'] scope. This behavior may change in the future where using the intended scope is required
  warnings.warn(msg)

2023-03-16 11:45:49.758 37 WARNING py.warnings [None req-9acee7af-979e-4708-869d-ca4ad7c1b741 85b537ff22d246d29b67535eecf74526 0b9bd6ed02d24d17a7e0bc0ae7e0345e - - default default] /var/lib/kolla/venv/lib/python3.9/site-packages/oslo_policy/policy.py:1129: UserWarning: Policy "identity:create_grant": "(role:admin and system_scope:all) or ((role:admin and domain_id:%(target.user.domain_id)s and domain_id:%(target.project.domain_id)s) or (role:admin and domain_id:%(target.user.domain_id)s and domain_id:%(target.domain.id)s) or (role:admin and domain_id:%(target.group.domain_id)s and domain_id:%(target.project.domain_id)s) or (role:admin and domain_id:%(target.group.domain_id)s and domain_id:%(target.domain.id)s)) and (domain_id:%(target.role.domain_id)s or None:%(target.role.domain_id)s)" failed scope check. The token used to make the request was project scoped but the policy requires ['system', 'domain'] scope. This behavior may change in the future where using the intended scope is required
  warnings.warn(msg)

2023-03-16 11:45:50.004 38 WARNING py.warnings [None req-23f1148d-9598-4a59-8c32-5837f2971d6f 85b537ff22d246d29b67535eecf74526 0b9bd6ed02d24d17a7e0bc0ae7e0345e - - default default] /var/lib/kolla/venv/lib/python3.9/site-packages/oslo_policy/policy.py:1129: UserWarning: Policy "identity:list_roles": "role:reader and system_scope:all" failed scope check. The token used to make the request was project scoped but the policy requires ['system'] scope. This behavior may change in the future where using the intended scope is required
  warnings.warn(msg)

2023-03-16 11:45:50.262 39 WARNING py.warnings [None req-9cb615d8-65ef-446c-9bc6-5444e795e275 85b537ff22d246d29b67535eecf74526 0b9bd6ed02d24d17a7e0bc0ae7e0345e - - default default] /var/lib/kolla/venv/lib/python3.9/site-packages/oslo_policy/policy.py:1129: UserWarning: Policy "identity:create_grant": "(role:admin and system_scope:all) or ((role:admin and domain_id:%(target.user.domain_id)s and domain_id:%(target.project.domain_id)s) or (role:admin and domain_id:%(target.user.domain_id)s and domain_id:%(target.domain.id)s) or (role:admin and domain_id:%(target.group.domain_id)s and domain_id:%(target.project.domain_id)s) or (role:admin and domain_id:%(target.group.domain_id)s and domain_id:%(target.domain.id)s)) and (domain_id:%(target.role.domain_id)s or None:%(target.role.domain_id)s)" failed scope check. The token used to make the request was project scoped but the policy requires ['system', 'domain'] scope. This behavior may change in the future where using the intended scope is required
  warnings.warn(msg)

2023-03-16 11:45:52.491 38 WARNING py.warnings [None req-9a0bbd58-ed40-4bbe-bce5-96036ccc8de1 85b537ff22d246d29b67535eecf74526 0b9bd6ed02d24d17a7e0bc0ae7e0345e - - default default] /var/lib/kolla/venv/lib/python3.9/site-packages/oslo_policy/policy.py:1129: UserWarning: Policy "identity:create_system_grant_for_user": "role:admin and system_scope:all" failed scope check. The token used to make the request was project scoped but the policy requires ['system'] scope. This behavior may change in the future where using the intended scope is required
  warnings.warn(msg)

