2023-02-14 03:19:22.273 23 INFO alembic.runtime.migration [-] Context impl MySQLImpl.
2023-02-14 03:19:22.275 23 INFO alembic.runtime.migration [-] Will assume non-transactional DDL.
2023-02-14 03:19:22.307 23 INFO alembic.runtime.migration [-] Context impl MySQLImpl.
2023-02-14 03:19:22.308 23 INFO alembic.runtime.migration [-] Will assume non-transactional DDL.
2023-02-14 03:19:22.357 23 INFO alembic.runtime.migration [-] Running upgrade  -> 27e647c0fad4, Initial version.
2023-02-14 03:19:23.734 23 INFO alembic.runtime.migration [-] Running upgrade 27e647c0fad4 -> e25ffa003242, Initial no-op Yoga contract migration.
2023-02-14 03:19:23.742 23 INFO alembic.runtime.migration [-] Running upgrade 27e647c0fad4 -> 29e87d24a316, Initial no-op Yoga expand migration.
2023-02-14 03:19:31.446 8 INFO keystone.common.fernet_utils [-] Created a new temporary key: /etc/keystone/fernet-keys/0.tmp
2023-02-14 03:19:31.449 8 INFO keystone.common.fernet_utils [-] Become a valid new key: /etc/keystone/fernet-keys/0
2023-02-14 03:19:31.451 8 INFO keystone.common.fernet_utils [-] Starting key rotation with 1 key files: ['/etc/keystone/fernet-keys/0']
2023-02-14 03:19:31.452 8 INFO keystone.common.fernet_utils [-] Created a new temporary key: /etc/keystone/fernet-keys/0.tmp
2023-02-14 03:19:31.453 8 INFO keystone.common.fernet_utils [-] Current primary key is: 0
2023-02-14 03:19:31.454 8 INFO keystone.common.fernet_utils [-] Next primary key will be: 1
2023-02-14 03:19:31.454 8 INFO keystone.common.fernet_utils [-] Promoted key 0 to be the primary: 1
2023-02-14 03:19:31.455 8 INFO keystone.common.fernet_utils [-] Become a valid new key: /etc/keystone/fernet-keys/0
2023-02-14 03:19:48.720 32 INFO keystone.cmd.bootstrap [None req-6d93460b-c0b6-414a-98ee-6c524deeb583 - - - - - -] Created domain default
2023-02-14 03:19:48.774 32 INFO keystone.cmd.bootstrap [None req-6d93460b-c0b6-414a-98ee-6c524deeb583 - - - - - -] Created project admin
2023-02-14 03:19:49.371 32 INFO keystone.cmd.bootstrap [None req-6d93460b-c0b6-414a-98ee-6c524deeb583 - - - - - -] Created user admin
2023-02-14 03:19:49.390 32 INFO keystone.cmd.bootstrap [None req-6d93460b-c0b6-414a-98ee-6c524deeb583 - - - - - -] Created role reader
2023-02-14 03:19:49.406 32 INFO keystone.cmd.bootstrap [None req-6d93460b-c0b6-414a-98ee-6c524deeb583 - - - - - -] Created role member
2023-02-14 03:19:49.434 32 INFO keystone.cmd.bootstrap [None req-6d93460b-c0b6-414a-98ee-6c524deeb583 - - - - - -] Created implied role where d06ab6db23544f2a887e83cf49ce9841 implies c1be740122314f78bdb161d765835677
2023-02-14 03:19:49.446 32 INFO keystone.cmd.bootstrap [None req-6d93460b-c0b6-414a-98ee-6c524deeb583 - - - - - -] Created role admin
2023-02-14 03:19:49.471 32 INFO keystone.cmd.bootstrap [None req-6d93460b-c0b6-414a-98ee-6c524deeb583 - - - - - -] Created implied role where d76639151c3d4aa680bc550f75433662 implies d06ab6db23544f2a887e83cf49ce9841
2023-02-14 03:19:49.486 32 INFO keystone.cmd.bootstrap [None req-6d93460b-c0b6-414a-98ee-6c524deeb583 - - - - - -] Granted role admin on project admin to user admin.
2023-02-14 03:19:49.493 32 INFO keystone.cmd.bootstrap [None req-6d93460b-c0b6-414a-98ee-6c524deeb583 - - - - - -] Granted role admin on the system to user admin.
2023-02-14 03:19:49.511 32 WARNING py.warnings [None req-6d93460b-c0b6-414a-98ee-6c524deeb583 - - - - - -] /var/lib/kolla/venv/lib/python3.9/site-packages/pycadf/identifier.py:71: UserWarning: Invalid uuid: RegionOne. To ensure interoperability, identifiers should be a valid uuid.
  warnings.warn(('Invalid uuid: %s. To ensure interoperability, '

2023-02-14 03:19:49.517 32 INFO keystone.cmd.bootstrap [None req-6d93460b-c0b6-414a-98ee-6c524deeb583 - - - - - -] Created region RegionOne
2023-02-14 03:19:49.557 32 INFO keystone.cmd.bootstrap [None req-6d93460b-c0b6-414a-98ee-6c524deeb583 - - - - - -] Created public endpoint http://169.16.1.142:5000
2023-02-14 03:19:49.568 32 INFO keystone.cmd.bootstrap [None req-6d93460b-c0b6-414a-98ee-6c524deeb583 - - - - - -] Created internal endpoint http://169.16.1.142:5000
2023-02-14 03:20:06.942 38 WARNING keystone.common.rbac_enforcer.enforcer [None req-cd1fd01d-ef58-482f-bdf7-ba7cdbe5b2ba 848faf0af3eb4aa7802674da265877bd - - all default -] Deprecated policy rules found. Use oslopolicy-policy-generator and oslopolicy-policy-upgrade to detect and resolve deprecated policies in your configuration.
2023-02-14 03:20:07.368 37 WARNING keystone.common.rbac_enforcer.enforcer [None req-4179c62d-ee92-4093-a5ea-349a7a67c6a8 848faf0af3eb4aa7802674da265877bd - - all default -] Deprecated policy rules found. Use oslopolicy-policy-generator and oslopolicy-policy-upgrade to detect and resolve deprecated policies in your configuration.
2023-02-14 05:14:02.803 37 ERROR keystone.server.flask.application [None req-7f7f0688-81b2-42ef-b41d-a28d915c4311 848faf0af3eb4aa7802674da265877bd - - all default -] Could not find project: service.: keystone.exception.ProjectNotFound: Could not find project: service.
2023-02-14 05:14:02.803 37 ERROR keystone.server.flask.application Traceback (most recent call last):
2023-02-14 05:14:02.803 37 ERROR keystone.server.flask.application   File "/var/lib/kolla/venv/lib/python3.9/site-packages/flask/app.py", line 1820, in full_dispatch_request
2023-02-14 05:14:02.803 37 ERROR keystone.server.flask.application     rv = self.dispatch_request()
2023-02-14 05:14:02.803 37 ERROR keystone.server.flask.application   File "/var/lib/kolla/venv/lib/python3.9/site-packages/flask/app.py", line 1796, in dispatch_request
2023-02-14 05:14:02.803 37 ERROR keystone.server.flask.application     return self.ensure_sync(self.view_functions[rule.endpoint])(**view_args)
2023-02-14 05:14:02.803 37 ERROR keystone.server.flask.application   File "/var/lib/kolla/venv/lib/python3.9/site-packages/flask_restful/__init__.py", line 467, in wrapper
2023-02-14 05:14:02.803 37 ERROR keystone.server.flask.application     resp = resource(*args, **kwargs)
2023-02-14 05:14:02.803 37 ERROR keystone.server.flask.application   File "/var/lib/kolla/venv/lib/python3.9/site-packages/flask/views.py", line 107, in view
2023-02-14 05:14:02.803 37 ERROR keystone.server.flask.application     return current_app.ensure_sync(self.dispatch_request)(**kwargs)
2023-02-14 05:14:02.803 37 ERROR keystone.server.flask.application   File "/var/lib/kolla/venv/lib/python3.9/site-packages/flask_restful/__init__.py", line 582, in dispatch_request
2023-02-14 05:14:02.803 37 ERROR keystone.server.flask.application     resp = meth(*args, **kwargs)
2023-02-14 05:14:02.803 37 ERROR keystone.server.flask.application   File "/var/lib/kolla/venv/lib/python3.9/site-packages/keystone/api/projects.py", line 151, in get
2023-02-14 05:14:02.803 37 ERROR keystone.server.flask.application     return self._get_project(project_id)
2023-02-14 05:14:02.803 37 ERROR keystone.server.flask.application   File "/var/lib/kolla/venv/lib/python3.9/site-packages/keystone/api/projects.py", line 107, in _get_project
2023-02-14 05:14:02.803 37 ERROR keystone.server.flask.application     project = PROVIDERS.resource_api.get_project(project_id)
2023-02-14 05:14:02.803 37 ERROR keystone.server.flask.application   File "/var/lib/kolla/venv/lib/python3.9/site-packages/keystone/common/manager.py", line 115, in wrapped
2023-02-14 05:14:02.803 37 ERROR keystone.server.flask.application     __ret_val = __f(*args, **kwargs)
2023-02-14 05:14:02.803 37 ERROR keystone.server.flask.application   File "/var/lib/kolla/venv/lib/python3.9/site-packages/decorator.py", line 232, in fun
2023-02-14 05:14:02.803 37 ERROR keystone.server.flask.application     return caller(func, *(extras + args), **kw)
2023-02-14 05:14:02.803 37 ERROR keystone.server.flask.application   File "/var/lib/kolla/venv/lib/python3.9/site-packages/dogpile/cache/region.py", line 1577, in get_or_create_for_user_func
2023-02-14 05:14:02.803 37 ERROR keystone.server.flask.application     return self.get_or_create(
2023-02-14 05:14:02.803 37 ERROR keystone.server.flask.application   File "/var/lib/kolla/venv/lib/python3.9/site-packages/dogpile/cache/region.py", line 1042, in get_or_create
2023-02-14 05:14:02.803 37 ERROR keystone.server.flask.application     with Lock(
2023-02-14 05:14:02.803 37 ERROR keystone.server.flask.application   File "/var/lib/kolla/venv/lib/python3.9/site-packages/dogpile/lock.py", line 185, in __enter__
2023-02-14 05:14:02.803 37 ERROR keystone.server.flask.application     return self._enter()
2023-02-14 05:14:02.803 37 ERROR keystone.server.flask.application   File "/var/lib/kolla/venv/lib/python3.9/site-packages/dogpile/lock.py", line 94, in _enter
2023-02-14 05:14:02.803 37 ERROR keystone.server.flask.application     generated = self._enter_create(value, createdtime)
2023-02-14 05:14:02.803 37 ERROR keystone.server.flask.application   File "/var/lib/kolla/venv/lib/python3.9/site-packages/dogpile/lock.py", line 178, in _enter_create
2023-02-14 05:14:02.803 37 ERROR keystone.server.flask.application     return self.creator()
2023-02-14 05:14:02.803 37 ERROR keystone.server.flask.application   File "/var/lib/kolla/venv/lib/python3.9/site-packages/dogpile/cache/region.py", line 995, in gen_value
2023-02-14 05:14:02.803 37 ERROR keystone.server.flask.application     created_value = creator(
2023-02-14 05:14:02.803 37 ERROR keystone.server.flask.application   File "/var/lib/kolla/venv/lib/python3.9/site-packages/keystone/resource/core.py", line 903, in get_project
2023-02-14 05:14:02.803 37 ERROR keystone.server.flask.application     return self.driver.get_project(project_id)
2023-02-14 05:14:02.803 37 ERROR keystone.server.flask.application   File "/var/lib/kolla/venv/lib/python3.9/site-packages/keystone/resource/backends/sql.py", line 49, in get_project
2023-02-14 05:14:02.803 37 ERROR keystone.server.flask.application     return self._get_project(session, project_id).to_dict()
2023-02-14 05:14:02.803 37 ERROR keystone.server.flask.application   File "/var/lib/kolla/venv/lib/python3.9/site-packages/keystone/resource/backends/sql.py", line 44, in _get_project
2023-02-14 05:14:02.803 37 ERROR keystone.server.flask.application     raise exception.ProjectNotFound(project_id=project_id)
2023-02-14 05:14:02.803 37 ERROR keystone.server.flask.application keystone.exception.ProjectNotFound: Could not find project: service.
2023-02-14 05:14:02.803 37 ERROR keystone.server.flask.application 
2023-02-14 05:14:11.652 37 ERROR keystone.server.flask.application [None req-d1958756-7d27-4e78-92bc-4e40884f9e89 848faf0af3eb4aa7802674da265877bd - - all default -] Could not find project: service.: keystone.exception.ProjectNotFound: Could not find project: service.
2023-02-14 05:14:11.652 37 ERROR keystone.server.flask.application Traceback (most recent call last):
2023-02-14 05:14:11.652 37 ERROR keystone.server.flask.application   File "/var/lib/kolla/venv/lib/python3.9/site-packages/flask/app.py", line 1820, in full_dispatch_request
2023-02-14 05:14:11.652 37 ERROR keystone.server.flask.application     rv = self.dispatch_request()
2023-02-14 05:14:11.652 37 ERROR keystone.server.flask.application   File "/var/lib/kolla/venv/lib/python3.9/site-packages/flask/app.py", line 1796, in dispatch_request
2023-02-14 05:14:11.652 37 ERROR keystone.server.flask.application     return self.ensure_sync(self.view_functions[rule.endpoint])(**view_args)
2023-02-14 05:14:11.652 37 ERROR keystone.server.flask.application   File "/var/lib/kolla/venv/lib/python3.9/site-packages/flask_restful/__init__.py", line 467, in wrapper
2023-02-14 05:14:11.652 37 ERROR keystone.server.flask.application     resp = resource(*args, **kwargs)
2023-02-14 05:14:11.652 37 ERROR keystone.server.flask.application   File "/var/lib/kolla/venv/lib/python3.9/site-packages/flask/views.py", line 107, in view
2023-02-14 05:14:11.652 37 ERROR keystone.server.flask.application     return current_app.ensure_sync(self.dispatch_request)(**kwargs)
2023-02-14 05:14:11.652 37 ERROR keystone.server.flask.application   File "/var/lib/kolla/venv/lib/python3.9/site-packages/flask_restful/__init__.py", line 582, in dispatch_request
2023-02-14 05:14:11.652 37 ERROR keystone.server.flask.application     resp = meth(*args, **kwargs)
2023-02-14 05:14:11.652 37 ERROR keystone.server.flask.application   File "/var/lib/kolla/venv/lib/python3.9/site-packages/keystone/api/projects.py", line 151, in get
2023-02-14 05:14:11.652 37 ERROR keystone.server.flask.application     return self._get_project(project_id)
2023-02-14 05:14:11.652 37 ERROR keystone.server.flask.application   File "/var/lib/kolla/venv/lib/python3.9/site-packages/keystone/api/projects.py", line 107, in _get_project
2023-02-14 05:14:11.652 37 ERROR keystone.server.flask.application     project = PROVIDERS.resource_api.get_project(project_id)
2023-02-14 05:14:11.652 37 ERROR keystone.server.flask.application   File "/var/lib/kolla/venv/lib/python3.9/site-packages/keystone/common/manager.py", line 115, in wrapped
2023-02-14 05:14:11.652 37 ERROR keystone.server.flask.application     __ret_val = __f(*args, **kwargs)
2023-02-14 05:14:11.652 37 ERROR keystone.server.flask.application   File "/var/lib/kolla/venv/lib/python3.9/site-packages/decorator.py", line 232, in fun
2023-02-14 05:14:11.652 37 ERROR keystone.server.flask.application     return caller(func, *(extras + args), **kw)
2023-02-14 05:14:11.652 37 ERROR keystone.server.flask.application   File "/var/lib/kolla/venv/lib/python3.9/site-packages/dogpile/cache/region.py", line 1577, in get_or_create_for_user_func
2023-02-14 05:14:11.652 37 ERROR keystone.server.flask.application     return self.get_or_create(
2023-02-14 05:14:11.652 37 ERROR keystone.server.flask.application   File "/var/lib/kolla/venv/lib/python3.9/site-packages/dogpile/cache/region.py", line 1042, in get_or_create
2023-02-14 05:14:11.652 37 ERROR keystone.server.flask.application     with Lock(
2023-02-14 05:14:11.652 37 ERROR keystone.server.flask.application   File "/var/lib/kolla/venv/lib/python3.9/site-packages/dogpile/lock.py", line 185, in __enter__
2023-02-14 05:14:11.652 37 ERROR keystone.server.flask.application     return self._enter()
2023-02-14 05:14:11.652 37 ERROR keystone.server.flask.application   File "/var/lib/kolla/venv/lib/python3.9/site-packages/dogpile/lock.py", line 94, in _enter
2023-02-14 05:14:11.652 37 ERROR keystone.server.flask.application     generated = self._enter_create(value, createdtime)
2023-02-14 05:14:11.652 37 ERROR keystone.server.flask.application   File "/var/lib/kolla/venv/lib/python3.9/site-packages/dogpile/lock.py", line 178, in _enter_create
2023-02-14 05:14:11.652 37 ERROR keystone.server.flask.application     return self.creator()
2023-02-14 05:14:11.652 37 ERROR keystone.server.flask.application   File "/var/lib/kolla/venv/lib/python3.9/site-packages/dogpile/cache/region.py", line 995, in gen_value
2023-02-14 05:14:11.652 37 ERROR keystone.server.flask.application     created_value = creator(
2023-02-14 05:14:11.652 37 ERROR keystone.server.flask.application   File "/var/lib/kolla/venv/lib/python3.9/site-packages/keystone/resource/core.py", line 903, in get_project
2023-02-14 05:14:11.652 37 ERROR keystone.server.flask.application     return self.driver.get_project(project_id)
2023-02-14 05:14:11.652 37 ERROR keystone.server.flask.application   File "/var/lib/kolla/venv/lib/python3.9/site-packages/keystone/resource/backends/sql.py", line 49, in get_project
2023-02-14 05:14:11.652 37 ERROR keystone.server.flask.application     return self._get_project(session, project_id).to_dict()
2023-02-14 05:14:11.652 37 ERROR keystone.server.flask.application   File "/var/lib/kolla/venv/lib/python3.9/site-packages/keystone/resource/backends/sql.py", line 44, in _get_project
2023-02-14 05:14:11.652 37 ERROR keystone.server.flask.application     raise exception.ProjectNotFound(project_id=project_id)
2023-02-14 05:14:11.652 37 ERROR keystone.server.flask.application keystone.exception.ProjectNotFound: Could not find project: service.
2023-02-14 05:14:11.652 37 ERROR keystone.server.flask.application 
2023-02-14 05:14:26.510 37 ERROR keystone.server.flask.application [None req-1ce617cc-8274-4092-bfea-4e166083c5cb 848faf0af3eb4aa7802674da265877bd - - all default -] Could not find role: admin.: keystone.exception.RoleNotFound: Could not find role: admin.
2023-02-14 05:14:26.510 37 ERROR keystone.server.flask.application Traceback (most recent call last):
2023-02-14 05:14:26.510 37 ERROR keystone.server.flask.application   File "/var/lib/kolla/venv/lib/python3.9/site-packages/flask/app.py", line 1820, in full_dispatch_request
2023-02-14 05:14:26.510 37 ERROR keystone.server.flask.application     rv = self.dispatch_request()
2023-02-14 05:14:26.510 37 ERROR keystone.server.flask.application   File "/var/lib/kolla/venv/lib/python3.9/site-packages/flask/app.py", line 1796, in dispatch_request
2023-02-14 05:14:26.510 37 ERROR keystone.server.flask.application     return self.ensure_sync(self.view_functions[rule.endpoint])(**view_args)
2023-02-14 05:14:26.510 37 ERROR keystone.server.flask.application   File "/var/lib/kolla/venv/lib/python3.9/site-packages/flask_restful/__init__.py", line 467, in wrapper
2023-02-14 05:14:26.510 37 ERROR keystone.server.flask.application     resp = resource(*args, **kwargs)
2023-02-14 05:14:26.510 37 ERROR keystone.server.flask.application   File "/var/lib/kolla/venv/lib/python3.9/site-packages/flask/views.py", line 107, in view
2023-02-14 05:14:26.510 37 ERROR keystone.server.flask.application     return current_app.ensure_sync(self.dispatch_request)(**kwargs)
2023-02-14 05:14:26.510 37 ERROR keystone.server.flask.application   File "/var/lib/kolla/venv/lib/python3.9/site-packages/flask_restful/__init__.py", line 582, in dispatch_request
2023-02-14 05:14:26.510 37 ERROR keystone.server.flask.application     resp = meth(*args, **kwargs)
2023-02-14 05:14:26.510 37 ERROR keystone.server.flask.application   File "/var/lib/kolla/venv/lib/python3.9/site-packages/keystone/api/roles.py", line 50, in get
2023-02-14 05:14:26.510 37 ERROR keystone.server.flask.application     return self._get_role(role_id)
2023-02-14 05:14:26.510 37 ERROR keystone.server.flask.application   File "/var/lib/kolla/venv/lib/python3.9/site-packages/keystone/api/roles.py", line 70, in _get_role
2023-02-14 05:14:26.510 37 ERROR keystone.server.flask.application     ENFORCER.enforce_call(action='identity:get_role')
2023-02-14 05:14:26.510 37 ERROR keystone.server.flask.application   File "/var/lib/kolla/venv/lib/python3.9/site-packages/keystone/common/rbac_enforcer/enforcer.py", line 402, in enforce_call
2023-02-14 05:14:26.510 37 ERROR keystone.server.flask.application     policy_dict.update(cls._extract_member_target_data(
2023-02-14 05:14:26.510 37 ERROR keystone.server.flask.application   File "/var/lib/kolla/venv/lib/python3.9/site-packages/keystone/common/rbac_enforcer/enforcer.py", line 234, in _extract_member_target_data
2023-02-14 05:14:26.510 37 ERROR keystone.server.flask.application     member_name: func(flask.request.view_args[key])
2023-02-14 05:14:26.510 37 ERROR keystone.server.flask.application   File "/var/lib/kolla/venv/lib/python3.9/site-packages/keystone/common/manager.py", line 115, in wrapped
2023-02-14 05:14:26.510 37 ERROR keystone.server.flask.application     __ret_val = __f(*args, **kwargs)
2023-02-14 05:14:26.510 37 ERROR keystone.server.flask.application   File "/var/lib/kolla/venv/lib/python3.9/site-packages/decorator.py", line 232, in fun
2023-02-14 05:14:26.510 37 ERROR keystone.server.flask.application     return caller(func, *(extras + args), **kw)
2023-02-14 05:14:26.510 37 ERROR keystone.server.flask.application   File "/var/lib/kolla/venv/lib/python3.9/site-packages/dogpile/cache/region.py", line 1577, in get_or_create_for_user_func
2023-02-14 05:14:26.510 37 ERROR keystone.server.flask.application     return self.get_or_create(
2023-02-14 05:14:26.510 37 ERROR keystone.server.flask.application   File "/var/lib/kolla/venv/lib/python3.9/site-packages/dogpile/cache/region.py", line 1042, in get_or_create
2023-02-14 05:14:26.510 37 ERROR keystone.server.flask.application     with Lock(
2023-02-14 05:14:26.510 37 ERROR keystone.server.flask.application   File "/var/lib/kolla/venv/lib/python3.9/site-packages/dogpile/lock.py", line 185, in __enter__
2023-02-14 05:14:26.510 37 ERROR keystone.server.flask.application     return self._enter()
2023-02-14 05:14:26.510 37 ERROR keystone.server.flask.application   File "/var/lib/kolla/venv/lib/python3.9/site-packages/dogpile/lock.py", line 94, in _enter
2023-02-14 05:14:26.510 37 ERROR keystone.server.flask.application     generated = self._enter_create(value, createdtime)
2023-02-14 05:14:26.510 37 ERROR keystone.server.flask.application   File "/var/lib/kolla/venv/lib/python3.9/site-packages/dogpile/lock.py", line 178, in _enter_create
2023-02-14 05:14:26.510 37 ERROR keystone.server.flask.application     return self.creator()
2023-02-14 05:14:26.510 37 ERROR keystone.server.flask.application   File "/var/lib/kolla/venv/lib/python3.9/site-packages/dogpile/cache/region.py", line 995, in gen_value
2023-02-14 05:14:26.510 37 ERROR keystone.server.flask.application     created_value = creator(
2023-02-14 05:14:26.510 37 ERROR keystone.server.flask.application   File "/var/lib/kolla/venv/lib/python3.9/site-packages/keystone/assignment/core.py", line 1276, in get_role
2023-02-14 05:14:26.510 37 ERROR keystone.server.flask.application     return self.driver.get_role(role_id)
2023-02-14 05:14:26.510 37 ERROR keystone.server.flask.application   File "/var/lib/kolla/venv/lib/python3.9/site-packages/keystone/assignment/role_backends/sql.py", line 70, in get_role
2023-02-14 05:14:26.510 37 ERROR keystone.server.flask.application     return self._get_role(session, role_id).to_dict()
2023-02-14 05:14:26.510 37 ERROR keystone.server.flask.application   File "/var/lib/kolla/venv/lib/python3.9/site-packages/keystone/assignment/role_backends/sql.py", line 65, in _get_role
2023-02-14 05:14:26.510 37 ERROR keystone.server.flask.application     raise exception.RoleNotFound(role_id=role_id)
2023-02-14 05:14:26.510 37 ERROR keystone.server.flask.application keystone.exception.RoleNotFound: Could not find role: admin.
2023-02-14 05:14:26.510 37 ERROR keystone.server.flask.application 
2023-02-14 05:14:27.463 38 ERROR keystone.server.flask.application [None req-2a63faef-24a1-47bb-b307-fe278e98b685 848faf0af3eb4aa7802674da265877bd - - all default -] Could not find user: ironic.: keystone.exception.UserNotFound: Could not find user: ironic.
2023-02-14 05:14:27.463 38 ERROR keystone.server.flask.application Traceback (most recent call last):
2023-02-14 05:14:27.463 38 ERROR keystone.server.flask.application   File "/var/lib/kolla/venv/lib/python3.9/site-packages/flask/app.py", line 1820, in full_dispatch_request
2023-02-14 05:14:27.463 38 ERROR keystone.server.flask.application     rv = self.dispatch_request()
2023-02-14 05:14:27.463 38 ERROR keystone.server.flask.application   File "/var/lib/kolla/venv/lib/python3.9/site-packages/flask/app.py", line 1796, in dispatch_request
2023-02-14 05:14:27.463 38 ERROR keystone.server.flask.application     return self.ensure_sync(self.view_functions[rule.endpoint])(**view_args)
2023-02-14 05:14:27.463 38 ERROR keystone.server.flask.application   File "/var/lib/kolla/venv/lib/python3.9/site-packages/flask_restful/__init__.py", line 467, in wrapper
2023-02-14 05:14:27.463 38 ERROR keystone.server.flask.application     resp = resource(*args, **kwargs)
2023-02-14 05:14:27.463 38 ERROR keystone.server.flask.application   File "/var/lib/kolla/venv/lib/python3.9/site-packages/flask/views.py", line 107, in view
2023-02-14 05:14:27.463 38 ERROR keystone.server.flask.application     return current_app.ensure_sync(self.dispatch_request)(**kwargs)
2023-02-14 05:14:27.463 38 ERROR keystone.server.flask.application   File "/var/lib/kolla/venv/lib/python3.9/site-packages/flask_restful/__init__.py", line 582, in dispatch_request
2023-02-14 05:14:27.463 38 ERROR keystone.server.flask.application     resp = meth(*args, **kwargs)
2023-02-14 05:14:27.463 38 ERROR keystone.server.flask.application   File "/var/lib/kolla/venv/lib/python3.9/site-packages/keystone/api/users.py", line 182, in get
2023-02-14 05:14:27.463 38 ERROR keystone.server.flask.application     return self._get_user(user_id)
2023-02-14 05:14:27.463 38 ERROR keystone.server.flask.application   File "/var/lib/kolla/venv/lib/python3.9/site-packages/keystone/api/users.py", line 194, in _get_user
2023-02-14 05:14:27.463 38 ERROR keystone.server.flask.application     ref = PROVIDERS.identity_api.get_user(user_id)
2023-02-14 05:14:27.463 38 ERROR keystone.server.flask.application   File "/var/lib/kolla/venv/lib/python3.9/site-packages/keystone/common/manager.py", line 115, in wrapped
2023-02-14 05:14:27.463 38 ERROR keystone.server.flask.application     __ret_val = __f(*args, **kwargs)
2023-02-14 05:14:27.463 38 ERROR keystone.server.flask.application   File "/var/lib/kolla/venv/lib/python3.9/site-packages/keystone/identity/core.py", line 414, in wrapper
2023-02-14 05:14:27.463 38 ERROR keystone.server.flask.application     return f(self, *args, **kwargs)
2023-02-14 05:14:27.463 38 ERROR keystone.server.flask.application   File "/var/lib/kolla/venv/lib/python3.9/site-packages/keystone/identity/core.py", line 424, in wrapper
2023-02-14 05:14:27.463 38 ERROR keystone.server.flask.application     return f(self, *args, **kwargs)
2023-02-14 05:14:27.463 38 ERROR keystone.server.flask.application   File "/var/lib/kolla/venv/lib/python3.9/site-packages/decorator.py", line 232, in fun
2023-02-14 05:14:27.463 38 ERROR keystone.server.flask.application     return caller(func, *(extras + args), **kw)
2023-02-14 05:14:27.463 38 ERROR keystone.server.flask.application   File "/var/lib/kolla/venv/lib/python3.9/site-packages/dogpile/cache/region.py", line 1577, in get_or_create_for_user_func
2023-02-14 05:14:27.463 38 ERROR keystone.server.flask.application     return self.get_or_create(
2023-02-14 05:14:27.463 38 ERROR keystone.server.flask.application   File "/var/lib/kolla/venv/lib/python3.9/site-packages/dogpile/cache/region.py", line 1042, in get_or_create
2023-02-14 05:14:27.463 38 ERROR keystone.server.flask.application     with Lock(
2023-02-14 05:14:27.463 38 ERROR keystone.server.flask.application   File "/var/lib/kolla/venv/lib/python3.9/site-packages/dogpile/lock.py", line 185, in __enter__
2023-02-14 05:14:27.463 38 ERROR keystone.server.flask.application     return self._enter()
2023-02-14 05:14:27.463 38 ERROR keystone.server.flask.application   File "/var/lib/kolla/venv/lib/python3.9/site-packages/dogpile/lock.py", line 94, in _enter
2023-02-14 05:14:27.463 38 ERROR keystone.server.flask.application     generated = self._enter_create(value, createdtime)
2023-02-14 05:14:27.463 38 ERROR keystone.server.flask.application   File "/var/lib/kolla/venv/lib/python3.9/site-packages/dogpile/lock.py", line 178, in _enter_create
2023-02-14 05:14:27.463 38 ERROR keystone.server.flask.application     return self.creator()
2023-02-14 05:14:27.463 38 ERROR keystone.server.flask.application   File "/var/lib/kolla/venv/lib/python3.9/site-packages/dogpile/cache/region.py", line 995, in gen_value
2023-02-14 05:14:27.463 38 ERROR keystone.server.flask.application     created_value = creator(
2023-02-14 05:14:27.463 38 ERROR keystone.server.flask.application   File "/var/lib/kolla/venv/lib/python3.9/site-packages/keystone/identity/core.py", line 1011, in get_user
2023-02-14 05:14:27.463 38 ERROR keystone.server.flask.application     ref = driver.get_user(entity_id)
2023-02-14 05:14:27.463 38 ERROR keystone.server.flask.application   File "/var/lib/kolla/venv/lib/python3.9/site-packages/keystone/identity/backends/sql.py", line 200, in get_user
2023-02-14 05:14:27.463 38 ERROR keystone.server.flask.application     self._get_user(session, user_id).to_dict())
2023-02-14 05:14:27.463 38 ERROR keystone.server.flask.application   File "/var/lib/kolla/venv/lib/python3.9/site-packages/keystone/identity/backends/sql.py", line 194, in _get_user
2023-02-14 05:14:27.463 38 ERROR keystone.server.flask.application     raise exception.UserNotFound(user_id=user_id)
2023-02-14 05:14:27.463 38 ERROR keystone.server.flask.application keystone.exception.UserNotFound: Could not find user: ironic.
2023-02-14 05:14:27.463 38 ERROR keystone.server.flask.application 
2023-02-14 05:14:28.227 38 ERROR keystone.server.flask.application [None req-2ca06b80-36aa-422f-9ec2-9f87ea6491b5 848faf0af3eb4aa7802674da265877bd - - all default -] Could not find project: service.: keystone.exception.ProjectNotFound: Could not find project: service.
2023-02-14 05:14:28.227 38 ERROR keystone.server.flask.application Traceback (most recent call last):
2023-02-14 05:14:28.227 38 ERROR keystone.server.flask.application   File "/var/lib/kolla/venv/lib/python3.9/site-packages/flask/app.py", line 1820, in full_dispatch_request
2023-02-14 05:14:28.227 38 ERROR keystone.server.flask.application     rv = self.dispatch_request()
2023-02-14 05:14:28.227 38 ERROR keystone.server.flask.application   File "/var/lib/kolla/venv/lib/python3.9/site-packages/flask/app.py", line 1796, in dispatch_request
2023-02-14 05:14:28.227 38 ERROR keystone.server.flask.application     return self.ensure_sync(self.view_functions[rule.endpoint])(**view_args)
2023-02-14 05:14:28.227 38 ERROR keystone.server.flask.application   File "/var/lib/kolla/venv/lib/python3.9/site-packages/flask_restful/__init__.py", line 467, in wrapper
2023-02-14 05:14:28.227 38 ERROR keystone.server.flask.application     resp = resource(*args, **kwargs)
2023-02-14 05:14:28.227 38 ERROR keystone.server.flask.application   File "/var/lib/kolla/venv/lib/python3.9/site-packages/flask/views.py", line 107, in view
2023-02-14 05:14:28.227 38 ERROR keystone.server.flask.application     return current_app.ensure_sync(self.dispatch_request)(**kwargs)
2023-02-14 05:14:28.227 38 ERROR keystone.server.flask.application   File "/var/lib/kolla/venv/lib/python3.9/site-packages/flask_restful/__init__.py", line 582, in dispatch_request
2023-02-14 05:14:28.227 38 ERROR keystone.server.flask.application     resp = meth(*args, **kwargs)
2023-02-14 05:14:28.227 38 ERROR keystone.server.flask.application   File "/var/lib/kolla/venv/lib/python3.9/site-packages/keystone/api/projects.py", line 151, in get
2023-02-14 05:14:28.227 38 ERROR keystone.server.flask.application     return self._get_project(project_id)
2023-02-14 05:14:28.227 38 ERROR keystone.server.flask.application   File "/var/lib/kolla/venv/lib/python3.9/site-packages/keystone/api/projects.py", line 107, in _get_project
2023-02-14 05:14:28.227 38 ERROR keystone.server.flask.application     project = PROVIDERS.resource_api.get_project(project_id)
2023-02-14 05:14:28.227 38 ERROR keystone.server.flask.application   File "/var/lib/kolla/venv/lib/python3.9/site-packages/keystone/common/manager.py", line 115, in wrapped
2023-02-14 05:14:28.227 38 ERROR keystone.server.flask.application     __ret_val = __f(*args, **kwargs)
2023-02-14 05:14:28.227 38 ERROR keystone.server.flask.application   File "/var/lib/kolla/venv/lib/python3.9/site-packages/decorator.py", line 232, in fun
2023-02-14 05:14:28.227 38 ERROR keystone.server.flask.application     return caller(func, *(extras + args), **kw)
2023-02-14 05:14:28.227 38 ERROR keystone.server.flask.application   File "/var/lib/kolla/venv/lib/python3.9/site-packages/dogpile/cache/region.py", line 1577, in get_or_create_for_user_func
2023-02-14 05:14:28.227 38 ERROR keystone.server.flask.application     return self.get_or_create(
2023-02-14 05:14:28.227 38 ERROR keystone.server.flask.application   File "/var/lib/kolla/venv/lib/python3.9/site-packages/dogpile/cache/region.py", line 1042, in get_or_create
2023-02-14 05:14:28.227 38 ERROR keystone.server.flask.application     with Lock(
2023-02-14 05:14:28.227 38 ERROR keystone.server.flask.application   File "/var/lib/kolla/venv/lib/python3.9/site-packages/dogpile/lock.py", line 185, in __enter__
2023-02-14 05:14:28.227 38 ERROR keystone.server.flask.application     return self._enter()
2023-02-14 05:14:28.227 38 ERROR keystone.server.flask.application   File "/var/lib/kolla/venv/lib/python3.9/site-packages/dogpile/lock.py", line 94, in _enter
2023-02-14 05:14:28.227 38 ERROR keystone.server.flask.application     generated = self._enter_create(value, createdtime)
2023-02-14 05:14:28.227 38 ERROR keystone.server.flask.application   File "/var/lib/kolla/venv/lib/python3.9/site-packages/dogpile/lock.py", line 178, in _enter_create
2023-02-14 05:14:28.227 38 ERROR keystone.server.flask.application     return self.creator()
2023-02-14 05:14:28.227 38 ERROR keystone.server.flask.application   File "/var/lib/kolla/venv/lib/python3.9/site-packages/dogpile/cache/region.py", line 995, in gen_value
2023-02-14 05:14:28.227 38 ERROR keystone.server.flask.application     created_value = creator(
2023-02-14 05:14:28.227 38 ERROR keystone.server.flask.application   File "/var/lib/kolla/venv/lib/python3.9/site-packages/keystone/resource/core.py", line 903, in get_project
2023-02-14 05:14:28.227 38 ERROR keystone.server.flask.application     return self.driver.get_project(project_id)
2023-02-14 05:14:28.227 38 ERROR keystone.server.flask.application   File "/var/lib/kolla/venv/lib/python3.9/site-packages/keystone/resource/backends/sql.py", line 49, in get_project
2023-02-14 05:14:28.227 38 ERROR keystone.server.flask.application     return self._get_project(session, project_id).to_dict()
2023-02-14 05:14:28.227 38 ERROR keystone.server.flask.application   File "/var/lib/kolla/venv/lib/python3.9/site-packages/keystone/resource/backends/sql.py", line 44, in _get_project
2023-02-14 05:14:28.227 38 ERROR keystone.server.flask.application     raise exception.ProjectNotFound(project_id=project_id)
2023-02-14 05:14:28.227 38 ERROR keystone.server.flask.application keystone.exception.ProjectNotFound: Could not find project: service.
2023-02-14 05:14:28.227 38 ERROR keystone.server.flask.application 
2023-02-14 05:14:37.054 37 ERROR keystone.server.flask.application [None req-5226f78b-cb02-4ff7-94ad-26ef4e1d377d 848faf0af3eb4aa7802674da265877bd - - all default -] Could not find role: admin.: keystone.exception.RoleNotFound: Could not find role: admin.
2023-02-14 05:14:37.054 37 ERROR keystone.server.flask.application Traceback (most recent call last):
2023-02-14 05:14:37.054 37 ERROR keystone.server.flask.application   File "/var/lib/kolla/venv/lib/python3.9/site-packages/flask/app.py", line 1820, in full_dispatch_request
2023-02-14 05:14:37.054 37 ERROR keystone.server.flask.application     rv = self.dispatch_request()
2023-02-14 05:14:37.054 37 ERROR keystone.server.flask.application   File "/var/lib/kolla/venv/lib/python3.9/site-packages/flask/app.py", line 1796, in dispatch_request
2023-02-14 05:14:37.054 37 ERROR keystone.server.flask.application     return self.ensure_sync(self.view_functions[rule.endpoint])(**view_args)
2023-02-14 05:14:37.054 37 ERROR keystone.server.flask.application   File "/var/lib/kolla/venv/lib/python3.9/site-packages/flask_restful/__init__.py", line 467, in wrapper
2023-02-14 05:14:37.054 37 ERROR keystone.server.flask.application     resp = resource(*args, **kwargs)
2023-02-14 05:14:37.054 37 ERROR keystone.server.flask.application   File "/var/lib/kolla/venv/lib/python3.9/site-packages/flask/views.py", line 107, in view
2023-02-14 05:14:37.054 37 ERROR keystone.server.flask.application     return current_app.ensure_sync(self.dispatch_request)(**kwargs)
2023-02-14 05:14:37.054 37 ERROR keystone.server.flask.application   File "/var/lib/kolla/venv/lib/python3.9/site-packages/flask_restful/__init__.py", line 582, in dispatch_request
2023-02-14 05:14:37.054 37 ERROR keystone.server.flask.application     resp = meth(*args, **kwargs)
2023-02-14 05:14:37.054 37 ERROR keystone.server.flask.application   File "/var/lib/kolla/venv/lib/python3.9/site-packages/keystone/api/roles.py", line 50, in get
2023-02-14 05:14:37.054 37 ERROR keystone.server.flask.application     return self._get_role(role_id)
2023-02-14 05:14:37.054 37 ERROR keystone.server.flask.application   File "/var/lib/kolla/venv/lib/python3.9/site-packages/keystone/api/roles.py", line 70, in _get_role
2023-02-14 05:14:37.054 37 ERROR keystone.server.flask.application     ENFORCER.enforce_call(action='identity:get_role')
2023-02-14 05:14:37.054 37 ERROR keystone.server.flask.application   File "/var/lib/kolla/venv/lib/python3.9/site-packages/keystone/common/rbac_enforcer/enforcer.py", line 402, in enforce_call
2023-02-14 05:14:37.054 37 ERROR keystone.server.flask.application     policy_dict.update(cls._extract_member_target_data(
2023-02-14 05:14:37.054 37 ERROR keystone.server.flask.application   File "/var/lib/kolla/venv/lib/python3.9/site-packages/keystone/common/rbac_enforcer/enforcer.py", line 234, in _extract_member_target_data
2023-02-14 05:14:37.054 37 ERROR keystone.server.flask.application     member_name: func(flask.request.view_args[key])
2023-02-14 05:14:37.054 37 ERROR keystone.server.flask.application   File "/var/lib/kolla/venv/lib/python3.9/site-packages/keystone/common/manager.py", line 115, in wrapped
2023-02-14 05:14:37.054 37 ERROR keystone.server.flask.application     __ret_val = __f(*args, **kwargs)
2023-02-14 05:14:37.054 37 ERROR keystone.server.flask.application   File "/var/lib/kolla/venv/lib/python3.9/site-packages/decorator.py", line 232, in fun
2023-02-14 05:14:37.054 37 ERROR keystone.server.flask.application     return caller(func, *(extras + args), **kw)
2023-02-14 05:14:37.054 37 ERROR keystone.server.flask.application   File "/var/lib/kolla/venv/lib/python3.9/site-packages/dogpile/cache/region.py", line 1577, in get_or_create_for_user_func
2023-02-14 05:14:37.054 37 ERROR keystone.server.flask.application     return self.get_or_create(
2023-02-14 05:14:37.054 37 ERROR keystone.server.flask.application   File "/var/lib/kolla/venv/lib/python3.9/site-packages/dogpile/cache/region.py", line 1042, in get_or_create
2023-02-14 05:14:37.054 37 ERROR keystone.server.flask.application     with Lock(
2023-02-14 05:14:37.054 37 ERROR keystone.server.flask.application   File "/var/lib/kolla/venv/lib/python3.9/site-packages/dogpile/lock.py", line 185, in __enter__
2023-02-14 05:14:37.054 37 ERROR keystone.server.flask.application     return self._enter()
2023-02-14 05:14:37.054 37 ERROR keystone.server.flask.application   File "/var/lib/kolla/venv/lib/python3.9/site-packages/dogpile/lock.py", line 94, in _enter
2023-02-14 05:14:37.054 37 ERROR keystone.server.flask.application     generated = self._enter_create(value, createdtime)
2023-02-14 05:14:37.054 37 ERROR keystone.server.flask.application   File "/var/lib/kolla/venv/lib/python3.9/site-packages/dogpile/lock.py", line 178, in _enter_create
2023-02-14 05:14:37.054 37 ERROR keystone.server.flask.application     return self.creator()
2023-02-14 05:14:37.054 37 ERROR keystone.server.flask.application   File "/var/lib/kolla/venv/lib/python3.9/site-packages/dogpile/cache/region.py", line 995, in gen_value
2023-02-14 05:14:37.054 37 ERROR keystone.server.flask.application     created_value = creator(
2023-02-14 05:14:37.054 37 ERROR keystone.server.flask.application   File "/var/lib/kolla/venv/lib/python3.9/site-packages/keystone/assignment/core.py", line 1276, in get_role
2023-02-14 05:14:37.054 37 ERROR keystone.server.flask.application     return self.driver.get_role(role_id)
2023-02-14 05:14:37.054 37 ERROR keystone.server.flask.application   File "/var/lib/kolla/venv/lib/python3.9/site-packages/keystone/assignment/role_backends/sql.py", line 70, in get_role
2023-02-14 05:14:37.054 37 ERROR keystone.server.flask.application     return self._get_role(session, role_id).to_dict()
2023-02-14 05:14:37.054 37 ERROR keystone.server.flask.application   File "/var/lib/kolla/venv/lib/python3.9/site-packages/keystone/assignment/role_backends/sql.py", line 65, in _get_role
2023-02-14 05:14:37.054 37 ERROR keystone.server.flask.application     raise exception.RoleNotFound(role_id=role_id)
2023-02-14 05:14:37.054 37 ERROR keystone.server.flask.application keystone.exception.RoleNotFound: Could not find role: admin.
2023-02-14 05:14:37.054 37 ERROR keystone.server.flask.application 
2023-02-14 05:14:37.995 38 ERROR keystone.server.flask.application [None req-4bb672d2-b93f-4a8d-9b87-7d7e97eea90d 848faf0af3eb4aa7802674da265877bd - - all default -] Could not find user: ironic-inspector.: keystone.exception.UserNotFound: Could not find user: ironic-inspector.
2023-02-14 05:14:37.995 38 ERROR keystone.server.flask.application Traceback (most recent call last):
2023-02-14 05:14:37.995 38 ERROR keystone.server.flask.application   File "/var/lib/kolla/venv/lib/python3.9/site-packages/flask/app.py", line 1820, in full_dispatch_request
2023-02-14 05:14:37.995 38 ERROR keystone.server.flask.application     rv = self.dispatch_request()
2023-02-14 05:14:37.995 38 ERROR keystone.server.flask.application   File "/var/lib/kolla/venv/lib/python3.9/site-packages/flask/app.py", line 1796, in dispatch_request
2023-02-14 05:14:37.995 38 ERROR keystone.server.flask.application     return self.ensure_sync(self.view_functions[rule.endpoint])(**view_args)
2023-02-14 05:14:37.995 38 ERROR keystone.server.flask.application   File "/var/lib/kolla/venv/lib/python3.9/site-packages/flask_restful/__init__.py", line 467, in wrapper
2023-02-14 05:14:37.995 38 ERROR keystone.server.flask.application     resp = resource(*args, **kwargs)
2023-02-14 05:14:37.995 38 ERROR keystone.server.flask.application   File "/var/lib/kolla/venv/lib/python3.9/site-packages/flask/views.py", line 107, in view
2023-02-14 05:14:37.995 38 ERROR keystone.server.flask.application     return current_app.ensure_sync(self.dispatch_request)(**kwargs)
2023-02-14 05:14:37.995 38 ERROR keystone.server.flask.application   File "/var/lib/kolla/venv/lib/python3.9/site-packages/flask_restful/__init__.py", line 582, in dispatch_request
2023-02-14 05:14:37.995 38 ERROR keystone.server.flask.application     resp = meth(*args, **kwargs)
2023-02-14 05:14:37.995 38 ERROR keystone.server.flask.application   File "/var/lib/kolla/venv/lib/python3.9/site-packages/keystone/api/users.py", line 182, in get
2023-02-14 05:14:37.995 38 ERROR keystone.server.flask.application     return self._get_user(user_id)
2023-02-14 05:14:37.995 38 ERROR keystone.server.flask.application   File "/var/lib/kolla/venv/lib/python3.9/site-packages/keystone/api/users.py", line 194, in _get_user
2023-02-14 05:14:37.995 38 ERROR keystone.server.flask.application     ref = PROVIDERS.identity_api.get_user(user_id)
2023-02-14 05:14:37.995 38 ERROR keystone.server.flask.application   File "/var/lib/kolla/venv/lib/python3.9/site-packages/keystone/common/manager.py", line 115, in wrapped
2023-02-14 05:14:37.995 38 ERROR keystone.server.flask.application     __ret_val = __f(*args, **kwargs)
2023-02-14 05:14:37.995 38 ERROR keystone.server.flask.application   File "/var/lib/kolla/venv/lib/python3.9/site-packages/keystone/identity/core.py", line 414, in wrapper
2023-02-14 05:14:37.995 38 ERROR keystone.server.flask.application     return f(self, *args, **kwargs)
2023-02-14 05:14:37.995 38 ERROR keystone.server.flask.application   File "/var/lib/kolla/venv/lib/python3.9/site-packages/keystone/identity/core.py", line 424, in wrapper
2023-02-14 05:14:37.995 38 ERROR keystone.server.flask.application     return f(self, *args, **kwargs)
2023-02-14 05:14:37.995 38 ERROR keystone.server.flask.application   File "/var/lib/kolla/venv/lib/python3.9/site-packages/decorator.py", line 232, in fun
2023-02-14 05:14:37.995 38 ERROR keystone.server.flask.application     return caller(func, *(extras + args), **kw)
2023-02-14 05:14:37.995 38 ERROR keystone.server.flask.application   File "/var/lib/kolla/venv/lib/python3.9/site-packages/dogpile/cache/region.py", line 1577, in get_or_create_for_user_func
2023-02-14 05:14:37.995 38 ERROR keystone.server.flask.application     return self.get_or_create(
2023-02-14 05:14:37.995 38 ERROR keystone.server.flask.application   File "/var/lib/kolla/venv/lib/python3.9/site-packages/dogpile/cache/region.py", line 1042, in get_or_create
2023-02-14 05:14:37.995 38 ERROR keystone.server.flask.application     with Lock(
2023-02-14 05:14:37.995 38 ERROR keystone.server.flask.application   File "/var/lib/kolla/venv/lib/python3.9/site-packages/dogpile/lock.py", line 185, in __enter__
2023-02-14 05:14:37.995 38 ERROR keystone.server.flask.application     return self._enter()
2023-02-14 05:14:37.995 38 ERROR keystone.server.flask.application   File "/var/lib/kolla/venv/lib/python3.9/site-packages/dogpile/lock.py", line 94, in _enter
2023-02-14 05:14:37.995 38 ERROR keystone.server.flask.application     generated = self._enter_create(value, createdtime)
2023-02-14 05:14:37.995 38 ERROR keystone.server.flask.application   File "/var/lib/kolla/venv/lib/python3.9/site-packages/dogpile/lock.py", line 178, in _enter_create
2023-02-14 05:14:37.995 38 ERROR keystone.server.flask.application     return self.creator()
2023-02-14 05:14:37.995 38 ERROR keystone.server.flask.application   File "/var/lib/kolla/venv/lib/python3.9/site-packages/dogpile/cache/region.py", line 995, in gen_value
2023-02-14 05:14:37.995 38 ERROR keystone.server.flask.application     created_value = creator(
2023-02-14 05:14:37.995 38 ERROR keystone.server.flask.application   File "/var/lib/kolla/venv/lib/python3.9/site-packages/keystone/identity/core.py", line 1011, in get_user
2023-02-14 05:14:37.995 38 ERROR keystone.server.flask.application     ref = driver.get_user(entity_id)
2023-02-14 05:14:37.995 38 ERROR keystone.server.flask.application   File "/var/lib/kolla/venv/lib/python3.9/site-packages/keystone/identity/backends/sql.py", line 200, in get_user
2023-02-14 05:14:37.995 38 ERROR keystone.server.flask.application     self._get_user(session, user_id).to_dict())
2023-02-14 05:14:37.995 38 ERROR keystone.server.flask.application   File "/var/lib/kolla/venv/lib/python3.9/site-packages/keystone/identity/backends/sql.py", line 194, in _get_user
2023-02-14 05:14:37.995 38 ERROR keystone.server.flask.application     raise exception.UserNotFound(user_id=user_id)
2023-02-14 05:14:37.995 38 ERROR keystone.server.flask.application keystone.exception.UserNotFound: Could not find user: ironic-inspector.
2023-02-14 05:14:37.995 38 ERROR keystone.server.flask.application 
2023-02-14 05:14:38.640 38 ERROR keystone.server.flask.application [None req-9e9721ab-05d2-443d-b3c1-a0c739fb4e9d 848faf0af3eb4aa7802674da265877bd - - all default -] Could not find project: service.: keystone.exception.ProjectNotFound: Could not find project: service.
2023-02-14 05:14:38.640 38 ERROR keystone.server.flask.application Traceback (most recent call last):
2023-02-14 05:14:38.640 38 ERROR keystone.server.flask.application   File "/var/lib/kolla/venv/lib/python3.9/site-packages/flask/app.py", line 1820, in full_dispatch_request
2023-02-14 05:14:38.640 38 ERROR keystone.server.flask.application     rv = self.dispatch_request()
2023-02-14 05:14:38.640 38 ERROR keystone.server.flask.application   File "/var/lib/kolla/venv/lib/python3.9/site-packages/flask/app.py", line 1796, in dispatch_request
2023-02-14 05:14:38.640 38 ERROR keystone.server.flask.application     return self.ensure_sync(self.view_functions[rule.endpoint])(**view_args)
2023-02-14 05:14:38.640 38 ERROR keystone.server.flask.application   File "/var/lib/kolla/venv/lib/python3.9/site-packages/flask_restful/__init__.py", line 467, in wrapper
2023-02-14 05:14:38.640 38 ERROR keystone.server.flask.application     resp = resource(*args, **kwargs)
2023-02-14 05:14:38.640 38 ERROR keystone.server.flask.application   File "/var/lib/kolla/venv/lib/python3.9/site-packages/flask/views.py", line 107, in view
2023-02-14 05:14:38.640 38 ERROR keystone.server.flask.application     return current_app.ensure_sync(self.dispatch_request)(**kwargs)
2023-02-14 05:14:38.640 38 ERROR keystone.server.flask.application   File "/var/lib/kolla/venv/lib/python3.9/site-packages/flask_restful/__init__.py", line 582, in dispatch_request
2023-02-14 05:14:38.640 38 ERROR keystone.server.flask.application     resp = meth(*args, **kwargs)
2023-02-14 05:14:38.640 38 ERROR keystone.server.flask.application   File "/var/lib/kolla/venv/lib/python3.9/site-packages/keystone/api/projects.py", line 151, in get
2023-02-14 05:14:38.640 38 ERROR keystone.server.flask.application     return self._get_project(project_id)
2023-02-14 05:14:38.640 38 ERROR keystone.server.flask.application   File "/var/lib/kolla/venv/lib/python3.9/site-packages/keystone/api/projects.py", line 107, in _get_project
2023-02-14 05:14:38.640 38 ERROR keystone.server.flask.application     project = PROVIDERS.resource_api.get_project(project_id)
2023-02-14 05:14:38.640 38 ERROR keystone.server.flask.application   File "/var/lib/kolla/venv/lib/python3.9/site-packages/keystone/common/manager.py", line 115, in wrapped
2023-02-14 05:14:38.640 38 ERROR keystone.server.flask.application     __ret_val = __f(*args, **kwargs)
2023-02-14 05:14:38.640 38 ERROR keystone.server.flask.application   File "/var/lib/kolla/venv/lib/python3.9/site-packages/decorator.py", line 232, in fun
2023-02-14 05:14:38.640 38 ERROR keystone.server.flask.application     return caller(func, *(extras + args), **kw)
2023-02-14 05:14:38.640 38 ERROR keystone.server.flask.application   File "/var/lib/kolla/venv/lib/python3.9/site-packages/dogpile/cache/region.py", line 1577, in get_or_create_for_user_func
2023-02-14 05:14:38.640 38 ERROR keystone.server.flask.application     return self.get_or_create(
2023-02-14 05:14:38.640 38 ERROR keystone.server.flask.application   File "/var/lib/kolla/venv/lib/python3.9/site-packages/dogpile/cache/region.py", line 1042, in get_or_create
2023-02-14 05:14:38.640 38 ERROR keystone.server.flask.application     with Lock(
2023-02-14 05:14:38.640 38 ERROR keystone.server.flask.application   File "/var/lib/kolla/venv/lib/python3.9/site-packages/dogpile/lock.py", line 185, in __enter__
2023-02-14 05:14:38.640 38 ERROR keystone.server.flask.application     return self._enter()
2023-02-14 05:14:38.640 38 ERROR keystone.server.flask.application   File "/var/lib/kolla/venv/lib/python3.9/site-packages/dogpile/lock.py", line 94, in _enter
2023-02-14 05:14:38.640 38 ERROR keystone.server.flask.application     generated = self._enter_create(value, createdtime)
2023-02-14 05:14:38.640 38 ERROR keystone.server.flask.application   File "/var/lib/kolla/venv/lib/python3.9/site-packages/dogpile/lock.py", line 178, in _enter_create
2023-02-14 05:14:38.640 38 ERROR keystone.server.flask.application     return self.creator()
2023-02-14 05:14:38.640 38 ERROR keystone.server.flask.application   File "/var/lib/kolla/venv/lib/python3.9/site-packages/dogpile/cache/region.py", line 995, in gen_value
2023-02-14 05:14:38.640 38 ERROR keystone.server.flask.application     created_value = creator(
2023-02-14 05:14:38.640 38 ERROR keystone.server.flask.application   File "/var/lib/kolla/venv/lib/python3.9/site-packages/keystone/resource/core.py", line 903, in get_project
2023-02-14 05:14:38.640 38 ERROR keystone.server.flask.application     return self.driver.get_project(project_id)
2023-02-14 05:14:38.640 38 ERROR keystone.server.flask.application   File "/var/lib/kolla/venv/lib/python3.9/site-packages/keystone/resource/backends/sql.py", line 49, in get_project
2023-02-14 05:14:38.640 38 ERROR keystone.server.flask.application     return self._get_project(session, project_id).to_dict()
2023-02-14 05:14:38.640 38 ERROR keystone.server.flask.application   File "/var/lib/kolla/venv/lib/python3.9/site-packages/keystone/resource/backends/sql.py", line 44, in _get_project
2023-02-14 05:14:38.640 38 ERROR keystone.server.flask.application     raise exception.ProjectNotFound(project_id=project_id)
2023-02-14 05:14:38.640 38 ERROR keystone.server.flask.application keystone.exception.ProjectNotFound: Could not find project: service.
2023-02-14 05:14:38.640 38 ERROR keystone.server.flask.application 
2023-02-14 05:18:04.831 38 WARNING py.warnings [None req-deb400d9-3fce-4f25-ba33-0d1a37cb07d1 848faf0af3eb4aa7802674da265877bd a7a6832c9baf4439bb3f06a923e8d1f5 - - default default] /var/lib/kolla/venv/lib/python3.9/site-packages/oslo_policy/policy.py:1129: UserWarning: Policy "identity:create_user": "(role:admin and system_scope:all) or (role:admin and token.domain.id:%(target.user.domain_id)s)" failed scope check. The token used to make the request was project scoped but the policy requires ['system', 'domain'] scope. This behavior may change in the future where using the intended scope is required
  warnings.warn(msg)

2023-02-14 05:18:09.530 37 ERROR keystone.server.flask.application [None req-433bcd0c-6e16-4322-86a7-b01a5028c9ca 848faf0af3eb4aa7802674da265877bd a7a6832c9baf4439bb3f06a923e8d1f5 - - default default] Could not find role: admin.: keystone.exception.RoleNotFound: Could not find role: admin.
2023-02-14 05:18:09.530 37 ERROR keystone.server.flask.application Traceback (most recent call last):
2023-02-14 05:18:09.530 37 ERROR keystone.server.flask.application   File "/var/lib/kolla/venv/lib/python3.9/site-packages/flask/app.py", line 1820, in full_dispatch_request
2023-02-14 05:18:09.530 37 ERROR keystone.server.flask.application     rv = self.dispatch_request()
2023-02-14 05:18:09.530 37 ERROR keystone.server.flask.application   File "/var/lib/kolla/venv/lib/python3.9/site-packages/flask/app.py", line 1796, in dispatch_request
2023-02-14 05:18:09.530 37 ERROR keystone.server.flask.application     return self.ensure_sync(self.view_functions[rule.endpoint])(**view_args)
2023-02-14 05:18:09.530 37 ERROR keystone.server.flask.application   File "/var/lib/kolla/venv/lib/python3.9/site-packages/flask_restful/__init__.py", line 467, in wrapper
2023-02-14 05:18:09.530 37 ERROR keystone.server.flask.application     resp = resource(*args, **kwargs)
2023-02-14 05:18:09.530 37 ERROR keystone.server.flask.application   File "/var/lib/kolla/venv/lib/python3.9/site-packages/flask/views.py", line 107, in view
2023-02-14 05:18:09.530 37 ERROR keystone.server.flask.application     return current_app.ensure_sync(self.dispatch_request)(**kwargs)
2023-02-14 05:18:09.530 37 ERROR keystone.server.flask.application   File "/var/lib/kolla/venv/lib/python3.9/site-packages/flask_restful/__init__.py", line 582, in dispatch_request
2023-02-14 05:18:09.530 37 ERROR keystone.server.flask.application     resp = meth(*args, **kwargs)
2023-02-14 05:18:09.530 37 ERROR keystone.server.flask.application   File "/var/lib/kolla/venv/lib/python3.9/site-packages/keystone/api/roles.py", line 50, in get
2023-02-14 05:18:09.530 37 ERROR keystone.server.flask.application     return self._get_role(role_id)
2023-02-14 05:18:09.530 37 ERROR keystone.server.flask.application   File "/var/lib/kolla/venv/lib/python3.9/site-packages/keystone/api/roles.py", line 70, in _get_role
2023-02-14 05:18:09.530 37 ERROR keystone.server.flask.application     ENFORCER.enforce_call(action='identity:get_role')
2023-02-14 05:18:09.530 37 ERROR keystone.server.flask.application   File "/var/lib/kolla/venv/lib/python3.9/site-packages/keystone/common/rbac_enforcer/enforcer.py", line 402, in enforce_call
2023-02-14 05:18:09.530 37 ERROR keystone.server.flask.application     policy_dict.update(cls._extract_member_target_data(
2023-02-14 05:18:09.530 37 ERROR keystone.server.flask.application   File "/var/lib/kolla/venv/lib/python3.9/site-packages/keystone/common/rbac_enforcer/enforcer.py", line 234, in _extract_member_target_data
2023-02-14 05:18:09.530 37 ERROR keystone.server.flask.application     member_name: func(flask.request.view_args[key])
2023-02-14 05:18:09.530 37 ERROR keystone.server.flask.application   File "/var/lib/kolla/venv/lib/python3.9/site-packages/keystone/common/manager.py", line 115, in wrapped
2023-02-14 05:18:09.530 37 ERROR keystone.server.flask.application     __ret_val = __f(*args, **kwargs)
2023-02-14 05:18:09.530 37 ERROR keystone.server.flask.application   File "/var/lib/kolla/venv/lib/python3.9/site-packages/decorator.py", line 232, in fun
2023-02-14 05:18:09.530 37 ERROR keystone.server.flask.application     return caller(func, *(extras + args), **kw)
2023-02-14 05:18:09.530 37 ERROR keystone.server.flask.application   File "/var/lib/kolla/venv/lib/python3.9/site-packages/dogpile/cache/region.py", line 1577, in get_or_create_for_user_func
2023-02-14 05:18:09.530 37 ERROR keystone.server.flask.application     return self.get_or_create(
2023-02-14 05:18:09.530 37 ERROR keystone.server.flask.application   File "/var/lib/kolla/venv/lib/python3.9/site-packages/dogpile/cache/region.py", line 1042, in get_or_create
2023-02-14 05:18:09.530 37 ERROR keystone.server.flask.application     with Lock(
2023-02-14 05:18:09.530 37 ERROR keystone.server.flask.application   File "/var/lib/kolla/venv/lib/python3.9/site-packages/dogpile/lock.py", line 185, in __enter__
2023-02-14 05:18:09.530 37 ERROR keystone.server.flask.application     return self._enter()
2023-02-14 05:18:09.530 37 ERROR keystone.server.flask.application   File "/var/lib/kolla/venv/lib/python3.9/site-packages/dogpile/lock.py", line 94, in _enter
2023-02-14 05:18:09.530 37 ERROR keystone.server.flask.application     generated = self._enter_create(value, createdtime)
2023-02-14 05:18:09.530 37 ERROR keystone.server.flask.application   File "/var/lib/kolla/venv/lib/python3.9/site-packages/dogpile/lock.py", line 178, in _enter_create
2023-02-14 05:18:09.530 37 ERROR keystone.server.flask.application     return self.creator()
2023-02-14 05:18:09.530 37 ERROR keystone.server.flask.application   File "/var/lib/kolla/venv/lib/python3.9/site-packages/dogpile/cache/region.py", line 995, in gen_value
2023-02-14 05:18:09.530 37 ERROR keystone.server.flask.application     created_value = creator(
2023-02-14 05:18:09.530 37 ERROR keystone.server.flask.application   File "/var/lib/kolla/venv/lib/python3.9/site-packages/keystone/assignment/core.py", line 1276, in get_role
2023-02-14 05:18:09.530 37 ERROR keystone.server.flask.application     return self.driver.get_role(role_id)
2023-02-14 05:18:09.530 37 ERROR keystone.server.flask.application   File "/var/lib/kolla/venv/lib/python3.9/site-packages/keystone/assignment/role_backends/sql.py", line 70, in get_role
2023-02-14 05:18:09.530 37 ERROR keystone.server.flask.application     return self._get_role(session, role_id).to_dict()
2023-02-14 05:18:09.530 37 ERROR keystone.server.flask.application   File "/var/lib/kolla/venv/lib/python3.9/site-packages/keystone/assignment/role_backends/sql.py", line 65, in _get_role
2023-02-14 05:18:09.530 37 ERROR keystone.server.flask.application     raise exception.RoleNotFound(role_id=role_id)
2023-02-14 05:18:09.530 37 ERROR keystone.server.flask.application keystone.exception.RoleNotFound: Could not find role: admin.
2023-02-14 05:18:09.530 37 ERROR keystone.server.flask.application 
2023-02-14 05:18:09.682 38 WARNING py.warnings [None req-7e5a431a-401e-4297-a6cf-0be05701ee26 848faf0af3eb4aa7802674da265877bd a7a6832c9baf4439bb3f06a923e8d1f5 - - default default] /var/lib/kolla/venv/lib/python3.9/site-packages/oslo_policy/policy.py:1129: UserWarning: Policy "identity:list_roles": "role:reader and system_scope:all" failed scope check. The token used to make the request was project scoped but the policy requires ['system'] scope. This behavior may change in the future where using the intended scope is required
  warnings.warn(msg)

2023-02-14 05:18:09.901 37 ERROR keystone.server.flask.application [None req-f5024556-317c-4239-a233-012d586e54bf 848faf0af3eb4aa7802674da265877bd a7a6832c9baf4439bb3f06a923e8d1f5 - - default default] Could not find user: neutron.: keystone.exception.UserNotFound: Could not find user: neutron.
2023-02-14 05:18:09.901 37 ERROR keystone.server.flask.application Traceback (most recent call last):
2023-02-14 05:18:09.901 37 ERROR keystone.server.flask.application   File "/var/lib/kolla/venv/lib/python3.9/site-packages/flask/app.py", line 1820, in full_dispatch_request
2023-02-14 05:18:09.901 37 ERROR keystone.server.flask.application     rv = self.dispatch_request()
2023-02-14 05:18:09.901 37 ERROR keystone.server.flask.application   File "/var/lib/kolla/venv/lib/python3.9/site-packages/flask/app.py", line 1796, in dispatch_request
2023-02-14 05:18:09.901 37 ERROR keystone.server.flask.application     return self.ensure_sync(self.view_functions[rule.endpoint])(**view_args)
2023-02-14 05:18:09.901 37 ERROR keystone.server.flask.application   File "/var/lib/kolla/venv/lib/python3.9/site-packages/flask_restful/__init__.py", line 467, in wrapper
2023-02-14 05:18:09.901 37 ERROR keystone.server.flask.application     resp = resource(*args, **kwargs)
2023-02-14 05:18:09.901 37 ERROR keystone.server.flask.application   File "/var/lib/kolla/venv/lib/python3.9/site-packages/flask/views.py", line 107, in view
2023-02-14 05:18:09.901 37 ERROR keystone.server.flask.application     return current_app.ensure_sync(self.dispatch_request)(**kwargs)
2023-02-14 05:18:09.901 37 ERROR keystone.server.flask.application   File "/var/lib/kolla/venv/lib/python3.9/site-packages/flask_restful/__init__.py", line 582, in dispatch_request
2023-02-14 05:18:09.901 37 ERROR keystone.server.flask.application     resp = meth(*args, **kwargs)
2023-02-14 05:18:09.901 37 ERROR keystone.server.flask.application   File "/var/lib/kolla/venv/lib/python3.9/site-packages/keystone/api/users.py", line 182, in get
2023-02-14 05:18:09.901 37 ERROR keystone.server.flask.application     return self._get_user(user_id)
2023-02-14 05:18:09.901 37 ERROR keystone.server.flask.application   File "/var/lib/kolla/venv/lib/python3.9/site-packages/keystone/api/users.py", line 194, in _get_user
2023-02-14 05:18:09.901 37 ERROR keystone.server.flask.application     ref = PROVIDERS.identity_api.get_user(user_id)
2023-02-14 05:18:09.901 37 ERROR keystone.server.flask.application   File "/var/lib/kolla/venv/lib/python3.9/site-packages/keystone/common/manager.py", line 115, in wrapped
2023-02-14 05:18:09.901 37 ERROR keystone.server.flask.application     __ret_val = __f(*args, **kwargs)
2023-02-14 05:18:09.901 37 ERROR keystone.server.flask.application   File "/var/lib/kolla/venv/lib/python3.9/site-packages/keystone/identity/core.py", line 414, in wrapper
2023-02-14 05:18:09.901 37 ERROR keystone.server.flask.application     return f(self, *args, **kwargs)
2023-02-14 05:18:09.901 37 ERROR keystone.server.flask.application   File "/var/lib/kolla/venv/lib/python3.9/site-packages/keystone/identity/core.py", line 424, in wrapper
2023-02-14 05:18:09.901 37 ERROR keystone.server.flask.application     return f(self, *args, **kwargs)
2023-02-14 05:18:09.901 37 ERROR keystone.server.flask.application   File "/var/lib/kolla/venv/lib/python3.9/site-packages/decorator.py", line 232, in fun
2023-02-14 05:18:09.901 37 ERROR keystone.server.flask.application     return caller(func, *(extras + args), **kw)
2023-02-14 05:18:09.901 37 ERROR keystone.server.flask.application   File "/var/lib/kolla/venv/lib/python3.9/site-packages/dogpile/cache/region.py", line 1577, in get_or_create_for_user_func
2023-02-14 05:18:09.901 37 ERROR keystone.server.flask.application     return self.get_or_create(
2023-02-14 05:18:09.901 37 ERROR keystone.server.flask.application   File "/var/lib/kolla/venv/lib/python3.9/site-packages/dogpile/cache/region.py", line 1042, in get_or_create
2023-02-14 05:18:09.901 37 ERROR keystone.server.flask.application     with Lock(
2023-02-14 05:18:09.901 37 ERROR keystone.server.flask.application   File "/var/lib/kolla/venv/lib/python3.9/site-packages/dogpile/lock.py", line 185, in __enter__
2023-02-14 05:18:09.901 37 ERROR keystone.server.flask.application     return self._enter()
2023-02-14 05:18:09.901 37 ERROR keystone.server.flask.application   File "/var/lib/kolla/venv/lib/python3.9/site-packages/dogpile/lock.py", line 94, in _enter
2023-02-14 05:18:09.901 37 ERROR keystone.server.flask.application     generated = self._enter_create(value, createdtime)
2023-02-14 05:18:09.901 37 ERROR keystone.server.flask.application   File "/var/lib/kolla/venv/lib/python3.9/site-packages/dogpile/lock.py", line 178, in _enter_create
2023-02-14 05:18:09.901 37 ERROR keystone.server.flask.application     return self.creator()
2023-02-14 05:18:09.901 37 ERROR keystone.server.flask.application   File "/var/lib/kolla/venv/lib/python3.9/site-packages/dogpile/cache/region.py", line 995, in gen_value
2023-02-14 05:18:09.901 37 ERROR keystone.server.flask.application     created_value = creator(
2023-02-14 05:18:09.901 37 ERROR keystone.server.flask.application   File "/var/lib/kolla/venv/lib/python3.9/site-packages/keystone/identity/core.py", line 1011, in get_user
2023-02-14 05:18:09.901 37 ERROR keystone.server.flask.application     ref = driver.get_user(entity_id)
2023-02-14 05:18:09.901 37 ERROR keystone.server.flask.application   File "/var/lib/kolla/venv/lib/python3.9/site-packages/keystone/identity/backends/sql.py", line 200, in get_user
2023-02-14 05:18:09.901 37 ERROR keystone.server.flask.application     self._get_user(session, user_id).to_dict())
2023-02-14 05:18:09.901 37 ERROR keystone.server.flask.application   File "/var/lib/kolla/venv/lib/python3.9/site-packages/keystone/identity/backends/sql.py", line 194, in _get_user
2023-02-14 05:18:09.901 37 ERROR keystone.server.flask.application     raise exception.UserNotFound(user_id=user_id)
2023-02-14 05:18:09.901 37 ERROR keystone.server.flask.application keystone.exception.UserNotFound: Could not find user: neutron.
2023-02-14 05:18:09.901 37 ERROR keystone.server.flask.application 
2023-02-14 05:18:10.094 38 WARNING py.warnings [None req-a04b75f8-80d1-4cdb-94e1-e58c20be9a8b 848faf0af3eb4aa7802674da265877bd a7a6832c9baf4439bb3f06a923e8d1f5 - - default default] /var/lib/kolla/venv/lib/python3.9/site-packages/oslo_policy/policy.py:1129: UserWarning: Policy "identity:list_users": "(role:reader and system_scope:all) or (role:reader and domain_id:%(target.domain_id)s)" failed scope check. The token used to make the request was project scoped but the policy requires ['system', 'domain'] scope. This behavior may change in the future where using the intended scope is required
  warnings.warn(msg)

2023-02-14 05:18:10.364 37 ERROR keystone.server.flask.application [None req-af375d1f-083b-4a55-b208-4f248db5572a 848faf0af3eb4aa7802674da265877bd a7a6832c9baf4439bb3f06a923e8d1f5 - - default default] Could not find project: service.: keystone.exception.ProjectNotFound: Could not find project: service.
2023-02-14 05:18:10.364 37 ERROR keystone.server.flask.application Traceback (most recent call last):
2023-02-14 05:18:10.364 37 ERROR keystone.server.flask.application   File "/var/lib/kolla/venv/lib/python3.9/site-packages/flask/app.py", line 1820, in full_dispatch_request
2023-02-14 05:18:10.364 37 ERROR keystone.server.flask.application     rv = self.dispatch_request()
2023-02-14 05:18:10.364 37 ERROR keystone.server.flask.application   File "/var/lib/kolla/venv/lib/python3.9/site-packages/flask/app.py", line 1796, in dispatch_request
2023-02-14 05:18:10.364 37 ERROR keystone.server.flask.application     return self.ensure_sync(self.view_functions[rule.endpoint])(**view_args)
2023-02-14 05:18:10.364 37 ERROR keystone.server.flask.application   File "/var/lib/kolla/venv/lib/python3.9/site-packages/flask_restful/__init__.py", line 467, in wrapper
2023-02-14 05:18:10.364 37 ERROR keystone.server.flask.application     resp = resource(*args, **kwargs)
2023-02-14 05:18:10.364 37 ERROR keystone.server.flask.application   File "/var/lib/kolla/venv/lib/python3.9/site-packages/flask/views.py", line 107, in view
2023-02-14 05:18:10.364 37 ERROR keystone.server.flask.application     return current_app.ensure_sync(self.dispatch_request)(**kwargs)
2023-02-14 05:18:10.364 37 ERROR keystone.server.flask.application   File "/var/lib/kolla/venv/lib/python3.9/site-packages/flask_restful/__init__.py", line 582, in dispatch_request
2023-02-14 05:18:10.364 37 ERROR keystone.server.flask.application     resp = meth(*args, **kwargs)
2023-02-14 05:18:10.364 37 ERROR keystone.server.flask.application   File "/var/lib/kolla/venv/lib/python3.9/site-packages/keystone/api/projects.py", line 151, in get
2023-02-14 05:18:10.364 37 ERROR keystone.server.flask.application     return self._get_project(project_id)
2023-02-14 05:18:10.364 37 ERROR keystone.server.flask.application   File "/var/lib/kolla/venv/lib/python3.9/site-packages/keystone/api/projects.py", line 107, in _get_project
2023-02-14 05:18:10.364 37 ERROR keystone.server.flask.application     project = PROVIDERS.resource_api.get_project(project_id)
2023-02-14 05:18:10.364 37 ERROR keystone.server.flask.application   File "/var/lib/kolla/venv/lib/python3.9/site-packages/keystone/common/manager.py", line 115, in wrapped
2023-02-14 05:18:10.364 37 ERROR keystone.server.flask.application     __ret_val = __f(*args, **kwargs)
2023-02-14 05:18:10.364 37 ERROR keystone.server.flask.application   File "/var/lib/kolla/venv/lib/python3.9/site-packages/decorator.py", line 232, in fun
2023-02-14 05:18:10.364 37 ERROR keystone.server.flask.application     return caller(func, *(extras + args), **kw)
2023-02-14 05:18:10.364 37 ERROR keystone.server.flask.application   File "/var/lib/kolla/venv/lib/python3.9/site-packages/dogpile/cache/region.py", line 1577, in get_or_create_for_user_func
2023-02-14 05:18:10.364 37 ERROR keystone.server.flask.application     return self.get_or_create(
2023-02-14 05:18:10.364 37 ERROR keystone.server.flask.application   File "/var/lib/kolla/venv/lib/python3.9/site-packages/dogpile/cache/region.py", line 1042, in get_or_create
2023-02-14 05:18:10.364 37 ERROR keystone.server.flask.application     with Lock(
2023-02-14 05:18:10.364 37 ERROR keystone.server.flask.application   File "/var/lib/kolla/venv/lib/python3.9/site-packages/dogpile/lock.py", line 185, in __enter__
2023-02-14 05:18:10.364 37 ERROR keystone.server.flask.application     return self._enter()
2023-02-14 05:18:10.364 37 ERROR keystone.server.flask.application   File "/var/lib/kolla/venv/lib/python3.9/site-packages/dogpile/lock.py", line 94, in _enter
2023-02-14 05:18:10.364 37 ERROR keystone.server.flask.application     generated = self._enter_create(value, createdtime)
2023-02-14 05:18:10.364 37 ERROR keystone.server.flask.application   File "/var/lib/kolla/venv/lib/python3.9/site-packages/dogpile/lock.py", line 178, in _enter_create
2023-02-14 05:18:10.364 37 ERROR keystone.server.flask.application     return self.creator()
2023-02-14 05:18:10.364 37 ERROR keystone.server.flask.application   File "/var/lib/kolla/venv/lib/python3.9/site-packages/dogpile/cache/region.py", line 995, in gen_value
2023-02-14 05:18:10.364 37 ERROR keystone.server.flask.application     created_value = creator(
2023-02-14 05:18:10.364 37 ERROR keystone.server.flask.application   File "/var/lib/kolla/venv/lib/python3.9/site-packages/keystone/resource/core.py", line 903, in get_project
2023-02-14 05:18:10.364 37 ERROR keystone.server.flask.application     return self.driver.get_project(project_id)
2023-02-14 05:18:10.364 37 ERROR keystone.server.flask.application   File "/var/lib/kolla/venv/lib/python3.9/site-packages/keystone/resource/backends/sql.py", line 49, in get_project
2023-02-14 05:18:10.364 37 ERROR keystone.server.flask.application     return self._get_project(session, project_id).to_dict()
2023-02-14 05:18:10.364 37 ERROR keystone.server.flask.application   File "/var/lib/kolla/venv/lib/python3.9/site-packages/keystone/resource/backends/sql.py", line 44, in _get_project
2023-02-14 05:18:10.364 37 ERROR keystone.server.flask.application     raise exception.ProjectNotFound(project_id=project_id)
2023-02-14 05:18:10.364 37 ERROR keystone.server.flask.application keystone.exception.ProjectNotFound: Could not find project: service.
2023-02-14 05:18:10.364 37 ERROR keystone.server.flask.application 
2023-02-14 05:18:10.548 38 WARNING py.warnings [None req-d05975ea-57e3-4234-9b03-c9b4cba8043b 848faf0af3eb4aa7802674da265877bd a7a6832c9baf4439bb3f06a923e8d1f5 - - default default] /var/lib/kolla/venv/lib/python3.9/site-packages/oslo_policy/policy.py:1129: UserWarning: Policy "identity:list_projects": "(role:reader and system_scope:all) or (role:reader and domain_id:%(target.domain_id)s)" failed scope check. The token used to make the request was project scoped but the policy requires ['system', 'domain'] scope. This behavior may change in the future where using the intended scope is required
  warnings.warn(msg)

2023-02-14 05:18:10.787 37 WARNING py.warnings [None req-076bf0e1-7134-45c6-bf51-8b9d9814f029 848faf0af3eb4aa7802674da265877bd a7a6832c9baf4439bb3f06a923e8d1f5 - - default default] /var/lib/kolla/venv/lib/python3.9/site-packages/oslo_policy/policy.py:1129: UserWarning: Policy "identity:create_grant": "(role:admin and system_scope:all) or ((role:admin and domain_id:%(target.user.domain_id)s and domain_id:%(target.project.domain_id)s) or (role:admin and domain_id:%(target.user.domain_id)s and domain_id:%(target.domain.id)s) or (role:admin and domain_id:%(target.group.domain_id)s and domain_id:%(target.project.domain_id)s) or (role:admin and domain_id:%(target.group.domain_id)s and domain_id:%(target.domain.id)s)) and (domain_id:%(target.role.domain_id)s or None:%(target.role.domain_id)s)" failed scope check. The token used to make the request was project scoped but the policy requires ['system', 'domain'] scope. This behavior may change in the future where using the intended scope is required
  warnings.warn(msg)

2023-02-14 05:18:14.768 37 WARNING py.warnings [None req-49b5e8b8-af52-473a-9c5a-1ef19a3fca50 848faf0af3eb4aa7802674da265877bd a7a6832c9baf4439bb3f06a923e8d1f5 - - default default] /var/lib/kolla/venv/lib/python3.9/site-packages/oslo_policy/policy.py:1129: UserWarning: Policy "identity:create_service": "role:admin and system_scope:all" failed scope check. The token used to make the request was project scoped but the policy requires ['system'] scope. This behavior may change in the future where using the intended scope is required
  warnings.warn(msg)

2023-02-14 05:18:18.638 37 WARNING py.warnings [None req-b8f937e2-9863-40a6-a447-cc5e803ccecf 848faf0af3eb4aa7802674da265877bd a7a6832c9baf4439bb3f06a923e8d1f5 - - default default] /var/lib/kolla/venv/lib/python3.9/site-packages/oslo_policy/policy.py:1129: UserWarning: Policy "identity:get_service": "role:reader and system_scope:all" failed scope check. The token used to make the request was project scoped but the policy requires ['system'] scope. This behavior may change in the future where using the intended scope is required
  warnings.warn(msg)

2023-02-14 05:18:18.651 37 ERROR keystone.server.flask.application [None req-b8f937e2-9863-40a6-a447-cc5e803ccecf 848faf0af3eb4aa7802674da265877bd a7a6832c9baf4439bb3f06a923e8d1f5 - - default default] Could not find service: network.: keystone.exception.ServiceNotFound: Could not find service: network.
2023-02-14 05:18:18.651 37 ERROR keystone.server.flask.application Traceback (most recent call last):
2023-02-14 05:18:18.651 37 ERROR keystone.server.flask.application   File "/var/lib/kolla/venv/lib/python3.9/site-packages/keystone/catalog/core.py", line 152, in get_service
2023-02-14 05:18:18.651 37 ERROR keystone.server.flask.application     return self.driver.get_service(service_id)
2023-02-14 05:18:18.651 37 ERROR keystone.server.flask.application   File "/var/lib/kolla/venv/lib/python3.9/site-packages/keystone/catalog/backends/sql.py", line 196, in get_service
2023-02-14 05:18:18.651 37 ERROR keystone.server.flask.application     return self._get_service(session, service_id).to_dict()
2023-02-14 05:18:18.651 37 ERROR keystone.server.flask.application   File "/var/lib/kolla/venv/lib/python3.9/site-packages/keystone/catalog/backends/sql.py", line 191, in _get_service
2023-02-14 05:18:18.651 37 ERROR keystone.server.flask.application     raise exception.ServiceNotFound(service_id=service_id)
2023-02-14 05:18:18.651 37 ERROR keystone.server.flask.application keystone.exception.ServiceNotFound: Could not find service: network.
2023-02-14 05:18:18.651 37 ERROR keystone.server.flask.application 
2023-02-14 05:18:18.651 37 ERROR keystone.server.flask.application During handling of the above exception, another exception occurred:
2023-02-14 05:18:18.651 37 ERROR keystone.server.flask.application 
2023-02-14 05:18:18.651 37 ERROR keystone.server.flask.application Traceback (most recent call last):
2023-02-14 05:18:18.651 37 ERROR keystone.server.flask.application   File "/var/lib/kolla/venv/lib/python3.9/site-packages/flask/app.py", line 1820, in full_dispatch_request
2023-02-14 05:18:18.651 37 ERROR keystone.server.flask.application     rv = self.dispatch_request()
2023-02-14 05:18:18.651 37 ERROR keystone.server.flask.application   File "/var/lib/kolla/venv/lib/python3.9/site-packages/flask/app.py", line 1796, in dispatch_request
2023-02-14 05:18:18.651 37 ERROR keystone.server.flask.application     return self.ensure_sync(self.view_functions[rule.endpoint])(**view_args)
2023-02-14 05:18:18.651 37 ERROR keystone.server.flask.application   File "/var/lib/kolla/venv/lib/python3.9/site-packages/flask_restful/__init__.py", line 467, in wrapper
2023-02-14 05:18:18.651 37 ERROR keystone.server.flask.application     resp = resource(*args, **kwargs)
2023-02-14 05:18:18.651 37 ERROR keystone.server.flask.application   File "/var/lib/kolla/venv/lib/python3.9/site-packages/flask/views.py", line 107, in view
2023-02-14 05:18:18.651 37 ERROR keystone.server.flask.application     return current_app.ensure_sync(self.dispatch_request)(**kwargs)
2023-02-14 05:18:18.651 37 ERROR keystone.server.flask.application   File "/var/lib/kolla/venv/lib/python3.9/site-packages/flask_restful/__init__.py", line 582, in dispatch_request
2023-02-14 05:18:18.651 37 ERROR keystone.server.flask.application     resp = meth(*args, **kwargs)
2023-02-14 05:18:18.651 37 ERROR keystone.server.flask.application   File "/var/lib/kolla/venv/lib/python3.9/site-packages/keystone/api/services.py", line 45, in get
2023-02-14 05:18:18.651 37 ERROR keystone.server.flask.application     return self._get_service(service_id)
2023-02-14 05:18:18.651 37 ERROR keystone.server.flask.application   File "/var/lib/kolla/venv/lib/python3.9/site-packages/keystone/api/services.py", line 34, in _get_service
2023-02-14 05:18:18.651 37 ERROR keystone.server.flask.application     return self.wrap_member(PROVIDERS.catalog_api.get_service(service_id))
2023-02-14 05:18:18.651 37 ERROR keystone.server.flask.application   File "/var/lib/kolla/venv/lib/python3.9/site-packages/keystone/common/manager.py", line 115, in wrapped
2023-02-14 05:18:18.651 37 ERROR keystone.server.flask.application     __ret_val = __f(*args, **kwargs)
2023-02-14 05:18:18.651 37 ERROR keystone.server.flask.application   File "/var/lib/kolla/venv/lib/python3.9/site-packages/decorator.py", line 232, in fun
2023-02-14 05:18:18.651 37 ERROR keystone.server.flask.application     return caller(func, *(extras + args), **kw)
2023-02-14 05:18:18.651 37 ERROR keystone.server.flask.application   File "/var/lib/kolla/venv/lib/python3.9/site-packages/dogpile/cache/region.py", line 1577, in get_or_create_for_user_func
2023-02-14 05:18:18.651 37 ERROR keystone.server.flask.application     return self.get_or_create(
2023-02-14 05:18:18.651 37 ERROR keystone.server.flask.application   File "/var/lib/kolla/venv/lib/python3.9/site-packages/dogpile/cache/region.py", line 1042, in get_or_create
2023-02-14 05:18:18.651 37 ERROR keystone.server.flask.application     with Lock(
2023-02-14 05:18:18.651 37 ERROR keystone.server.flask.application   File "/var/lib/kolla/venv/lib/python3.9/site-packages/dogpile/lock.py", line 185, in __enter__
2023-02-14 05:18:18.651 37 ERROR keystone.server.flask.application     return self._enter()
2023-02-14 05:18:18.651 37 ERROR keystone.server.flask.application   File "/var/lib/kolla/venv/lib/python3.9/site-packages/dogpile/lock.py", line 94, in _enter
2023-02-14 05:18:18.651 37 ERROR keystone.server.flask.application     generated = self._enter_create(value, createdtime)
2023-02-14 05:18:18.651 37 ERROR keystone.server.flask.application   File "/var/lib/kolla/venv/lib/python3.9/site-packages/dogpile/lock.py", line 178, in _enter_create
2023-02-14 05:18:18.651 37 ERROR keystone.server.flask.application     return self.creator()
2023-02-14 05:18:18.651 37 ERROR keystone.server.flask.application   File "/var/lib/kolla/venv/lib/python3.9/site-packages/dogpile/cache/region.py", line 995, in gen_value
2023-02-14 05:18:18.651 37 ERROR keystone.server.flask.application     created_value = creator(
2023-02-14 05:18:18.651 37 ERROR keystone.server.flask.application   File "/var/lib/kolla/venv/lib/python3.9/site-packages/keystone/catalog/core.py", line 154, in get_service
2023-02-14 05:18:18.651 37 ERROR keystone.server.flask.application     raise exception.ServiceNotFound(service_id=service_id)
2023-02-14 05:18:18.651 37 ERROR keystone.server.flask.application keystone.exception.ServiceNotFound: Could not find service: network.
2023-02-14 05:18:18.651 37 ERROR keystone.server.flask.application 
2023-02-14 05:18:18.813 38 WARNING py.warnings [None req-c2e94e1e-055d-47e9-90b0-56a2ba76979b 848faf0af3eb4aa7802674da265877bd a7a6832c9baf4439bb3f06a923e8d1f5 - - default default] /var/lib/kolla/venv/lib/python3.9/site-packages/oslo_policy/policy.py:1129: UserWarning: Policy "identity:list_services": "role:reader and system_scope:all" failed scope check. The token used to make the request was project scoped but the policy requires ['system'] scope. This behavior may change in the future where using the intended scope is required
  warnings.warn(msg)

2023-02-14 05:18:19.022 37 WARNING py.warnings [None req-eda66f05-71e3-4ef7-b69d-92a1de5ea44a 848faf0af3eb4aa7802674da265877bd a7a6832c9baf4439bb3f06a923e8d1f5 - - default default] /var/lib/kolla/venv/lib/python3.9/site-packages/oslo_policy/policy.py:1129: UserWarning: Policy "identity:list_services": "role:reader and system_scope:all" failed scope check. The token used to make the request was project scoped but the policy requires ['system'] scope. This behavior may change in the future where using the intended scope is required
  warnings.warn(msg)

2023-02-14 05:18:19.243 38 WARNING py.warnings [None req-57e0855c-83aa-4b07-8a44-b144560b438a 848faf0af3eb4aa7802674da265877bd a7a6832c9baf4439bb3f06a923e8d1f5 - - default default] /var/lib/kolla/venv/lib/python3.9/site-packages/oslo_policy/policy.py:1129: UserWarning: Policy "identity:create_endpoint": "role:admin and system_scope:all" failed scope check. The token used to make the request was project scoped but the policy requires ['system'] scope. This behavior may change in the future where using the intended scope is required
  warnings.warn(msg)

2023-02-14 05:18:23.523 37 ERROR keystone.server.flask.application [None req-fe07f580-ec29-4624-8d7d-bd9d28c199e2 848faf0af3eb4aa7802674da265877bd a7a6832c9baf4439bb3f06a923e8d1f5 - - default default] Could not find service: network.: keystone.exception.ServiceNotFound: Could not find service: network.
2023-02-14 05:18:23.523 37 ERROR keystone.server.flask.application Traceback (most recent call last):
2023-02-14 05:18:23.523 37 ERROR keystone.server.flask.application   File "/var/lib/kolla/venv/lib/python3.9/site-packages/keystone/catalog/core.py", line 152, in get_service
2023-02-14 05:18:23.523 37 ERROR keystone.server.flask.application     return self.driver.get_service(service_id)
2023-02-14 05:18:23.523 37 ERROR keystone.server.flask.application   File "/var/lib/kolla/venv/lib/python3.9/site-packages/keystone/catalog/backends/sql.py", line 196, in get_service
2023-02-14 05:18:23.523 37 ERROR keystone.server.flask.application     return self._get_service(session, service_id).to_dict()
2023-02-14 05:18:23.523 37 ERROR keystone.server.flask.application   File "/var/lib/kolla/venv/lib/python3.9/site-packages/keystone/catalog/backends/sql.py", line 191, in _get_service
2023-02-14 05:18:23.523 37 ERROR keystone.server.flask.application     raise exception.ServiceNotFound(service_id=service_id)
2023-02-14 05:18:23.523 37 ERROR keystone.server.flask.application keystone.exception.ServiceNotFound: Could not find service: network.
2023-02-14 05:18:23.523 37 ERROR keystone.server.flask.application 
2023-02-14 05:18:23.523 37 ERROR keystone.server.flask.application During handling of the above exception, another exception occurred:
2023-02-14 05:18:23.523 37 ERROR keystone.server.flask.application 
2023-02-14 05:18:23.523 37 ERROR keystone.server.flask.application Traceback (most recent call last):
2023-02-14 05:18:23.523 37 ERROR keystone.server.flask.application   File "/var/lib/kolla/venv/lib/python3.9/site-packages/flask/app.py", line 1820, in full_dispatch_request
2023-02-14 05:18:23.523 37 ERROR keystone.server.flask.application     rv = self.dispatch_request()
2023-02-14 05:18:23.523 37 ERROR keystone.server.flask.application   File "/var/lib/kolla/venv/lib/python3.9/site-packages/flask/app.py", line 1796, in dispatch_request
2023-02-14 05:18:23.523 37 ERROR keystone.server.flask.application     return self.ensure_sync(self.view_functions[rule.endpoint])(**view_args)
2023-02-14 05:18:23.523 37 ERROR keystone.server.flask.application   File "/var/lib/kolla/venv/lib/python3.9/site-packages/flask_restful/__init__.py", line 467, in wrapper
2023-02-14 05:18:23.523 37 ERROR keystone.server.flask.application     resp = resource(*args, **kwargs)
2023-02-14 05:18:23.523 37 ERROR keystone.server.flask.application   File "/var/lib/kolla/venv/lib/python3.9/site-packages/flask/views.py", line 107, in view
2023-02-14 05:18:23.523 37 ERROR keystone.server.flask.application     return current_app.ensure_sync(self.dispatch_request)(**kwargs)
2023-02-14 05:18:23.523 37 ERROR keystone.server.flask.application   File "/var/lib/kolla/venv/lib/python3.9/site-packages/flask_restful/__init__.py", line 582, in dispatch_request
2023-02-14 05:18:23.523 37 ERROR keystone.server.flask.application     resp = meth(*args, **kwargs)
2023-02-14 05:18:23.523 37 ERROR keystone.server.flask.application   File "/var/lib/kolla/venv/lib/python3.9/site-packages/keystone/api/services.py", line 45, in get
2023-02-14 05:18:23.523 37 ERROR keystone.server.flask.application     return self._get_service(service_id)
2023-02-14 05:18:23.523 37 ERROR keystone.server.flask.application   File "/var/lib/kolla/venv/lib/python3.9/site-packages/keystone/api/services.py", line 34, in _get_service
2023-02-14 05:18:23.523 37 ERROR keystone.server.flask.application     return self.wrap_member(PROVIDERS.catalog_api.get_service(service_id))
2023-02-14 05:18:23.523 37 ERROR keystone.server.flask.application   File "/var/lib/kolla/venv/lib/python3.9/site-packages/keystone/common/manager.py", line 115, in wrapped
2023-02-14 05:18:23.523 37 ERROR keystone.server.flask.application     __ret_val = __f(*args, **kwargs)
2023-02-14 05:18:23.523 37 ERROR keystone.server.flask.application   File "/var/lib/kolla/venv/lib/python3.9/site-packages/decorator.py", line 232, in fun
2023-02-14 05:18:23.523 37 ERROR keystone.server.flask.application     return caller(func, *(extras + args), **kw)
2023-02-14 05:18:23.523 37 ERROR keystone.server.flask.application   File "/var/lib/kolla/venv/lib/python3.9/site-packages/dogpile/cache/region.py", line 1577, in get_or_create_for_user_func
2023-02-14 05:18:23.523 37 ERROR keystone.server.flask.application     return self.get_or_create(
2023-02-14 05:18:23.523 37 ERROR keystone.server.flask.application   File "/var/lib/kolla/venv/lib/python3.9/site-packages/dogpile/cache/region.py", line 1042, in get_or_create
2023-02-14 05:18:23.523 37 ERROR keystone.server.flask.application     with Lock(
2023-02-14 05:18:23.523 37 ERROR keystone.server.flask.application   File "/var/lib/kolla/venv/lib/python3.9/site-packages/dogpile/lock.py", line 185, in __enter__
2023-02-14 05:18:23.523 37 ERROR keystone.server.flask.application     return self._enter()
2023-02-14 05:18:23.523 37 ERROR keystone.server.flask.application   File "/var/lib/kolla/venv/lib/python3.9/site-packages/dogpile/lock.py", line 94, in _enter
2023-02-14 05:18:23.523 37 ERROR keystone.server.flask.application     generated = self._enter_create(value, createdtime)
2023-02-14 05:18:23.523 37 ERROR keystone.server.flask.application   File "/var/lib/kolla/venv/lib/python3.9/site-packages/dogpile/lock.py", line 178, in _enter_create
2023-02-14 05:18:23.523 37 ERROR keystone.server.flask.application     return self.creator()
2023-02-14 05:18:23.523 37 ERROR keystone.server.flask.application   File "/var/lib/kolla/venv/lib/python3.9/site-packages/dogpile/cache/region.py", line 995, in gen_value
2023-02-14 05:18:23.523 37 ERROR keystone.server.flask.application     created_value = creator(
2023-02-14 05:18:23.523 37 ERROR keystone.server.flask.application   File "/var/lib/kolla/venv/lib/python3.9/site-packages/keystone/catalog/core.py", line 154, in get_service
2023-02-14 05:18:23.523 37 ERROR keystone.server.flask.application     raise exception.ServiceNotFound(service_id=service_id)
2023-02-14 05:18:23.523 37 ERROR keystone.server.flask.application keystone.exception.ServiceNotFound: Could not find service: network.
2023-02-14 05:18:23.523 37 ERROR keystone.server.flask.application 
2023-02-14 05:18:29.594 37 ERROR keystone.server.flask.application [None req-144e6f64-9062-42f9-ac33-769820c4af16 848faf0af3eb4aa7802674da265877bd a7a6832c9baf4439bb3f06a923e8d1f5 - - default default] Could not find service: network.: keystone.exception.ServiceNotFound: Could not find service: network.
2023-02-14 05:18:29.594 37 ERROR keystone.server.flask.application Traceback (most recent call last):
2023-02-14 05:18:29.594 37 ERROR keystone.server.flask.application   File "/var/lib/kolla/venv/lib/python3.9/site-packages/keystone/catalog/core.py", line 152, in get_service
2023-02-14 05:18:29.594 37 ERROR keystone.server.flask.application     return self.driver.get_service(service_id)
2023-02-14 05:18:29.594 37 ERROR keystone.server.flask.application   File "/var/lib/kolla/venv/lib/python3.9/site-packages/keystone/catalog/backends/sql.py", line 196, in get_service
2023-02-14 05:18:29.594 37 ERROR keystone.server.flask.application     return self._get_service(session, service_id).to_dict()
2023-02-14 05:18:29.594 37 ERROR keystone.server.flask.application   File "/var/lib/kolla/venv/lib/python3.9/site-packages/keystone/catalog/backends/sql.py", line 191, in _get_service
2023-02-14 05:18:29.594 37 ERROR keystone.server.flask.application     raise exception.ServiceNotFound(service_id=service_id)
2023-02-14 05:18:29.594 37 ERROR keystone.server.flask.application keystone.exception.ServiceNotFound: Could not find service: network.
2023-02-14 05:18:29.594 37 ERROR keystone.server.flask.application 
2023-02-14 05:18:29.594 37 ERROR keystone.server.flask.application During handling of the above exception, another exception occurred:
2023-02-14 05:18:29.594 37 ERROR keystone.server.flask.application 
2023-02-14 05:18:29.594 37 ERROR keystone.server.flask.application Traceback (most recent call last):
2023-02-14 05:18:29.594 37 ERROR keystone.server.flask.application   File "/var/lib/kolla/venv/lib/python3.9/site-packages/flask/app.py", line 1820, in full_dispatch_request
2023-02-14 05:18:29.594 37 ERROR keystone.server.flask.application     rv = self.dispatch_request()
2023-02-14 05:18:29.594 37 ERROR keystone.server.flask.application   File "/var/lib/kolla/venv/lib/python3.9/site-packages/flask/app.py", line 1796, in dispatch_request
2023-02-14 05:18:29.594 37 ERROR keystone.server.flask.application     return self.ensure_sync(self.view_functions[rule.endpoint])(**view_args)
2023-02-14 05:18:29.594 37 ERROR keystone.server.flask.application   File "/var/lib/kolla/venv/lib/python3.9/site-packages/flask_restful/__init__.py", line 467, in wrapper
2023-02-14 05:18:29.594 37 ERROR keystone.server.flask.application     resp = resource(*args, **kwargs)
2023-02-14 05:18:29.594 37 ERROR keystone.server.flask.application   File "/var/lib/kolla/venv/lib/python3.9/site-packages/flask/views.py", line 107, in view
2023-02-14 05:18:29.594 37 ERROR keystone.server.flask.application     return current_app.ensure_sync(self.dispatch_request)(**kwargs)
2023-02-14 05:18:29.594 37 ERROR keystone.server.flask.application   File "/var/lib/kolla/venv/lib/python3.9/site-packages/flask_restful/__init__.py", line 582, in dispatch_request
2023-02-14 05:18:29.594 37 ERROR keystone.server.flask.application     resp = meth(*args, **kwargs)
2023-02-14 05:18:29.594 37 ERROR keystone.server.flask.application   File "/var/lib/kolla/venv/lib/python3.9/site-packages/keystone/api/services.py", line 45, in get
2023-02-14 05:18:29.594 37 ERROR keystone.server.flask.application     return self._get_service(service_id)
2023-02-14 05:18:29.594 37 ERROR keystone.server.flask.application   File "/var/lib/kolla/venv/lib/python3.9/site-packages/keystone/api/services.py", line 34, in _get_service
2023-02-14 05:18:29.594 37 ERROR keystone.server.flask.application     return self.wrap_member(PROVIDERS.catalog_api.get_service(service_id))
2023-02-14 05:18:29.594 37 ERROR keystone.server.flask.application   File "/var/lib/kolla/venv/lib/python3.9/site-packages/keystone/common/manager.py", line 115, in wrapped
2023-02-14 05:18:29.594 37 ERROR keystone.server.flask.application     __ret_val = __f(*args, **kwargs)
2023-02-14 05:18:29.594 37 ERROR keystone.server.flask.application   File "/var/lib/kolla/venv/lib/python3.9/site-packages/decorator.py", line 232, in fun
2023-02-14 05:18:29.594 37 ERROR keystone.server.flask.application     return caller(func, *(extras + args), **kw)
2023-02-14 05:18:29.594 37 ERROR keystone.server.flask.application   File "/var/lib/kolla/venv/lib/python3.9/site-packages/dogpile/cache/region.py", line 1577, in get_or_create_for_user_func
2023-02-14 05:18:29.594 37 ERROR keystone.server.flask.application     return self.get_or_create(
2023-02-14 05:18:29.594 37 ERROR keystone.server.flask.application   File "/var/lib/kolla/venv/lib/python3.9/site-packages/dogpile/cache/region.py", line 1042, in get_or_create
2023-02-14 05:18:29.594 37 ERROR keystone.server.flask.application     with Lock(
2023-02-14 05:18:29.594 37 ERROR keystone.server.flask.application   File "/var/lib/kolla/venv/lib/python3.9/site-packages/dogpile/lock.py", line 185, in __enter__
2023-02-14 05:18:29.594 37 ERROR keystone.server.flask.application     return self._enter()
2023-02-14 05:18:29.594 37 ERROR keystone.server.flask.application   File "/var/lib/kolla/venv/lib/python3.9/site-packages/dogpile/lock.py", line 94, in _enter
2023-02-14 05:18:29.594 37 ERROR keystone.server.flask.application     generated = self._enter_create(value, createdtime)
2023-02-14 05:18:29.594 37 ERROR keystone.server.flask.application   File "/var/lib/kolla/venv/lib/python3.9/site-packages/dogpile/lock.py", line 178, in _enter_create
2023-02-14 05:18:29.594 37 ERROR keystone.server.flask.application     return self.creator()
2023-02-14 05:18:29.594 37 ERROR keystone.server.flask.application   File "/var/lib/kolla/venv/lib/python3.9/site-packages/dogpile/cache/region.py", line 995, in gen_value
2023-02-14 05:18:29.594 37 ERROR keystone.server.flask.application     created_value = creator(
2023-02-14 05:18:29.594 37 ERROR keystone.server.flask.application   File "/var/lib/kolla/venv/lib/python3.9/site-packages/keystone/catalog/core.py", line 154, in get_service
2023-02-14 05:18:29.594 37 ERROR keystone.server.flask.application     raise exception.ServiceNotFound(service_id=service_id)
2023-02-14 05:18:29.594 37 ERROR keystone.server.flask.application keystone.exception.ServiceNotFound: Could not find service: network.
2023-02-14 05:18:29.594 37 ERROR keystone.server.flask.application 
