2023-03-15 15:04:07.720 23 INFO alembic.runtime.migration [-] Context impl MySQLImpl.
2023-03-15 15:04:07.724 23 INFO alembic.runtime.migration [-] Will assume non-transactional DDL.
2023-03-15 15:04:07.764 23 INFO alembic.runtime.migration [-] Context impl MySQLImpl.
2023-03-15 15:04:07.765 23 INFO alembic.runtime.migration [-] Will assume non-transactional DDL.
2023-03-15 15:04:07.831 23 INFO alembic.runtime.migration [-] Running upgrade  -> 27e647c0fad4, Initial version.
2023-03-15 15:04:09.271 23 INFO alembic.runtime.migration [-] Running upgrade 27e647c0fad4 -> e25ffa003242, Initial no-op Yoga contract migration.
2023-03-15 15:04:09.286 23 INFO alembic.runtime.migration [-] Running upgrade 27e647c0fad4 -> 29e87d24a316, Initial no-op Yoga expand migration.
2023-03-15 15:04:18.156 8 INFO keystone.common.fernet_utils [-] Created a new temporary key: /etc/keystone/fernet-keys/0.tmp
2023-03-15 15:04:18.161 8 INFO keystone.common.fernet_utils [-] Become a valid new key: /etc/keystone/fernet-keys/0
2023-03-15 15:04:18.162 8 INFO keystone.common.fernet_utils [-] Starting key rotation with 1 key files: ['/etc/keystone/fernet-keys/0']
2023-03-15 15:04:18.163 8 INFO keystone.common.fernet_utils [-] Created a new temporary key: /etc/keystone/fernet-keys/0.tmp
2023-03-15 15:04:18.163 8 INFO keystone.common.fernet_utils [-] Current primary key is: 0
2023-03-15 15:04:18.164 8 INFO keystone.common.fernet_utils [-] Next primary key will be: 1
2023-03-15 15:04:18.165 8 INFO keystone.common.fernet_utils [-] Promoted key 0 to be the primary: 1
2023-03-15 15:04:18.165 8 INFO keystone.common.fernet_utils [-] Become a valid new key: /etc/keystone/fernet-keys/0
2023-03-15 15:04:35.984 33 INFO keystone.cmd.bootstrap [None req-b81c9e19-ee6b-44e3-a520-852e1a609ca6 - - - - - -] Created domain default
2023-03-15 15:04:36.049 33 INFO keystone.cmd.bootstrap [None req-b81c9e19-ee6b-44e3-a520-852e1a609ca6 - - - - - -] Created project admin
2023-03-15 15:04:36.661 33 INFO keystone.cmd.bootstrap [None req-b81c9e19-ee6b-44e3-a520-852e1a609ca6 - - - - - -] Created user admin
2023-03-15 15:04:36.685 33 INFO keystone.cmd.bootstrap [None req-b81c9e19-ee6b-44e3-a520-852e1a609ca6 - - - - - -] Created role reader
2023-03-15 15:04:36.700 33 INFO keystone.cmd.bootstrap [None req-b81c9e19-ee6b-44e3-a520-852e1a609ca6 - - - - - -] Created role member
2023-03-15 15:04:36.733 33 INFO keystone.cmd.bootstrap [None req-b81c9e19-ee6b-44e3-a520-852e1a609ca6 - - - - - -] Created implied role where bda6a31c71a642d4a6d4b0bbed553258 implies ccf5119efce242d5a4c35d7538f28152
2023-03-15 15:04:36.745 33 INFO keystone.cmd.bootstrap [None req-b81c9e19-ee6b-44e3-a520-852e1a609ca6 - - - - - -] Created role admin
2023-03-15 15:04:36.767 33 INFO keystone.cmd.bootstrap [None req-b81c9e19-ee6b-44e3-a520-852e1a609ca6 - - - - - -] Created implied role where 09ad5d1fd1b242dea94ee4eea7266bce implies bda6a31c71a642d4a6d4b0bbed553258
2023-03-15 15:04:36.782 33 INFO keystone.cmd.bootstrap [None req-b81c9e19-ee6b-44e3-a520-852e1a609ca6 - - - - - -] Granted role admin on project admin to user admin.
2023-03-15 15:04:36.790 33 INFO keystone.cmd.bootstrap [None req-b81c9e19-ee6b-44e3-a520-852e1a609ca6 - - - - - -] Granted role admin on the system to user admin.
2023-03-15 15:04:36.807 33 WARNING py.warnings [None req-b81c9e19-ee6b-44e3-a520-852e1a609ca6 - - - - - -] /var/lib/kolla/venv/lib/python3.9/site-packages/pycadf/identifier.py:71: UserWarning: Invalid uuid: RegionOne. To ensure interoperability, identifiers should be a valid uuid.
  warnings.warn(('Invalid uuid: %s. To ensure interoperability, '

2023-03-15 15:04:36.814 33 INFO keystone.cmd.bootstrap [None req-b81c9e19-ee6b-44e3-a520-852e1a609ca6 - - - - - -] Created region RegionOne
2023-03-15 15:04:36.859 33 INFO keystone.cmd.bootstrap [None req-b81c9e19-ee6b-44e3-a520-852e1a609ca6 - - - - - -] Created public endpoint http://169.16.1.186:5000
2023-03-15 15:04:36.871 33 INFO keystone.cmd.bootstrap [None req-b81c9e19-ee6b-44e3-a520-852e1a609ca6 - - - - - -] Created internal endpoint http://169.16.1.186:5000
2023-03-15 15:05:02.529 39 WARNING keystone.common.rbac_enforcer.enforcer [None req-4961c048-2aa4-4d5c-91c5-1a9e57fefdb5 c05eac42db3b4672a5b2dcff754581a1 - - all default -] Deprecated policy rules found. Use oslopolicy-policy-generator and oslopolicy-policy-upgrade to detect and resolve deprecated policies in your configuration.
2023-03-15 15:05:03.430 38 WARNING keystone.common.rbac_enforcer.enforcer [None req-c53529e9-6bcc-4205-b71e-4fe8cf9bc402 c05eac42db3b4672a5b2dcff754581a1 - - all default -] Deprecated policy rules found. Use oslopolicy-policy-generator and oslopolicy-policy-upgrade to detect and resolve deprecated policies in your configuration.
2023-03-15 15:05:10.639 40 WARNING keystone.common.rbac_enforcer.enforcer [None req-bc2c3cd8-3313-40e4-8f7c-23a7647d4312 c05eac42db3b4672a5b2dcff754581a1 - - all default -] Deprecated policy rules found. Use oslopolicy-policy-generator and oslopolicy-policy-upgrade to detect and resolve deprecated policies in your configuration.
2023-03-15 15:06:23.780 39 ERROR keystone.server.flask.application [None req-eb5aa50f-3f73-42e0-8eae-ae3eacf28bde c05eac42db3b4672a5b2dcff754581a1 - - all default -] Could not find project: service.: keystone.exception.ProjectNotFound: Could not find project: service.
2023-03-15 15:06:23.780 39 ERROR keystone.server.flask.application Traceback (most recent call last):
2023-03-15 15:06:23.780 39 ERROR keystone.server.flask.application   File "/var/lib/kolla/venv/lib/python3.9/site-packages/flask/app.py", line 1820, in full_dispatch_request
2023-03-15 15:06:23.780 39 ERROR keystone.server.flask.application     rv = self.dispatch_request()
2023-03-15 15:06:23.780 39 ERROR keystone.server.flask.application   File "/var/lib/kolla/venv/lib/python3.9/site-packages/flask/app.py", line 1796, in dispatch_request
2023-03-15 15:06:23.780 39 ERROR keystone.server.flask.application     return self.ensure_sync(self.view_functions[rule.endpoint])(**view_args)
2023-03-15 15:06:23.780 39 ERROR keystone.server.flask.application   File "/var/lib/kolla/venv/lib/python3.9/site-packages/flask_restful/__init__.py", line 467, in wrapper
2023-03-15 15:06:23.780 39 ERROR keystone.server.flask.application     resp = resource(*args, **kwargs)
2023-03-15 15:06:23.780 39 ERROR keystone.server.flask.application   File "/var/lib/kolla/venv/lib/python3.9/site-packages/flask/views.py", line 107, in view
2023-03-15 15:06:23.780 39 ERROR keystone.server.flask.application     return current_app.ensure_sync(self.dispatch_request)(**kwargs)
2023-03-15 15:06:23.780 39 ERROR keystone.server.flask.application   File "/var/lib/kolla/venv/lib/python3.9/site-packages/flask_restful/__init__.py", line 582, in dispatch_request
2023-03-15 15:06:23.780 39 ERROR keystone.server.flask.application     resp = meth(*args, **kwargs)
2023-03-15 15:06:23.780 39 ERROR keystone.server.flask.application   File "/var/lib/kolla/venv/lib/python3.9/site-packages/keystone/api/projects.py", line 151, in get
2023-03-15 15:06:23.780 39 ERROR keystone.server.flask.application     return self._get_project(project_id)
2023-03-15 15:06:23.780 39 ERROR keystone.server.flask.application   File "/var/lib/kolla/venv/lib/python3.9/site-packages/keystone/api/projects.py", line 107, in _get_project
2023-03-15 15:06:23.780 39 ERROR keystone.server.flask.application     project = PROVIDERS.resource_api.get_project(project_id)
2023-03-15 15:06:23.780 39 ERROR keystone.server.flask.application   File "/var/lib/kolla/venv/lib/python3.9/site-packages/keystone/common/manager.py", line 115, in wrapped
2023-03-15 15:06:23.780 39 ERROR keystone.server.flask.application     __ret_val = __f(*args, **kwargs)
2023-03-15 15:06:23.780 39 ERROR keystone.server.flask.application   File "/var/lib/kolla/venv/lib/python3.9/site-packages/decorator.py", line 232, in fun
2023-03-15 15:06:23.780 39 ERROR keystone.server.flask.application     return caller(func, *(extras + args), **kw)
2023-03-15 15:06:23.780 39 ERROR keystone.server.flask.application   File "/var/lib/kolla/venv/lib/python3.9/site-packages/dogpile/cache/region.py", line 1577, in get_or_create_for_user_func
2023-03-15 15:06:23.780 39 ERROR keystone.server.flask.application     return self.get_or_create(
2023-03-15 15:06:23.780 39 ERROR keystone.server.flask.application   File "/var/lib/kolla/venv/lib/python3.9/site-packages/dogpile/cache/region.py", line 1042, in get_or_create
2023-03-15 15:06:23.780 39 ERROR keystone.server.flask.application     with Lock(
2023-03-15 15:06:23.780 39 ERROR keystone.server.flask.application   File "/var/lib/kolla/venv/lib/python3.9/site-packages/dogpile/lock.py", line 185, in __enter__
2023-03-15 15:06:23.780 39 ERROR keystone.server.flask.application     return self._enter()
2023-03-15 15:06:23.780 39 ERROR keystone.server.flask.application   File "/var/lib/kolla/venv/lib/python3.9/site-packages/dogpile/lock.py", line 94, in _enter
2023-03-15 15:06:23.780 39 ERROR keystone.server.flask.application     generated = self._enter_create(value, createdtime)
2023-03-15 15:06:23.780 39 ERROR keystone.server.flask.application   File "/var/lib/kolla/venv/lib/python3.9/site-packages/dogpile/lock.py", line 178, in _enter_create
2023-03-15 15:06:23.780 39 ERROR keystone.server.flask.application     return self.creator()
2023-03-15 15:06:23.780 39 ERROR keystone.server.flask.application   File "/var/lib/kolla/venv/lib/python3.9/site-packages/dogpile/cache/region.py", line 995, in gen_value
2023-03-15 15:06:23.780 39 ERROR keystone.server.flask.application     created_value = creator(
2023-03-15 15:06:23.780 39 ERROR keystone.server.flask.application   File "/var/lib/kolla/venv/lib/python3.9/site-packages/keystone/resource/core.py", line 903, in get_project
2023-03-15 15:06:23.780 39 ERROR keystone.server.flask.application     return self.driver.get_project(project_id)
2023-03-15 15:06:23.780 39 ERROR keystone.server.flask.application   File "/var/lib/kolla/venv/lib/python3.9/site-packages/keystone/resource/backends/sql.py", line 49, in get_project
2023-03-15 15:06:23.780 39 ERROR keystone.server.flask.application     return self._get_project(session, project_id).to_dict()
2023-03-15 15:06:23.780 39 ERROR keystone.server.flask.application   File "/var/lib/kolla/venv/lib/python3.9/site-packages/keystone/resource/backends/sql.py", line 44, in _get_project
2023-03-15 15:06:23.780 39 ERROR keystone.server.flask.application     raise exception.ProjectNotFound(project_id=project_id)
2023-03-15 15:06:23.780 39 ERROR keystone.server.flask.application keystone.exception.ProjectNotFound: Could not find project: service.
2023-03-15 15:06:23.780 39 ERROR keystone.server.flask.application 
2023-03-15 15:06:32.657 40 ERROR keystone.server.flask.application [None req-d77427f8-0749-4407-8cdd-294ac337c5d6 c05eac42db3b4672a5b2dcff754581a1 - - all default -] Could not find project: service.: keystone.exception.ProjectNotFound: Could not find project: service.
2023-03-15 15:06:32.657 40 ERROR keystone.server.flask.application Traceback (most recent call last):
2023-03-15 15:06:32.657 40 ERROR keystone.server.flask.application   File "/var/lib/kolla/venv/lib/python3.9/site-packages/flask/app.py", line 1820, in full_dispatch_request
2023-03-15 15:06:32.657 40 ERROR keystone.server.flask.application     rv = self.dispatch_request()
2023-03-15 15:06:32.657 40 ERROR keystone.server.flask.application   File "/var/lib/kolla/venv/lib/python3.9/site-packages/flask/app.py", line 1796, in dispatch_request
2023-03-15 15:06:32.657 40 ERROR keystone.server.flask.application     return self.ensure_sync(self.view_functions[rule.endpoint])(**view_args)
2023-03-15 15:06:32.657 40 ERROR keystone.server.flask.application   File "/var/lib/kolla/venv/lib/python3.9/site-packages/flask_restful/__init__.py", line 467, in wrapper
2023-03-15 15:06:32.657 40 ERROR keystone.server.flask.application     resp = resource(*args, **kwargs)
2023-03-15 15:06:32.657 40 ERROR keystone.server.flask.application   File "/var/lib/kolla/venv/lib/python3.9/site-packages/flask/views.py", line 107, in view
2023-03-15 15:06:32.657 40 ERROR keystone.server.flask.application     return current_app.ensure_sync(self.dispatch_request)(**kwargs)
2023-03-15 15:06:32.657 40 ERROR keystone.server.flask.application   File "/var/lib/kolla/venv/lib/python3.9/site-packages/flask_restful/__init__.py", line 582, in dispatch_request
2023-03-15 15:06:32.657 40 ERROR keystone.server.flask.application     resp = meth(*args, **kwargs)
2023-03-15 15:06:32.657 40 ERROR keystone.server.flask.application   File "/var/lib/kolla/venv/lib/python3.9/site-packages/keystone/api/projects.py", line 151, in get
2023-03-15 15:06:32.657 40 ERROR keystone.server.flask.application     return self._get_project(project_id)
2023-03-15 15:06:32.657 40 ERROR keystone.server.flask.application   File "/var/lib/kolla/venv/lib/python3.9/site-packages/keystone/api/projects.py", line 107, in _get_project
2023-03-15 15:06:32.657 40 ERROR keystone.server.flask.application     project = PROVIDERS.resource_api.get_project(project_id)
2023-03-15 15:06:32.657 40 ERROR keystone.server.flask.application   File "/var/lib/kolla/venv/lib/python3.9/site-packages/keystone/common/manager.py", line 115, in wrapped
2023-03-15 15:06:32.657 40 ERROR keystone.server.flask.application     __ret_val = __f(*args, **kwargs)
2023-03-15 15:06:32.657 40 ERROR keystone.server.flask.application   File "/var/lib/kolla/venv/lib/python3.9/site-packages/decorator.py", line 232, in fun
2023-03-15 15:06:32.657 40 ERROR keystone.server.flask.application     return caller(func, *(extras + args), **kw)
2023-03-15 15:06:32.657 40 ERROR keystone.server.flask.application   File "/var/lib/kolla/venv/lib/python3.9/site-packages/dogpile/cache/region.py", line 1577, in get_or_create_for_user_func
2023-03-15 15:06:32.657 40 ERROR keystone.server.flask.application     return self.get_or_create(
2023-03-15 15:06:32.657 40 ERROR keystone.server.flask.application   File "/var/lib/kolla/venv/lib/python3.9/site-packages/dogpile/cache/region.py", line 1042, in get_or_create
2023-03-15 15:06:32.657 40 ERROR keystone.server.flask.application     with Lock(
2023-03-15 15:06:32.657 40 ERROR keystone.server.flask.application   File "/var/lib/kolla/venv/lib/python3.9/site-packages/dogpile/lock.py", line 185, in __enter__
2023-03-15 15:06:32.657 40 ERROR keystone.server.flask.application     return self._enter()
2023-03-15 15:06:32.657 40 ERROR keystone.server.flask.application   File "/var/lib/kolla/venv/lib/python3.9/site-packages/dogpile/lock.py", line 94, in _enter
2023-03-15 15:06:32.657 40 ERROR keystone.server.flask.application     generated = self._enter_create(value, createdtime)
2023-03-15 15:06:32.657 40 ERROR keystone.server.flask.application   File "/var/lib/kolla/venv/lib/python3.9/site-packages/dogpile/lock.py", line 178, in _enter_create
2023-03-15 15:06:32.657 40 ERROR keystone.server.flask.application     return self.creator()
2023-03-15 15:06:32.657 40 ERROR keystone.server.flask.application   File "/var/lib/kolla/venv/lib/python3.9/site-packages/dogpile/cache/region.py", line 995, in gen_value
2023-03-15 15:06:32.657 40 ERROR keystone.server.flask.application     created_value = creator(
2023-03-15 15:06:32.657 40 ERROR keystone.server.flask.application   File "/var/lib/kolla/venv/lib/python3.9/site-packages/keystone/resource/core.py", line 903, in get_project
2023-03-15 15:06:32.657 40 ERROR keystone.server.flask.application     return self.driver.get_project(project_id)
2023-03-15 15:06:32.657 40 ERROR keystone.server.flask.application   File "/var/lib/kolla/venv/lib/python3.9/site-packages/keystone/resource/backends/sql.py", line 49, in get_project
2023-03-15 15:06:32.657 40 ERROR keystone.server.flask.application     return self._get_project(session, project_id).to_dict()
2023-03-15 15:06:32.657 40 ERROR keystone.server.flask.application   File "/var/lib/kolla/venv/lib/python3.9/site-packages/keystone/resource/backends/sql.py", line 44, in _get_project
2023-03-15 15:06:32.657 40 ERROR keystone.server.flask.application     raise exception.ProjectNotFound(project_id=project_id)
2023-03-15 15:06:32.657 40 ERROR keystone.server.flask.application keystone.exception.ProjectNotFound: Could not find project: service.
2023-03-15 15:06:32.657 40 ERROR keystone.server.flask.application 
2023-03-15 15:06:47.011 40 ERROR keystone.server.flask.application [None req-7ab4d33c-ef4c-4a88-a28a-0b08e76afe8f c05eac42db3b4672a5b2dcff754581a1 - - all default -] Could not find role: admin.: keystone.exception.RoleNotFound: Could not find role: admin.
2023-03-15 15:06:47.011 40 ERROR keystone.server.flask.application Traceback (most recent call last):
2023-03-15 15:06:47.011 40 ERROR keystone.server.flask.application   File "/var/lib/kolla/venv/lib/python3.9/site-packages/flask/app.py", line 1820, in full_dispatch_request
2023-03-15 15:06:47.011 40 ERROR keystone.server.flask.application     rv = self.dispatch_request()
2023-03-15 15:06:47.011 40 ERROR keystone.server.flask.application   File "/var/lib/kolla/venv/lib/python3.9/site-packages/flask/app.py", line 1796, in dispatch_request
2023-03-15 15:06:47.011 40 ERROR keystone.server.flask.application     return self.ensure_sync(self.view_functions[rule.endpoint])(**view_args)
2023-03-15 15:06:47.011 40 ERROR keystone.server.flask.application   File "/var/lib/kolla/venv/lib/python3.9/site-packages/flask_restful/__init__.py", line 467, in wrapper
2023-03-15 15:06:47.011 40 ERROR keystone.server.flask.application     resp = resource(*args, **kwargs)
2023-03-15 15:06:47.011 40 ERROR keystone.server.flask.application   File "/var/lib/kolla/venv/lib/python3.9/site-packages/flask/views.py", line 107, in view
2023-03-15 15:06:47.011 40 ERROR keystone.server.flask.application     return current_app.ensure_sync(self.dispatch_request)(**kwargs)
2023-03-15 15:06:47.011 40 ERROR keystone.server.flask.application   File "/var/lib/kolla/venv/lib/python3.9/site-packages/flask_restful/__init__.py", line 582, in dispatch_request
2023-03-15 15:06:47.011 40 ERROR keystone.server.flask.application     resp = meth(*args, **kwargs)
2023-03-15 15:06:47.011 40 ERROR keystone.server.flask.application   File "/var/lib/kolla/venv/lib/python3.9/site-packages/keystone/api/roles.py", line 50, in get
2023-03-15 15:06:47.011 40 ERROR keystone.server.flask.application     return self._get_role(role_id)
2023-03-15 15:06:47.011 40 ERROR keystone.server.flask.application   File "/var/lib/kolla/venv/lib/python3.9/site-packages/keystone/api/roles.py", line 70, in _get_role
2023-03-15 15:06:47.011 40 ERROR keystone.server.flask.application     ENFORCER.enforce_call(action='identity:get_role')
2023-03-15 15:06:47.011 40 ERROR keystone.server.flask.application   File "/var/lib/kolla/venv/lib/python3.9/site-packages/keystone/common/rbac_enforcer/enforcer.py", line 402, in enforce_call
2023-03-15 15:06:47.011 40 ERROR keystone.server.flask.application     policy_dict.update(cls._extract_member_target_data(
2023-03-15 15:06:47.011 40 ERROR keystone.server.flask.application   File "/var/lib/kolla/venv/lib/python3.9/site-packages/keystone/common/rbac_enforcer/enforcer.py", line 234, in _extract_member_target_data
2023-03-15 15:06:47.011 40 ERROR keystone.server.flask.application     member_name: func(flask.request.view_args[key])
2023-03-15 15:06:47.011 40 ERROR keystone.server.flask.application   File "/var/lib/kolla/venv/lib/python3.9/site-packages/keystone/common/manager.py", line 115, in wrapped
2023-03-15 15:06:47.011 40 ERROR keystone.server.flask.application     __ret_val = __f(*args, **kwargs)
2023-03-15 15:06:47.011 40 ERROR keystone.server.flask.application   File "/var/lib/kolla/venv/lib/python3.9/site-packages/decorator.py", line 232, in fun
2023-03-15 15:06:47.011 40 ERROR keystone.server.flask.application     return caller(func, *(extras + args), **kw)
2023-03-15 15:06:47.011 40 ERROR keystone.server.flask.application   File "/var/lib/kolla/venv/lib/python3.9/site-packages/dogpile/cache/region.py", line 1577, in get_or_create_for_user_func
2023-03-15 15:06:47.011 40 ERROR keystone.server.flask.application     return self.get_or_create(
2023-03-15 15:06:47.011 40 ERROR keystone.server.flask.application   File "/var/lib/kolla/venv/lib/python3.9/site-packages/dogpile/cache/region.py", line 1042, in get_or_create
2023-03-15 15:06:47.011 40 ERROR keystone.server.flask.application     with Lock(
2023-03-15 15:06:47.011 40 ERROR keystone.server.flask.application   File "/var/lib/kolla/venv/lib/python3.9/site-packages/dogpile/lock.py", line 185, in __enter__
2023-03-15 15:06:47.011 40 ERROR keystone.server.flask.application     return self._enter()
2023-03-15 15:06:47.011 40 ERROR keystone.server.flask.application   File "/var/lib/kolla/venv/lib/python3.9/site-packages/dogpile/lock.py", line 94, in _enter
2023-03-15 15:06:47.011 40 ERROR keystone.server.flask.application     generated = self._enter_create(value, createdtime)
2023-03-15 15:06:47.011 40 ERROR keystone.server.flask.application   File "/var/lib/kolla/venv/lib/python3.9/site-packages/dogpile/lock.py", line 178, in _enter_create
2023-03-15 15:06:47.011 40 ERROR keystone.server.flask.application     return self.creator()
2023-03-15 15:06:47.011 40 ERROR keystone.server.flask.application   File "/var/lib/kolla/venv/lib/python3.9/site-packages/dogpile/cache/region.py", line 995, in gen_value
2023-03-15 15:06:47.011 40 ERROR keystone.server.flask.application     created_value = creator(
2023-03-15 15:06:47.011 40 ERROR keystone.server.flask.application   File "/var/lib/kolla/venv/lib/python3.9/site-packages/keystone/assignment/core.py", line 1276, in get_role
2023-03-15 15:06:47.011 40 ERROR keystone.server.flask.application     return self.driver.get_role(role_id)
2023-03-15 15:06:47.011 40 ERROR keystone.server.flask.application   File "/var/lib/kolla/venv/lib/python3.9/site-packages/keystone/assignment/role_backends/sql.py", line 70, in get_role
2023-03-15 15:06:47.011 40 ERROR keystone.server.flask.application     return self._get_role(session, role_id).to_dict()
2023-03-15 15:06:47.011 40 ERROR keystone.server.flask.application   File "/var/lib/kolla/venv/lib/python3.9/site-packages/keystone/assignment/role_backends/sql.py", line 65, in _get_role
2023-03-15 15:06:47.011 40 ERROR keystone.server.flask.application     raise exception.RoleNotFound(role_id=role_id)
2023-03-15 15:06:47.011 40 ERROR keystone.server.flask.application keystone.exception.RoleNotFound: Could not find role: admin.
2023-03-15 15:06:47.011 40 ERROR keystone.server.flask.application 
2023-03-15 15:06:48.352 40 ERROR keystone.server.flask.application [None req-ea51798d-dd73-4665-9fb8-69bfb5d36c63 c05eac42db3b4672a5b2dcff754581a1 - - all default -] Could not find user: ironic.: keystone.exception.UserNotFound: Could not find user: ironic.
2023-03-15 15:06:48.352 40 ERROR keystone.server.flask.application Traceback (most recent call last):
2023-03-15 15:06:48.352 40 ERROR keystone.server.flask.application   File "/var/lib/kolla/venv/lib/python3.9/site-packages/flask/app.py", line 1820, in full_dispatch_request
2023-03-15 15:06:48.352 40 ERROR keystone.server.flask.application     rv = self.dispatch_request()
2023-03-15 15:06:48.352 40 ERROR keystone.server.flask.application   File "/var/lib/kolla/venv/lib/python3.9/site-packages/flask/app.py", line 1796, in dispatch_request
2023-03-15 15:06:48.352 40 ERROR keystone.server.flask.application     return self.ensure_sync(self.view_functions[rule.endpoint])(**view_args)
2023-03-15 15:06:48.352 40 ERROR keystone.server.flask.application   File "/var/lib/kolla/venv/lib/python3.9/site-packages/flask_restful/__init__.py", line 467, in wrapper
2023-03-15 15:06:48.352 40 ERROR keystone.server.flask.application     resp = resource(*args, **kwargs)
2023-03-15 15:06:48.352 40 ERROR keystone.server.flask.application   File "/var/lib/kolla/venv/lib/python3.9/site-packages/flask/views.py", line 107, in view
2023-03-15 15:06:48.352 40 ERROR keystone.server.flask.application     return current_app.ensure_sync(self.dispatch_request)(**kwargs)
2023-03-15 15:06:48.352 40 ERROR keystone.server.flask.application   File "/var/lib/kolla/venv/lib/python3.9/site-packages/flask_restful/__init__.py", line 582, in dispatch_request
2023-03-15 15:06:48.352 40 ERROR keystone.server.flask.application     resp = meth(*args, **kwargs)
2023-03-15 15:06:48.352 40 ERROR keystone.server.flask.application   File "/var/lib/kolla/venv/lib/python3.9/site-packages/keystone/api/users.py", line 182, in get
2023-03-15 15:06:48.352 40 ERROR keystone.server.flask.application     return self._get_user(user_id)
2023-03-15 15:06:48.352 40 ERROR keystone.server.flask.application   File "/var/lib/kolla/venv/lib/python3.9/site-packages/keystone/api/users.py", line 194, in _get_user
2023-03-15 15:06:48.352 40 ERROR keystone.server.flask.application     ref = PROVIDERS.identity_api.get_user(user_id)
2023-03-15 15:06:48.352 40 ERROR keystone.server.flask.application   File "/var/lib/kolla/venv/lib/python3.9/site-packages/keystone/common/manager.py", line 115, in wrapped
2023-03-15 15:06:48.352 40 ERROR keystone.server.flask.application     __ret_val = __f(*args, **kwargs)
2023-03-15 15:06:48.352 40 ERROR keystone.server.flask.application   File "/var/lib/kolla/venv/lib/python3.9/site-packages/keystone/identity/core.py", line 414, in wrapper
2023-03-15 15:06:48.352 40 ERROR keystone.server.flask.application     return f(self, *args, **kwargs)
2023-03-15 15:06:48.352 40 ERROR keystone.server.flask.application   File "/var/lib/kolla/venv/lib/python3.9/site-packages/keystone/identity/core.py", line 424, in wrapper
2023-03-15 15:06:48.352 40 ERROR keystone.server.flask.application     return f(self, *args, **kwargs)
2023-03-15 15:06:48.352 40 ERROR keystone.server.flask.application   File "/var/lib/kolla/venv/lib/python3.9/site-packages/decorator.py", line 232, in fun
2023-03-15 15:06:48.352 40 ERROR keystone.server.flask.application     return caller(func, *(extras + args), **kw)
2023-03-15 15:06:48.352 40 ERROR keystone.server.flask.application   File "/var/lib/kolla/venv/lib/python3.9/site-packages/dogpile/cache/region.py", line 1577, in get_or_create_for_user_func
2023-03-15 15:06:48.352 40 ERROR keystone.server.flask.application     return self.get_or_create(
2023-03-15 15:06:48.352 40 ERROR keystone.server.flask.application   File "/var/lib/kolla/venv/lib/python3.9/site-packages/dogpile/cache/region.py", line 1042, in get_or_create
2023-03-15 15:06:48.352 40 ERROR keystone.server.flask.application     with Lock(
2023-03-15 15:06:48.352 40 ERROR keystone.server.flask.application   File "/var/lib/kolla/venv/lib/python3.9/site-packages/dogpile/lock.py", line 185, in __enter__
2023-03-15 15:06:48.352 40 ERROR keystone.server.flask.application     return self._enter()
2023-03-15 15:06:48.352 40 ERROR keystone.server.flask.application   File "/var/lib/kolla/venv/lib/python3.9/site-packages/dogpile/lock.py", line 94, in _enter
2023-03-15 15:06:48.352 40 ERROR keystone.server.flask.application     generated = self._enter_create(value, createdtime)
2023-03-15 15:06:48.352 40 ERROR keystone.server.flask.application   File "/var/lib/kolla/venv/lib/python3.9/site-packages/dogpile/lock.py", line 178, in _enter_create
2023-03-15 15:06:48.352 40 ERROR keystone.server.flask.application     return self.creator()
2023-03-15 15:06:48.352 40 ERROR keystone.server.flask.application   File "/var/lib/kolla/venv/lib/python3.9/site-packages/dogpile/cache/region.py", line 995, in gen_value
2023-03-15 15:06:48.352 40 ERROR keystone.server.flask.application     created_value = creator(
2023-03-15 15:06:48.352 40 ERROR keystone.server.flask.application   File "/var/lib/kolla/venv/lib/python3.9/site-packages/keystone/identity/core.py", line 1011, in get_user
2023-03-15 15:06:48.352 40 ERROR keystone.server.flask.application     ref = driver.get_user(entity_id)
2023-03-15 15:06:48.352 40 ERROR keystone.server.flask.application   File "/var/lib/kolla/venv/lib/python3.9/site-packages/keystone/identity/backends/sql.py", line 200, in get_user
2023-03-15 15:06:48.352 40 ERROR keystone.server.flask.application     self._get_user(session, user_id).to_dict())
2023-03-15 15:06:48.352 40 ERROR keystone.server.flask.application   File "/var/lib/kolla/venv/lib/python3.9/site-packages/keystone/identity/backends/sql.py", line 194, in _get_user
2023-03-15 15:06:48.352 40 ERROR keystone.server.flask.application     raise exception.UserNotFound(user_id=user_id)
2023-03-15 15:06:48.352 40 ERROR keystone.server.flask.application keystone.exception.UserNotFound: Could not find user: ironic.
2023-03-15 15:06:48.352 40 ERROR keystone.server.flask.application 
2023-03-15 15:06:49.213 38 ERROR keystone.server.flask.application [None req-b4b9d342-9b31-475c-88eb-3ccdcdec9c04 c05eac42db3b4672a5b2dcff754581a1 - - all default -] Could not find project: service.: keystone.exception.ProjectNotFound: Could not find project: service.
2023-03-15 15:06:49.213 38 ERROR keystone.server.flask.application Traceback (most recent call last):
2023-03-15 15:06:49.213 38 ERROR keystone.server.flask.application   File "/var/lib/kolla/venv/lib/python3.9/site-packages/flask/app.py", line 1820, in full_dispatch_request
2023-03-15 15:06:49.213 38 ERROR keystone.server.flask.application     rv = self.dispatch_request()
2023-03-15 15:06:49.213 38 ERROR keystone.server.flask.application   File "/var/lib/kolla/venv/lib/python3.9/site-packages/flask/app.py", line 1796, in dispatch_request
2023-03-15 15:06:49.213 38 ERROR keystone.server.flask.application     return self.ensure_sync(self.view_functions[rule.endpoint])(**view_args)
2023-03-15 15:06:49.213 38 ERROR keystone.server.flask.application   File "/var/lib/kolla/venv/lib/python3.9/site-packages/flask_restful/__init__.py", line 467, in wrapper
2023-03-15 15:06:49.213 38 ERROR keystone.server.flask.application     resp = resource(*args, **kwargs)
2023-03-15 15:06:49.213 38 ERROR keystone.server.flask.application   File "/var/lib/kolla/venv/lib/python3.9/site-packages/flask/views.py", line 107, in view
2023-03-15 15:06:49.213 38 ERROR keystone.server.flask.application     return current_app.ensure_sync(self.dispatch_request)(**kwargs)
2023-03-15 15:06:49.213 38 ERROR keystone.server.flask.application   File "/var/lib/kolla/venv/lib/python3.9/site-packages/flask_restful/__init__.py", line 582, in dispatch_request
2023-03-15 15:06:49.213 38 ERROR keystone.server.flask.application     resp = meth(*args, **kwargs)
2023-03-15 15:06:49.213 38 ERROR keystone.server.flask.application   File "/var/lib/kolla/venv/lib/python3.9/site-packages/keystone/api/projects.py", line 151, in get
2023-03-15 15:06:49.213 38 ERROR keystone.server.flask.application     return self._get_project(project_id)
2023-03-15 15:06:49.213 38 ERROR keystone.server.flask.application   File "/var/lib/kolla/venv/lib/python3.9/site-packages/keystone/api/projects.py", line 107, in _get_project
2023-03-15 15:06:49.213 38 ERROR keystone.server.flask.application     project = PROVIDERS.resource_api.get_project(project_id)
2023-03-15 15:06:49.213 38 ERROR keystone.server.flask.application   File "/var/lib/kolla/venv/lib/python3.9/site-packages/keystone/common/manager.py", line 115, in wrapped
2023-03-15 15:06:49.213 38 ERROR keystone.server.flask.application     __ret_val = __f(*args, **kwargs)
2023-03-15 15:06:49.213 38 ERROR keystone.server.flask.application   File "/var/lib/kolla/venv/lib/python3.9/site-packages/decorator.py", line 232, in fun
2023-03-15 15:06:49.213 38 ERROR keystone.server.flask.application     return caller(func, *(extras + args), **kw)
2023-03-15 15:06:49.213 38 ERROR keystone.server.flask.application   File "/var/lib/kolla/venv/lib/python3.9/site-packages/dogpile/cache/region.py", line 1577, in get_or_create_for_user_func
2023-03-15 15:06:49.213 38 ERROR keystone.server.flask.application     return self.get_or_create(
2023-03-15 15:06:49.213 38 ERROR keystone.server.flask.application   File "/var/lib/kolla/venv/lib/python3.9/site-packages/dogpile/cache/region.py", line 1042, in get_or_create
2023-03-15 15:06:49.213 38 ERROR keystone.server.flask.application     with Lock(
2023-03-15 15:06:49.213 38 ERROR keystone.server.flask.application   File "/var/lib/kolla/venv/lib/python3.9/site-packages/dogpile/lock.py", line 185, in __enter__
2023-03-15 15:06:49.213 38 ERROR keystone.server.flask.application     return self._enter()
2023-03-15 15:06:49.213 38 ERROR keystone.server.flask.application   File "/var/lib/kolla/venv/lib/python3.9/site-packages/dogpile/lock.py", line 94, in _enter
2023-03-15 15:06:49.213 38 ERROR keystone.server.flask.application     generated = self._enter_create(value, createdtime)
2023-03-15 15:06:49.213 38 ERROR keystone.server.flask.application   File "/var/lib/kolla/venv/lib/python3.9/site-packages/dogpile/lock.py", line 178, in _enter_create
2023-03-15 15:06:49.213 38 ERROR keystone.server.flask.application     return self.creator()
2023-03-15 15:06:49.213 38 ERROR keystone.server.flask.application   File "/var/lib/kolla/venv/lib/python3.9/site-packages/dogpile/cache/region.py", line 995, in gen_value
2023-03-15 15:06:49.213 38 ERROR keystone.server.flask.application     created_value = creator(
2023-03-15 15:06:49.213 38 ERROR keystone.server.flask.application   File "/var/lib/kolla/venv/lib/python3.9/site-packages/keystone/resource/core.py", line 903, in get_project
2023-03-15 15:06:49.213 38 ERROR keystone.server.flask.application     return self.driver.get_project(project_id)
2023-03-15 15:06:49.213 38 ERROR keystone.server.flask.application   File "/var/lib/kolla/venv/lib/python3.9/site-packages/keystone/resource/backends/sql.py", line 49, in get_project
2023-03-15 15:06:49.213 38 ERROR keystone.server.flask.application     return self._get_project(session, project_id).to_dict()
2023-03-15 15:06:49.213 38 ERROR keystone.server.flask.application   File "/var/lib/kolla/venv/lib/python3.9/site-packages/keystone/resource/backends/sql.py", line 44, in _get_project
2023-03-15 15:06:49.213 38 ERROR keystone.server.flask.application     raise exception.ProjectNotFound(project_id=project_id)
2023-03-15 15:06:49.213 38 ERROR keystone.server.flask.application keystone.exception.ProjectNotFound: Could not find project: service.
2023-03-15 15:06:49.213 38 ERROR keystone.server.flask.application 
2023-03-15 15:06:58.494 39 ERROR keystone.server.flask.application [None req-e66fc172-0896-494c-91f1-1817c46522d3 c05eac42db3b4672a5b2dcff754581a1 - - all default -] Could not find role: admin.: keystone.exception.RoleNotFound: Could not find role: admin.
2023-03-15 15:06:58.494 39 ERROR keystone.server.flask.application Traceback (most recent call last):
2023-03-15 15:06:58.494 39 ERROR keystone.server.flask.application   File "/var/lib/kolla/venv/lib/python3.9/site-packages/flask/app.py", line 1820, in full_dispatch_request
2023-03-15 15:06:58.494 39 ERROR keystone.server.flask.application     rv = self.dispatch_request()
2023-03-15 15:06:58.494 39 ERROR keystone.server.flask.application   File "/var/lib/kolla/venv/lib/python3.9/site-packages/flask/app.py", line 1796, in dispatch_request
2023-03-15 15:06:58.494 39 ERROR keystone.server.flask.application     return self.ensure_sync(self.view_functions[rule.endpoint])(**view_args)
2023-03-15 15:06:58.494 39 ERROR keystone.server.flask.application   File "/var/lib/kolla/venv/lib/python3.9/site-packages/flask_restful/__init__.py", line 467, in wrapper
2023-03-15 15:06:58.494 39 ERROR keystone.server.flask.application     resp = resource(*args, **kwargs)
2023-03-15 15:06:58.494 39 ERROR keystone.server.flask.application   File "/var/lib/kolla/venv/lib/python3.9/site-packages/flask/views.py", line 107, in view
2023-03-15 15:06:58.494 39 ERROR keystone.server.flask.application     return current_app.ensure_sync(self.dispatch_request)(**kwargs)
2023-03-15 15:06:58.494 39 ERROR keystone.server.flask.application   File "/var/lib/kolla/venv/lib/python3.9/site-packages/flask_restful/__init__.py", line 582, in dispatch_request
2023-03-15 15:06:58.494 39 ERROR keystone.server.flask.application     resp = meth(*args, **kwargs)
2023-03-15 15:06:58.494 39 ERROR keystone.server.flask.application   File "/var/lib/kolla/venv/lib/python3.9/site-packages/keystone/api/roles.py", line 50, in get
2023-03-15 15:06:58.494 39 ERROR keystone.server.flask.application     return self._get_role(role_id)
2023-03-15 15:06:58.494 39 ERROR keystone.server.flask.application   File "/var/lib/kolla/venv/lib/python3.9/site-packages/keystone/api/roles.py", line 70, in _get_role
2023-03-15 15:06:58.494 39 ERROR keystone.server.flask.application     ENFORCER.enforce_call(action='identity:get_role')
2023-03-15 15:06:58.494 39 ERROR keystone.server.flask.application   File "/var/lib/kolla/venv/lib/python3.9/site-packages/keystone/common/rbac_enforcer/enforcer.py", line 402, in enforce_call
2023-03-15 15:06:58.494 39 ERROR keystone.server.flask.application     policy_dict.update(cls._extract_member_target_data(
2023-03-15 15:06:58.494 39 ERROR keystone.server.flask.application   File "/var/lib/kolla/venv/lib/python3.9/site-packages/keystone/common/rbac_enforcer/enforcer.py", line 234, in _extract_member_target_data
2023-03-15 15:06:58.494 39 ERROR keystone.server.flask.application     member_name: func(flask.request.view_args[key])
2023-03-15 15:06:58.494 39 ERROR keystone.server.flask.application   File "/var/lib/kolla/venv/lib/python3.9/site-packages/keystone/common/manager.py", line 115, in wrapped
2023-03-15 15:06:58.494 39 ERROR keystone.server.flask.application     __ret_val = __f(*args, **kwargs)
2023-03-15 15:06:58.494 39 ERROR keystone.server.flask.application   File "/var/lib/kolla/venv/lib/python3.9/site-packages/decorator.py", line 232, in fun
2023-03-15 15:06:58.494 39 ERROR keystone.server.flask.application     return caller(func, *(extras + args), **kw)
2023-03-15 15:06:58.494 39 ERROR keystone.server.flask.application   File "/var/lib/kolla/venv/lib/python3.9/site-packages/dogpile/cache/region.py", line 1577, in get_or_create_for_user_func
2023-03-15 15:06:58.494 39 ERROR keystone.server.flask.application     return self.get_or_create(
2023-03-15 15:06:58.494 39 ERROR keystone.server.flask.application   File "/var/lib/kolla/venv/lib/python3.9/site-packages/dogpile/cache/region.py", line 1042, in get_or_create
2023-03-15 15:06:58.494 39 ERROR keystone.server.flask.application     with Lock(
2023-03-15 15:06:58.494 39 ERROR keystone.server.flask.application   File "/var/lib/kolla/venv/lib/python3.9/site-packages/dogpile/lock.py", line 185, in __enter__
2023-03-15 15:06:58.494 39 ERROR keystone.server.flask.application     return self._enter()
2023-03-15 15:06:58.494 39 ERROR keystone.server.flask.application   File "/var/lib/kolla/venv/lib/python3.9/site-packages/dogpile/lock.py", line 94, in _enter
2023-03-15 15:06:58.494 39 ERROR keystone.server.flask.application     generated = self._enter_create(value, createdtime)
2023-03-15 15:06:58.494 39 ERROR keystone.server.flask.application   File "/var/lib/kolla/venv/lib/python3.9/site-packages/dogpile/lock.py", line 178, in _enter_create
2023-03-15 15:06:58.494 39 ERROR keystone.server.flask.application     return self.creator()
2023-03-15 15:06:58.494 39 ERROR keystone.server.flask.application   File "/var/lib/kolla/venv/lib/python3.9/site-packages/dogpile/cache/region.py", line 995, in gen_value
2023-03-15 15:06:58.494 39 ERROR keystone.server.flask.application     created_value = creator(
2023-03-15 15:06:58.494 39 ERROR keystone.server.flask.application   File "/var/lib/kolla/venv/lib/python3.9/site-packages/keystone/assignment/core.py", line 1276, in get_role
2023-03-15 15:06:58.494 39 ERROR keystone.server.flask.application     return self.driver.get_role(role_id)
2023-03-15 15:06:58.494 39 ERROR keystone.server.flask.application   File "/var/lib/kolla/venv/lib/python3.9/site-packages/keystone/assignment/role_backends/sql.py", line 70, in get_role
2023-03-15 15:06:58.494 39 ERROR keystone.server.flask.application     return self._get_role(session, role_id).to_dict()
2023-03-15 15:06:58.494 39 ERROR keystone.server.flask.application   File "/var/lib/kolla/venv/lib/python3.9/site-packages/keystone/assignment/role_backends/sql.py", line 65, in _get_role
2023-03-15 15:06:58.494 39 ERROR keystone.server.flask.application     raise exception.RoleNotFound(role_id=role_id)
2023-03-15 15:06:58.494 39 ERROR keystone.server.flask.application keystone.exception.RoleNotFound: Could not find role: admin.
2023-03-15 15:06:58.494 39 ERROR keystone.server.flask.application 
2023-03-15 15:06:59.757 39 ERROR keystone.server.flask.application [None req-ecda3dfa-68ef-4abf-86df-0fc3953901c5 c05eac42db3b4672a5b2dcff754581a1 - - all default -] Could not find user: ironic-inspector.: keystone.exception.UserNotFound: Could not find user: ironic-inspector.
2023-03-15 15:06:59.757 39 ERROR keystone.server.flask.application Traceback (most recent call last):
2023-03-15 15:06:59.757 39 ERROR keystone.server.flask.application   File "/var/lib/kolla/venv/lib/python3.9/site-packages/flask/app.py", line 1820, in full_dispatch_request
2023-03-15 15:06:59.757 39 ERROR keystone.server.flask.application     rv = self.dispatch_request()
2023-03-15 15:06:59.757 39 ERROR keystone.server.flask.application   File "/var/lib/kolla/venv/lib/python3.9/site-packages/flask/app.py", line 1796, in dispatch_request
2023-03-15 15:06:59.757 39 ERROR keystone.server.flask.application     return self.ensure_sync(self.view_functions[rule.endpoint])(**view_args)
2023-03-15 15:06:59.757 39 ERROR keystone.server.flask.application   File "/var/lib/kolla/venv/lib/python3.9/site-packages/flask_restful/__init__.py", line 467, in wrapper
2023-03-15 15:06:59.757 39 ERROR keystone.server.flask.application     resp = resource(*args, **kwargs)
2023-03-15 15:06:59.757 39 ERROR keystone.server.flask.application   File "/var/lib/kolla/venv/lib/python3.9/site-packages/flask/views.py", line 107, in view
2023-03-15 15:06:59.757 39 ERROR keystone.server.flask.application     return current_app.ensure_sync(self.dispatch_request)(**kwargs)
2023-03-15 15:06:59.757 39 ERROR keystone.server.flask.application   File "/var/lib/kolla/venv/lib/python3.9/site-packages/flask_restful/__init__.py", line 582, in dispatch_request
2023-03-15 15:06:59.757 39 ERROR keystone.server.flask.application     resp = meth(*args, **kwargs)
2023-03-15 15:06:59.757 39 ERROR keystone.server.flask.application   File "/var/lib/kolla/venv/lib/python3.9/site-packages/keystone/api/users.py", line 182, in get
2023-03-15 15:06:59.757 39 ERROR keystone.server.flask.application     return self._get_user(user_id)
2023-03-15 15:06:59.757 39 ERROR keystone.server.flask.application   File "/var/lib/kolla/venv/lib/python3.9/site-packages/keystone/api/users.py", line 194, in _get_user
2023-03-15 15:06:59.757 39 ERROR keystone.server.flask.application     ref = PROVIDERS.identity_api.get_user(user_id)
2023-03-15 15:06:59.757 39 ERROR keystone.server.flask.application   File "/var/lib/kolla/venv/lib/python3.9/site-packages/keystone/common/manager.py", line 115, in wrapped
2023-03-15 15:06:59.757 39 ERROR keystone.server.flask.application     __ret_val = __f(*args, **kwargs)
2023-03-15 15:06:59.757 39 ERROR keystone.server.flask.application   File "/var/lib/kolla/venv/lib/python3.9/site-packages/keystone/identity/core.py", line 414, in wrapper
2023-03-15 15:06:59.757 39 ERROR keystone.server.flask.application     return f(self, *args, **kwargs)
2023-03-15 15:06:59.757 39 ERROR keystone.server.flask.application   File "/var/lib/kolla/venv/lib/python3.9/site-packages/keystone/identity/core.py", line 424, in wrapper
2023-03-15 15:06:59.757 39 ERROR keystone.server.flask.application     return f(self, *args, **kwargs)
2023-03-15 15:06:59.757 39 ERROR keystone.server.flask.application   File "/var/lib/kolla/venv/lib/python3.9/site-packages/decorator.py", line 232, in fun
2023-03-15 15:06:59.757 39 ERROR keystone.server.flask.application     return caller(func, *(extras + args), **kw)
2023-03-15 15:06:59.757 39 ERROR keystone.server.flask.application   File "/var/lib/kolla/venv/lib/python3.9/site-packages/dogpile/cache/region.py", line 1577, in get_or_create_for_user_func
2023-03-15 15:06:59.757 39 ERROR keystone.server.flask.application     return self.get_or_create(
2023-03-15 15:06:59.757 39 ERROR keystone.server.flask.application   File "/var/lib/kolla/venv/lib/python3.9/site-packages/dogpile/cache/region.py", line 1042, in get_or_create
2023-03-15 15:06:59.757 39 ERROR keystone.server.flask.application     with Lock(
2023-03-15 15:06:59.757 39 ERROR keystone.server.flask.application   File "/var/lib/kolla/venv/lib/python3.9/site-packages/dogpile/lock.py", line 185, in __enter__
2023-03-15 15:06:59.757 39 ERROR keystone.server.flask.application     return self._enter()
2023-03-15 15:06:59.757 39 ERROR keystone.server.flask.application   File "/var/lib/kolla/venv/lib/python3.9/site-packages/dogpile/lock.py", line 94, in _enter
2023-03-15 15:06:59.757 39 ERROR keystone.server.flask.application     generated = self._enter_create(value, createdtime)
2023-03-15 15:06:59.757 39 ERROR keystone.server.flask.application   File "/var/lib/kolla/venv/lib/python3.9/site-packages/dogpile/lock.py", line 178, in _enter_create
2023-03-15 15:06:59.757 39 ERROR keystone.server.flask.application     return self.creator()
2023-03-15 15:06:59.757 39 ERROR keystone.server.flask.application   File "/var/lib/kolla/venv/lib/python3.9/site-packages/dogpile/cache/region.py", line 995, in gen_value
2023-03-15 15:06:59.757 39 ERROR keystone.server.flask.application     created_value = creator(
2023-03-15 15:06:59.757 39 ERROR keystone.server.flask.application   File "/var/lib/kolla/venv/lib/python3.9/site-packages/keystone/identity/core.py", line 1011, in get_user
2023-03-15 15:06:59.757 39 ERROR keystone.server.flask.application     ref = driver.get_user(entity_id)
2023-03-15 15:06:59.757 39 ERROR keystone.server.flask.application   File "/var/lib/kolla/venv/lib/python3.9/site-packages/keystone/identity/backends/sql.py", line 200, in get_user
2023-03-15 15:06:59.757 39 ERROR keystone.server.flask.application     self._get_user(session, user_id).to_dict())
2023-03-15 15:06:59.757 39 ERROR keystone.server.flask.application   File "/var/lib/kolla/venv/lib/python3.9/site-packages/keystone/identity/backends/sql.py", line 194, in _get_user
2023-03-15 15:06:59.757 39 ERROR keystone.server.flask.application     raise exception.UserNotFound(user_id=user_id)
2023-03-15 15:06:59.757 39 ERROR keystone.server.flask.application keystone.exception.UserNotFound: Could not find user: ironic-inspector.
2023-03-15 15:06:59.757 39 ERROR keystone.server.flask.application 
2023-03-15 15:07:00.592 40 ERROR keystone.server.flask.application [None req-d7ba57e4-85d6-463a-be88-984146553dff c05eac42db3b4672a5b2dcff754581a1 - - all default -] Could not find project: service.: keystone.exception.ProjectNotFound: Could not find project: service.
2023-03-15 15:07:00.592 40 ERROR keystone.server.flask.application Traceback (most recent call last):
2023-03-15 15:07:00.592 40 ERROR keystone.server.flask.application   File "/var/lib/kolla/venv/lib/python3.9/site-packages/flask/app.py", line 1820, in full_dispatch_request
2023-03-15 15:07:00.592 40 ERROR keystone.server.flask.application     rv = self.dispatch_request()
2023-03-15 15:07:00.592 40 ERROR keystone.server.flask.application   File "/var/lib/kolla/venv/lib/python3.9/site-packages/flask/app.py", line 1796, in dispatch_request
2023-03-15 15:07:00.592 40 ERROR keystone.server.flask.application     return self.ensure_sync(self.view_functions[rule.endpoint])(**view_args)
2023-03-15 15:07:00.592 40 ERROR keystone.server.flask.application   File "/var/lib/kolla/venv/lib/python3.9/site-packages/flask_restful/__init__.py", line 467, in wrapper
2023-03-15 15:07:00.592 40 ERROR keystone.server.flask.application     resp = resource(*args, **kwargs)
2023-03-15 15:07:00.592 40 ERROR keystone.server.flask.application   File "/var/lib/kolla/venv/lib/python3.9/site-packages/flask/views.py", line 107, in view
2023-03-15 15:07:00.592 40 ERROR keystone.server.flask.application     return current_app.ensure_sync(self.dispatch_request)(**kwargs)
2023-03-15 15:07:00.592 40 ERROR keystone.server.flask.application   File "/var/lib/kolla/venv/lib/python3.9/site-packages/flask_restful/__init__.py", line 582, in dispatch_request
2023-03-15 15:07:00.592 40 ERROR keystone.server.flask.application     resp = meth(*args, **kwargs)
2023-03-15 15:07:00.592 40 ERROR keystone.server.flask.application   File "/var/lib/kolla/venv/lib/python3.9/site-packages/keystone/api/projects.py", line 151, in get
2023-03-15 15:07:00.592 40 ERROR keystone.server.flask.application     return self._get_project(project_id)
2023-03-15 15:07:00.592 40 ERROR keystone.server.flask.application   File "/var/lib/kolla/venv/lib/python3.9/site-packages/keystone/api/projects.py", line 107, in _get_project
2023-03-15 15:07:00.592 40 ERROR keystone.server.flask.application     project = PROVIDERS.resource_api.get_project(project_id)
2023-03-15 15:07:00.592 40 ERROR keystone.server.flask.application   File "/var/lib/kolla/venv/lib/python3.9/site-packages/keystone/common/manager.py", line 115, in wrapped
2023-03-15 15:07:00.592 40 ERROR keystone.server.flask.application     __ret_val = __f(*args, **kwargs)
2023-03-15 15:07:00.592 40 ERROR keystone.server.flask.application   File "/var/lib/kolla/venv/lib/python3.9/site-packages/decorator.py", line 232, in fun
2023-03-15 15:07:00.592 40 ERROR keystone.server.flask.application     return caller(func, *(extras + args), **kw)
2023-03-15 15:07:00.592 40 ERROR keystone.server.flask.application   File "/var/lib/kolla/venv/lib/python3.9/site-packages/dogpile/cache/region.py", line 1577, in get_or_create_for_user_func
2023-03-15 15:07:00.592 40 ERROR keystone.server.flask.application     return self.get_or_create(
2023-03-15 15:07:00.592 40 ERROR keystone.server.flask.application   File "/var/lib/kolla/venv/lib/python3.9/site-packages/dogpile/cache/region.py", line 1042, in get_or_create
2023-03-15 15:07:00.592 40 ERROR keystone.server.flask.application     with Lock(
2023-03-15 15:07:00.592 40 ERROR keystone.server.flask.application   File "/var/lib/kolla/venv/lib/python3.9/site-packages/dogpile/lock.py", line 185, in __enter__
2023-03-15 15:07:00.592 40 ERROR keystone.server.flask.application     return self._enter()
2023-03-15 15:07:00.592 40 ERROR keystone.server.flask.application   File "/var/lib/kolla/venv/lib/python3.9/site-packages/dogpile/lock.py", line 94, in _enter
2023-03-15 15:07:00.592 40 ERROR keystone.server.flask.application     generated = self._enter_create(value, createdtime)
2023-03-15 15:07:00.592 40 ERROR keystone.server.flask.application   File "/var/lib/kolla/venv/lib/python3.9/site-packages/dogpile/lock.py", line 178, in _enter_create
2023-03-15 15:07:00.592 40 ERROR keystone.server.flask.application     return self.creator()
2023-03-15 15:07:00.592 40 ERROR keystone.server.flask.application   File "/var/lib/kolla/venv/lib/python3.9/site-packages/dogpile/cache/region.py", line 995, in gen_value
2023-03-15 15:07:00.592 40 ERROR keystone.server.flask.application     created_value = creator(
2023-03-15 15:07:00.592 40 ERROR keystone.server.flask.application   File "/var/lib/kolla/venv/lib/python3.9/site-packages/keystone/resource/core.py", line 903, in get_project
2023-03-15 15:07:00.592 40 ERROR keystone.server.flask.application     return self.driver.get_project(project_id)
2023-03-15 15:07:00.592 40 ERROR keystone.server.flask.application   File "/var/lib/kolla/venv/lib/python3.9/site-packages/keystone/resource/backends/sql.py", line 49, in get_project
2023-03-15 15:07:00.592 40 ERROR keystone.server.flask.application     return self._get_project(session, project_id).to_dict()
2023-03-15 15:07:00.592 40 ERROR keystone.server.flask.application   File "/var/lib/kolla/venv/lib/python3.9/site-packages/keystone/resource/backends/sql.py", line 44, in _get_project
2023-03-15 15:07:00.592 40 ERROR keystone.server.flask.application     raise exception.ProjectNotFound(project_id=project_id)
2023-03-15 15:07:00.592 40 ERROR keystone.server.flask.application keystone.exception.ProjectNotFound: Could not find project: service.
2023-03-15 15:07:00.592 40 ERROR keystone.server.flask.application 
2023-03-15 15:09:42.477 40 ERROR keystone.server.flask.application [None req-3b9ce566-d927-4c6d-be15-1ec245b6fa81 c05eac42db3b4672a5b2dcff754581a1 - - all default -] Could not find project: service.: keystone.exception.ProjectNotFound: Could not find project: service.
2023-03-15 15:09:42.477 40 ERROR keystone.server.flask.application Traceback (most recent call last):
2023-03-15 15:09:42.477 40 ERROR keystone.server.flask.application   File "/var/lib/kolla/venv/lib/python3.9/site-packages/flask/app.py", line 1820, in full_dispatch_request
2023-03-15 15:09:42.477 40 ERROR keystone.server.flask.application     rv = self.dispatch_request()
2023-03-15 15:09:42.477 40 ERROR keystone.server.flask.application   File "/var/lib/kolla/venv/lib/python3.9/site-packages/flask/app.py", line 1796, in dispatch_request
2023-03-15 15:09:42.477 40 ERROR keystone.server.flask.application     return self.ensure_sync(self.view_functions[rule.endpoint])(**view_args)
2023-03-15 15:09:42.477 40 ERROR keystone.server.flask.application   File "/var/lib/kolla/venv/lib/python3.9/site-packages/flask_restful/__init__.py", line 467, in wrapper
2023-03-15 15:09:42.477 40 ERROR keystone.server.flask.application     resp = resource(*args, **kwargs)
2023-03-15 15:09:42.477 40 ERROR keystone.server.flask.application   File "/var/lib/kolla/venv/lib/python3.9/site-packages/flask/views.py", line 107, in view
2023-03-15 15:09:42.477 40 ERROR keystone.server.flask.application     return current_app.ensure_sync(self.dispatch_request)(**kwargs)
2023-03-15 15:09:42.477 40 ERROR keystone.server.flask.application   File "/var/lib/kolla/venv/lib/python3.9/site-packages/flask_restful/__init__.py", line 582, in dispatch_request
2023-03-15 15:09:42.477 40 ERROR keystone.server.flask.application     resp = meth(*args, **kwargs)
2023-03-15 15:09:42.477 40 ERROR keystone.server.flask.application   File "/var/lib/kolla/venv/lib/python3.9/site-packages/keystone/api/projects.py", line 151, in get
2023-03-15 15:09:42.477 40 ERROR keystone.server.flask.application     return self._get_project(project_id)
2023-03-15 15:09:42.477 40 ERROR keystone.server.flask.application   File "/var/lib/kolla/venv/lib/python3.9/site-packages/keystone/api/projects.py", line 107, in _get_project
2023-03-15 15:09:42.477 40 ERROR keystone.server.flask.application     project = PROVIDERS.resource_api.get_project(project_id)
2023-03-15 15:09:42.477 40 ERROR keystone.server.flask.application   File "/var/lib/kolla/venv/lib/python3.9/site-packages/keystone/common/manager.py", line 115, in wrapped
2023-03-15 15:09:42.477 40 ERROR keystone.server.flask.application     __ret_val = __f(*args, **kwargs)
2023-03-15 15:09:42.477 40 ERROR keystone.server.flask.application   File "/var/lib/kolla/venv/lib/python3.9/site-packages/decorator.py", line 232, in fun
2023-03-15 15:09:42.477 40 ERROR keystone.server.flask.application     return caller(func, *(extras + args), **kw)
2023-03-15 15:09:42.477 40 ERROR keystone.server.flask.application   File "/var/lib/kolla/venv/lib/python3.9/site-packages/dogpile/cache/region.py", line 1577, in get_or_create_for_user_func
2023-03-15 15:09:42.477 40 ERROR keystone.server.flask.application     return self.get_or_create(
2023-03-15 15:09:42.477 40 ERROR keystone.server.flask.application   File "/var/lib/kolla/venv/lib/python3.9/site-packages/dogpile/cache/region.py", line 1042, in get_or_create
2023-03-15 15:09:42.477 40 ERROR keystone.server.flask.application     with Lock(
2023-03-15 15:09:42.477 40 ERROR keystone.server.flask.application   File "/var/lib/kolla/venv/lib/python3.9/site-packages/dogpile/lock.py", line 185, in __enter__
2023-03-15 15:09:42.477 40 ERROR keystone.server.flask.application     return self._enter()
2023-03-15 15:09:42.477 40 ERROR keystone.server.flask.application   File "/var/lib/kolla/venv/lib/python3.9/site-packages/dogpile/lock.py", line 94, in _enter
2023-03-15 15:09:42.477 40 ERROR keystone.server.flask.application     generated = self._enter_create(value, createdtime)
2023-03-15 15:09:42.477 40 ERROR keystone.server.flask.application   File "/var/lib/kolla/venv/lib/python3.9/site-packages/dogpile/lock.py", line 178, in _enter_create
2023-03-15 15:09:42.477 40 ERROR keystone.server.flask.application     return self.creator()
2023-03-15 15:09:42.477 40 ERROR keystone.server.flask.application   File "/var/lib/kolla/venv/lib/python3.9/site-packages/dogpile/cache/region.py", line 995, in gen_value
2023-03-15 15:09:42.477 40 ERROR keystone.server.flask.application     created_value = creator(
2023-03-15 15:09:42.477 40 ERROR keystone.server.flask.application   File "/var/lib/kolla/venv/lib/python3.9/site-packages/keystone/resource/core.py", line 903, in get_project
2023-03-15 15:09:42.477 40 ERROR keystone.server.flask.application     return self.driver.get_project(project_id)
2023-03-15 15:09:42.477 40 ERROR keystone.server.flask.application   File "/var/lib/kolla/venv/lib/python3.9/site-packages/keystone/resource/backends/sql.py", line 49, in get_project
2023-03-15 15:09:42.477 40 ERROR keystone.server.flask.application     return self._get_project(session, project_id).to_dict()
2023-03-15 15:09:42.477 40 ERROR keystone.server.flask.application   File "/var/lib/kolla/venv/lib/python3.9/site-packages/keystone/resource/backends/sql.py", line 44, in _get_project
2023-03-15 15:09:42.477 40 ERROR keystone.server.flask.application     raise exception.ProjectNotFound(project_id=project_id)
2023-03-15 15:09:42.477 40 ERROR keystone.server.flask.application keystone.exception.ProjectNotFound: Could not find project: service.
2023-03-15 15:09:42.477 40 ERROR keystone.server.flask.application 
2023-03-15 15:09:56.515 39 ERROR keystone.server.flask.application [None req-f36bc967-0af1-43c1-a4f0-3d88e089e02c c05eac42db3b4672a5b2dcff754581a1 - - all default -] Could not find role: admin.: keystone.exception.RoleNotFound: Could not find role: admin.
2023-03-15 15:09:56.515 39 ERROR keystone.server.flask.application Traceback (most recent call last):
2023-03-15 15:09:56.515 39 ERROR keystone.server.flask.application   File "/var/lib/kolla/venv/lib/python3.9/site-packages/flask/app.py", line 1820, in full_dispatch_request
2023-03-15 15:09:56.515 39 ERROR keystone.server.flask.application     rv = self.dispatch_request()
2023-03-15 15:09:56.515 39 ERROR keystone.server.flask.application   File "/var/lib/kolla/venv/lib/python3.9/site-packages/flask/app.py", line 1796, in dispatch_request
2023-03-15 15:09:56.515 39 ERROR keystone.server.flask.application     return self.ensure_sync(self.view_functions[rule.endpoint])(**view_args)
2023-03-15 15:09:56.515 39 ERROR keystone.server.flask.application   File "/var/lib/kolla/venv/lib/python3.9/site-packages/flask_restful/__init__.py", line 467, in wrapper
2023-03-15 15:09:56.515 39 ERROR keystone.server.flask.application     resp = resource(*args, **kwargs)
2023-03-15 15:09:56.515 39 ERROR keystone.server.flask.application   File "/var/lib/kolla/venv/lib/python3.9/site-packages/flask/views.py", line 107, in view
2023-03-15 15:09:56.515 39 ERROR keystone.server.flask.application     return current_app.ensure_sync(self.dispatch_request)(**kwargs)
2023-03-15 15:09:56.515 39 ERROR keystone.server.flask.application   File "/var/lib/kolla/venv/lib/python3.9/site-packages/flask_restful/__init__.py", line 582, in dispatch_request
2023-03-15 15:09:56.515 39 ERROR keystone.server.flask.application     resp = meth(*args, **kwargs)
2023-03-15 15:09:56.515 39 ERROR keystone.server.flask.application   File "/var/lib/kolla/venv/lib/python3.9/site-packages/keystone/api/roles.py", line 50, in get
2023-03-15 15:09:56.515 39 ERROR keystone.server.flask.application     return self._get_role(role_id)
2023-03-15 15:09:56.515 39 ERROR keystone.server.flask.application   File "/var/lib/kolla/venv/lib/python3.9/site-packages/keystone/api/roles.py", line 70, in _get_role
2023-03-15 15:09:56.515 39 ERROR keystone.server.flask.application     ENFORCER.enforce_call(action='identity:get_role')
2023-03-15 15:09:56.515 39 ERROR keystone.server.flask.application   File "/var/lib/kolla/venv/lib/python3.9/site-packages/keystone/common/rbac_enforcer/enforcer.py", line 402, in enforce_call
2023-03-15 15:09:56.515 39 ERROR keystone.server.flask.application     policy_dict.update(cls._extract_member_target_data(
2023-03-15 15:09:56.515 39 ERROR keystone.server.flask.application   File "/var/lib/kolla/venv/lib/python3.9/site-packages/keystone/common/rbac_enforcer/enforcer.py", line 234, in _extract_member_target_data
2023-03-15 15:09:56.515 39 ERROR keystone.server.flask.application     member_name: func(flask.request.view_args[key])
2023-03-15 15:09:56.515 39 ERROR keystone.server.flask.application   File "/var/lib/kolla/venv/lib/python3.9/site-packages/keystone/common/manager.py", line 115, in wrapped
2023-03-15 15:09:56.515 39 ERROR keystone.server.flask.application     __ret_val = __f(*args, **kwargs)
2023-03-15 15:09:56.515 39 ERROR keystone.server.flask.application   File "/var/lib/kolla/venv/lib/python3.9/site-packages/decorator.py", line 232, in fun
2023-03-15 15:09:56.515 39 ERROR keystone.server.flask.application     return caller(func, *(extras + args), **kw)
2023-03-15 15:09:56.515 39 ERROR keystone.server.flask.application   File "/var/lib/kolla/venv/lib/python3.9/site-packages/dogpile/cache/region.py", line 1577, in get_or_create_for_user_func
2023-03-15 15:09:56.515 39 ERROR keystone.server.flask.application     return self.get_or_create(
2023-03-15 15:09:56.515 39 ERROR keystone.server.flask.application   File "/var/lib/kolla/venv/lib/python3.9/site-packages/dogpile/cache/region.py", line 1042, in get_or_create
2023-03-15 15:09:56.515 39 ERROR keystone.server.flask.application     with Lock(
2023-03-15 15:09:56.515 39 ERROR keystone.server.flask.application   File "/var/lib/kolla/venv/lib/python3.9/site-packages/dogpile/lock.py", line 185, in __enter__
2023-03-15 15:09:56.515 39 ERROR keystone.server.flask.application     return self._enter()
2023-03-15 15:09:56.515 39 ERROR keystone.server.flask.application   File "/var/lib/kolla/venv/lib/python3.9/site-packages/dogpile/lock.py", line 94, in _enter
2023-03-15 15:09:56.515 39 ERROR keystone.server.flask.application     generated = self._enter_create(value, createdtime)
2023-03-15 15:09:56.515 39 ERROR keystone.server.flask.application   File "/var/lib/kolla/venv/lib/python3.9/site-packages/dogpile/lock.py", line 178, in _enter_create
2023-03-15 15:09:56.515 39 ERROR keystone.server.flask.application     return self.creator()
2023-03-15 15:09:56.515 39 ERROR keystone.server.flask.application   File "/var/lib/kolla/venv/lib/python3.9/site-packages/dogpile/cache/region.py", line 995, in gen_value
2023-03-15 15:09:56.515 39 ERROR keystone.server.flask.application     created_value = creator(
2023-03-15 15:09:56.515 39 ERROR keystone.server.flask.application   File "/var/lib/kolla/venv/lib/python3.9/site-packages/keystone/assignment/core.py", line 1276, in get_role
2023-03-15 15:09:56.515 39 ERROR keystone.server.flask.application     return self.driver.get_role(role_id)
2023-03-15 15:09:56.515 39 ERROR keystone.server.flask.application   File "/var/lib/kolla/venv/lib/python3.9/site-packages/keystone/assignment/role_backends/sql.py", line 70, in get_role
2023-03-15 15:09:56.515 39 ERROR keystone.server.flask.application     return self._get_role(session, role_id).to_dict()
2023-03-15 15:09:56.515 39 ERROR keystone.server.flask.application   File "/var/lib/kolla/venv/lib/python3.9/site-packages/keystone/assignment/role_backends/sql.py", line 65, in _get_role
2023-03-15 15:09:56.515 39 ERROR keystone.server.flask.application     raise exception.RoleNotFound(role_id=role_id)
2023-03-15 15:09:56.515 39 ERROR keystone.server.flask.application keystone.exception.RoleNotFound: Could not find role: admin.
2023-03-15 15:09:56.515 39 ERROR keystone.server.flask.application 
2023-03-15 15:09:57.753 39 ERROR keystone.server.flask.application [None req-42e5edbe-af2b-48e0-a4d0-c632f58280e1 c05eac42db3b4672a5b2dcff754581a1 - - all default -] Could not find user: neutron.: keystone.exception.UserNotFound: Could not find user: neutron.
2023-03-15 15:09:57.753 39 ERROR keystone.server.flask.application Traceback (most recent call last):
2023-03-15 15:09:57.753 39 ERROR keystone.server.flask.application   File "/var/lib/kolla/venv/lib/python3.9/site-packages/flask/app.py", line 1820, in full_dispatch_request
2023-03-15 15:09:57.753 39 ERROR keystone.server.flask.application     rv = self.dispatch_request()
2023-03-15 15:09:57.753 39 ERROR keystone.server.flask.application   File "/var/lib/kolla/venv/lib/python3.9/site-packages/flask/app.py", line 1796, in dispatch_request
2023-03-15 15:09:57.753 39 ERROR keystone.server.flask.application     return self.ensure_sync(self.view_functions[rule.endpoint])(**view_args)
2023-03-15 15:09:57.753 39 ERROR keystone.server.flask.application   File "/var/lib/kolla/venv/lib/python3.9/site-packages/flask_restful/__init__.py", line 467, in wrapper
2023-03-15 15:09:57.753 39 ERROR keystone.server.flask.application     resp = resource(*args, **kwargs)
2023-03-15 15:09:57.753 39 ERROR keystone.server.flask.application   File "/var/lib/kolla/venv/lib/python3.9/site-packages/flask/views.py", line 107, in view
2023-03-15 15:09:57.753 39 ERROR keystone.server.flask.application     return current_app.ensure_sync(self.dispatch_request)(**kwargs)
2023-03-15 15:09:57.753 39 ERROR keystone.server.flask.application   File "/var/lib/kolla/venv/lib/python3.9/site-packages/flask_restful/__init__.py", line 582, in dispatch_request
2023-03-15 15:09:57.753 39 ERROR keystone.server.flask.application     resp = meth(*args, **kwargs)
2023-03-15 15:09:57.753 39 ERROR keystone.server.flask.application   File "/var/lib/kolla/venv/lib/python3.9/site-packages/keystone/api/users.py", line 182, in get
2023-03-15 15:09:57.753 39 ERROR keystone.server.flask.application     return self._get_user(user_id)
2023-03-15 15:09:57.753 39 ERROR keystone.server.flask.application   File "/var/lib/kolla/venv/lib/python3.9/site-packages/keystone/api/users.py", line 194, in _get_user
2023-03-15 15:09:57.753 39 ERROR keystone.server.flask.application     ref = PROVIDERS.identity_api.get_user(user_id)
2023-03-15 15:09:57.753 39 ERROR keystone.server.flask.application   File "/var/lib/kolla/venv/lib/python3.9/site-packages/keystone/common/manager.py", line 115, in wrapped
2023-03-15 15:09:57.753 39 ERROR keystone.server.flask.application     __ret_val = __f(*args, **kwargs)
2023-03-15 15:09:57.753 39 ERROR keystone.server.flask.application   File "/var/lib/kolla/venv/lib/python3.9/site-packages/keystone/identity/core.py", line 414, in wrapper
2023-03-15 15:09:57.753 39 ERROR keystone.server.flask.application     return f(self, *args, **kwargs)
2023-03-15 15:09:57.753 39 ERROR keystone.server.flask.application   File "/var/lib/kolla/venv/lib/python3.9/site-packages/keystone/identity/core.py", line 424, in wrapper
2023-03-15 15:09:57.753 39 ERROR keystone.server.flask.application     return f(self, *args, **kwargs)
2023-03-15 15:09:57.753 39 ERROR keystone.server.flask.application   File "/var/lib/kolla/venv/lib/python3.9/site-packages/decorator.py", line 232, in fun
2023-03-15 15:09:57.753 39 ERROR keystone.server.flask.application     return caller(func, *(extras + args), **kw)
2023-03-15 15:09:57.753 39 ERROR keystone.server.flask.application   File "/var/lib/kolla/venv/lib/python3.9/site-packages/dogpile/cache/region.py", line 1577, in get_or_create_for_user_func
2023-03-15 15:09:57.753 39 ERROR keystone.server.flask.application     return self.get_or_create(
2023-03-15 15:09:57.753 39 ERROR keystone.server.flask.application   File "/var/lib/kolla/venv/lib/python3.9/site-packages/dogpile/cache/region.py", line 1042, in get_or_create
2023-03-15 15:09:57.753 39 ERROR keystone.server.flask.application     with Lock(
2023-03-15 15:09:57.753 39 ERROR keystone.server.flask.application   File "/var/lib/kolla/venv/lib/python3.9/site-packages/dogpile/lock.py", line 185, in __enter__
2023-03-15 15:09:57.753 39 ERROR keystone.server.flask.application     return self._enter()
2023-03-15 15:09:57.753 39 ERROR keystone.server.flask.application   File "/var/lib/kolla/venv/lib/python3.9/site-packages/dogpile/lock.py", line 94, in _enter
2023-03-15 15:09:57.753 39 ERROR keystone.server.flask.application     generated = self._enter_create(value, createdtime)
2023-03-15 15:09:57.753 39 ERROR keystone.server.flask.application   File "/var/lib/kolla/venv/lib/python3.9/site-packages/dogpile/lock.py", line 178, in _enter_create
2023-03-15 15:09:57.753 39 ERROR keystone.server.flask.application     return self.creator()
2023-03-15 15:09:57.753 39 ERROR keystone.server.flask.application   File "/var/lib/kolla/venv/lib/python3.9/site-packages/dogpile/cache/region.py", line 995, in gen_value
2023-03-15 15:09:57.753 39 ERROR keystone.server.flask.application     created_value = creator(
2023-03-15 15:09:57.753 39 ERROR keystone.server.flask.application   File "/var/lib/kolla/venv/lib/python3.9/site-packages/keystone/identity/core.py", line 1011, in get_user
2023-03-15 15:09:57.753 39 ERROR keystone.server.flask.application     ref = driver.get_user(entity_id)
2023-03-15 15:09:57.753 39 ERROR keystone.server.flask.application   File "/var/lib/kolla/venv/lib/python3.9/site-packages/keystone/identity/backends/sql.py", line 200, in get_user
2023-03-15 15:09:57.753 39 ERROR keystone.server.flask.application     self._get_user(session, user_id).to_dict())
2023-03-15 15:09:57.753 39 ERROR keystone.server.flask.application   File "/var/lib/kolla/venv/lib/python3.9/site-packages/keystone/identity/backends/sql.py", line 194, in _get_user
2023-03-15 15:09:57.753 39 ERROR keystone.server.flask.application     raise exception.UserNotFound(user_id=user_id)
2023-03-15 15:09:57.753 39 ERROR keystone.server.flask.application keystone.exception.UserNotFound: Could not find user: neutron.
2023-03-15 15:09:57.753 39 ERROR keystone.server.flask.application 
2023-03-15 15:09:58.550 38 ERROR keystone.server.flask.application [None req-5ff7de38-5a07-4411-99a9-fc6f2b732c03 c05eac42db3b4672a5b2dcff754581a1 - - all default -] Could not find project: service.: keystone.exception.ProjectNotFound: Could not find project: service.
2023-03-15 15:09:58.550 38 ERROR keystone.server.flask.application Traceback (most recent call last):
2023-03-15 15:09:58.550 38 ERROR keystone.server.flask.application   File "/var/lib/kolla/venv/lib/python3.9/site-packages/flask/app.py", line 1820, in full_dispatch_request
2023-03-15 15:09:58.550 38 ERROR keystone.server.flask.application     rv = self.dispatch_request()
2023-03-15 15:09:58.550 38 ERROR keystone.server.flask.application   File "/var/lib/kolla/venv/lib/python3.9/site-packages/flask/app.py", line 1796, in dispatch_request
2023-03-15 15:09:58.550 38 ERROR keystone.server.flask.application     return self.ensure_sync(self.view_functions[rule.endpoint])(**view_args)
2023-03-15 15:09:58.550 38 ERROR keystone.server.flask.application   File "/var/lib/kolla/venv/lib/python3.9/site-packages/flask_restful/__init__.py", line 467, in wrapper
2023-03-15 15:09:58.550 38 ERROR keystone.server.flask.application     resp = resource(*args, **kwargs)
2023-03-15 15:09:58.550 38 ERROR keystone.server.flask.application   File "/var/lib/kolla/venv/lib/python3.9/site-packages/flask/views.py", line 107, in view
2023-03-15 15:09:58.550 38 ERROR keystone.server.flask.application     return current_app.ensure_sync(self.dispatch_request)(**kwargs)
2023-03-15 15:09:58.550 38 ERROR keystone.server.flask.application   File "/var/lib/kolla/venv/lib/python3.9/site-packages/flask_restful/__init__.py", line 582, in dispatch_request
2023-03-15 15:09:58.550 38 ERROR keystone.server.flask.application     resp = meth(*args, **kwargs)
2023-03-15 15:09:58.550 38 ERROR keystone.server.flask.application   File "/var/lib/kolla/venv/lib/python3.9/site-packages/keystone/api/projects.py", line 151, in get
2023-03-15 15:09:58.550 38 ERROR keystone.server.flask.application     return self._get_project(project_id)
2023-03-15 15:09:58.550 38 ERROR keystone.server.flask.application   File "/var/lib/kolla/venv/lib/python3.9/site-packages/keystone/api/projects.py", line 107, in _get_project
2023-03-15 15:09:58.550 38 ERROR keystone.server.flask.application     project = PROVIDERS.resource_api.get_project(project_id)
2023-03-15 15:09:58.550 38 ERROR keystone.server.flask.application   File "/var/lib/kolla/venv/lib/python3.9/site-packages/keystone/common/manager.py", line 115, in wrapped
2023-03-15 15:09:58.550 38 ERROR keystone.server.flask.application     __ret_val = __f(*args, **kwargs)
2023-03-15 15:09:58.550 38 ERROR keystone.server.flask.application   File "/var/lib/kolla/venv/lib/python3.9/site-packages/decorator.py", line 232, in fun
2023-03-15 15:09:58.550 38 ERROR keystone.server.flask.application     return caller(func, *(extras + args), **kw)
2023-03-15 15:09:58.550 38 ERROR keystone.server.flask.application   File "/var/lib/kolla/venv/lib/python3.9/site-packages/dogpile/cache/region.py", line 1577, in get_or_create_for_user_func
2023-03-15 15:09:58.550 38 ERROR keystone.server.flask.application     return self.get_or_create(
2023-03-15 15:09:58.550 38 ERROR keystone.server.flask.application   File "/var/lib/kolla/venv/lib/python3.9/site-packages/dogpile/cache/region.py", line 1042, in get_or_create
2023-03-15 15:09:58.550 38 ERROR keystone.server.flask.application     with Lock(
2023-03-15 15:09:58.550 38 ERROR keystone.server.flask.application   File "/var/lib/kolla/venv/lib/python3.9/site-packages/dogpile/lock.py", line 185, in __enter__
2023-03-15 15:09:58.550 38 ERROR keystone.server.flask.application     return self._enter()
2023-03-15 15:09:58.550 38 ERROR keystone.server.flask.application   File "/var/lib/kolla/venv/lib/python3.9/site-packages/dogpile/lock.py", line 94, in _enter
2023-03-15 15:09:58.550 38 ERROR keystone.server.flask.application     generated = self._enter_create(value, createdtime)
2023-03-15 15:09:58.550 38 ERROR keystone.server.flask.application   File "/var/lib/kolla/venv/lib/python3.9/site-packages/dogpile/lock.py", line 178, in _enter_create
2023-03-15 15:09:58.550 38 ERROR keystone.server.flask.application     return self.creator()
2023-03-15 15:09:58.550 38 ERROR keystone.server.flask.application   File "/var/lib/kolla/venv/lib/python3.9/site-packages/dogpile/cache/region.py", line 995, in gen_value
2023-03-15 15:09:58.550 38 ERROR keystone.server.flask.application     created_value = creator(
2023-03-15 15:09:58.550 38 ERROR keystone.server.flask.application   File "/var/lib/kolla/venv/lib/python3.9/site-packages/keystone/resource/core.py", line 903, in get_project
2023-03-15 15:09:58.550 38 ERROR keystone.server.flask.application     return self.driver.get_project(project_id)
2023-03-15 15:09:58.550 38 ERROR keystone.server.flask.application   File "/var/lib/kolla/venv/lib/python3.9/site-packages/keystone/resource/backends/sql.py", line 49, in get_project
2023-03-15 15:09:58.550 38 ERROR keystone.server.flask.application     return self._get_project(session, project_id).to_dict()
2023-03-15 15:09:58.550 38 ERROR keystone.server.flask.application   File "/var/lib/kolla/venv/lib/python3.9/site-packages/keystone/resource/backends/sql.py", line 44, in _get_project
2023-03-15 15:09:58.550 38 ERROR keystone.server.flask.application     raise exception.ProjectNotFound(project_id=project_id)
2023-03-15 15:09:58.550 38 ERROR keystone.server.flask.application keystone.exception.ProjectNotFound: Could not find project: service.
2023-03-15 15:09:58.550 38 ERROR keystone.server.flask.application 
