2023-02-17 11:31:47.994504 2023-02-17 11:31:47.993 38 WARNING keystone.common.rbac_enforcer.enforcer [None req-2a4dde31-7452-4669-8776-af910faf21f6 ea378d77e35945abb7effbd999872281 - - all default -] Deprecated policy rules found. Use oslopolicy-policy-generator and oslopolicy-policy-upgrade to detect and resolve deprecated policies in your configuration.\x1b[00m
2023-02-17 11:31:48.753587 2023-02-17 11:31:48.752 39 WARNING keystone.common.rbac_enforcer.enforcer [None req-c725da82-0e7c-4b0e-b8da-0a88a5f1b000 ea378d77e35945abb7effbd999872281 - - all default -] Deprecated policy rules found. Use oslopolicy-policy-generator and oslopolicy-policy-upgrade to detect and resolve deprecated policies in your configuration.\x1b[00m
2023-02-17 11:31:55.804749 2023-02-17 11:31:55.802 37 WARNING keystone.common.rbac_enforcer.enforcer [None req-2c98cc57-7f3c-42a8-bfb0-2eb17febfa39 ea378d77e35945abb7effbd999872281 - - all default -] Deprecated policy rules found. Use oslopolicy-policy-generator and oslopolicy-policy-upgrade to detect and resolve deprecated policies in your configuration.\x1b[00m
2023-02-17 11:33:07.676354 2023-02-17 11:33:07.645 39 ERROR keystone.server.flask.application [None req-b64bd0c0-c6a0-4cc8-b08d-b66e55bad1a6 ea378d77e35945abb7effbd999872281 - - all default -] Could not find project: service.: keystone.exception.ProjectNotFound: Could not find project: service.
2023-02-17 11:33:07.676408 2023-02-17 11:33:07.645 39 ERROR keystone.server.flask.application Traceback (most recent call last):
2023-02-17 11:33:07.676437 2023-02-17 11:33:07.645 39 ERROR keystone.server.flask.application   File "/var/lib/kolla/venv/lib/python3.9/site-packages/flask/app.py", line 1820, in full_dispatch_request
2023-02-17 11:33:07.676447 2023-02-17 11:33:07.645 39 ERROR keystone.server.flask.application     rv = self.dispatch_request()
2023-02-17 11:33:07.676456 2023-02-17 11:33:07.645 39 ERROR keystone.server.flask.application   File "/var/lib/kolla/venv/lib/python3.9/site-packages/flask/app.py", line 1796, in dispatch_request
2023-02-17 11:33:07.676466 2023-02-17 11:33:07.645 39 ERROR keystone.server.flask.application     return self.ensure_sync(self.view_functions[rule.endpoint])(**view_args)
2023-02-17 11:33:07.676476 2023-02-17 11:33:07.645 39 ERROR keystone.server.flask.application   File "/var/lib/kolla/venv/lib/python3.9/site-packages/flask_restful/__init__.py", line 467, in wrapper
2023-02-17 11:33:07.676485 2023-02-17 11:33:07.645 39 ERROR keystone.server.flask.application     resp = resource(*args, **kwargs)
2023-02-17 11:33:07.676501 2023-02-17 11:33:07.645 39 ERROR keystone.server.flask.application   File "/var/lib/kolla/venv/lib/python3.9/site-packages/flask/views.py", line 107, in view
2023-02-17 11:33:07.676513 2023-02-17 11:33:07.645 39 ERROR keystone.server.flask.application     return current_app.ensure_sync(self.dispatch_request)(**kwargs)
2023-02-17 11:33:07.676523 2023-02-17 11:33:07.645 39 ERROR keystone.server.flask.application   File "/var/lib/kolla/venv/lib/python3.9/site-packages/flask_restful/__init__.py", line 582, in dispatch_request
2023-02-17 11:33:07.676533 2023-02-17 11:33:07.645 39 ERROR keystone.server.flask.application     resp = meth(*args, **kwargs)
2023-02-17 11:33:07.676542 2023-02-17 11:33:07.645 39 ERROR keystone.server.flask.application   File "/var/lib/kolla/venv/lib/python3.9/site-packages/keystone/api/projects.py", line 151, in get
2023-02-17 11:33:07.676552 2023-02-17 11:33:07.645 39 ERROR keystone.server.flask.application     return self._get_project(project_id)
2023-02-17 11:33:07.676561 2023-02-17 11:33:07.645 39 ERROR keystone.server.flask.application   File "/var/lib/kolla/venv/lib/python3.9/site-packages/keystone/api/projects.py", line 107, in _get_project
2023-02-17 11:33:07.676570 2023-02-17 11:33:07.645 39 ERROR keystone.server.flask.application     project = PROVIDERS.resource_api.get_project(project_id)
2023-02-17 11:33:07.676580 2023-02-17 11:33:07.645 39 ERROR keystone.server.flask.application   File "/var/lib/kolla/venv/lib/python3.9/site-packages/keystone/common/manager.py", line 115, in wrapped
2023-02-17 11:33:07.676613 2023-02-17 11:33:07.645 39 ERROR keystone.server.flask.application     __ret_val = __f(*args, **kwargs)
2023-02-17 11:33:07.676625 2023-02-17 11:33:07.645 39 ERROR keystone.server.flask.application   File "/var/lib/kolla/venv/lib/python3.9/site-packages/decorator.py", line 232, in fun
2023-02-17 11:33:07.676635 2023-02-17 11:33:07.645 39 ERROR keystone.server.flask.application     return caller(func, *(extras + args), **kw)
2023-02-17 11:33:07.676652 2023-02-17 11:33:07.645 39 ERROR keystone.server.flask.application   File "/var/lib/kolla/venv/lib/python3.9/site-packages/dogpile/cache/region.py", line 1577, in get_or_create_for_user_func
2023-02-17 11:33:07.676664 2023-02-17 11:33:07.645 39 ERROR keystone.server.flask.application     return self.get_or_create(
2023-02-17 11:33:07.676673 2023-02-17 11:33:07.645 39 ERROR keystone.server.flask.application   File "/var/lib/kolla/venv/lib/python3.9/site-packages/dogpile/cache/region.py", line 1042, in get_or_create
2023-02-17 11:33:07.676698 2023-02-17 11:33:07.645 39 ERROR keystone.server.flask.application     with Lock(
2023-02-17 11:33:07.676708 2023-02-17 11:33:07.645 39 ERROR keystone.server.flask.application   File "/var/lib/kolla/venv/lib/python3.9/site-packages/dogpile/lock.py", line 185, in __enter__
2023-02-17 11:33:07.676717 2023-02-17 11:33:07.645 39 ERROR keystone.server.flask.application     return self._enter()
2023-02-17 11:33:07.676726 2023-02-17 11:33:07.645 39 ERROR keystone.server.flask.application   File "/var/lib/kolla/venv/lib/python3.9/site-packages/dogpile/lock.py", line 94, in _enter
2023-02-17 11:33:07.676736 2023-02-17 11:33:07.645 39 ERROR keystone.server.flask.application     generated = self._enter_create(value, createdtime)
2023-02-17 11:33:07.676745 2023-02-17 11:33:07.645 39 ERROR keystone.server.flask.application   File "/var/lib/kolla/venv/lib/python3.9/site-packages/dogpile/lock.py", line 178, in _enter_create
2023-02-17 11:33:07.676754 2023-02-17 11:33:07.645 39 ERROR keystone.server.flask.application     return self.creator()
2023-02-17 11:33:07.676763 2023-02-17 11:33:07.645 39 ERROR keystone.server.flask.application   File "/var/lib/kolla/venv/lib/python3.9/site-packages/dogpile/cache/region.py", line 995, in gen_value
2023-02-17 11:33:07.676773 2023-02-17 11:33:07.645 39 ERROR keystone.server.flask.application     created_value = creator(
2023-02-17 11:33:07.676782 2023-02-17 11:33:07.645 39 ERROR keystone.server.flask.application   File "/var/lib/kolla/venv/lib/python3.9/site-packages/keystone/resource/core.py", line 903, in get_project
2023-02-17 11:33:07.676791 2023-02-17 11:33:07.645 39 ERROR keystone.server.flask.application     return self.driver.get_project(project_id)
2023-02-17 11:33:07.676800 2023-02-17 11:33:07.645 39 ERROR keystone.server.flask.application   File "/var/lib/kolla/venv/lib/python3.9/site-packages/keystone/resource/backends/sql.py", line 49, in get_project
2023-02-17 11:33:07.676810 2023-02-17 11:33:07.645 39 ERROR keystone.server.flask.application     return self._get_project(session, project_id).to_dict()
2023-02-17 11:33:07.676819 2023-02-17 11:33:07.645 39 ERROR keystone.server.flask.application   File "/var/lib/kolla/venv/lib/python3.9/site-packages/keystone/resource/backends/sql.py", line 44, in _get_project
2023-02-17 11:33:07.676829 2023-02-17 11:33:07.645 39 ERROR keystone.server.flask.application     raise exception.ProjectNotFound(project_id=project_id)
2023-02-17 11:33:07.676838 2023-02-17 11:33:07.645 39 ERROR keystone.server.flask.application keystone.exception.ProjectNotFound: Could not find project: service.
2023-02-17 11:33:07.676847 2023-02-17 11:33:07.645 39 ERROR keystone.server.flask.application \x1b[00m
2023-02-17 11:33:16.247596 2023-02-17 11:33:16.234 37 ERROR keystone.server.flask.application [None req-6903b064-0c32-402b-bfe4-b1a830b90bc4 ea378d77e35945abb7effbd999872281 - - all default -] Could not find project: service.: keystone.exception.ProjectNotFound: Could not find project: service.
2023-02-17 11:33:16.247644 2023-02-17 11:33:16.234 37 ERROR keystone.server.flask.application Traceback (most recent call last):
2023-02-17 11:33:16.247684 2023-02-17 11:33:16.234 37 ERROR keystone.server.flask.application   File "/var/lib/kolla/venv/lib/python3.9/site-packages/flask/app.py", line 1820, in full_dispatch_request
2023-02-17 11:33:16.247697 2023-02-17 11:33:16.234 37 ERROR keystone.server.flask.application     rv = self.dispatch_request()
2023-02-17 11:33:16.247706 2023-02-17 11:33:16.234 37 ERROR keystone.server.flask.application   File "/var/lib/kolla/venv/lib/python3.9/site-packages/flask/app.py", line 1796, in dispatch_request
2023-02-17 11:33:16.247716 2023-02-17 11:33:16.234 37 ERROR keystone.server.flask.application     return self.ensure_sync(self.view_functions[rule.endpoint])(**view_args)
2023-02-17 11:33:16.247726 2023-02-17 11:33:16.234 37 ERROR keystone.server.flask.application   File "/var/lib/kolla/venv/lib/python3.9/site-packages/flask_restful/__init__.py", line 467, in wrapper
2023-02-17 11:33:16.247735 2023-02-17 11:33:16.234 37 ERROR keystone.server.flask.application     resp = resource(*args, **kwargs)
2023-02-17 11:33:16.247751 2023-02-17 11:33:16.234 37 ERROR keystone.server.flask.application   File "/var/lib/kolla/venv/lib/python3.9/site-packages/flask/views.py", line 107, in view
2023-02-17 11:33:16.247764 2023-02-17 11:33:16.234 37 ERROR keystone.server.flask.application     return current_app.ensure_sync(self.dispatch_request)(**kwargs)
2023-02-17 11:33:16.247773 2023-02-17 11:33:16.234 37 ERROR keystone.server.flask.application   File "/var/lib/kolla/venv/lib/python3.9/site-packages/flask_restful/__init__.py", line 582, in dispatch_request
2023-02-17 11:33:16.247783 2023-02-17 11:33:16.234 37 ERROR keystone.server.flask.application     resp = meth(*args, **kwargs)
2023-02-17 11:33:16.247792 2023-02-17 11:33:16.234 37 ERROR keystone.server.flask.application   File "/var/lib/kolla/venv/lib/python3.9/site-packages/keystone/api/projects.py", line 151, in get
2023-02-17 11:33:16.247803 2023-02-17 11:33:16.234 37 ERROR keystone.server.flask.application     return self._get_project(project_id)
2023-02-17 11:33:16.247812 2023-02-17 11:33:16.234 37 ERROR keystone.server.flask.application   File "/var/lib/kolla/venv/lib/python3.9/site-packages/keystone/api/projects.py", line 107, in _get_project
2023-02-17 11:33:16.247822 2023-02-17 11:33:16.234 37 ERROR keystone.server.flask.application     project = PROVIDERS.resource_api.get_project(project_id)
2023-02-17 11:33:16.247831 2023-02-17 11:33:16.234 37 ERROR keystone.server.flask.application   File "/var/lib/kolla/venv/lib/python3.9/site-packages/keystone/common/manager.py", line 115, in wrapped
2023-02-17 11:33:16.247841 2023-02-17 11:33:16.234 37 ERROR keystone.server.flask.application     __ret_val = __f(*args, **kwargs)
2023-02-17 11:33:16.247850 2023-02-17 11:33:16.234 37 ERROR keystone.server.flask.application   File "/var/lib/kolla/venv/lib/python3.9/site-packages/decorator.py", line 232, in fun
2023-02-17 11:33:16.247882 2023-02-17 11:33:16.234 37 ERROR keystone.server.flask.application     return caller(func, *(extras + args), **kw)
2023-02-17 11:33:16.247901 2023-02-17 11:33:16.234 37 ERROR keystone.server.flask.application   File "/var/lib/kolla/venv/lib/python3.9/site-packages/dogpile/cache/region.py", line 1577, in get_or_create_for_user_func
2023-02-17 11:33:16.247912 2023-02-17 11:33:16.234 37 ERROR keystone.server.flask.application     return self.get_or_create(
2023-02-17 11:33:16.247921 2023-02-17 11:33:16.234 37 ERROR keystone.server.flask.application   File "/var/lib/kolla/venv/lib/python3.9/site-packages/dogpile/cache/region.py", line 1042, in get_or_create
2023-02-17 11:33:16.247932 2023-02-17 11:33:16.234 37 ERROR keystone.server.flask.application     with Lock(
2023-02-17 11:33:16.247941 2023-02-17 11:33:16.234 37 ERROR keystone.server.flask.application   File "/var/lib/kolla/venv/lib/python3.9/site-packages/dogpile/lock.py", line 185, in __enter__
2023-02-17 11:33:16.247950 2023-02-17 11:33:16.234 37 ERROR keystone.server.flask.application     return self._enter()
2023-02-17 11:33:16.247992 2023-02-17 11:33:16.234 37 ERROR keystone.server.flask.application   File "/var/lib/kolla/venv/lib/python3.9/site-packages/dogpile/lock.py", line 94, in _enter
2023-02-17 11:33:16.248030 2023-02-17 11:33:16.234 37 ERROR keystone.server.flask.application     generated = self._enter_create(value, createdtime)
2023-02-17 11:33:16.248044 2023-02-17 11:33:16.234 37 ERROR keystone.server.flask.application   File "/var/lib/kolla/venv/lib/python3.9/site-packages/dogpile/lock.py", line 178, in _enter_create
2023-02-17 11:33:16.248054 2023-02-17 11:33:16.234 37 ERROR keystone.server.flask.application     return self.creator()
2023-02-17 11:33:16.248064 2023-02-17 11:33:16.234 37 ERROR keystone.server.flask.application   File "/var/lib/kolla/venv/lib/python3.9/site-packages/dogpile/cache/region.py", line 995, in gen_value
2023-02-17 11:33:16.248073 2023-02-17 11:33:16.234 37 ERROR keystone.server.flask.application     created_value = creator(
2023-02-17 11:33:16.248083 2023-02-17 11:33:16.234 37 ERROR keystone.server.flask.application   File "/var/lib/kolla/venv/lib/python3.9/site-packages/keystone/resource/core.py", line 903, in get_project
2023-02-17 11:33:16.248092 2023-02-17 11:33:16.234 37 ERROR keystone.server.flask.application     return self.driver.get_project(project_id)
2023-02-17 11:33:16.248102 2023-02-17 11:33:16.234 37 ERROR keystone.server.flask.application   File "/var/lib/kolla/venv/lib/python3.9/site-packages/keystone/resource/backends/sql.py", line 49, in get_project
2023-02-17 11:33:16.248111 2023-02-17 11:33:16.234 37 ERROR keystone.server.flask.application     return self._get_project(session, project_id).to_dict()
2023-02-17 11:33:16.248121 2023-02-17 11:33:16.234 37 ERROR keystone.server.flask.application   File "/var/lib/kolla/venv/lib/python3.9/site-packages/keystone/resource/backends/sql.py", line 44, in _get_project
2023-02-17 11:33:16.248131 2023-02-17 11:33:16.234 37 ERROR keystone.server.flask.application     raise exception.ProjectNotFound(project_id=project_id)
2023-02-17 11:33:16.248141 2023-02-17 11:33:16.234 37 ERROR keystone.server.flask.application keystone.exception.ProjectNotFound: Could not find project: service.
2023-02-17 11:33:16.248150 2023-02-17 11:33:16.234 37 ERROR keystone.server.flask.application \x1b[00m
2023-02-17 11:33:30.680765 2023-02-17 11:33:30.674 37 ERROR keystone.server.flask.application [None req-1dfebf3a-5a6a-4cdf-8d0b-a530aac22950 ea378d77e35945abb7effbd999872281 - - all default -] Could not find role: admin.: keystone.exception.RoleNotFound: Could not find role: admin.
2023-02-17 11:33:30.680808 2023-02-17 11:33:30.674 37 ERROR keystone.server.flask.application Traceback (most recent call last):
2023-02-17 11:33:30.680820 2023-02-17 11:33:30.674 37 ERROR keystone.server.flask.application   File "/var/lib/kolla/venv/lib/python3.9/site-packages/flask/app.py", line 1820, in full_dispatch_request
2023-02-17 11:33:30.680839 2023-02-17 11:33:30.674 37 ERROR keystone.server.flask.application     rv = self.dispatch_request()
2023-02-17 11:33:30.680849 2023-02-17 11:33:30.674 37 ERROR keystone.server.flask.application   File "/var/lib/kolla/venv/lib/python3.9/site-packages/flask/app.py", line 1796, in dispatch_request
2023-02-17 11:33:30.680884 2023-02-17 11:33:30.674 37 ERROR keystone.server.flask.application     return self.ensure_sync(self.view_functions[rule.endpoint])(**view_args)
2023-02-17 11:33:30.680897 2023-02-17 11:33:30.674 37 ERROR keystone.server.flask.application   File "/var/lib/kolla/venv/lib/python3.9/site-packages/flask_restful/__init__.py", line 467, in wrapper
2023-02-17 11:33:30.680907 2023-02-17 11:33:30.674 37 ERROR keystone.server.flask.application     resp = resource(*args, **kwargs)
2023-02-17 11:33:30.680923 2023-02-17 11:33:30.674 37 ERROR keystone.server.flask.application   File "/var/lib/kolla/venv/lib/python3.9/site-packages/flask/views.py", line 107, in view
2023-02-17 11:33:30.680936 2023-02-17 11:33:30.674 37 ERROR keystone.server.flask.application     return current_app.ensure_sync(self.dispatch_request)(**kwargs)
2023-02-17 11:33:30.680945 2023-02-17 11:33:30.674 37 ERROR keystone.server.flask.application   File "/var/lib/kolla/venv/lib/python3.9/site-packages/flask_restful/__init__.py", line 582, in dispatch_request
2023-02-17 11:33:30.680977 2023-02-17 11:33:30.674 37 ERROR keystone.server.flask.application     resp = meth(*args, **kwargs)
2023-02-17 11:33:30.680989 2023-02-17 11:33:30.674 37 ERROR keystone.server.flask.application   File "/var/lib/kolla/venv/lib/python3.9/site-packages/keystone/api/roles.py", line 50, in get
2023-02-17 11:33:30.681024 2023-02-17 11:33:30.674 37 ERROR keystone.server.flask.application     return self._get_role(role_id)
2023-02-17 11:33:30.681040 2023-02-17 11:33:30.674 37 ERROR keystone.server.flask.application   File "/var/lib/kolla/venv/lib/python3.9/site-packages/keystone/api/roles.py", line 70, in _get_role
2023-02-17 11:33:30.681050 2023-02-17 11:33:30.674 37 ERROR keystone.server.flask.application     ENFORCER.enforce_call(action='identity:get_role')
2023-02-17 11:33:30.681060 2023-02-17 11:33:30.674 37 ERROR keystone.server.flask.application   File "/var/lib/kolla/venv/lib/python3.9/site-packages/keystone/common/rbac_enforcer/enforcer.py", line 402, in enforce_call
2023-02-17 11:33:30.681070 2023-02-17 11:33:30.674 37 ERROR keystone.server.flask.application     policy_dict.update(cls._extract_member_target_data(
2023-02-17 11:33:30.681079 2023-02-17 11:33:30.674 37 ERROR keystone.server.flask.application   File "/var/lib/kolla/venv/lib/python3.9/site-packages/keystone/common/rbac_enforcer/enforcer.py", line 234, in _extract_member_target_data
2023-02-17 11:33:30.681089 2023-02-17 11:33:30.674 37 ERROR keystone.server.flask.application     member_name: func(flask.request.view_args[key])
2023-02-17 11:33:30.681103 2023-02-17 11:33:30.674 37 ERROR keystone.server.flask.application   File "/var/lib/kolla/venv/lib/python3.9/site-packages/keystone/common/manager.py", line 115, in wrapped
2023-02-17 11:33:30.681117 2023-02-17 11:33:30.674 37 ERROR keystone.server.flask.application     __ret_val = __f(*args, **kwargs)
2023-02-17 11:33:30.681130 2023-02-17 11:33:30.674 37 ERROR keystone.server.flask.application   File "/var/lib/kolla/venv/lib/python3.9/site-packages/decorator.py", line 232, in fun
2023-02-17 11:33:30.681140 2023-02-17 11:33:30.674 37 ERROR keystone.server.flask.application     return caller(func, *(extras + args), **kw)
2023-02-17 11:33:30.681149 2023-02-17 11:33:30.674 37 ERROR keystone.server.flask.application   File "/var/lib/kolla/venv/lib/python3.9/site-packages/dogpile/cache/region.py", line 1577, in get_or_create_for_user_func
2023-02-17 11:33:30.681159 2023-02-17 11:33:30.674 37 ERROR keystone.server.flask.application     return self.get_or_create(
2023-02-17 11:33:30.681168 2023-02-17 11:33:30.674 37 ERROR keystone.server.flask.application   File "/var/lib/kolla/venv/lib/python3.9/site-packages/dogpile/cache/region.py", line 1042, in get_or_create
2023-02-17 11:33:30.681178 2023-02-17 11:33:30.674 37 ERROR keystone.server.flask.application     with Lock(
2023-02-17 11:33:30.681187 2023-02-17 11:33:30.674 37 ERROR keystone.server.flask.application   File "/var/lib/kolla/venv/lib/python3.9/site-packages/dogpile/lock.py", line 185, in __enter__
2023-02-17 11:33:30.681196 2023-02-17 11:33:30.674 37 ERROR keystone.server.flask.application     return self._enter()
2023-02-17 11:33:30.681205 2023-02-17 11:33:30.674 37 ERROR keystone.server.flask.application   File "/var/lib/kolla/venv/lib/python3.9/site-packages/dogpile/lock.py", line 94, in _enter
2023-02-17 11:33:30.681214 2023-02-17 11:33:30.674 37 ERROR keystone.server.flask.application     generated = self._enter_create(value, createdtime)
2023-02-17 11:33:30.681224 2023-02-17 11:33:30.674 37 ERROR keystone.server.flask.application   File "/var/lib/kolla/venv/lib/python3.9/site-packages/dogpile/lock.py", line 178, in _enter_create
2023-02-17 11:33:30.681233 2023-02-17 11:33:30.674 37 ERROR keystone.server.flask.application     return self.creator()
2023-02-17 11:33:30.681242 2023-02-17 11:33:30.674 37 ERROR keystone.server.flask.application   File "/var/lib/kolla/venv/lib/python3.9/site-packages/dogpile/cache/region.py", line 995, in gen_value
2023-02-17 11:33:30.681274 2023-02-17 11:33:30.674 37 ERROR keystone.server.flask.application     created_value = creator(
2023-02-17 11:33:30.681287 2023-02-17 11:33:30.674 37 ERROR keystone.server.flask.application   File "/var/lib/kolla/venv/lib/python3.9/site-packages/keystone/assignment/core.py", line 1276, in get_role
2023-02-17 11:33:30.681300 2023-02-17 11:33:30.674 37 ERROR keystone.server.flask.application     return self.driver.get_role(role_id)
2023-02-17 11:33:30.681309 2023-02-17 11:33:30.674 37 ERROR keystone.server.flask.application   File "/var/lib/kolla/venv/lib/python3.9/site-packages/keystone/assignment/role_backends/sql.py", line 70, in get_role
2023-02-17 11:33:30.681319 2023-02-17 11:33:30.674 37 ERROR keystone.server.flask.application     return self._get_role(session, role_id).to_dict()
2023-02-17 11:33:30.681328 2023-02-17 11:33:30.674 37 ERROR keystone.server.flask.application   File "/var/lib/kolla/venv/lib/python3.9/site-packages/keystone/assignment/role_backends/sql.py", line 65, in _get_role
2023-02-17 11:33:30.681338 2023-02-17 11:33:30.674 37 ERROR keystone.server.flask.application     raise exception.RoleNotFound(role_id=role_id)
2023-02-17 11:33:30.681347 2023-02-17 11:33:30.674 37 ERROR keystone.server.flask.application keystone.exception.RoleNotFound: Could not find role: admin.
2023-02-17 11:33:30.681356 2023-02-17 11:33:30.674 37 ERROR keystone.server.flask.application \x1b[00m
2023-02-17 11:33:31.789915 2023-02-17 11:33:31.783 37 ERROR keystone.server.flask.application [None req-dcf3da8c-31f2-4478-bcdf-657a80ae942f ea378d77e35945abb7effbd999872281 - - all default -] Could not find user: ironic.: keystone.exception.UserNotFound: Could not find user: ironic.
2023-02-17 11:33:31.789955 2023-02-17 11:33:31.783 37 ERROR keystone.server.flask.application Traceback (most recent call last):
2023-02-17 11:33:31.789967 2023-02-17 11:33:31.783 37 ERROR keystone.server.flask.application   File "/var/lib/kolla/venv/lib/python3.9/site-packages/flask/app.py", line 1820, in full_dispatch_request
2023-02-17 11:33:31.789977 2023-02-17 11:33:31.783 37 ERROR keystone.server.flask.application     rv = self.dispatch_request()
2023-02-17 11:33:31.789986 2023-02-17 11:33:31.783 37 ERROR keystone.server.flask.application   File "/var/lib/kolla/venv/lib/python3.9/site-packages/flask/app.py", line 1796, in dispatch_request
2023-02-17 11:33:31.790031 2023-02-17 11:33:31.783 37 ERROR keystone.server.flask.application     return self.ensure_sync(self.view_functions[rule.endpoint])(**view_args)
2023-02-17 11:33:31.790045 2023-02-17 11:33:31.783 37 ERROR keystone.server.flask.application   File "/var/lib/kolla/venv/lib/python3.9/site-packages/flask_restful/__init__.py", line 467, in wrapper
2023-02-17 11:33:31.790055 2023-02-17 11:33:31.783 37 ERROR keystone.server.flask.application     resp = resource(*args, **kwargs)
2023-02-17 11:33:31.790066 2023-02-17 11:33:31.783 37 ERROR keystone.server.flask.application   File "/var/lib/kolla/venv/lib/python3.9/site-packages/flask/views.py", line 107, in view
2023-02-17 11:33:31.790076 2023-02-17 11:33:31.783 37 ERROR keystone.server.flask.application     return current_app.ensure_sync(self.dispatch_request)(**kwargs)
2023-02-17 11:33:31.790085 2023-02-17 11:33:31.783 37 ERROR keystone.server.flask.application   File "/var/lib/kolla/venv/lib/python3.9/site-packages/flask_restful/__init__.py", line 582, in dispatch_request
2023-02-17 11:33:31.790095 2023-02-17 11:33:31.783 37 ERROR keystone.server.flask.application     resp = meth(*args, **kwargs)
2023-02-17 11:33:31.790104 2023-02-17 11:33:31.783 37 ERROR keystone.server.flask.application   File "/var/lib/kolla/venv/lib/python3.9/site-packages/keystone/api/users.py", line 182, in get
2023-02-17 11:33:31.790120 2023-02-17 11:33:31.783 37 ERROR keystone.server.flask.application     return self._get_user(user_id)
2023-02-17 11:33:31.790130 2023-02-17 11:33:31.783 37 ERROR keystone.server.flask.application   File "/var/lib/kolla/venv/lib/python3.9/site-packages/keystone/api/users.py", line 194, in _get_user
2023-02-17 11:33:31.790162 2023-02-17 11:33:31.783 37 ERROR keystone.server.flask.application     ref = PROVIDERS.identity_api.get_user(user_id)
2023-02-17 11:33:31.790173 2023-02-17 11:33:31.783 37 ERROR keystone.server.flask.application   File "/var/lib/kolla/venv/lib/python3.9/site-packages/keystone/common/manager.py", line 115, in wrapped
2023-02-17 11:33:31.790183 2023-02-17 11:33:31.783 37 ERROR keystone.server.flask.application     __ret_val = __f(*args, **kwargs)
2023-02-17 11:33:31.790193 2023-02-17 11:33:31.783 37 ERROR keystone.server.flask.application   File "/var/lib/kolla/venv/lib/python3.9/site-packages/keystone/identity/core.py", line 414, in wrapper
2023-02-17 11:33:31.790202 2023-02-17 11:33:31.783 37 ERROR keystone.server.flask.application     return f(self, *args, **kwargs)
2023-02-17 11:33:31.790212 2023-02-17 11:33:31.783 37 ERROR keystone.server.flask.application   File "/var/lib/kolla/venv/lib/python3.9/site-packages/keystone/identity/core.py", line 424, in wrapper
2023-02-17 11:33:31.790222 2023-02-17 11:33:31.783 37 ERROR keystone.server.flask.application     return f(self, *args, **kwargs)
2023-02-17 11:33:31.790234 2023-02-17 11:33:31.783 37 ERROR keystone.server.flask.application   File "/var/lib/kolla/venv/lib/python3.9/site-packages/decorator.py", line 232, in fun
2023-02-17 11:33:31.790244 2023-02-17 11:33:31.783 37 ERROR keystone.server.flask.application     return caller(func, *(extras + args), **kw)
2023-02-17 11:33:31.790254 2023-02-17 11:33:31.783 37 ERROR keystone.server.flask.application   File "/var/lib/kolla/venv/lib/python3.9/site-packages/dogpile/cache/region.py", line 1577, in get_or_create_for_user_func
2023-02-17 11:33:31.790264 2023-02-17 11:33:31.783 37 ERROR keystone.server.flask.application     return self.get_or_create(
2023-02-17 11:33:31.790273 2023-02-17 11:33:31.783 37 ERROR keystone.server.flask.application   File "/var/lib/kolla/venv/lib/python3.9/site-packages/dogpile/cache/region.py", line 1042, in get_or_create
2023-02-17 11:33:31.790283 2023-02-17 11:33:31.783 37 ERROR keystone.server.flask.application     with Lock(
2023-02-17 11:33:31.790293 2023-02-17 11:33:31.783 37 ERROR keystone.server.flask.application   File "/var/lib/kolla/venv/lib/python3.9/site-packages/dogpile/lock.py", line 185, in __enter__
2023-02-17 11:33:31.790302 2023-02-17 11:33:31.783 37 ERROR keystone.server.flask.application     return self._enter()
2023-02-17 11:33:31.790312 2023-02-17 11:33:31.783 37 ERROR keystone.server.flask.application   File "/var/lib/kolla/venv/lib/python3.9/site-packages/dogpile/lock.py", line 94, in _enter
2023-02-17 11:33:31.790322 2023-02-17 11:33:31.783 37 ERROR keystone.server.flask.application     generated = self._enter_create(value, createdtime)
2023-02-17 11:33:31.790331 2023-02-17 11:33:31.783 37 ERROR keystone.server.flask.application   File "/var/lib/kolla/venv/lib/python3.9/site-packages/dogpile/lock.py", line 178, in _enter_create
2023-02-17 11:33:31.790342 2023-02-17 11:33:31.783 37 ERROR keystone.server.flask.application     return self.creator()
2023-02-17 11:33:31.790351 2023-02-17 11:33:31.783 37 ERROR keystone.server.flask.application   File "/var/lib/kolla/venv/lib/python3.9/site-packages/dogpile/cache/region.py", line 995, in gen_value
2023-02-17 11:33:31.790361 2023-02-17 11:33:31.783 37 ERROR keystone.server.flask.application     created_value = creator(
2023-02-17 11:33:31.790371 2023-02-17 11:33:31.783 37 ERROR keystone.server.flask.application   File "/var/lib/kolla/venv/lib/python3.9/site-packages/keystone/identity/core.py", line 1011, in get_user
2023-02-17 11:33:31.790380 2023-02-17 11:33:31.783 37 ERROR keystone.server.flask.application     ref = driver.get_user(entity_id)
2023-02-17 11:33:31.790390 2023-02-17 11:33:31.783 37 ERROR keystone.server.flask.application   File "/var/lib/kolla/venv/lib/python3.9/site-packages/keystone/identity/backends/sql.py", line 200, in get_user
2023-02-17 11:33:31.790400 2023-02-17 11:33:31.783 37 ERROR keystone.server.flask.application     self._get_user(session, user_id).to_dict())
2023-02-17 11:33:31.790419 2023-02-17 11:33:31.783 37 ERROR keystone.server.flask.application   File "/var/lib/kolla/venv/lib/python3.9/site-packages/keystone/identity/backends/sql.py", line 194, in _get_user
2023-02-17 11:33:31.790431 2023-02-17 11:33:31.783 37 ERROR keystone.server.flask.application     raise exception.UserNotFound(user_id=user_id)
2023-02-17 11:33:31.790440 2023-02-17 11:33:31.783 37 ERROR keystone.server.flask.application keystone.exception.UserNotFound: Could not find user: ironic.
2023-02-17 11:33:31.790450 2023-02-17 11:33:31.783 37 ERROR keystone.server.flask.application \x1b[00m
2023-02-17 11:33:32.549671 2023-02-17 11:33:32.539 38 ERROR keystone.server.flask.application [None req-024e606f-1811-4356-bd86-916d2ca622fa ea378d77e35945abb7effbd999872281 - - all default -] Could not find project: service.: keystone.exception.ProjectNotFound: Could not find project: service.
2023-02-17 11:33:32.549711 2023-02-17 11:33:32.539 38 ERROR keystone.server.flask.application Traceback (most recent call last):
2023-02-17 11:33:32.549722 2023-02-17 11:33:32.539 38 ERROR keystone.server.flask.application   File "/var/lib/kolla/venv/lib/python3.9/site-packages/flask/app.py", line 1820, in full_dispatch_request
2023-02-17 11:33:32.549732 2023-02-17 11:33:32.539 38 ERROR keystone.server.flask.application     rv = self.dispatch_request()
2023-02-17 11:33:32.549756 2023-02-17 11:33:32.539 38 ERROR keystone.server.flask.application   File "/var/lib/kolla/venv/lib/python3.9/site-packages/flask/app.py", line 1796, in dispatch_request
2023-02-17 11:33:32.549766 2023-02-17 11:33:32.539 38 ERROR keystone.server.flask.application     return self.ensure_sync(self.view_functions[rule.endpoint])(**view_args)
2023-02-17 11:33:32.549776 2023-02-17 11:33:32.539 38 ERROR keystone.server.flask.application   File "/var/lib/kolla/venv/lib/python3.9/site-packages/flask_restful/__init__.py", line 467, in wrapper
2023-02-17 11:33:32.549785 2023-02-17 11:33:32.539 38 ERROR keystone.server.flask.application     resp = resource(*args, **kwargs)
2023-02-17 11:33:32.549806 2023-02-17 11:33:32.539 38 ERROR keystone.server.flask.application   File "/var/lib/kolla/venv/lib/python3.9/site-packages/flask/views.py", line 107, in view
2023-02-17 11:33:32.549820 2023-02-17 11:33:32.539 38 ERROR keystone.server.flask.application     return current_app.ensure_sync(self.dispatch_request)(**kwargs)
2023-02-17 11:33:32.549830 2023-02-17 11:33:32.539 38 ERROR keystone.server.flask.application   File "/var/lib/kolla/venv/lib/python3.9/site-packages/flask_restful/__init__.py", line 582, in dispatch_request
2023-02-17 11:33:32.549840 2023-02-17 11:33:32.539 38 ERROR keystone.server.flask.application     resp = meth(*args, **kwargs)
2023-02-17 11:33:32.549849 2023-02-17 11:33:32.539 38 ERROR keystone.server.flask.application   File "/var/lib/kolla/venv/lib/python3.9/site-packages/keystone/api/projects.py", line 151, in get
2023-02-17 11:33:32.549888 2023-02-17 11:33:32.539 38 ERROR keystone.server.flask.application     return self._get_project(project_id)
2023-02-17 11:33:32.549898 2023-02-17 11:33:32.539 38 ERROR keystone.server.flask.application   File "/var/lib/kolla/venv/lib/python3.9/site-packages/keystone/api/projects.py", line 107, in _get_project
2023-02-17 11:33:32.549908 2023-02-17 11:33:32.539 38 ERROR keystone.server.flask.application     project = PROVIDERS.resource_api.get_project(project_id)
2023-02-17 11:33:32.549918 2023-02-17 11:33:32.539 38 ERROR keystone.server.flask.application   File "/var/lib/kolla/venv/lib/python3.9/site-packages/keystone/common/manager.py", line 115, in wrapped
2023-02-17 11:33:32.549927 2023-02-17 11:33:32.539 38 ERROR keystone.server.flask.application     __ret_val = __f(*args, **kwargs)
2023-02-17 11:33:32.549937 2023-02-17 11:33:32.539 38 ERROR keystone.server.flask.application   File "/var/lib/kolla/venv/lib/python3.9/site-packages/decorator.py", line 232, in fun
2023-02-17 11:33:32.549946 2023-02-17 11:33:32.539 38 ERROR keystone.server.flask.application     return caller(func, *(extras + args), **kw)
2023-02-17 11:33:32.549971 2023-02-17 11:33:32.539 38 ERROR keystone.server.flask.application   File "/var/lib/kolla/venv/lib/python3.9/site-packages/dogpile/cache/region.py", line 1577, in get_or_create_for_user_func
2023-02-17 11:33:32.549984 2023-02-17 11:33:32.539 38 ERROR keystone.server.flask.application     return self.get_or_create(
2023-02-17 11:33:32.549993 2023-02-17 11:33:32.539 38 ERROR keystone.server.flask.application   File "/var/lib/kolla/venv/lib/python3.9/site-packages/dogpile/cache/region.py", line 1042, in get_or_create
2023-02-17 11:33:32.550026 2023-02-17 11:33:32.539 38 ERROR keystone.server.flask.application     with Lock(
2023-02-17 11:33:32.550042 2023-02-17 11:33:32.539 38 ERROR keystone.server.flask.application   File "/var/lib/kolla/venv/lib/python3.9/site-packages/dogpile/lock.py", line 185, in __enter__
2023-02-17 11:33:32.550052 2023-02-17 11:33:32.539 38 ERROR keystone.server.flask.application     return self._enter()
2023-02-17 11:33:32.550061 2023-02-17 11:33:32.539 38 ERROR keystone.server.flask.application   File "/var/lib/kolla/venv/lib/python3.9/site-packages/dogpile/lock.py", line 94, in _enter
2023-02-17 11:33:32.550071 2023-02-17 11:33:32.539 38 ERROR keystone.server.flask.application     generated = self._enter_create(value, createdtime)
2023-02-17 11:33:32.550080 2023-02-17 11:33:32.539 38 ERROR keystone.server.flask.application   File "/var/lib/kolla/venv/lib/python3.9/site-packages/dogpile/lock.py", line 178, in _enter_create
2023-02-17 11:33:32.550090 2023-02-17 11:33:32.539 38 ERROR keystone.server.flask.application     return self.creator()
2023-02-17 11:33:32.550099 2023-02-17 11:33:32.539 38 ERROR keystone.server.flask.application   File "/var/lib/kolla/venv/lib/python3.9/site-packages/dogpile/cache/region.py", line 995, in gen_value
2023-02-17 11:33:32.550109 2023-02-17 11:33:32.539 38 ERROR keystone.server.flask.application     created_value = creator(
2023-02-17 11:33:32.550118 2023-02-17 11:33:32.539 38 ERROR keystone.server.flask.application   File "/var/lib/kolla/venv/lib/python3.9/site-packages/keystone/resource/core.py", line 903, in get_project
2023-02-17 11:33:32.550128 2023-02-17 11:33:32.539 38 ERROR keystone.server.flask.application     return self.driver.get_project(project_id)
2023-02-17 11:33:32.550137 2023-02-17 11:33:32.539 38 ERROR keystone.server.flask.application   File "/var/lib/kolla/venv/lib/python3.9/site-packages/keystone/resource/backends/sql.py", line 49, in get_project
2023-02-17 11:33:32.550147 2023-02-17 11:33:32.539 38 ERROR keystone.server.flask.application     return self._get_project(session, project_id).to_dict()
2023-02-17 11:33:32.550156 2023-02-17 11:33:32.539 38 ERROR keystone.server.flask.application   File "/var/lib/kolla/venv/lib/python3.9/site-packages/keystone/resource/backends/sql.py", line 44, in _get_project
2023-02-17 11:33:32.550165 2023-02-17 11:33:32.539 38 ERROR keystone.server.flask.application     raise exception.ProjectNotFound(project_id=project_id)
2023-02-17 11:33:32.550187 2023-02-17 11:33:32.539 38 ERROR keystone.server.flask.application keystone.exception.ProjectNotFound: Could not find project: service.
2023-02-17 11:33:32.550196 2023-02-17 11:33:32.539 38 ERROR keystone.server.flask.application \x1b[00m
2023-02-17 11:33:41.301473 2023-02-17 11:33:41.295 39 ERROR keystone.server.flask.application [None req-4fcdef2b-f8af-4e21-ac70-9d584187f562 ea378d77e35945abb7effbd999872281 - - all default -] Could not find role: admin.: keystone.exception.RoleNotFound: Could not find role: admin.
2023-02-17 11:33:41.301513 2023-02-17 11:33:41.295 39 ERROR keystone.server.flask.application Traceback (most recent call last):
2023-02-17 11:33:41.301524 2023-02-17 11:33:41.295 39 ERROR keystone.server.flask.application   File "/var/lib/kolla/venv/lib/python3.9/site-packages/flask/app.py", line 1820, in full_dispatch_request
2023-02-17 11:33:41.301535 2023-02-17 11:33:41.295 39 ERROR keystone.server.flask.application     rv = self.dispatch_request()
2023-02-17 11:33:41.301544 2023-02-17 11:33:41.295 39 ERROR keystone.server.flask.application   File "/var/lib/kolla/venv/lib/python3.9/site-packages/flask/app.py", line 1796, in dispatch_request
2023-02-17 11:33:41.301567 2023-02-17 11:33:41.295 39 ERROR keystone.server.flask.application     return self.ensure_sync(self.view_functions[rule.endpoint])(**view_args)
2023-02-17 11:33:41.301578 2023-02-17 11:33:41.295 39 ERROR keystone.server.flask.application   File "/var/lib/kolla/venv/lib/python3.9/site-packages/flask_restful/__init__.py", line 467, in wrapper
2023-02-17 11:33:41.301588 2023-02-17 11:33:41.295 39 ERROR keystone.server.flask.application     resp = resource(*args, **kwargs)
2023-02-17 11:33:41.301606 2023-02-17 11:33:41.295 39 ERROR keystone.server.flask.application   File "/var/lib/kolla/venv/lib/python3.9/site-packages/flask/views.py", line 107, in view
2023-02-17 11:33:41.301619 2023-02-17 11:33:41.295 39 ERROR keystone.server.flask.application     return current_app.ensure_sync(self.dispatch_request)(**kwargs)
2023-02-17 11:33:41.301628 2023-02-17 11:33:41.295 39 ERROR keystone.server.flask.application   File "/var/lib/kolla/venv/lib/python3.9/site-packages/flask_restful/__init__.py", line 582, in dispatch_request
2023-02-17 11:33:41.301638 2023-02-17 11:33:41.295 39 ERROR keystone.server.flask.application     resp = meth(*args, **kwargs)
2023-02-17 11:33:41.301647 2023-02-17 11:33:41.295 39 ERROR keystone.server.flask.application   File "/var/lib/kolla/venv/lib/python3.9/site-packages/keystone/api/roles.py", line 50, in get
2023-02-17 11:33:41.301656 2023-02-17 11:33:41.295 39 ERROR keystone.server.flask.application     return self._get_role(role_id)
2023-02-17 11:33:41.301665 2023-02-17 11:33:41.295 39 ERROR keystone.server.flask.application   File "/var/lib/kolla/venv/lib/python3.9/site-packages/keystone/api/roles.py", line 70, in _get_role
2023-02-17 11:33:41.301675 2023-02-17 11:33:41.295 39 ERROR keystone.server.flask.application     ENFORCER.enforce_call(action='identity:get_role')
2023-02-17 11:33:41.301690 2023-02-17 11:33:41.295 39 ERROR keystone.server.flask.application   File "/var/lib/kolla/venv/lib/python3.9/site-packages/keystone/common/rbac_enforcer/enforcer.py", line 402, in enforce_call
2023-02-17 11:33:41.301702 2023-02-17 11:33:41.295 39 ERROR keystone.server.flask.application     policy_dict.update(cls._extract_member_target_data(
2023-02-17 11:33:41.301718 2023-02-17 11:33:41.295 39 ERROR keystone.server.flask.application   File "/var/lib/kolla/venv/lib/python3.9/site-packages/keystone/common/rbac_enforcer/enforcer.py", line 234, in _extract_member_target_data
2023-02-17 11:33:41.301730 2023-02-17 11:33:41.295 39 ERROR keystone.server.flask.application     member_name: func(flask.request.view_args[key])
2023-02-17 11:33:41.301740 2023-02-17 11:33:41.295 39 ERROR keystone.server.flask.application   File "/var/lib/kolla/venv/lib/python3.9/site-packages/keystone/common/manager.py", line 115, in wrapped
2023-02-17 11:33:41.301749 2023-02-17 11:33:41.295 39 ERROR keystone.server.flask.application     __ret_val = __f(*args, **kwargs)
2023-02-17 11:33:41.301759 2023-02-17 11:33:41.295 39 ERROR keystone.server.flask.application   File "/var/lib/kolla/venv/lib/python3.9/site-packages/decorator.py", line 232, in fun
2023-02-17 11:33:41.301768 2023-02-17 11:33:41.295 39 ERROR keystone.server.flask.application     return caller(func, *(extras + args), **kw)
2023-02-17 11:33:41.301777 2023-02-17 11:33:41.295 39 ERROR keystone.server.flask.application   File "/var/lib/kolla/venv/lib/python3.9/site-packages/dogpile/cache/region.py", line 1577, in get_or_create_for_user_func
2023-02-17 11:33:41.301787 2023-02-17 11:33:41.295 39 ERROR keystone.server.flask.application     return self.get_or_create(
2023-02-17 11:33:41.301796 2023-02-17 11:33:41.295 39 ERROR keystone.server.flask.application   File "/var/lib/kolla/venv/lib/python3.9/site-packages/dogpile/cache/region.py", line 1042, in get_or_create
2023-02-17 11:33:41.301806 2023-02-17 11:33:41.295 39 ERROR keystone.server.flask.application     with Lock(
2023-02-17 11:33:41.301827 2023-02-17 11:33:41.295 39 ERROR keystone.server.flask.application   File "/var/lib/kolla/venv/lib/python3.9/site-packages/dogpile/lock.py", line 185, in __enter__
2023-02-17 11:33:41.301838 2023-02-17 11:33:41.295 39 ERROR keystone.server.flask.application     return self._enter()
2023-02-17 11:33:41.301847 2023-02-17 11:33:41.295 39 ERROR keystone.server.flask.application   File "/var/lib/kolla/venv/lib/python3.9/site-packages/dogpile/lock.py", line 94, in _enter
2023-02-17 11:33:41.301874 2023-02-17 11:33:41.295 39 ERROR keystone.server.flask.application     generated = self._enter_create(value, createdtime)
2023-02-17 11:33:41.301888 2023-02-17 11:33:41.295 39 ERROR keystone.server.flask.application   File "/var/lib/kolla/venv/lib/python3.9/site-packages/dogpile/lock.py", line 178, in _enter_create
2023-02-17 11:33:41.301897 2023-02-17 11:33:41.295 39 ERROR keystone.server.flask.application     return self.creator()
2023-02-17 11:33:41.301907 2023-02-17 11:33:41.295 39 ERROR keystone.server.flask.application   File "/var/lib/kolla/venv/lib/python3.9/site-packages/dogpile/cache/region.py", line 995, in gen_value
2023-02-17 11:33:41.301916 2023-02-17 11:33:41.295 39 ERROR keystone.server.flask.application     created_value = creator(
2023-02-17 11:33:41.301925 2023-02-17 11:33:41.295 39 ERROR keystone.server.flask.application   File "/var/lib/kolla/venv/lib/python3.9/site-packages/keystone/assignment/core.py", line 1276, in get_role
2023-02-17 11:33:41.301935 2023-02-17 11:33:41.295 39 ERROR keystone.server.flask.application     return self.driver.get_role(role_id)
2023-02-17 11:33:41.301944 2023-02-17 11:33:41.295 39 ERROR keystone.server.flask.application   File "/var/lib/kolla/venv/lib/python3.9/site-packages/keystone/assignment/role_backends/sql.py", line 70, in get_role
2023-02-17 11:33:41.301953 2023-02-17 11:33:41.295 39 ERROR keystone.server.flask.application     return self._get_role(session, role_id).to_dict()
2023-02-17 11:33:41.301962 2023-02-17 11:33:41.295 39 ERROR keystone.server.flask.application   File "/var/lib/kolla/venv/lib/python3.9/site-packages/keystone/assignment/role_backends/sql.py", line 65, in _get_role
2023-02-17 11:33:41.301972 2023-02-17 11:33:41.295 39 ERROR keystone.server.flask.application     raise exception.RoleNotFound(role_id=role_id)
2023-02-17 11:33:41.301981 2023-02-17 11:33:41.295 39 ERROR keystone.server.flask.application keystone.exception.RoleNotFound: Could not find role: admin.
2023-02-17 11:33:41.301990 2023-02-17 11:33:41.295 39 ERROR keystone.server.flask.application \x1b[00m
2023-02-17 11:33:42.445916 2023-02-17 11:33:42.439 39 ERROR keystone.server.flask.application [None req-8a35173f-8f9c-4c6c-a025-6ed011ccd239 ea378d77e35945abb7effbd999872281 - - all default -] Could not find user: ironic-inspector.: keystone.exception.UserNotFound: Could not find user: ironic-inspector.
2023-02-17 11:33:42.445966 2023-02-17 11:33:42.439 39 ERROR keystone.server.flask.application Traceback (most recent call last):
2023-02-17 11:33:42.445979 2023-02-17 11:33:42.439 39 ERROR keystone.server.flask.application   File "/var/lib/kolla/venv/lib/python3.9/site-packages/flask/app.py", line 1820, in full_dispatch_request
2023-02-17 11:33:42.445990 2023-02-17 11:33:42.439 39 ERROR keystone.server.flask.application     rv = self.dispatch_request()
2023-02-17 11:33:42.446026 2023-02-17 11:33:42.439 39 ERROR keystone.server.flask.application   File "/var/lib/kolla/venv/lib/python3.9/site-packages/flask/app.py", line 1796, in dispatch_request
2023-02-17 11:33:42.446064 2023-02-17 11:33:42.439 39 ERROR keystone.server.flask.application     return self.ensure_sync(self.view_functions[rule.endpoint])(**view_args)
2023-02-17 11:33:42.446075 2023-02-17 11:33:42.439 39 ERROR keystone.server.flask.application   File "/var/lib/kolla/venv/lib/python3.9/site-packages/flask_restful/__init__.py", line 467, in wrapper
2023-02-17 11:33:42.446086 2023-02-17 11:33:42.439 39 ERROR keystone.server.flask.application     resp = resource(*args, **kwargs)
2023-02-17 11:33:42.446097 2023-02-17 11:33:42.439 39 ERROR keystone.server.flask.application   File "/var/lib/kolla/venv/lib/python3.9/site-packages/flask/views.py", line 107, in view
2023-02-17 11:33:42.446157 2023-02-17 11:33:42.439 39 ERROR keystone.server.flask.application     return current_app.ensure_sync(self.dispatch_request)(**kwargs)
2023-02-17 11:33:42.446169 2023-02-17 11:33:42.439 39 ERROR keystone.server.flask.application   File "/var/lib/kolla/venv/lib/python3.9/site-packages/flask_restful/__init__.py", line 582, in dispatch_request
2023-02-17 11:33:42.446180 2023-02-17 11:33:42.439 39 ERROR keystone.server.flask.application     resp = meth(*args, **kwargs)
2023-02-17 11:33:42.446190 2023-02-17 11:33:42.439 39 ERROR keystone.server.flask.application   File "/var/lib/kolla/venv/lib/python3.9/site-packages/keystone/api/users.py", line 182, in get
2023-02-17 11:33:42.446201 2023-02-17 11:33:42.439 39 ERROR keystone.server.flask.application     return self._get_user(user_id)
2023-02-17 11:33:42.446211 2023-02-17 11:33:42.439 39 ERROR keystone.server.flask.application   File "/var/lib/kolla/venv/lib/python3.9/site-packages/keystone/api/users.py", line 194, in _get_user
2023-02-17 11:33:42.446222 2023-02-17 11:33:42.439 39 ERROR keystone.server.flask.application     ref = PROVIDERS.identity_api.get_user(user_id)
2023-02-17 11:33:42.446233 2023-02-17 11:33:42.439 39 ERROR keystone.server.flask.application   File "/var/lib/kolla/venv/lib/python3.9/site-packages/keystone/common/manager.py", line 115, in wrapped
2023-02-17 11:33:42.446243 2023-02-17 11:33:42.439 39 ERROR keystone.server.flask.application     __ret_val = __f(*args, **kwargs)
2023-02-17 11:33:42.446253 2023-02-17 11:33:42.439 39 ERROR keystone.server.flask.application   File "/var/lib/kolla/venv/lib/python3.9/site-packages/keystone/identity/core.py", line 414, in wrapper
2023-02-17 11:33:42.446264 2023-02-17 11:33:42.439 39 ERROR keystone.server.flask.application     return f(self, *args, **kwargs)
2023-02-17 11:33:42.446274 2023-02-17 11:33:42.439 39 ERROR keystone.server.flask.application   File "/var/lib/kolla/venv/lib/python3.9/site-packages/keystone/identity/core.py", line 424, in wrapper
2023-02-17 11:33:42.446284 2023-02-17 11:33:42.439 39 ERROR keystone.server.flask.application     return f(self, *args, **kwargs)
2023-02-17 11:33:42.446295 2023-02-17 11:33:42.439 39 ERROR keystone.server.flask.application   File "/var/lib/kolla/venv/lib/python3.9/site-packages/decorator.py", line 232, in fun
2023-02-17 11:33:42.446305 2023-02-17 11:33:42.439 39 ERROR keystone.server.flask.application     return caller(func, *(extras + args), **kw)
2023-02-17 11:33:42.446316 2023-02-17 11:33:42.439 39 ERROR keystone.server.flask.application   File "/var/lib/kolla/venv/lib/python3.9/site-packages/dogpile/cache/region.py", line 1577, in get_or_create_for_user_func
2023-02-17 11:33:42.446327 2023-02-17 11:33:42.439 39 ERROR keystone.server.flask.application     return self.get_or_create(
2023-02-17 11:33:42.446337 2023-02-17 11:33:42.439 39 ERROR keystone.server.flask.application   File "/var/lib/kolla/venv/lib/python3.9/site-packages/dogpile/cache/region.py", line 1042, in get_or_create
2023-02-17 11:33:42.446348 2023-02-17 11:33:42.439 39 ERROR keystone.server.flask.application     with Lock(
2023-02-17 11:33:42.446358 2023-02-17 11:33:42.439 39 ERROR keystone.server.flask.application   File "/var/lib/kolla/venv/lib/python3.9/site-packages/dogpile/lock.py", line 185, in __enter__
2023-02-17 11:33:42.446369 2023-02-17 11:33:42.439 39 ERROR keystone.server.flask.application     return self._enter()
2023-02-17 11:33:42.446379 2023-02-17 11:33:42.439 39 ERROR keystone.server.flask.application   File "/var/lib/kolla/venv/lib/python3.9/site-packages/dogpile/lock.py", line 94, in _enter
2023-02-17 11:33:42.446389 2023-02-17 11:33:42.439 39 ERROR keystone.server.flask.application     generated = self._enter_create(value, createdtime)
2023-02-17 11:33:42.446400 2023-02-17 11:33:42.439 39 ERROR keystone.server.flask.application   File "/var/lib/kolla/venv/lib/python3.9/site-packages/dogpile/lock.py", line 178, in _enter_create
2023-02-17 11:33:42.446422 2023-02-17 11:33:42.439 39 ERROR keystone.server.flask.application     return self.creator()
2023-02-17 11:33:42.446434 2023-02-17 11:33:42.439 39 ERROR keystone.server.flask.application   File "/var/lib/kolla/venv/lib/python3.9/site-packages/dogpile/cache/region.py", line 995, in gen_value
2023-02-17 11:33:42.446445 2023-02-17 11:33:42.439 39 ERROR keystone.server.flask.application     created_value = creator(
2023-02-17 11:33:42.446455 2023-02-17 11:33:42.439 39 ERROR keystone.server.flask.application   File "/var/lib/kolla/venv/lib/python3.9/site-packages/keystone/identity/core.py", line 1011, in get_user
2023-02-17 11:33:42.446466 2023-02-17 11:33:42.439 39 ERROR keystone.server.flask.application     ref = driver.get_user(entity_id)
2023-02-17 11:33:42.446476 2023-02-17 11:33:42.439 39 ERROR keystone.server.flask.application   File "/var/lib/kolla/venv/lib/python3.9/site-packages/keystone/identity/backends/sql.py", line 200, in get_user
2023-02-17 11:33:42.446487 2023-02-17 11:33:42.439 39 ERROR keystone.server.flask.application     self._get_user(session, user_id).to_dict())
2023-02-17 11:33:42.446497 2023-02-17 11:33:42.439 39 ERROR keystone.server.flask.application   File "/var/lib/kolla/venv/lib/python3.9/site-packages/keystone/identity/backends/sql.py", line 194, in _get_user
2023-02-17 11:33:42.446508 2023-02-17 11:33:42.439 39 ERROR keystone.server.flask.application     raise exception.UserNotFound(user_id=user_id)
2023-02-17 11:33:42.446518 2023-02-17 11:33:42.439 39 ERROR keystone.server.flask.application keystone.exception.UserNotFound: Could not find user: ironic-inspector.
2023-02-17 11:33:42.446529 2023-02-17 11:33:42.439 39 ERROR keystone.server.flask.application \x1b[00m
2023-02-17 11:33:43.458944 2023-02-17 11:33:43.455 37 ERROR keystone.server.flask.application [None req-3ba1f851-4d4a-48f7-86be-17876e7a07a8 ea378d77e35945abb7effbd999872281 - - all default -] Could not find project: service.: keystone.exception.ProjectNotFound: Could not find project: service.
2023-02-17 11:33:43.458987 2023-02-17 11:33:43.455 37 ERROR keystone.server.flask.application Traceback (most recent call last):
2023-02-17 11:33:43.458998 2023-02-17 11:33:43.455 37 ERROR keystone.server.flask.application   File "/var/lib/kolla/venv/lib/python3.9/site-packages/flask/app.py", line 1820, in full_dispatch_request
2023-02-17 11:33:43.459053 2023-02-17 11:33:43.455 37 ERROR keystone.server.flask.application     rv = self.dispatch_request()
2023-02-17 11:33:43.459064 2023-02-17 11:33:43.455 37 ERROR keystone.server.flask.application   File "/var/lib/kolla/venv/lib/python3.9/site-packages/flask/app.py", line 1796, in dispatch_request
2023-02-17 11:33:43.459074 2023-02-17 11:33:43.455 37 ERROR keystone.server.flask.application     return self.ensure_sync(self.view_functions[rule.endpoint])(**view_args)
2023-02-17 11:33:43.459084 2023-02-17 11:33:43.455 37 ERROR keystone.server.flask.application   File "/var/lib/kolla/venv/lib/python3.9/site-packages/flask_restful/__init__.py", line 467, in wrapper
2023-02-17 11:33:43.459093 2023-02-17 11:33:43.455 37 ERROR keystone.server.flask.application     resp = resource(*args, **kwargs)
2023-02-17 11:33:43.459103 2023-02-17 11:33:43.455 37 ERROR keystone.server.flask.application   File "/var/lib/kolla/venv/lib/python3.9/site-packages/flask/views.py", line 107, in view
2023-02-17 11:33:43.459113 2023-02-17 11:33:43.455 37 ERROR keystone.server.flask.application     return current_app.ensure_sync(self.dispatch_request)(**kwargs)
2023-02-17 11:33:43.459122 2023-02-17 11:33:43.455 37 ERROR keystone.server.flask.application   File "/var/lib/kolla/venv/lib/python3.9/site-packages/flask_restful/__init__.py", line 582, in dispatch_request
2023-02-17 11:33:43.459134 2023-02-17 11:33:43.455 37 ERROR keystone.server.flask.application     resp = meth(*args, **kwargs)
2023-02-17 11:33:43.459161 2023-02-17 11:33:43.455 37 ERROR keystone.server.flask.application   File "/var/lib/kolla/venv/lib/python3.9/site-packages/keystone/api/projects.py", line 151, in get
2023-02-17 11:33:43.459202 2023-02-17 11:33:43.455 37 ERROR keystone.server.flask.application     return self._get_project(project_id)
2023-02-17 11:33:43.459215 2023-02-17 11:33:43.455 37 ERROR keystone.server.flask.application   File "/var/lib/kolla/venv/lib/python3.9/site-packages/keystone/api/projects.py", line 107, in _get_project
2023-02-17 11:33:43.459225 2023-02-17 11:33:43.455 37 ERROR keystone.server.flask.application     project = PROVIDERS.resource_api.get_project(project_id)
2023-02-17 11:33:43.459234 2023-02-17 11:33:43.455 37 ERROR keystone.server.flask.application   File "/var/lib/kolla/venv/lib/python3.9/site-packages/keystone/common/manager.py", line 115, in wrapped
2023-02-17 11:33:43.459244 2023-02-17 11:33:43.455 37 ERROR keystone.server.flask.application     __ret_val = __f(*args, **kwargs)
2023-02-17 11:33:43.459253 2023-02-17 11:33:43.455 37 ERROR keystone.server.flask.application   File "/var/lib/kolla/venv/lib/python3.9/site-packages/decorator.py", line 232, in fun
2023-02-17 11:33:43.459262 2023-02-17 11:33:43.455 37 ERROR keystone.server.flask.application     return caller(func, *(extras + args), **kw)
2023-02-17 11:33:43.459272 2023-02-17 11:33:43.455 37 ERROR keystone.server.flask.application   File "/var/lib/kolla/venv/lib/python3.9/site-packages/dogpile/cache/region.py", line 1577, in get_or_create_for_user_func
2023-02-17 11:33:43.459281 2023-02-17 11:33:43.455 37 ERROR keystone.server.flask.application     return self.get_or_create(
2023-02-17 11:33:43.459291 2023-02-17 11:33:43.455 37 ERROR keystone.server.flask.application   File "/var/lib/kolla/venv/lib/python3.9/site-packages/dogpile/cache/region.py", line 1042, in get_or_create
2023-02-17 11:33:43.459301 2023-02-17 11:33:43.455 37 ERROR keystone.server.flask.application     with Lock(
2023-02-17 11:33:43.459310 2023-02-17 11:33:43.455 37 ERROR keystone.server.flask.application   File "/var/lib/kolla/venv/lib/python3.9/site-packages/dogpile/lock.py", line 185, in __enter__
2023-02-17 11:33:43.459319 2023-02-17 11:33:43.455 37 ERROR keystone.server.flask.application     return self._enter()
2023-02-17 11:33:43.459328 2023-02-17 11:33:43.455 37 ERROR keystone.server.flask.application   File "/var/lib/kolla/venv/lib/python3.9/site-packages/dogpile/lock.py", line 94, in _enter
2023-02-17 11:33:43.459338 2023-02-17 11:33:43.455 37 ERROR keystone.server.flask.application     generated = self._enter_create(value, createdtime)
2023-02-17 11:33:43.459347 2023-02-17 11:33:43.455 37 ERROR keystone.server.flask.application   File "/var/lib/kolla/venv/lib/python3.9/site-packages/dogpile/lock.py", line 178, in _enter_create
2023-02-17 11:33:43.459356 2023-02-17 11:33:43.455 37 ERROR keystone.server.flask.application     return self.creator()
2023-02-17 11:33:43.459365 2023-02-17 11:33:43.455 37 ERROR keystone.server.flask.application   File "/var/lib/kolla/venv/lib/python3.9/site-packages/dogpile/cache/region.py", line 995, in gen_value
2023-02-17 11:33:43.459375 2023-02-17 11:33:43.455 37 ERROR keystone.server.flask.application     created_value = creator(
2023-02-17 11:33:43.459384 2023-02-17 11:33:43.455 37 ERROR keystone.server.flask.application   File "/var/lib/kolla/venv/lib/python3.9/site-packages/keystone/resource/core.py", line 903, in get_project
2023-02-17 11:33:43.459393 2023-02-17 11:33:43.455 37 ERROR keystone.server.flask.application     return self.driver.get_project(project_id)
2023-02-17 11:33:43.459402 2023-02-17 11:33:43.455 37 ERROR keystone.server.flask.application   File "/var/lib/kolla/venv/lib/python3.9/site-packages/keystone/resource/backends/sql.py", line 49, in get_project
2023-02-17 11:33:43.459412 2023-02-17 11:33:43.455 37 ERROR keystone.server.flask.application     return self._get_project(session, project_id).to_dict()
2023-02-17 11:33:43.459421 2023-02-17 11:33:43.455 37 ERROR keystone.server.flask.application   File "/var/lib/kolla/venv/lib/python3.9/site-packages/keystone/resource/backends/sql.py", line 44, in _get_project
2023-02-17 11:33:43.459431 2023-02-17 11:33:43.455 37 ERROR keystone.server.flask.application     raise exception.ProjectNotFound(project_id=project_id)
2023-02-17 11:33:43.459459 2023-02-17 11:33:43.455 37 ERROR keystone.server.flask.application keystone.exception.ProjectNotFound: Could not find project: service.
2023-02-17 11:33:43.459472 2023-02-17 11:33:43.455 37 ERROR keystone.server.flask.application \x1b[00m
2023-02-17 11:36:23.845528 2023-02-17 11:36:23.840 38 ERROR keystone.server.flask.application [None req-c179fb7f-4dc9-48df-a703-462cd1fef8b2 ea378d77e35945abb7effbd999872281 - - all default -] Could not find project: service.: keystone.exception.ProjectNotFound: Could not find project: service.
2023-02-17 11:36:23.845585 2023-02-17 11:36:23.840 38 ERROR keystone.server.flask.application Traceback (most recent call last):
2023-02-17 11:36:23.845598 2023-02-17 11:36:23.840 38 ERROR keystone.server.flask.application   File "/var/lib/kolla/venv/lib/python3.9/site-packages/flask/app.py", line 1820, in full_dispatch_request
2023-02-17 11:36:23.845608 2023-02-17 11:36:23.840 38 ERROR keystone.server.flask.application     rv = self.dispatch_request()
2023-02-17 11:36:23.845618 2023-02-17 11:36:23.840 38 ERROR keystone.server.flask.application   File "/var/lib/kolla/venv/lib/python3.9/site-packages/flask/app.py", line 1796, in dispatch_request
2023-02-17 11:36:23.845628 2023-02-17 11:36:23.840 38 ERROR keystone.server.flask.application     return self.ensure_sync(self.view_functions[rule.endpoint])(**view_args)
2023-02-17 11:36:23.845638 2023-02-17 11:36:23.840 38 ERROR keystone.server.flask.application   File "/var/lib/kolla/venv/lib/python3.9/site-packages/flask_restful/__init__.py", line 467, in wrapper
2023-02-17 11:36:23.845647 2023-02-17 11:36:23.840 38 ERROR keystone.server.flask.application     resp = resource(*args, **kwargs)
2023-02-17 11:36:23.845663 2023-02-17 11:36:23.840 38 ERROR keystone.server.flask.application   File "/var/lib/kolla/venv/lib/python3.9/site-packages/flask/views.py", line 107, in view
2023-02-17 11:36:23.845676 2023-02-17 11:36:23.840 38 ERROR keystone.server.flask.application     return current_app.ensure_sync(self.dispatch_request)(**kwargs)
2023-02-17 11:36:23.845686 2023-02-17 11:36:23.840 38 ERROR keystone.server.flask.application   File "/var/lib/kolla/venv/lib/python3.9/site-packages/flask_restful/__init__.py", line 582, in dispatch_request
2023-02-17 11:36:23.845695 2023-02-17 11:36:23.840 38 ERROR keystone.server.flask.application     resp = meth(*args, **kwargs)
2023-02-17 11:36:23.845705 2023-02-17 11:36:23.840 38 ERROR keystone.server.flask.application   File "/var/lib/kolla/venv/lib/python3.9/site-packages/keystone/api/projects.py", line 151, in get
2023-02-17 11:36:23.845714 2023-02-17 11:36:23.840 38 ERROR keystone.server.flask.application     return self._get_project(project_id)
2023-02-17 11:36:23.845724 2023-02-17 11:36:23.840 38 ERROR keystone.server.flask.application   File "/var/lib/kolla/venv/lib/python3.9/site-packages/keystone/api/projects.py", line 107, in _get_project
2023-02-17 11:36:23.845733 2023-02-17 11:36:23.840 38 ERROR keystone.server.flask.application     project = PROVIDERS.resource_api.get_project(project_id)
2023-02-17 11:36:23.845743 2023-02-17 11:36:23.840 38 ERROR keystone.server.flask.application   File "/var/lib/kolla/venv/lib/python3.9/site-packages/keystone/common/manager.py", line 115, in wrapped
2023-02-17 11:36:23.845752 2023-02-17 11:36:23.840 38 ERROR keystone.server.flask.application     __ret_val = __f(*args, **kwargs)
2023-02-17 11:36:23.845762 2023-02-17 11:36:23.840 38 ERROR keystone.server.flask.application   File "/var/lib/kolla/venv/lib/python3.9/site-packages/decorator.py", line 232, in fun
2023-02-17 11:36:23.845771 2023-02-17 11:36:23.840 38 ERROR keystone.server.flask.application     return caller(func, *(extras + args), **kw)
2023-02-17 11:36:23.845781 2023-02-17 11:36:23.840 38 ERROR keystone.server.flask.application   File "/var/lib/kolla/venv/lib/python3.9/site-packages/dogpile/cache/region.py", line 1577, in get_or_create_for_user_func
2023-02-17 11:36:23.845791 2023-02-17 11:36:23.840 38 ERROR keystone.server.flask.application     return self.get_or_create(
2023-02-17 11:36:23.845819 2023-02-17 11:36:23.840 38 ERROR keystone.server.flask.application   File "/var/lib/kolla/venv/lib/python3.9/site-packages/dogpile/cache/region.py", line 1042, in get_or_create
2023-02-17 11:36:23.845859 2023-02-17 11:36:23.840 38 ERROR keystone.server.flask.application     with Lock(
2023-02-17 11:36:23.845878 2023-02-17 11:36:23.840 38 ERROR keystone.server.flask.application   File "/var/lib/kolla/venv/lib/python3.9/site-packages/dogpile/lock.py", line 185, in __enter__
2023-02-17 11:36:23.845888 2023-02-17 11:36:23.840 38 ERROR keystone.server.flask.application     return self._enter()
2023-02-17 11:36:23.845897 2023-02-17 11:36:23.840 38 ERROR keystone.server.flask.application   File "/var/lib/kolla/venv/lib/python3.9/site-packages/dogpile/lock.py", line 94, in _enter
2023-02-17 11:36:23.845907 2023-02-17 11:36:23.840 38 ERROR keystone.server.flask.application     generated = self._enter_create(value, createdtime)
2023-02-17 11:36:23.845916 2023-02-17 11:36:23.840 38 ERROR keystone.server.flask.application   File "/var/lib/kolla/venv/lib/python3.9/site-packages/dogpile/lock.py", line 178, in _enter_create
2023-02-17 11:36:23.845926 2023-02-17 11:36:23.840 38 ERROR keystone.server.flask.application     return self.creator()
2023-02-17 11:36:23.845935 2023-02-17 11:36:23.840 38 ERROR keystone.server.flask.application   File "/var/lib/kolla/venv/lib/python3.9/site-packages/dogpile/cache/region.py", line 995, in gen_value
2023-02-17 11:36:23.845944 2023-02-17 11:36:23.840 38 ERROR keystone.server.flask.application     created_value = creator(
2023-02-17 11:36:23.845954 2023-02-17 11:36:23.840 38 ERROR keystone.server.flask.application   File "/var/lib/kolla/venv/lib/python3.9/site-packages/keystone/resource/core.py", line 903, in get_project
2023-02-17 11:36:23.845963 2023-02-17 11:36:23.840 38 ERROR keystone.server.flask.application     return self.driver.get_project(project_id)
2023-02-17 11:36:23.845972 2023-02-17 11:36:23.840 38 ERROR keystone.server.flask.application   File "/var/lib/kolla/venv/lib/python3.9/site-packages/keystone/resource/backends/sql.py", line 49, in get_project
2023-02-17 11:36:23.845982 2023-02-17 11:36:23.840 38 ERROR keystone.server.flask.application     return self._get_project(session, project_id).to_dict()
2023-02-17 11:36:23.845991 2023-02-17 11:36:23.840 38 ERROR keystone.server.flask.application   File "/var/lib/kolla/venv/lib/python3.9/site-packages/keystone/resource/backends/sql.py", line 44, in _get_project
2023-02-17 11:36:23.846025 2023-02-17 11:36:23.840 38 ERROR keystone.server.flask.application     raise exception.ProjectNotFound(project_id=project_id)
2023-02-17 11:36:23.846042 2023-02-17 11:36:23.840 38 ERROR keystone.server.flask.application keystone.exception.ProjectNotFound: Could not find project: service.
2023-02-17 11:36:23.846052 2023-02-17 11:36:23.840 38 ERROR keystone.server.flask.application \x1b[00m
2023-02-17 11:36:37.974675 2023-02-17 11:36:37.969 39 ERROR keystone.server.flask.application [None req-7b8dbb07-96b1-4d0d-b667-9962952525ea ea378d77e35945abb7effbd999872281 - - all default -] Could not find role: admin.: keystone.exception.RoleNotFound: Could not find role: admin.
2023-02-17 11:36:37.974750 2023-02-17 11:36:37.969 39 ERROR keystone.server.flask.application Traceback (most recent call last):
2023-02-17 11:36:37.974762 2023-02-17 11:36:37.969 39 ERROR keystone.server.flask.application   File "/var/lib/kolla/venv/lib/python3.9/site-packages/flask/app.py", line 1820, in full_dispatch_request
2023-02-17 11:36:37.974772 2023-02-17 11:36:37.969 39 ERROR keystone.server.flask.application     rv = self.dispatch_request()
2023-02-17 11:36:37.974781 2023-02-17 11:36:37.969 39 ERROR keystone.server.flask.application   File "/var/lib/kolla/venv/lib/python3.9/site-packages/flask/app.py", line 1796, in dispatch_request
2023-02-17 11:36:37.974791 2023-02-17 11:36:37.969 39 ERROR keystone.server.flask.application     return self.ensure_sync(self.view_functions[rule.endpoint])(**view_args)
2023-02-17 11:36:37.974801 2023-02-17 11:36:37.969 39 ERROR keystone.server.flask.application   File "/var/lib/kolla/venv/lib/python3.9/site-packages/flask_restful/__init__.py", line 467, in wrapper
2023-02-17 11:36:37.974869 2023-02-17 11:36:37.969 39 ERROR keystone.server.flask.application     resp = resource(*args, **kwargs)
2023-02-17 11:36:37.974891 2023-02-17 11:36:37.969 39 ERROR keystone.server.flask.application   File "/var/lib/kolla/venv/lib/python3.9/site-packages/flask/views.py", line 107, in view
2023-02-17 11:36:37.974904 2023-02-17 11:36:37.969 39 ERROR keystone.server.flask.application     return current_app.ensure_sync(self.dispatch_request)(**kwargs)
2023-02-17 11:36:37.974913 2023-02-17 11:36:37.969 39 ERROR keystone.server.flask.application   File "/var/lib/kolla/venv/lib/python3.9/site-packages/flask_restful/__init__.py", line 582, in dispatch_request
2023-02-17 11:36:37.974923 2023-02-17 11:36:37.969 39 ERROR keystone.server.flask.application     resp = meth(*args, **kwargs)
2023-02-17 11:36:37.974932 2023-02-17 11:36:37.969 39 ERROR keystone.server.flask.application   File "/var/lib/kolla/venv/lib/python3.9/site-packages/keystone/api/roles.py", line 50, in get
2023-02-17 11:36:37.974941 2023-02-17 11:36:37.969 39 ERROR keystone.server.flask.application     return self._get_role(role_id)
2023-02-17 11:36:37.974950 2023-02-17 11:36:37.969 39 ERROR keystone.server.flask.application   File "/var/lib/kolla/venv/lib/python3.9/site-packages/keystone/api/roles.py", line 70, in _get_role
2023-02-17 11:36:37.974960 2023-02-17 11:36:37.969 39 ERROR keystone.server.flask.application     ENFORCER.enforce_call(action='identity:get_role')
2023-02-17 11:36:37.974975 2023-02-17 11:36:37.969 39 ERROR keystone.server.flask.application   File "/var/lib/kolla/venv/lib/python3.9/site-packages/keystone/common/rbac_enforcer/enforcer.py", line 402, in enforce_call
2023-02-17 11:36:37.974987 2023-02-17 11:36:37.969 39 ERROR keystone.server.flask.application     policy_dict.update(cls._extract_member_target_data(
2023-02-17 11:36:37.975001 2023-02-17 11:36:37.969 39 ERROR keystone.server.flask.application   File "/var/lib/kolla/venv/lib/python3.9/site-packages/keystone/common/rbac_enforcer/enforcer.py", line 234, in _extract_member_target_data
2023-02-17 11:36:37.975062 2023-02-17 11:36:37.969 39 ERROR keystone.server.flask.application     member_name: func(flask.request.view_args[key])
2023-02-17 11:36:37.975080 2023-02-17 11:36:37.969 39 ERROR keystone.server.flask.application   File "/var/lib/kolla/venv/lib/python3.9/site-packages/keystone/common/manager.py", line 115, in wrapped
2023-02-17 11:36:37.975091 2023-02-17 11:36:37.969 39 ERROR keystone.server.flask.application     __ret_val = __f(*args, **kwargs)
2023-02-17 11:36:37.975100 2023-02-17 11:36:37.969 39 ERROR keystone.server.flask.application   File "/var/lib/kolla/venv/lib/python3.9/site-packages/decorator.py", line 232, in fun
2023-02-17 11:36:37.975110 2023-02-17 11:36:37.969 39 ERROR keystone.server.flask.application     return caller(func, *(extras + args), **kw)
2023-02-17 11:36:37.975119 2023-02-17 11:36:37.969 39 ERROR keystone.server.flask.application   File "/var/lib/kolla/venv/lib/python3.9/site-packages/dogpile/cache/region.py", line 1577, in get_or_create_for_user_func
2023-02-17 11:36:37.975128 2023-02-17 11:36:37.969 39 ERROR keystone.server.flask.application     return self.get_or_create(
2023-02-17 11:36:37.975137 2023-02-17 11:36:37.969 39 ERROR keystone.server.flask.application   File "/var/lib/kolla/venv/lib/python3.9/site-packages/dogpile/cache/region.py", line 1042, in get_or_create
2023-02-17 11:36:37.975174 2023-02-17 11:36:37.969 39 ERROR keystone.server.flask.application     with Lock(
2023-02-17 11:36:37.975183 2023-02-17 11:36:37.969 39 ERROR keystone.server.flask.application   File "/var/lib/kolla/venv/lib/python3.9/site-packages/dogpile/lock.py", line 185, in __enter__
2023-02-17 11:36:37.975193 2023-02-17 11:36:37.969 39 ERROR keystone.server.flask.application     return self._enter()
2023-02-17 11:36:37.975202 2023-02-17 11:36:37.969 39 ERROR keystone.server.flask.application   File "/var/lib/kolla/venv/lib/python3.9/site-packages/dogpile/lock.py", line 94, in _enter
2023-02-17 11:36:37.975229 2023-02-17 11:36:37.969 39 ERROR keystone.server.flask.application     generated = self._enter_create(value, createdtime)
2023-02-17 11:36:37.975240 2023-02-17 11:36:37.969 39 ERROR keystone.server.flask.application   File "/var/lib/kolla/venv/lib/python3.9/site-packages/dogpile/lock.py", line 178, in _enter_create
2023-02-17 11:36:37.975250 2023-02-17 11:36:37.969 39 ERROR keystone.server.flask.application     return self.creator()
2023-02-17 11:36:37.975259 2023-02-17 11:36:37.969 39 ERROR keystone.server.flask.application   File "/var/lib/kolla/venv/lib/python3.9/site-packages/dogpile/cache/region.py", line 995, in gen_value
2023-02-17 11:36:37.975269 2023-02-17 11:36:37.969 39 ERROR keystone.server.flask.application     created_value = creator(
2023-02-17 11:36:37.975278 2023-02-17 11:36:37.969 39 ERROR keystone.server.flask.application   File "/var/lib/kolla/venv/lib/python3.9/site-packages/keystone/assignment/core.py", line 1276, in get_role
2023-02-17 11:36:37.975287 2023-02-17 11:36:37.969 39 ERROR keystone.server.flask.application     return self.driver.get_role(role_id)
2023-02-17 11:36:37.975297 2023-02-17 11:36:37.969 39 ERROR keystone.server.flask.application   File "/var/lib/kolla/venv/lib/python3.9/site-packages/keystone/assignment/role_backends/sql.py", line 70, in get_role
2023-02-17 11:36:37.975307 2023-02-17 11:36:37.969 39 ERROR keystone.server.flask.application     return self._get_role(session, role_id).to_dict()
2023-02-17 11:36:37.975317 2023-02-17 11:36:37.969 39 ERROR keystone.server.flask.application   File "/var/lib/kolla/venv/lib/python3.9/site-packages/keystone/assignment/role_backends/sql.py", line 65, in _get_role
2023-02-17 11:36:37.975326 2023-02-17 11:36:37.969 39 ERROR keystone.server.flask.application     raise exception.RoleNotFound(role_id=role_id)
2023-02-17 11:36:37.975335 2023-02-17 11:36:37.969 39 ERROR keystone.server.flask.application keystone.exception.RoleNotFound: Could not find role: admin.
2023-02-17 11:36:37.975345 2023-02-17 11:36:37.969 39 ERROR keystone.server.flask.application \x1b[00m
2023-02-17 11:36:39.086580 2023-02-17 11:36:39.083 39 ERROR keystone.server.flask.application [None req-32e028f8-c394-4064-988b-77dcdb9867c4 ea378d77e35945abb7effbd999872281 - - all default -] Could not find user: neutron.: keystone.exception.UserNotFound: Could not find user: neutron.
2023-02-17 11:36:39.086623 2023-02-17 11:36:39.083 39 ERROR keystone.server.flask.application Traceback (most recent call last):
2023-02-17 11:36:39.086634 2023-02-17 11:36:39.083 39 ERROR keystone.server.flask.application   File "/var/lib/kolla/venv/lib/python3.9/site-packages/flask/app.py", line 1820, in full_dispatch_request
2023-02-17 11:36:39.086644 2023-02-17 11:36:39.083 39 ERROR keystone.server.flask.application     rv = self.dispatch_request()
2023-02-17 11:36:39.086653 2023-02-17 11:36:39.083 39 ERROR keystone.server.flask.application   File "/var/lib/kolla/venv/lib/python3.9/site-packages/flask/app.py", line 1796, in dispatch_request
2023-02-17 11:36:39.086663 2023-02-17 11:36:39.083 39 ERROR keystone.server.flask.application     return self.ensure_sync(self.view_functions[rule.endpoint])(**view_args)
2023-02-17 11:36:39.086673 2023-02-17 11:36:39.083 39 ERROR keystone.server.flask.application   File "/var/lib/kolla/venv/lib/python3.9/site-packages/flask_restful/__init__.py", line 467, in wrapper
2023-02-17 11:36:39.086682 2023-02-17 11:36:39.083 39 ERROR keystone.server.flask.application     resp = resource(*args, **kwargs)
2023-02-17 11:36:39.086692 2023-02-17 11:36:39.083 39 ERROR keystone.server.flask.application   File "/var/lib/kolla/venv/lib/python3.9/site-packages/flask/views.py", line 107, in view
2023-02-17 11:36:39.086701 2023-02-17 11:36:39.083 39 ERROR keystone.server.flask.application     return current_app.ensure_sync(self.dispatch_request)(**kwargs)
2023-02-17 11:36:39.086710 2023-02-17 11:36:39.083 39 ERROR keystone.server.flask.application   File "/var/lib/kolla/venv/lib/python3.9/site-packages/flask_restful/__init__.py", line 582, in dispatch_request
2023-02-17 11:36:39.086778 2023-02-17 11:36:39.083 39 ERROR keystone.server.flask.application     resp = meth(*args, **kwargs)
2023-02-17 11:36:39.086793 2023-02-17 11:36:39.083 39 ERROR keystone.server.flask.application   File "/var/lib/kolla/venv/lib/python3.9/site-packages/keystone/api/users.py", line 182, in get
2023-02-17 11:36:39.086803 2023-02-17 11:36:39.083 39 ERROR keystone.server.flask.application     return self._get_user(user_id)
2023-02-17 11:36:39.086812 2023-02-17 11:36:39.083 39 ERROR keystone.server.flask.application   File "/var/lib/kolla/venv/lib/python3.9/site-packages/keystone/api/users.py", line 194, in _get_user
2023-02-17 11:36:39.086833 2023-02-17 11:36:39.083 39 ERROR keystone.server.flask.application     ref = PROVIDERS.identity_api.get_user(user_id)
2023-02-17 11:36:39.086866 2023-02-17 11:36:39.083 39 ERROR keystone.server.flask.application   File "/var/lib/kolla/venv/lib/python3.9/site-packages/keystone/common/manager.py", line 115, in wrapped
2023-02-17 11:36:39.086876 2023-02-17 11:36:39.083 39 ERROR keystone.server.flask.application     __ret_val = __f(*args, **kwargs)
2023-02-17 11:36:39.086885 2023-02-17 11:36:39.083 39 ERROR keystone.server.flask.application   File "/var/lib/kolla/venv/lib/python3.9/site-packages/keystone/identity/core.py", line 414, in wrapper
2023-02-17 11:36:39.086895 2023-02-17 11:36:39.083 39 ERROR keystone.server.flask.application     return f(self, *args, **kwargs)
2023-02-17 11:36:39.086905 2023-02-17 11:36:39.083 39 ERROR keystone.server.flask.application   File "/var/lib/kolla/venv/lib/python3.9/site-packages/keystone/identity/core.py", line 424, in wrapper
2023-02-17 11:36:39.086915 2023-02-17 11:36:39.083 39 ERROR keystone.server.flask.application     return f(self, *args, **kwargs)
2023-02-17 11:36:39.086927 2023-02-17 11:36:39.083 39 ERROR keystone.server.flask.application   File "/var/lib/kolla/venv/lib/python3.9/site-packages/decorator.py", line 232, in fun
2023-02-17 11:36:39.086939 2023-02-17 11:36:39.083 39 ERROR keystone.server.flask.application     return caller(func, *(extras + args), **kw)
2023-02-17 11:36:39.086949 2023-02-17 11:36:39.083 39 ERROR keystone.server.flask.application   File "/var/lib/kolla/venv/lib/python3.9/site-packages/dogpile/cache/region.py", line 1577, in get_or_create_for_user_func
2023-02-17 11:36:39.086958 2023-02-17 11:36:39.083 39 ERROR keystone.server.flask.application     return self.get_or_create(
2023-02-17 11:36:39.086968 2023-02-17 11:36:39.083 39 ERROR keystone.server.flask.application   File "/var/lib/kolla/venv/lib/python3.9/site-packages/dogpile/cache/region.py", line 1042, in get_or_create
2023-02-17 11:36:39.086977 2023-02-17 11:36:39.083 39 ERROR keystone.server.flask.application     with Lock(
2023-02-17 11:36:39.086986 2023-02-17 11:36:39.083 39 ERROR keystone.server.flask.application   File "/var/lib/kolla/venv/lib/python3.9/site-packages/dogpile/lock.py", line 185, in __enter__
2023-02-17 11:36:39.086996 2023-02-17 11:36:39.083 39 ERROR keystone.server.flask.application     return self._enter()
2023-02-17 11:36:39.087031 2023-02-17 11:36:39.083 39 ERROR keystone.server.flask.application   File "/var/lib/kolla/venv/lib/python3.9/site-packages/dogpile/lock.py", line 94, in _enter
2023-02-17 11:36:39.087054 2023-02-17 11:36:39.083 39 ERROR keystone.server.flask.application     generated = self._enter_create(value, createdtime)
2023-02-17 11:36:39.087063 2023-02-17 11:36:39.083 39 ERROR keystone.server.flask.application   File "/var/lib/kolla/venv/lib/python3.9/site-packages/dogpile/lock.py", line 178, in _enter_create
2023-02-17 11:36:39.087073 2023-02-17 11:36:39.083 39 ERROR keystone.server.flask.application     return self.creator()
2023-02-17 11:36:39.087082 2023-02-17 11:36:39.083 39 ERROR keystone.server.flask.application   File "/var/lib/kolla/venv/lib/python3.9/site-packages/dogpile/cache/region.py", line 995, in gen_value
2023-02-17 11:36:39.087092 2023-02-17 11:36:39.083 39 ERROR keystone.server.flask.application     created_value = creator(
2023-02-17 11:36:39.087144 2023-02-17 11:36:39.083 39 ERROR keystone.server.flask.application   File "/var/lib/kolla/venv/lib/python3.9/site-packages/keystone/identity/core.py", line 1011, in get_user
2023-02-17 11:36:39.087156 2023-02-17 11:36:39.083 39 ERROR keystone.server.flask.application     ref = driver.get_user(entity_id)
2023-02-17 11:36:39.087165 2023-02-17 11:36:39.083 39 ERROR keystone.server.flask.application   File "/var/lib/kolla/venv/lib/python3.9/site-packages/keystone/identity/backends/sql.py", line 200, in get_user
2023-02-17 11:36:39.087175 2023-02-17 11:36:39.083 39 ERROR keystone.server.flask.application     self._get_user(session, user_id).to_dict())
2023-02-17 11:36:39.087185 2023-02-17 11:36:39.083 39 ERROR keystone.server.flask.application   File "/var/lib/kolla/venv/lib/python3.9/site-packages/keystone/identity/backends/sql.py", line 194, in _get_user
2023-02-17 11:36:39.087195 2023-02-17 11:36:39.083 39 ERROR keystone.server.flask.application     raise exception.UserNotFound(user_id=user_id)
2023-02-17 11:36:39.087204 2023-02-17 11:36:39.083 39 ERROR keystone.server.flask.application keystone.exception.UserNotFound: Could not find user: neutron.
2023-02-17 11:36:39.087213 2023-02-17 11:36:39.083 39 ERROR keystone.server.flask.application \x1b[00m
2023-02-17 11:36:39.944390 2023-02-17 11:36:39.939 37 ERROR keystone.server.flask.application [None req-aa6a0563-6cdf-41c3-9af5-1913871437bf ea378d77e35945abb7effbd999872281 - - all default -] Could not find project: service.: keystone.exception.ProjectNotFound: Could not find project: service.
2023-02-17 11:36:39.944434 2023-02-17 11:36:39.939 37 ERROR keystone.server.flask.application Traceback (most recent call last):
2023-02-17 11:36:39.944446 2023-02-17 11:36:39.939 37 ERROR keystone.server.flask.application   File "/var/lib/kolla/venv/lib/python3.9/site-packages/flask/app.py", line 1820, in full_dispatch_request
2023-02-17 11:36:39.944456 2023-02-17 11:36:39.939 37 ERROR keystone.server.flask.application     rv = self.dispatch_request()
2023-02-17 11:36:39.944465 2023-02-17 11:36:39.939 37 ERROR keystone.server.flask.application   File "/var/lib/kolla/venv/lib/python3.9/site-packages/flask/app.py", line 1796, in dispatch_request
2023-02-17 11:36:39.944476 2023-02-17 11:36:39.939 37 ERROR keystone.server.flask.application     return self.ensure_sync(self.view_functions[rule.endpoint])(**view_args)
2023-02-17 11:36:39.944485 2023-02-17 11:36:39.939 37 ERROR keystone.server.flask.application   File "/var/lib/kolla/venv/lib/python3.9/site-packages/flask_restful/__init__.py", line 467, in wrapper
2023-02-17 11:36:39.944495 2023-02-17 11:36:39.939 37 ERROR keystone.server.flask.application     resp = resource(*args, **kwargs)
2023-02-17 11:36:39.944504 2023-02-17 11:36:39.939 37 ERROR keystone.server.flask.application   File "/var/lib/kolla/venv/lib/python3.9/site-packages/flask/views.py", line 107, in view
2023-02-17 11:36:39.944514 2023-02-17 11:36:39.939 37 ERROR keystone.server.flask.application     return current_app.ensure_sync(self.dispatch_request)(**kwargs)
2023-02-17 11:36:39.944523 2023-02-17 11:36:39.939 37 ERROR keystone.server.flask.application   File "/var/lib/kolla/venv/lib/python3.9/site-packages/flask_restful/__init__.py", line 582, in dispatch_request
2023-02-17 11:36:39.944533 2023-02-17 11:36:39.939 37 ERROR keystone.server.flask.application     resp = meth(*args, **kwargs)
2023-02-17 11:36:39.944542 2023-02-17 11:36:39.939 37 ERROR keystone.server.flask.application   File "/var/lib/kolla/venv/lib/python3.9/site-packages/keystone/api/projects.py", line 151, in get
2023-02-17 11:36:39.944551 2023-02-17 11:36:39.939 37 ERROR keystone.server.flask.application     return self._get_project(project_id)
2023-02-17 11:36:39.944560 2023-02-17 11:36:39.939 37 ERROR keystone.server.flask.application   File "/var/lib/kolla/venv/lib/python3.9/site-packages/keystone/api/projects.py", line 107, in _get_project
2023-02-17 11:36:39.944570 2023-02-17 11:36:39.939 37 ERROR keystone.server.flask.application     project = PROVIDERS.resource_api.get_project(project_id)
2023-02-17 11:36:39.944630 2023-02-17 11:36:39.939 37 ERROR keystone.server.flask.application   File "/var/lib/kolla/venv/lib/python3.9/site-packages/keystone/common/manager.py", line 115, in wrapped
2023-02-17 11:36:39.944644 2023-02-17 11:36:39.939 37 ERROR keystone.server.flask.application     __ret_val = __f(*args, **kwargs)
2023-02-17 11:36:39.944654 2023-02-17 11:36:39.939 37 ERROR keystone.server.flask.application   File "/var/lib/kolla/venv/lib/python3.9/site-packages/decorator.py", line 232, in fun
2023-02-17 11:36:39.944663 2023-02-17 11:36:39.939 37 ERROR keystone.server.flask.application     return caller(func, *(extras + args), **kw)
2023-02-17 11:36:39.944673 2023-02-17 11:36:39.939 37 ERROR keystone.server.flask.application   File "/var/lib/kolla/venv/lib/python3.9/site-packages/dogpile/cache/region.py", line 1577, in get_or_create_for_user_func
2023-02-17 11:36:39.944683 2023-02-17 11:36:39.939 37 ERROR keystone.server.flask.application     return self.get_or_create(
2023-02-17 11:36:39.944692 2023-02-17 11:36:39.939 37 ERROR keystone.server.flask.application   File "/var/lib/kolla/venv/lib/python3.9/site-packages/dogpile/cache/region.py", line 1042, in get_or_create
2023-02-17 11:36:39.944701 2023-02-17 11:36:39.939 37 ERROR keystone.server.flask.application     with Lock(
2023-02-17 11:36:39.944711 2023-02-17 11:36:39.939 37 ERROR keystone.server.flask.application   File "/var/lib/kolla/venv/lib/python3.9/site-packages/dogpile/lock.py", line 185, in __enter__
2023-02-17 11:36:39.944720 2023-02-17 11:36:39.939 37 ERROR keystone.server.flask.application     return self._enter()
2023-02-17 11:36:39.944729 2023-02-17 11:36:39.939 37 ERROR keystone.server.flask.application   File "/var/lib/kolla/venv/lib/python3.9/site-packages/dogpile/lock.py", line 94, in _enter
2023-02-17 11:36:39.944738 2023-02-17 11:36:39.939 37 ERROR keystone.server.flask.application     generated = self._enter_create(value, createdtime)
2023-02-17 11:36:39.944747 2023-02-17 11:36:39.939 37 ERROR keystone.server.flask.application   File "/var/lib/kolla/venv/lib/python3.9/site-packages/dogpile/lock.py", line 178, in _enter_create
2023-02-17 11:36:39.944757 2023-02-17 11:36:39.939 37 ERROR keystone.server.flask.application     return self.creator()
2023-02-17 11:36:39.944766 2023-02-17 11:36:39.939 37 ERROR keystone.server.flask.application   File "/var/lib/kolla/venv/lib/python3.9/site-packages/dogpile/cache/region.py", line 995, in gen_value
2023-02-17 11:36:39.944775 2023-02-17 11:36:39.939 37 ERROR keystone.server.flask.application     created_value = creator(
2023-02-17 11:36:39.944784 2023-02-17 11:36:39.939 37 ERROR keystone.server.flask.application   File "/var/lib/kolla/venv/lib/python3.9/site-packages/keystone/resource/core.py", line 903, in get_project
2023-02-17 11:36:39.944794 2023-02-17 11:36:39.939 37 ERROR keystone.server.flask.application     return self.driver.get_project(project_id)
2023-02-17 11:36:39.944803 2023-02-17 11:36:39.939 37 ERROR keystone.server.flask.application   File "/var/lib/kolla/venv/lib/python3.9/site-packages/keystone/resource/backends/sql.py", line 49, in get_project
2023-02-17 11:36:39.944813 2023-02-17 11:36:39.939 37 ERROR keystone.server.flask.application     return self._get_project(session, project_id).to_dict()
2023-02-17 11:36:39.944822 2023-02-17 11:36:39.939 37 ERROR keystone.server.flask.application   File "/var/lib/kolla/venv/lib/python3.9/site-packages/keystone/resource/backends/sql.py", line 44, in _get_project
2023-02-17 11:36:39.944831 2023-02-17 11:36:39.939 37 ERROR keystone.server.flask.application     raise exception.ProjectNotFound(project_id=project_id)
2023-02-17 11:36:39.944861 2023-02-17 11:36:39.939 37 ERROR keystone.server.flask.application keystone.exception.ProjectNotFound: Could not find project: service.
2023-02-17 11:36:39.944872 2023-02-17 11:36:39.939 37 ERROR keystone.server.flask.application \x1b[00m
2023-02-17 13:02:09.920047 2023-02-17 13:02:09.918 37 WARNING py.warnings [None req-d5454376-d5d5-41c1-8ceb-2b46dcef04ee ea378d77e35945abb7effbd999872281 ba56c5a38b03424e8f9e5277c51867fb - - default default] /var/lib/kolla/venv/lib/python3.9/site-packages/oslo_policy/policy.py:1129: UserWarning: Policy "identity:list_domains": "role:reader and system_scope:all" failed scope check. The token used to make the request was project scoped but the policy requires ['system'] scope. This behavior may change in the future where using the intended scope is required
2023-02-17 13:02:09.920172   warnings.warn(msg)
2023-02-17 13:02:09.920187 \x1b[00m
2023-02-17 13:02:10.137205 2023-02-17 13:02:10.135 38 WARNING py.warnings [None req-562f26fc-6627-472a-b35c-265feee04f54 ea378d77e35945abb7effbd999872281 ba56c5a38b03424e8f9e5277c51867fb - - default default] /var/lib/kolla/venv/lib/python3.9/site-packages/oslo_policy/policy.py:1129: UserWarning: Policy "identity:create_project": "(role:admin and system_scope:all) or (role:admin and domain_id:%(target.project.domain_id)s)" failed scope check. The token used to make the request was project scoped but the policy requires ['system', 'domain'] scope. This behavior may change in the future where using the intended scope is required
2023-02-17 13:02:10.137288   warnings.warn(msg)
2023-02-17 13:02:10.137301 \x1b[00m
2023-02-17 13:02:10.406939 2023-02-17 13:02:10.405 39 WARNING py.warnings [None req-ed3ef85a-c12a-4d2e-8bb8-0d4a25181d34 ea378d77e35945abb7effbd999872281 ba56c5a38b03424e8f9e5277c51867fb - - default default] /var/lib/kolla/venv/lib/python3.9/site-packages/oslo_policy/policy.py:1129: UserWarning: Policy "identity:create_user": "(role:admin and system_scope:all) or (role:admin and token.domain.id:%(target.user.domain_id)s)" failed scope check. The token used to make the request was project scoped but the policy requires ['system', 'domain'] scope. This behavior may change in the future where using the intended scope is required
2023-02-17 13:02:10.406989   warnings.warn(msg)
2023-02-17 13:02:10.407060 \x1b[00m
2023-02-17 13:02:11.209525 2023-02-17 13:02:11.208 37 WARNING py.warnings [None req-38b0e713-7100-4be4-ad26-4e90dc517f51 ea378d77e35945abb7effbd999872281 ba56c5a38b03424e8f9e5277c51867fb - - default default] /var/lib/kolla/venv/lib/python3.9/site-packages/oslo_policy/policy.py:1129: UserWarning: Policy "identity:list_roles": "role:reader and system_scope:all" failed scope check. The token used to make the request was project scoped but the policy requires ['system'] scope. This behavior may change in the future where using the intended scope is required
2023-02-17 13:02:11.209601   warnings.warn(msg)
2023-02-17 13:02:11.209623 \x1b[00m
2023-02-17 13:02:11.523512 2023-02-17 13:02:11.522 38 WARNING py.warnings [None req-a7a3314a-dd3b-4ded-be3f-36890b56a08e ea378d77e35945abb7effbd999872281 ba56c5a38b03424e8f9e5277c51867fb - - default default] /var/lib/kolla/venv/lib/python3.9/site-packages/oslo_policy/policy.py:1129: UserWarning: Policy "identity:list_roles": "role:reader and system_scope:all" failed scope check. The token used to make the request was project scoped but the policy requires ['system'] scope. This behavior may change in the future where using the intended scope is required
2023-02-17 13:02:11.523575   warnings.warn(msg)
2023-02-17 13:02:11.523586 \x1b[00m
2023-02-17 13:02:11.804290 2023-02-17 13:02:11.803 39 WARNING py.warnings [None req-1860d63b-d75c-4603-ba28-105137c1b43c ea378d77e35945abb7effbd999872281 ba56c5a38b03424e8f9e5277c51867fb - - default default] /var/lib/kolla/venv/lib/python3.9/site-packages/oslo_policy/policy.py:1129: UserWarning: Policy "identity:create_grant": "(role:admin and system_scope:all) or ((role:admin and domain_id:%(target.user.domain_id)s and domain_id:%(target.project.domain_id)s) or (role:admin and domain_id:%(target.user.domain_id)s and domain_id:%(target.domain.id)s) or (role:admin and domain_id:%(target.group.domain_id)s and domain_id:%(target.project.domain_id)s) or (role:admin and domain_id:%(target.group.domain_id)s and domain_id:%(target.domain.id)s)) and (domain_id:%(target.role.domain_id)s or None:%(target.role.domain_id)s)" failed scope check. The token used to make the request was project scoped but the policy requires ['system', 'domain'] scope. This behavior may change in the future where using the intended scope is required
2023-02-17 13:02:11.804387   warnings.warn(msg)
2023-02-17 13:02:11.804411 \x1b[00m
2023-02-17 13:02:14.546921 2023-02-17 13:02:14.546 38 WARNING py.warnings [None req-9bd54f07-dcdc-4bdf-a13f-85a6001ace7c ea378d77e35945abb7effbd999872281 ba56c5a38b03424e8f9e5277c51867fb - - default default] /var/lib/kolla/venv/lib/python3.9/site-packages/oslo_policy/policy.py:1129: UserWarning: Policy "identity:create_grant": "(role:admin and system_scope:all) or ((role:admin and domain_id:%(target.user.domain_id)s and domain_id:%(target.project.domain_id)s) or (role:admin and domain_id:%(target.user.domain_id)s and domain_id:%(target.domain.id)s) or (role:admin and domain_id:%(target.group.domain_id)s and domain_id:%(target.project.domain_id)s) or (role:admin and domain_id:%(target.group.domain_id)s and domain_id:%(target.domain.id)s)) and (domain_id:%(target.role.domain_id)s or None:%(target.role.domain_id)s)" failed scope check. The token used to make the request was project scoped but the policy requires ['system', 'domain'] scope. This behavior may change in the future where using the intended scope is required
2023-02-17 13:02:14.546967   warnings.warn(msg)
2023-02-17 13:02:14.546978 \x1b[00m
2023-02-17 13:02:14.757964 2023-02-17 13:02:14.757 39 WARNING py.warnings [None req-1dc23555-c1a1-4632-845e-cf7f85c737a4 ea378d77e35945abb7effbd999872281 ba56c5a38b03424e8f9e5277c51867fb - - default default] /var/lib/kolla/venv/lib/python3.9/site-packages/oslo_policy/policy.py:1129: UserWarning: Policy "identity:list_roles": "role:reader and system_scope:all" failed scope check. The token used to make the request was project scoped but the policy requires ['system'] scope. This behavior may change in the future where using the intended scope is required
2023-02-17 13:02:14.758033   warnings.warn(msg)
2023-02-17 13:02:14.758048 \x1b[00m
2023-02-17 13:02:15.053311 2023-02-17 13:02:15.052 37 WARNING py.warnings [None req-d05870f0-f200-4689-9d97-40fc9c001aa1 ea378d77e35945abb7effbd999872281 ba56c5a38b03424e8f9e5277c51867fb - - default default] /var/lib/kolla/venv/lib/python3.9/site-packages/oslo_policy/policy.py:1129: UserWarning: Policy "identity:create_grant": "(role:admin and system_scope:all) or ((role:admin and domain_id:%(target.user.domain_id)s and domain_id:%(target.project.domain_id)s) or (role:admin and domain_id:%(target.user.domain_id)s and domain_id:%(target.domain.id)s) or (role:admin and domain_id:%(target.group.domain_id)s and domain_id:%(target.project.domain_id)s) or (role:admin and domain_id:%(target.group.domain_id)s and domain_id:%(target.domain.id)s)) and (domain_id:%(target.role.domain_id)s or None:%(target.role.domain_id)s)" failed scope check. The token used to make the request was project scoped but the policy requires ['system', 'domain'] scope. This behavior may change in the future where using the intended scope is required
2023-02-17 13:02:15.053358   warnings.warn(msg)
2023-02-17 13:02:15.053369 \x1b[00m
2023-02-17 13:02:17.252171 2023-02-17 13:02:17.251 38 WARNING py.warnings [None req-504c6d52-d28c-4c25-be83-1e9aac4107cc ea378d77e35945abb7effbd999872281 ba56c5a38b03424e8f9e5277c51867fb - - default default] /var/lib/kolla/venv/lib/python3.9/site-packages/oslo_policy/policy.py:1129: UserWarning: Policy "identity:create_system_grant_for_user": "role:admin and system_scope:all" failed scope check. The token used to make the request was project scoped but the policy requires ['system'] scope. This behavior may change in the future where using the intended scope is required
2023-02-17 13:02:17.252216   warnings.warn(msg)
2023-02-17 13:02:17.252227 \x1b[00m
