2023-03-15 13:23:29.926 24 INFO alembic.runtime.migration [-] Context impl MySQLImpl.
2023-03-15 13:23:29.929 24 INFO alembic.runtime.migration [-] Will assume non-transactional DDL.
2023-03-15 13:23:29.968 24 INFO alembic.runtime.migration [-] Context impl MySQLImpl.
2023-03-15 13:23:29.969 24 INFO alembic.runtime.migration [-] Will assume non-transactional DDL.
2023-03-15 13:23:30.017 24 INFO alembic.runtime.migration [-] Running upgrade  -> 27e647c0fad4, Initial version.
2023-03-15 13:23:31.040 24 INFO alembic.runtime.migration [-] Running upgrade 27e647c0fad4 -> e25ffa003242, Initial no-op Yoga contract migration.
2023-03-15 13:23:31.064 24 INFO alembic.runtime.migration [-] Running upgrade 27e647c0fad4 -> 29e87d24a316, Initial no-op Yoga expand migration.
2023-03-15 13:23:39.430 8 INFO keystone.common.fernet_utils [-] Created a new temporary key: /etc/keystone/fernet-keys/0.tmp
2023-03-15 13:23:39.435 8 INFO keystone.common.fernet_utils [-] Become a valid new key: /etc/keystone/fernet-keys/0
2023-03-15 13:23:39.436 8 INFO keystone.common.fernet_utils [-] Starting key rotation with 1 key files: ['/etc/keystone/fernet-keys/0']
2023-03-15 13:23:39.437 8 INFO keystone.common.fernet_utils [-] Created a new temporary key: /etc/keystone/fernet-keys/0.tmp
2023-03-15 13:23:39.438 8 INFO keystone.common.fernet_utils [-] Current primary key is: 0
2023-03-15 13:23:39.438 8 INFO keystone.common.fernet_utils [-] Next primary key will be: 1
2023-03-15 13:23:39.439 8 INFO keystone.common.fernet_utils [-] Promoted key 0 to be the primary: 1
2023-03-15 13:23:39.440 8 INFO keystone.common.fernet_utils [-] Become a valid new key: /etc/keystone/fernet-keys/0
2023-03-15 13:23:58.804 148 INFO keystone.cmd.bootstrap [None req-1fe5368f-f1f3-4012-8c0a-6839328113ec - - - - - -] Created domain default
2023-03-15 13:23:58.897 148 INFO keystone.cmd.bootstrap [None req-1fe5368f-f1f3-4012-8c0a-6839328113ec - - - - - -] Created project admin
2023-03-15 13:23:59.586 148 INFO keystone.cmd.bootstrap [None req-1fe5368f-f1f3-4012-8c0a-6839328113ec - - - - - -] Created user admin
2023-03-15 13:23:59.605 148 INFO keystone.cmd.bootstrap [None req-1fe5368f-f1f3-4012-8c0a-6839328113ec - - - - - -] Created role reader
2023-03-15 13:23:59.623 148 INFO keystone.cmd.bootstrap [None req-1fe5368f-f1f3-4012-8c0a-6839328113ec - - - - - -] Created role member
2023-03-15 13:23:59.665 148 INFO keystone.cmd.bootstrap [None req-1fe5368f-f1f3-4012-8c0a-6839328113ec - - - - - -] Created implied role where ee77603af7fb4b2da19636214ff2cc1e implies 5b3cfbe483c64df383a755a9d0f7ad30
2023-03-15 13:23:59.680 148 INFO keystone.cmd.bootstrap [None req-1fe5368f-f1f3-4012-8c0a-6839328113ec - - - - - -] Created role admin
2023-03-15 13:23:59.718 148 INFO keystone.cmd.bootstrap [None req-1fe5368f-f1f3-4012-8c0a-6839328113ec - - - - - -] Created implied role where 1d3167cc6a3f4adebd28e2ce0b88e70e implies ee77603af7fb4b2da19636214ff2cc1e
2023-03-15 13:23:59.748 148 INFO keystone.cmd.bootstrap [None req-1fe5368f-f1f3-4012-8c0a-6839328113ec - - - - - -] Granted role admin on project admin to user admin.
2023-03-15 13:23:59.765 148 INFO keystone.cmd.bootstrap [None req-1fe5368f-f1f3-4012-8c0a-6839328113ec - - - - - -] Granted role admin on the system to user admin.
2023-03-15 13:23:59.798 148 WARNING py.warnings [None req-1fe5368f-f1f3-4012-8c0a-6839328113ec - - - - - -] /var/lib/kolla/venv/lib/python3.9/site-packages/pycadf/identifier.py:71: UserWarning: Invalid uuid: RegionOne. To ensure interoperability, identifiers should be a valid uuid.
  warnings.warn(('Invalid uuid: %s. To ensure interoperability, '

2023-03-15 13:23:59.809 148 INFO keystone.cmd.bootstrap [None req-1fe5368f-f1f3-4012-8c0a-6839328113ec - - - - - -] Created region RegionOne
2023-03-15 13:23:59.905 148 INFO keystone.cmd.bootstrap [None req-1fe5368f-f1f3-4012-8c0a-6839328113ec - - - - - -] Created public endpoint http://169.16.1.175:5000
2023-03-15 13:23:59.935 148 INFO keystone.cmd.bootstrap [None req-1fe5368f-f1f3-4012-8c0a-6839328113ec - - - - - -] Created internal endpoint http://169.16.1.175:5000
2023-03-15 13:24:25.090 26 WARNING keystone.common.rbac_enforcer.enforcer [None req-42529f50-1537-4c31-9439-b58ed04a4272 55310a9e3d274235956eebc732471ab7 - - all default -] Deprecated policy rules found. Use oslopolicy-policy-generator and oslopolicy-policy-upgrade to detect and resolve deprecated policies in your configuration.
2023-03-15 13:24:25.967 28 WARNING keystone.common.rbac_enforcer.enforcer [None req-a5bff313-3069-4ad4-ab42-cb3e2f11475f 55310a9e3d274235956eebc732471ab7 - - all default -] Deprecated policy rules found. Use oslopolicy-policy-generator and oslopolicy-policy-upgrade to detect and resolve deprecated policies in your configuration.
2023-03-15 13:24:33.082 27 WARNING keystone.common.rbac_enforcer.enforcer [None req-ae254931-472a-4ade-ba79-39afe9fa65d0 55310a9e3d274235956eebc732471ab7 - - all default -] Deprecated policy rules found. Use oslopolicy-policy-generator and oslopolicy-policy-upgrade to detect and resolve deprecated policies in your configuration.
2023-03-15 13:25:50.908 27 ERROR keystone.server.flask.application [None req-0c695ddc-08cb-4ed4-b355-f104a59bc86e 55310a9e3d274235956eebc732471ab7 - - all default -] Could not find project: service.: keystone.exception.ProjectNotFound: Could not find project: service.
2023-03-15 13:25:50.908 27 ERROR keystone.server.flask.application Traceback (most recent call last):
2023-03-15 13:25:50.908 27 ERROR keystone.server.flask.application   File "/var/lib/kolla/venv/lib/python3.9/site-packages/flask/app.py", line 1820, in full_dispatch_request
2023-03-15 13:25:50.908 27 ERROR keystone.server.flask.application     rv = self.dispatch_request()
2023-03-15 13:25:50.908 27 ERROR keystone.server.flask.application   File "/var/lib/kolla/venv/lib/python3.9/site-packages/flask/app.py", line 1796, in dispatch_request
2023-03-15 13:25:50.908 27 ERROR keystone.server.flask.application     return self.ensure_sync(self.view_functions[rule.endpoint])(**view_args)
2023-03-15 13:25:50.908 27 ERROR keystone.server.flask.application   File "/var/lib/kolla/venv/lib/python3.9/site-packages/flask_restful/__init__.py", line 467, in wrapper
2023-03-15 13:25:50.908 27 ERROR keystone.server.flask.application     resp = resource(*args, **kwargs)
2023-03-15 13:25:50.908 27 ERROR keystone.server.flask.application   File "/var/lib/kolla/venv/lib/python3.9/site-packages/flask/views.py", line 107, in view
2023-03-15 13:25:50.908 27 ERROR keystone.server.flask.application     return current_app.ensure_sync(self.dispatch_request)(**kwargs)
2023-03-15 13:25:50.908 27 ERROR keystone.server.flask.application   File "/var/lib/kolla/venv/lib/python3.9/site-packages/flask_restful/__init__.py", line 582, in dispatch_request
2023-03-15 13:25:50.908 27 ERROR keystone.server.flask.application     resp = meth(*args, **kwargs)
2023-03-15 13:25:50.908 27 ERROR keystone.server.flask.application   File "/var/lib/kolla/venv/lib/python3.9/site-packages/keystone/api/projects.py", line 151, in get
2023-03-15 13:25:50.908 27 ERROR keystone.server.flask.application     return self._get_project(project_id)
2023-03-15 13:25:50.908 27 ERROR keystone.server.flask.application   File "/var/lib/kolla/venv/lib/python3.9/site-packages/keystone/api/projects.py", line 107, in _get_project
2023-03-15 13:25:50.908 27 ERROR keystone.server.flask.application     project = PROVIDERS.resource_api.get_project(project_id)
2023-03-15 13:25:50.908 27 ERROR keystone.server.flask.application   File "/var/lib/kolla/venv/lib/python3.9/site-packages/keystone/common/manager.py", line 115, in wrapped
2023-03-15 13:25:50.908 27 ERROR keystone.server.flask.application     __ret_val = __f(*args, **kwargs)
2023-03-15 13:25:50.908 27 ERROR keystone.server.flask.application   File "/var/lib/kolla/venv/lib/python3.9/site-packages/decorator.py", line 232, in fun
2023-03-15 13:25:50.908 27 ERROR keystone.server.flask.application     return caller(func, *(extras + args), **kw)
2023-03-15 13:25:50.908 27 ERROR keystone.server.flask.application   File "/var/lib/kolla/venv/lib/python3.9/site-packages/dogpile/cache/region.py", line 1577, in get_or_create_for_user_func
2023-03-15 13:25:50.908 27 ERROR keystone.server.flask.application     return self.get_or_create(
2023-03-15 13:25:50.908 27 ERROR keystone.server.flask.application   File "/var/lib/kolla/venv/lib/python3.9/site-packages/dogpile/cache/region.py", line 1042, in get_or_create
2023-03-15 13:25:50.908 27 ERROR keystone.server.flask.application     with Lock(
2023-03-15 13:25:50.908 27 ERROR keystone.server.flask.application   File "/var/lib/kolla/venv/lib/python3.9/site-packages/dogpile/lock.py", line 185, in __enter__
2023-03-15 13:25:50.908 27 ERROR keystone.server.flask.application     return self._enter()
2023-03-15 13:25:50.908 27 ERROR keystone.server.flask.application   File "/var/lib/kolla/venv/lib/python3.9/site-packages/dogpile/lock.py", line 94, in _enter
2023-03-15 13:25:50.908 27 ERROR keystone.server.flask.application     generated = self._enter_create(value, createdtime)
2023-03-15 13:25:50.908 27 ERROR keystone.server.flask.application   File "/var/lib/kolla/venv/lib/python3.9/site-packages/dogpile/lock.py", line 178, in _enter_create
2023-03-15 13:25:50.908 27 ERROR keystone.server.flask.application     return self.creator()
2023-03-15 13:25:50.908 27 ERROR keystone.server.flask.application   File "/var/lib/kolla/venv/lib/python3.9/site-packages/dogpile/cache/region.py", line 995, in gen_value
2023-03-15 13:25:50.908 27 ERROR keystone.server.flask.application     created_value = creator(
2023-03-15 13:25:50.908 27 ERROR keystone.server.flask.application   File "/var/lib/kolla/venv/lib/python3.9/site-packages/keystone/resource/core.py", line 903, in get_project
2023-03-15 13:25:50.908 27 ERROR keystone.server.flask.application     return self.driver.get_project(project_id)
2023-03-15 13:25:50.908 27 ERROR keystone.server.flask.application   File "/var/lib/kolla/venv/lib/python3.9/site-packages/keystone/resource/backends/sql.py", line 49, in get_project
2023-03-15 13:25:50.908 27 ERROR keystone.server.flask.application     return self._get_project(session, project_id).to_dict()
2023-03-15 13:25:50.908 27 ERROR keystone.server.flask.application   File "/var/lib/kolla/venv/lib/python3.9/site-packages/keystone/resource/backends/sql.py", line 44, in _get_project
2023-03-15 13:25:50.908 27 ERROR keystone.server.flask.application     raise exception.ProjectNotFound(project_id=project_id)
2023-03-15 13:25:50.908 27 ERROR keystone.server.flask.application keystone.exception.ProjectNotFound: Could not find project: service.
2023-03-15 13:25:50.908 27 ERROR keystone.server.flask.application 
2023-03-15 13:26:00.891 28 ERROR keystone.server.flask.application [None req-4f7b340d-00d0-45ac-aab0-6302d0cfc401 55310a9e3d274235956eebc732471ab7 - - all default -] Could not find project: service.: keystone.exception.ProjectNotFound: Could not find project: service.
2023-03-15 13:26:00.891 28 ERROR keystone.server.flask.application Traceback (most recent call last):
2023-03-15 13:26:00.891 28 ERROR keystone.server.flask.application   File "/var/lib/kolla/venv/lib/python3.9/site-packages/flask/app.py", line 1820, in full_dispatch_request
2023-03-15 13:26:00.891 28 ERROR keystone.server.flask.application     rv = self.dispatch_request()
2023-03-15 13:26:00.891 28 ERROR keystone.server.flask.application   File "/var/lib/kolla/venv/lib/python3.9/site-packages/flask/app.py", line 1796, in dispatch_request
2023-03-15 13:26:00.891 28 ERROR keystone.server.flask.application     return self.ensure_sync(self.view_functions[rule.endpoint])(**view_args)
2023-03-15 13:26:00.891 28 ERROR keystone.server.flask.application   File "/var/lib/kolla/venv/lib/python3.9/site-packages/flask_restful/__init__.py", line 467, in wrapper
2023-03-15 13:26:00.891 28 ERROR keystone.server.flask.application     resp = resource(*args, **kwargs)
2023-03-15 13:26:00.891 28 ERROR keystone.server.flask.application   File "/var/lib/kolla/venv/lib/python3.9/site-packages/flask/views.py", line 107, in view
2023-03-15 13:26:00.891 28 ERROR keystone.server.flask.application     return current_app.ensure_sync(self.dispatch_request)(**kwargs)
2023-03-15 13:26:00.891 28 ERROR keystone.server.flask.application   File "/var/lib/kolla/venv/lib/python3.9/site-packages/flask_restful/__init__.py", line 582, in dispatch_request
2023-03-15 13:26:00.891 28 ERROR keystone.server.flask.application     resp = meth(*args, **kwargs)
2023-03-15 13:26:00.891 28 ERROR keystone.server.flask.application   File "/var/lib/kolla/venv/lib/python3.9/site-packages/keystone/api/projects.py", line 151, in get
2023-03-15 13:26:00.891 28 ERROR keystone.server.flask.application     return self._get_project(project_id)
2023-03-15 13:26:00.891 28 ERROR keystone.server.flask.application   File "/var/lib/kolla/venv/lib/python3.9/site-packages/keystone/api/projects.py", line 107, in _get_project
2023-03-15 13:26:00.891 28 ERROR keystone.server.flask.application     project = PROVIDERS.resource_api.get_project(project_id)
2023-03-15 13:26:00.891 28 ERROR keystone.server.flask.application   File "/var/lib/kolla/venv/lib/python3.9/site-packages/keystone/common/manager.py", line 115, in wrapped
2023-03-15 13:26:00.891 28 ERROR keystone.server.flask.application     __ret_val = __f(*args, **kwargs)
2023-03-15 13:26:00.891 28 ERROR keystone.server.flask.application   File "/var/lib/kolla/venv/lib/python3.9/site-packages/decorator.py", line 232, in fun
2023-03-15 13:26:00.891 28 ERROR keystone.server.flask.application     return caller(func, *(extras + args), **kw)
2023-03-15 13:26:00.891 28 ERROR keystone.server.flask.application   File "/var/lib/kolla/venv/lib/python3.9/site-packages/dogpile/cache/region.py", line 1577, in get_or_create_for_user_func
2023-03-15 13:26:00.891 28 ERROR keystone.server.flask.application     return self.get_or_create(
2023-03-15 13:26:00.891 28 ERROR keystone.server.flask.application   File "/var/lib/kolla/venv/lib/python3.9/site-packages/dogpile/cache/region.py", line 1042, in get_or_create
2023-03-15 13:26:00.891 28 ERROR keystone.server.flask.application     with Lock(
2023-03-15 13:26:00.891 28 ERROR keystone.server.flask.application   File "/var/lib/kolla/venv/lib/python3.9/site-packages/dogpile/lock.py", line 185, in __enter__
2023-03-15 13:26:00.891 28 ERROR keystone.server.flask.application     return self._enter()
2023-03-15 13:26:00.891 28 ERROR keystone.server.flask.application   File "/var/lib/kolla/venv/lib/python3.9/site-packages/dogpile/lock.py", line 94, in _enter
2023-03-15 13:26:00.891 28 ERROR keystone.server.flask.application     generated = self._enter_create(value, createdtime)
2023-03-15 13:26:00.891 28 ERROR keystone.server.flask.application   File "/var/lib/kolla/venv/lib/python3.9/site-packages/dogpile/lock.py", line 178, in _enter_create
2023-03-15 13:26:00.891 28 ERROR keystone.server.flask.application     return self.creator()
2023-03-15 13:26:00.891 28 ERROR keystone.server.flask.application   File "/var/lib/kolla/venv/lib/python3.9/site-packages/dogpile/cache/region.py", line 995, in gen_value
2023-03-15 13:26:00.891 28 ERROR keystone.server.flask.application     created_value = creator(
2023-03-15 13:26:00.891 28 ERROR keystone.server.flask.application   File "/var/lib/kolla/venv/lib/python3.9/site-packages/keystone/resource/core.py", line 903, in get_project
2023-03-15 13:26:00.891 28 ERROR keystone.server.flask.application     return self.driver.get_project(project_id)
2023-03-15 13:26:00.891 28 ERROR keystone.server.flask.application   File "/var/lib/kolla/venv/lib/python3.9/site-packages/keystone/resource/backends/sql.py", line 49, in get_project
2023-03-15 13:26:00.891 28 ERROR keystone.server.flask.application     return self._get_project(session, project_id).to_dict()
2023-03-15 13:26:00.891 28 ERROR keystone.server.flask.application   File "/var/lib/kolla/venv/lib/python3.9/site-packages/keystone/resource/backends/sql.py", line 44, in _get_project
2023-03-15 13:26:00.891 28 ERROR keystone.server.flask.application     raise exception.ProjectNotFound(project_id=project_id)
2023-03-15 13:26:00.891 28 ERROR keystone.server.flask.application keystone.exception.ProjectNotFound: Could not find project: service.
2023-03-15 13:26:00.891 28 ERROR keystone.server.flask.application 
2023-03-15 13:26:15.986 28 ERROR keystone.server.flask.application [None req-8c713023-7b24-47ea-aa97-495c9beeb10e 55310a9e3d274235956eebc732471ab7 - - all default -] Could not find role: admin.: keystone.exception.RoleNotFound: Could not find role: admin.
2023-03-15 13:26:15.986 28 ERROR keystone.server.flask.application Traceback (most recent call last):
2023-03-15 13:26:15.986 28 ERROR keystone.server.flask.application   File "/var/lib/kolla/venv/lib/python3.9/site-packages/flask/app.py", line 1820, in full_dispatch_request
2023-03-15 13:26:15.986 28 ERROR keystone.server.flask.application     rv = self.dispatch_request()
2023-03-15 13:26:15.986 28 ERROR keystone.server.flask.application   File "/var/lib/kolla/venv/lib/python3.9/site-packages/flask/app.py", line 1796, in dispatch_request
2023-03-15 13:26:15.986 28 ERROR keystone.server.flask.application     return self.ensure_sync(self.view_functions[rule.endpoint])(**view_args)
2023-03-15 13:26:15.986 28 ERROR keystone.server.flask.application   File "/var/lib/kolla/venv/lib/python3.9/site-packages/flask_restful/__init__.py", line 467, in wrapper
2023-03-15 13:26:15.986 28 ERROR keystone.server.flask.application     resp = resource(*args, **kwargs)
2023-03-15 13:26:15.986 28 ERROR keystone.server.flask.application   File "/var/lib/kolla/venv/lib/python3.9/site-packages/flask/views.py", line 107, in view
2023-03-15 13:26:15.986 28 ERROR keystone.server.flask.application     return current_app.ensure_sync(self.dispatch_request)(**kwargs)
2023-03-15 13:26:15.986 28 ERROR keystone.server.flask.application   File "/var/lib/kolla/venv/lib/python3.9/site-packages/flask_restful/__init__.py", line 582, in dispatch_request
2023-03-15 13:26:15.986 28 ERROR keystone.server.flask.application     resp = meth(*args, **kwargs)
2023-03-15 13:26:15.986 28 ERROR keystone.server.flask.application   File "/var/lib/kolla/venv/lib/python3.9/site-packages/keystone/api/roles.py", line 50, in get
2023-03-15 13:26:15.986 28 ERROR keystone.server.flask.application     return self._get_role(role_id)
2023-03-15 13:26:15.986 28 ERROR keystone.server.flask.application   File "/var/lib/kolla/venv/lib/python3.9/site-packages/keystone/api/roles.py", line 70, in _get_role
2023-03-15 13:26:15.986 28 ERROR keystone.server.flask.application     ENFORCER.enforce_call(action='identity:get_role')
2023-03-15 13:26:15.986 28 ERROR keystone.server.flask.application   File "/var/lib/kolla/venv/lib/python3.9/site-packages/keystone/common/rbac_enforcer/enforcer.py", line 402, in enforce_call
2023-03-15 13:26:15.986 28 ERROR keystone.server.flask.application     policy_dict.update(cls._extract_member_target_data(
2023-03-15 13:26:15.986 28 ERROR keystone.server.flask.application   File "/var/lib/kolla/venv/lib/python3.9/site-packages/keystone/common/rbac_enforcer/enforcer.py", line 234, in _extract_member_target_data
2023-03-15 13:26:15.986 28 ERROR keystone.server.flask.application     member_name: func(flask.request.view_args[key])
2023-03-15 13:26:15.986 28 ERROR keystone.server.flask.application   File "/var/lib/kolla/venv/lib/python3.9/site-packages/keystone/common/manager.py", line 115, in wrapped
2023-03-15 13:26:15.986 28 ERROR keystone.server.flask.application     __ret_val = __f(*args, **kwargs)
2023-03-15 13:26:15.986 28 ERROR keystone.server.flask.application   File "/var/lib/kolla/venv/lib/python3.9/site-packages/decorator.py", line 232, in fun
2023-03-15 13:26:15.986 28 ERROR keystone.server.flask.application     return caller(func, *(extras + args), **kw)
2023-03-15 13:26:15.986 28 ERROR keystone.server.flask.application   File "/var/lib/kolla/venv/lib/python3.9/site-packages/dogpile/cache/region.py", line 1577, in get_or_create_for_user_func
2023-03-15 13:26:15.986 28 ERROR keystone.server.flask.application     return self.get_or_create(
2023-03-15 13:26:15.986 28 ERROR keystone.server.flask.application   File "/var/lib/kolla/venv/lib/python3.9/site-packages/dogpile/cache/region.py", line 1042, in get_or_create
2023-03-15 13:26:15.986 28 ERROR keystone.server.flask.application     with Lock(
2023-03-15 13:26:15.986 28 ERROR keystone.server.flask.application   File "/var/lib/kolla/venv/lib/python3.9/site-packages/dogpile/lock.py", line 185, in __enter__
2023-03-15 13:26:15.986 28 ERROR keystone.server.flask.application     return self._enter()
2023-03-15 13:26:15.986 28 ERROR keystone.server.flask.application   File "/var/lib/kolla/venv/lib/python3.9/site-packages/dogpile/lock.py", line 94, in _enter
2023-03-15 13:26:15.986 28 ERROR keystone.server.flask.application     generated = self._enter_create(value, createdtime)
2023-03-15 13:26:15.986 28 ERROR keystone.server.flask.application   File "/var/lib/kolla/venv/lib/python3.9/site-packages/dogpile/lock.py", line 178, in _enter_create
2023-03-15 13:26:15.986 28 ERROR keystone.server.flask.application     return self.creator()
2023-03-15 13:26:15.986 28 ERROR keystone.server.flask.application   File "/var/lib/kolla/venv/lib/python3.9/site-packages/dogpile/cache/region.py", line 995, in gen_value
2023-03-15 13:26:15.986 28 ERROR keystone.server.flask.application     created_value = creator(
2023-03-15 13:26:15.986 28 ERROR keystone.server.flask.application   File "/var/lib/kolla/venv/lib/python3.9/site-packages/keystone/assignment/core.py", line 1276, in get_role
2023-03-15 13:26:15.986 28 ERROR keystone.server.flask.application     return self.driver.get_role(role_id)
2023-03-15 13:26:15.986 28 ERROR keystone.server.flask.application   File "/var/lib/kolla/venv/lib/python3.9/site-packages/keystone/assignment/role_backends/sql.py", line 70, in get_role
2023-03-15 13:26:15.986 28 ERROR keystone.server.flask.application     return self._get_role(session, role_id).to_dict()
2023-03-15 13:26:15.986 28 ERROR keystone.server.flask.application   File "/var/lib/kolla/venv/lib/python3.9/site-packages/keystone/assignment/role_backends/sql.py", line 65, in _get_role
2023-03-15 13:26:15.986 28 ERROR keystone.server.flask.application     raise exception.RoleNotFound(role_id=role_id)
2023-03-15 13:26:15.986 28 ERROR keystone.server.flask.application keystone.exception.RoleNotFound: Could not find role: admin.
2023-03-15 13:26:15.986 28 ERROR keystone.server.flask.application 
2023-03-15 13:26:17.506 28 ERROR keystone.server.flask.application [None req-e9361114-5180-4543-892e-dfceb8f064ee 55310a9e3d274235956eebc732471ab7 - - all default -] Could not find user: ironic.: keystone.exception.UserNotFound: Could not find user: ironic.
2023-03-15 13:26:17.506 28 ERROR keystone.server.flask.application Traceback (most recent call last):
2023-03-15 13:26:17.506 28 ERROR keystone.server.flask.application   File "/var/lib/kolla/venv/lib/python3.9/site-packages/flask/app.py", line 1820, in full_dispatch_request
2023-03-15 13:26:17.506 28 ERROR keystone.server.flask.application     rv = self.dispatch_request()
2023-03-15 13:26:17.506 28 ERROR keystone.server.flask.application   File "/var/lib/kolla/venv/lib/python3.9/site-packages/flask/app.py", line 1796, in dispatch_request
2023-03-15 13:26:17.506 28 ERROR keystone.server.flask.application     return self.ensure_sync(self.view_functions[rule.endpoint])(**view_args)
2023-03-15 13:26:17.506 28 ERROR keystone.server.flask.application   File "/var/lib/kolla/venv/lib/python3.9/site-packages/flask_restful/__init__.py", line 467, in wrapper
2023-03-15 13:26:17.506 28 ERROR keystone.server.flask.application     resp = resource(*args, **kwargs)
2023-03-15 13:26:17.506 28 ERROR keystone.server.flask.application   File "/var/lib/kolla/venv/lib/python3.9/site-packages/flask/views.py", line 107, in view
2023-03-15 13:26:17.506 28 ERROR keystone.server.flask.application     return current_app.ensure_sync(self.dispatch_request)(**kwargs)
2023-03-15 13:26:17.506 28 ERROR keystone.server.flask.application   File "/var/lib/kolla/venv/lib/python3.9/site-packages/flask_restful/__init__.py", line 582, in dispatch_request
2023-03-15 13:26:17.506 28 ERROR keystone.server.flask.application     resp = meth(*args, **kwargs)
2023-03-15 13:26:17.506 28 ERROR keystone.server.flask.application   File "/var/lib/kolla/venv/lib/python3.9/site-packages/keystone/api/users.py", line 182, in get
2023-03-15 13:26:17.506 28 ERROR keystone.server.flask.application     return self._get_user(user_id)
2023-03-15 13:26:17.506 28 ERROR keystone.server.flask.application   File "/var/lib/kolla/venv/lib/python3.9/site-packages/keystone/api/users.py", line 194, in _get_user
2023-03-15 13:26:17.506 28 ERROR keystone.server.flask.application     ref = PROVIDERS.identity_api.get_user(user_id)
2023-03-15 13:26:17.506 28 ERROR keystone.server.flask.application   File "/var/lib/kolla/venv/lib/python3.9/site-packages/keystone/common/manager.py", line 115, in wrapped
2023-03-15 13:26:17.506 28 ERROR keystone.server.flask.application     __ret_val = __f(*args, **kwargs)
2023-03-15 13:26:17.506 28 ERROR keystone.server.flask.application   File "/var/lib/kolla/venv/lib/python3.9/site-packages/keystone/identity/core.py", line 414, in wrapper
2023-03-15 13:26:17.506 28 ERROR keystone.server.flask.application     return f(self, *args, **kwargs)
2023-03-15 13:26:17.506 28 ERROR keystone.server.flask.application   File "/var/lib/kolla/venv/lib/python3.9/site-packages/keystone/identity/core.py", line 424, in wrapper
2023-03-15 13:26:17.506 28 ERROR keystone.server.flask.application     return f(self, *args, **kwargs)
2023-03-15 13:26:17.506 28 ERROR keystone.server.flask.application   File "/var/lib/kolla/venv/lib/python3.9/site-packages/decorator.py", line 232, in fun
2023-03-15 13:26:17.506 28 ERROR keystone.server.flask.application     return caller(func, *(extras + args), **kw)
2023-03-15 13:26:17.506 28 ERROR keystone.server.flask.application   File "/var/lib/kolla/venv/lib/python3.9/site-packages/dogpile/cache/region.py", line 1577, in get_or_create_for_user_func
2023-03-15 13:26:17.506 28 ERROR keystone.server.flask.application     return self.get_or_create(
2023-03-15 13:26:17.506 28 ERROR keystone.server.flask.application   File "/var/lib/kolla/venv/lib/python3.9/site-packages/dogpile/cache/region.py", line 1042, in get_or_create
2023-03-15 13:26:17.506 28 ERROR keystone.server.flask.application     with Lock(
2023-03-15 13:26:17.506 28 ERROR keystone.server.flask.application   File "/var/lib/kolla/venv/lib/python3.9/site-packages/dogpile/lock.py", line 185, in __enter__
2023-03-15 13:26:17.506 28 ERROR keystone.server.flask.application     return self._enter()
2023-03-15 13:26:17.506 28 ERROR keystone.server.flask.application   File "/var/lib/kolla/venv/lib/python3.9/site-packages/dogpile/lock.py", line 94, in _enter
2023-03-15 13:26:17.506 28 ERROR keystone.server.flask.application     generated = self._enter_create(value, createdtime)
2023-03-15 13:26:17.506 28 ERROR keystone.server.flask.application   File "/var/lib/kolla/venv/lib/python3.9/site-packages/dogpile/lock.py", line 178, in _enter_create
2023-03-15 13:26:17.506 28 ERROR keystone.server.flask.application     return self.creator()
2023-03-15 13:26:17.506 28 ERROR keystone.server.flask.application   File "/var/lib/kolla/venv/lib/python3.9/site-packages/dogpile/cache/region.py", line 995, in gen_value
2023-03-15 13:26:17.506 28 ERROR keystone.server.flask.application     created_value = creator(
2023-03-15 13:26:17.506 28 ERROR keystone.server.flask.application   File "/var/lib/kolla/venv/lib/python3.9/site-packages/keystone/identity/core.py", line 1011, in get_user
2023-03-15 13:26:17.506 28 ERROR keystone.server.flask.application     ref = driver.get_user(entity_id)
2023-03-15 13:26:17.506 28 ERROR keystone.server.flask.application   File "/var/lib/kolla/venv/lib/python3.9/site-packages/keystone/identity/backends/sql.py", line 200, in get_user
2023-03-15 13:26:17.506 28 ERROR keystone.server.flask.application     self._get_user(session, user_id).to_dict())
2023-03-15 13:26:17.506 28 ERROR keystone.server.flask.application   File "/var/lib/kolla/venv/lib/python3.9/site-packages/keystone/identity/backends/sql.py", line 194, in _get_user
2023-03-15 13:26:17.506 28 ERROR keystone.server.flask.application     raise exception.UserNotFound(user_id=user_id)
2023-03-15 13:26:17.506 28 ERROR keystone.server.flask.application keystone.exception.UserNotFound: Could not find user: ironic.
2023-03-15 13:26:17.506 28 ERROR keystone.server.flask.application 
2023-03-15 13:26:18.414 26 ERROR keystone.server.flask.application [None req-06dc02b2-f53f-49f6-ad45-b53168a8ed2a 55310a9e3d274235956eebc732471ab7 - - all default -] Could not find project: service.: keystone.exception.ProjectNotFound: Could not find project: service.
2023-03-15 13:26:18.414 26 ERROR keystone.server.flask.application Traceback (most recent call last):
2023-03-15 13:26:18.414 26 ERROR keystone.server.flask.application   File "/var/lib/kolla/venv/lib/python3.9/site-packages/flask/app.py", line 1820, in full_dispatch_request
2023-03-15 13:26:18.414 26 ERROR keystone.server.flask.application     rv = self.dispatch_request()
2023-03-15 13:26:18.414 26 ERROR keystone.server.flask.application   File "/var/lib/kolla/venv/lib/python3.9/site-packages/flask/app.py", line 1796, in dispatch_request
2023-03-15 13:26:18.414 26 ERROR keystone.server.flask.application     return self.ensure_sync(self.view_functions[rule.endpoint])(**view_args)
2023-03-15 13:26:18.414 26 ERROR keystone.server.flask.application   File "/var/lib/kolla/venv/lib/python3.9/site-packages/flask_restful/__init__.py", line 467, in wrapper
2023-03-15 13:26:18.414 26 ERROR keystone.server.flask.application     resp = resource(*args, **kwargs)
2023-03-15 13:26:18.414 26 ERROR keystone.server.flask.application   File "/var/lib/kolla/venv/lib/python3.9/site-packages/flask/views.py", line 107, in view
2023-03-15 13:26:18.414 26 ERROR keystone.server.flask.application     return current_app.ensure_sync(self.dispatch_request)(**kwargs)
2023-03-15 13:26:18.414 26 ERROR keystone.server.flask.application   File "/var/lib/kolla/venv/lib/python3.9/site-packages/flask_restful/__init__.py", line 582, in dispatch_request
2023-03-15 13:26:18.414 26 ERROR keystone.server.flask.application     resp = meth(*args, **kwargs)
2023-03-15 13:26:18.414 26 ERROR keystone.server.flask.application   File "/var/lib/kolla/venv/lib/python3.9/site-packages/keystone/api/projects.py", line 151, in get
2023-03-15 13:26:18.414 26 ERROR keystone.server.flask.application     return self._get_project(project_id)
2023-03-15 13:26:18.414 26 ERROR keystone.server.flask.application   File "/var/lib/kolla/venv/lib/python3.9/site-packages/keystone/api/projects.py", line 107, in _get_project
2023-03-15 13:26:18.414 26 ERROR keystone.server.flask.application     project = PROVIDERS.resource_api.get_project(project_id)
2023-03-15 13:26:18.414 26 ERROR keystone.server.flask.application   File "/var/lib/kolla/venv/lib/python3.9/site-packages/keystone/common/manager.py", line 115, in wrapped
2023-03-15 13:26:18.414 26 ERROR keystone.server.flask.application     __ret_val = __f(*args, **kwargs)
2023-03-15 13:26:18.414 26 ERROR keystone.server.flask.application   File "/var/lib/kolla/venv/lib/python3.9/site-packages/decorator.py", line 232, in fun
2023-03-15 13:26:18.414 26 ERROR keystone.server.flask.application     return caller(func, *(extras + args), **kw)
2023-03-15 13:26:18.414 26 ERROR keystone.server.flask.application   File "/var/lib/kolla/venv/lib/python3.9/site-packages/dogpile/cache/region.py", line 1577, in get_or_create_for_user_func
2023-03-15 13:26:18.414 26 ERROR keystone.server.flask.application     return self.get_or_create(
2023-03-15 13:26:18.414 26 ERROR keystone.server.flask.application   File "/var/lib/kolla/venv/lib/python3.9/site-packages/dogpile/cache/region.py", line 1042, in get_or_create
2023-03-15 13:26:18.414 26 ERROR keystone.server.flask.application     with Lock(
2023-03-15 13:26:18.414 26 ERROR keystone.server.flask.application   File "/var/lib/kolla/venv/lib/python3.9/site-packages/dogpile/lock.py", line 185, in __enter__
2023-03-15 13:26:18.414 26 ERROR keystone.server.flask.application     return self._enter()
2023-03-15 13:26:18.414 26 ERROR keystone.server.flask.application   File "/var/lib/kolla/venv/lib/python3.9/site-packages/dogpile/lock.py", line 94, in _enter
2023-03-15 13:26:18.414 26 ERROR keystone.server.flask.application     generated = self._enter_create(value, createdtime)
2023-03-15 13:26:18.414 26 ERROR keystone.server.flask.application   File "/var/lib/kolla/venv/lib/python3.9/site-packages/dogpile/lock.py", line 178, in _enter_create
2023-03-15 13:26:18.414 26 ERROR keystone.server.flask.application     return self.creator()
2023-03-15 13:26:18.414 26 ERROR keystone.server.flask.application   File "/var/lib/kolla/venv/lib/python3.9/site-packages/dogpile/cache/region.py", line 995, in gen_value
2023-03-15 13:26:18.414 26 ERROR keystone.server.flask.application     created_value = creator(
2023-03-15 13:26:18.414 26 ERROR keystone.server.flask.application   File "/var/lib/kolla/venv/lib/python3.9/site-packages/keystone/resource/core.py", line 903, in get_project
2023-03-15 13:26:18.414 26 ERROR keystone.server.flask.application     return self.driver.get_project(project_id)
2023-03-15 13:26:18.414 26 ERROR keystone.server.flask.application   File "/var/lib/kolla/venv/lib/python3.9/site-packages/keystone/resource/backends/sql.py", line 49, in get_project
2023-03-15 13:26:18.414 26 ERROR keystone.server.flask.application     return self._get_project(session, project_id).to_dict()
2023-03-15 13:26:18.414 26 ERROR keystone.server.flask.application   File "/var/lib/kolla/venv/lib/python3.9/site-packages/keystone/resource/backends/sql.py", line 44, in _get_project
2023-03-15 13:26:18.414 26 ERROR keystone.server.flask.application     raise exception.ProjectNotFound(project_id=project_id)
2023-03-15 13:26:18.414 26 ERROR keystone.server.flask.application keystone.exception.ProjectNotFound: Could not find project: service.
2023-03-15 13:26:18.414 26 ERROR keystone.server.flask.application 
2023-03-15 13:26:28.585 27 ERROR keystone.server.flask.application [None req-55ae6608-6cec-40f8-8343-d3d5910f3e0e 55310a9e3d274235956eebc732471ab7 - - all default -] Could not find role: admin.: keystone.exception.RoleNotFound: Could not find role: admin.
2023-03-15 13:26:28.585 27 ERROR keystone.server.flask.application Traceback (most recent call last):
2023-03-15 13:26:28.585 27 ERROR keystone.server.flask.application   File "/var/lib/kolla/venv/lib/python3.9/site-packages/flask/app.py", line 1820, in full_dispatch_request
2023-03-15 13:26:28.585 27 ERROR keystone.server.flask.application     rv = self.dispatch_request()
2023-03-15 13:26:28.585 27 ERROR keystone.server.flask.application   File "/var/lib/kolla/venv/lib/python3.9/site-packages/flask/app.py", line 1796, in dispatch_request
2023-03-15 13:26:28.585 27 ERROR keystone.server.flask.application     return self.ensure_sync(self.view_functions[rule.endpoint])(**view_args)
2023-03-15 13:26:28.585 27 ERROR keystone.server.flask.application   File "/var/lib/kolla/venv/lib/python3.9/site-packages/flask_restful/__init__.py", line 467, in wrapper
2023-03-15 13:26:28.585 27 ERROR keystone.server.flask.application     resp = resource(*args, **kwargs)
2023-03-15 13:26:28.585 27 ERROR keystone.server.flask.application   File "/var/lib/kolla/venv/lib/python3.9/site-packages/flask/views.py", line 107, in view
2023-03-15 13:26:28.585 27 ERROR keystone.server.flask.application     return current_app.ensure_sync(self.dispatch_request)(**kwargs)
2023-03-15 13:26:28.585 27 ERROR keystone.server.flask.application   File "/var/lib/kolla/venv/lib/python3.9/site-packages/flask_restful/__init__.py", line 582, in dispatch_request
2023-03-15 13:26:28.585 27 ERROR keystone.server.flask.application     resp = meth(*args, **kwargs)
2023-03-15 13:26:28.585 27 ERROR keystone.server.flask.application   File "/var/lib/kolla/venv/lib/python3.9/site-packages/keystone/api/roles.py", line 50, in get
2023-03-15 13:26:28.585 27 ERROR keystone.server.flask.application     return self._get_role(role_id)
2023-03-15 13:26:28.585 27 ERROR keystone.server.flask.application   File "/var/lib/kolla/venv/lib/python3.9/site-packages/keystone/api/roles.py", line 70, in _get_role
2023-03-15 13:26:28.585 27 ERROR keystone.server.flask.application     ENFORCER.enforce_call(action='identity:get_role')
2023-03-15 13:26:28.585 27 ERROR keystone.server.flask.application   File "/var/lib/kolla/venv/lib/python3.9/site-packages/keystone/common/rbac_enforcer/enforcer.py", line 402, in enforce_call
2023-03-15 13:26:28.585 27 ERROR keystone.server.flask.application     policy_dict.update(cls._extract_member_target_data(
2023-03-15 13:26:28.585 27 ERROR keystone.server.flask.application   File "/var/lib/kolla/venv/lib/python3.9/site-packages/keystone/common/rbac_enforcer/enforcer.py", line 234, in _extract_member_target_data
2023-03-15 13:26:28.585 27 ERROR keystone.server.flask.application     member_name: func(flask.request.view_args[key])
2023-03-15 13:26:28.585 27 ERROR keystone.server.flask.application   File "/var/lib/kolla/venv/lib/python3.9/site-packages/keystone/common/manager.py", line 115, in wrapped
2023-03-15 13:26:28.585 27 ERROR keystone.server.flask.application     __ret_val = __f(*args, **kwargs)
2023-03-15 13:26:28.585 27 ERROR keystone.server.flask.application   File "/var/lib/kolla/venv/lib/python3.9/site-packages/decorator.py", line 232, in fun
2023-03-15 13:26:28.585 27 ERROR keystone.server.flask.application     return caller(func, *(extras + args), **kw)
2023-03-15 13:26:28.585 27 ERROR keystone.server.flask.application   File "/var/lib/kolla/venv/lib/python3.9/site-packages/dogpile/cache/region.py", line 1577, in get_or_create_for_user_func
2023-03-15 13:26:28.585 27 ERROR keystone.server.flask.application     return self.get_or_create(
2023-03-15 13:26:28.585 27 ERROR keystone.server.flask.application   File "/var/lib/kolla/venv/lib/python3.9/site-packages/dogpile/cache/region.py", line 1042, in get_or_create
2023-03-15 13:26:28.585 27 ERROR keystone.server.flask.application     with Lock(
2023-03-15 13:26:28.585 27 ERROR keystone.server.flask.application   File "/var/lib/kolla/venv/lib/python3.9/site-packages/dogpile/lock.py", line 185, in __enter__
2023-03-15 13:26:28.585 27 ERROR keystone.server.flask.application     return self._enter()
2023-03-15 13:26:28.585 27 ERROR keystone.server.flask.application   File "/var/lib/kolla/venv/lib/python3.9/site-packages/dogpile/lock.py", line 94, in _enter
2023-03-15 13:26:28.585 27 ERROR keystone.server.flask.application     generated = self._enter_create(value, createdtime)
2023-03-15 13:26:28.585 27 ERROR keystone.server.flask.application   File "/var/lib/kolla/venv/lib/python3.9/site-packages/dogpile/lock.py", line 178, in _enter_create
2023-03-15 13:26:28.585 27 ERROR keystone.server.flask.application     return self.creator()
2023-03-15 13:26:28.585 27 ERROR keystone.server.flask.application   File "/var/lib/kolla/venv/lib/python3.9/site-packages/dogpile/cache/region.py", line 995, in gen_value
2023-03-15 13:26:28.585 27 ERROR keystone.server.flask.application     created_value = creator(
2023-03-15 13:26:28.585 27 ERROR keystone.server.flask.application   File "/var/lib/kolla/venv/lib/python3.9/site-packages/keystone/assignment/core.py", line 1276, in get_role
2023-03-15 13:26:28.585 27 ERROR keystone.server.flask.application     return self.driver.get_role(role_id)
2023-03-15 13:26:28.585 27 ERROR keystone.server.flask.application   File "/var/lib/kolla/venv/lib/python3.9/site-packages/keystone/assignment/role_backends/sql.py", line 70, in get_role
2023-03-15 13:26:28.585 27 ERROR keystone.server.flask.application     return self._get_role(session, role_id).to_dict()
2023-03-15 13:26:28.585 27 ERROR keystone.server.flask.application   File "/var/lib/kolla/venv/lib/python3.9/site-packages/keystone/assignment/role_backends/sql.py", line 65, in _get_role
2023-03-15 13:26:28.585 27 ERROR keystone.server.flask.application     raise exception.RoleNotFound(role_id=role_id)
2023-03-15 13:26:28.585 27 ERROR keystone.server.flask.application keystone.exception.RoleNotFound: Could not find role: admin.
2023-03-15 13:26:28.585 27 ERROR keystone.server.flask.application 
2023-03-15 13:26:29.698 27 ERROR keystone.server.flask.application [None req-efda00d2-484d-4200-b738-ccad88b624f7 55310a9e3d274235956eebc732471ab7 - - all default -] Could not find user: ironic-inspector.: keystone.exception.UserNotFound: Could not find user: ironic-inspector.
2023-03-15 13:26:29.698 27 ERROR keystone.server.flask.application Traceback (most recent call last):
2023-03-15 13:26:29.698 27 ERROR keystone.server.flask.application   File "/var/lib/kolla/venv/lib/python3.9/site-packages/flask/app.py", line 1820, in full_dispatch_request
2023-03-15 13:26:29.698 27 ERROR keystone.server.flask.application     rv = self.dispatch_request()
2023-03-15 13:26:29.698 27 ERROR keystone.server.flask.application   File "/var/lib/kolla/venv/lib/python3.9/site-packages/flask/app.py", line 1796, in dispatch_request
2023-03-15 13:26:29.698 27 ERROR keystone.server.flask.application     return self.ensure_sync(self.view_functions[rule.endpoint])(**view_args)
2023-03-15 13:26:29.698 27 ERROR keystone.server.flask.application   File "/var/lib/kolla/venv/lib/python3.9/site-packages/flask_restful/__init__.py", line 467, in wrapper
2023-03-15 13:26:29.698 27 ERROR keystone.server.flask.application     resp = resource(*args, **kwargs)
2023-03-15 13:26:29.698 27 ERROR keystone.server.flask.application   File "/var/lib/kolla/venv/lib/python3.9/site-packages/flask/views.py", line 107, in view
2023-03-15 13:26:29.698 27 ERROR keystone.server.flask.application     return current_app.ensure_sync(self.dispatch_request)(**kwargs)
2023-03-15 13:26:29.698 27 ERROR keystone.server.flask.application   File "/var/lib/kolla/venv/lib/python3.9/site-packages/flask_restful/__init__.py", line 582, in dispatch_request
2023-03-15 13:26:29.698 27 ERROR keystone.server.flask.application     resp = meth(*args, **kwargs)
2023-03-15 13:26:29.698 27 ERROR keystone.server.flask.application   File "/var/lib/kolla/venv/lib/python3.9/site-packages/keystone/api/users.py", line 182, in get
2023-03-15 13:26:29.698 27 ERROR keystone.server.flask.application     return self._get_user(user_id)
2023-03-15 13:26:29.698 27 ERROR keystone.server.flask.application   File "/var/lib/kolla/venv/lib/python3.9/site-packages/keystone/api/users.py", line 194, in _get_user
2023-03-15 13:26:29.698 27 ERROR keystone.server.flask.application     ref = PROVIDERS.identity_api.get_user(user_id)
2023-03-15 13:26:29.698 27 ERROR keystone.server.flask.application   File "/var/lib/kolla/venv/lib/python3.9/site-packages/keystone/common/manager.py", line 115, in wrapped
2023-03-15 13:26:29.698 27 ERROR keystone.server.flask.application     __ret_val = __f(*args, **kwargs)
2023-03-15 13:26:29.698 27 ERROR keystone.server.flask.application   File "/var/lib/kolla/venv/lib/python3.9/site-packages/keystone/identity/core.py", line 414, in wrapper
2023-03-15 13:26:29.698 27 ERROR keystone.server.flask.application     return f(self, *args, **kwargs)
2023-03-15 13:26:29.698 27 ERROR keystone.server.flask.application   File "/var/lib/kolla/venv/lib/python3.9/site-packages/keystone/identity/core.py", line 424, in wrapper
2023-03-15 13:26:29.698 27 ERROR keystone.server.flask.application     return f(self, *args, **kwargs)
2023-03-15 13:26:29.698 27 ERROR keystone.server.flask.application   File "/var/lib/kolla/venv/lib/python3.9/site-packages/decorator.py", line 232, in fun
2023-03-15 13:26:29.698 27 ERROR keystone.server.flask.application     return caller(func, *(extras + args), **kw)
2023-03-15 13:26:29.698 27 ERROR keystone.server.flask.application   File "/var/lib/kolla/venv/lib/python3.9/site-packages/dogpile/cache/region.py", line 1577, in get_or_create_for_user_func
2023-03-15 13:26:29.698 27 ERROR keystone.server.flask.application     return self.get_or_create(
2023-03-15 13:26:29.698 27 ERROR keystone.server.flask.application   File "/var/lib/kolla/venv/lib/python3.9/site-packages/dogpile/cache/region.py", line 1042, in get_or_create
2023-03-15 13:26:29.698 27 ERROR keystone.server.flask.application     with Lock(
2023-03-15 13:26:29.698 27 ERROR keystone.server.flask.application   File "/var/lib/kolla/venv/lib/python3.9/site-packages/dogpile/lock.py", line 185, in __enter__
2023-03-15 13:26:29.698 27 ERROR keystone.server.flask.application     return self._enter()
2023-03-15 13:26:29.698 27 ERROR keystone.server.flask.application   File "/var/lib/kolla/venv/lib/python3.9/site-packages/dogpile/lock.py", line 94, in _enter
2023-03-15 13:26:29.698 27 ERROR keystone.server.flask.application     generated = self._enter_create(value, createdtime)
2023-03-15 13:26:29.698 27 ERROR keystone.server.flask.application   File "/var/lib/kolla/venv/lib/python3.9/site-packages/dogpile/lock.py", line 178, in _enter_create
2023-03-15 13:26:29.698 27 ERROR keystone.server.flask.application     return self.creator()
2023-03-15 13:26:29.698 27 ERROR keystone.server.flask.application   File "/var/lib/kolla/venv/lib/python3.9/site-packages/dogpile/cache/region.py", line 995, in gen_value
2023-03-15 13:26:29.698 27 ERROR keystone.server.flask.application     created_value = creator(
2023-03-15 13:26:29.698 27 ERROR keystone.server.flask.application   File "/var/lib/kolla/venv/lib/python3.9/site-packages/keystone/identity/core.py", line 1011, in get_user
2023-03-15 13:26:29.698 27 ERROR keystone.server.flask.application     ref = driver.get_user(entity_id)
2023-03-15 13:26:29.698 27 ERROR keystone.server.flask.application   File "/var/lib/kolla/venv/lib/python3.9/site-packages/keystone/identity/backends/sql.py", line 200, in get_user
2023-03-15 13:26:29.698 27 ERROR keystone.server.flask.application     self._get_user(session, user_id).to_dict())
2023-03-15 13:26:29.698 27 ERROR keystone.server.flask.application   File "/var/lib/kolla/venv/lib/python3.9/site-packages/keystone/identity/backends/sql.py", line 194, in _get_user
2023-03-15 13:26:29.698 27 ERROR keystone.server.flask.application     raise exception.UserNotFound(user_id=user_id)
2023-03-15 13:26:29.698 27 ERROR keystone.server.flask.application keystone.exception.UserNotFound: Could not find user: ironic-inspector.
2023-03-15 13:26:29.698 27 ERROR keystone.server.flask.application 
2023-03-15 13:26:30.444 28 ERROR keystone.server.flask.application [None req-7d25c69d-c13d-46f9-bf72-499c7dff66cf 55310a9e3d274235956eebc732471ab7 - - all default -] Could not find project: service.: keystone.exception.ProjectNotFound: Could not find project: service.
2023-03-15 13:26:30.444 28 ERROR keystone.server.flask.application Traceback (most recent call last):
2023-03-15 13:26:30.444 28 ERROR keystone.server.flask.application   File "/var/lib/kolla/venv/lib/python3.9/site-packages/flask/app.py", line 1820, in full_dispatch_request
2023-03-15 13:26:30.444 28 ERROR keystone.server.flask.application     rv = self.dispatch_request()
2023-03-15 13:26:30.444 28 ERROR keystone.server.flask.application   File "/var/lib/kolla/venv/lib/python3.9/site-packages/flask/app.py", line 1796, in dispatch_request
2023-03-15 13:26:30.444 28 ERROR keystone.server.flask.application     return self.ensure_sync(self.view_functions[rule.endpoint])(**view_args)
2023-03-15 13:26:30.444 28 ERROR keystone.server.flask.application   File "/var/lib/kolla/venv/lib/python3.9/site-packages/flask_restful/__init__.py", line 467, in wrapper
2023-03-15 13:26:30.444 28 ERROR keystone.server.flask.application     resp = resource(*args, **kwargs)
2023-03-15 13:26:30.444 28 ERROR keystone.server.flask.application   File "/var/lib/kolla/venv/lib/python3.9/site-packages/flask/views.py", line 107, in view
2023-03-15 13:26:30.444 28 ERROR keystone.server.flask.application     return current_app.ensure_sync(self.dispatch_request)(**kwargs)
2023-03-15 13:26:30.444 28 ERROR keystone.server.flask.application   File "/var/lib/kolla/venv/lib/python3.9/site-packages/flask_restful/__init__.py", line 582, in dispatch_request
2023-03-15 13:26:30.444 28 ERROR keystone.server.flask.application     resp = meth(*args, **kwargs)
2023-03-15 13:26:30.444 28 ERROR keystone.server.flask.application   File "/var/lib/kolla/venv/lib/python3.9/site-packages/keystone/api/projects.py", line 151, in get
2023-03-15 13:26:30.444 28 ERROR keystone.server.flask.application     return self._get_project(project_id)
2023-03-15 13:26:30.444 28 ERROR keystone.server.flask.application   File "/var/lib/kolla/venv/lib/python3.9/site-packages/keystone/api/projects.py", line 107, in _get_project
2023-03-15 13:26:30.444 28 ERROR keystone.server.flask.application     project = PROVIDERS.resource_api.get_project(project_id)
2023-03-15 13:26:30.444 28 ERROR keystone.server.flask.application   File "/var/lib/kolla/venv/lib/python3.9/site-packages/keystone/common/manager.py", line 115, in wrapped
2023-03-15 13:26:30.444 28 ERROR keystone.server.flask.application     __ret_val = __f(*args, **kwargs)
2023-03-15 13:26:30.444 28 ERROR keystone.server.flask.application   File "/var/lib/kolla/venv/lib/python3.9/site-packages/decorator.py", line 232, in fun
2023-03-15 13:26:30.444 28 ERROR keystone.server.flask.application     return caller(func, *(extras + args), **kw)
2023-03-15 13:26:30.444 28 ERROR keystone.server.flask.application   File "/var/lib/kolla/venv/lib/python3.9/site-packages/dogpile/cache/region.py", line 1577, in get_or_create_for_user_func
2023-03-15 13:26:30.444 28 ERROR keystone.server.flask.application     return self.get_or_create(
2023-03-15 13:26:30.444 28 ERROR keystone.server.flask.application   File "/var/lib/kolla/venv/lib/python3.9/site-packages/dogpile/cache/region.py", line 1042, in get_or_create
2023-03-15 13:26:30.444 28 ERROR keystone.server.flask.application     with Lock(
2023-03-15 13:26:30.444 28 ERROR keystone.server.flask.application   File "/var/lib/kolla/venv/lib/python3.9/site-packages/dogpile/lock.py", line 185, in __enter__
2023-03-15 13:26:30.444 28 ERROR keystone.server.flask.application     return self._enter()
2023-03-15 13:26:30.444 28 ERROR keystone.server.flask.application   File "/var/lib/kolla/venv/lib/python3.9/site-packages/dogpile/lock.py", line 94, in _enter
2023-03-15 13:26:30.444 28 ERROR keystone.server.flask.application     generated = self._enter_create(value, createdtime)
2023-03-15 13:26:30.444 28 ERROR keystone.server.flask.application   File "/var/lib/kolla/venv/lib/python3.9/site-packages/dogpile/lock.py", line 178, in _enter_create
2023-03-15 13:26:30.444 28 ERROR keystone.server.flask.application     return self.creator()
2023-03-15 13:26:30.444 28 ERROR keystone.server.flask.application   File "/var/lib/kolla/venv/lib/python3.9/site-packages/dogpile/cache/region.py", line 995, in gen_value
2023-03-15 13:26:30.444 28 ERROR keystone.server.flask.application     created_value = creator(
2023-03-15 13:26:30.444 28 ERROR keystone.server.flask.application   File "/var/lib/kolla/venv/lib/python3.9/site-packages/keystone/resource/core.py", line 903, in get_project
2023-03-15 13:26:30.444 28 ERROR keystone.server.flask.application     return self.driver.get_project(project_id)
2023-03-15 13:26:30.444 28 ERROR keystone.server.flask.application   File "/var/lib/kolla/venv/lib/python3.9/site-packages/keystone/resource/backends/sql.py", line 49, in get_project
2023-03-15 13:26:30.444 28 ERROR keystone.server.flask.application     return self._get_project(session, project_id).to_dict()
2023-03-15 13:26:30.444 28 ERROR keystone.server.flask.application   File "/var/lib/kolla/venv/lib/python3.9/site-packages/keystone/resource/backends/sql.py", line 44, in _get_project
2023-03-15 13:26:30.444 28 ERROR keystone.server.flask.application     raise exception.ProjectNotFound(project_id=project_id)
2023-03-15 13:26:30.444 28 ERROR keystone.server.flask.application keystone.exception.ProjectNotFound: Could not find project: service.
2023-03-15 13:26:30.444 28 ERROR keystone.server.flask.application 
2023-03-15 13:30:02.378 26 ERROR keystone.server.flask.application [None req-1805bf88-3c98-41c8-88aa-ce3f1dfb181d 55310a9e3d274235956eebc732471ab7 - - all default -] Could not find project: service.: keystone.exception.ProjectNotFound: Could not find project: service.
2023-03-15 13:30:02.378 26 ERROR keystone.server.flask.application Traceback (most recent call last):
2023-03-15 13:30:02.378 26 ERROR keystone.server.flask.application   File "/var/lib/kolla/venv/lib/python3.9/site-packages/flask/app.py", line 1820, in full_dispatch_request
2023-03-15 13:30:02.378 26 ERROR keystone.server.flask.application     rv = self.dispatch_request()
2023-03-15 13:30:02.378 26 ERROR keystone.server.flask.application   File "/var/lib/kolla/venv/lib/python3.9/site-packages/flask/app.py", line 1796, in dispatch_request
2023-03-15 13:30:02.378 26 ERROR keystone.server.flask.application     return self.ensure_sync(self.view_functions[rule.endpoint])(**view_args)
2023-03-15 13:30:02.378 26 ERROR keystone.server.flask.application   File "/var/lib/kolla/venv/lib/python3.9/site-packages/flask_restful/__init__.py", line 467, in wrapper
2023-03-15 13:30:02.378 26 ERROR keystone.server.flask.application     resp = resource(*args, **kwargs)
2023-03-15 13:30:02.378 26 ERROR keystone.server.flask.application   File "/var/lib/kolla/venv/lib/python3.9/site-packages/flask/views.py", line 107, in view
2023-03-15 13:30:02.378 26 ERROR keystone.server.flask.application     return current_app.ensure_sync(self.dispatch_request)(**kwargs)
2023-03-15 13:30:02.378 26 ERROR keystone.server.flask.application   File "/var/lib/kolla/venv/lib/python3.9/site-packages/flask_restful/__init__.py", line 582, in dispatch_request
2023-03-15 13:30:02.378 26 ERROR keystone.server.flask.application     resp = meth(*args, **kwargs)
2023-03-15 13:30:02.378 26 ERROR keystone.server.flask.application   File "/var/lib/kolla/venv/lib/python3.9/site-packages/keystone/api/projects.py", line 151, in get
2023-03-15 13:30:02.378 26 ERROR keystone.server.flask.application     return self._get_project(project_id)
2023-03-15 13:30:02.378 26 ERROR keystone.server.flask.application   File "/var/lib/kolla/venv/lib/python3.9/site-packages/keystone/api/projects.py", line 107, in _get_project
2023-03-15 13:30:02.378 26 ERROR keystone.server.flask.application     project = PROVIDERS.resource_api.get_project(project_id)
2023-03-15 13:30:02.378 26 ERROR keystone.server.flask.application   File "/var/lib/kolla/venv/lib/python3.9/site-packages/keystone/common/manager.py", line 115, in wrapped
2023-03-15 13:30:02.378 26 ERROR keystone.server.flask.application     __ret_val = __f(*args, **kwargs)
2023-03-15 13:30:02.378 26 ERROR keystone.server.flask.application   File "/var/lib/kolla/venv/lib/python3.9/site-packages/decorator.py", line 232, in fun
2023-03-15 13:30:02.378 26 ERROR keystone.server.flask.application     return caller(func, *(extras + args), **kw)
2023-03-15 13:30:02.378 26 ERROR keystone.server.flask.application   File "/var/lib/kolla/venv/lib/python3.9/site-packages/dogpile/cache/region.py", line 1577, in get_or_create_for_user_func
2023-03-15 13:30:02.378 26 ERROR keystone.server.flask.application     return self.get_or_create(
2023-03-15 13:30:02.378 26 ERROR keystone.server.flask.application   File "/var/lib/kolla/venv/lib/python3.9/site-packages/dogpile/cache/region.py", line 1042, in get_or_create
2023-03-15 13:30:02.378 26 ERROR keystone.server.flask.application     with Lock(
2023-03-15 13:30:02.378 26 ERROR keystone.server.flask.application   File "/var/lib/kolla/venv/lib/python3.9/site-packages/dogpile/lock.py", line 185, in __enter__
2023-03-15 13:30:02.378 26 ERROR keystone.server.flask.application     return self._enter()
2023-03-15 13:30:02.378 26 ERROR keystone.server.flask.application   File "/var/lib/kolla/venv/lib/python3.9/site-packages/dogpile/lock.py", line 94, in _enter
2023-03-15 13:30:02.378 26 ERROR keystone.server.flask.application     generated = self._enter_create(value, createdtime)
2023-03-15 13:30:02.378 26 ERROR keystone.server.flask.application   File "/var/lib/kolla/venv/lib/python3.9/site-packages/dogpile/lock.py", line 178, in _enter_create
2023-03-15 13:30:02.378 26 ERROR keystone.server.flask.application     return self.creator()
2023-03-15 13:30:02.378 26 ERROR keystone.server.flask.application   File "/var/lib/kolla/venv/lib/python3.9/site-packages/dogpile/cache/region.py", line 995, in gen_value
2023-03-15 13:30:02.378 26 ERROR keystone.server.flask.application     created_value = creator(
2023-03-15 13:30:02.378 26 ERROR keystone.server.flask.application   File "/var/lib/kolla/venv/lib/python3.9/site-packages/keystone/resource/core.py", line 903, in get_project
2023-03-15 13:30:02.378 26 ERROR keystone.server.flask.application     return self.driver.get_project(project_id)
2023-03-15 13:30:02.378 26 ERROR keystone.server.flask.application   File "/var/lib/kolla/venv/lib/python3.9/site-packages/keystone/resource/backends/sql.py", line 49, in get_project
2023-03-15 13:30:02.378 26 ERROR keystone.server.flask.application     return self._get_project(session, project_id).to_dict()
2023-03-15 13:30:02.378 26 ERROR keystone.server.flask.application   File "/var/lib/kolla/venv/lib/python3.9/site-packages/keystone/resource/backends/sql.py", line 44, in _get_project
2023-03-15 13:30:02.378 26 ERROR keystone.server.flask.application     raise exception.ProjectNotFound(project_id=project_id)
2023-03-15 13:30:02.378 26 ERROR keystone.server.flask.application keystone.exception.ProjectNotFound: Could not find project: service.
2023-03-15 13:30:02.378 26 ERROR keystone.server.flask.application 
2023-03-15 13:30:18.561 27 ERROR keystone.server.flask.application [None req-79aec103-ae3f-4f18-9e5a-dd9ed0cb71a4 55310a9e3d274235956eebc732471ab7 - - all default -] Could not find role: admin.: keystone.exception.RoleNotFound: Could not find role: admin.
2023-03-15 13:30:18.561 27 ERROR keystone.server.flask.application Traceback (most recent call last):
2023-03-15 13:30:18.561 27 ERROR keystone.server.flask.application   File "/var/lib/kolla/venv/lib/python3.9/site-packages/flask/app.py", line 1820, in full_dispatch_request
2023-03-15 13:30:18.561 27 ERROR keystone.server.flask.application     rv = self.dispatch_request()
2023-03-15 13:30:18.561 27 ERROR keystone.server.flask.application   File "/var/lib/kolla/venv/lib/python3.9/site-packages/flask/app.py", line 1796, in dispatch_request
2023-03-15 13:30:18.561 27 ERROR keystone.server.flask.application     return self.ensure_sync(self.view_functions[rule.endpoint])(**view_args)
2023-03-15 13:30:18.561 27 ERROR keystone.server.flask.application   File "/var/lib/kolla/venv/lib/python3.9/site-packages/flask_restful/__init__.py", line 467, in wrapper
2023-03-15 13:30:18.561 27 ERROR keystone.server.flask.application     resp = resource(*args, **kwargs)
2023-03-15 13:30:18.561 27 ERROR keystone.server.flask.application   File "/var/lib/kolla/venv/lib/python3.9/site-packages/flask/views.py", line 107, in view
2023-03-15 13:30:18.561 27 ERROR keystone.server.flask.application     return current_app.ensure_sync(self.dispatch_request)(**kwargs)
2023-03-15 13:30:18.561 27 ERROR keystone.server.flask.application   File "/var/lib/kolla/venv/lib/python3.9/site-packages/flask_restful/__init__.py", line 582, in dispatch_request
2023-03-15 13:30:18.561 27 ERROR keystone.server.flask.application     resp = meth(*args, **kwargs)
2023-03-15 13:30:18.561 27 ERROR keystone.server.flask.application   File "/var/lib/kolla/venv/lib/python3.9/site-packages/keystone/api/roles.py", line 50, in get
2023-03-15 13:30:18.561 27 ERROR keystone.server.flask.application     return self._get_role(role_id)
2023-03-15 13:30:18.561 27 ERROR keystone.server.flask.application   File "/var/lib/kolla/venv/lib/python3.9/site-packages/keystone/api/roles.py", line 70, in _get_role
2023-03-15 13:30:18.561 27 ERROR keystone.server.flask.application     ENFORCER.enforce_call(action='identity:get_role')
2023-03-15 13:30:18.561 27 ERROR keystone.server.flask.application   File "/var/lib/kolla/venv/lib/python3.9/site-packages/keystone/common/rbac_enforcer/enforcer.py", line 402, in enforce_call
2023-03-15 13:30:18.561 27 ERROR keystone.server.flask.application     policy_dict.update(cls._extract_member_target_data(
2023-03-15 13:30:18.561 27 ERROR keystone.server.flask.application   File "/var/lib/kolla/venv/lib/python3.9/site-packages/keystone/common/rbac_enforcer/enforcer.py", line 234, in _extract_member_target_data
2023-03-15 13:30:18.561 27 ERROR keystone.server.flask.application     member_name: func(flask.request.view_args[key])
2023-03-15 13:30:18.561 27 ERROR keystone.server.flask.application   File "/var/lib/kolla/venv/lib/python3.9/site-packages/keystone/common/manager.py", line 115, in wrapped
2023-03-15 13:30:18.561 27 ERROR keystone.server.flask.application     __ret_val = __f(*args, **kwargs)
2023-03-15 13:30:18.561 27 ERROR keystone.server.flask.application   File "/var/lib/kolla/venv/lib/python3.9/site-packages/decorator.py", line 232, in fun
2023-03-15 13:30:18.561 27 ERROR keystone.server.flask.application     return caller(func, *(extras + args), **kw)
2023-03-15 13:30:18.561 27 ERROR keystone.server.flask.application   File "/var/lib/kolla/venv/lib/python3.9/site-packages/dogpile/cache/region.py", line 1577, in get_or_create_for_user_func
2023-03-15 13:30:18.561 27 ERROR keystone.server.flask.application     return self.get_or_create(
2023-03-15 13:30:18.561 27 ERROR keystone.server.flask.application   File "/var/lib/kolla/venv/lib/python3.9/site-packages/dogpile/cache/region.py", line 1042, in get_or_create
2023-03-15 13:30:18.561 27 ERROR keystone.server.flask.application     with Lock(
2023-03-15 13:30:18.561 27 ERROR keystone.server.flask.application   File "/var/lib/kolla/venv/lib/python3.9/site-packages/dogpile/lock.py", line 185, in __enter__
2023-03-15 13:30:18.561 27 ERROR keystone.server.flask.application     return self._enter()
2023-03-15 13:30:18.561 27 ERROR keystone.server.flask.application   File "/var/lib/kolla/venv/lib/python3.9/site-packages/dogpile/lock.py", line 94, in _enter
2023-03-15 13:30:18.561 27 ERROR keystone.server.flask.application     generated = self._enter_create(value, createdtime)
2023-03-15 13:30:18.561 27 ERROR keystone.server.flask.application   File "/var/lib/kolla/venv/lib/python3.9/site-packages/dogpile/lock.py", line 178, in _enter_create
2023-03-15 13:30:18.561 27 ERROR keystone.server.flask.application     return self.creator()
2023-03-15 13:30:18.561 27 ERROR keystone.server.flask.application   File "/var/lib/kolla/venv/lib/python3.9/site-packages/dogpile/cache/region.py", line 995, in gen_value
2023-03-15 13:30:18.561 27 ERROR keystone.server.flask.application     created_value = creator(
2023-03-15 13:30:18.561 27 ERROR keystone.server.flask.application   File "/var/lib/kolla/venv/lib/python3.9/site-packages/keystone/assignment/core.py", line 1276, in get_role
2023-03-15 13:30:18.561 27 ERROR keystone.server.flask.application     return self.driver.get_role(role_id)
2023-03-15 13:30:18.561 27 ERROR keystone.server.flask.application   File "/var/lib/kolla/venv/lib/python3.9/site-packages/keystone/assignment/role_backends/sql.py", line 70, in get_role
2023-03-15 13:30:18.561 27 ERROR keystone.server.flask.application     return self._get_role(session, role_id).to_dict()
2023-03-15 13:30:18.561 27 ERROR keystone.server.flask.application   File "/var/lib/kolla/venv/lib/python3.9/site-packages/keystone/assignment/role_backends/sql.py", line 65, in _get_role
2023-03-15 13:30:18.561 27 ERROR keystone.server.flask.application     raise exception.RoleNotFound(role_id=role_id)
2023-03-15 13:30:18.561 27 ERROR keystone.server.flask.application keystone.exception.RoleNotFound: Could not find role: admin.
2023-03-15 13:30:18.561 27 ERROR keystone.server.flask.application 
2023-03-15 13:30:19.673 27 ERROR keystone.server.flask.application [None req-a67ac7d4-6d51-47b6-8e79-d993b1fc5690 55310a9e3d274235956eebc732471ab7 - - all default -] Could not find user: neutron.: keystone.exception.UserNotFound: Could not find user: neutron.
2023-03-15 13:30:19.673 27 ERROR keystone.server.flask.application Traceback (most recent call last):
2023-03-15 13:30:19.673 27 ERROR keystone.server.flask.application   File "/var/lib/kolla/venv/lib/python3.9/site-packages/flask/app.py", line 1820, in full_dispatch_request
2023-03-15 13:30:19.673 27 ERROR keystone.server.flask.application     rv = self.dispatch_request()
2023-03-15 13:30:19.673 27 ERROR keystone.server.flask.application   File "/var/lib/kolla/venv/lib/python3.9/site-packages/flask/app.py", line 1796, in dispatch_request
2023-03-15 13:30:19.673 27 ERROR keystone.server.flask.application     return self.ensure_sync(self.view_functions[rule.endpoint])(**view_args)
2023-03-15 13:30:19.673 27 ERROR keystone.server.flask.application   File "/var/lib/kolla/venv/lib/python3.9/site-packages/flask_restful/__init__.py", line 467, in wrapper
2023-03-15 13:30:19.673 27 ERROR keystone.server.flask.application     resp = resource(*args, **kwargs)
2023-03-15 13:30:19.673 27 ERROR keystone.server.flask.application   File "/var/lib/kolla/venv/lib/python3.9/site-packages/flask/views.py", line 107, in view
2023-03-15 13:30:19.673 27 ERROR keystone.server.flask.application     return current_app.ensure_sync(self.dispatch_request)(**kwargs)
2023-03-15 13:30:19.673 27 ERROR keystone.server.flask.application   File "/var/lib/kolla/venv/lib/python3.9/site-packages/flask_restful/__init__.py", line 582, in dispatch_request
2023-03-15 13:30:19.673 27 ERROR keystone.server.flask.application     resp = meth(*args, **kwargs)
2023-03-15 13:30:19.673 27 ERROR keystone.server.flask.application   File "/var/lib/kolla/venv/lib/python3.9/site-packages/keystone/api/users.py", line 182, in get
2023-03-15 13:30:19.673 27 ERROR keystone.server.flask.application     return self._get_user(user_id)
2023-03-15 13:30:19.673 27 ERROR keystone.server.flask.application   File "/var/lib/kolla/venv/lib/python3.9/site-packages/keystone/api/users.py", line 194, in _get_user
2023-03-15 13:30:19.673 27 ERROR keystone.server.flask.application     ref = PROVIDERS.identity_api.get_user(user_id)
2023-03-15 13:30:19.673 27 ERROR keystone.server.flask.application   File "/var/lib/kolla/venv/lib/python3.9/site-packages/keystone/common/manager.py", line 115, in wrapped
2023-03-15 13:30:19.673 27 ERROR keystone.server.flask.application     __ret_val = __f(*args, **kwargs)
2023-03-15 13:30:19.673 27 ERROR keystone.server.flask.application   File "/var/lib/kolla/venv/lib/python3.9/site-packages/keystone/identity/core.py", line 414, in wrapper
2023-03-15 13:30:19.673 27 ERROR keystone.server.flask.application     return f(self, *args, **kwargs)
2023-03-15 13:30:19.673 27 ERROR keystone.server.flask.application   File "/var/lib/kolla/venv/lib/python3.9/site-packages/keystone/identity/core.py", line 424, in wrapper
2023-03-15 13:30:19.673 27 ERROR keystone.server.flask.application     return f(self, *args, **kwargs)
2023-03-15 13:30:19.673 27 ERROR keystone.server.flask.application   File "/var/lib/kolla/venv/lib/python3.9/site-packages/decorator.py", line 232, in fun
2023-03-15 13:30:19.673 27 ERROR keystone.server.flask.application     return caller(func, *(extras + args), **kw)
2023-03-15 13:30:19.673 27 ERROR keystone.server.flask.application   File "/var/lib/kolla/venv/lib/python3.9/site-packages/dogpile/cache/region.py", line 1577, in get_or_create_for_user_func
2023-03-15 13:30:19.673 27 ERROR keystone.server.flask.application     return self.get_or_create(
2023-03-15 13:30:19.673 27 ERROR keystone.server.flask.application   File "/var/lib/kolla/venv/lib/python3.9/site-packages/dogpile/cache/region.py", line 1042, in get_or_create
2023-03-15 13:30:19.673 27 ERROR keystone.server.flask.application     with Lock(
2023-03-15 13:30:19.673 27 ERROR keystone.server.flask.application   File "/var/lib/kolla/venv/lib/python3.9/site-packages/dogpile/lock.py", line 185, in __enter__
2023-03-15 13:30:19.673 27 ERROR keystone.server.flask.application     return self._enter()
2023-03-15 13:30:19.673 27 ERROR keystone.server.flask.application   File "/var/lib/kolla/venv/lib/python3.9/site-packages/dogpile/lock.py", line 94, in _enter
2023-03-15 13:30:19.673 27 ERROR keystone.server.flask.application     generated = self._enter_create(value, createdtime)
2023-03-15 13:30:19.673 27 ERROR keystone.server.flask.application   File "/var/lib/kolla/venv/lib/python3.9/site-packages/dogpile/lock.py", line 178, in _enter_create
2023-03-15 13:30:19.673 27 ERROR keystone.server.flask.application     return self.creator()
2023-03-15 13:30:19.673 27 ERROR keystone.server.flask.application   File "/var/lib/kolla/venv/lib/python3.9/site-packages/dogpile/cache/region.py", line 995, in gen_value
2023-03-15 13:30:19.673 27 ERROR keystone.server.flask.application     created_value = creator(
2023-03-15 13:30:19.673 27 ERROR keystone.server.flask.application   File "/var/lib/kolla/venv/lib/python3.9/site-packages/keystone/identity/core.py", line 1011, in get_user
2023-03-15 13:30:19.673 27 ERROR keystone.server.flask.application     ref = driver.get_user(entity_id)
2023-03-15 13:30:19.673 27 ERROR keystone.server.flask.application   File "/var/lib/kolla/venv/lib/python3.9/site-packages/keystone/identity/backends/sql.py", line 200, in get_user
2023-03-15 13:30:19.673 27 ERROR keystone.server.flask.application     self._get_user(session, user_id).to_dict())
2023-03-15 13:30:19.673 27 ERROR keystone.server.flask.application   File "/var/lib/kolla/venv/lib/python3.9/site-packages/keystone/identity/backends/sql.py", line 194, in _get_user
2023-03-15 13:30:19.673 27 ERROR keystone.server.flask.application     raise exception.UserNotFound(user_id=user_id)
2023-03-15 13:30:19.673 27 ERROR keystone.server.flask.application keystone.exception.UserNotFound: Could not find user: neutron.
2023-03-15 13:30:19.673 27 ERROR keystone.server.flask.application 
2023-03-15 13:30:20.678 28 ERROR keystone.server.flask.application [None req-302fe0b6-6acd-4559-89ec-f6a1cba50875 55310a9e3d274235956eebc732471ab7 - - all default -] Could not find project: service.: keystone.exception.ProjectNotFound: Could not find project: service.
2023-03-15 13:30:20.678 28 ERROR keystone.server.flask.application Traceback (most recent call last):
2023-03-15 13:30:20.678 28 ERROR keystone.server.flask.application   File "/var/lib/kolla/venv/lib/python3.9/site-packages/flask/app.py", line 1820, in full_dispatch_request
2023-03-15 13:30:20.678 28 ERROR keystone.server.flask.application     rv = self.dispatch_request()
2023-03-15 13:30:20.678 28 ERROR keystone.server.flask.application   File "/var/lib/kolla/venv/lib/python3.9/site-packages/flask/app.py", line 1796, in dispatch_request
2023-03-15 13:30:20.678 28 ERROR keystone.server.flask.application     return self.ensure_sync(self.view_functions[rule.endpoint])(**view_args)
2023-03-15 13:30:20.678 28 ERROR keystone.server.flask.application   File "/var/lib/kolla/venv/lib/python3.9/site-packages/flask_restful/__init__.py", line 467, in wrapper
2023-03-15 13:30:20.678 28 ERROR keystone.server.flask.application     resp = resource(*args, **kwargs)
2023-03-15 13:30:20.678 28 ERROR keystone.server.flask.application   File "/var/lib/kolla/venv/lib/python3.9/site-packages/flask/views.py", line 107, in view
2023-03-15 13:30:20.678 28 ERROR keystone.server.flask.application     return current_app.ensure_sync(self.dispatch_request)(**kwargs)
2023-03-15 13:30:20.678 28 ERROR keystone.server.flask.application   File "/var/lib/kolla/venv/lib/python3.9/site-packages/flask_restful/__init__.py", line 582, in dispatch_request
2023-03-15 13:30:20.678 28 ERROR keystone.server.flask.application     resp = meth(*args, **kwargs)
2023-03-15 13:30:20.678 28 ERROR keystone.server.flask.application   File "/var/lib/kolla/venv/lib/python3.9/site-packages/keystone/api/projects.py", line 151, in get
2023-03-15 13:30:20.678 28 ERROR keystone.server.flask.application     return self._get_project(project_id)
2023-03-15 13:30:20.678 28 ERROR keystone.server.flask.application   File "/var/lib/kolla/venv/lib/python3.9/site-packages/keystone/api/projects.py", line 107, in _get_project
2023-03-15 13:30:20.678 28 ERROR keystone.server.flask.application     project = PROVIDERS.resource_api.get_project(project_id)
2023-03-15 13:30:20.678 28 ERROR keystone.server.flask.application   File "/var/lib/kolla/venv/lib/python3.9/site-packages/keystone/common/manager.py", line 115, in wrapped
2023-03-15 13:30:20.678 28 ERROR keystone.server.flask.application     __ret_val = __f(*args, **kwargs)
2023-03-15 13:30:20.678 28 ERROR keystone.server.flask.application   File "/var/lib/kolla/venv/lib/python3.9/site-packages/decorator.py", line 232, in fun
2023-03-15 13:30:20.678 28 ERROR keystone.server.flask.application     return caller(func, *(extras + args), **kw)
2023-03-15 13:30:20.678 28 ERROR keystone.server.flask.application   File "/var/lib/kolla/venv/lib/python3.9/site-packages/dogpile/cache/region.py", line 1577, in get_or_create_for_user_func
2023-03-15 13:30:20.678 28 ERROR keystone.server.flask.application     return self.get_or_create(
2023-03-15 13:30:20.678 28 ERROR keystone.server.flask.application   File "/var/lib/kolla/venv/lib/python3.9/site-packages/dogpile/cache/region.py", line 1042, in get_or_create
2023-03-15 13:30:20.678 28 ERROR keystone.server.flask.application     with Lock(
2023-03-15 13:30:20.678 28 ERROR keystone.server.flask.application   File "/var/lib/kolla/venv/lib/python3.9/site-packages/dogpile/lock.py", line 185, in __enter__
2023-03-15 13:30:20.678 28 ERROR keystone.server.flask.application     return self._enter()
2023-03-15 13:30:20.678 28 ERROR keystone.server.flask.application   File "/var/lib/kolla/venv/lib/python3.9/site-packages/dogpile/lock.py", line 94, in _enter
2023-03-15 13:30:20.678 28 ERROR keystone.server.flask.application     generated = self._enter_create(value, createdtime)
2023-03-15 13:30:20.678 28 ERROR keystone.server.flask.application   File "/var/lib/kolla/venv/lib/python3.9/site-packages/dogpile/lock.py", line 178, in _enter_create
2023-03-15 13:30:20.678 28 ERROR keystone.server.flask.application     return self.creator()
2023-03-15 13:30:20.678 28 ERROR keystone.server.flask.application   File "/var/lib/kolla/venv/lib/python3.9/site-packages/dogpile/cache/region.py", line 995, in gen_value
2023-03-15 13:30:20.678 28 ERROR keystone.server.flask.application     created_value = creator(
2023-03-15 13:30:20.678 28 ERROR keystone.server.flask.application   File "/var/lib/kolla/venv/lib/python3.9/site-packages/keystone/resource/core.py", line 903, in get_project
2023-03-15 13:30:20.678 28 ERROR keystone.server.flask.application     return self.driver.get_project(project_id)
2023-03-15 13:30:20.678 28 ERROR keystone.server.flask.application   File "/var/lib/kolla/venv/lib/python3.9/site-packages/keystone/resource/backends/sql.py", line 49, in get_project
2023-03-15 13:30:20.678 28 ERROR keystone.server.flask.application     return self._get_project(session, project_id).to_dict()
2023-03-15 13:30:20.678 28 ERROR keystone.server.flask.application   File "/var/lib/kolla/venv/lib/python3.9/site-packages/keystone/resource/backends/sql.py", line 44, in _get_project
2023-03-15 13:30:20.678 28 ERROR keystone.server.flask.application     raise exception.ProjectNotFound(project_id=project_id)
2023-03-15 13:30:20.678 28 ERROR keystone.server.flask.application keystone.exception.ProjectNotFound: Could not find project: service.
2023-03-15 13:30:20.678 28 ERROR keystone.server.flask.application 
