2023-03-02 18:22:13.441 23 INFO alembic.runtime.migration [-] Context impl MySQLImpl.
2023-03-02 18:22:13.442 23 INFO alembic.runtime.migration [-] Will assume non-transactional DDL.
2023-03-02 18:22:13.482 23 INFO alembic.runtime.migration [-] Context impl MySQLImpl.
2023-03-02 18:22:13.482 23 INFO alembic.runtime.migration [-] Will assume non-transactional DDL.
2023-03-02 18:22:13.526 23 INFO alembic.runtime.migration [-] Running upgrade  -> 27e647c0fad4, Initial version.
2023-03-02 18:22:14.800 23 INFO alembic.runtime.migration [-] Running upgrade 27e647c0fad4 -> e25ffa003242, Initial no-op Yoga contract migration.
2023-03-02 18:22:14.831 23 INFO alembic.runtime.migration [-] Running upgrade 27e647c0fad4 -> 29e87d24a316, Initial no-op Yoga expand migration.
2023-03-02 18:22:23.388 8 INFO keystone.common.fernet_utils [-] Created a new temporary key: /etc/keystone/fernet-keys/0.tmp
2023-03-02 18:22:23.392 8 INFO keystone.common.fernet_utils [-] Become a valid new key: /etc/keystone/fernet-keys/0
2023-03-02 18:22:23.393 8 INFO keystone.common.fernet_utils [-] Starting key rotation with 1 key files: ['/etc/keystone/fernet-keys/0']
2023-03-02 18:22:23.394 8 INFO keystone.common.fernet_utils [-] Created a new temporary key: /etc/keystone/fernet-keys/0.tmp
2023-03-02 18:22:23.395 8 INFO keystone.common.fernet_utils [-] Current primary key is: 0
2023-03-02 18:22:23.395 8 INFO keystone.common.fernet_utils [-] Next primary key will be: 1
2023-03-02 18:22:23.396 8 INFO keystone.common.fernet_utils [-] Promoted key 0 to be the primary: 1
2023-03-02 18:22:23.397 8 INFO keystone.common.fernet_utils [-] Become a valid new key: /etc/keystone/fernet-keys/0
2023-03-02 18:22:42.533 32 INFO keystone.cmd.bootstrap [None req-168e1848-5416-45f3-a73d-d570b701c1fd - - - - - -] Created domain default
2023-03-02 18:22:42.602 32 INFO keystone.cmd.bootstrap [None req-168e1848-5416-45f3-a73d-d570b701c1fd - - - - - -] Created project admin
2023-03-02 18:22:43.205 32 INFO keystone.cmd.bootstrap [None req-168e1848-5416-45f3-a73d-d570b701c1fd - - - - - -] Created user admin
2023-03-02 18:22:43.227 32 INFO keystone.cmd.bootstrap [None req-168e1848-5416-45f3-a73d-d570b701c1fd - - - - - -] Created role reader
2023-03-02 18:22:43.245 32 INFO keystone.cmd.bootstrap [None req-168e1848-5416-45f3-a73d-d570b701c1fd - - - - - -] Created role member
2023-03-02 18:22:43.294 32 INFO keystone.cmd.bootstrap [None req-168e1848-5416-45f3-a73d-d570b701c1fd - - - - - -] Created implied role where 9d1ca9dd9f6e43a68b247c8d761fd1eb implies 8a6b684d48fd4eb7b51a0594982a20ee
2023-03-02 18:22:43.323 32 INFO keystone.cmd.bootstrap [None req-168e1848-5416-45f3-a73d-d570b701c1fd - - - - - -] Created role admin
2023-03-02 18:22:43.353 32 INFO keystone.cmd.bootstrap [None req-168e1848-5416-45f3-a73d-d570b701c1fd - - - - - -] Created implied role where 8c50de03d94e435b93ad4e1c792b259c implies 9d1ca9dd9f6e43a68b247c8d761fd1eb
2023-03-02 18:22:43.372 32 INFO keystone.cmd.bootstrap [None req-168e1848-5416-45f3-a73d-d570b701c1fd - - - - - -] Granted role admin on project admin to user admin.
2023-03-02 18:22:43.383 32 INFO keystone.cmd.bootstrap [None req-168e1848-5416-45f3-a73d-d570b701c1fd - - - - - -] Granted role admin on the system to user admin.
2023-03-02 18:22:43.406 32 WARNING py.warnings [None req-168e1848-5416-45f3-a73d-d570b701c1fd - - - - - -] /var/lib/kolla/venv/lib/python3.9/site-packages/pycadf/identifier.py:71: UserWarning: Invalid uuid: RegionOne. To ensure interoperability, identifiers should be a valid uuid.
  warnings.warn(('Invalid uuid: %s. To ensure interoperability, '

2023-03-02 18:22:43.414 32 INFO keystone.cmd.bootstrap [None req-168e1848-5416-45f3-a73d-d570b701c1fd - - - - - -] Created region RegionOne
2023-03-02 18:22:43.466 32 INFO keystone.cmd.bootstrap [None req-168e1848-5416-45f3-a73d-d570b701c1fd - - - - - -] Created public endpoint http://169.16.1.176:5000
2023-03-02 18:22:43.482 32 INFO keystone.cmd.bootstrap [None req-168e1848-5416-45f3-a73d-d570b701c1fd - - - - - -] Created internal endpoint http://169.16.1.176:5000
2023-03-02 18:23:08.584 39 WARNING keystone.common.rbac_enforcer.enforcer [None req-9c9679d9-ee60-4756-9225-678694ab30b0 ab07bc931e7145edbac9433742ba552a - - all default -] Deprecated policy rules found. Use oslopolicy-policy-generator and oslopolicy-policy-upgrade to detect and resolve deprecated policies in your configuration.
2023-03-02 18:23:09.354 38 WARNING keystone.common.rbac_enforcer.enforcer [None req-8b1f9561-1cad-49c0-a5fd-5eba9c8b50f5 ab07bc931e7145edbac9433742ba552a - - all default -] Deprecated policy rules found. Use oslopolicy-policy-generator and oslopolicy-policy-upgrade to detect and resolve deprecated policies in your configuration.
2023-03-02 18:23:16.533 37 WARNING keystone.common.rbac_enforcer.enforcer [None req-251a4775-184c-41f9-b2fb-2bf3d9830478 ab07bc931e7145edbac9433742ba552a - - all default -] Deprecated policy rules found. Use oslopolicy-policy-generator and oslopolicy-policy-upgrade to detect and resolve deprecated policies in your configuration.
2023-03-02 18:24:32.469 39 ERROR keystone.server.flask.application [None req-460d8139-0f3d-4184-8277-ff93c30aa915 ab07bc931e7145edbac9433742ba552a - - all default -] Could not find project: service.: keystone.exception.ProjectNotFound: Could not find project: service.
2023-03-02 18:24:32.469 39 ERROR keystone.server.flask.application Traceback (most recent call last):
2023-03-02 18:24:32.469 39 ERROR keystone.server.flask.application   File "/var/lib/kolla/venv/lib/python3.9/site-packages/flask/app.py", line 1820, in full_dispatch_request
2023-03-02 18:24:32.469 39 ERROR keystone.server.flask.application     rv = self.dispatch_request()
2023-03-02 18:24:32.469 39 ERROR keystone.server.flask.application   File "/var/lib/kolla/venv/lib/python3.9/site-packages/flask/app.py", line 1796, in dispatch_request
2023-03-02 18:24:32.469 39 ERROR keystone.server.flask.application     return self.ensure_sync(self.view_functions[rule.endpoint])(**view_args)
2023-03-02 18:24:32.469 39 ERROR keystone.server.flask.application   File "/var/lib/kolla/venv/lib/python3.9/site-packages/flask_restful/__init__.py", line 467, in wrapper
2023-03-02 18:24:32.469 39 ERROR keystone.server.flask.application     resp = resource(*args, **kwargs)
2023-03-02 18:24:32.469 39 ERROR keystone.server.flask.application   File "/var/lib/kolla/venv/lib/python3.9/site-packages/flask/views.py", line 107, in view
2023-03-02 18:24:32.469 39 ERROR keystone.server.flask.application     return current_app.ensure_sync(self.dispatch_request)(**kwargs)
2023-03-02 18:24:32.469 39 ERROR keystone.server.flask.application   File "/var/lib/kolla/venv/lib/python3.9/site-packages/flask_restful/__init__.py", line 582, in dispatch_request
2023-03-02 18:24:32.469 39 ERROR keystone.server.flask.application     resp = meth(*args, **kwargs)
2023-03-02 18:24:32.469 39 ERROR keystone.server.flask.application   File "/var/lib/kolla/venv/lib/python3.9/site-packages/keystone/api/projects.py", line 151, in get
2023-03-02 18:24:32.469 39 ERROR keystone.server.flask.application     return self._get_project(project_id)
2023-03-02 18:24:32.469 39 ERROR keystone.server.flask.application   File "/var/lib/kolla/venv/lib/python3.9/site-packages/keystone/api/projects.py", line 107, in _get_project
2023-03-02 18:24:32.469 39 ERROR keystone.server.flask.application     project = PROVIDERS.resource_api.get_project(project_id)
2023-03-02 18:24:32.469 39 ERROR keystone.server.flask.application   File "/var/lib/kolla/venv/lib/python3.9/site-packages/keystone/common/manager.py", line 115, in wrapped
2023-03-02 18:24:32.469 39 ERROR keystone.server.flask.application     __ret_val = __f(*args, **kwargs)
2023-03-02 18:24:32.469 39 ERROR keystone.server.flask.application   File "/var/lib/kolla/venv/lib/python3.9/site-packages/decorator.py", line 232, in fun
2023-03-02 18:24:32.469 39 ERROR keystone.server.flask.application     return caller(func, *(extras + args), **kw)
2023-03-02 18:24:32.469 39 ERROR keystone.server.flask.application   File "/var/lib/kolla/venv/lib/python3.9/site-packages/dogpile/cache/region.py", line 1577, in get_or_create_for_user_func
2023-03-02 18:24:32.469 39 ERROR keystone.server.flask.application     return self.get_or_create(
2023-03-02 18:24:32.469 39 ERROR keystone.server.flask.application   File "/var/lib/kolla/venv/lib/python3.9/site-packages/dogpile/cache/region.py", line 1042, in get_or_create
2023-03-02 18:24:32.469 39 ERROR keystone.server.flask.application     with Lock(
2023-03-02 18:24:32.469 39 ERROR keystone.server.flask.application   File "/var/lib/kolla/venv/lib/python3.9/site-packages/dogpile/lock.py", line 185, in __enter__
2023-03-02 18:24:32.469 39 ERROR keystone.server.flask.application     return self._enter()
2023-03-02 18:24:32.469 39 ERROR keystone.server.flask.application   File "/var/lib/kolla/venv/lib/python3.9/site-packages/dogpile/lock.py", line 94, in _enter
2023-03-02 18:24:32.469 39 ERROR keystone.server.flask.application     generated = self._enter_create(value, createdtime)
2023-03-02 18:24:32.469 39 ERROR keystone.server.flask.application   File "/var/lib/kolla/venv/lib/python3.9/site-packages/dogpile/lock.py", line 178, in _enter_create
2023-03-02 18:24:32.469 39 ERROR keystone.server.flask.application     return self.creator()
2023-03-02 18:24:32.469 39 ERROR keystone.server.flask.application   File "/var/lib/kolla/venv/lib/python3.9/site-packages/dogpile/cache/region.py", line 995, in gen_value
2023-03-02 18:24:32.469 39 ERROR keystone.server.flask.application     created_value = creator(
2023-03-02 18:24:32.469 39 ERROR keystone.server.flask.application   File "/var/lib/kolla/venv/lib/python3.9/site-packages/keystone/resource/core.py", line 903, in get_project
2023-03-02 18:24:32.469 39 ERROR keystone.server.flask.application     return self.driver.get_project(project_id)
2023-03-02 18:24:32.469 39 ERROR keystone.server.flask.application   File "/var/lib/kolla/venv/lib/python3.9/site-packages/keystone/resource/backends/sql.py", line 49, in get_project
2023-03-02 18:24:32.469 39 ERROR keystone.server.flask.application     return self._get_project(session, project_id).to_dict()
2023-03-02 18:24:32.469 39 ERROR keystone.server.flask.application   File "/var/lib/kolla/venv/lib/python3.9/site-packages/keystone/resource/backends/sql.py", line 44, in _get_project
2023-03-02 18:24:32.469 39 ERROR keystone.server.flask.application     raise exception.ProjectNotFound(project_id=project_id)
2023-03-02 18:24:32.469 39 ERROR keystone.server.flask.application keystone.exception.ProjectNotFound: Could not find project: service.
2023-03-02 18:24:32.469 39 ERROR keystone.server.flask.application 
2023-03-02 18:24:41.398 37 ERROR keystone.server.flask.application [None req-063b2cfe-fb36-4e46-ada2-39d3730881bf ab07bc931e7145edbac9433742ba552a - - all default -] Could not find project: service.: keystone.exception.ProjectNotFound: Could not find project: service.
2023-03-02 18:24:41.398 37 ERROR keystone.server.flask.application Traceback (most recent call last):
2023-03-02 18:24:41.398 37 ERROR keystone.server.flask.application   File "/var/lib/kolla/venv/lib/python3.9/site-packages/flask/app.py", line 1820, in full_dispatch_request
2023-03-02 18:24:41.398 37 ERROR keystone.server.flask.application     rv = self.dispatch_request()
2023-03-02 18:24:41.398 37 ERROR keystone.server.flask.application   File "/var/lib/kolla/venv/lib/python3.9/site-packages/flask/app.py", line 1796, in dispatch_request
2023-03-02 18:24:41.398 37 ERROR keystone.server.flask.application     return self.ensure_sync(self.view_functions[rule.endpoint])(**view_args)
2023-03-02 18:24:41.398 37 ERROR keystone.server.flask.application   File "/var/lib/kolla/venv/lib/python3.9/site-packages/flask_restful/__init__.py", line 467, in wrapper
2023-03-02 18:24:41.398 37 ERROR keystone.server.flask.application     resp = resource(*args, **kwargs)
2023-03-02 18:24:41.398 37 ERROR keystone.server.flask.application   File "/var/lib/kolla/venv/lib/python3.9/site-packages/flask/views.py", line 107, in view
2023-03-02 18:24:41.398 37 ERROR keystone.server.flask.application     return current_app.ensure_sync(self.dispatch_request)(**kwargs)
2023-03-02 18:24:41.398 37 ERROR keystone.server.flask.application   File "/var/lib/kolla/venv/lib/python3.9/site-packages/flask_restful/__init__.py", line 582, in dispatch_request
2023-03-02 18:24:41.398 37 ERROR keystone.server.flask.application     resp = meth(*args, **kwargs)
2023-03-02 18:24:41.398 37 ERROR keystone.server.flask.application   File "/var/lib/kolla/venv/lib/python3.9/site-packages/keystone/api/projects.py", line 151, in get
2023-03-02 18:24:41.398 37 ERROR keystone.server.flask.application     return self._get_project(project_id)
2023-03-02 18:24:41.398 37 ERROR keystone.server.flask.application   File "/var/lib/kolla/venv/lib/python3.9/site-packages/keystone/api/projects.py", line 107, in _get_project
2023-03-02 18:24:41.398 37 ERROR keystone.server.flask.application     project = PROVIDERS.resource_api.get_project(project_id)
2023-03-02 18:24:41.398 37 ERROR keystone.server.flask.application   File "/var/lib/kolla/venv/lib/python3.9/site-packages/keystone/common/manager.py", line 115, in wrapped
2023-03-02 18:24:41.398 37 ERROR keystone.server.flask.application     __ret_val = __f(*args, **kwargs)
2023-03-02 18:24:41.398 37 ERROR keystone.server.flask.application   File "/var/lib/kolla/venv/lib/python3.9/site-packages/decorator.py", line 232, in fun
2023-03-02 18:24:41.398 37 ERROR keystone.server.flask.application     return caller(func, *(extras + args), **kw)
2023-03-02 18:24:41.398 37 ERROR keystone.server.flask.application   File "/var/lib/kolla/venv/lib/python3.9/site-packages/dogpile/cache/region.py", line 1577, in get_or_create_for_user_func
2023-03-02 18:24:41.398 37 ERROR keystone.server.flask.application     return self.get_or_create(
2023-03-02 18:24:41.398 37 ERROR keystone.server.flask.application   File "/var/lib/kolla/venv/lib/python3.9/site-packages/dogpile/cache/region.py", line 1042, in get_or_create
2023-03-02 18:24:41.398 37 ERROR keystone.server.flask.application     with Lock(
2023-03-02 18:24:41.398 37 ERROR keystone.server.flask.application   File "/var/lib/kolla/venv/lib/python3.9/site-packages/dogpile/lock.py", line 185, in __enter__
2023-03-02 18:24:41.398 37 ERROR keystone.server.flask.application     return self._enter()
2023-03-02 18:24:41.398 37 ERROR keystone.server.flask.application   File "/var/lib/kolla/venv/lib/python3.9/site-packages/dogpile/lock.py", line 94, in _enter
2023-03-02 18:24:41.398 37 ERROR keystone.server.flask.application     generated = self._enter_create(value, createdtime)
2023-03-02 18:24:41.398 37 ERROR keystone.server.flask.application   File "/var/lib/kolla/venv/lib/python3.9/site-packages/dogpile/lock.py", line 178, in _enter_create
2023-03-02 18:24:41.398 37 ERROR keystone.server.flask.application     return self.creator()
2023-03-02 18:24:41.398 37 ERROR keystone.server.flask.application   File "/var/lib/kolla/venv/lib/python3.9/site-packages/dogpile/cache/region.py", line 995, in gen_value
2023-03-02 18:24:41.398 37 ERROR keystone.server.flask.application     created_value = creator(
2023-03-02 18:24:41.398 37 ERROR keystone.server.flask.application   File "/var/lib/kolla/venv/lib/python3.9/site-packages/keystone/resource/core.py", line 903, in get_project
2023-03-02 18:24:41.398 37 ERROR keystone.server.flask.application     return self.driver.get_project(project_id)
2023-03-02 18:24:41.398 37 ERROR keystone.server.flask.application   File "/var/lib/kolla/venv/lib/python3.9/site-packages/keystone/resource/backends/sql.py", line 49, in get_project
2023-03-02 18:24:41.398 37 ERROR keystone.server.flask.application     return self._get_project(session, project_id).to_dict()
2023-03-02 18:24:41.398 37 ERROR keystone.server.flask.application   File "/var/lib/kolla/venv/lib/python3.9/site-packages/keystone/resource/backends/sql.py", line 44, in _get_project
2023-03-02 18:24:41.398 37 ERROR keystone.server.flask.application     raise exception.ProjectNotFound(project_id=project_id)
2023-03-02 18:24:41.398 37 ERROR keystone.server.flask.application keystone.exception.ProjectNotFound: Could not find project: service.
2023-03-02 18:24:41.398 37 ERROR keystone.server.flask.application 
2023-03-02 18:24:56.147 37 ERROR keystone.server.flask.application [None req-31aaa555-130b-4c4e-b680-13b83eae2727 ab07bc931e7145edbac9433742ba552a - - all default -] Could not find role: admin.: keystone.exception.RoleNotFound: Could not find role: admin.
2023-03-02 18:24:56.147 37 ERROR keystone.server.flask.application Traceback (most recent call last):
2023-03-02 18:24:56.147 37 ERROR keystone.server.flask.application   File "/var/lib/kolla/venv/lib/python3.9/site-packages/flask/app.py", line 1820, in full_dispatch_request
2023-03-02 18:24:56.147 37 ERROR keystone.server.flask.application     rv = self.dispatch_request()
2023-03-02 18:24:56.147 37 ERROR keystone.server.flask.application   File "/var/lib/kolla/venv/lib/python3.9/site-packages/flask/app.py", line 1796, in dispatch_request
2023-03-02 18:24:56.147 37 ERROR keystone.server.flask.application     return self.ensure_sync(self.view_functions[rule.endpoint])(**view_args)
2023-03-02 18:24:56.147 37 ERROR keystone.server.flask.application   File "/var/lib/kolla/venv/lib/python3.9/site-packages/flask_restful/__init__.py", line 467, in wrapper
2023-03-02 18:24:56.147 37 ERROR keystone.server.flask.application     resp = resource(*args, **kwargs)
2023-03-02 18:24:56.147 37 ERROR keystone.server.flask.application   File "/var/lib/kolla/venv/lib/python3.9/site-packages/flask/views.py", line 107, in view
2023-03-02 18:24:56.147 37 ERROR keystone.server.flask.application     return current_app.ensure_sync(self.dispatch_request)(**kwargs)
2023-03-02 18:24:56.147 37 ERROR keystone.server.flask.application   File "/var/lib/kolla/venv/lib/python3.9/site-packages/flask_restful/__init__.py", line 582, in dispatch_request
2023-03-02 18:24:56.147 37 ERROR keystone.server.flask.application     resp = meth(*args, **kwargs)
2023-03-02 18:24:56.147 37 ERROR keystone.server.flask.application   File "/var/lib/kolla/venv/lib/python3.9/site-packages/keystone/api/roles.py", line 50, in get
2023-03-02 18:24:56.147 37 ERROR keystone.server.flask.application     return self._get_role(role_id)
2023-03-02 18:24:56.147 37 ERROR keystone.server.flask.application   File "/var/lib/kolla/venv/lib/python3.9/site-packages/keystone/api/roles.py", line 70, in _get_role
2023-03-02 18:24:56.147 37 ERROR keystone.server.flask.application     ENFORCER.enforce_call(action='identity:get_role')
2023-03-02 18:24:56.147 37 ERROR keystone.server.flask.application   File "/var/lib/kolla/venv/lib/python3.9/site-packages/keystone/common/rbac_enforcer/enforcer.py", line 402, in enforce_call
2023-03-02 18:24:56.147 37 ERROR keystone.server.flask.application     policy_dict.update(cls._extract_member_target_data(
2023-03-02 18:24:56.147 37 ERROR keystone.server.flask.application   File "/var/lib/kolla/venv/lib/python3.9/site-packages/keystone/common/rbac_enforcer/enforcer.py", line 234, in _extract_member_target_data
2023-03-02 18:24:56.147 37 ERROR keystone.server.flask.application     member_name: func(flask.request.view_args[key])
2023-03-02 18:24:56.147 37 ERROR keystone.server.flask.application   File "/var/lib/kolla/venv/lib/python3.9/site-packages/keystone/common/manager.py", line 115, in wrapped
2023-03-02 18:24:56.147 37 ERROR keystone.server.flask.application     __ret_val = __f(*args, **kwargs)
2023-03-02 18:24:56.147 37 ERROR keystone.server.flask.application   File "/var/lib/kolla/venv/lib/python3.9/site-packages/decorator.py", line 232, in fun
2023-03-02 18:24:56.147 37 ERROR keystone.server.flask.application     return caller(func, *(extras + args), **kw)
2023-03-02 18:24:56.147 37 ERROR keystone.server.flask.application   File "/var/lib/kolla/venv/lib/python3.9/site-packages/dogpile/cache/region.py", line 1577, in get_or_create_for_user_func
2023-03-02 18:24:56.147 37 ERROR keystone.server.flask.application     return self.get_or_create(
2023-03-02 18:24:56.147 37 ERROR keystone.server.flask.application   File "/var/lib/kolla/venv/lib/python3.9/site-packages/dogpile/cache/region.py", line 1042, in get_or_create
2023-03-02 18:24:56.147 37 ERROR keystone.server.flask.application     with Lock(
2023-03-02 18:24:56.147 37 ERROR keystone.server.flask.application   File "/var/lib/kolla/venv/lib/python3.9/site-packages/dogpile/lock.py", line 185, in __enter__
2023-03-02 18:24:56.147 37 ERROR keystone.server.flask.application     return self._enter()
2023-03-02 18:24:56.147 37 ERROR keystone.server.flask.application   File "/var/lib/kolla/venv/lib/python3.9/site-packages/dogpile/lock.py", line 94, in _enter
2023-03-02 18:24:56.147 37 ERROR keystone.server.flask.application     generated = self._enter_create(value, createdtime)
2023-03-02 18:24:56.147 37 ERROR keystone.server.flask.application   File "/var/lib/kolla/venv/lib/python3.9/site-packages/dogpile/lock.py", line 178, in _enter_create
2023-03-02 18:24:56.147 37 ERROR keystone.server.flask.application     return self.creator()
2023-03-02 18:24:56.147 37 ERROR keystone.server.flask.application   File "/var/lib/kolla/venv/lib/python3.9/site-packages/dogpile/cache/region.py", line 995, in gen_value
2023-03-02 18:24:56.147 37 ERROR keystone.server.flask.application     created_value = creator(
2023-03-02 18:24:56.147 37 ERROR keystone.server.flask.application   File "/var/lib/kolla/venv/lib/python3.9/site-packages/keystone/assignment/core.py", line 1276, in get_role
2023-03-02 18:24:56.147 37 ERROR keystone.server.flask.application     return self.driver.get_role(role_id)
2023-03-02 18:24:56.147 37 ERROR keystone.server.flask.application   File "/var/lib/kolla/venv/lib/python3.9/site-packages/keystone/assignment/role_backends/sql.py", line 70, in get_role
2023-03-02 18:24:56.147 37 ERROR keystone.server.flask.application     return self._get_role(session, role_id).to_dict()
2023-03-02 18:24:56.147 37 ERROR keystone.server.flask.application   File "/var/lib/kolla/venv/lib/python3.9/site-packages/keystone/assignment/role_backends/sql.py", line 65, in _get_role
2023-03-02 18:24:56.147 37 ERROR keystone.server.flask.application     raise exception.RoleNotFound(role_id=role_id)
2023-03-02 18:24:56.147 37 ERROR keystone.server.flask.application keystone.exception.RoleNotFound: Could not find role: admin.
2023-03-02 18:24:56.147 37 ERROR keystone.server.flask.application 
2023-03-02 18:24:57.438 37 ERROR keystone.server.flask.application [None req-db9e1096-e212-46d4-880b-2134a47c534e ab07bc931e7145edbac9433742ba552a - - all default -] Could not find user: ironic.: keystone.exception.UserNotFound: Could not find user: ironic.
2023-03-02 18:24:57.438 37 ERROR keystone.server.flask.application Traceback (most recent call last):
2023-03-02 18:24:57.438 37 ERROR keystone.server.flask.application   File "/var/lib/kolla/venv/lib/python3.9/site-packages/flask/app.py", line 1820, in full_dispatch_request
2023-03-02 18:24:57.438 37 ERROR keystone.server.flask.application     rv = self.dispatch_request()
2023-03-02 18:24:57.438 37 ERROR keystone.server.flask.application   File "/var/lib/kolla/venv/lib/python3.9/site-packages/flask/app.py", line 1796, in dispatch_request
2023-03-02 18:24:57.438 37 ERROR keystone.server.flask.application     return self.ensure_sync(self.view_functions[rule.endpoint])(**view_args)
2023-03-02 18:24:57.438 37 ERROR keystone.server.flask.application   File "/var/lib/kolla/venv/lib/python3.9/site-packages/flask_restful/__init__.py", line 467, in wrapper
2023-03-02 18:24:57.438 37 ERROR keystone.server.flask.application     resp = resource(*args, **kwargs)
2023-03-02 18:24:57.438 37 ERROR keystone.server.flask.application   File "/var/lib/kolla/venv/lib/python3.9/site-packages/flask/views.py", line 107, in view
2023-03-02 18:24:57.438 37 ERROR keystone.server.flask.application     return current_app.ensure_sync(self.dispatch_request)(**kwargs)
2023-03-02 18:24:57.438 37 ERROR keystone.server.flask.application   File "/var/lib/kolla/venv/lib/python3.9/site-packages/flask_restful/__init__.py", line 582, in dispatch_request
2023-03-02 18:24:57.438 37 ERROR keystone.server.flask.application     resp = meth(*args, **kwargs)
2023-03-02 18:24:57.438 37 ERROR keystone.server.flask.application   File "/var/lib/kolla/venv/lib/python3.9/site-packages/keystone/api/users.py", line 182, in get
2023-03-02 18:24:57.438 37 ERROR keystone.server.flask.application     return self._get_user(user_id)
2023-03-02 18:24:57.438 37 ERROR keystone.server.flask.application   File "/var/lib/kolla/venv/lib/python3.9/site-packages/keystone/api/users.py", line 194, in _get_user
2023-03-02 18:24:57.438 37 ERROR keystone.server.flask.application     ref = PROVIDERS.identity_api.get_user(user_id)
2023-03-02 18:24:57.438 37 ERROR keystone.server.flask.application   File "/var/lib/kolla/venv/lib/python3.9/site-packages/keystone/common/manager.py", line 115, in wrapped
2023-03-02 18:24:57.438 37 ERROR keystone.server.flask.application     __ret_val = __f(*args, **kwargs)
2023-03-02 18:24:57.438 37 ERROR keystone.server.flask.application   File "/var/lib/kolla/venv/lib/python3.9/site-packages/keystone/identity/core.py", line 414, in wrapper
2023-03-02 18:24:57.438 37 ERROR keystone.server.flask.application     return f(self, *args, **kwargs)
2023-03-02 18:24:57.438 37 ERROR keystone.server.flask.application   File "/var/lib/kolla/venv/lib/python3.9/site-packages/keystone/identity/core.py", line 424, in wrapper
2023-03-02 18:24:57.438 37 ERROR keystone.server.flask.application     return f(self, *args, **kwargs)
2023-03-02 18:24:57.438 37 ERROR keystone.server.flask.application   File "/var/lib/kolla/venv/lib/python3.9/site-packages/decorator.py", line 232, in fun
2023-03-02 18:24:57.438 37 ERROR keystone.server.flask.application     return caller(func, *(extras + args), **kw)
2023-03-02 18:24:57.438 37 ERROR keystone.server.flask.application   File "/var/lib/kolla/venv/lib/python3.9/site-packages/dogpile/cache/region.py", line 1577, in get_or_create_for_user_func
2023-03-02 18:24:57.438 37 ERROR keystone.server.flask.application     return self.get_or_create(
2023-03-02 18:24:57.438 37 ERROR keystone.server.flask.application   File "/var/lib/kolla/venv/lib/python3.9/site-packages/dogpile/cache/region.py", line 1042, in get_or_create
2023-03-02 18:24:57.438 37 ERROR keystone.server.flask.application     with Lock(
2023-03-02 18:24:57.438 37 ERROR keystone.server.flask.application   File "/var/lib/kolla/venv/lib/python3.9/site-packages/dogpile/lock.py", line 185, in __enter__
2023-03-02 18:24:57.438 37 ERROR keystone.server.flask.application     return self._enter()
2023-03-02 18:24:57.438 37 ERROR keystone.server.flask.application   File "/var/lib/kolla/venv/lib/python3.9/site-packages/dogpile/lock.py", line 94, in _enter
2023-03-02 18:24:57.438 37 ERROR keystone.server.flask.application     generated = self._enter_create(value, createdtime)
2023-03-02 18:24:57.438 37 ERROR keystone.server.flask.application   File "/var/lib/kolla/venv/lib/python3.9/site-packages/dogpile/lock.py", line 178, in _enter_create
2023-03-02 18:24:57.438 37 ERROR keystone.server.flask.application     return self.creator()
2023-03-02 18:24:57.438 37 ERROR keystone.server.flask.application   File "/var/lib/kolla/venv/lib/python3.9/site-packages/dogpile/cache/region.py", line 995, in gen_value
2023-03-02 18:24:57.438 37 ERROR keystone.server.flask.application     created_value = creator(
2023-03-02 18:24:57.438 37 ERROR keystone.server.flask.application   File "/var/lib/kolla/venv/lib/python3.9/site-packages/keystone/identity/core.py", line 1011, in get_user
2023-03-02 18:24:57.438 37 ERROR keystone.server.flask.application     ref = driver.get_user(entity_id)
2023-03-02 18:24:57.438 37 ERROR keystone.server.flask.application   File "/var/lib/kolla/venv/lib/python3.9/site-packages/keystone/identity/backends/sql.py", line 200, in get_user
2023-03-02 18:24:57.438 37 ERROR keystone.server.flask.application     self._get_user(session, user_id).to_dict())
2023-03-02 18:24:57.438 37 ERROR keystone.server.flask.application   File "/var/lib/kolla/venv/lib/python3.9/site-packages/keystone/identity/backends/sql.py", line 194, in _get_user
2023-03-02 18:24:57.438 37 ERROR keystone.server.flask.application     raise exception.UserNotFound(user_id=user_id)
2023-03-02 18:24:57.438 37 ERROR keystone.server.flask.application keystone.exception.UserNotFound: Could not find user: ironic.
2023-03-02 18:24:57.438 37 ERROR keystone.server.flask.application 
2023-03-02 18:24:58.455 38 ERROR keystone.server.flask.application [None req-21a47abb-6f8f-4b14-a52b-211206767f10 ab07bc931e7145edbac9433742ba552a - - all default -] Could not find project: service.: keystone.exception.ProjectNotFound: Could not find project: service.
2023-03-02 18:24:58.455 38 ERROR keystone.server.flask.application Traceback (most recent call last):
2023-03-02 18:24:58.455 38 ERROR keystone.server.flask.application   File "/var/lib/kolla/venv/lib/python3.9/site-packages/flask/app.py", line 1820, in full_dispatch_request
2023-03-02 18:24:58.455 38 ERROR keystone.server.flask.application     rv = self.dispatch_request()
2023-03-02 18:24:58.455 38 ERROR keystone.server.flask.application   File "/var/lib/kolla/venv/lib/python3.9/site-packages/flask/app.py", line 1796, in dispatch_request
2023-03-02 18:24:58.455 38 ERROR keystone.server.flask.application     return self.ensure_sync(self.view_functions[rule.endpoint])(**view_args)
2023-03-02 18:24:58.455 38 ERROR keystone.server.flask.application   File "/var/lib/kolla/venv/lib/python3.9/site-packages/flask_restful/__init__.py", line 467, in wrapper
2023-03-02 18:24:58.455 38 ERROR keystone.server.flask.application     resp = resource(*args, **kwargs)
2023-03-02 18:24:58.455 38 ERROR keystone.server.flask.application   File "/var/lib/kolla/venv/lib/python3.9/site-packages/flask/views.py", line 107, in view
2023-03-02 18:24:58.455 38 ERROR keystone.server.flask.application     return current_app.ensure_sync(self.dispatch_request)(**kwargs)
2023-03-02 18:24:58.455 38 ERROR keystone.server.flask.application   File "/var/lib/kolla/venv/lib/python3.9/site-packages/flask_restful/__init__.py", line 582, in dispatch_request
2023-03-02 18:24:58.455 38 ERROR keystone.server.flask.application     resp = meth(*args, **kwargs)
2023-03-02 18:24:58.455 38 ERROR keystone.server.flask.application   File "/var/lib/kolla/venv/lib/python3.9/site-packages/keystone/api/projects.py", line 151, in get
2023-03-02 18:24:58.455 38 ERROR keystone.server.flask.application     return self._get_project(project_id)
2023-03-02 18:24:58.455 38 ERROR keystone.server.flask.application   File "/var/lib/kolla/venv/lib/python3.9/site-packages/keystone/api/projects.py", line 107, in _get_project
2023-03-02 18:24:58.455 38 ERROR keystone.server.flask.application     project = PROVIDERS.resource_api.get_project(project_id)
2023-03-02 18:24:58.455 38 ERROR keystone.server.flask.application   File "/var/lib/kolla/venv/lib/python3.9/site-packages/keystone/common/manager.py", line 115, in wrapped
2023-03-02 18:24:58.455 38 ERROR keystone.server.flask.application     __ret_val = __f(*args, **kwargs)
2023-03-02 18:24:58.455 38 ERROR keystone.server.flask.application   File "/var/lib/kolla/venv/lib/python3.9/site-packages/decorator.py", line 232, in fun
2023-03-02 18:24:58.455 38 ERROR keystone.server.flask.application     return caller(func, *(extras + args), **kw)
2023-03-02 18:24:58.455 38 ERROR keystone.server.flask.application   File "/var/lib/kolla/venv/lib/python3.9/site-packages/dogpile/cache/region.py", line 1577, in get_or_create_for_user_func
2023-03-02 18:24:58.455 38 ERROR keystone.server.flask.application     return self.get_or_create(
2023-03-02 18:24:58.455 38 ERROR keystone.server.flask.application   File "/var/lib/kolla/venv/lib/python3.9/site-packages/dogpile/cache/region.py", line 1042, in get_or_create
2023-03-02 18:24:58.455 38 ERROR keystone.server.flask.application     with Lock(
2023-03-02 18:24:58.455 38 ERROR keystone.server.flask.application   File "/var/lib/kolla/venv/lib/python3.9/site-packages/dogpile/lock.py", line 185, in __enter__
2023-03-02 18:24:58.455 38 ERROR keystone.server.flask.application     return self._enter()
2023-03-02 18:24:58.455 38 ERROR keystone.server.flask.application   File "/var/lib/kolla/venv/lib/python3.9/site-packages/dogpile/lock.py", line 94, in _enter
2023-03-02 18:24:58.455 38 ERROR keystone.server.flask.application     generated = self._enter_create(value, createdtime)
2023-03-02 18:24:58.455 38 ERROR keystone.server.flask.application   File "/var/lib/kolla/venv/lib/python3.9/site-packages/dogpile/lock.py", line 178, in _enter_create
2023-03-02 18:24:58.455 38 ERROR keystone.server.flask.application     return self.creator()
2023-03-02 18:24:58.455 38 ERROR keystone.server.flask.application   File "/var/lib/kolla/venv/lib/python3.9/site-packages/dogpile/cache/region.py", line 995, in gen_value
2023-03-02 18:24:58.455 38 ERROR keystone.server.flask.application     created_value = creator(
2023-03-02 18:24:58.455 38 ERROR keystone.server.flask.application   File "/var/lib/kolla/venv/lib/python3.9/site-packages/keystone/resource/core.py", line 903, in get_project
2023-03-02 18:24:58.455 38 ERROR keystone.server.flask.application     return self.driver.get_project(project_id)
2023-03-02 18:24:58.455 38 ERROR keystone.server.flask.application   File "/var/lib/kolla/venv/lib/python3.9/site-packages/keystone/resource/backends/sql.py", line 49, in get_project
2023-03-02 18:24:58.455 38 ERROR keystone.server.flask.application     return self._get_project(session, project_id).to_dict()
2023-03-02 18:24:58.455 38 ERROR keystone.server.flask.application   File "/var/lib/kolla/venv/lib/python3.9/site-packages/keystone/resource/backends/sql.py", line 44, in _get_project
2023-03-02 18:24:58.455 38 ERROR keystone.server.flask.application     raise exception.ProjectNotFound(project_id=project_id)
2023-03-02 18:24:58.455 38 ERROR keystone.server.flask.application keystone.exception.ProjectNotFound: Could not find project: service.
2023-03-02 18:24:58.455 38 ERROR keystone.server.flask.application 
2023-03-02 18:25:08.082 39 ERROR keystone.server.flask.application [None req-6a2aa1e3-f756-4512-993b-df44e081007b ab07bc931e7145edbac9433742ba552a - - all default -] Could not find role: admin.: keystone.exception.RoleNotFound: Could not find role: admin.
2023-03-02 18:25:08.082 39 ERROR keystone.server.flask.application Traceback (most recent call last):
2023-03-02 18:25:08.082 39 ERROR keystone.server.flask.application   File "/var/lib/kolla/venv/lib/python3.9/site-packages/flask/app.py", line 1820, in full_dispatch_request
2023-03-02 18:25:08.082 39 ERROR keystone.server.flask.application     rv = self.dispatch_request()
2023-03-02 18:25:08.082 39 ERROR keystone.server.flask.application   File "/var/lib/kolla/venv/lib/python3.9/site-packages/flask/app.py", line 1796, in dispatch_request
2023-03-02 18:25:08.082 39 ERROR keystone.server.flask.application     return self.ensure_sync(self.view_functions[rule.endpoint])(**view_args)
2023-03-02 18:25:08.082 39 ERROR keystone.server.flask.application   File "/var/lib/kolla/venv/lib/python3.9/site-packages/flask_restful/__init__.py", line 467, in wrapper
2023-03-02 18:25:08.082 39 ERROR keystone.server.flask.application     resp = resource(*args, **kwargs)
2023-03-02 18:25:08.082 39 ERROR keystone.server.flask.application   File "/var/lib/kolla/venv/lib/python3.9/site-packages/flask/views.py", line 107, in view
2023-03-02 18:25:08.082 39 ERROR keystone.server.flask.application     return current_app.ensure_sync(self.dispatch_request)(**kwargs)
2023-03-02 18:25:08.082 39 ERROR keystone.server.flask.application   File "/var/lib/kolla/venv/lib/python3.9/site-packages/flask_restful/__init__.py", line 582, in dispatch_request
2023-03-02 18:25:08.082 39 ERROR keystone.server.flask.application     resp = meth(*args, **kwargs)
2023-03-02 18:25:08.082 39 ERROR keystone.server.flask.application   File "/var/lib/kolla/venv/lib/python3.9/site-packages/keystone/api/roles.py", line 50, in get
2023-03-02 18:25:08.082 39 ERROR keystone.server.flask.application     return self._get_role(role_id)
2023-03-02 18:25:08.082 39 ERROR keystone.server.flask.application   File "/var/lib/kolla/venv/lib/python3.9/site-packages/keystone/api/roles.py", line 70, in _get_role
2023-03-02 18:25:08.082 39 ERROR keystone.server.flask.application     ENFORCER.enforce_call(action='identity:get_role')
2023-03-02 18:25:08.082 39 ERROR keystone.server.flask.application   File "/var/lib/kolla/venv/lib/python3.9/site-packages/keystone/common/rbac_enforcer/enforcer.py", line 402, in enforce_call
2023-03-02 18:25:08.082 39 ERROR keystone.server.flask.application     policy_dict.update(cls._extract_member_target_data(
2023-03-02 18:25:08.082 39 ERROR keystone.server.flask.application   File "/var/lib/kolla/venv/lib/python3.9/site-packages/keystone/common/rbac_enforcer/enforcer.py", line 234, in _extract_member_target_data
2023-03-02 18:25:08.082 39 ERROR keystone.server.flask.application     member_name: func(flask.request.view_args[key])
2023-03-02 18:25:08.082 39 ERROR keystone.server.flask.application   File "/var/lib/kolla/venv/lib/python3.9/site-packages/keystone/common/manager.py", line 115, in wrapped
2023-03-02 18:25:08.082 39 ERROR keystone.server.flask.application     __ret_val = __f(*args, **kwargs)
2023-03-02 18:25:08.082 39 ERROR keystone.server.flask.application   File "/var/lib/kolla/venv/lib/python3.9/site-packages/decorator.py", line 232, in fun
2023-03-02 18:25:08.082 39 ERROR keystone.server.flask.application     return caller(func, *(extras + args), **kw)
2023-03-02 18:25:08.082 39 ERROR keystone.server.flask.application   File "/var/lib/kolla/venv/lib/python3.9/site-packages/dogpile/cache/region.py", line 1577, in get_or_create_for_user_func
2023-03-02 18:25:08.082 39 ERROR keystone.server.flask.application     return self.get_or_create(
2023-03-02 18:25:08.082 39 ERROR keystone.server.flask.application   File "/var/lib/kolla/venv/lib/python3.9/site-packages/dogpile/cache/region.py", line 1042, in get_or_create
2023-03-02 18:25:08.082 39 ERROR keystone.server.flask.application     with Lock(
2023-03-02 18:25:08.082 39 ERROR keystone.server.flask.application   File "/var/lib/kolla/venv/lib/python3.9/site-packages/dogpile/lock.py", line 185, in __enter__
2023-03-02 18:25:08.082 39 ERROR keystone.server.flask.application     return self._enter()
2023-03-02 18:25:08.082 39 ERROR keystone.server.flask.application   File "/var/lib/kolla/venv/lib/python3.9/site-packages/dogpile/lock.py", line 94, in _enter
2023-03-02 18:25:08.082 39 ERROR keystone.server.flask.application     generated = self._enter_create(value, createdtime)
2023-03-02 18:25:08.082 39 ERROR keystone.server.flask.application   File "/var/lib/kolla/venv/lib/python3.9/site-packages/dogpile/lock.py", line 178, in _enter_create
2023-03-02 18:25:08.082 39 ERROR keystone.server.flask.application     return self.creator()
2023-03-02 18:25:08.082 39 ERROR keystone.server.flask.application   File "/var/lib/kolla/venv/lib/python3.9/site-packages/dogpile/cache/region.py", line 995, in gen_value
2023-03-02 18:25:08.082 39 ERROR keystone.server.flask.application     created_value = creator(
2023-03-02 18:25:08.082 39 ERROR keystone.server.flask.application   File "/var/lib/kolla/venv/lib/python3.9/site-packages/keystone/assignment/core.py", line 1276, in get_role
2023-03-02 18:25:08.082 39 ERROR keystone.server.flask.application     return self.driver.get_role(role_id)
2023-03-02 18:25:08.082 39 ERROR keystone.server.flask.application   File "/var/lib/kolla/venv/lib/python3.9/site-packages/keystone/assignment/role_backends/sql.py", line 70, in get_role
2023-03-02 18:25:08.082 39 ERROR keystone.server.flask.application     return self._get_role(session, role_id).to_dict()
2023-03-02 18:25:08.082 39 ERROR keystone.server.flask.application   File "/var/lib/kolla/venv/lib/python3.9/site-packages/keystone/assignment/role_backends/sql.py", line 65, in _get_role
2023-03-02 18:25:08.082 39 ERROR keystone.server.flask.application     raise exception.RoleNotFound(role_id=role_id)
2023-03-02 18:25:08.082 39 ERROR keystone.server.flask.application keystone.exception.RoleNotFound: Could not find role: admin.
2023-03-02 18:25:08.082 39 ERROR keystone.server.flask.application 
2023-03-02 18:25:09.461 39 ERROR keystone.server.flask.application [None req-85d0375a-2056-4775-909d-2fc62e2323f2 ab07bc931e7145edbac9433742ba552a - - all default -] Could not find user: ironic-inspector.: keystone.exception.UserNotFound: Could not find user: ironic-inspector.
2023-03-02 18:25:09.461 39 ERROR keystone.server.flask.application Traceback (most recent call last):
2023-03-02 18:25:09.461 39 ERROR keystone.server.flask.application   File "/var/lib/kolla/venv/lib/python3.9/site-packages/flask/app.py", line 1820, in full_dispatch_request
2023-03-02 18:25:09.461 39 ERROR keystone.server.flask.application     rv = self.dispatch_request()
2023-03-02 18:25:09.461 39 ERROR keystone.server.flask.application   File "/var/lib/kolla/venv/lib/python3.9/site-packages/flask/app.py", line 1796, in dispatch_request
2023-03-02 18:25:09.461 39 ERROR keystone.server.flask.application     return self.ensure_sync(self.view_functions[rule.endpoint])(**view_args)
2023-03-02 18:25:09.461 39 ERROR keystone.server.flask.application   File "/var/lib/kolla/venv/lib/python3.9/site-packages/flask_restful/__init__.py", line 467, in wrapper
2023-03-02 18:25:09.461 39 ERROR keystone.server.flask.application     resp = resource(*args, **kwargs)
2023-03-02 18:25:09.461 39 ERROR keystone.server.flask.application   File "/var/lib/kolla/venv/lib/python3.9/site-packages/flask/views.py", line 107, in view
2023-03-02 18:25:09.461 39 ERROR keystone.server.flask.application     return current_app.ensure_sync(self.dispatch_request)(**kwargs)
2023-03-02 18:25:09.461 39 ERROR keystone.server.flask.application   File "/var/lib/kolla/venv/lib/python3.9/site-packages/flask_restful/__init__.py", line 582, in dispatch_request
2023-03-02 18:25:09.461 39 ERROR keystone.server.flask.application     resp = meth(*args, **kwargs)
2023-03-02 18:25:09.461 39 ERROR keystone.server.flask.application   File "/var/lib/kolla/venv/lib/python3.9/site-packages/keystone/api/users.py", line 182, in get
2023-03-02 18:25:09.461 39 ERROR keystone.server.flask.application     return self._get_user(user_id)
2023-03-02 18:25:09.461 39 ERROR keystone.server.flask.application   File "/var/lib/kolla/venv/lib/python3.9/site-packages/keystone/api/users.py", line 194, in _get_user
2023-03-02 18:25:09.461 39 ERROR keystone.server.flask.application     ref = PROVIDERS.identity_api.get_user(user_id)
2023-03-02 18:25:09.461 39 ERROR keystone.server.flask.application   File "/var/lib/kolla/venv/lib/python3.9/site-packages/keystone/common/manager.py", line 115, in wrapped
2023-03-02 18:25:09.461 39 ERROR keystone.server.flask.application     __ret_val = __f(*args, **kwargs)
2023-03-02 18:25:09.461 39 ERROR keystone.server.flask.application   File "/var/lib/kolla/venv/lib/python3.9/site-packages/keystone/identity/core.py", line 414, in wrapper
2023-03-02 18:25:09.461 39 ERROR keystone.server.flask.application     return f(self, *args, **kwargs)
2023-03-02 18:25:09.461 39 ERROR keystone.server.flask.application   File "/var/lib/kolla/venv/lib/python3.9/site-packages/keystone/identity/core.py", line 424, in wrapper
2023-03-02 18:25:09.461 39 ERROR keystone.server.flask.application     return f(self, *args, **kwargs)
2023-03-02 18:25:09.461 39 ERROR keystone.server.flask.application   File "/var/lib/kolla/venv/lib/python3.9/site-packages/decorator.py", line 232, in fun
2023-03-02 18:25:09.461 39 ERROR keystone.server.flask.application     return caller(func, *(extras + args), **kw)
2023-03-02 18:25:09.461 39 ERROR keystone.server.flask.application   File "/var/lib/kolla/venv/lib/python3.9/site-packages/dogpile/cache/region.py", line 1577, in get_or_create_for_user_func
2023-03-02 18:25:09.461 39 ERROR keystone.server.flask.application     return self.get_or_create(
2023-03-02 18:25:09.461 39 ERROR keystone.server.flask.application   File "/var/lib/kolla/venv/lib/python3.9/site-packages/dogpile/cache/region.py", line 1042, in get_or_create
2023-03-02 18:25:09.461 39 ERROR keystone.server.flask.application     with Lock(
2023-03-02 18:25:09.461 39 ERROR keystone.server.flask.application   File "/var/lib/kolla/venv/lib/python3.9/site-packages/dogpile/lock.py", line 185, in __enter__
2023-03-02 18:25:09.461 39 ERROR keystone.server.flask.application     return self._enter()
2023-03-02 18:25:09.461 39 ERROR keystone.server.flask.application   File "/var/lib/kolla/venv/lib/python3.9/site-packages/dogpile/lock.py", line 94, in _enter
2023-03-02 18:25:09.461 39 ERROR keystone.server.flask.application     generated = self._enter_create(value, createdtime)
2023-03-02 18:25:09.461 39 ERROR keystone.server.flask.application   File "/var/lib/kolla/venv/lib/python3.9/site-packages/dogpile/lock.py", line 178, in _enter_create
2023-03-02 18:25:09.461 39 ERROR keystone.server.flask.application     return self.creator()
2023-03-02 18:25:09.461 39 ERROR keystone.server.flask.application   File "/var/lib/kolla/venv/lib/python3.9/site-packages/dogpile/cache/region.py", line 995, in gen_value
2023-03-02 18:25:09.461 39 ERROR keystone.server.flask.application     created_value = creator(
2023-03-02 18:25:09.461 39 ERROR keystone.server.flask.application   File "/var/lib/kolla/venv/lib/python3.9/site-packages/keystone/identity/core.py", line 1011, in get_user
2023-03-02 18:25:09.461 39 ERROR keystone.server.flask.application     ref = driver.get_user(entity_id)
2023-03-02 18:25:09.461 39 ERROR keystone.server.flask.application   File "/var/lib/kolla/venv/lib/python3.9/site-packages/keystone/identity/backends/sql.py", line 200, in get_user
2023-03-02 18:25:09.461 39 ERROR keystone.server.flask.application     self._get_user(session, user_id).to_dict())
2023-03-02 18:25:09.461 39 ERROR keystone.server.flask.application   File "/var/lib/kolla/venv/lib/python3.9/site-packages/keystone/identity/backends/sql.py", line 194, in _get_user
2023-03-02 18:25:09.461 39 ERROR keystone.server.flask.application     raise exception.UserNotFound(user_id=user_id)
2023-03-02 18:25:09.461 39 ERROR keystone.server.flask.application keystone.exception.UserNotFound: Could not find user: ironic-inspector.
2023-03-02 18:25:09.461 39 ERROR keystone.server.flask.application 
2023-03-02 18:25:10.446 37 ERROR keystone.server.flask.application [None req-7373cf0e-0f72-4c51-abbe-4602cc1f1e86 ab07bc931e7145edbac9433742ba552a - - all default -] Could not find project: service.: keystone.exception.ProjectNotFound: Could not find project: service.
2023-03-02 18:25:10.446 37 ERROR keystone.server.flask.application Traceback (most recent call last):
2023-03-02 18:25:10.446 37 ERROR keystone.server.flask.application   File "/var/lib/kolla/venv/lib/python3.9/site-packages/flask/app.py", line 1820, in full_dispatch_request
2023-03-02 18:25:10.446 37 ERROR keystone.server.flask.application     rv = self.dispatch_request()
2023-03-02 18:25:10.446 37 ERROR keystone.server.flask.application   File "/var/lib/kolla/venv/lib/python3.9/site-packages/flask/app.py", line 1796, in dispatch_request
2023-03-02 18:25:10.446 37 ERROR keystone.server.flask.application     return self.ensure_sync(self.view_functions[rule.endpoint])(**view_args)
2023-03-02 18:25:10.446 37 ERROR keystone.server.flask.application   File "/var/lib/kolla/venv/lib/python3.9/site-packages/flask_restful/__init__.py", line 467, in wrapper
2023-03-02 18:25:10.446 37 ERROR keystone.server.flask.application     resp = resource(*args, **kwargs)
2023-03-02 18:25:10.446 37 ERROR keystone.server.flask.application   File "/var/lib/kolla/venv/lib/python3.9/site-packages/flask/views.py", line 107, in view
2023-03-02 18:25:10.446 37 ERROR keystone.server.flask.application     return current_app.ensure_sync(self.dispatch_request)(**kwargs)
2023-03-02 18:25:10.446 37 ERROR keystone.server.flask.application   File "/var/lib/kolla/venv/lib/python3.9/site-packages/flask_restful/__init__.py", line 582, in dispatch_request
2023-03-02 18:25:10.446 37 ERROR keystone.server.flask.application     resp = meth(*args, **kwargs)
2023-03-02 18:25:10.446 37 ERROR keystone.server.flask.application   File "/var/lib/kolla/venv/lib/python3.9/site-packages/keystone/api/projects.py", line 151, in get
2023-03-02 18:25:10.446 37 ERROR keystone.server.flask.application     return self._get_project(project_id)
2023-03-02 18:25:10.446 37 ERROR keystone.server.flask.application   File "/var/lib/kolla/venv/lib/python3.9/site-packages/keystone/api/projects.py", line 107, in _get_project
2023-03-02 18:25:10.446 37 ERROR keystone.server.flask.application     project = PROVIDERS.resource_api.get_project(project_id)
2023-03-02 18:25:10.446 37 ERROR keystone.server.flask.application   File "/var/lib/kolla/venv/lib/python3.9/site-packages/keystone/common/manager.py", line 115, in wrapped
2023-03-02 18:25:10.446 37 ERROR keystone.server.flask.application     __ret_val = __f(*args, **kwargs)
2023-03-02 18:25:10.446 37 ERROR keystone.server.flask.application   File "/var/lib/kolla/venv/lib/python3.9/site-packages/decorator.py", line 232, in fun
2023-03-02 18:25:10.446 37 ERROR keystone.server.flask.application     return caller(func, *(extras + args), **kw)
2023-03-02 18:25:10.446 37 ERROR keystone.server.flask.application   File "/var/lib/kolla/venv/lib/python3.9/site-packages/dogpile/cache/region.py", line 1577, in get_or_create_for_user_func
2023-03-02 18:25:10.446 37 ERROR keystone.server.flask.application     return self.get_or_create(
2023-03-02 18:25:10.446 37 ERROR keystone.server.flask.application   File "/var/lib/kolla/venv/lib/python3.9/site-packages/dogpile/cache/region.py", line 1042, in get_or_create
2023-03-02 18:25:10.446 37 ERROR keystone.server.flask.application     with Lock(
2023-03-02 18:25:10.446 37 ERROR keystone.server.flask.application   File "/var/lib/kolla/venv/lib/python3.9/site-packages/dogpile/lock.py", line 185, in __enter__
2023-03-02 18:25:10.446 37 ERROR keystone.server.flask.application     return self._enter()
2023-03-02 18:25:10.446 37 ERROR keystone.server.flask.application   File "/var/lib/kolla/venv/lib/python3.9/site-packages/dogpile/lock.py", line 94, in _enter
2023-03-02 18:25:10.446 37 ERROR keystone.server.flask.application     generated = self._enter_create(value, createdtime)
2023-03-02 18:25:10.446 37 ERROR keystone.server.flask.application   File "/var/lib/kolla/venv/lib/python3.9/site-packages/dogpile/lock.py", line 178, in _enter_create
2023-03-02 18:25:10.446 37 ERROR keystone.server.flask.application     return self.creator()
2023-03-02 18:25:10.446 37 ERROR keystone.server.flask.application   File "/var/lib/kolla/venv/lib/python3.9/site-packages/dogpile/cache/region.py", line 995, in gen_value
2023-03-02 18:25:10.446 37 ERROR keystone.server.flask.application     created_value = creator(
2023-03-02 18:25:10.446 37 ERROR keystone.server.flask.application   File "/var/lib/kolla/venv/lib/python3.9/site-packages/keystone/resource/core.py", line 903, in get_project
2023-03-02 18:25:10.446 37 ERROR keystone.server.flask.application     return self.driver.get_project(project_id)
2023-03-02 18:25:10.446 37 ERROR keystone.server.flask.application   File "/var/lib/kolla/venv/lib/python3.9/site-packages/keystone/resource/backends/sql.py", line 49, in get_project
2023-03-02 18:25:10.446 37 ERROR keystone.server.flask.application     return self._get_project(session, project_id).to_dict()
2023-03-02 18:25:10.446 37 ERROR keystone.server.flask.application   File "/var/lib/kolla/venv/lib/python3.9/site-packages/keystone/resource/backends/sql.py", line 44, in _get_project
2023-03-02 18:25:10.446 37 ERROR keystone.server.flask.application     raise exception.ProjectNotFound(project_id=project_id)
2023-03-02 18:25:10.446 37 ERROR keystone.server.flask.application keystone.exception.ProjectNotFound: Could not find project: service.
2023-03-02 18:25:10.446 37 ERROR keystone.server.flask.application 
2023-03-02 18:28:04.697 39 ERROR keystone.server.flask.application [None req-aa0916df-17b7-4d08-8498-6b4686c42d3f ab07bc931e7145edbac9433742ba552a - - all default -] Could not find project: service.: keystone.exception.ProjectNotFound: Could not find project: service.
2023-03-02 18:28:04.697 39 ERROR keystone.server.flask.application Traceback (most recent call last):
2023-03-02 18:28:04.697 39 ERROR keystone.server.flask.application   File "/var/lib/kolla/venv/lib/python3.9/site-packages/flask/app.py", line 1820, in full_dispatch_request
2023-03-02 18:28:04.697 39 ERROR keystone.server.flask.application     rv = self.dispatch_request()
2023-03-02 18:28:04.697 39 ERROR keystone.server.flask.application   File "/var/lib/kolla/venv/lib/python3.9/site-packages/flask/app.py", line 1796, in dispatch_request
2023-03-02 18:28:04.697 39 ERROR keystone.server.flask.application     return self.ensure_sync(self.view_functions[rule.endpoint])(**view_args)
2023-03-02 18:28:04.697 39 ERROR keystone.server.flask.application   File "/var/lib/kolla/venv/lib/python3.9/site-packages/flask_restful/__init__.py", line 467, in wrapper
2023-03-02 18:28:04.697 39 ERROR keystone.server.flask.application     resp = resource(*args, **kwargs)
2023-03-02 18:28:04.697 39 ERROR keystone.server.flask.application   File "/var/lib/kolla/venv/lib/python3.9/site-packages/flask/views.py", line 107, in view
2023-03-02 18:28:04.697 39 ERROR keystone.server.flask.application     return current_app.ensure_sync(self.dispatch_request)(**kwargs)
2023-03-02 18:28:04.697 39 ERROR keystone.server.flask.application   File "/var/lib/kolla/venv/lib/python3.9/site-packages/flask_restful/__init__.py", line 582, in dispatch_request
2023-03-02 18:28:04.697 39 ERROR keystone.server.flask.application     resp = meth(*args, **kwargs)
2023-03-02 18:28:04.697 39 ERROR keystone.server.flask.application   File "/var/lib/kolla/venv/lib/python3.9/site-packages/keystone/api/projects.py", line 151, in get
2023-03-02 18:28:04.697 39 ERROR keystone.server.flask.application     return self._get_project(project_id)
2023-03-02 18:28:04.697 39 ERROR keystone.server.flask.application   File "/var/lib/kolla/venv/lib/python3.9/site-packages/keystone/api/projects.py", line 107, in _get_project
2023-03-02 18:28:04.697 39 ERROR keystone.server.flask.application     project = PROVIDERS.resource_api.get_project(project_id)
2023-03-02 18:28:04.697 39 ERROR keystone.server.flask.application   File "/var/lib/kolla/venv/lib/python3.9/site-packages/keystone/common/manager.py", line 115, in wrapped
2023-03-02 18:28:04.697 39 ERROR keystone.server.flask.application     __ret_val = __f(*args, **kwargs)
2023-03-02 18:28:04.697 39 ERROR keystone.server.flask.application   File "/var/lib/kolla/venv/lib/python3.9/site-packages/decorator.py", line 232, in fun
2023-03-02 18:28:04.697 39 ERROR keystone.server.flask.application     return caller(func, *(extras + args), **kw)
2023-03-02 18:28:04.697 39 ERROR keystone.server.flask.application   File "/var/lib/kolla/venv/lib/python3.9/site-packages/dogpile/cache/region.py", line 1577, in get_or_create_for_user_func
2023-03-02 18:28:04.697 39 ERROR keystone.server.flask.application     return self.get_or_create(
2023-03-02 18:28:04.697 39 ERROR keystone.server.flask.application   File "/var/lib/kolla/venv/lib/python3.9/site-packages/dogpile/cache/region.py", line 1042, in get_or_create
2023-03-02 18:28:04.697 39 ERROR keystone.server.flask.application     with Lock(
2023-03-02 18:28:04.697 39 ERROR keystone.server.flask.application   File "/var/lib/kolla/venv/lib/python3.9/site-packages/dogpile/lock.py", line 185, in __enter__
2023-03-02 18:28:04.697 39 ERROR keystone.server.flask.application     return self._enter()
2023-03-02 18:28:04.697 39 ERROR keystone.server.flask.application   File "/var/lib/kolla/venv/lib/python3.9/site-packages/dogpile/lock.py", line 94, in _enter
2023-03-02 18:28:04.697 39 ERROR keystone.server.flask.application     generated = self._enter_create(value, createdtime)
2023-03-02 18:28:04.697 39 ERROR keystone.server.flask.application   File "/var/lib/kolla/venv/lib/python3.9/site-packages/dogpile/lock.py", line 178, in _enter_create
2023-03-02 18:28:04.697 39 ERROR keystone.server.flask.application     return self.creator()
2023-03-02 18:28:04.697 39 ERROR keystone.server.flask.application   File "/var/lib/kolla/venv/lib/python3.9/site-packages/dogpile/cache/region.py", line 995, in gen_value
2023-03-02 18:28:04.697 39 ERROR keystone.server.flask.application     created_value = creator(
2023-03-02 18:28:04.697 39 ERROR keystone.server.flask.application   File "/var/lib/kolla/venv/lib/python3.9/site-packages/keystone/resource/core.py", line 903, in get_project
2023-03-02 18:28:04.697 39 ERROR keystone.server.flask.application     return self.driver.get_project(project_id)
2023-03-02 18:28:04.697 39 ERROR keystone.server.flask.application   File "/var/lib/kolla/venv/lib/python3.9/site-packages/keystone/resource/backends/sql.py", line 49, in get_project
2023-03-02 18:28:04.697 39 ERROR keystone.server.flask.application     return self._get_project(session, project_id).to_dict()
2023-03-02 18:28:04.697 39 ERROR keystone.server.flask.application   File "/var/lib/kolla/venv/lib/python3.9/site-packages/keystone/resource/backends/sql.py", line 44, in _get_project
2023-03-02 18:28:04.697 39 ERROR keystone.server.flask.application     raise exception.ProjectNotFound(project_id=project_id)
2023-03-02 18:28:04.697 39 ERROR keystone.server.flask.application keystone.exception.ProjectNotFound: Could not find project: service.
2023-03-02 18:28:04.697 39 ERROR keystone.server.flask.application 
2023-03-02 18:28:18.789 37 ERROR keystone.server.flask.application [None req-37f45f29-506e-4987-8b6c-65e5c586da78 ab07bc931e7145edbac9433742ba552a - - all default -] Could not find role: admin.: keystone.exception.RoleNotFound: Could not find role: admin.
2023-03-02 18:28:18.789 37 ERROR keystone.server.flask.application Traceback (most recent call last):
2023-03-02 18:28:18.789 37 ERROR keystone.server.flask.application   File "/var/lib/kolla/venv/lib/python3.9/site-packages/flask/app.py", line 1820, in full_dispatch_request
2023-03-02 18:28:18.789 37 ERROR keystone.server.flask.application     rv = self.dispatch_request()
2023-03-02 18:28:18.789 37 ERROR keystone.server.flask.application   File "/var/lib/kolla/venv/lib/python3.9/site-packages/flask/app.py", line 1796, in dispatch_request
2023-03-02 18:28:18.789 37 ERROR keystone.server.flask.application     return self.ensure_sync(self.view_functions[rule.endpoint])(**view_args)
2023-03-02 18:28:18.789 37 ERROR keystone.server.flask.application   File "/var/lib/kolla/venv/lib/python3.9/site-packages/flask_restful/__init__.py", line 467, in wrapper
2023-03-02 18:28:18.789 37 ERROR keystone.server.flask.application     resp = resource(*args, **kwargs)
2023-03-02 18:28:18.789 37 ERROR keystone.server.flask.application   File "/var/lib/kolla/venv/lib/python3.9/site-packages/flask/views.py", line 107, in view
2023-03-02 18:28:18.789 37 ERROR keystone.server.flask.application     return current_app.ensure_sync(self.dispatch_request)(**kwargs)
2023-03-02 18:28:18.789 37 ERROR keystone.server.flask.application   File "/var/lib/kolla/venv/lib/python3.9/site-packages/flask_restful/__init__.py", line 582, in dispatch_request
2023-03-02 18:28:18.789 37 ERROR keystone.server.flask.application     resp = meth(*args, **kwargs)
2023-03-02 18:28:18.789 37 ERROR keystone.server.flask.application   File "/var/lib/kolla/venv/lib/python3.9/site-packages/keystone/api/roles.py", line 50, in get
2023-03-02 18:28:18.789 37 ERROR keystone.server.flask.application     return self._get_role(role_id)
2023-03-02 18:28:18.789 37 ERROR keystone.server.flask.application   File "/var/lib/kolla/venv/lib/python3.9/site-packages/keystone/api/roles.py", line 70, in _get_role
2023-03-02 18:28:18.789 37 ERROR keystone.server.flask.application     ENFORCER.enforce_call(action='identity:get_role')
2023-03-02 18:28:18.789 37 ERROR keystone.server.flask.application   File "/var/lib/kolla/venv/lib/python3.9/site-packages/keystone/common/rbac_enforcer/enforcer.py", line 402, in enforce_call
2023-03-02 18:28:18.789 37 ERROR keystone.server.flask.application     policy_dict.update(cls._extract_member_target_data(
2023-03-02 18:28:18.789 37 ERROR keystone.server.flask.application   File "/var/lib/kolla/venv/lib/python3.9/site-packages/keystone/common/rbac_enforcer/enforcer.py", line 234, in _extract_member_target_data
2023-03-02 18:28:18.789 37 ERROR keystone.server.flask.application     member_name: func(flask.request.view_args[key])
2023-03-02 18:28:18.789 37 ERROR keystone.server.flask.application   File "/var/lib/kolla/venv/lib/python3.9/site-packages/keystone/common/manager.py", line 115, in wrapped
2023-03-02 18:28:18.789 37 ERROR keystone.server.flask.application     __ret_val = __f(*args, **kwargs)
2023-03-02 18:28:18.789 37 ERROR keystone.server.flask.application   File "/var/lib/kolla/venv/lib/python3.9/site-packages/decorator.py", line 232, in fun
2023-03-02 18:28:18.789 37 ERROR keystone.server.flask.application     return caller(func, *(extras + args), **kw)
2023-03-02 18:28:18.789 37 ERROR keystone.server.flask.application   File "/var/lib/kolla/venv/lib/python3.9/site-packages/dogpile/cache/region.py", line 1577, in get_or_create_for_user_func
2023-03-02 18:28:18.789 37 ERROR keystone.server.flask.application     return self.get_or_create(
2023-03-02 18:28:18.789 37 ERROR keystone.server.flask.application   File "/var/lib/kolla/venv/lib/python3.9/site-packages/dogpile/cache/region.py", line 1042, in get_or_create
2023-03-02 18:28:18.789 37 ERROR keystone.server.flask.application     with Lock(
2023-03-02 18:28:18.789 37 ERROR keystone.server.flask.application   File "/var/lib/kolla/venv/lib/python3.9/site-packages/dogpile/lock.py", line 185, in __enter__
2023-03-02 18:28:18.789 37 ERROR keystone.server.flask.application     return self._enter()
2023-03-02 18:28:18.789 37 ERROR keystone.server.flask.application   File "/var/lib/kolla/venv/lib/python3.9/site-packages/dogpile/lock.py", line 94, in _enter
2023-03-02 18:28:18.789 37 ERROR keystone.server.flask.application     generated = self._enter_create(value, createdtime)
2023-03-02 18:28:18.789 37 ERROR keystone.server.flask.application   File "/var/lib/kolla/venv/lib/python3.9/site-packages/dogpile/lock.py", line 178, in _enter_create
2023-03-02 18:28:18.789 37 ERROR keystone.server.flask.application     return self.creator()
2023-03-02 18:28:18.789 37 ERROR keystone.server.flask.application   File "/var/lib/kolla/venv/lib/python3.9/site-packages/dogpile/cache/region.py", line 995, in gen_value
2023-03-02 18:28:18.789 37 ERROR keystone.server.flask.application     created_value = creator(
2023-03-02 18:28:18.789 37 ERROR keystone.server.flask.application   File "/var/lib/kolla/venv/lib/python3.9/site-packages/keystone/assignment/core.py", line 1276, in get_role
2023-03-02 18:28:18.789 37 ERROR keystone.server.flask.application     return self.driver.get_role(role_id)
2023-03-02 18:28:18.789 37 ERROR keystone.server.flask.application   File "/var/lib/kolla/venv/lib/python3.9/site-packages/keystone/assignment/role_backends/sql.py", line 70, in get_role
2023-03-02 18:28:18.789 37 ERROR keystone.server.flask.application     return self._get_role(session, role_id).to_dict()
2023-03-02 18:28:18.789 37 ERROR keystone.server.flask.application   File "/var/lib/kolla/venv/lib/python3.9/site-packages/keystone/assignment/role_backends/sql.py", line 65, in _get_role
2023-03-02 18:28:18.789 37 ERROR keystone.server.flask.application     raise exception.RoleNotFound(role_id=role_id)
2023-03-02 18:28:18.789 37 ERROR keystone.server.flask.application keystone.exception.RoleNotFound: Could not find role: admin.
2023-03-02 18:28:18.789 37 ERROR keystone.server.flask.application 
2023-03-02 18:28:19.849 37 ERROR keystone.server.flask.application [None req-d39ef3b3-175e-4eb7-9ed1-4629ae32a970 ab07bc931e7145edbac9433742ba552a - - all default -] Could not find user: neutron.: keystone.exception.UserNotFound: Could not find user: neutron.
2023-03-02 18:28:19.849 37 ERROR keystone.server.flask.application Traceback (most recent call last):
2023-03-02 18:28:19.849 37 ERROR keystone.server.flask.application   File "/var/lib/kolla/venv/lib/python3.9/site-packages/flask/app.py", line 1820, in full_dispatch_request
2023-03-02 18:28:19.849 37 ERROR keystone.server.flask.application     rv = self.dispatch_request()
2023-03-02 18:28:19.849 37 ERROR keystone.server.flask.application   File "/var/lib/kolla/venv/lib/python3.9/site-packages/flask/app.py", line 1796, in dispatch_request
2023-03-02 18:28:19.849 37 ERROR keystone.server.flask.application     return self.ensure_sync(self.view_functions[rule.endpoint])(**view_args)
2023-03-02 18:28:19.849 37 ERROR keystone.server.flask.application   File "/var/lib/kolla/venv/lib/python3.9/site-packages/flask_restful/__init__.py", line 467, in wrapper
2023-03-02 18:28:19.849 37 ERROR keystone.server.flask.application     resp = resource(*args, **kwargs)
2023-03-02 18:28:19.849 37 ERROR keystone.server.flask.application   File "/var/lib/kolla/venv/lib/python3.9/site-packages/flask/views.py", line 107, in view
2023-03-02 18:28:19.849 37 ERROR keystone.server.flask.application     return current_app.ensure_sync(self.dispatch_request)(**kwargs)
2023-03-02 18:28:19.849 37 ERROR keystone.server.flask.application   File "/var/lib/kolla/venv/lib/python3.9/site-packages/flask_restful/__init__.py", line 582, in dispatch_request
2023-03-02 18:28:19.849 37 ERROR keystone.server.flask.application     resp = meth(*args, **kwargs)
2023-03-02 18:28:19.849 37 ERROR keystone.server.flask.application   File "/var/lib/kolla/venv/lib/python3.9/site-packages/keystone/api/users.py", line 182, in get
2023-03-02 18:28:19.849 37 ERROR keystone.server.flask.application     return self._get_user(user_id)
2023-03-02 18:28:19.849 37 ERROR keystone.server.flask.application   File "/var/lib/kolla/venv/lib/python3.9/site-packages/keystone/api/users.py", line 194, in _get_user
2023-03-02 18:28:19.849 37 ERROR keystone.server.flask.application     ref = PROVIDERS.identity_api.get_user(user_id)
2023-03-02 18:28:19.849 37 ERROR keystone.server.flask.application   File "/var/lib/kolla/venv/lib/python3.9/site-packages/keystone/common/manager.py", line 115, in wrapped
2023-03-02 18:28:19.849 37 ERROR keystone.server.flask.application     __ret_val = __f(*args, **kwargs)
2023-03-02 18:28:19.849 37 ERROR keystone.server.flask.application   File "/var/lib/kolla/venv/lib/python3.9/site-packages/keystone/identity/core.py", line 414, in wrapper
2023-03-02 18:28:19.849 37 ERROR keystone.server.flask.application     return f(self, *args, **kwargs)
2023-03-02 18:28:19.849 37 ERROR keystone.server.flask.application   File "/var/lib/kolla/venv/lib/python3.9/site-packages/keystone/identity/core.py", line 424, in wrapper
2023-03-02 18:28:19.849 37 ERROR keystone.server.flask.application     return f(self, *args, **kwargs)
2023-03-02 18:28:19.849 37 ERROR keystone.server.flask.application   File "/var/lib/kolla/venv/lib/python3.9/site-packages/decorator.py", line 232, in fun
2023-03-02 18:28:19.849 37 ERROR keystone.server.flask.application     return caller(func, *(extras + args), **kw)
2023-03-02 18:28:19.849 37 ERROR keystone.server.flask.application   File "/var/lib/kolla/venv/lib/python3.9/site-packages/dogpile/cache/region.py", line 1577, in get_or_create_for_user_func
2023-03-02 18:28:19.849 37 ERROR keystone.server.flask.application     return self.get_or_create(
2023-03-02 18:28:19.849 37 ERROR keystone.server.flask.application   File "/var/lib/kolla/venv/lib/python3.9/site-packages/dogpile/cache/region.py", line 1042, in get_or_create
2023-03-02 18:28:19.849 37 ERROR keystone.server.flask.application     with Lock(
2023-03-02 18:28:19.849 37 ERROR keystone.server.flask.application   File "/var/lib/kolla/venv/lib/python3.9/site-packages/dogpile/lock.py", line 185, in __enter__
2023-03-02 18:28:19.849 37 ERROR keystone.server.flask.application     return self._enter()
2023-03-02 18:28:19.849 37 ERROR keystone.server.flask.application   File "/var/lib/kolla/venv/lib/python3.9/site-packages/dogpile/lock.py", line 94, in _enter
2023-03-02 18:28:19.849 37 ERROR keystone.server.flask.application     generated = self._enter_create(value, createdtime)
2023-03-02 18:28:19.849 37 ERROR keystone.server.flask.application   File "/var/lib/kolla/venv/lib/python3.9/site-packages/dogpile/lock.py", line 178, in _enter_create
2023-03-02 18:28:19.849 37 ERROR keystone.server.flask.application     return self.creator()
2023-03-02 18:28:19.849 37 ERROR keystone.server.flask.application   File "/var/lib/kolla/venv/lib/python3.9/site-packages/dogpile/cache/region.py", line 995, in gen_value
2023-03-02 18:28:19.849 37 ERROR keystone.server.flask.application     created_value = creator(
2023-03-02 18:28:19.849 37 ERROR keystone.server.flask.application   File "/var/lib/kolla/venv/lib/python3.9/site-packages/keystone/identity/core.py", line 1011, in get_user
2023-03-02 18:28:19.849 37 ERROR keystone.server.flask.application     ref = driver.get_user(entity_id)
2023-03-02 18:28:19.849 37 ERROR keystone.server.flask.application   File "/var/lib/kolla/venv/lib/python3.9/site-packages/keystone/identity/backends/sql.py", line 200, in get_user
2023-03-02 18:28:19.849 37 ERROR keystone.server.flask.application     self._get_user(session, user_id).to_dict())
2023-03-02 18:28:19.849 37 ERROR keystone.server.flask.application   File "/var/lib/kolla/venv/lib/python3.9/site-packages/keystone/identity/backends/sql.py", line 194, in _get_user
2023-03-02 18:28:19.849 37 ERROR keystone.server.flask.application     raise exception.UserNotFound(user_id=user_id)
2023-03-02 18:28:19.849 37 ERROR keystone.server.flask.application keystone.exception.UserNotFound: Could not find user: neutron.
2023-03-02 18:28:19.849 37 ERROR keystone.server.flask.application 
2023-03-02 18:28:20.708 38 ERROR keystone.server.flask.application [None req-f7aef8bc-0d42-4bb3-8c85-4678bf4b4833 ab07bc931e7145edbac9433742ba552a - - all default -] Could not find project: service.: keystone.exception.ProjectNotFound: Could not find project: service.
2023-03-02 18:28:20.708 38 ERROR keystone.server.flask.application Traceback (most recent call last):
2023-03-02 18:28:20.708 38 ERROR keystone.server.flask.application   File "/var/lib/kolla/venv/lib/python3.9/site-packages/flask/app.py", line 1820, in full_dispatch_request
2023-03-02 18:28:20.708 38 ERROR keystone.server.flask.application     rv = self.dispatch_request()
2023-03-02 18:28:20.708 38 ERROR keystone.server.flask.application   File "/var/lib/kolla/venv/lib/python3.9/site-packages/flask/app.py", line 1796, in dispatch_request
2023-03-02 18:28:20.708 38 ERROR keystone.server.flask.application     return self.ensure_sync(self.view_functions[rule.endpoint])(**view_args)
2023-03-02 18:28:20.708 38 ERROR keystone.server.flask.application   File "/var/lib/kolla/venv/lib/python3.9/site-packages/flask_restful/__init__.py", line 467, in wrapper
2023-03-02 18:28:20.708 38 ERROR keystone.server.flask.application     resp = resource(*args, **kwargs)
2023-03-02 18:28:20.708 38 ERROR keystone.server.flask.application   File "/var/lib/kolla/venv/lib/python3.9/site-packages/flask/views.py", line 107, in view
2023-03-02 18:28:20.708 38 ERROR keystone.server.flask.application     return current_app.ensure_sync(self.dispatch_request)(**kwargs)
2023-03-02 18:28:20.708 38 ERROR keystone.server.flask.application   File "/var/lib/kolla/venv/lib/python3.9/site-packages/flask_restful/__init__.py", line 582, in dispatch_request
2023-03-02 18:28:20.708 38 ERROR keystone.server.flask.application     resp = meth(*args, **kwargs)
2023-03-02 18:28:20.708 38 ERROR keystone.server.flask.application   File "/var/lib/kolla/venv/lib/python3.9/site-packages/keystone/api/projects.py", line 151, in get
2023-03-02 18:28:20.708 38 ERROR keystone.server.flask.application     return self._get_project(project_id)
2023-03-02 18:28:20.708 38 ERROR keystone.server.flask.application   File "/var/lib/kolla/venv/lib/python3.9/site-packages/keystone/api/projects.py", line 107, in _get_project
2023-03-02 18:28:20.708 38 ERROR keystone.server.flask.application     project = PROVIDERS.resource_api.get_project(project_id)
2023-03-02 18:28:20.708 38 ERROR keystone.server.flask.application   File "/var/lib/kolla/venv/lib/python3.9/site-packages/keystone/common/manager.py", line 115, in wrapped
2023-03-02 18:28:20.708 38 ERROR keystone.server.flask.application     __ret_val = __f(*args, **kwargs)
2023-03-02 18:28:20.708 38 ERROR keystone.server.flask.application   File "/var/lib/kolla/venv/lib/python3.9/site-packages/decorator.py", line 232, in fun
2023-03-02 18:28:20.708 38 ERROR keystone.server.flask.application     return caller(func, *(extras + args), **kw)
2023-03-02 18:28:20.708 38 ERROR keystone.server.flask.application   File "/var/lib/kolla/venv/lib/python3.9/site-packages/dogpile/cache/region.py", line 1577, in get_or_create_for_user_func
2023-03-02 18:28:20.708 38 ERROR keystone.server.flask.application     return self.get_or_create(
2023-03-02 18:28:20.708 38 ERROR keystone.server.flask.application   File "/var/lib/kolla/venv/lib/python3.9/site-packages/dogpile/cache/region.py", line 1042, in get_or_create
2023-03-02 18:28:20.708 38 ERROR keystone.server.flask.application     with Lock(
2023-03-02 18:28:20.708 38 ERROR keystone.server.flask.application   File "/var/lib/kolla/venv/lib/python3.9/site-packages/dogpile/lock.py", line 185, in __enter__
2023-03-02 18:28:20.708 38 ERROR keystone.server.flask.application     return self._enter()
2023-03-02 18:28:20.708 38 ERROR keystone.server.flask.application   File "/var/lib/kolla/venv/lib/python3.9/site-packages/dogpile/lock.py", line 94, in _enter
2023-03-02 18:28:20.708 38 ERROR keystone.server.flask.application     generated = self._enter_create(value, createdtime)
2023-03-02 18:28:20.708 38 ERROR keystone.server.flask.application   File "/var/lib/kolla/venv/lib/python3.9/site-packages/dogpile/lock.py", line 178, in _enter_create
2023-03-02 18:28:20.708 38 ERROR keystone.server.flask.application     return self.creator()
2023-03-02 18:28:20.708 38 ERROR keystone.server.flask.application   File "/var/lib/kolla/venv/lib/python3.9/site-packages/dogpile/cache/region.py", line 995, in gen_value
2023-03-02 18:28:20.708 38 ERROR keystone.server.flask.application     created_value = creator(
2023-03-02 18:28:20.708 38 ERROR keystone.server.flask.application   File "/var/lib/kolla/venv/lib/python3.9/site-packages/keystone/resource/core.py", line 903, in get_project
2023-03-02 18:28:20.708 38 ERROR keystone.server.flask.application     return self.driver.get_project(project_id)
2023-03-02 18:28:20.708 38 ERROR keystone.server.flask.application   File "/var/lib/kolla/venv/lib/python3.9/site-packages/keystone/resource/backends/sql.py", line 49, in get_project
2023-03-02 18:28:20.708 38 ERROR keystone.server.flask.application     return self._get_project(session, project_id).to_dict()
2023-03-02 18:28:20.708 38 ERROR keystone.server.flask.application   File "/var/lib/kolla/venv/lib/python3.9/site-packages/keystone/resource/backends/sql.py", line 44, in _get_project
2023-03-02 18:28:20.708 38 ERROR keystone.server.flask.application     raise exception.ProjectNotFound(project_id=project_id)
2023-03-02 18:28:20.708 38 ERROR keystone.server.flask.application keystone.exception.ProjectNotFound: Could not find project: service.
2023-03-02 18:28:20.708 38 ERROR keystone.server.flask.application 
