2023-04-03 22:40:17.428426 2023-04-03 22:40:17.426 38 WARNING keystone.common.rbac_enforcer.enforcer [None req-623f0f65-0e1a-4c60-ac8b-a02105dfc81f ec6785048b4c4da0b2826501dcd6781c - - all default -] Deprecated policy rules found. Use oslopolicy-policy-generator and oslopolicy-policy-upgrade to detect and resolve deprecated policies in your configuration.\x1b[00m
2023-04-03 22:40:18.258367 2023-04-03 22:40:18.256 37 WARNING keystone.common.rbac_enforcer.enforcer [None req-f2dae6bd-2e82-4620-9708-a210daf66610 ec6785048b4c4da0b2826501dcd6781c - - all default -] Deprecated policy rules found. Use oslopolicy-policy-generator and oslopolicy-policy-upgrade to detect and resolve deprecated policies in your configuration.\x1b[00m
2023-04-03 22:40:25.883833 2023-04-03 22:40:25.881 39 WARNING keystone.common.rbac_enforcer.enforcer [None req-fb300e9c-5635-4c59-b18f-6f5ce60afa61 ec6785048b4c4da0b2826501dcd6781c - - all default -] Deprecated policy rules found. Use oslopolicy-policy-generator and oslopolicy-policy-upgrade to detect and resolve deprecated policies in your configuration.\x1b[00m
2023-04-03 22:41:44.610440 2023-04-03 22:41:44.597 38 ERROR keystone.server.flask.application [None req-ca446e40-cbfe-499e-aec8-eb39cce271dd ec6785048b4c4da0b2826501dcd6781c - - all default -] Could not find project: service.: keystone.exception.ProjectNotFound: Could not find project: service.
2023-04-03 22:41:44.610533 2023-04-03 22:41:44.597 38 ERROR keystone.server.flask.application Traceback (most recent call last):
2023-04-03 22:41:44.610556 2023-04-03 22:41:44.597 38 ERROR keystone.server.flask.application   File "/var/lib/kolla/venv/lib/python3.9/site-packages/flask/app.py", line 1820, in full_dispatch_request
2023-04-03 22:41:44.610569 2023-04-03 22:41:44.597 38 ERROR keystone.server.flask.application     rv = self.dispatch_request()
2023-04-03 22:41:44.610579 2023-04-03 22:41:44.597 38 ERROR keystone.server.flask.application   File "/var/lib/kolla/venv/lib/python3.9/site-packages/flask/app.py", line 1796, in dispatch_request
2023-04-03 22:41:44.610589 2023-04-03 22:41:44.597 38 ERROR keystone.server.flask.application     return self.ensure_sync(self.view_functions[rule.endpoint])(**view_args)
2023-04-03 22:41:44.610599 2023-04-03 22:41:44.597 38 ERROR keystone.server.flask.application   File "/var/lib/kolla/venv/lib/python3.9/site-packages/flask_restful/__init__.py", line 467, in wrapper
2023-04-03 22:41:44.610609 2023-04-03 22:41:44.597 38 ERROR keystone.server.flask.application     resp = resource(*args, **kwargs)
2023-04-03 22:41:44.610624 2023-04-03 22:41:44.597 38 ERROR keystone.server.flask.application   File "/var/lib/kolla/venv/lib/python3.9/site-packages/flask/views.py", line 107, in view
2023-04-03 22:41:44.610636 2023-04-03 22:41:44.597 38 ERROR keystone.server.flask.application     return current_app.ensure_sync(self.dispatch_request)(**kwargs)
2023-04-03 22:41:44.610647 2023-04-03 22:41:44.597 38 ERROR keystone.server.flask.application   File "/var/lib/kolla/venv/lib/python3.9/site-packages/flask_restful/__init__.py", line 582, in dispatch_request
2023-04-03 22:41:44.610656 2023-04-03 22:41:44.597 38 ERROR keystone.server.flask.application     resp = meth(*args, **kwargs)
2023-04-03 22:41:44.610666 2023-04-03 22:41:44.597 38 ERROR keystone.server.flask.application   File "/var/lib/kolla/venv/lib/python3.9/site-packages/keystone/api/projects.py", line 151, in get
2023-04-03 22:41:44.610676 2023-04-03 22:41:44.597 38 ERROR keystone.server.flask.application     return self._get_project(project_id)
2023-04-03 22:41:44.610686 2023-04-03 22:41:44.597 38 ERROR keystone.server.flask.application   File "/var/lib/kolla/venv/lib/python3.9/site-packages/keystone/api/projects.py", line 107, in _get_project
2023-04-03 22:41:44.610695 2023-04-03 22:41:44.597 38 ERROR keystone.server.flask.application     project = PROVIDERS.resource_api.get_project(project_id)
2023-04-03 22:41:44.610705 2023-04-03 22:41:44.597 38 ERROR keystone.server.flask.application   File "/var/lib/kolla/venv/lib/python3.9/site-packages/keystone/common/manager.py", line 115, in wrapped
2023-04-03 22:41:44.610746 2023-04-03 22:41:44.597 38 ERROR keystone.server.flask.application     __ret_val = __f(*args, **kwargs)
2023-04-03 22:41:44.610758 2023-04-03 22:41:44.597 38 ERROR keystone.server.flask.application   File "/var/lib/kolla/venv/lib/python3.9/site-packages/decorator.py", line 232, in fun
2023-04-03 22:41:44.610768 2023-04-03 22:41:44.597 38 ERROR keystone.server.flask.application     return caller(func, *(extras + args), **kw)
2023-04-03 22:41:44.610799 2023-04-03 22:41:44.597 38 ERROR keystone.server.flask.application   File "/var/lib/kolla/venv/lib/python3.9/site-packages/dogpile/cache/region.py", line 1577, in get_or_create_for_user_func
2023-04-03 22:41:44.610809 2023-04-03 22:41:44.597 38 ERROR keystone.server.flask.application     return self.get_or_create(
2023-04-03 22:41:44.610819 2023-04-03 22:41:44.597 38 ERROR keystone.server.flask.application   File "/var/lib/kolla/venv/lib/python3.9/site-packages/dogpile/cache/region.py", line 1042, in get_or_create
2023-04-03 22:41:44.610829 2023-04-03 22:41:44.597 38 ERROR keystone.server.flask.application     with Lock(
2023-04-03 22:41:44.610838 2023-04-03 22:41:44.597 38 ERROR keystone.server.flask.application   File "/var/lib/kolla/venv/lib/python3.9/site-packages/dogpile/lock.py", line 185, in __enter__
2023-04-03 22:41:44.610848 2023-04-03 22:41:44.597 38 ERROR keystone.server.flask.application     return self._enter()
2023-04-03 22:41:44.610857 2023-04-03 22:41:44.597 38 ERROR keystone.server.flask.application   File "/var/lib/kolla/venv/lib/python3.9/site-packages/dogpile/lock.py", line 94, in _enter
2023-04-03 22:41:44.610867 2023-04-03 22:41:44.597 38 ERROR keystone.server.flask.application     generated = self._enter_create(value, createdtime)
2023-04-03 22:41:44.610876 2023-04-03 22:41:44.597 38 ERROR keystone.server.flask.application   File "/var/lib/kolla/venv/lib/python3.9/site-packages/dogpile/lock.py", line 178, in _enter_create
2023-04-03 22:41:44.610886 2023-04-03 22:41:44.597 38 ERROR keystone.server.flask.application     return self.creator()
2023-04-03 22:41:44.610896 2023-04-03 22:41:44.597 38 ERROR keystone.server.flask.application   File "/var/lib/kolla/venv/lib/python3.9/site-packages/dogpile/cache/region.py", line 995, in gen_value
2023-04-03 22:41:44.610905 2023-04-03 22:41:44.597 38 ERROR keystone.server.flask.application     created_value = creator(
2023-04-03 22:41:44.610915 2023-04-03 22:41:44.597 38 ERROR keystone.server.flask.application   File "/var/lib/kolla/venv/lib/python3.9/site-packages/keystone/resource/core.py", line 903, in get_project
2023-04-03 22:41:44.610925 2023-04-03 22:41:44.597 38 ERROR keystone.server.flask.application     return self.driver.get_project(project_id)
2023-04-03 22:41:44.610934 2023-04-03 22:41:44.597 38 ERROR keystone.server.flask.application   File "/var/lib/kolla/venv/lib/python3.9/site-packages/keystone/resource/backends/sql.py", line 49, in get_project
2023-04-03 22:41:44.610944 2023-04-03 22:41:44.597 38 ERROR keystone.server.flask.application     return self._get_project(session, project_id).to_dict()
2023-04-03 22:41:44.610954 2023-04-03 22:41:44.597 38 ERROR keystone.server.flask.application   File "/var/lib/kolla/venv/lib/python3.9/site-packages/keystone/resource/backends/sql.py", line 44, in _get_project
2023-04-03 22:41:44.610964 2023-04-03 22:41:44.597 38 ERROR keystone.server.flask.application     raise exception.ProjectNotFound(project_id=project_id)
2023-04-03 22:41:44.610973 2023-04-03 22:41:44.597 38 ERROR keystone.server.flask.application keystone.exception.ProjectNotFound: Could not find project: service.
2023-04-03 22:41:44.610982 2023-04-03 22:41:44.597 38 ERROR keystone.server.flask.application \x1b[00m
2023-04-03 22:41:53.614828 2023-04-03 22:41:53.596 39 ERROR keystone.server.flask.application [None req-03ae86f2-fce7-491f-83c0-fcfea29c54ba ec6785048b4c4da0b2826501dcd6781c - - all default -] Could not find project: service.: keystone.exception.ProjectNotFound: Could not find project: service.
2023-04-03 22:41:53.614918 2023-04-03 22:41:53.596 39 ERROR keystone.server.flask.application Traceback (most recent call last):
2023-04-03 22:41:53.614968 2023-04-03 22:41:53.596 39 ERROR keystone.server.flask.application   File "/var/lib/kolla/venv/lib/python3.9/site-packages/flask/app.py", line 1820, in full_dispatch_request
2023-04-03 22:41:53.614982 2023-04-03 22:41:53.596 39 ERROR keystone.server.flask.application     rv = self.dispatch_request()
2023-04-03 22:41:53.614991 2023-04-03 22:41:53.596 39 ERROR keystone.server.flask.application   File "/var/lib/kolla/venv/lib/python3.9/site-packages/flask/app.py", line 1796, in dispatch_request
2023-04-03 22:41:53.615002 2023-04-03 22:41:53.596 39 ERROR keystone.server.flask.application     return self.ensure_sync(self.view_functions[rule.endpoint])(**view_args)
2023-04-03 22:41:53.615012 2023-04-03 22:41:53.596 39 ERROR keystone.server.flask.application   File "/var/lib/kolla/venv/lib/python3.9/site-packages/flask_restful/__init__.py", line 467, in wrapper
2023-04-03 22:41:53.615022 2023-04-03 22:41:53.596 39 ERROR keystone.server.flask.application     resp = resource(*args, **kwargs)
2023-04-03 22:41:53.615032 2023-04-03 22:41:53.596 39 ERROR keystone.server.flask.application   File "/var/lib/kolla/venv/lib/python3.9/site-packages/flask/views.py", line 107, in view
2023-04-03 22:41:53.615073 2023-04-03 22:41:53.596 39 ERROR keystone.server.flask.application     return current_app.ensure_sync(self.dispatch_request)(**kwargs)
2023-04-03 22:41:53.615090 2023-04-03 22:41:53.596 39 ERROR keystone.server.flask.application   File "/var/lib/kolla/venv/lib/python3.9/site-packages/flask_restful/__init__.py", line 582, in dispatch_request
2023-04-03 22:41:53.615100 2023-04-03 22:41:53.596 39 ERROR keystone.server.flask.application     resp = meth(*args, **kwargs)
2023-04-03 22:41:53.615109 2023-04-03 22:41:53.596 39 ERROR keystone.server.flask.application   File "/var/lib/kolla/venv/lib/python3.9/site-packages/keystone/api/projects.py", line 151, in get
2023-04-03 22:41:53.615120 2023-04-03 22:41:53.596 39 ERROR keystone.server.flask.application     return self._get_project(project_id)
2023-04-03 22:41:53.615133 2023-04-03 22:41:53.596 39 ERROR keystone.server.flask.application   File "/var/lib/kolla/venv/lib/python3.9/site-packages/keystone/api/projects.py", line 107, in _get_project
2023-04-03 22:41:53.615146 2023-04-03 22:41:53.596 39 ERROR keystone.server.flask.application     project = PROVIDERS.resource_api.get_project(project_id)
2023-04-03 22:41:53.615155 2023-04-03 22:41:53.596 39 ERROR keystone.server.flask.application   File "/var/lib/kolla/venv/lib/python3.9/site-packages/keystone/common/manager.py", line 115, in wrapped
2023-04-03 22:41:53.615165 2023-04-03 22:41:53.596 39 ERROR keystone.server.flask.application     __ret_val = __f(*args, **kwargs)
2023-04-03 22:41:53.615174 2023-04-03 22:41:53.596 39 ERROR keystone.server.flask.application   File "/var/lib/kolla/venv/lib/python3.9/site-packages/decorator.py", line 232, in fun
2023-04-03 22:41:53.615184 2023-04-03 22:41:53.596 39 ERROR keystone.server.flask.application     return caller(func, *(extras + args), **kw)
2023-04-03 22:41:53.615202 2023-04-03 22:41:53.596 39 ERROR keystone.server.flask.application   File "/var/lib/kolla/venv/lib/python3.9/site-packages/dogpile/cache/region.py", line 1577, in get_or_create_for_user_func
2023-04-03 22:41:53.615214 2023-04-03 22:41:53.596 39 ERROR keystone.server.flask.application     return self.get_or_create(
2023-04-03 22:41:53.615224 2023-04-03 22:41:53.596 39 ERROR keystone.server.flask.application   File "/var/lib/kolla/venv/lib/python3.9/site-packages/dogpile/cache/region.py", line 1042, in get_or_create
2023-04-03 22:41:53.615234 2023-04-03 22:41:53.596 39 ERROR keystone.server.flask.application     with Lock(
2023-04-03 22:41:53.615243 2023-04-03 22:41:53.596 39 ERROR keystone.server.flask.application   File "/var/lib/kolla/venv/lib/python3.9/site-packages/dogpile/lock.py", line 185, in __enter__
2023-04-03 22:41:53.615253 2023-04-03 22:41:53.596 39 ERROR keystone.server.flask.application     return self._enter()
2023-04-03 22:41:53.615284 2023-04-03 22:41:53.596 39 ERROR keystone.server.flask.application   File "/var/lib/kolla/venv/lib/python3.9/site-packages/dogpile/lock.py", line 94, in _enter
2023-04-03 22:41:53.615305 2023-04-03 22:41:53.596 39 ERROR keystone.server.flask.application     generated = self._enter_create(value, createdtime)
2023-04-03 22:41:53.615314 2023-04-03 22:41:53.596 39 ERROR keystone.server.flask.application   File "/var/lib/kolla/venv/lib/python3.9/site-packages/dogpile/lock.py", line 178, in _enter_create
2023-04-03 22:41:53.615330 2023-04-03 22:41:53.596 39 ERROR keystone.server.flask.application     return self.creator()
2023-04-03 22:41:53.615341 2023-04-03 22:41:53.596 39 ERROR keystone.server.flask.application   File "/var/lib/kolla/venv/lib/python3.9/site-packages/dogpile/cache/region.py", line 995, in gen_value
2023-04-03 22:41:53.615351 2023-04-03 22:41:53.596 39 ERROR keystone.server.flask.application     created_value = creator(
2023-04-03 22:41:53.615360 2023-04-03 22:41:53.596 39 ERROR keystone.server.flask.application   File "/var/lib/kolla/venv/lib/python3.9/site-packages/keystone/resource/core.py", line 903, in get_project
2023-04-03 22:41:53.615370 2023-04-03 22:41:53.596 39 ERROR keystone.server.flask.application     return self.driver.get_project(project_id)
2023-04-03 22:41:53.615379 2023-04-03 22:41:53.596 39 ERROR keystone.server.flask.application   File "/var/lib/kolla/venv/lib/python3.9/site-packages/keystone/resource/backends/sql.py", line 49, in get_project
2023-04-03 22:41:53.615389 2023-04-03 22:41:53.596 39 ERROR keystone.server.flask.application     return self._get_project(session, project_id).to_dict()
2023-04-03 22:41:53.615398 2023-04-03 22:41:53.596 39 ERROR keystone.server.flask.application   File "/var/lib/kolla/venv/lib/python3.9/site-packages/keystone/resource/backends/sql.py", line 44, in _get_project
2023-04-03 22:41:53.615408 2023-04-03 22:41:53.596 39 ERROR keystone.server.flask.application     raise exception.ProjectNotFound(project_id=project_id)
2023-04-03 22:41:53.615417 2023-04-03 22:41:53.596 39 ERROR keystone.server.flask.application keystone.exception.ProjectNotFound: Could not find project: service.
2023-04-03 22:41:53.615426 2023-04-03 22:41:53.596 39 ERROR keystone.server.flask.application \x1b[00m
2023-04-03 22:42:08.420982 2023-04-03 22:42:08.414 39 ERROR keystone.server.flask.application [None req-21122378-86db-41cf-b4f1-d68806d06850 ec6785048b4c4da0b2826501dcd6781c - - all default -] Could not find role: admin.: keystone.exception.RoleNotFound: Could not find role: admin.
2023-04-03 22:42:08.421070 2023-04-03 22:42:08.414 39 ERROR keystone.server.flask.application Traceback (most recent call last):
2023-04-03 22:42:08.421088 2023-04-03 22:42:08.414 39 ERROR keystone.server.flask.application   File "/var/lib/kolla/venv/lib/python3.9/site-packages/flask/app.py", line 1820, in full_dispatch_request
2023-04-03 22:42:08.421099 2023-04-03 22:42:08.414 39 ERROR keystone.server.flask.application     rv = self.dispatch_request()
2023-04-03 22:42:08.421108 2023-04-03 22:42:08.414 39 ERROR keystone.server.flask.application   File "/var/lib/kolla/venv/lib/python3.9/site-packages/flask/app.py", line 1796, in dispatch_request
2023-04-03 22:42:08.421119 2023-04-03 22:42:08.414 39 ERROR keystone.server.flask.application     return self.ensure_sync(self.view_functions[rule.endpoint])(**view_args)
2023-04-03 22:42:08.421128 2023-04-03 22:42:08.414 39 ERROR keystone.server.flask.application   File "/var/lib/kolla/venv/lib/python3.9/site-packages/flask_restful/__init__.py", line 467, in wrapper
2023-04-03 22:42:08.421138 2023-04-03 22:42:08.414 39 ERROR keystone.server.flask.application     resp = resource(*args, **kwargs)
2023-04-03 22:42:08.421148 2023-04-03 22:42:08.414 39 ERROR keystone.server.flask.application   File "/var/lib/kolla/venv/lib/python3.9/site-packages/flask/views.py", line 107, in view
2023-04-03 22:42:08.421158 2023-04-03 22:42:08.414 39 ERROR keystone.server.flask.application     return current_app.ensure_sync(self.dispatch_request)(**kwargs)
2023-04-03 22:42:08.421167 2023-04-03 22:42:08.414 39 ERROR keystone.server.flask.application   File "/var/lib/kolla/venv/lib/python3.9/site-packages/flask_restful/__init__.py", line 582, in dispatch_request
2023-04-03 22:42:08.421207 2023-04-03 22:42:08.414 39 ERROR keystone.server.flask.application     resp = meth(*args, **kwargs)
2023-04-03 22:42:08.421218 2023-04-03 22:42:08.414 39 ERROR keystone.server.flask.application   File "/var/lib/kolla/venv/lib/python3.9/site-packages/keystone/api/roles.py", line 50, in get
2023-04-03 22:42:08.421228 2023-04-03 22:42:08.414 39 ERROR keystone.server.flask.application     return self._get_role(role_id)
2023-04-03 22:42:08.421237 2023-04-03 22:42:08.414 39 ERROR keystone.server.flask.application   File "/var/lib/kolla/venv/lib/python3.9/site-packages/keystone/api/roles.py", line 70, in _get_role
2023-04-03 22:42:08.421247 2023-04-03 22:42:08.414 39 ERROR keystone.server.flask.application     ENFORCER.enforce_call(action='identity:get_role')
2023-04-03 22:42:08.421265 2023-04-03 22:42:08.414 39 ERROR keystone.server.flask.application   File "/var/lib/kolla/venv/lib/python3.9/site-packages/keystone/common/rbac_enforcer/enforcer.py", line 402, in enforce_call
2023-04-03 22:42:08.421278 2023-04-03 22:42:08.414 39 ERROR keystone.server.flask.application     policy_dict.update(cls._extract_member_target_data(
2023-04-03 22:42:08.421289 2023-04-03 22:42:08.414 39 ERROR keystone.server.flask.application   File "/var/lib/kolla/venv/lib/python3.9/site-packages/keystone/common/rbac_enforcer/enforcer.py", line 234, in _extract_member_target_data
2023-04-03 22:42:08.421299 2023-04-03 22:42:08.414 39 ERROR keystone.server.flask.application     member_name: func(flask.request.view_args[key])
2023-04-03 22:42:08.421308 2023-04-03 22:42:08.414 39 ERROR keystone.server.flask.application   File "/var/lib/kolla/venv/lib/python3.9/site-packages/keystone/common/manager.py", line 115, in wrapped
2023-04-03 22:42:08.421318 2023-04-03 22:42:08.414 39 ERROR keystone.server.flask.application     __ret_val = __f(*args, **kwargs)
2023-04-03 22:42:08.421327 2023-04-03 22:42:08.414 39 ERROR keystone.server.flask.application   File "/var/lib/kolla/venv/lib/python3.9/site-packages/decorator.py", line 232, in fun
2023-04-03 22:42:08.421349 2023-04-03 22:42:08.414 39 ERROR keystone.server.flask.application     return caller(func, *(extras + args), **kw)
2023-04-03 22:42:08.421360 2023-04-03 22:42:08.414 39 ERROR keystone.server.flask.application   File "/var/lib/kolla/venv/lib/python3.9/site-packages/dogpile/cache/region.py", line 1577, in get_or_create_for_user_func
2023-04-03 22:42:08.421370 2023-04-03 22:42:08.414 39 ERROR keystone.server.flask.application     return self.get_or_create(
2023-04-03 22:42:08.421380 2023-04-03 22:42:08.414 39 ERROR keystone.server.flask.application   File "/var/lib/kolla/venv/lib/python3.9/site-packages/dogpile/cache/region.py", line 1042, in get_or_create
2023-04-03 22:42:08.421390 2023-04-03 22:42:08.414 39 ERROR keystone.server.flask.application     with Lock(
2023-04-03 22:42:08.421399 2023-04-03 22:42:08.414 39 ERROR keystone.server.flask.application   File "/var/lib/kolla/venv/lib/python3.9/site-packages/dogpile/lock.py", line 185, in __enter__
2023-04-03 22:42:08.421409 2023-04-03 22:42:08.414 39 ERROR keystone.server.flask.application     return self._enter()
2023-04-03 22:42:08.421418 2023-04-03 22:42:08.414 39 ERROR keystone.server.flask.application   File "/var/lib/kolla/venv/lib/python3.9/site-packages/dogpile/lock.py", line 94, in _enter
2023-04-03 22:42:08.421428 2023-04-03 22:42:08.414 39 ERROR keystone.server.flask.application     generated = self._enter_create(value, createdtime)
2023-04-03 22:42:08.421437 2023-04-03 22:42:08.414 39 ERROR keystone.server.flask.application   File "/var/lib/kolla/venv/lib/python3.9/site-packages/dogpile/lock.py", line 178, in _enter_create
2023-04-03 22:42:08.421464 2023-04-03 22:42:08.414 39 ERROR keystone.server.flask.application     return self.creator()
2023-04-03 22:42:08.421476 2023-04-03 22:42:08.414 39 ERROR keystone.server.flask.application   File "/var/lib/kolla/venv/lib/python3.9/site-packages/dogpile/cache/region.py", line 995, in gen_value
2023-04-03 22:42:08.421537 2023-04-03 22:42:08.414 39 ERROR keystone.server.flask.application     created_value = creator(
2023-04-03 22:42:08.421552 2023-04-03 22:42:08.414 39 ERROR keystone.server.flask.application   File "/var/lib/kolla/venv/lib/python3.9/site-packages/keystone/assignment/core.py", line 1276, in get_role
2023-04-03 22:42:08.421562 2023-04-03 22:42:08.414 39 ERROR keystone.server.flask.application     return self.driver.get_role(role_id)
2023-04-03 22:42:08.421572 2023-04-03 22:42:08.414 39 ERROR keystone.server.flask.application   File "/var/lib/kolla/venv/lib/python3.9/site-packages/keystone/assignment/role_backends/sql.py", line 70, in get_role
2023-04-03 22:42:08.421581 2023-04-03 22:42:08.414 39 ERROR keystone.server.flask.application     return self._get_role(session, role_id).to_dict()
2023-04-03 22:42:08.421591 2023-04-03 22:42:08.414 39 ERROR keystone.server.flask.application   File "/var/lib/kolla/venv/lib/python3.9/site-packages/keystone/assignment/role_backends/sql.py", line 65, in _get_role
2023-04-03 22:42:08.421601 2023-04-03 22:42:08.414 39 ERROR keystone.server.flask.application     raise exception.RoleNotFound(role_id=role_id)
2023-04-03 22:42:08.421610 2023-04-03 22:42:08.414 39 ERROR keystone.server.flask.application keystone.exception.RoleNotFound: Could not find role: admin.
2023-04-03 22:42:08.421620 2023-04-03 22:42:08.414 39 ERROR keystone.server.flask.application \x1b[00m
2023-04-03 22:42:09.790986 2023-04-03 22:42:09.785 39 ERROR keystone.server.flask.application [None req-a1521ade-678c-4109-8f31-9dae5186ae88 ec6785048b4c4da0b2826501dcd6781c - - all default -] Could not find user: ironic.: keystone.exception.UserNotFound: Could not find user: ironic.
2023-04-03 22:42:09.791069 2023-04-03 22:42:09.785 39 ERROR keystone.server.flask.application Traceback (most recent call last):
2023-04-03 22:42:09.791085 2023-04-03 22:42:09.785 39 ERROR keystone.server.flask.application   File "/var/lib/kolla/venv/lib/python3.9/site-packages/flask/app.py", line 1820, in full_dispatch_request
2023-04-03 22:42:09.791095 2023-04-03 22:42:09.785 39 ERROR keystone.server.flask.application     rv = self.dispatch_request()
2023-04-03 22:42:09.791105 2023-04-03 22:42:09.785 39 ERROR keystone.server.flask.application   File "/var/lib/kolla/venv/lib/python3.9/site-packages/flask/app.py", line 1796, in dispatch_request
2023-04-03 22:42:09.791115 2023-04-03 22:42:09.785 39 ERROR keystone.server.flask.application     return self.ensure_sync(self.view_functions[rule.endpoint])(**view_args)
2023-04-03 22:42:09.791125 2023-04-03 22:42:09.785 39 ERROR keystone.server.flask.application   File "/var/lib/kolla/venv/lib/python3.9/site-packages/flask_restful/__init__.py", line 467, in wrapper
2023-04-03 22:42:09.791134 2023-04-03 22:42:09.785 39 ERROR keystone.server.flask.application     resp = resource(*args, **kwargs)
2023-04-03 22:42:09.791144 2023-04-03 22:42:09.785 39 ERROR keystone.server.flask.application   File "/var/lib/kolla/venv/lib/python3.9/site-packages/flask/views.py", line 107, in view
2023-04-03 22:42:09.791154 2023-04-03 22:42:09.785 39 ERROR keystone.server.flask.application     return current_app.ensure_sync(self.dispatch_request)(**kwargs)
2023-04-03 22:42:09.791163 2023-04-03 22:42:09.785 39 ERROR keystone.server.flask.application   File "/var/lib/kolla/venv/lib/python3.9/site-packages/flask_restful/__init__.py", line 582, in dispatch_request
2023-04-03 22:42:09.791173 2023-04-03 22:42:09.785 39 ERROR keystone.server.flask.application     resp = meth(*args, **kwargs)
2023-04-03 22:42:09.791182 2023-04-03 22:42:09.785 39 ERROR keystone.server.flask.application   File "/var/lib/kolla/venv/lib/python3.9/site-packages/keystone/api/users.py", line 182, in get
2023-04-03 22:42:09.791191 2023-04-03 22:42:09.785 39 ERROR keystone.server.flask.application     return self._get_user(user_id)
2023-04-03 22:42:09.791201 2023-04-03 22:42:09.785 39 ERROR keystone.server.flask.application   File "/var/lib/kolla/venv/lib/python3.9/site-packages/keystone/api/users.py", line 194, in _get_user
2023-04-03 22:42:09.791226 2023-04-03 22:42:09.785 39 ERROR keystone.server.flask.application     ref = PROVIDERS.identity_api.get_user(user_id)
2023-04-03 22:42:09.791237 2023-04-03 22:42:09.785 39 ERROR keystone.server.flask.application   File "/var/lib/kolla/venv/lib/python3.9/site-packages/keystone/common/manager.py", line 115, in wrapped
2023-04-03 22:42:09.791247 2023-04-03 22:42:09.785 39 ERROR keystone.server.flask.application     __ret_val = __f(*args, **kwargs)
2023-04-03 22:42:09.791257 2023-04-03 22:42:09.785 39 ERROR keystone.server.flask.application   File "/var/lib/kolla/venv/lib/python3.9/site-packages/keystone/identity/core.py", line 414, in wrapper
2023-04-03 22:42:09.791267 2023-04-03 22:42:09.785 39 ERROR keystone.server.flask.application     return f(self, *args, **kwargs)
2023-04-03 22:42:09.791276 2023-04-03 22:42:09.785 39 ERROR keystone.server.flask.application   File "/var/lib/kolla/venv/lib/python3.9/site-packages/keystone/identity/core.py", line 424, in wrapper
2023-04-03 22:42:09.791286 2023-04-03 22:42:09.785 39 ERROR keystone.server.flask.application     return f(self, *args, **kwargs)
2023-04-03 22:42:09.791296 2023-04-03 22:42:09.785 39 ERROR keystone.server.flask.application   File "/var/lib/kolla/venv/lib/python3.9/site-packages/decorator.py", line 232, in fun
2023-04-03 22:42:09.791306 2023-04-03 22:42:09.785 39 ERROR keystone.server.flask.application     return caller(func, *(extras + args), **kw)
2023-04-03 22:42:09.791316 2023-04-03 22:42:09.785 39 ERROR keystone.server.flask.application   File "/var/lib/kolla/venv/lib/python3.9/site-packages/dogpile/cache/region.py", line 1577, in get_or_create_for_user_func
2023-04-03 22:42:09.791326 2023-04-03 22:42:09.785 39 ERROR keystone.server.flask.application     return self.get_or_create(
2023-04-03 22:42:09.791335 2023-04-03 22:42:09.785 39 ERROR keystone.server.flask.application   File "/var/lib/kolla/venv/lib/python3.9/site-packages/dogpile/cache/region.py", line 1042, in get_or_create
2023-04-03 22:42:09.791346 2023-04-03 22:42:09.785 39 ERROR keystone.server.flask.application     with Lock(
2023-04-03 22:42:09.791355 2023-04-03 22:42:09.785 39 ERROR keystone.server.flask.application   File "/var/lib/kolla/venv/lib/python3.9/site-packages/dogpile/lock.py", line 185, in __enter__
2023-04-03 22:42:09.791365 2023-04-03 22:42:09.785 39 ERROR keystone.server.flask.application     return self._enter()
2023-04-03 22:42:09.791374 2023-04-03 22:42:09.785 39 ERROR keystone.server.flask.application   File "/var/lib/kolla/venv/lib/python3.9/site-packages/dogpile/lock.py", line 94, in _enter
2023-04-03 22:42:09.791384 2023-04-03 22:42:09.785 39 ERROR keystone.server.flask.application     generated = self._enter_create(value, createdtime)
2023-04-03 22:42:09.791394 2023-04-03 22:42:09.785 39 ERROR keystone.server.flask.application   File "/var/lib/kolla/venv/lib/python3.9/site-packages/dogpile/lock.py", line 178, in _enter_create
2023-04-03 22:42:09.791404 2023-04-03 22:42:09.785 39 ERROR keystone.server.flask.application     return self.creator()
2023-04-03 22:42:09.791413 2023-04-03 22:42:09.785 39 ERROR keystone.server.flask.application   File "/var/lib/kolla/venv/lib/python3.9/site-packages/dogpile/cache/region.py", line 995, in gen_value
2023-04-03 22:42:09.791423 2023-04-03 22:42:09.785 39 ERROR keystone.server.flask.application     created_value = creator(
2023-04-03 22:42:09.791433 2023-04-03 22:42:09.785 39 ERROR keystone.server.flask.application   File "/var/lib/kolla/venv/lib/python3.9/site-packages/keystone/identity/core.py", line 1011, in get_user
2023-04-03 22:42:09.791442 2023-04-03 22:42:09.785 39 ERROR keystone.server.flask.application     ref = driver.get_user(entity_id)
2023-04-03 22:42:09.791452 2023-04-03 22:42:09.785 39 ERROR keystone.server.flask.application   File "/var/lib/kolla/venv/lib/python3.9/site-packages/keystone/identity/backends/sql.py", line 200, in get_user
2023-04-03 22:42:09.791462 2023-04-03 22:42:09.785 39 ERROR keystone.server.flask.application     self._get_user(session, user_id).to_dict())
2023-04-03 22:42:09.791505 2023-04-03 22:42:09.785 39 ERROR keystone.server.flask.application   File "/var/lib/kolla/venv/lib/python3.9/site-packages/keystone/identity/backends/sql.py", line 194, in _get_user
2023-04-03 22:42:09.791521 2023-04-03 22:42:09.785 39 ERROR keystone.server.flask.application     raise exception.UserNotFound(user_id=user_id)
2023-04-03 22:42:09.791531 2023-04-03 22:42:09.785 39 ERROR keystone.server.flask.application keystone.exception.UserNotFound: Could not find user: ironic.
2023-04-03 22:42:09.791541 2023-04-03 22:42:09.785 39 ERROR keystone.server.flask.application \x1b[00m
2023-04-03 22:42:10.720409 2023-04-03 22:42:10.705 37 ERROR keystone.server.flask.application [None req-36451cda-49de-4eb4-a1b7-35265be09417 ec6785048b4c4da0b2826501dcd6781c - - all default -] Could not find project: service.: keystone.exception.ProjectNotFound: Could not find project: service.
2023-04-03 22:42:10.720518 2023-04-03 22:42:10.705 37 ERROR keystone.server.flask.application Traceback (most recent call last):
2023-04-03 22:42:10.720540 2023-04-03 22:42:10.705 37 ERROR keystone.server.flask.application   File "/var/lib/kolla/venv/lib/python3.9/site-packages/flask/app.py", line 1820, in full_dispatch_request
2023-04-03 22:42:10.720562 2023-04-03 22:42:10.705 37 ERROR keystone.server.flask.application     rv = self.dispatch_request()
2023-04-03 22:42:10.720573 2023-04-03 22:42:10.705 37 ERROR keystone.server.flask.application   File "/var/lib/kolla/venv/lib/python3.9/site-packages/flask/app.py", line 1796, in dispatch_request
2023-04-03 22:42:10.720583 2023-04-03 22:42:10.705 37 ERROR keystone.server.flask.application     return self.ensure_sync(self.view_functions[rule.endpoint])(**view_args)
2023-04-03 22:42:10.720593 2023-04-03 22:42:10.705 37 ERROR keystone.server.flask.application   File "/var/lib/kolla/venv/lib/python3.9/site-packages/flask_restful/__init__.py", line 467, in wrapper
2023-04-03 22:42:10.720603 2023-04-03 22:42:10.705 37 ERROR keystone.server.flask.application     resp = resource(*args, **kwargs)
2023-04-03 22:42:10.720619 2023-04-03 22:42:10.705 37 ERROR keystone.server.flask.application   File "/var/lib/kolla/venv/lib/python3.9/site-packages/flask/views.py", line 107, in view
2023-04-03 22:42:10.720632 2023-04-03 22:42:10.705 37 ERROR keystone.server.flask.application     return current_app.ensure_sync(self.dispatch_request)(**kwargs)
2023-04-03 22:42:10.720642 2023-04-03 22:42:10.705 37 ERROR keystone.server.flask.application   File "/var/lib/kolla/venv/lib/python3.9/site-packages/flask_restful/__init__.py", line 582, in dispatch_request
2023-04-03 22:42:10.720652 2023-04-03 22:42:10.705 37 ERROR keystone.server.flask.application     resp = meth(*args, **kwargs)
2023-04-03 22:42:10.720662 2023-04-03 22:42:10.705 37 ERROR keystone.server.flask.application   File "/var/lib/kolla/venv/lib/python3.9/site-packages/keystone/api/projects.py", line 151, in get
2023-04-03 22:42:10.720672 2023-04-03 22:42:10.705 37 ERROR keystone.server.flask.application     return self._get_project(project_id)
2023-04-03 22:42:10.720682 2023-04-03 22:42:10.705 37 ERROR keystone.server.flask.application   File "/var/lib/kolla/venv/lib/python3.9/site-packages/keystone/api/projects.py", line 107, in _get_project
2023-04-03 22:42:10.720691 2023-04-03 22:42:10.705 37 ERROR keystone.server.flask.application     project = PROVIDERS.resource_api.get_project(project_id)
2023-04-03 22:42:10.720701 2023-04-03 22:42:10.705 37 ERROR keystone.server.flask.application   File "/var/lib/kolla/venv/lib/python3.9/site-packages/keystone/common/manager.py", line 115, in wrapped
2023-04-03 22:42:10.720711 2023-04-03 22:42:10.705 37 ERROR keystone.server.flask.application     __ret_val = __f(*args, **kwargs)
2023-04-03 22:42:10.720720 2023-04-03 22:42:10.705 37 ERROR keystone.server.flask.application   File "/var/lib/kolla/venv/lib/python3.9/site-packages/decorator.py", line 232, in fun
2023-04-03 22:42:10.720730 2023-04-03 22:42:10.705 37 ERROR keystone.server.flask.application     return caller(func, *(extras + args), **kw)
2023-04-03 22:42:10.720756 2023-04-03 22:42:10.705 37 ERROR keystone.server.flask.application   File "/var/lib/kolla/venv/lib/python3.9/site-packages/dogpile/cache/region.py", line 1577, in get_or_create_for_user_func
2023-04-03 22:42:10.720769 2023-04-03 22:42:10.705 37 ERROR keystone.server.flask.application     return self.get_or_create(
2023-04-03 22:42:10.720778 2023-04-03 22:42:10.705 37 ERROR keystone.server.flask.application   File "/var/lib/kolla/venv/lib/python3.9/site-packages/dogpile/cache/region.py", line 1042, in get_or_create
2023-04-03 22:42:10.720789 2023-04-03 22:42:10.705 37 ERROR keystone.server.flask.application     with Lock(
2023-04-03 22:42:10.720798 2023-04-03 22:42:10.705 37 ERROR keystone.server.flask.application   File "/var/lib/kolla/venv/lib/python3.9/site-packages/dogpile/lock.py", line 185, in __enter__
2023-04-03 22:42:10.720808 2023-04-03 22:42:10.705 37 ERROR keystone.server.flask.application     return self._enter()
2023-04-03 22:42:10.720818 2023-04-03 22:42:10.705 37 ERROR keystone.server.flask.application   File "/var/lib/kolla/venv/lib/python3.9/site-packages/dogpile/lock.py", line 94, in _enter
2023-04-03 22:42:10.720828 2023-04-03 22:42:10.705 37 ERROR keystone.server.flask.application     generated = self._enter_create(value, createdtime)
2023-04-03 22:42:10.720837 2023-04-03 22:42:10.705 37 ERROR keystone.server.flask.application   File "/var/lib/kolla/venv/lib/python3.9/site-packages/dogpile/lock.py", line 178, in _enter_create
2023-04-03 22:42:10.720847 2023-04-03 22:42:10.705 37 ERROR keystone.server.flask.application     return self.creator()
2023-04-03 22:42:10.720856 2023-04-03 22:42:10.705 37 ERROR keystone.server.flask.application   File "/var/lib/kolla/venv/lib/python3.9/site-packages/dogpile/cache/region.py", line 995, in gen_value
2023-04-03 22:42:10.720866 2023-04-03 22:42:10.705 37 ERROR keystone.server.flask.application     created_value = creator(
2023-04-03 22:42:10.720876 2023-04-03 22:42:10.705 37 ERROR keystone.server.flask.application   File "/var/lib/kolla/venv/lib/python3.9/site-packages/keystone/resource/core.py", line 903, in get_project
2023-04-03 22:42:10.720886 2023-04-03 22:42:10.705 37 ERROR keystone.server.flask.application     return self.driver.get_project(project_id)
2023-04-03 22:42:10.720896 2023-04-03 22:42:10.705 37 ERROR keystone.server.flask.application   File "/var/lib/kolla/venv/lib/python3.9/site-packages/keystone/resource/backends/sql.py", line 49, in get_project
2023-04-03 22:42:10.720906 2023-04-03 22:42:10.705 37 ERROR keystone.server.flask.application     return self._get_project(session, project_id).to_dict()
2023-04-03 22:42:10.720915 2023-04-03 22:42:10.705 37 ERROR keystone.server.flask.application   File "/var/lib/kolla/venv/lib/python3.9/site-packages/keystone/resource/backends/sql.py", line 44, in _get_project
2023-04-03 22:42:10.720925 2023-04-03 22:42:10.705 37 ERROR keystone.server.flask.application     raise exception.ProjectNotFound(project_id=project_id)
2023-04-03 22:42:10.720934 2023-04-03 22:42:10.705 37 ERROR keystone.server.flask.application keystone.exception.ProjectNotFound: Could not find project: service.
2023-04-03 22:42:10.720944 2023-04-03 22:42:10.705 37 ERROR keystone.server.flask.application \x1b[00m
2023-04-03 22:42:20.654946 2023-04-03 22:42:20.646 38 ERROR keystone.server.flask.application [None req-ba97d9d6-6afd-4728-b200-986db46eb724 ec6785048b4c4da0b2826501dcd6781c - - all default -] Could not find role: admin.: keystone.exception.RoleNotFound: Could not find role: admin.
2023-04-03 22:42:20.655014 2023-04-03 22:42:20.646 38 ERROR keystone.server.flask.application Traceback (most recent call last):
2023-04-03 22:42:20.655028 2023-04-03 22:42:20.646 38 ERROR keystone.server.flask.application   File "/var/lib/kolla/venv/lib/python3.9/site-packages/flask/app.py", line 1820, in full_dispatch_request
2023-04-03 22:42:20.655075 2023-04-03 22:42:20.646 38 ERROR keystone.server.flask.application     rv = self.dispatch_request()
2023-04-03 22:42:20.655087 2023-04-03 22:42:20.646 38 ERROR keystone.server.flask.application   File "/var/lib/kolla/venv/lib/python3.9/site-packages/flask/app.py", line 1796, in dispatch_request
2023-04-03 22:42:20.655113 2023-04-03 22:42:20.646 38 ERROR keystone.server.flask.application     return self.ensure_sync(self.view_functions[rule.endpoint])(**view_args)
2023-04-03 22:42:20.655125 2023-04-03 22:42:20.646 38 ERROR keystone.server.flask.application   File "/var/lib/kolla/venv/lib/python3.9/site-packages/flask_restful/__init__.py", line 467, in wrapper
2023-04-03 22:42:20.655136 2023-04-03 22:42:20.646 38 ERROR keystone.server.flask.application     resp = resource(*args, **kwargs)
2023-04-03 22:42:20.655155 2023-04-03 22:42:20.646 38 ERROR keystone.server.flask.application   File "/var/lib/kolla/venv/lib/python3.9/site-packages/flask/views.py", line 107, in view
2023-04-03 22:42:20.655174 2023-04-03 22:42:20.646 38 ERROR keystone.server.flask.application     return current_app.ensure_sync(self.dispatch_request)(**kwargs)
2023-04-03 22:42:20.655187 2023-04-03 22:42:20.646 38 ERROR keystone.server.flask.application   File "/var/lib/kolla/venv/lib/python3.9/site-packages/flask_restful/__init__.py", line 582, in dispatch_request
2023-04-03 22:42:20.655199 2023-04-03 22:42:20.646 38 ERROR keystone.server.flask.application     resp = meth(*args, **kwargs)
2023-04-03 22:42:20.655209 2023-04-03 22:42:20.646 38 ERROR keystone.server.flask.application   File "/var/lib/kolla/venv/lib/python3.9/site-packages/keystone/api/roles.py", line 50, in get
2023-04-03 22:42:20.655220 2023-04-03 22:42:20.646 38 ERROR keystone.server.flask.application     return self._get_role(role_id)
2023-04-03 22:42:20.655230 2023-04-03 22:42:20.646 38 ERROR keystone.server.flask.application   File "/var/lib/kolla/venv/lib/python3.9/site-packages/keystone/api/roles.py", line 70, in _get_role
2023-04-03 22:42:20.655241 2023-04-03 22:42:20.646 38 ERROR keystone.server.flask.application     ENFORCER.enforce_call(action='identity:get_role')
2023-04-03 22:42:20.655258 2023-04-03 22:42:20.646 38 ERROR keystone.server.flask.application   File "/var/lib/kolla/venv/lib/python3.9/site-packages/keystone/common/rbac_enforcer/enforcer.py", line 402, in enforce_call
2023-04-03 22:42:20.655271 2023-04-03 22:42:20.646 38 ERROR keystone.server.flask.application     policy_dict.update(cls._extract_member_target_data(
2023-04-03 22:42:20.655288 2023-04-03 22:42:20.646 38 ERROR keystone.server.flask.application   File "/var/lib/kolla/venv/lib/python3.9/site-packages/keystone/common/rbac_enforcer/enforcer.py", line 234, in _extract_member_target_data
2023-04-03 22:42:20.655311 2023-04-03 22:42:20.646 38 ERROR keystone.server.flask.application     member_name: func(flask.request.view_args[key])
2023-04-03 22:42:20.655322 2023-04-03 22:42:20.646 38 ERROR keystone.server.flask.application   File "/var/lib/kolla/venv/lib/python3.9/site-packages/keystone/common/manager.py", line 115, in wrapped
2023-04-03 22:42:20.655333 2023-04-03 22:42:20.646 38 ERROR keystone.server.flask.application     __ret_val = __f(*args, **kwargs)
2023-04-03 22:42:20.655343 2023-04-03 22:42:20.646 38 ERROR keystone.server.flask.application   File "/var/lib/kolla/venv/lib/python3.9/site-packages/decorator.py", line 232, in fun
2023-04-03 22:42:20.655354 2023-04-03 22:42:20.646 38 ERROR keystone.server.flask.application     return caller(func, *(extras + args), **kw)
2023-04-03 22:42:20.655365 2023-04-03 22:42:20.646 38 ERROR keystone.server.flask.application   File "/var/lib/kolla/venv/lib/python3.9/site-packages/dogpile/cache/region.py", line 1577, in get_or_create_for_user_func
2023-04-03 22:42:20.655375 2023-04-03 22:42:20.646 38 ERROR keystone.server.flask.application     return self.get_or_create(
2023-04-03 22:42:20.655386 2023-04-03 22:42:20.646 38 ERROR keystone.server.flask.application   File "/var/lib/kolla/venv/lib/python3.9/site-packages/dogpile/cache/region.py", line 1042, in get_or_create
2023-04-03 22:42:20.655397 2023-04-03 22:42:20.646 38 ERROR keystone.server.flask.application     with Lock(
2023-04-03 22:42:20.655428 2023-04-03 22:42:20.646 38 ERROR keystone.server.flask.application   File "/var/lib/kolla/venv/lib/python3.9/site-packages/dogpile/lock.py", line 185, in __enter__
2023-04-03 22:42:20.655441 2023-04-03 22:42:20.646 38 ERROR keystone.server.flask.application     return self._enter()
2023-04-03 22:42:20.655452 2023-04-03 22:42:20.646 38 ERROR keystone.server.flask.application   File "/var/lib/kolla/venv/lib/python3.9/site-packages/dogpile/lock.py", line 94, in _enter
2023-04-03 22:42:20.655463 2023-04-03 22:42:20.646 38 ERROR keystone.server.flask.application     generated = self._enter_create(value, createdtime)
2023-04-03 22:42:20.655474 2023-04-03 22:42:20.646 38 ERROR keystone.server.flask.application   File "/var/lib/kolla/venv/lib/python3.9/site-packages/dogpile/lock.py", line 178, in _enter_create
2023-04-03 22:42:20.655518 2023-04-03 22:42:20.646 38 ERROR keystone.server.flask.application     return self.creator()
2023-04-03 22:42:20.655534 2023-04-03 22:42:20.646 38 ERROR keystone.server.flask.application   File "/var/lib/kolla/venv/lib/python3.9/site-packages/dogpile/cache/region.py", line 995, in gen_value
2023-04-03 22:42:20.655546 2023-04-03 22:42:20.646 38 ERROR keystone.server.flask.application     created_value = creator(
2023-04-03 22:42:20.655670 2023-04-03 22:42:20.646 38 ERROR keystone.server.flask.application   File "/var/lib/kolla/venv/lib/python3.9/site-packages/keystone/assignment/core.py", line 1276, in get_role
2023-04-03 22:42:20.655685 2023-04-03 22:42:20.646 38 ERROR keystone.server.flask.application     return self.driver.get_role(role_id)
2023-04-03 22:42:20.655696 2023-04-03 22:42:20.646 38 ERROR keystone.server.flask.application   File "/var/lib/kolla/venv/lib/python3.9/site-packages/keystone/assignment/role_backends/sql.py", line 70, in get_role
2023-04-03 22:42:20.655707 2023-04-03 22:42:20.646 38 ERROR keystone.server.flask.application     return self._get_role(session, role_id).to_dict()
2023-04-03 22:42:20.655718 2023-04-03 22:42:20.646 38 ERROR keystone.server.flask.application   File "/var/lib/kolla/venv/lib/python3.9/site-packages/keystone/assignment/role_backends/sql.py", line 65, in _get_role
2023-04-03 22:42:20.655729 2023-04-03 22:42:20.646 38 ERROR keystone.server.flask.application     raise exception.RoleNotFound(role_id=role_id)
2023-04-03 22:42:20.655740 2023-04-03 22:42:20.646 38 ERROR keystone.server.flask.application keystone.exception.RoleNotFound: Could not find role: admin.
2023-04-03 22:42:20.655751 2023-04-03 22:42:20.646 38 ERROR keystone.server.flask.application \x1b[00m
2023-04-03 22:42:22.147412 2023-04-03 22:42:22.137 38 ERROR keystone.server.flask.application [None req-a2473199-dad0-4a2c-83ea-c07f57787882 ec6785048b4c4da0b2826501dcd6781c - - all default -] Could not find user: ironic-inspector.: keystone.exception.UserNotFound: Could not find user: ironic-inspector.
2023-04-03 22:42:22.147562 2023-04-03 22:42:22.137 38 ERROR keystone.server.flask.application Traceback (most recent call last):
2023-04-03 22:42:22.147581 2023-04-03 22:42:22.137 38 ERROR keystone.server.flask.application   File "/var/lib/kolla/venv/lib/python3.9/site-packages/flask/app.py", line 1820, in full_dispatch_request
2023-04-03 22:42:22.147596 2023-04-03 22:42:22.137 38 ERROR keystone.server.flask.application     rv = self.dispatch_request()
2023-04-03 22:42:22.147609 2023-04-03 22:42:22.137 38 ERROR keystone.server.flask.application   File "/var/lib/kolla/venv/lib/python3.9/site-packages/flask/app.py", line 1796, in dispatch_request
2023-04-03 22:42:22.147623 2023-04-03 22:42:22.137 38 ERROR keystone.server.flask.application     return self.ensure_sync(self.view_functions[rule.endpoint])(**view_args)
2023-04-03 22:42:22.147637 2023-04-03 22:42:22.137 38 ERROR keystone.server.flask.application   File "/var/lib/kolla/venv/lib/python3.9/site-packages/flask_restful/__init__.py", line 467, in wrapper
2023-04-03 22:42:22.147651 2023-04-03 22:42:22.137 38 ERROR keystone.server.flask.application     resp = resource(*args, **kwargs)
2023-04-03 22:42:22.147674 2023-04-03 22:42:22.137 38 ERROR keystone.server.flask.application   File "/var/lib/kolla/venv/lib/python3.9/site-packages/flask/views.py", line 107, in view
2023-04-03 22:42:22.147714 2023-04-03 22:42:22.137 38 ERROR keystone.server.flask.application     return current_app.ensure_sync(self.dispatch_request)(**kwargs)
2023-04-03 22:42:22.147730 2023-04-03 22:42:22.137 38 ERROR keystone.server.flask.application   File "/var/lib/kolla/venv/lib/python3.9/site-packages/flask_restful/__init__.py", line 582, in dispatch_request
2023-04-03 22:42:22.147744 2023-04-03 22:42:22.137 38 ERROR keystone.server.flask.application     resp = meth(*args, **kwargs)
2023-04-03 22:42:22.147758 2023-04-03 22:42:22.137 38 ERROR keystone.server.flask.application   File "/var/lib/kolla/venv/lib/python3.9/site-packages/keystone/api/users.py", line 182, in get
2023-04-03 22:42:22.147771 2023-04-03 22:42:22.137 38 ERROR keystone.server.flask.application     return self._get_user(user_id)
2023-04-03 22:42:22.147785 2023-04-03 22:42:22.137 38 ERROR keystone.server.flask.application   File "/var/lib/kolla/venv/lib/python3.9/site-packages/keystone/api/users.py", line 194, in _get_user
2023-04-03 22:42:22.147810 2023-04-03 22:42:22.137 38 ERROR keystone.server.flask.application     ref = PROVIDERS.identity_api.get_user(user_id)
2023-04-03 22:42:22.147826 2023-04-03 22:42:22.137 38 ERROR keystone.server.flask.application   File "/var/lib/kolla/venv/lib/python3.9/site-packages/keystone/common/manager.py", line 115, in wrapped
2023-04-03 22:42:22.147840 2023-04-03 22:42:22.137 38 ERROR keystone.server.flask.application     __ret_val = __f(*args, **kwargs)
2023-04-03 22:42:22.147854 2023-04-03 22:42:22.137 38 ERROR keystone.server.flask.application   File "/var/lib/kolla/venv/lib/python3.9/site-packages/keystone/identity/core.py", line 414, in wrapper
2023-04-03 22:42:22.147868 2023-04-03 22:42:22.137 38 ERROR keystone.server.flask.application     return f(self, *args, **kwargs)
2023-04-03 22:42:22.147881 2023-04-03 22:42:22.137 38 ERROR keystone.server.flask.application   File "/var/lib/kolla/venv/lib/python3.9/site-packages/keystone/identity/core.py", line 424, in wrapper
2023-04-03 22:42:22.147895 2023-04-03 22:42:22.137 38 ERROR keystone.server.flask.application     return f(self, *args, **kwargs)
2023-04-03 22:42:22.147908 2023-04-03 22:42:22.137 38 ERROR keystone.server.flask.application   File "/var/lib/kolla/venv/lib/python3.9/site-packages/decorator.py", line 232, in fun
2023-04-03 22:42:22.147922 2023-04-03 22:42:22.137 38 ERROR keystone.server.flask.application     return caller(func, *(extras + args), **kw)
2023-04-03 22:42:22.147936 2023-04-03 22:42:22.137 38 ERROR keystone.server.flask.application   File "/var/lib/kolla/venv/lib/python3.9/site-packages/dogpile/cache/region.py", line 1577, in get_or_create_for_user_func
2023-04-03 22:42:22.147950 2023-04-03 22:42:22.137 38 ERROR keystone.server.flask.application     return self.get_or_create(
2023-04-03 22:42:22.147963 2023-04-03 22:42:22.137 38 ERROR keystone.server.flask.application   File "/var/lib/kolla/venv/lib/python3.9/site-packages/dogpile/cache/region.py", line 1042, in get_or_create
2023-04-03 22:42:22.147977 2023-04-03 22:42:22.137 38 ERROR keystone.server.flask.application     with Lock(
2023-04-03 22:42:22.147991 2023-04-03 22:42:22.137 38 ERROR keystone.server.flask.application   File "/var/lib/kolla/venv/lib/python3.9/site-packages/dogpile/lock.py", line 185, in __enter__
2023-04-03 22:42:22.148004 2023-04-03 22:42:22.137 38 ERROR keystone.server.flask.application     return self._enter()
2023-04-03 22:42:22.148018 2023-04-03 22:42:22.137 38 ERROR keystone.server.flask.application   File "/var/lib/kolla/venv/lib/python3.9/site-packages/dogpile/lock.py", line 94, in _enter
2023-04-03 22:42:22.148031 2023-04-03 22:42:22.137 38 ERROR keystone.server.flask.application     generated = self._enter_create(value, createdtime)
2023-04-03 22:42:22.148045 2023-04-03 22:42:22.137 38 ERROR keystone.server.flask.application   File "/var/lib/kolla/venv/lib/python3.9/site-packages/dogpile/lock.py", line 178, in _enter_create
2023-04-03 22:42:22.148118 2023-04-03 22:42:22.137 38 ERROR keystone.server.flask.application     return self.creator()
2023-04-03 22:42:22.148134 2023-04-03 22:42:22.137 38 ERROR keystone.server.flask.application   File "/var/lib/kolla/venv/lib/python3.9/site-packages/dogpile/cache/region.py", line 995, in gen_value
2023-04-03 22:42:22.148148 2023-04-03 22:42:22.137 38 ERROR keystone.server.flask.application     created_value = creator(
2023-04-03 22:42:22.148161 2023-04-03 22:42:22.137 38 ERROR keystone.server.flask.application   File "/var/lib/kolla/venv/lib/python3.9/site-packages/keystone/identity/core.py", line 1011, in get_user
2023-04-03 22:42:22.148175 2023-04-03 22:42:22.137 38 ERROR keystone.server.flask.application     ref = driver.get_user(entity_id)
2023-04-03 22:42:22.148189 2023-04-03 22:42:22.137 38 ERROR keystone.server.flask.application   File "/var/lib/kolla/venv/lib/python3.9/site-packages/keystone/identity/backends/sql.py", line 200, in get_user
2023-04-03 22:42:22.148203 2023-04-03 22:42:22.137 38 ERROR keystone.server.flask.application     self._get_user(session, user_id).to_dict())
2023-04-03 22:42:22.148216 2023-04-03 22:42:22.137 38 ERROR keystone.server.flask.application   File "/var/lib/kolla/venv/lib/python3.9/site-packages/keystone/identity/backends/sql.py", line 194, in _get_user
2023-04-03 22:42:22.148230 2023-04-03 22:42:22.137 38 ERROR keystone.server.flask.application     raise exception.UserNotFound(user_id=user_id)
2023-04-03 22:42:22.148244 2023-04-03 22:42:22.137 38 ERROR keystone.server.flask.application keystone.exception.UserNotFound: Could not find user: ironic-inspector.
2023-04-03 22:42:22.148257 2023-04-03 22:42:22.137 38 ERROR keystone.server.flask.application \x1b[00m
2023-04-03 22:42:22.981436 2023-04-03 22:42:22.978 39 ERROR keystone.server.flask.application [None req-82f265db-baf3-43b5-b2a4-f5c2be11826c ec6785048b4c4da0b2826501dcd6781c - - all default -] Could not find project: service.: keystone.exception.ProjectNotFound: Could not find project: service.
2023-04-03 22:42:22.981507 2023-04-03 22:42:22.978 39 ERROR keystone.server.flask.application Traceback (most recent call last):
2023-04-03 22:42:22.981524 2023-04-03 22:42:22.978 39 ERROR keystone.server.flask.application   File "/var/lib/kolla/venv/lib/python3.9/site-packages/flask/app.py", line 1820, in full_dispatch_request
2023-04-03 22:42:22.981535 2023-04-03 22:42:22.978 39 ERROR keystone.server.flask.application     rv = self.dispatch_request()
2023-04-03 22:42:22.981544 2023-04-03 22:42:22.978 39 ERROR keystone.server.flask.application   File "/var/lib/kolla/venv/lib/python3.9/site-packages/flask/app.py", line 1796, in dispatch_request
2023-04-03 22:42:22.981555 2023-04-03 22:42:22.978 39 ERROR keystone.server.flask.application     return self.ensure_sync(self.view_functions[rule.endpoint])(**view_args)
2023-04-03 22:42:22.981564 2023-04-03 22:42:22.978 39 ERROR keystone.server.flask.application   File "/var/lib/kolla/venv/lib/python3.9/site-packages/flask_restful/__init__.py", line 467, in wrapper
2023-04-03 22:42:22.981574 2023-04-03 22:42:22.978 39 ERROR keystone.server.flask.application     resp = resource(*args, **kwargs)
2023-04-03 22:42:22.981584 2023-04-03 22:42:22.978 39 ERROR keystone.server.flask.application   File "/var/lib/kolla/venv/lib/python3.9/site-packages/flask/views.py", line 107, in view
2023-04-03 22:42:22.981594 2023-04-03 22:42:22.978 39 ERROR keystone.server.flask.application     return current_app.ensure_sync(self.dispatch_request)(**kwargs)
2023-04-03 22:42:22.981603 2023-04-03 22:42:22.978 39 ERROR keystone.server.flask.application   File "/var/lib/kolla/venv/lib/python3.9/site-packages/flask_restful/__init__.py", line 582, in dispatch_request
2023-04-03 22:42:22.981613 2023-04-03 22:42:22.978 39 ERROR keystone.server.flask.application     resp = meth(*args, **kwargs)
2023-04-03 22:42:22.981622 2023-04-03 22:42:22.978 39 ERROR keystone.server.flask.application   File "/var/lib/kolla/venv/lib/python3.9/site-packages/keystone/api/projects.py", line 151, in get
2023-04-03 22:42:22.981667 2023-04-03 22:42:22.978 39 ERROR keystone.server.flask.application     return self._get_project(project_id)
2023-04-03 22:42:22.981680 2023-04-03 22:42:22.978 39 ERROR keystone.server.flask.application   File "/var/lib/kolla/venv/lib/python3.9/site-packages/keystone/api/projects.py", line 107, in _get_project
2023-04-03 22:42:22.981690 2023-04-03 22:42:22.978 39 ERROR keystone.server.flask.application     project = PROVIDERS.resource_api.get_project(project_id)
2023-04-03 22:42:22.981700 2023-04-03 22:42:22.978 39 ERROR keystone.server.flask.application   File "/var/lib/kolla/venv/lib/python3.9/site-packages/keystone/common/manager.py", line 115, in wrapped
2023-04-03 22:42:22.981710 2023-04-03 22:42:22.978 39 ERROR keystone.server.flask.application     __ret_val = __f(*args, **kwargs)
2023-04-03 22:42:22.981719 2023-04-03 22:42:22.978 39 ERROR keystone.server.flask.application   File "/var/lib/kolla/venv/lib/python3.9/site-packages/decorator.py", line 232, in fun
2023-04-03 22:42:22.981729 2023-04-03 22:42:22.978 39 ERROR keystone.server.flask.application     return caller(func, *(extras + args), **kw)
2023-04-03 22:42:22.981739 2023-04-03 22:42:22.978 39 ERROR keystone.server.flask.application   File "/var/lib/kolla/venv/lib/python3.9/site-packages/dogpile/cache/region.py", line 1577, in get_or_create_for_user_func
2023-04-03 22:42:22.981749 2023-04-03 22:42:22.978 39 ERROR keystone.server.flask.application     return self.get_or_create(
2023-04-03 22:42:22.981758 2023-04-03 22:42:22.978 39 ERROR keystone.server.flask.application   File "/var/lib/kolla/venv/lib/python3.9/site-packages/dogpile/cache/region.py", line 1042, in get_or_create
2023-04-03 22:42:22.981768 2023-04-03 22:42:22.978 39 ERROR keystone.server.flask.application     with Lock(
2023-04-03 22:42:22.981778 2023-04-03 22:42:22.978 39 ERROR keystone.server.flask.application   File "/var/lib/kolla/venv/lib/python3.9/site-packages/dogpile/lock.py", line 185, in __enter__
2023-04-03 22:42:22.981788 2023-04-03 22:42:22.978 39 ERROR keystone.server.flask.application     return self._enter()
2023-04-03 22:42:22.981797 2023-04-03 22:42:22.978 39 ERROR keystone.server.flask.application   File "/var/lib/kolla/venv/lib/python3.9/site-packages/dogpile/lock.py", line 94, in _enter
2023-04-03 22:42:22.981813 2023-04-03 22:42:22.978 39 ERROR keystone.server.flask.application     generated = self._enter_create(value, createdtime)
2023-04-03 22:42:22.981831 2023-04-03 22:42:22.978 39 ERROR keystone.server.flask.application   File "/var/lib/kolla/venv/lib/python3.9/site-packages/dogpile/lock.py", line 178, in _enter_create
2023-04-03 22:42:22.981857 2023-04-03 22:42:22.978 39 ERROR keystone.server.flask.application     return self.creator()
2023-04-03 22:42:22.981875 2023-04-03 22:42:22.978 39 ERROR keystone.server.flask.application   File "/var/lib/kolla/venv/lib/python3.9/site-packages/dogpile/cache/region.py", line 995, in gen_value
2023-04-03 22:42:22.981885 2023-04-03 22:42:22.978 39 ERROR keystone.server.flask.application     created_value = creator(
2023-04-03 22:42:22.981895 2023-04-03 22:42:22.978 39 ERROR keystone.server.flask.application   File "/var/lib/kolla/venv/lib/python3.9/site-packages/keystone/resource/core.py", line 903, in get_project
2023-04-03 22:42:22.981904 2023-04-03 22:42:22.978 39 ERROR keystone.server.flask.application     return self.driver.get_project(project_id)
2023-04-03 22:42:22.981913 2023-04-03 22:42:22.978 39 ERROR keystone.server.flask.application   File "/var/lib/kolla/venv/lib/python3.9/site-packages/keystone/resource/backends/sql.py", line 49, in get_project
2023-04-03 22:42:22.981923 2023-04-03 22:42:22.978 39 ERROR keystone.server.flask.application     return self._get_project(session, project_id).to_dict()
2023-04-03 22:42:22.981932 2023-04-03 22:42:22.978 39 ERROR keystone.server.flask.application   File "/var/lib/kolla/venv/lib/python3.9/site-packages/keystone/resource/backends/sql.py", line 44, in _get_project
2023-04-03 22:42:22.981942 2023-04-03 22:42:22.978 39 ERROR keystone.server.flask.application     raise exception.ProjectNotFound(project_id=project_id)
2023-04-03 22:42:22.981967 2023-04-03 22:42:22.978 39 ERROR keystone.server.flask.application keystone.exception.ProjectNotFound: Could not find project: service.
2023-04-03 22:42:22.981978 2023-04-03 22:42:22.978 39 ERROR keystone.server.flask.application \x1b[00m
2023-04-03 22:45:09.873264 2023-04-03 22:45:09.869 38 ERROR keystone.server.flask.application [None req-170bb9bb-42ca-4985-b084-9371403e3c72 ec6785048b4c4da0b2826501dcd6781c - - all default -] Could not find project: service.: keystone.exception.ProjectNotFound: Could not find project: service.
2023-04-03 22:45:09.873330 2023-04-03 22:45:09.869 38 ERROR keystone.server.flask.application Traceback (most recent call last):
2023-04-03 22:45:09.873343 2023-04-03 22:45:09.869 38 ERROR keystone.server.flask.application   File "/var/lib/kolla/venv/lib/python3.9/site-packages/flask/app.py", line 1820, in full_dispatch_request
2023-04-03 22:45:09.873354 2023-04-03 22:45:09.869 38 ERROR keystone.server.flask.application     rv = self.dispatch_request()
2023-04-03 22:45:09.873363 2023-04-03 22:45:09.869 38 ERROR keystone.server.flask.application   File "/var/lib/kolla/venv/lib/python3.9/site-packages/flask/app.py", line 1796, in dispatch_request
2023-04-03 22:45:09.873374 2023-04-03 22:45:09.869 38 ERROR keystone.server.flask.application     return self.ensure_sync(self.view_functions[rule.endpoint])(**view_args)
2023-04-03 22:45:09.873383 2023-04-03 22:45:09.869 38 ERROR keystone.server.flask.application   File "/var/lib/kolla/venv/lib/python3.9/site-packages/flask_restful/__init__.py", line 467, in wrapper
2023-04-03 22:45:09.873393 2023-04-03 22:45:09.869 38 ERROR keystone.server.flask.application     resp = resource(*args, **kwargs)
2023-04-03 22:45:09.873403 2023-04-03 22:45:09.869 38 ERROR keystone.server.flask.application   File "/var/lib/kolla/venv/lib/python3.9/site-packages/flask/views.py", line 107, in view
2023-04-03 22:45:09.873413 2023-04-03 22:45:09.869 38 ERROR keystone.server.flask.application     return current_app.ensure_sync(self.dispatch_request)(**kwargs)
2023-04-03 22:45:09.873423 2023-04-03 22:45:09.869 38 ERROR keystone.server.flask.application   File "/var/lib/kolla/venv/lib/python3.9/site-packages/flask_restful/__init__.py", line 582, in dispatch_request
2023-04-03 22:45:09.873432 2023-04-03 22:45:09.869 38 ERROR keystone.server.flask.application     resp = meth(*args, **kwargs)
2023-04-03 22:45:09.873442 2023-04-03 22:45:09.869 38 ERROR keystone.server.flask.application   File "/var/lib/kolla/venv/lib/python3.9/site-packages/keystone/api/projects.py", line 151, in get
2023-04-03 22:45:09.873452 2023-04-03 22:45:09.869 38 ERROR keystone.server.flask.application     return self._get_project(project_id)
2023-04-03 22:45:09.873461 2023-04-03 22:45:09.869 38 ERROR keystone.server.flask.application   File "/var/lib/kolla/venv/lib/python3.9/site-packages/keystone/api/projects.py", line 107, in _get_project
2023-04-03 22:45:09.873471 2023-04-03 22:45:09.869 38 ERROR keystone.server.flask.application     project = PROVIDERS.resource_api.get_project(project_id)
2023-04-03 22:45:09.873512 2023-04-03 22:45:09.869 38 ERROR keystone.server.flask.application   File "/var/lib/kolla/venv/lib/python3.9/site-packages/keystone/common/manager.py", line 115, in wrapped
2023-04-03 22:45:09.873529 2023-04-03 22:45:09.869 38 ERROR keystone.server.flask.application     __ret_val = __f(*args, **kwargs)
2023-04-03 22:45:09.873539 2023-04-03 22:45:09.869 38 ERROR keystone.server.flask.application   File "/var/lib/kolla/venv/lib/python3.9/site-packages/decorator.py", line 232, in fun
2023-04-03 22:45:09.873548 2023-04-03 22:45:09.869 38 ERROR keystone.server.flask.application     return caller(func, *(extras + args), **kw)
2023-04-03 22:45:09.873558 2023-04-03 22:45:09.869 38 ERROR keystone.server.flask.application   File "/var/lib/kolla/venv/lib/python3.9/site-packages/dogpile/cache/region.py", line 1577, in get_or_create_for_user_func
2023-04-03 22:45:09.873568 2023-04-03 22:45:09.869 38 ERROR keystone.server.flask.application     return self.get_or_create(
2023-04-03 22:45:09.873593 2023-04-03 22:45:09.869 38 ERROR keystone.server.flask.application   File "/var/lib/kolla/venv/lib/python3.9/site-packages/dogpile/cache/region.py", line 1042, in get_or_create
2023-04-03 22:45:09.873610 2023-04-03 22:45:09.869 38 ERROR keystone.server.flask.application     with Lock(
2023-04-03 22:45:09.873627 2023-04-03 22:45:09.869 38 ERROR keystone.server.flask.application   File "/var/lib/kolla/venv/lib/python3.9/site-packages/dogpile/lock.py", line 185, in __enter__
2023-04-03 22:45:09.873650 2023-04-03 22:45:09.869 38 ERROR keystone.server.flask.application     return self._enter()
2023-04-03 22:45:09.873668 2023-04-03 22:45:09.869 38 ERROR keystone.server.flask.application   File "/var/lib/kolla/venv/lib/python3.9/site-packages/dogpile/lock.py", line 94, in _enter
2023-04-03 22:45:09.873692 2023-04-03 22:45:09.869 38 ERROR keystone.server.flask.application     generated = self._enter_create(value, createdtime)
2023-04-03 22:45:09.873714 2023-04-03 22:45:09.869 38 ERROR keystone.server.flask.application   File "/var/lib/kolla/venv/lib/python3.9/site-packages/dogpile/lock.py", line 178, in _enter_create
2023-04-03 22:45:09.873732 2023-04-03 22:45:09.869 38 ERROR keystone.server.flask.application     return self.creator()
2023-04-03 22:45:09.873750 2023-04-03 22:45:09.869 38 ERROR keystone.server.flask.application   File "/var/lib/kolla/venv/lib/python3.9/site-packages/dogpile/cache/region.py", line 995, in gen_value
2023-04-03 22:45:09.873764 2023-04-03 22:45:09.869 38 ERROR keystone.server.flask.application     created_value = creator(
2023-04-03 22:45:09.873774 2023-04-03 22:45:09.869 38 ERROR keystone.server.flask.application   File "/var/lib/kolla/venv/lib/python3.9/site-packages/keystone/resource/core.py", line 903, in get_project
2023-04-03 22:45:09.873784 2023-04-03 22:45:09.869 38 ERROR keystone.server.flask.application     return self.driver.get_project(project_id)
2023-04-03 22:45:09.873793 2023-04-03 22:45:09.869 38 ERROR keystone.server.flask.application   File "/var/lib/kolla/venv/lib/python3.9/site-packages/keystone/resource/backends/sql.py", line 49, in get_project
2023-04-03 22:45:09.873802 2023-04-03 22:45:09.869 38 ERROR keystone.server.flask.application     return self._get_project(session, project_id).to_dict()
2023-04-03 22:45:09.873812 2023-04-03 22:45:09.869 38 ERROR keystone.server.flask.application   File "/var/lib/kolla/venv/lib/python3.9/site-packages/keystone/resource/backends/sql.py", line 44, in _get_project
2023-04-03 22:45:09.873821 2023-04-03 22:45:09.869 38 ERROR keystone.server.flask.application     raise exception.ProjectNotFound(project_id=project_id)
2023-04-03 22:45:09.873831 2023-04-03 22:45:09.869 38 ERROR keystone.server.flask.application keystone.exception.ProjectNotFound: Could not find project: service.
2023-04-03 22:45:09.873840 2023-04-03 22:45:09.869 38 ERROR keystone.server.flask.application \x1b[00m
2023-04-03 22:45:24.119298 2023-04-03 22:45:24.113 37 ERROR keystone.server.flask.application [None req-3364994a-813e-40b4-85d5-2888f949eeb9 ec6785048b4c4da0b2826501dcd6781c - - all default -] Could not find role: admin.: keystone.exception.RoleNotFound: Could not find role: admin.
2023-04-03 22:45:24.119383 2023-04-03 22:45:24.113 37 ERROR keystone.server.flask.application Traceback (most recent call last):
2023-04-03 22:45:24.119403 2023-04-03 22:45:24.113 37 ERROR keystone.server.flask.application   File "/var/lib/kolla/venv/lib/python3.9/site-packages/flask/app.py", line 1820, in full_dispatch_request
2023-04-03 22:45:24.119414 2023-04-03 22:45:24.113 37 ERROR keystone.server.flask.application     rv = self.dispatch_request()
2023-04-03 22:45:24.119424 2023-04-03 22:45:24.113 37 ERROR keystone.server.flask.application   File "/var/lib/kolla/venv/lib/python3.9/site-packages/flask/app.py", line 1796, in dispatch_request
2023-04-03 22:45:24.119434 2023-04-03 22:45:24.113 37 ERROR keystone.server.flask.application     return self.ensure_sync(self.view_functions[rule.endpoint])(**view_args)
2023-04-03 22:45:24.119444 2023-04-03 22:45:24.113 37 ERROR keystone.server.flask.application   File "/var/lib/kolla/venv/lib/python3.9/site-packages/flask_restful/__init__.py", line 467, in wrapper
2023-04-03 22:45:24.119469 2023-04-03 22:45:24.113 37 ERROR keystone.server.flask.application     resp = resource(*args, **kwargs)
2023-04-03 22:45:24.119480 2023-04-03 22:45:24.113 37 ERROR keystone.server.flask.application   File "/var/lib/kolla/venv/lib/python3.9/site-packages/flask/views.py", line 107, in view
2023-04-03 22:45:24.119527 2023-04-03 22:45:24.113 37 ERROR keystone.server.flask.application     return current_app.ensure_sync(self.dispatch_request)(**kwargs)
2023-04-03 22:45:24.119614 2023-04-03 22:45:24.113 37 ERROR keystone.server.flask.application   File "/var/lib/kolla/venv/lib/python3.9/site-packages/flask_restful/__init__.py", line 582, in dispatch_request
2023-04-03 22:45:24.119627 2023-04-03 22:45:24.113 37 ERROR keystone.server.flask.application     resp = meth(*args, **kwargs)
2023-04-03 22:45:24.119637 2023-04-03 22:45:24.113 37 ERROR keystone.server.flask.application   File "/var/lib/kolla/venv/lib/python3.9/site-packages/keystone/api/roles.py", line 50, in get
2023-04-03 22:45:24.119647 2023-04-03 22:45:24.113 37 ERROR keystone.server.flask.application     return self._get_role(role_id)
2023-04-03 22:45:24.119657 2023-04-03 22:45:24.113 37 ERROR keystone.server.flask.application   File "/var/lib/kolla/venv/lib/python3.9/site-packages/keystone/api/roles.py", line 70, in _get_role
2023-04-03 22:45:24.119666 2023-04-03 22:45:24.113 37 ERROR keystone.server.flask.application     ENFORCER.enforce_call(action='identity:get_role')
2023-04-03 22:45:24.119676 2023-04-03 22:45:24.113 37 ERROR keystone.server.flask.application   File "/var/lib/kolla/venv/lib/python3.9/site-packages/keystone/common/rbac_enforcer/enforcer.py", line 402, in enforce_call
2023-04-03 22:45:24.119686 2023-04-03 22:45:24.113 37 ERROR keystone.server.flask.application     policy_dict.update(cls._extract_member_target_data(
2023-04-03 22:45:24.119696 2023-04-03 22:45:24.113 37 ERROR keystone.server.flask.application   File "/var/lib/kolla/venv/lib/python3.9/site-packages/keystone/common/rbac_enforcer/enforcer.py", line 234, in _extract_member_target_data
2023-04-03 22:45:24.119706 2023-04-03 22:45:24.113 37 ERROR keystone.server.flask.application     member_name: func(flask.request.view_args[key])
2023-04-03 22:45:24.119716 2023-04-03 22:45:24.113 37 ERROR keystone.server.flask.application   File "/var/lib/kolla/venv/lib/python3.9/site-packages/keystone/common/manager.py", line 115, in wrapped
2023-04-03 22:45:24.119726 2023-04-03 22:45:24.113 37 ERROR keystone.server.flask.application     __ret_val = __f(*args, **kwargs)
2023-04-03 22:45:24.119735 2023-04-03 22:45:24.113 37 ERROR keystone.server.flask.application   File "/var/lib/kolla/venv/lib/python3.9/site-packages/decorator.py", line 232, in fun
2023-04-03 22:45:24.119745 2023-04-03 22:45:24.113 37 ERROR keystone.server.flask.application     return caller(func, *(extras + args), **kw)
2023-04-03 22:45:24.119755 2023-04-03 22:45:24.113 37 ERROR keystone.server.flask.application   File "/var/lib/kolla/venv/lib/python3.9/site-packages/dogpile/cache/region.py", line 1577, in get_or_create_for_user_func
2023-04-03 22:45:24.119765 2023-04-03 22:45:24.113 37 ERROR keystone.server.flask.application     return self.get_or_create(
2023-04-03 22:45:24.119774 2023-04-03 22:45:24.113 37 ERROR keystone.server.flask.application   File "/var/lib/kolla/venv/lib/python3.9/site-packages/dogpile/cache/region.py", line 1042, in get_or_create
2023-04-03 22:45:24.119793 2023-04-03 22:45:24.113 37 ERROR keystone.server.flask.application     with Lock(
2023-04-03 22:45:24.119807 2023-04-03 22:45:24.113 37 ERROR keystone.server.flask.application   File "/var/lib/kolla/venv/lib/python3.9/site-packages/dogpile/lock.py", line 185, in __enter__
2023-04-03 22:45:24.119817 2023-04-03 22:45:24.113 37 ERROR keystone.server.flask.application     return self._enter()
2023-04-03 22:45:24.119827 2023-04-03 22:45:24.113 37 ERROR keystone.server.flask.application   File "/var/lib/kolla/venv/lib/python3.9/site-packages/dogpile/lock.py", line 94, in _enter
2023-04-03 22:45:24.119860 2023-04-03 22:45:24.113 37 ERROR keystone.server.flask.application     generated = self._enter_create(value, createdtime)
2023-04-03 22:45:24.119871 2023-04-03 22:45:24.113 37 ERROR keystone.server.flask.application   File "/var/lib/kolla/venv/lib/python3.9/site-packages/dogpile/lock.py", line 178, in _enter_create
2023-04-03 22:45:24.119881 2023-04-03 22:45:24.113 37 ERROR keystone.server.flask.application     return self.creator()
2023-04-03 22:45:24.119890 2023-04-03 22:45:24.113 37 ERROR keystone.server.flask.application   File "/var/lib/kolla/venv/lib/python3.9/site-packages/dogpile/cache/region.py", line 995, in gen_value
2023-04-03 22:45:24.119900 2023-04-03 22:45:24.113 37 ERROR keystone.server.flask.application     created_value = creator(
2023-04-03 22:45:24.119910 2023-04-03 22:45:24.113 37 ERROR keystone.server.flask.application   File "/var/lib/kolla/venv/lib/python3.9/site-packages/keystone/assignment/core.py", line 1276, in get_role
2023-04-03 22:45:24.119920 2023-04-03 22:45:24.113 37 ERROR keystone.server.flask.application     return self.driver.get_role(role_id)
2023-04-03 22:45:24.119929 2023-04-03 22:45:24.113 37 ERROR keystone.server.flask.application   File "/var/lib/kolla/venv/lib/python3.9/site-packages/keystone/assignment/role_backends/sql.py", line 70, in get_role
2023-04-03 22:45:24.119939 2023-04-03 22:45:24.113 37 ERROR keystone.server.flask.application     return self._get_role(session, role_id).to_dict()
2023-04-03 22:45:24.119949 2023-04-03 22:45:24.113 37 ERROR keystone.server.flask.application   File "/var/lib/kolla/venv/lib/python3.9/site-packages/keystone/assignment/role_backends/sql.py", line 65, in _get_role
2023-04-03 22:45:24.119959 2023-04-03 22:45:24.113 37 ERROR keystone.server.flask.application     raise exception.RoleNotFound(role_id=role_id)
2023-04-03 22:45:24.119968 2023-04-03 22:45:24.113 37 ERROR keystone.server.flask.application keystone.exception.RoleNotFound: Could not find role: admin.
2023-04-03 22:45:24.119978 2023-04-03 22:45:24.113 37 ERROR keystone.server.flask.application \x1b[00m
2023-04-03 22:45:25.258257 2023-04-03 22:45:25.252 37 ERROR keystone.server.flask.application [None req-beff0365-9ea1-41d8-8adc-8235543c3268 ec6785048b4c4da0b2826501dcd6781c - - all default -] Could not find user: neutron.: keystone.exception.UserNotFound: Could not find user: neutron.
2023-04-03 22:45:25.258299 2023-04-03 22:45:25.252 37 ERROR keystone.server.flask.application Traceback (most recent call last):
2023-04-03 22:45:25.258312 2023-04-03 22:45:25.252 37 ERROR keystone.server.flask.application   File "/var/lib/kolla/venv/lib/python3.9/site-packages/flask/app.py", line 1820, in full_dispatch_request
2023-04-03 22:45:25.258322 2023-04-03 22:45:25.252 37 ERROR keystone.server.flask.application     rv = self.dispatch_request()
2023-04-03 22:45:25.258332 2023-04-03 22:45:25.252 37 ERROR keystone.server.flask.application   File "/var/lib/kolla/venv/lib/python3.9/site-packages/flask/app.py", line 1796, in dispatch_request
2023-04-03 22:45:25.258342 2023-04-03 22:45:25.252 37 ERROR keystone.server.flask.application     return self.ensure_sync(self.view_functions[rule.endpoint])(**view_args)
2023-04-03 22:45:25.258351 2023-04-03 22:45:25.252 37 ERROR keystone.server.flask.application   File "/var/lib/kolla/venv/lib/python3.9/site-packages/flask_restful/__init__.py", line 467, in wrapper
2023-04-03 22:45:25.258361 2023-04-03 22:45:25.252 37 ERROR keystone.server.flask.application     resp = resource(*args, **kwargs)
2023-04-03 22:45:25.258371 2023-04-03 22:45:25.252 37 ERROR keystone.server.flask.application   File "/var/lib/kolla/venv/lib/python3.9/site-packages/flask/views.py", line 107, in view
2023-04-03 22:45:25.258381 2023-04-03 22:45:25.252 37 ERROR keystone.server.flask.application     return current_app.ensure_sync(self.dispatch_request)(**kwargs)
2023-04-03 22:45:25.258391 2023-04-03 22:45:25.252 37 ERROR keystone.server.flask.application   File "/var/lib/kolla/venv/lib/python3.9/site-packages/flask_restful/__init__.py", line 582, in dispatch_request
2023-04-03 22:45:25.258430 2023-04-03 22:45:25.252 37 ERROR keystone.server.flask.application     resp = meth(*args, **kwargs)
2023-04-03 22:45:25.258443 2023-04-03 22:45:25.252 37 ERROR keystone.server.flask.application   File "/var/lib/kolla/venv/lib/python3.9/site-packages/keystone/api/users.py", line 182, in get
2023-04-03 22:45:25.258456 2023-04-03 22:45:25.252 37 ERROR keystone.server.flask.application     return self._get_user(user_id)
2023-04-03 22:45:25.258466 2023-04-03 22:45:25.252 37 ERROR keystone.server.flask.application   File "/var/lib/kolla/venv/lib/python3.9/site-packages/keystone/api/users.py", line 194, in _get_user
2023-04-03 22:45:25.258480 2023-04-03 22:45:25.252 37 ERROR keystone.server.flask.application     ref = PROVIDERS.identity_api.get_user(user_id)
2023-04-03 22:45:25.258537 2023-04-03 22:45:25.252 37 ERROR keystone.server.flask.application   File "/var/lib/kolla/venv/lib/python3.9/site-packages/keystone/common/manager.py", line 115, in wrapped
2023-04-03 22:45:25.258557 2023-04-03 22:45:25.252 37 ERROR keystone.server.flask.application     __ret_val = __f(*args, **kwargs)
2023-04-03 22:45:25.258575 2023-04-03 22:45:25.252 37 ERROR keystone.server.flask.application   File "/var/lib/kolla/venv/lib/python3.9/site-packages/keystone/identity/core.py", line 414, in wrapper
2023-04-03 22:45:25.258588 2023-04-03 22:45:25.252 37 ERROR keystone.server.flask.application     return f(self, *args, **kwargs)
2023-04-03 22:45:25.258598 2023-04-03 22:45:25.252 37 ERROR keystone.server.flask.application   File "/var/lib/kolla/venv/lib/python3.9/site-packages/keystone/identity/core.py", line 424, in wrapper
2023-04-03 22:45:25.258608 2023-04-03 22:45:25.252 37 ERROR keystone.server.flask.application     return f(self, *args, **kwargs)
2023-04-03 22:45:25.258618 2023-04-03 22:45:25.252 37 ERROR keystone.server.flask.application   File "/var/lib/kolla/venv/lib/python3.9/site-packages/decorator.py", line 232, in fun
2023-04-03 22:45:25.258627 2023-04-03 22:45:25.252 37 ERROR keystone.server.flask.application     return caller(func, *(extras + args), **kw)
2023-04-03 22:45:25.258637 2023-04-03 22:45:25.252 37 ERROR keystone.server.flask.application   File "/var/lib/kolla/venv/lib/python3.9/site-packages/dogpile/cache/region.py", line 1577, in get_or_create_for_user_func
2023-04-03 22:45:25.258647 2023-04-03 22:45:25.252 37 ERROR keystone.server.flask.application     return self.get_or_create(
2023-04-03 22:45:25.258661 2023-04-03 22:45:25.252 37 ERROR keystone.server.flask.application   File "/var/lib/kolla/venv/lib/python3.9/site-packages/dogpile/cache/region.py", line 1042, in get_or_create
2023-04-03 22:45:25.258674 2023-04-03 22:45:25.252 37 ERROR keystone.server.flask.application     with Lock(
2023-04-03 22:45:25.258683 2023-04-03 22:45:25.252 37 ERROR keystone.server.flask.application   File "/var/lib/kolla/venv/lib/python3.9/site-packages/dogpile/lock.py", line 185, in __enter__
2023-04-03 22:45:25.258693 2023-04-03 22:45:25.252 37 ERROR keystone.server.flask.application     return self._enter()
2023-04-03 22:45:25.258702 2023-04-03 22:45:25.252 37 ERROR keystone.server.flask.application   File "/var/lib/kolla/venv/lib/python3.9/site-packages/dogpile/lock.py", line 94, in _enter
2023-04-03 22:45:25.258712 2023-04-03 22:45:25.252 37 ERROR keystone.server.flask.application     generated = self._enter_create(value, createdtime)
2023-04-03 22:45:25.258722 2023-04-03 22:45:25.252 37 ERROR keystone.server.flask.application   File "/var/lib/kolla/venv/lib/python3.9/site-packages/dogpile/lock.py", line 178, in _enter_create
2023-04-03 22:45:25.258731 2023-04-03 22:45:25.252 37 ERROR keystone.server.flask.application     return self.creator()
2023-04-03 22:45:25.258741 2023-04-03 22:45:25.252 37 ERROR keystone.server.flask.application   File "/var/lib/kolla/venv/lib/python3.9/site-packages/dogpile/cache/region.py", line 995, in gen_value
2023-04-03 22:45:25.258751 2023-04-03 22:45:25.252 37 ERROR keystone.server.flask.application     created_value = creator(
2023-04-03 22:45:25.258785 2023-04-03 22:45:25.252 37 ERROR keystone.server.flask.application   File "/var/lib/kolla/venv/lib/python3.9/site-packages/keystone/identity/core.py", line 1011, in get_user
2023-04-03 22:45:25.258800 2023-04-03 22:45:25.252 37 ERROR keystone.server.flask.application     ref = driver.get_user(entity_id)
2023-04-03 22:45:25.258817 2023-04-03 22:45:25.252 37 ERROR keystone.server.flask.application   File "/var/lib/kolla/venv/lib/python3.9/site-packages/keystone/identity/backends/sql.py", line 200, in get_user
2023-04-03 22:45:25.258835 2023-04-03 22:45:25.252 37 ERROR keystone.server.flask.application     self._get_user(session, user_id).to_dict())
2023-04-03 22:45:25.258855 2023-04-03 22:45:25.252 37 ERROR keystone.server.flask.application   File "/var/lib/kolla/venv/lib/python3.9/site-packages/keystone/identity/backends/sql.py", line 194, in _get_user
2023-04-03 22:45:25.258877 2023-04-03 22:45:25.252 37 ERROR keystone.server.flask.application     raise exception.UserNotFound(user_id=user_id)
2023-04-03 22:45:25.258898 2023-04-03 22:45:25.252 37 ERROR keystone.server.flask.application keystone.exception.UserNotFound: Could not find user: neutron.
2023-04-03 22:45:25.258918 2023-04-03 22:45:25.252 37 ERROR keystone.server.flask.application \x1b[00m
2023-04-03 22:45:26.047069 2023-04-03 22:45:26.042 39 ERROR keystone.server.flask.application [None req-b408d28d-499f-4b4e-99b9-a56428752107 ec6785048b4c4da0b2826501dcd6781c - - all default -] Could not find project: service.: keystone.exception.ProjectNotFound: Could not find project: service.
2023-04-03 22:45:26.047133 2023-04-03 22:45:26.042 39 ERROR keystone.server.flask.application Traceback (most recent call last):
2023-04-03 22:45:26.047146 2023-04-03 22:45:26.042 39 ERROR keystone.server.flask.application   File "/var/lib/kolla/venv/lib/python3.9/site-packages/flask/app.py", line 1820, in full_dispatch_request
2023-04-03 22:45:26.047156 2023-04-03 22:45:26.042 39 ERROR keystone.server.flask.application     rv = self.dispatch_request()
2023-04-03 22:45:26.047166 2023-04-03 22:45:26.042 39 ERROR keystone.server.flask.application   File "/var/lib/kolla/venv/lib/python3.9/site-packages/flask/app.py", line 1796, in dispatch_request
2023-04-03 22:45:26.047176 2023-04-03 22:45:26.042 39 ERROR keystone.server.flask.application     return self.ensure_sync(self.view_functions[rule.endpoint])(**view_args)
2023-04-03 22:45:26.047186 2023-04-03 22:45:26.042 39 ERROR keystone.server.flask.application   File "/var/lib/kolla/venv/lib/python3.9/site-packages/flask_restful/__init__.py", line 467, in wrapper
2023-04-03 22:45:26.047196 2023-04-03 22:45:26.042 39 ERROR keystone.server.flask.application     resp = resource(*args, **kwargs)
2023-04-03 22:45:26.047212 2023-04-03 22:45:26.042 39 ERROR keystone.server.flask.application   File "/var/lib/kolla/venv/lib/python3.9/site-packages/flask/views.py", line 107, in view
2023-04-03 22:45:26.047225 2023-04-03 22:45:26.042 39 ERROR keystone.server.flask.application     return current_app.ensure_sync(self.dispatch_request)(**kwargs)
2023-04-03 22:45:26.047235 2023-04-03 22:45:26.042 39 ERROR keystone.server.flask.application   File "/var/lib/kolla/venv/lib/python3.9/site-packages/flask_restful/__init__.py", line 582, in dispatch_request
2023-04-03 22:45:26.047245 2023-04-03 22:45:26.042 39 ERROR keystone.server.flask.application     resp = meth(*args, **kwargs)
2023-04-03 22:45:26.047255 2023-04-03 22:45:26.042 39 ERROR keystone.server.flask.application   File "/var/lib/kolla/venv/lib/python3.9/site-packages/keystone/api/projects.py", line 151, in get
2023-04-03 22:45:26.047278 2023-04-03 22:45:26.042 39 ERROR keystone.server.flask.application     return self._get_project(project_id)
2023-04-03 22:45:26.047293 2023-04-03 22:45:26.042 39 ERROR keystone.server.flask.application   File "/var/lib/kolla/venv/lib/python3.9/site-packages/keystone/api/projects.py", line 107, in _get_project
2023-04-03 22:45:26.047303 2023-04-03 22:45:26.042 39 ERROR keystone.server.flask.application     project = PROVIDERS.resource_api.get_project(project_id)
2023-04-03 22:45:26.047337 2023-04-03 22:45:26.042 39 ERROR keystone.server.flask.application   File "/var/lib/kolla/venv/lib/python3.9/site-packages/keystone/common/manager.py", line 115, in wrapped
2023-04-03 22:45:26.047350 2023-04-03 22:45:26.042 39 ERROR keystone.server.flask.application     __ret_val = __f(*args, **kwargs)
2023-04-03 22:45:26.047360 2023-04-03 22:45:26.042 39 ERROR keystone.server.flask.application   File "/var/lib/kolla/venv/lib/python3.9/site-packages/decorator.py", line 232, in fun
2023-04-03 22:45:26.047370 2023-04-03 22:45:26.042 39 ERROR keystone.server.flask.application     return caller(func, *(extras + args), **kw)
2023-04-03 22:45:26.047385 2023-04-03 22:45:26.042 39 ERROR keystone.server.flask.application   File "/var/lib/kolla/venv/lib/python3.9/site-packages/dogpile/cache/region.py", line 1577, in get_or_create_for_user_func
2023-04-03 22:45:26.047397 2023-04-03 22:45:26.042 39 ERROR keystone.server.flask.application     return self.get_or_create(
2023-04-03 22:45:26.047407 2023-04-03 22:45:26.042 39 ERROR keystone.server.flask.application   File "/var/lib/kolla/venv/lib/python3.9/site-packages/dogpile/cache/region.py", line 1042, in get_or_create
2023-04-03 22:45:26.047417 2023-04-03 22:45:26.042 39 ERROR keystone.server.flask.application     with Lock(
2023-04-03 22:45:26.047427 2023-04-03 22:45:26.042 39 ERROR keystone.server.flask.application   File "/var/lib/kolla/venv/lib/python3.9/site-packages/dogpile/lock.py", line 185, in __enter__
2023-04-03 22:45:26.047437 2023-04-03 22:45:26.042 39 ERROR keystone.server.flask.application     return self._enter()
2023-04-03 22:45:26.047446 2023-04-03 22:45:26.042 39 ERROR keystone.server.flask.application   File "/var/lib/kolla/venv/lib/python3.9/site-packages/dogpile/lock.py", line 94, in _enter
2023-04-03 22:45:26.047461 2023-04-03 22:45:26.042 39 ERROR keystone.server.flask.application     generated = self._enter_create(value, createdtime)
2023-04-03 22:45:26.047470 2023-04-03 22:45:26.042 39 ERROR keystone.server.flask.application   File "/var/lib/kolla/venv/lib/python3.9/site-packages/dogpile/lock.py", line 178, in _enter_create
2023-04-03 22:45:26.047513 2023-04-03 22:45:26.042 39 ERROR keystone.server.flask.application     return self.creator()
2023-04-03 22:45:26.047543 2023-04-03 22:45:26.042 39 ERROR keystone.server.flask.application   File "/var/lib/kolla/venv/lib/python3.9/site-packages/dogpile/cache/region.py", line 995, in gen_value
2023-04-03 22:45:26.047563 2023-04-03 22:45:26.042 39 ERROR keystone.server.flask.application     created_value = creator(
2023-04-03 22:45:26.047580 2023-04-03 22:45:26.042 39 ERROR keystone.server.flask.application   File "/var/lib/kolla/venv/lib/python3.9/site-packages/keystone/resource/core.py", line 903, in get_project
2023-04-03 22:45:26.047591 2023-04-03 22:45:26.042 39 ERROR keystone.server.flask.application     return self.driver.get_project(project_id)
2023-04-03 22:45:26.047600 2023-04-03 22:45:26.042 39 ERROR keystone.server.flask.application   File "/var/lib/kolla/venv/lib/python3.9/site-packages/keystone/resource/backends/sql.py", line 49, in get_project
2023-04-03 22:45:26.047610 2023-04-03 22:45:26.042 39 ERROR keystone.server.flask.application     return self._get_project(session, project_id).to_dict()
2023-04-03 22:45:26.047620 2023-04-03 22:45:26.042 39 ERROR keystone.server.flask.application   File "/var/lib/kolla/venv/lib/python3.9/site-packages/keystone/resource/backends/sql.py", line 44, in _get_project
2023-04-03 22:45:26.047629 2023-04-03 22:45:26.042 39 ERROR keystone.server.flask.application     raise exception.ProjectNotFound(project_id=project_id)
2023-04-03 22:45:26.047639 2023-04-03 22:45:26.042 39 ERROR keystone.server.flask.application keystone.exception.ProjectNotFound: Could not find project: service.
2023-04-03 22:45:26.047648 2023-04-03 22:45:26.042 39 ERROR keystone.server.flask.application \x1b[00m
