2023-04-01 08:35:27.336 24 INFO alembic.runtime.migration [-] Context impl MySQLImpl.
2023-04-01 08:35:27.338 24 INFO alembic.runtime.migration [-] Will assume non-transactional DDL.
2023-04-01 08:35:27.377 24 INFO alembic.runtime.migration [-] Context impl MySQLImpl.
2023-04-01 08:35:27.378 24 INFO alembic.runtime.migration [-] Will assume non-transactional DDL.
2023-04-01 08:35:27.427 24 INFO alembic.runtime.migration [-] Running upgrade  -> 27e647c0fad4, Initial version.
2023-04-01 08:35:28.858 24 INFO alembic.runtime.migration [-] Running upgrade 27e647c0fad4 -> e25ffa003242, Initial no-op Yoga contract migration.
2023-04-01 08:35:28.869 24 INFO alembic.runtime.migration [-] Running upgrade 27e647c0fad4 -> 29e87d24a316, Initial no-op Yoga expand migration.
2023-04-01 08:35:37.558 7 INFO keystone.common.fernet_utils [-] Created a new temporary key: /etc/keystone/fernet-keys/0.tmp
2023-04-01 08:35:37.562 7 INFO keystone.common.fernet_utils [-] Become a valid new key: /etc/keystone/fernet-keys/0
2023-04-01 08:35:37.563 7 INFO keystone.common.fernet_utils [-] Starting key rotation with 1 key files: ['/etc/keystone/fernet-keys/0']
2023-04-01 08:35:37.563 7 INFO keystone.common.fernet_utils [-] Created a new temporary key: /etc/keystone/fernet-keys/0.tmp
2023-04-01 08:35:37.564 7 INFO keystone.common.fernet_utils [-] Current primary key is: 0
2023-04-01 08:35:37.565 7 INFO keystone.common.fernet_utils [-] Next primary key will be: 1
2023-04-01 08:35:37.565 7 INFO keystone.common.fernet_utils [-] Promoted key 0 to be the primary: 1
2023-04-01 08:35:37.566 7 INFO keystone.common.fernet_utils [-] Become a valid new key: /etc/keystone/fernet-keys/0
2023-04-01 08:35:54.947 149 INFO keystone.cmd.bootstrap [None req-db8d0614-65a0-43e9-b303-987574e3f917 - - - - - -] Created domain default
2023-04-01 08:35:55.017 149 INFO keystone.cmd.bootstrap [None req-db8d0614-65a0-43e9-b303-987574e3f917 - - - - - -] Created project admin
2023-04-01 08:35:55.629 149 INFO keystone.cmd.bootstrap [None req-db8d0614-65a0-43e9-b303-987574e3f917 - - - - - -] Created user admin
2023-04-01 08:35:55.654 149 INFO keystone.cmd.bootstrap [None req-db8d0614-65a0-43e9-b303-987574e3f917 - - - - - -] Created role reader
2023-04-01 08:35:55.676 149 INFO keystone.cmd.bootstrap [None req-db8d0614-65a0-43e9-b303-987574e3f917 - - - - - -] Created role member
2023-04-01 08:35:55.720 149 INFO keystone.cmd.bootstrap [None req-db8d0614-65a0-43e9-b303-987574e3f917 - - - - - -] Created implied role where 15bd3673c0ec494c903f468ccb73f2a9 implies 45a52797be2e450ba6704bafc45b7d10
2023-04-01 08:35:55.733 149 INFO keystone.cmd.bootstrap [None req-db8d0614-65a0-43e9-b303-987574e3f917 - - - - - -] Created role admin
2023-04-01 08:35:55.755 149 INFO keystone.cmd.bootstrap [None req-db8d0614-65a0-43e9-b303-987574e3f917 - - - - - -] Created implied role where 1c61ea7166694bc380e6c5ddd42ca658 implies 15bd3673c0ec494c903f468ccb73f2a9
2023-04-01 08:35:55.770 149 INFO keystone.cmd.bootstrap [None req-db8d0614-65a0-43e9-b303-987574e3f917 - - - - - -] Granted role admin on project admin to user admin.
2023-04-01 08:35:55.778 149 INFO keystone.cmd.bootstrap [None req-db8d0614-65a0-43e9-b303-987574e3f917 - - - - - -] Granted role admin on the system to user admin.
2023-04-01 08:35:55.794 149 WARNING py.warnings [None req-db8d0614-65a0-43e9-b303-987574e3f917 - - - - - -] /var/lib/kolla/venv/lib/python3.9/site-packages/pycadf/identifier.py:71: UserWarning: Invalid uuid: RegionOne. To ensure interoperability, identifiers should be a valid uuid.
  warnings.warn(('Invalid uuid: %s. To ensure interoperability, '

2023-04-01 08:35:55.800 149 INFO keystone.cmd.bootstrap [None req-db8d0614-65a0-43e9-b303-987574e3f917 - - - - - -] Created region RegionOne
2023-04-01 08:35:55.845 149 INFO keystone.cmd.bootstrap [None req-db8d0614-65a0-43e9-b303-987574e3f917 - - - - - -] Created public endpoint http://169.16.1.151:5000
2023-04-01 08:35:55.862 149 INFO keystone.cmd.bootstrap [None req-db8d0614-65a0-43e9-b303-987574e3f917 - - - - - -] Created internal endpoint http://169.16.1.151:5000
2023-04-01 08:36:20.621 28 WARNING keystone.common.rbac_enforcer.enforcer [None req-8a1030c5-ce5e-46ef-9188-adac11e89976 9e470207b35a4ed1b323ab95faad5f45 - - all default -] Deprecated policy rules found. Use oslopolicy-policy-generator and oslopolicy-policy-upgrade to detect and resolve deprecated policies in your configuration.
2023-04-01 08:36:21.413 27 WARNING keystone.common.rbac_enforcer.enforcer [None req-dab6ef9e-adf5-42cc-8267-4fd3c573dfe0 9e470207b35a4ed1b323ab95faad5f45 - - all default -] Deprecated policy rules found. Use oslopolicy-policy-generator and oslopolicy-policy-upgrade to detect and resolve deprecated policies in your configuration.
2023-04-01 08:36:28.894 26 WARNING keystone.common.rbac_enforcer.enforcer [None req-b05cc9ec-a759-4d67-bd45-5681bc9709af 9e470207b35a4ed1b323ab95faad5f45 - - all default -] Deprecated policy rules found. Use oslopolicy-policy-generator and oslopolicy-policy-upgrade to detect and resolve deprecated policies in your configuration.
2023-04-01 08:37:46.638 28 ERROR keystone.server.flask.application [None req-6a3a43ab-751d-4b2c-b68b-fc43d1a04230 9e470207b35a4ed1b323ab95faad5f45 - - all default -] Could not find project: service.: keystone.exception.ProjectNotFound: Could not find project: service.
2023-04-01 08:37:46.638 28 ERROR keystone.server.flask.application Traceback (most recent call last):
2023-04-01 08:37:46.638 28 ERROR keystone.server.flask.application   File "/var/lib/kolla/venv/lib/python3.9/site-packages/flask/app.py", line 1820, in full_dispatch_request
2023-04-01 08:37:46.638 28 ERROR keystone.server.flask.application     rv = self.dispatch_request()
2023-04-01 08:37:46.638 28 ERROR keystone.server.flask.application   File "/var/lib/kolla/venv/lib/python3.9/site-packages/flask/app.py", line 1796, in dispatch_request
2023-04-01 08:37:46.638 28 ERROR keystone.server.flask.application     return self.ensure_sync(self.view_functions[rule.endpoint])(**view_args)
2023-04-01 08:37:46.638 28 ERROR keystone.server.flask.application   File "/var/lib/kolla/venv/lib/python3.9/site-packages/flask_restful/__init__.py", line 467, in wrapper
2023-04-01 08:37:46.638 28 ERROR keystone.server.flask.application     resp = resource(*args, **kwargs)
2023-04-01 08:37:46.638 28 ERROR keystone.server.flask.application   File "/var/lib/kolla/venv/lib/python3.9/site-packages/flask/views.py", line 107, in view
2023-04-01 08:37:46.638 28 ERROR keystone.server.flask.application     return current_app.ensure_sync(self.dispatch_request)(**kwargs)
2023-04-01 08:37:46.638 28 ERROR keystone.server.flask.application   File "/var/lib/kolla/venv/lib/python3.9/site-packages/flask_restful/__init__.py", line 582, in dispatch_request
2023-04-01 08:37:46.638 28 ERROR keystone.server.flask.application     resp = meth(*args, **kwargs)
2023-04-01 08:37:46.638 28 ERROR keystone.server.flask.application   File "/var/lib/kolla/venv/lib/python3.9/site-packages/keystone/api/projects.py", line 151, in get
2023-04-01 08:37:46.638 28 ERROR keystone.server.flask.application     return self._get_project(project_id)
2023-04-01 08:37:46.638 28 ERROR keystone.server.flask.application   File "/var/lib/kolla/venv/lib/python3.9/site-packages/keystone/api/projects.py", line 107, in _get_project
2023-04-01 08:37:46.638 28 ERROR keystone.server.flask.application     project = PROVIDERS.resource_api.get_project(project_id)
2023-04-01 08:37:46.638 28 ERROR keystone.server.flask.application   File "/var/lib/kolla/venv/lib/python3.9/site-packages/keystone/common/manager.py", line 115, in wrapped
2023-04-01 08:37:46.638 28 ERROR keystone.server.flask.application     __ret_val = __f(*args, **kwargs)
2023-04-01 08:37:46.638 28 ERROR keystone.server.flask.application   File "/var/lib/kolla/venv/lib/python3.9/site-packages/decorator.py", line 232, in fun
2023-04-01 08:37:46.638 28 ERROR keystone.server.flask.application     return caller(func, *(extras + args), **kw)
2023-04-01 08:37:46.638 28 ERROR keystone.server.flask.application   File "/var/lib/kolla/venv/lib/python3.9/site-packages/dogpile/cache/region.py", line 1577, in get_or_create_for_user_func
2023-04-01 08:37:46.638 28 ERROR keystone.server.flask.application     return self.get_or_create(
2023-04-01 08:37:46.638 28 ERROR keystone.server.flask.application   File "/var/lib/kolla/venv/lib/python3.9/site-packages/dogpile/cache/region.py", line 1042, in get_or_create
2023-04-01 08:37:46.638 28 ERROR keystone.server.flask.application     with Lock(
2023-04-01 08:37:46.638 28 ERROR keystone.server.flask.application   File "/var/lib/kolla/venv/lib/python3.9/site-packages/dogpile/lock.py", line 185, in __enter__
2023-04-01 08:37:46.638 28 ERROR keystone.server.flask.application     return self._enter()
2023-04-01 08:37:46.638 28 ERROR keystone.server.flask.application   File "/var/lib/kolla/venv/lib/python3.9/site-packages/dogpile/lock.py", line 94, in _enter
2023-04-01 08:37:46.638 28 ERROR keystone.server.flask.application     generated = self._enter_create(value, createdtime)
2023-04-01 08:37:46.638 28 ERROR keystone.server.flask.application   File "/var/lib/kolla/venv/lib/python3.9/site-packages/dogpile/lock.py", line 178, in _enter_create
2023-04-01 08:37:46.638 28 ERROR keystone.server.flask.application     return self.creator()
2023-04-01 08:37:46.638 28 ERROR keystone.server.flask.application   File "/var/lib/kolla/venv/lib/python3.9/site-packages/dogpile/cache/region.py", line 995, in gen_value
2023-04-01 08:37:46.638 28 ERROR keystone.server.flask.application     created_value = creator(
2023-04-01 08:37:46.638 28 ERROR keystone.server.flask.application   File "/var/lib/kolla/venv/lib/python3.9/site-packages/keystone/resource/core.py", line 903, in get_project
2023-04-01 08:37:46.638 28 ERROR keystone.server.flask.application     return self.driver.get_project(project_id)
2023-04-01 08:37:46.638 28 ERROR keystone.server.flask.application   File "/var/lib/kolla/venv/lib/python3.9/site-packages/keystone/resource/backends/sql.py", line 49, in get_project
2023-04-01 08:37:46.638 28 ERROR keystone.server.flask.application     return self._get_project(session, project_id).to_dict()
2023-04-01 08:37:46.638 28 ERROR keystone.server.flask.application   File "/var/lib/kolla/venv/lib/python3.9/site-packages/keystone/resource/backends/sql.py", line 44, in _get_project
2023-04-01 08:37:46.638 28 ERROR keystone.server.flask.application     raise exception.ProjectNotFound(project_id=project_id)
2023-04-01 08:37:46.638 28 ERROR keystone.server.flask.application keystone.exception.ProjectNotFound: Could not find project: service.
2023-04-01 08:37:46.638 28 ERROR keystone.server.flask.application 
2023-04-01 08:37:55.492 26 ERROR keystone.server.flask.application [None req-d6341da1-986d-4178-8506-2460121a774d 9e470207b35a4ed1b323ab95faad5f45 - - all default -] Could not find project: service.: keystone.exception.ProjectNotFound: Could not find project: service.
2023-04-01 08:37:55.492 26 ERROR keystone.server.flask.application Traceback (most recent call last):
2023-04-01 08:37:55.492 26 ERROR keystone.server.flask.application   File "/var/lib/kolla/venv/lib/python3.9/site-packages/flask/app.py", line 1820, in full_dispatch_request
2023-04-01 08:37:55.492 26 ERROR keystone.server.flask.application     rv = self.dispatch_request()
2023-04-01 08:37:55.492 26 ERROR keystone.server.flask.application   File "/var/lib/kolla/venv/lib/python3.9/site-packages/flask/app.py", line 1796, in dispatch_request
2023-04-01 08:37:55.492 26 ERROR keystone.server.flask.application     return self.ensure_sync(self.view_functions[rule.endpoint])(**view_args)
2023-04-01 08:37:55.492 26 ERROR keystone.server.flask.application   File "/var/lib/kolla/venv/lib/python3.9/site-packages/flask_restful/__init__.py", line 467, in wrapper
2023-04-01 08:37:55.492 26 ERROR keystone.server.flask.application     resp = resource(*args, **kwargs)
2023-04-01 08:37:55.492 26 ERROR keystone.server.flask.application   File "/var/lib/kolla/venv/lib/python3.9/site-packages/flask/views.py", line 107, in view
2023-04-01 08:37:55.492 26 ERROR keystone.server.flask.application     return current_app.ensure_sync(self.dispatch_request)(**kwargs)
2023-04-01 08:37:55.492 26 ERROR keystone.server.flask.application   File "/var/lib/kolla/venv/lib/python3.9/site-packages/flask_restful/__init__.py", line 582, in dispatch_request
2023-04-01 08:37:55.492 26 ERROR keystone.server.flask.application     resp = meth(*args, **kwargs)
2023-04-01 08:37:55.492 26 ERROR keystone.server.flask.application   File "/var/lib/kolla/venv/lib/python3.9/site-packages/keystone/api/projects.py", line 151, in get
2023-04-01 08:37:55.492 26 ERROR keystone.server.flask.application     return self._get_project(project_id)
2023-04-01 08:37:55.492 26 ERROR keystone.server.flask.application   File "/var/lib/kolla/venv/lib/python3.9/site-packages/keystone/api/projects.py", line 107, in _get_project
2023-04-01 08:37:55.492 26 ERROR keystone.server.flask.application     project = PROVIDERS.resource_api.get_project(project_id)
2023-04-01 08:37:55.492 26 ERROR keystone.server.flask.application   File "/var/lib/kolla/venv/lib/python3.9/site-packages/keystone/common/manager.py", line 115, in wrapped
2023-04-01 08:37:55.492 26 ERROR keystone.server.flask.application     __ret_val = __f(*args, **kwargs)
2023-04-01 08:37:55.492 26 ERROR keystone.server.flask.application   File "/var/lib/kolla/venv/lib/python3.9/site-packages/decorator.py", line 232, in fun
2023-04-01 08:37:55.492 26 ERROR keystone.server.flask.application     return caller(func, *(extras + args), **kw)
2023-04-01 08:37:55.492 26 ERROR keystone.server.flask.application   File "/var/lib/kolla/venv/lib/python3.9/site-packages/dogpile/cache/region.py", line 1577, in get_or_create_for_user_func
2023-04-01 08:37:55.492 26 ERROR keystone.server.flask.application     return self.get_or_create(
2023-04-01 08:37:55.492 26 ERROR keystone.server.flask.application   File "/var/lib/kolla/venv/lib/python3.9/site-packages/dogpile/cache/region.py", line 1042, in get_or_create
2023-04-01 08:37:55.492 26 ERROR keystone.server.flask.application     with Lock(
2023-04-01 08:37:55.492 26 ERROR keystone.server.flask.application   File "/var/lib/kolla/venv/lib/python3.9/site-packages/dogpile/lock.py", line 185, in __enter__
2023-04-01 08:37:55.492 26 ERROR keystone.server.flask.application     return self._enter()
2023-04-01 08:37:55.492 26 ERROR keystone.server.flask.application   File "/var/lib/kolla/venv/lib/python3.9/site-packages/dogpile/lock.py", line 94, in _enter
2023-04-01 08:37:55.492 26 ERROR keystone.server.flask.application     generated = self._enter_create(value, createdtime)
2023-04-01 08:37:55.492 26 ERROR keystone.server.flask.application   File "/var/lib/kolla/venv/lib/python3.9/site-packages/dogpile/lock.py", line 178, in _enter_create
2023-04-01 08:37:55.492 26 ERROR keystone.server.flask.application     return self.creator()
2023-04-01 08:37:55.492 26 ERROR keystone.server.flask.application   File "/var/lib/kolla/venv/lib/python3.9/site-packages/dogpile/cache/region.py", line 995, in gen_value
2023-04-01 08:37:55.492 26 ERROR keystone.server.flask.application     created_value = creator(
2023-04-01 08:37:55.492 26 ERROR keystone.server.flask.application   File "/var/lib/kolla/venv/lib/python3.9/site-packages/keystone/resource/core.py", line 903, in get_project
2023-04-01 08:37:55.492 26 ERROR keystone.server.flask.application     return self.driver.get_project(project_id)
2023-04-01 08:37:55.492 26 ERROR keystone.server.flask.application   File "/var/lib/kolla/venv/lib/python3.9/site-packages/keystone/resource/backends/sql.py", line 49, in get_project
2023-04-01 08:37:55.492 26 ERROR keystone.server.flask.application     return self._get_project(session, project_id).to_dict()
2023-04-01 08:37:55.492 26 ERROR keystone.server.flask.application   File "/var/lib/kolla/venv/lib/python3.9/site-packages/keystone/resource/backends/sql.py", line 44, in _get_project
2023-04-01 08:37:55.492 26 ERROR keystone.server.flask.application     raise exception.ProjectNotFound(project_id=project_id)
2023-04-01 08:37:55.492 26 ERROR keystone.server.flask.application keystone.exception.ProjectNotFound: Could not find project: service.
2023-04-01 08:37:55.492 26 ERROR keystone.server.flask.application 
2023-04-01 08:38:10.665 26 ERROR keystone.server.flask.application [None req-b7ec637d-a06d-4704-a8ce-829bc3d4139f 9e470207b35a4ed1b323ab95faad5f45 - - all default -] Could not find role: admin.: keystone.exception.RoleNotFound: Could not find role: admin.
2023-04-01 08:38:10.665 26 ERROR keystone.server.flask.application Traceback (most recent call last):
2023-04-01 08:38:10.665 26 ERROR keystone.server.flask.application   File "/var/lib/kolla/venv/lib/python3.9/site-packages/flask/app.py", line 1820, in full_dispatch_request
2023-04-01 08:38:10.665 26 ERROR keystone.server.flask.application     rv = self.dispatch_request()
2023-04-01 08:38:10.665 26 ERROR keystone.server.flask.application   File "/var/lib/kolla/venv/lib/python3.9/site-packages/flask/app.py", line 1796, in dispatch_request
2023-04-01 08:38:10.665 26 ERROR keystone.server.flask.application     return self.ensure_sync(self.view_functions[rule.endpoint])(**view_args)
2023-04-01 08:38:10.665 26 ERROR keystone.server.flask.application   File "/var/lib/kolla/venv/lib/python3.9/site-packages/flask_restful/__init__.py", line 467, in wrapper
2023-04-01 08:38:10.665 26 ERROR keystone.server.flask.application     resp = resource(*args, **kwargs)
2023-04-01 08:38:10.665 26 ERROR keystone.server.flask.application   File "/var/lib/kolla/venv/lib/python3.9/site-packages/flask/views.py", line 107, in view
2023-04-01 08:38:10.665 26 ERROR keystone.server.flask.application     return current_app.ensure_sync(self.dispatch_request)(**kwargs)
2023-04-01 08:38:10.665 26 ERROR keystone.server.flask.application   File "/var/lib/kolla/venv/lib/python3.9/site-packages/flask_restful/__init__.py", line 582, in dispatch_request
2023-04-01 08:38:10.665 26 ERROR keystone.server.flask.application     resp = meth(*args, **kwargs)
2023-04-01 08:38:10.665 26 ERROR keystone.server.flask.application   File "/var/lib/kolla/venv/lib/python3.9/site-packages/keystone/api/roles.py", line 50, in get
2023-04-01 08:38:10.665 26 ERROR keystone.server.flask.application     return self._get_role(role_id)
2023-04-01 08:38:10.665 26 ERROR keystone.server.flask.application   File "/var/lib/kolla/venv/lib/python3.9/site-packages/keystone/api/roles.py", line 70, in _get_role
2023-04-01 08:38:10.665 26 ERROR keystone.server.flask.application     ENFORCER.enforce_call(action='identity:get_role')
2023-04-01 08:38:10.665 26 ERROR keystone.server.flask.application   File "/var/lib/kolla/venv/lib/python3.9/site-packages/keystone/common/rbac_enforcer/enforcer.py", line 402, in enforce_call
2023-04-01 08:38:10.665 26 ERROR keystone.server.flask.application     policy_dict.update(cls._extract_member_target_data(
2023-04-01 08:38:10.665 26 ERROR keystone.server.flask.application   File "/var/lib/kolla/venv/lib/python3.9/site-packages/keystone/common/rbac_enforcer/enforcer.py", line 234, in _extract_member_target_data
2023-04-01 08:38:10.665 26 ERROR keystone.server.flask.application     member_name: func(flask.request.view_args[key])
2023-04-01 08:38:10.665 26 ERROR keystone.server.flask.application   File "/var/lib/kolla/venv/lib/python3.9/site-packages/keystone/common/manager.py", line 115, in wrapped
2023-04-01 08:38:10.665 26 ERROR keystone.server.flask.application     __ret_val = __f(*args, **kwargs)
2023-04-01 08:38:10.665 26 ERROR keystone.server.flask.application   File "/var/lib/kolla/venv/lib/python3.9/site-packages/decorator.py", line 232, in fun
2023-04-01 08:38:10.665 26 ERROR keystone.server.flask.application     return caller(func, *(extras + args), **kw)
2023-04-01 08:38:10.665 26 ERROR keystone.server.flask.application   File "/var/lib/kolla/venv/lib/python3.9/site-packages/dogpile/cache/region.py", line 1577, in get_or_create_for_user_func
2023-04-01 08:38:10.665 26 ERROR keystone.server.flask.application     return self.get_or_create(
2023-04-01 08:38:10.665 26 ERROR keystone.server.flask.application   File "/var/lib/kolla/venv/lib/python3.9/site-packages/dogpile/cache/region.py", line 1042, in get_or_create
2023-04-01 08:38:10.665 26 ERROR keystone.server.flask.application     with Lock(
2023-04-01 08:38:10.665 26 ERROR keystone.server.flask.application   File "/var/lib/kolla/venv/lib/python3.9/site-packages/dogpile/lock.py", line 185, in __enter__
2023-04-01 08:38:10.665 26 ERROR keystone.server.flask.application     return self._enter()
2023-04-01 08:38:10.665 26 ERROR keystone.server.flask.application   File "/var/lib/kolla/venv/lib/python3.9/site-packages/dogpile/lock.py", line 94, in _enter
2023-04-01 08:38:10.665 26 ERROR keystone.server.flask.application     generated = self._enter_create(value, createdtime)
2023-04-01 08:38:10.665 26 ERROR keystone.server.flask.application   File "/var/lib/kolla/venv/lib/python3.9/site-packages/dogpile/lock.py", line 178, in _enter_create
2023-04-01 08:38:10.665 26 ERROR keystone.server.flask.application     return self.creator()
2023-04-01 08:38:10.665 26 ERROR keystone.server.flask.application   File "/var/lib/kolla/venv/lib/python3.9/site-packages/dogpile/cache/region.py", line 995, in gen_value
2023-04-01 08:38:10.665 26 ERROR keystone.server.flask.application     created_value = creator(
2023-04-01 08:38:10.665 26 ERROR keystone.server.flask.application   File "/var/lib/kolla/venv/lib/python3.9/site-packages/keystone/assignment/core.py", line 1276, in get_role
2023-04-01 08:38:10.665 26 ERROR keystone.server.flask.application     return self.driver.get_role(role_id)
2023-04-01 08:38:10.665 26 ERROR keystone.server.flask.application   File "/var/lib/kolla/venv/lib/python3.9/site-packages/keystone/assignment/role_backends/sql.py", line 70, in get_role
2023-04-01 08:38:10.665 26 ERROR keystone.server.flask.application     return self._get_role(session, role_id).to_dict()
2023-04-01 08:38:10.665 26 ERROR keystone.server.flask.application   File "/var/lib/kolla/venv/lib/python3.9/site-packages/keystone/assignment/role_backends/sql.py", line 65, in _get_role
2023-04-01 08:38:10.665 26 ERROR keystone.server.flask.application     raise exception.RoleNotFound(role_id=role_id)
2023-04-01 08:38:10.665 26 ERROR keystone.server.flask.application keystone.exception.RoleNotFound: Could not find role: admin.
2023-04-01 08:38:10.665 26 ERROR keystone.server.flask.application 
2023-04-01 08:38:12.020 26 ERROR keystone.server.flask.application [None req-eee48d6e-4add-4569-bed4-74ea300a2577 9e470207b35a4ed1b323ab95faad5f45 - - all default -] Could not find user: ironic.: keystone.exception.UserNotFound: Could not find user: ironic.
2023-04-01 08:38:12.020 26 ERROR keystone.server.flask.application Traceback (most recent call last):
2023-04-01 08:38:12.020 26 ERROR keystone.server.flask.application   File "/var/lib/kolla/venv/lib/python3.9/site-packages/flask/app.py", line 1820, in full_dispatch_request
2023-04-01 08:38:12.020 26 ERROR keystone.server.flask.application     rv = self.dispatch_request()
2023-04-01 08:38:12.020 26 ERROR keystone.server.flask.application   File "/var/lib/kolla/venv/lib/python3.9/site-packages/flask/app.py", line 1796, in dispatch_request
2023-04-01 08:38:12.020 26 ERROR keystone.server.flask.application     return self.ensure_sync(self.view_functions[rule.endpoint])(**view_args)
2023-04-01 08:38:12.020 26 ERROR keystone.server.flask.application   File "/var/lib/kolla/venv/lib/python3.9/site-packages/flask_restful/__init__.py", line 467, in wrapper
2023-04-01 08:38:12.020 26 ERROR keystone.server.flask.application     resp = resource(*args, **kwargs)
2023-04-01 08:38:12.020 26 ERROR keystone.server.flask.application   File "/var/lib/kolla/venv/lib/python3.9/site-packages/flask/views.py", line 107, in view
2023-04-01 08:38:12.020 26 ERROR keystone.server.flask.application     return current_app.ensure_sync(self.dispatch_request)(**kwargs)
2023-04-01 08:38:12.020 26 ERROR keystone.server.flask.application   File "/var/lib/kolla/venv/lib/python3.9/site-packages/flask_restful/__init__.py", line 582, in dispatch_request
2023-04-01 08:38:12.020 26 ERROR keystone.server.flask.application     resp = meth(*args, **kwargs)
2023-04-01 08:38:12.020 26 ERROR keystone.server.flask.application   File "/var/lib/kolla/venv/lib/python3.9/site-packages/keystone/api/users.py", line 182, in get
2023-04-01 08:38:12.020 26 ERROR keystone.server.flask.application     return self._get_user(user_id)
2023-04-01 08:38:12.020 26 ERROR keystone.server.flask.application   File "/var/lib/kolla/venv/lib/python3.9/site-packages/keystone/api/users.py", line 194, in _get_user
2023-04-01 08:38:12.020 26 ERROR keystone.server.flask.application     ref = PROVIDERS.identity_api.get_user(user_id)
2023-04-01 08:38:12.020 26 ERROR keystone.server.flask.application   File "/var/lib/kolla/venv/lib/python3.9/site-packages/keystone/common/manager.py", line 115, in wrapped
2023-04-01 08:38:12.020 26 ERROR keystone.server.flask.application     __ret_val = __f(*args, **kwargs)
2023-04-01 08:38:12.020 26 ERROR keystone.server.flask.application   File "/var/lib/kolla/venv/lib/python3.9/site-packages/keystone/identity/core.py", line 414, in wrapper
2023-04-01 08:38:12.020 26 ERROR keystone.server.flask.application     return f(self, *args, **kwargs)
2023-04-01 08:38:12.020 26 ERROR keystone.server.flask.application   File "/var/lib/kolla/venv/lib/python3.9/site-packages/keystone/identity/core.py", line 424, in wrapper
2023-04-01 08:38:12.020 26 ERROR keystone.server.flask.application     return f(self, *args, **kwargs)
2023-04-01 08:38:12.020 26 ERROR keystone.server.flask.application   File "/var/lib/kolla/venv/lib/python3.9/site-packages/decorator.py", line 232, in fun
2023-04-01 08:38:12.020 26 ERROR keystone.server.flask.application     return caller(func, *(extras + args), **kw)
2023-04-01 08:38:12.020 26 ERROR keystone.server.flask.application   File "/var/lib/kolla/venv/lib/python3.9/site-packages/dogpile/cache/region.py", line 1577, in get_or_create_for_user_func
2023-04-01 08:38:12.020 26 ERROR keystone.server.flask.application     return self.get_or_create(
2023-04-01 08:38:12.020 26 ERROR keystone.server.flask.application   File "/var/lib/kolla/venv/lib/python3.9/site-packages/dogpile/cache/region.py", line 1042, in get_or_create
2023-04-01 08:38:12.020 26 ERROR keystone.server.flask.application     with Lock(
2023-04-01 08:38:12.020 26 ERROR keystone.server.flask.application   File "/var/lib/kolla/venv/lib/python3.9/site-packages/dogpile/lock.py", line 185, in __enter__
2023-04-01 08:38:12.020 26 ERROR keystone.server.flask.application     return self._enter()
2023-04-01 08:38:12.020 26 ERROR keystone.server.flask.application   File "/var/lib/kolla/venv/lib/python3.9/site-packages/dogpile/lock.py", line 94, in _enter
2023-04-01 08:38:12.020 26 ERROR keystone.server.flask.application     generated = self._enter_create(value, createdtime)
2023-04-01 08:38:12.020 26 ERROR keystone.server.flask.application   File "/var/lib/kolla/venv/lib/python3.9/site-packages/dogpile/lock.py", line 178, in _enter_create
2023-04-01 08:38:12.020 26 ERROR keystone.server.flask.application     return self.creator()
2023-04-01 08:38:12.020 26 ERROR keystone.server.flask.application   File "/var/lib/kolla/venv/lib/python3.9/site-packages/dogpile/cache/region.py", line 995, in gen_value
2023-04-01 08:38:12.020 26 ERROR keystone.server.flask.application     created_value = creator(
2023-04-01 08:38:12.020 26 ERROR keystone.server.flask.application   File "/var/lib/kolla/venv/lib/python3.9/site-packages/keystone/identity/core.py", line 1011, in get_user
2023-04-01 08:38:12.020 26 ERROR keystone.server.flask.application     ref = driver.get_user(entity_id)
2023-04-01 08:38:12.020 26 ERROR keystone.server.flask.application   File "/var/lib/kolla/venv/lib/python3.9/site-packages/keystone/identity/backends/sql.py", line 200, in get_user
2023-04-01 08:38:12.020 26 ERROR keystone.server.flask.application     self._get_user(session, user_id).to_dict())
2023-04-01 08:38:12.020 26 ERROR keystone.server.flask.application   File "/var/lib/kolla/venv/lib/python3.9/site-packages/keystone/identity/backends/sql.py", line 194, in _get_user
2023-04-01 08:38:12.020 26 ERROR keystone.server.flask.application     raise exception.UserNotFound(user_id=user_id)
2023-04-01 08:38:12.020 26 ERROR keystone.server.flask.application keystone.exception.UserNotFound: Could not find user: ironic.
2023-04-01 08:38:12.020 26 ERROR keystone.server.flask.application 
2023-04-01 08:38:12.882 27 ERROR keystone.server.flask.application [None req-aa68450e-00a3-4ed0-ae0c-7440e218ac84 9e470207b35a4ed1b323ab95faad5f45 - - all default -] Could not find project: service.: keystone.exception.ProjectNotFound: Could not find project: service.
2023-04-01 08:38:12.882 27 ERROR keystone.server.flask.application Traceback (most recent call last):
2023-04-01 08:38:12.882 27 ERROR keystone.server.flask.application   File "/var/lib/kolla/venv/lib/python3.9/site-packages/flask/app.py", line 1820, in full_dispatch_request
2023-04-01 08:38:12.882 27 ERROR keystone.server.flask.application     rv = self.dispatch_request()
2023-04-01 08:38:12.882 27 ERROR keystone.server.flask.application   File "/var/lib/kolla/venv/lib/python3.9/site-packages/flask/app.py", line 1796, in dispatch_request
2023-04-01 08:38:12.882 27 ERROR keystone.server.flask.application     return self.ensure_sync(self.view_functions[rule.endpoint])(**view_args)
2023-04-01 08:38:12.882 27 ERROR keystone.server.flask.application   File "/var/lib/kolla/venv/lib/python3.9/site-packages/flask_restful/__init__.py", line 467, in wrapper
2023-04-01 08:38:12.882 27 ERROR keystone.server.flask.application     resp = resource(*args, **kwargs)
2023-04-01 08:38:12.882 27 ERROR keystone.server.flask.application   File "/var/lib/kolla/venv/lib/python3.9/site-packages/flask/views.py", line 107, in view
2023-04-01 08:38:12.882 27 ERROR keystone.server.flask.application     return current_app.ensure_sync(self.dispatch_request)(**kwargs)
2023-04-01 08:38:12.882 27 ERROR keystone.server.flask.application   File "/var/lib/kolla/venv/lib/python3.9/site-packages/flask_restful/__init__.py", line 582, in dispatch_request
2023-04-01 08:38:12.882 27 ERROR keystone.server.flask.application     resp = meth(*args, **kwargs)
2023-04-01 08:38:12.882 27 ERROR keystone.server.flask.application   File "/var/lib/kolla/venv/lib/python3.9/site-packages/keystone/api/projects.py", line 151, in get
2023-04-01 08:38:12.882 27 ERROR keystone.server.flask.application     return self._get_project(project_id)
2023-04-01 08:38:12.882 27 ERROR keystone.server.flask.application   File "/var/lib/kolla/venv/lib/python3.9/site-packages/keystone/api/projects.py", line 107, in _get_project
2023-04-01 08:38:12.882 27 ERROR keystone.server.flask.application     project = PROVIDERS.resource_api.get_project(project_id)
2023-04-01 08:38:12.882 27 ERROR keystone.server.flask.application   File "/var/lib/kolla/venv/lib/python3.9/site-packages/keystone/common/manager.py", line 115, in wrapped
2023-04-01 08:38:12.882 27 ERROR keystone.server.flask.application     __ret_val = __f(*args, **kwargs)
2023-04-01 08:38:12.882 27 ERROR keystone.server.flask.application   File "/var/lib/kolla/venv/lib/python3.9/site-packages/decorator.py", line 232, in fun
2023-04-01 08:38:12.882 27 ERROR keystone.server.flask.application     return caller(func, *(extras + args), **kw)
2023-04-01 08:38:12.882 27 ERROR keystone.server.flask.application   File "/var/lib/kolla/venv/lib/python3.9/site-packages/dogpile/cache/region.py", line 1577, in get_or_create_for_user_func
2023-04-01 08:38:12.882 27 ERROR keystone.server.flask.application     return self.get_or_create(
2023-04-01 08:38:12.882 27 ERROR keystone.server.flask.application   File "/var/lib/kolla/venv/lib/python3.9/site-packages/dogpile/cache/region.py", line 1042, in get_or_create
2023-04-01 08:38:12.882 27 ERROR keystone.server.flask.application     with Lock(
2023-04-01 08:38:12.882 27 ERROR keystone.server.flask.application   File "/var/lib/kolla/venv/lib/python3.9/site-packages/dogpile/lock.py", line 185, in __enter__
2023-04-01 08:38:12.882 27 ERROR keystone.server.flask.application     return self._enter()
2023-04-01 08:38:12.882 27 ERROR keystone.server.flask.application   File "/var/lib/kolla/venv/lib/python3.9/site-packages/dogpile/lock.py", line 94, in _enter
2023-04-01 08:38:12.882 27 ERROR keystone.server.flask.application     generated = self._enter_create(value, createdtime)
2023-04-01 08:38:12.882 27 ERROR keystone.server.flask.application   File "/var/lib/kolla/venv/lib/python3.9/site-packages/dogpile/lock.py", line 178, in _enter_create
2023-04-01 08:38:12.882 27 ERROR keystone.server.flask.application     return self.creator()
2023-04-01 08:38:12.882 27 ERROR keystone.server.flask.application   File "/var/lib/kolla/venv/lib/python3.9/site-packages/dogpile/cache/region.py", line 995, in gen_value
2023-04-01 08:38:12.882 27 ERROR keystone.server.flask.application     created_value = creator(
2023-04-01 08:38:12.882 27 ERROR keystone.server.flask.application   File "/var/lib/kolla/venv/lib/python3.9/site-packages/keystone/resource/core.py", line 903, in get_project
2023-04-01 08:38:12.882 27 ERROR keystone.server.flask.application     return self.driver.get_project(project_id)
2023-04-01 08:38:12.882 27 ERROR keystone.server.flask.application   File "/var/lib/kolla/venv/lib/python3.9/site-packages/keystone/resource/backends/sql.py", line 49, in get_project
2023-04-01 08:38:12.882 27 ERROR keystone.server.flask.application     return self._get_project(session, project_id).to_dict()
2023-04-01 08:38:12.882 27 ERROR keystone.server.flask.application   File "/var/lib/kolla/venv/lib/python3.9/site-packages/keystone/resource/backends/sql.py", line 44, in _get_project
2023-04-01 08:38:12.882 27 ERROR keystone.server.flask.application     raise exception.ProjectNotFound(project_id=project_id)
2023-04-01 08:38:12.882 27 ERROR keystone.server.flask.application keystone.exception.ProjectNotFound: Could not find project: service.
2023-04-01 08:38:12.882 27 ERROR keystone.server.flask.application 
2023-04-01 08:38:22.962 28 ERROR keystone.server.flask.application [None req-38e33db5-ec9a-4309-b3d0-abccf8f18324 9e470207b35a4ed1b323ab95faad5f45 - - all default -] Could not find role: admin.: keystone.exception.RoleNotFound: Could not find role: admin.
2023-04-01 08:38:22.962 28 ERROR keystone.server.flask.application Traceback (most recent call last):
2023-04-01 08:38:22.962 28 ERROR keystone.server.flask.application   File "/var/lib/kolla/venv/lib/python3.9/site-packages/flask/app.py", line 1820, in full_dispatch_request
2023-04-01 08:38:22.962 28 ERROR keystone.server.flask.application     rv = self.dispatch_request()
2023-04-01 08:38:22.962 28 ERROR keystone.server.flask.application   File "/var/lib/kolla/venv/lib/python3.9/site-packages/flask/app.py", line 1796, in dispatch_request
2023-04-01 08:38:22.962 28 ERROR keystone.server.flask.application     return self.ensure_sync(self.view_functions[rule.endpoint])(**view_args)
2023-04-01 08:38:22.962 28 ERROR keystone.server.flask.application   File "/var/lib/kolla/venv/lib/python3.9/site-packages/flask_restful/__init__.py", line 467, in wrapper
2023-04-01 08:38:22.962 28 ERROR keystone.server.flask.application     resp = resource(*args, **kwargs)
2023-04-01 08:38:22.962 28 ERROR keystone.server.flask.application   File "/var/lib/kolla/venv/lib/python3.9/site-packages/flask/views.py", line 107, in view
2023-04-01 08:38:22.962 28 ERROR keystone.server.flask.application     return current_app.ensure_sync(self.dispatch_request)(**kwargs)
2023-04-01 08:38:22.962 28 ERROR keystone.server.flask.application   File "/var/lib/kolla/venv/lib/python3.9/site-packages/flask_restful/__init__.py", line 582, in dispatch_request
2023-04-01 08:38:22.962 28 ERROR keystone.server.flask.application     resp = meth(*args, **kwargs)
2023-04-01 08:38:22.962 28 ERROR keystone.server.flask.application   File "/var/lib/kolla/venv/lib/python3.9/site-packages/keystone/api/roles.py", line 50, in get
2023-04-01 08:38:22.962 28 ERROR keystone.server.flask.application     return self._get_role(role_id)
2023-04-01 08:38:22.962 28 ERROR keystone.server.flask.application   File "/var/lib/kolla/venv/lib/python3.9/site-packages/keystone/api/roles.py", line 70, in _get_role
2023-04-01 08:38:22.962 28 ERROR keystone.server.flask.application     ENFORCER.enforce_call(action='identity:get_role')
2023-04-01 08:38:22.962 28 ERROR keystone.server.flask.application   File "/var/lib/kolla/venv/lib/python3.9/site-packages/keystone/common/rbac_enforcer/enforcer.py", line 402, in enforce_call
2023-04-01 08:38:22.962 28 ERROR keystone.server.flask.application     policy_dict.update(cls._extract_member_target_data(
2023-04-01 08:38:22.962 28 ERROR keystone.server.flask.application   File "/var/lib/kolla/venv/lib/python3.9/site-packages/keystone/common/rbac_enforcer/enforcer.py", line 234, in _extract_member_target_data
2023-04-01 08:38:22.962 28 ERROR keystone.server.flask.application     member_name: func(flask.request.view_args[key])
2023-04-01 08:38:22.962 28 ERROR keystone.server.flask.application   File "/var/lib/kolla/venv/lib/python3.9/site-packages/keystone/common/manager.py", line 115, in wrapped
2023-04-01 08:38:22.962 28 ERROR keystone.server.flask.application     __ret_val = __f(*args, **kwargs)
2023-04-01 08:38:22.962 28 ERROR keystone.server.flask.application   File "/var/lib/kolla/venv/lib/python3.9/site-packages/decorator.py", line 232, in fun
2023-04-01 08:38:22.962 28 ERROR keystone.server.flask.application     return caller(func, *(extras + args), **kw)
2023-04-01 08:38:22.962 28 ERROR keystone.server.flask.application   File "/var/lib/kolla/venv/lib/python3.9/site-packages/dogpile/cache/region.py", line 1577, in get_or_create_for_user_func
2023-04-01 08:38:22.962 28 ERROR keystone.server.flask.application     return self.get_or_create(
2023-04-01 08:38:22.962 28 ERROR keystone.server.flask.application   File "/var/lib/kolla/venv/lib/python3.9/site-packages/dogpile/cache/region.py", line 1042, in get_or_create
2023-04-01 08:38:22.962 28 ERROR keystone.server.flask.application     with Lock(
2023-04-01 08:38:22.962 28 ERROR keystone.server.flask.application   File "/var/lib/kolla/venv/lib/python3.9/site-packages/dogpile/lock.py", line 185, in __enter__
2023-04-01 08:38:22.962 28 ERROR keystone.server.flask.application     return self._enter()
2023-04-01 08:38:22.962 28 ERROR keystone.server.flask.application   File "/var/lib/kolla/venv/lib/python3.9/site-packages/dogpile/lock.py", line 94, in _enter
2023-04-01 08:38:22.962 28 ERROR keystone.server.flask.application     generated = self._enter_create(value, createdtime)
2023-04-01 08:38:22.962 28 ERROR keystone.server.flask.application   File "/var/lib/kolla/venv/lib/python3.9/site-packages/dogpile/lock.py", line 178, in _enter_create
2023-04-01 08:38:22.962 28 ERROR keystone.server.flask.application     return self.creator()
2023-04-01 08:38:22.962 28 ERROR keystone.server.flask.application   File "/var/lib/kolla/venv/lib/python3.9/site-packages/dogpile/cache/region.py", line 995, in gen_value
2023-04-01 08:38:22.962 28 ERROR keystone.server.flask.application     created_value = creator(
2023-04-01 08:38:22.962 28 ERROR keystone.server.flask.application   File "/var/lib/kolla/venv/lib/python3.9/site-packages/keystone/assignment/core.py", line 1276, in get_role
2023-04-01 08:38:22.962 28 ERROR keystone.server.flask.application     return self.driver.get_role(role_id)
2023-04-01 08:38:22.962 28 ERROR keystone.server.flask.application   File "/var/lib/kolla/venv/lib/python3.9/site-packages/keystone/assignment/role_backends/sql.py", line 70, in get_role
2023-04-01 08:38:22.962 28 ERROR keystone.server.flask.application     return self._get_role(session, role_id).to_dict()
2023-04-01 08:38:22.962 28 ERROR keystone.server.flask.application   File "/var/lib/kolla/venv/lib/python3.9/site-packages/keystone/assignment/role_backends/sql.py", line 65, in _get_role
2023-04-01 08:38:22.962 28 ERROR keystone.server.flask.application     raise exception.RoleNotFound(role_id=role_id)
2023-04-01 08:38:22.962 28 ERROR keystone.server.flask.application keystone.exception.RoleNotFound: Could not find role: admin.
2023-04-01 08:38:22.962 28 ERROR keystone.server.flask.application 
2023-04-01 08:38:24.274 28 ERROR keystone.server.flask.application [None req-20ee686e-6f30-428e-9962-f41bd0418540 9e470207b35a4ed1b323ab95faad5f45 - - all default -] Could not find user: ironic-inspector.: keystone.exception.UserNotFound: Could not find user: ironic-inspector.
2023-04-01 08:38:24.274 28 ERROR keystone.server.flask.application Traceback (most recent call last):
2023-04-01 08:38:24.274 28 ERROR keystone.server.flask.application   File "/var/lib/kolla/venv/lib/python3.9/site-packages/flask/app.py", line 1820, in full_dispatch_request
2023-04-01 08:38:24.274 28 ERROR keystone.server.flask.application     rv = self.dispatch_request()
2023-04-01 08:38:24.274 28 ERROR keystone.server.flask.application   File "/var/lib/kolla/venv/lib/python3.9/site-packages/flask/app.py", line 1796, in dispatch_request
2023-04-01 08:38:24.274 28 ERROR keystone.server.flask.application     return self.ensure_sync(self.view_functions[rule.endpoint])(**view_args)
2023-04-01 08:38:24.274 28 ERROR keystone.server.flask.application   File "/var/lib/kolla/venv/lib/python3.9/site-packages/flask_restful/__init__.py", line 467, in wrapper
2023-04-01 08:38:24.274 28 ERROR keystone.server.flask.application     resp = resource(*args, **kwargs)
2023-04-01 08:38:24.274 28 ERROR keystone.server.flask.application   File "/var/lib/kolla/venv/lib/python3.9/site-packages/flask/views.py", line 107, in view
2023-04-01 08:38:24.274 28 ERROR keystone.server.flask.application     return current_app.ensure_sync(self.dispatch_request)(**kwargs)
2023-04-01 08:38:24.274 28 ERROR keystone.server.flask.application   File "/var/lib/kolla/venv/lib/python3.9/site-packages/flask_restful/__init__.py", line 582, in dispatch_request
2023-04-01 08:38:24.274 28 ERROR keystone.server.flask.application     resp = meth(*args, **kwargs)
2023-04-01 08:38:24.274 28 ERROR keystone.server.flask.application   File "/var/lib/kolla/venv/lib/python3.9/site-packages/keystone/api/users.py", line 182, in get
2023-04-01 08:38:24.274 28 ERROR keystone.server.flask.application     return self._get_user(user_id)
2023-04-01 08:38:24.274 28 ERROR keystone.server.flask.application   File "/var/lib/kolla/venv/lib/python3.9/site-packages/keystone/api/users.py", line 194, in _get_user
2023-04-01 08:38:24.274 28 ERROR keystone.server.flask.application     ref = PROVIDERS.identity_api.get_user(user_id)
2023-04-01 08:38:24.274 28 ERROR keystone.server.flask.application   File "/var/lib/kolla/venv/lib/python3.9/site-packages/keystone/common/manager.py", line 115, in wrapped
2023-04-01 08:38:24.274 28 ERROR keystone.server.flask.application     __ret_val = __f(*args, **kwargs)
2023-04-01 08:38:24.274 28 ERROR keystone.server.flask.application   File "/var/lib/kolla/venv/lib/python3.9/site-packages/keystone/identity/core.py", line 414, in wrapper
2023-04-01 08:38:24.274 28 ERROR keystone.server.flask.application     return f(self, *args, **kwargs)
2023-04-01 08:38:24.274 28 ERROR keystone.server.flask.application   File "/var/lib/kolla/venv/lib/python3.9/site-packages/keystone/identity/core.py", line 424, in wrapper
2023-04-01 08:38:24.274 28 ERROR keystone.server.flask.application     return f(self, *args, **kwargs)
2023-04-01 08:38:24.274 28 ERROR keystone.server.flask.application   File "/var/lib/kolla/venv/lib/python3.9/site-packages/decorator.py", line 232, in fun
2023-04-01 08:38:24.274 28 ERROR keystone.server.flask.application     return caller(func, *(extras + args), **kw)
2023-04-01 08:38:24.274 28 ERROR keystone.server.flask.application   File "/var/lib/kolla/venv/lib/python3.9/site-packages/dogpile/cache/region.py", line 1577, in get_or_create_for_user_func
2023-04-01 08:38:24.274 28 ERROR keystone.server.flask.application     return self.get_or_create(
2023-04-01 08:38:24.274 28 ERROR keystone.server.flask.application   File "/var/lib/kolla/venv/lib/python3.9/site-packages/dogpile/cache/region.py", line 1042, in get_or_create
2023-04-01 08:38:24.274 28 ERROR keystone.server.flask.application     with Lock(
2023-04-01 08:38:24.274 28 ERROR keystone.server.flask.application   File "/var/lib/kolla/venv/lib/python3.9/site-packages/dogpile/lock.py", line 185, in __enter__
2023-04-01 08:38:24.274 28 ERROR keystone.server.flask.application     return self._enter()
2023-04-01 08:38:24.274 28 ERROR keystone.server.flask.application   File "/var/lib/kolla/venv/lib/python3.9/site-packages/dogpile/lock.py", line 94, in _enter
2023-04-01 08:38:24.274 28 ERROR keystone.server.flask.application     generated = self._enter_create(value, createdtime)
2023-04-01 08:38:24.274 28 ERROR keystone.server.flask.application   File "/var/lib/kolla/venv/lib/python3.9/site-packages/dogpile/lock.py", line 178, in _enter_create
2023-04-01 08:38:24.274 28 ERROR keystone.server.flask.application     return self.creator()
2023-04-01 08:38:24.274 28 ERROR keystone.server.flask.application   File "/var/lib/kolla/venv/lib/python3.9/site-packages/dogpile/cache/region.py", line 995, in gen_value
2023-04-01 08:38:24.274 28 ERROR keystone.server.flask.application     created_value = creator(
2023-04-01 08:38:24.274 28 ERROR keystone.server.flask.application   File "/var/lib/kolla/venv/lib/python3.9/site-packages/keystone/identity/core.py", line 1011, in get_user
2023-04-01 08:38:24.274 28 ERROR keystone.server.flask.application     ref = driver.get_user(entity_id)
2023-04-01 08:38:24.274 28 ERROR keystone.server.flask.application   File "/var/lib/kolla/venv/lib/python3.9/site-packages/keystone/identity/backends/sql.py", line 200, in get_user
2023-04-01 08:38:24.274 28 ERROR keystone.server.flask.application     self._get_user(session, user_id).to_dict())
2023-04-01 08:38:24.274 28 ERROR keystone.server.flask.application   File "/var/lib/kolla/venv/lib/python3.9/site-packages/keystone/identity/backends/sql.py", line 194, in _get_user
2023-04-01 08:38:24.274 28 ERROR keystone.server.flask.application     raise exception.UserNotFound(user_id=user_id)
2023-04-01 08:38:24.274 28 ERROR keystone.server.flask.application keystone.exception.UserNotFound: Could not find user: ironic-inspector.
2023-04-01 08:38:24.274 28 ERROR keystone.server.flask.application 
2023-04-01 08:38:25.151 26 ERROR keystone.server.flask.application [None req-59aa375a-ffa9-4f6a-9d34-53bf5b0ae6ba 9e470207b35a4ed1b323ab95faad5f45 - - all default -] Could not find project: service.: keystone.exception.ProjectNotFound: Could not find project: service.
2023-04-01 08:38:25.151 26 ERROR keystone.server.flask.application Traceback (most recent call last):
2023-04-01 08:38:25.151 26 ERROR keystone.server.flask.application   File "/var/lib/kolla/venv/lib/python3.9/site-packages/flask/app.py", line 1820, in full_dispatch_request
2023-04-01 08:38:25.151 26 ERROR keystone.server.flask.application     rv = self.dispatch_request()
2023-04-01 08:38:25.151 26 ERROR keystone.server.flask.application   File "/var/lib/kolla/venv/lib/python3.9/site-packages/flask/app.py", line 1796, in dispatch_request
2023-04-01 08:38:25.151 26 ERROR keystone.server.flask.application     return self.ensure_sync(self.view_functions[rule.endpoint])(**view_args)
2023-04-01 08:38:25.151 26 ERROR keystone.server.flask.application   File "/var/lib/kolla/venv/lib/python3.9/site-packages/flask_restful/__init__.py", line 467, in wrapper
2023-04-01 08:38:25.151 26 ERROR keystone.server.flask.application     resp = resource(*args, **kwargs)
2023-04-01 08:38:25.151 26 ERROR keystone.server.flask.application   File "/var/lib/kolla/venv/lib/python3.9/site-packages/flask/views.py", line 107, in view
2023-04-01 08:38:25.151 26 ERROR keystone.server.flask.application     return current_app.ensure_sync(self.dispatch_request)(**kwargs)
2023-04-01 08:38:25.151 26 ERROR keystone.server.flask.application   File "/var/lib/kolla/venv/lib/python3.9/site-packages/flask_restful/__init__.py", line 582, in dispatch_request
2023-04-01 08:38:25.151 26 ERROR keystone.server.flask.application     resp = meth(*args, **kwargs)
2023-04-01 08:38:25.151 26 ERROR keystone.server.flask.application   File "/var/lib/kolla/venv/lib/python3.9/site-packages/keystone/api/projects.py", line 151, in get
2023-04-01 08:38:25.151 26 ERROR keystone.server.flask.application     return self._get_project(project_id)
2023-04-01 08:38:25.151 26 ERROR keystone.server.flask.application   File "/var/lib/kolla/venv/lib/python3.9/site-packages/keystone/api/projects.py", line 107, in _get_project
2023-04-01 08:38:25.151 26 ERROR keystone.server.flask.application     project = PROVIDERS.resource_api.get_project(project_id)
2023-04-01 08:38:25.151 26 ERROR keystone.server.flask.application   File "/var/lib/kolla/venv/lib/python3.9/site-packages/keystone/common/manager.py", line 115, in wrapped
2023-04-01 08:38:25.151 26 ERROR keystone.server.flask.application     __ret_val = __f(*args, **kwargs)
2023-04-01 08:38:25.151 26 ERROR keystone.server.flask.application   File "/var/lib/kolla/venv/lib/python3.9/site-packages/decorator.py", line 232, in fun
2023-04-01 08:38:25.151 26 ERROR keystone.server.flask.application     return caller(func, *(extras + args), **kw)
2023-04-01 08:38:25.151 26 ERROR keystone.server.flask.application   File "/var/lib/kolla/venv/lib/python3.9/site-packages/dogpile/cache/region.py", line 1577, in get_or_create_for_user_func
2023-04-01 08:38:25.151 26 ERROR keystone.server.flask.application     return self.get_or_create(
2023-04-01 08:38:25.151 26 ERROR keystone.server.flask.application   File "/var/lib/kolla/venv/lib/python3.9/site-packages/dogpile/cache/region.py", line 1042, in get_or_create
2023-04-01 08:38:25.151 26 ERROR keystone.server.flask.application     with Lock(
2023-04-01 08:38:25.151 26 ERROR keystone.server.flask.application   File "/var/lib/kolla/venv/lib/python3.9/site-packages/dogpile/lock.py", line 185, in __enter__
2023-04-01 08:38:25.151 26 ERROR keystone.server.flask.application     return self._enter()
2023-04-01 08:38:25.151 26 ERROR keystone.server.flask.application   File "/var/lib/kolla/venv/lib/python3.9/site-packages/dogpile/lock.py", line 94, in _enter
2023-04-01 08:38:25.151 26 ERROR keystone.server.flask.application     generated = self._enter_create(value, createdtime)
2023-04-01 08:38:25.151 26 ERROR keystone.server.flask.application   File "/var/lib/kolla/venv/lib/python3.9/site-packages/dogpile/lock.py", line 178, in _enter_create
2023-04-01 08:38:25.151 26 ERROR keystone.server.flask.application     return self.creator()
2023-04-01 08:38:25.151 26 ERROR keystone.server.flask.application   File "/var/lib/kolla/venv/lib/python3.9/site-packages/dogpile/cache/region.py", line 995, in gen_value
2023-04-01 08:38:25.151 26 ERROR keystone.server.flask.application     created_value = creator(
2023-04-01 08:38:25.151 26 ERROR keystone.server.flask.application   File "/var/lib/kolla/venv/lib/python3.9/site-packages/keystone/resource/core.py", line 903, in get_project
2023-04-01 08:38:25.151 26 ERROR keystone.server.flask.application     return self.driver.get_project(project_id)
2023-04-01 08:38:25.151 26 ERROR keystone.server.flask.application   File "/var/lib/kolla/venv/lib/python3.9/site-packages/keystone/resource/backends/sql.py", line 49, in get_project
2023-04-01 08:38:25.151 26 ERROR keystone.server.flask.application     return self._get_project(session, project_id).to_dict()
2023-04-01 08:38:25.151 26 ERROR keystone.server.flask.application   File "/var/lib/kolla/venv/lib/python3.9/site-packages/keystone/resource/backends/sql.py", line 44, in _get_project
2023-04-01 08:38:25.151 26 ERROR keystone.server.flask.application     raise exception.ProjectNotFound(project_id=project_id)
2023-04-01 08:38:25.151 26 ERROR keystone.server.flask.application keystone.exception.ProjectNotFound: Could not find project: service.
2023-04-01 08:38:25.151 26 ERROR keystone.server.flask.application 
2023-04-01 08:41:20.814 26 ERROR keystone.server.flask.application [None req-b66004f8-3067-49ea-b242-c7885ce8edf7 9e470207b35a4ed1b323ab95faad5f45 - - all default -] Could not find project: service.: keystone.exception.ProjectNotFound: Could not find project: service.
2023-04-01 08:41:20.814 26 ERROR keystone.server.flask.application Traceback (most recent call last):
2023-04-01 08:41:20.814 26 ERROR keystone.server.flask.application   File "/var/lib/kolla/venv/lib/python3.9/site-packages/flask/app.py", line 1820, in full_dispatch_request
2023-04-01 08:41:20.814 26 ERROR keystone.server.flask.application     rv = self.dispatch_request()
2023-04-01 08:41:20.814 26 ERROR keystone.server.flask.application   File "/var/lib/kolla/venv/lib/python3.9/site-packages/flask/app.py", line 1796, in dispatch_request
2023-04-01 08:41:20.814 26 ERROR keystone.server.flask.application     return self.ensure_sync(self.view_functions[rule.endpoint])(**view_args)
2023-04-01 08:41:20.814 26 ERROR keystone.server.flask.application   File "/var/lib/kolla/venv/lib/python3.9/site-packages/flask_restful/__init__.py", line 467, in wrapper
2023-04-01 08:41:20.814 26 ERROR keystone.server.flask.application     resp = resource(*args, **kwargs)
2023-04-01 08:41:20.814 26 ERROR keystone.server.flask.application   File "/var/lib/kolla/venv/lib/python3.9/site-packages/flask/views.py", line 107, in view
2023-04-01 08:41:20.814 26 ERROR keystone.server.flask.application     return current_app.ensure_sync(self.dispatch_request)(**kwargs)
2023-04-01 08:41:20.814 26 ERROR keystone.server.flask.application   File "/var/lib/kolla/venv/lib/python3.9/site-packages/flask_restful/__init__.py", line 582, in dispatch_request
2023-04-01 08:41:20.814 26 ERROR keystone.server.flask.application     resp = meth(*args, **kwargs)
2023-04-01 08:41:20.814 26 ERROR keystone.server.flask.application   File "/var/lib/kolla/venv/lib/python3.9/site-packages/keystone/api/projects.py", line 151, in get
2023-04-01 08:41:20.814 26 ERROR keystone.server.flask.application     return self._get_project(project_id)
2023-04-01 08:41:20.814 26 ERROR keystone.server.flask.application   File "/var/lib/kolla/venv/lib/python3.9/site-packages/keystone/api/projects.py", line 107, in _get_project
2023-04-01 08:41:20.814 26 ERROR keystone.server.flask.application     project = PROVIDERS.resource_api.get_project(project_id)
2023-04-01 08:41:20.814 26 ERROR keystone.server.flask.application   File "/var/lib/kolla/venv/lib/python3.9/site-packages/keystone/common/manager.py", line 115, in wrapped
2023-04-01 08:41:20.814 26 ERROR keystone.server.flask.application     __ret_val = __f(*args, **kwargs)
2023-04-01 08:41:20.814 26 ERROR keystone.server.flask.application   File "/var/lib/kolla/venv/lib/python3.9/site-packages/decorator.py", line 232, in fun
2023-04-01 08:41:20.814 26 ERROR keystone.server.flask.application     return caller(func, *(extras + args), **kw)
2023-04-01 08:41:20.814 26 ERROR keystone.server.flask.application   File "/var/lib/kolla/venv/lib/python3.9/site-packages/dogpile/cache/region.py", line 1577, in get_or_create_for_user_func
2023-04-01 08:41:20.814 26 ERROR keystone.server.flask.application     return self.get_or_create(
2023-04-01 08:41:20.814 26 ERROR keystone.server.flask.application   File "/var/lib/kolla/venv/lib/python3.9/site-packages/dogpile/cache/region.py", line 1042, in get_or_create
2023-04-01 08:41:20.814 26 ERROR keystone.server.flask.application     with Lock(
2023-04-01 08:41:20.814 26 ERROR keystone.server.flask.application   File "/var/lib/kolla/venv/lib/python3.9/site-packages/dogpile/lock.py", line 185, in __enter__
2023-04-01 08:41:20.814 26 ERROR keystone.server.flask.application     return self._enter()
2023-04-01 08:41:20.814 26 ERROR keystone.server.flask.application   File "/var/lib/kolla/venv/lib/python3.9/site-packages/dogpile/lock.py", line 94, in _enter
2023-04-01 08:41:20.814 26 ERROR keystone.server.flask.application     generated = self._enter_create(value, createdtime)
2023-04-01 08:41:20.814 26 ERROR keystone.server.flask.application   File "/var/lib/kolla/venv/lib/python3.9/site-packages/dogpile/lock.py", line 178, in _enter_create
2023-04-01 08:41:20.814 26 ERROR keystone.server.flask.application     return self.creator()
2023-04-01 08:41:20.814 26 ERROR keystone.server.flask.application   File "/var/lib/kolla/venv/lib/python3.9/site-packages/dogpile/cache/region.py", line 995, in gen_value
2023-04-01 08:41:20.814 26 ERROR keystone.server.flask.application     created_value = creator(
2023-04-01 08:41:20.814 26 ERROR keystone.server.flask.application   File "/var/lib/kolla/venv/lib/python3.9/site-packages/keystone/resource/core.py", line 903, in get_project
2023-04-01 08:41:20.814 26 ERROR keystone.server.flask.application     return self.driver.get_project(project_id)
2023-04-01 08:41:20.814 26 ERROR keystone.server.flask.application   File "/var/lib/kolla/venv/lib/python3.9/site-packages/keystone/resource/backends/sql.py", line 49, in get_project
2023-04-01 08:41:20.814 26 ERROR keystone.server.flask.application     return self._get_project(session, project_id).to_dict()
2023-04-01 08:41:20.814 26 ERROR keystone.server.flask.application   File "/var/lib/kolla/venv/lib/python3.9/site-packages/keystone/resource/backends/sql.py", line 44, in _get_project
2023-04-01 08:41:20.814 26 ERROR keystone.server.flask.application     raise exception.ProjectNotFound(project_id=project_id)
2023-04-01 08:41:20.814 26 ERROR keystone.server.flask.application keystone.exception.ProjectNotFound: Could not find project: service.
2023-04-01 08:41:20.814 26 ERROR keystone.server.flask.application 
2023-04-01 08:41:34.562 28 ERROR keystone.server.flask.application [None req-21a2f0ab-0211-4139-9851-dcba4ad94eda 9e470207b35a4ed1b323ab95faad5f45 - - all default -] Could not find role: admin.: keystone.exception.RoleNotFound: Could not find role: admin.
2023-04-01 08:41:34.562 28 ERROR keystone.server.flask.application Traceback (most recent call last):
2023-04-01 08:41:34.562 28 ERROR keystone.server.flask.application   File "/var/lib/kolla/venv/lib/python3.9/site-packages/flask/app.py", line 1820, in full_dispatch_request
2023-04-01 08:41:34.562 28 ERROR keystone.server.flask.application     rv = self.dispatch_request()
2023-04-01 08:41:34.562 28 ERROR keystone.server.flask.application   File "/var/lib/kolla/venv/lib/python3.9/site-packages/flask/app.py", line 1796, in dispatch_request
2023-04-01 08:41:34.562 28 ERROR keystone.server.flask.application     return self.ensure_sync(self.view_functions[rule.endpoint])(**view_args)
2023-04-01 08:41:34.562 28 ERROR keystone.server.flask.application   File "/var/lib/kolla/venv/lib/python3.9/site-packages/flask_restful/__init__.py", line 467, in wrapper
2023-04-01 08:41:34.562 28 ERROR keystone.server.flask.application     resp = resource(*args, **kwargs)
2023-04-01 08:41:34.562 28 ERROR keystone.server.flask.application   File "/var/lib/kolla/venv/lib/python3.9/site-packages/flask/views.py", line 107, in view
2023-04-01 08:41:34.562 28 ERROR keystone.server.flask.application     return current_app.ensure_sync(self.dispatch_request)(**kwargs)
2023-04-01 08:41:34.562 28 ERROR keystone.server.flask.application   File "/var/lib/kolla/venv/lib/python3.9/site-packages/flask_restful/__init__.py", line 582, in dispatch_request
2023-04-01 08:41:34.562 28 ERROR keystone.server.flask.application     resp = meth(*args, **kwargs)
2023-04-01 08:41:34.562 28 ERROR keystone.server.flask.application   File "/var/lib/kolla/venv/lib/python3.9/site-packages/keystone/api/roles.py", line 50, in get
2023-04-01 08:41:34.562 28 ERROR keystone.server.flask.application     return self._get_role(role_id)
2023-04-01 08:41:34.562 28 ERROR keystone.server.flask.application   File "/var/lib/kolla/venv/lib/python3.9/site-packages/keystone/api/roles.py", line 70, in _get_role
2023-04-01 08:41:34.562 28 ERROR keystone.server.flask.application     ENFORCER.enforce_call(action='identity:get_role')
2023-04-01 08:41:34.562 28 ERROR keystone.server.flask.application   File "/var/lib/kolla/venv/lib/python3.9/site-packages/keystone/common/rbac_enforcer/enforcer.py", line 402, in enforce_call
2023-04-01 08:41:34.562 28 ERROR keystone.server.flask.application     policy_dict.update(cls._extract_member_target_data(
2023-04-01 08:41:34.562 28 ERROR keystone.server.flask.application   File "/var/lib/kolla/venv/lib/python3.9/site-packages/keystone/common/rbac_enforcer/enforcer.py", line 234, in _extract_member_target_data
2023-04-01 08:41:34.562 28 ERROR keystone.server.flask.application     member_name: func(flask.request.view_args[key])
2023-04-01 08:41:34.562 28 ERROR keystone.server.flask.application   File "/var/lib/kolla/venv/lib/python3.9/site-packages/keystone/common/manager.py", line 115, in wrapped
2023-04-01 08:41:34.562 28 ERROR keystone.server.flask.application     __ret_val = __f(*args, **kwargs)
2023-04-01 08:41:34.562 28 ERROR keystone.server.flask.application   File "/var/lib/kolla/venv/lib/python3.9/site-packages/decorator.py", line 232, in fun
2023-04-01 08:41:34.562 28 ERROR keystone.server.flask.application     return caller(func, *(extras + args), **kw)
2023-04-01 08:41:34.562 28 ERROR keystone.server.flask.application   File "/var/lib/kolla/venv/lib/python3.9/site-packages/dogpile/cache/region.py", line 1577, in get_or_create_for_user_func
2023-04-01 08:41:34.562 28 ERROR keystone.server.flask.application     return self.get_or_create(
2023-04-01 08:41:34.562 28 ERROR keystone.server.flask.application   File "/var/lib/kolla/venv/lib/python3.9/site-packages/dogpile/cache/region.py", line 1042, in get_or_create
2023-04-01 08:41:34.562 28 ERROR keystone.server.flask.application     with Lock(
2023-04-01 08:41:34.562 28 ERROR keystone.server.flask.application   File "/var/lib/kolla/venv/lib/python3.9/site-packages/dogpile/lock.py", line 185, in __enter__
2023-04-01 08:41:34.562 28 ERROR keystone.server.flask.application     return self._enter()
2023-04-01 08:41:34.562 28 ERROR keystone.server.flask.application   File "/var/lib/kolla/venv/lib/python3.9/site-packages/dogpile/lock.py", line 94, in _enter
2023-04-01 08:41:34.562 28 ERROR keystone.server.flask.application     generated = self._enter_create(value, createdtime)
2023-04-01 08:41:34.562 28 ERROR keystone.server.flask.application   File "/var/lib/kolla/venv/lib/python3.9/site-packages/dogpile/lock.py", line 178, in _enter_create
2023-04-01 08:41:34.562 28 ERROR keystone.server.flask.application     return self.creator()
2023-04-01 08:41:34.562 28 ERROR keystone.server.flask.application   File "/var/lib/kolla/venv/lib/python3.9/site-packages/dogpile/cache/region.py", line 995, in gen_value
2023-04-01 08:41:34.562 28 ERROR keystone.server.flask.application     created_value = creator(
2023-04-01 08:41:34.562 28 ERROR keystone.server.flask.application   File "/var/lib/kolla/venv/lib/python3.9/site-packages/keystone/assignment/core.py", line 1276, in get_role
2023-04-01 08:41:34.562 28 ERROR keystone.server.flask.application     return self.driver.get_role(role_id)
2023-04-01 08:41:34.562 28 ERROR keystone.server.flask.application   File "/var/lib/kolla/venv/lib/python3.9/site-packages/keystone/assignment/role_backends/sql.py", line 70, in get_role
2023-04-01 08:41:34.562 28 ERROR keystone.server.flask.application     return self._get_role(session, role_id).to_dict()
2023-04-01 08:41:34.562 28 ERROR keystone.server.flask.application   File "/var/lib/kolla/venv/lib/python3.9/site-packages/keystone/assignment/role_backends/sql.py", line 65, in _get_role
2023-04-01 08:41:34.562 28 ERROR keystone.server.flask.application     raise exception.RoleNotFound(role_id=role_id)
2023-04-01 08:41:34.562 28 ERROR keystone.server.flask.application keystone.exception.RoleNotFound: Could not find role: admin.
2023-04-01 08:41:34.562 28 ERROR keystone.server.flask.application 
2023-04-01 08:41:35.621 28 ERROR keystone.server.flask.application [None req-5afd856d-b298-4377-9c79-c3aa5ead5086 9e470207b35a4ed1b323ab95faad5f45 - - all default -] Could not find user: neutron.: keystone.exception.UserNotFound: Could not find user: neutron.
2023-04-01 08:41:35.621 28 ERROR keystone.server.flask.application Traceback (most recent call last):
2023-04-01 08:41:35.621 28 ERROR keystone.server.flask.application   File "/var/lib/kolla/venv/lib/python3.9/site-packages/flask/app.py", line 1820, in full_dispatch_request
2023-04-01 08:41:35.621 28 ERROR keystone.server.flask.application     rv = self.dispatch_request()
2023-04-01 08:41:35.621 28 ERROR keystone.server.flask.application   File "/var/lib/kolla/venv/lib/python3.9/site-packages/flask/app.py", line 1796, in dispatch_request
2023-04-01 08:41:35.621 28 ERROR keystone.server.flask.application     return self.ensure_sync(self.view_functions[rule.endpoint])(**view_args)
2023-04-01 08:41:35.621 28 ERROR keystone.server.flask.application   File "/var/lib/kolla/venv/lib/python3.9/site-packages/flask_restful/__init__.py", line 467, in wrapper
2023-04-01 08:41:35.621 28 ERROR keystone.server.flask.application     resp = resource(*args, **kwargs)
2023-04-01 08:41:35.621 28 ERROR keystone.server.flask.application   File "/var/lib/kolla/venv/lib/python3.9/site-packages/flask/views.py", line 107, in view
2023-04-01 08:41:35.621 28 ERROR keystone.server.flask.application     return current_app.ensure_sync(self.dispatch_request)(**kwargs)
2023-04-01 08:41:35.621 28 ERROR keystone.server.flask.application   File "/var/lib/kolla/venv/lib/python3.9/site-packages/flask_restful/__init__.py", line 582, in dispatch_request
2023-04-01 08:41:35.621 28 ERROR keystone.server.flask.application     resp = meth(*args, **kwargs)
2023-04-01 08:41:35.621 28 ERROR keystone.server.flask.application   File "/var/lib/kolla/venv/lib/python3.9/site-packages/keystone/api/users.py", line 182, in get
2023-04-01 08:41:35.621 28 ERROR keystone.server.flask.application     return self._get_user(user_id)
2023-04-01 08:41:35.621 28 ERROR keystone.server.flask.application   File "/var/lib/kolla/venv/lib/python3.9/site-packages/keystone/api/users.py", line 194, in _get_user
2023-04-01 08:41:35.621 28 ERROR keystone.server.flask.application     ref = PROVIDERS.identity_api.get_user(user_id)
2023-04-01 08:41:35.621 28 ERROR keystone.server.flask.application   File "/var/lib/kolla/venv/lib/python3.9/site-packages/keystone/common/manager.py", line 115, in wrapped
2023-04-01 08:41:35.621 28 ERROR keystone.server.flask.application     __ret_val = __f(*args, **kwargs)
2023-04-01 08:41:35.621 28 ERROR keystone.server.flask.application   File "/var/lib/kolla/venv/lib/python3.9/site-packages/keystone/identity/core.py", line 414, in wrapper
2023-04-01 08:41:35.621 28 ERROR keystone.server.flask.application     return f(self, *args, **kwargs)
2023-04-01 08:41:35.621 28 ERROR keystone.server.flask.application   File "/var/lib/kolla/venv/lib/python3.9/site-packages/keystone/identity/core.py", line 424, in wrapper
2023-04-01 08:41:35.621 28 ERROR keystone.server.flask.application     return f(self, *args, **kwargs)
2023-04-01 08:41:35.621 28 ERROR keystone.server.flask.application   File "/var/lib/kolla/venv/lib/python3.9/site-packages/decorator.py", line 232, in fun
2023-04-01 08:41:35.621 28 ERROR keystone.server.flask.application     return caller(func, *(extras + args), **kw)
2023-04-01 08:41:35.621 28 ERROR keystone.server.flask.application   File "/var/lib/kolla/venv/lib/python3.9/site-packages/dogpile/cache/region.py", line 1577, in get_or_create_for_user_func
2023-04-01 08:41:35.621 28 ERROR keystone.server.flask.application     return self.get_or_create(
2023-04-01 08:41:35.621 28 ERROR keystone.server.flask.application   File "/var/lib/kolla/venv/lib/python3.9/site-packages/dogpile/cache/region.py", line 1042, in get_or_create
2023-04-01 08:41:35.621 28 ERROR keystone.server.flask.application     with Lock(
2023-04-01 08:41:35.621 28 ERROR keystone.server.flask.application   File "/var/lib/kolla/venv/lib/python3.9/site-packages/dogpile/lock.py", line 185, in __enter__
2023-04-01 08:41:35.621 28 ERROR keystone.server.flask.application     return self._enter()
2023-04-01 08:41:35.621 28 ERROR keystone.server.flask.application   File "/var/lib/kolla/venv/lib/python3.9/site-packages/dogpile/lock.py", line 94, in _enter
2023-04-01 08:41:35.621 28 ERROR keystone.server.flask.application     generated = self._enter_create(value, createdtime)
2023-04-01 08:41:35.621 28 ERROR keystone.server.flask.application   File "/var/lib/kolla/venv/lib/python3.9/site-packages/dogpile/lock.py", line 178, in _enter_create
2023-04-01 08:41:35.621 28 ERROR keystone.server.flask.application     return self.creator()
2023-04-01 08:41:35.621 28 ERROR keystone.server.flask.application   File "/var/lib/kolla/venv/lib/python3.9/site-packages/dogpile/cache/region.py", line 995, in gen_value
2023-04-01 08:41:35.621 28 ERROR keystone.server.flask.application     created_value = creator(
2023-04-01 08:41:35.621 28 ERROR keystone.server.flask.application   File "/var/lib/kolla/venv/lib/python3.9/site-packages/keystone/identity/core.py", line 1011, in get_user
2023-04-01 08:41:35.621 28 ERROR keystone.server.flask.application     ref = driver.get_user(entity_id)
2023-04-01 08:41:35.621 28 ERROR keystone.server.flask.application   File "/var/lib/kolla/venv/lib/python3.9/site-packages/keystone/identity/backends/sql.py", line 200, in get_user
2023-04-01 08:41:35.621 28 ERROR keystone.server.flask.application     self._get_user(session, user_id).to_dict())
2023-04-01 08:41:35.621 28 ERROR keystone.server.flask.application   File "/var/lib/kolla/venv/lib/python3.9/site-packages/keystone/identity/backends/sql.py", line 194, in _get_user
2023-04-01 08:41:35.621 28 ERROR keystone.server.flask.application     raise exception.UserNotFound(user_id=user_id)
2023-04-01 08:41:35.621 28 ERROR keystone.server.flask.application keystone.exception.UserNotFound: Could not find user: neutron.
2023-04-01 08:41:35.621 28 ERROR keystone.server.flask.application 
2023-04-01 08:41:36.318 27 ERROR keystone.server.flask.application [None req-306087db-4785-4927-938a-53bbfb3d4bd3 9e470207b35a4ed1b323ab95faad5f45 - - all default -] Could not find project: service.: keystone.exception.ProjectNotFound: Could not find project: service.
2023-04-01 08:41:36.318 27 ERROR keystone.server.flask.application Traceback (most recent call last):
2023-04-01 08:41:36.318 27 ERROR keystone.server.flask.application   File "/var/lib/kolla/venv/lib/python3.9/site-packages/flask/app.py", line 1820, in full_dispatch_request
2023-04-01 08:41:36.318 27 ERROR keystone.server.flask.application     rv = self.dispatch_request()
2023-04-01 08:41:36.318 27 ERROR keystone.server.flask.application   File "/var/lib/kolla/venv/lib/python3.9/site-packages/flask/app.py", line 1796, in dispatch_request
2023-04-01 08:41:36.318 27 ERROR keystone.server.flask.application     return self.ensure_sync(self.view_functions[rule.endpoint])(**view_args)
2023-04-01 08:41:36.318 27 ERROR keystone.server.flask.application   File "/var/lib/kolla/venv/lib/python3.9/site-packages/flask_restful/__init__.py", line 467, in wrapper
2023-04-01 08:41:36.318 27 ERROR keystone.server.flask.application     resp = resource(*args, **kwargs)
2023-04-01 08:41:36.318 27 ERROR keystone.server.flask.application   File "/var/lib/kolla/venv/lib/python3.9/site-packages/flask/views.py", line 107, in view
2023-04-01 08:41:36.318 27 ERROR keystone.server.flask.application     return current_app.ensure_sync(self.dispatch_request)(**kwargs)
2023-04-01 08:41:36.318 27 ERROR keystone.server.flask.application   File "/var/lib/kolla/venv/lib/python3.9/site-packages/flask_restful/__init__.py", line 582, in dispatch_request
2023-04-01 08:41:36.318 27 ERROR keystone.server.flask.application     resp = meth(*args, **kwargs)
2023-04-01 08:41:36.318 27 ERROR keystone.server.flask.application   File "/var/lib/kolla/venv/lib/python3.9/site-packages/keystone/api/projects.py", line 151, in get
2023-04-01 08:41:36.318 27 ERROR keystone.server.flask.application     return self._get_project(project_id)
2023-04-01 08:41:36.318 27 ERROR keystone.server.flask.application   File "/var/lib/kolla/venv/lib/python3.9/site-packages/keystone/api/projects.py", line 107, in _get_project
2023-04-01 08:41:36.318 27 ERROR keystone.server.flask.application     project = PROVIDERS.resource_api.get_project(project_id)
2023-04-01 08:41:36.318 27 ERROR keystone.server.flask.application   File "/var/lib/kolla/venv/lib/python3.9/site-packages/keystone/common/manager.py", line 115, in wrapped
2023-04-01 08:41:36.318 27 ERROR keystone.server.flask.application     __ret_val = __f(*args, **kwargs)
2023-04-01 08:41:36.318 27 ERROR keystone.server.flask.application   File "/var/lib/kolla/venv/lib/python3.9/site-packages/decorator.py", line 232, in fun
2023-04-01 08:41:36.318 27 ERROR keystone.server.flask.application     return caller(func, *(extras + args), **kw)
2023-04-01 08:41:36.318 27 ERROR keystone.server.flask.application   File "/var/lib/kolla/venv/lib/python3.9/site-packages/dogpile/cache/region.py", line 1577, in get_or_create_for_user_func
2023-04-01 08:41:36.318 27 ERROR keystone.server.flask.application     return self.get_or_create(
2023-04-01 08:41:36.318 27 ERROR keystone.server.flask.application   File "/var/lib/kolla/venv/lib/python3.9/site-packages/dogpile/cache/region.py", line 1042, in get_or_create
2023-04-01 08:41:36.318 27 ERROR keystone.server.flask.application     with Lock(
2023-04-01 08:41:36.318 27 ERROR keystone.server.flask.application   File "/var/lib/kolla/venv/lib/python3.9/site-packages/dogpile/lock.py", line 185, in __enter__
2023-04-01 08:41:36.318 27 ERROR keystone.server.flask.application     return self._enter()
2023-04-01 08:41:36.318 27 ERROR keystone.server.flask.application   File "/var/lib/kolla/venv/lib/python3.9/site-packages/dogpile/lock.py", line 94, in _enter
2023-04-01 08:41:36.318 27 ERROR keystone.server.flask.application     generated = self._enter_create(value, createdtime)
2023-04-01 08:41:36.318 27 ERROR keystone.server.flask.application   File "/var/lib/kolla/venv/lib/python3.9/site-packages/dogpile/lock.py", line 178, in _enter_create
2023-04-01 08:41:36.318 27 ERROR keystone.server.flask.application     return self.creator()
2023-04-01 08:41:36.318 27 ERROR keystone.server.flask.application   File "/var/lib/kolla/venv/lib/python3.9/site-packages/dogpile/cache/region.py", line 995, in gen_value
2023-04-01 08:41:36.318 27 ERROR keystone.server.flask.application     created_value = creator(
2023-04-01 08:41:36.318 27 ERROR keystone.server.flask.application   File "/var/lib/kolla/venv/lib/python3.9/site-packages/keystone/resource/core.py", line 903, in get_project
2023-04-01 08:41:36.318 27 ERROR keystone.server.flask.application     return self.driver.get_project(project_id)
2023-04-01 08:41:36.318 27 ERROR keystone.server.flask.application   File "/var/lib/kolla/venv/lib/python3.9/site-packages/keystone/resource/backends/sql.py", line 49, in get_project
2023-04-01 08:41:36.318 27 ERROR keystone.server.flask.application     return self._get_project(session, project_id).to_dict()
2023-04-01 08:41:36.318 27 ERROR keystone.server.flask.application   File "/var/lib/kolla/venv/lib/python3.9/site-packages/keystone/resource/backends/sql.py", line 44, in _get_project
2023-04-01 08:41:36.318 27 ERROR keystone.server.flask.application     raise exception.ProjectNotFound(project_id=project_id)
2023-04-01 08:41:36.318 27 ERROR keystone.server.flask.application keystone.exception.ProjectNotFound: Could not find project: service.
2023-04-01 08:41:36.318 27 ERROR keystone.server.flask.application 
