2023-03-15 00:15:35.577764 2023-03-15 00:15:35.575 37 WARNING keystone.common.rbac_enforcer.enforcer [None req-c1903bff-81f4-42e9-a4f6-a42a80af0dea 1e917c8eefa1409693db319fb971e603 - - all default -] Deprecated policy rules found. Use oslopolicy-policy-generator and oslopolicy-policy-upgrade to detect and resolve deprecated policies in your configuration.\x1b[00m
2023-03-15 00:15:36.396378 2023-03-15 00:15:36.394 38 WARNING keystone.common.rbac_enforcer.enforcer [None req-4ef22afc-75fa-439c-973b-fa4d7aab7d95 1e917c8eefa1409693db319fb971e603 - - all default -] Deprecated policy rules found. Use oslopolicy-policy-generator and oslopolicy-policy-upgrade to detect and resolve deprecated policies in your configuration.\x1b[00m
2023-03-15 00:15:44.337393 2023-03-15 00:15:44.335 39 WARNING keystone.common.rbac_enforcer.enforcer [None req-5bdb04b5-0965-4cfc-9acd-ec86a59ce50b 1e917c8eefa1409693db319fb971e603 - - all default -] Deprecated policy rules found. Use oslopolicy-policy-generator and oslopolicy-policy-upgrade to detect and resolve deprecated policies in your configuration.\x1b[00m
2023-03-15 00:17:04.461082 2023-03-15 00:17:04.180 37 ERROR keystone.server.flask.application [None req-b2f02b9e-ba69-4b2a-ad96-655ebcfecdab 1e917c8eefa1409693db319fb971e603 - - all default -] Could not find project: service.: keystone.exception.ProjectNotFound: Could not find project: service.
2023-03-15 00:17:04.461148 2023-03-15 00:17:04.180 37 ERROR keystone.server.flask.application Traceback (most recent call last):
2023-03-15 00:17:04.461163 2023-03-15 00:17:04.180 37 ERROR keystone.server.flask.application   File "/var/lib/kolla/venv/lib/python3.9/site-packages/flask/app.py", line 1820, in full_dispatch_request
2023-03-15 00:17:04.461174 2023-03-15 00:17:04.180 37 ERROR keystone.server.flask.application     rv = self.dispatch_request()
2023-03-15 00:17:04.461185 2023-03-15 00:17:04.180 37 ERROR keystone.server.flask.application   File "/var/lib/kolla/venv/lib/python3.9/site-packages/flask/app.py", line 1796, in dispatch_request
2023-03-15 00:17:04.461207 2023-03-15 00:17:04.180 37 ERROR keystone.server.flask.application     return self.ensure_sync(self.view_functions[rule.endpoint])(**view_args)
2023-03-15 00:17:04.461218 2023-03-15 00:17:04.180 37 ERROR keystone.server.flask.application   File "/var/lib/kolla/venv/lib/python3.9/site-packages/flask_restful/__init__.py", line 467, in wrapper
2023-03-15 00:17:04.461229 2023-03-15 00:17:04.180 37 ERROR keystone.server.flask.application     resp = resource(*args, **kwargs)
2023-03-15 00:17:04.461240 2023-03-15 00:17:04.180 37 ERROR keystone.server.flask.application   File "/var/lib/kolla/venv/lib/python3.9/site-packages/flask/views.py", line 107, in view
2023-03-15 00:17:04.461251 2023-03-15 00:17:04.180 37 ERROR keystone.server.flask.application     return current_app.ensure_sync(self.dispatch_request)(**kwargs)
2023-03-15 00:17:04.461261 2023-03-15 00:17:04.180 37 ERROR keystone.server.flask.application   File "/var/lib/kolla/venv/lib/python3.9/site-packages/flask_restful/__init__.py", line 582, in dispatch_request
2023-03-15 00:17:04.461272 2023-03-15 00:17:04.180 37 ERROR keystone.server.flask.application     resp = meth(*args, **kwargs)
2023-03-15 00:17:04.461282 2023-03-15 00:17:04.180 37 ERROR keystone.server.flask.application   File "/var/lib/kolla/venv/lib/python3.9/site-packages/keystone/api/projects.py", line 151, in get
2023-03-15 00:17:04.461293 2023-03-15 00:17:04.180 37 ERROR keystone.server.flask.application     return self._get_project(project_id)
2023-03-15 00:17:04.461304 2023-03-15 00:17:04.180 37 ERROR keystone.server.flask.application   File "/var/lib/kolla/venv/lib/python3.9/site-packages/keystone/api/projects.py", line 107, in _get_project
2023-03-15 00:17:04.461314 2023-03-15 00:17:04.180 37 ERROR keystone.server.flask.application     project = PROVIDERS.resource_api.get_project(project_id)
2023-03-15 00:17:04.461325 2023-03-15 00:17:04.180 37 ERROR keystone.server.flask.application   File "/var/lib/kolla/venv/lib/python3.9/site-packages/keystone/common/manager.py", line 115, in wrapped
2023-03-15 00:17:04.461405 2023-03-15 00:17:04.180 37 ERROR keystone.server.flask.application     __ret_val = __f(*args, **kwargs)
2023-03-15 00:17:04.461421 2023-03-15 00:17:04.180 37 ERROR keystone.server.flask.application   File "/var/lib/kolla/venv/lib/python3.9/site-packages/decorator.py", line 232, in fun
2023-03-15 00:17:04.461432 2023-03-15 00:17:04.180 37 ERROR keystone.server.flask.application     return caller(func, *(extras + args), **kw)
2023-03-15 00:17:04.461442 2023-03-15 00:17:04.180 37 ERROR keystone.server.flask.application   File "/var/lib/kolla/venv/lib/python3.9/site-packages/dogpile/cache/region.py", line 1577, in get_or_create_for_user_func
2023-03-15 00:17:04.461453 2023-03-15 00:17:04.180 37 ERROR keystone.server.flask.application     return self.get_or_create(
2023-03-15 00:17:04.461464 2023-03-15 00:17:04.180 37 ERROR keystone.server.flask.application   File "/var/lib/kolla/venv/lib/python3.9/site-packages/dogpile/cache/region.py", line 1042, in get_or_create
2023-03-15 00:17:04.461475 2023-03-15 00:17:04.180 37 ERROR keystone.server.flask.application     with Lock(
2023-03-15 00:17:04.461485 2023-03-15 00:17:04.180 37 ERROR keystone.server.flask.application   File "/var/lib/kolla/venv/lib/python3.9/site-packages/dogpile/lock.py", line 185, in __enter__
2023-03-15 00:17:04.461496 2023-03-15 00:17:04.180 37 ERROR keystone.server.flask.application     return self._enter()
2023-03-15 00:17:04.461506 2023-03-15 00:17:04.180 37 ERROR keystone.server.flask.application   File "/var/lib/kolla/venv/lib/python3.9/site-packages/dogpile/lock.py", line 94, in _enter
2023-03-15 00:17:04.461517 2023-03-15 00:17:04.180 37 ERROR keystone.server.flask.application     generated = self._enter_create(value, createdtime)
2023-03-15 00:17:04.461528 2023-03-15 00:17:04.180 37 ERROR keystone.server.flask.application   File "/var/lib/kolla/venv/lib/python3.9/site-packages/dogpile/lock.py", line 178, in _enter_create
2023-03-15 00:17:04.461538 2023-03-15 00:17:04.180 37 ERROR keystone.server.flask.application     return self.creator()
2023-03-15 00:17:04.461549 2023-03-15 00:17:04.180 37 ERROR keystone.server.flask.application   File "/var/lib/kolla/venv/lib/python3.9/site-packages/dogpile/cache/region.py", line 995, in gen_value
2023-03-15 00:17:04.461559 2023-03-15 00:17:04.180 37 ERROR keystone.server.flask.application     created_value = creator(
2023-03-15 00:17:04.461570 2023-03-15 00:17:04.180 37 ERROR keystone.server.flask.application   File "/var/lib/kolla/venv/lib/python3.9/site-packages/keystone/resource/core.py", line 903, in get_project
2023-03-15 00:17:04.461580 2023-03-15 00:17:04.180 37 ERROR keystone.server.flask.application     return self.driver.get_project(project_id)
2023-03-15 00:17:04.461591 2023-03-15 00:17:04.180 37 ERROR keystone.server.flask.application   File "/var/lib/kolla/venv/lib/python3.9/site-packages/keystone/resource/backends/sql.py", line 49, in get_project
2023-03-15 00:17:04.461602 2023-03-15 00:17:04.180 37 ERROR keystone.server.flask.application     return self._get_project(session, project_id).to_dict()
2023-03-15 00:17:04.461612 2023-03-15 00:17:04.180 37 ERROR keystone.server.flask.application   File "/var/lib/kolla/venv/lib/python3.9/site-packages/keystone/resource/backends/sql.py", line 44, in _get_project
2023-03-15 00:17:04.461623 2023-03-15 00:17:04.180 37 ERROR keystone.server.flask.application     raise exception.ProjectNotFound(project_id=project_id)
2023-03-15 00:17:04.461633 2023-03-15 00:17:04.180 37 ERROR keystone.server.flask.application keystone.exception.ProjectNotFound: Could not find project: service.
2023-03-15 00:17:04.461644 2023-03-15 00:17:04.180 37 ERROR keystone.server.flask.application \x1b[00m
2023-03-15 00:17:13.686312 2023-03-15 00:17:13.673 39 ERROR keystone.server.flask.application [None req-97111aa6-aef2-4db4-a110-888af8344aad 1e917c8eefa1409693db319fb971e603 - - all default -] Could not find project: service.: keystone.exception.ProjectNotFound: Could not find project: service.
2023-03-15 00:17:13.686387 2023-03-15 00:17:13.673 39 ERROR keystone.server.flask.application Traceback (most recent call last):
2023-03-15 00:17:13.686418 2023-03-15 00:17:13.673 39 ERROR keystone.server.flask.application   File "/var/lib/kolla/venv/lib/python3.9/site-packages/flask/app.py", line 1820, in full_dispatch_request
2023-03-15 00:17:13.686430 2023-03-15 00:17:13.673 39 ERROR keystone.server.flask.application     rv = self.dispatch_request()
2023-03-15 00:17:13.686440 2023-03-15 00:17:13.673 39 ERROR keystone.server.flask.application   File "/var/lib/kolla/venv/lib/python3.9/site-packages/flask/app.py", line 1796, in dispatch_request
2023-03-15 00:17:13.686450 2023-03-15 00:17:13.673 39 ERROR keystone.server.flask.application     return self.ensure_sync(self.view_functions[rule.endpoint])(**view_args)
2023-03-15 00:17:13.686460 2023-03-15 00:17:13.673 39 ERROR keystone.server.flask.application   File "/var/lib/kolla/venv/lib/python3.9/site-packages/flask_restful/__init__.py", line 467, in wrapper
2023-03-15 00:17:13.686470 2023-03-15 00:17:13.673 39 ERROR keystone.server.flask.application     resp = resource(*args, **kwargs)
2023-03-15 00:17:13.686488 2023-03-15 00:17:13.673 39 ERROR keystone.server.flask.application   File "/var/lib/kolla/venv/lib/python3.9/site-packages/flask/views.py", line 107, in view
2023-03-15 00:17:13.686501 2023-03-15 00:17:13.673 39 ERROR keystone.server.flask.application     return current_app.ensure_sync(self.dispatch_request)(**kwargs)
2023-03-15 00:17:13.686511 2023-03-15 00:17:13.673 39 ERROR keystone.server.flask.application   File "/var/lib/kolla/venv/lib/python3.9/site-packages/flask_restful/__init__.py", line 582, in dispatch_request
2023-03-15 00:17:13.686521 2023-03-15 00:17:13.673 39 ERROR keystone.server.flask.application     resp = meth(*args, **kwargs)
2023-03-15 00:17:13.686531 2023-03-15 00:17:13.673 39 ERROR keystone.server.flask.application   File "/var/lib/kolla/venv/lib/python3.9/site-packages/keystone/api/projects.py", line 151, in get
2023-03-15 00:17:13.686541 2023-03-15 00:17:13.673 39 ERROR keystone.server.flask.application     return self._get_project(project_id)
2023-03-15 00:17:13.686551 2023-03-15 00:17:13.673 39 ERROR keystone.server.flask.application   File "/var/lib/kolla/venv/lib/python3.9/site-packages/keystone/api/projects.py", line 107, in _get_project
2023-03-15 00:17:13.686560 2023-03-15 00:17:13.673 39 ERROR keystone.server.flask.application     project = PROVIDERS.resource_api.get_project(project_id)
2023-03-15 00:17:13.686570 2023-03-15 00:17:13.673 39 ERROR keystone.server.flask.application   File "/var/lib/kolla/venv/lib/python3.9/site-packages/keystone/common/manager.py", line 115, in wrapped
2023-03-15 00:17:13.686580 2023-03-15 00:17:13.673 39 ERROR keystone.server.flask.application     __ret_val = __f(*args, **kwargs)
2023-03-15 00:17:13.686589 2023-03-15 00:17:13.673 39 ERROR keystone.server.flask.application   File "/var/lib/kolla/venv/lib/python3.9/site-packages/decorator.py", line 232, in fun
2023-03-15 00:17:13.686599 2023-03-15 00:17:13.673 39 ERROR keystone.server.flask.application     return caller(func, *(extras + args), **kw)
2023-03-15 00:17:13.686612 2023-03-15 00:17:13.673 39 ERROR keystone.server.flask.application   File "/var/lib/kolla/venv/lib/python3.9/site-packages/dogpile/cache/region.py", line 1577, in get_or_create_for_user_func
2023-03-15 00:17:13.686622 2023-03-15 00:17:13.673 39 ERROR keystone.server.flask.application     return self.get_or_create(
2023-03-15 00:17:13.686631 2023-03-15 00:17:13.673 39 ERROR keystone.server.flask.application   File "/var/lib/kolla/venv/lib/python3.9/site-packages/dogpile/cache/region.py", line 1042, in get_or_create
2023-03-15 00:17:13.686642 2023-03-15 00:17:13.673 39 ERROR keystone.server.flask.application     with Lock(
2023-03-15 00:17:13.687470 2023-03-15 00:17:13.673 39 ERROR keystone.server.flask.application   File "/var/lib/kolla/venv/lib/python3.9/site-packages/dogpile/lock.py", line 185, in __enter__
2023-03-15 00:17:13.687482 2023-03-15 00:17:13.673 39 ERROR keystone.server.flask.application     return self._enter()
2023-03-15 00:17:13.687507 2023-03-15 00:17:13.673 39 ERROR keystone.server.flask.application   File "/var/lib/kolla/venv/lib/python3.9/site-packages/dogpile/lock.py", line 94, in _enter
2023-03-15 00:17:13.687518 2023-03-15 00:17:13.673 39 ERROR keystone.server.flask.application     generated = self._enter_create(value, createdtime)
2023-03-15 00:17:13.687528 2023-03-15 00:17:13.673 39 ERROR keystone.server.flask.application   File "/var/lib/kolla/venv/lib/python3.9/site-packages/dogpile/lock.py", line 178, in _enter_create
2023-03-15 00:17:13.687538 2023-03-15 00:17:13.673 39 ERROR keystone.server.flask.application     return self.creator()
2023-03-15 00:17:13.687548 2023-03-15 00:17:13.673 39 ERROR keystone.server.flask.application   File "/var/lib/kolla/venv/lib/python3.9/site-packages/dogpile/cache/region.py", line 995, in gen_value
2023-03-15 00:17:13.687558 2023-03-15 00:17:13.673 39 ERROR keystone.server.flask.application     created_value = creator(
2023-03-15 00:17:13.687567 2023-03-15 00:17:13.673 39 ERROR keystone.server.flask.application   File "/var/lib/kolla/venv/lib/python3.9/site-packages/keystone/resource/core.py", line 903, in get_project
2023-03-15 00:17:13.687577 2023-03-15 00:17:13.673 39 ERROR keystone.server.flask.application     return self.driver.get_project(project_id)
2023-03-15 00:17:13.687587 2023-03-15 00:17:13.673 39 ERROR keystone.server.flask.application   File "/var/lib/kolla/venv/lib/python3.9/site-packages/keystone/resource/backends/sql.py", line 49, in get_project
2023-03-15 00:17:13.687597 2023-03-15 00:17:13.673 39 ERROR keystone.server.flask.application     return self._get_project(session, project_id).to_dict()
2023-03-15 00:17:13.687607 2023-03-15 00:17:13.673 39 ERROR keystone.server.flask.application   File "/var/lib/kolla/venv/lib/python3.9/site-packages/keystone/resource/backends/sql.py", line 44, in _get_project
2023-03-15 00:17:13.687617 2023-03-15 00:17:13.673 39 ERROR keystone.server.flask.application     raise exception.ProjectNotFound(project_id=project_id)
2023-03-15 00:17:13.687626 2023-03-15 00:17:13.673 39 ERROR keystone.server.flask.application keystone.exception.ProjectNotFound: Could not find project: service.
2023-03-15 00:17:13.687636 2023-03-15 00:17:13.673 39 ERROR keystone.server.flask.application \x1b[00m
2023-03-15 00:17:28.847005 2023-03-15 00:17:28.839 39 ERROR keystone.server.flask.application [None req-e16f4c67-b134-4b63-9758-be66c0fb79f1 1e917c8eefa1409693db319fb971e603 - - all default -] Could not find role: admin.: keystone.exception.RoleNotFound: Could not find role: admin.
2023-03-15 00:17:28.847081 2023-03-15 00:17:28.839 39 ERROR keystone.server.flask.application Traceback (most recent call last):
2023-03-15 00:17:28.847095 2023-03-15 00:17:28.839 39 ERROR keystone.server.flask.application   File "/var/lib/kolla/venv/lib/python3.9/site-packages/flask/app.py", line 1820, in full_dispatch_request
2023-03-15 00:17:28.847107 2023-03-15 00:17:28.839 39 ERROR keystone.server.flask.application     rv = self.dispatch_request()
2023-03-15 00:17:28.847119 2023-03-15 00:17:28.839 39 ERROR keystone.server.flask.application   File "/var/lib/kolla/venv/lib/python3.9/site-packages/flask/app.py", line 1796, in dispatch_request
2023-03-15 00:17:28.847150 2023-03-15 00:17:28.839 39 ERROR keystone.server.flask.application     return self.ensure_sync(self.view_functions[rule.endpoint])(**view_args)
2023-03-15 00:17:28.847161 2023-03-15 00:17:28.839 39 ERROR keystone.server.flask.application   File "/var/lib/kolla/venv/lib/python3.9/site-packages/flask_restful/__init__.py", line 467, in wrapper
2023-03-15 00:17:28.847172 2023-03-15 00:17:28.839 39 ERROR keystone.server.flask.application     resp = resource(*args, **kwargs)
2023-03-15 00:17:28.847191 2023-03-15 00:17:28.839 39 ERROR keystone.server.flask.application   File "/var/lib/kolla/venv/lib/python3.9/site-packages/flask/views.py", line 107, in view
2023-03-15 00:17:28.847205 2023-03-15 00:17:28.839 39 ERROR keystone.server.flask.application     return current_app.ensure_sync(self.dispatch_request)(**kwargs)
2023-03-15 00:17:28.847217 2023-03-15 00:17:28.839 39 ERROR keystone.server.flask.application   File "/var/lib/kolla/venv/lib/python3.9/site-packages/flask_restful/__init__.py", line 582, in dispatch_request
2023-03-15 00:17:28.847253 2023-03-15 00:17:28.839 39 ERROR keystone.server.flask.application     resp = meth(*args, **kwargs)
2023-03-15 00:17:28.847266 2023-03-15 00:17:28.839 39 ERROR keystone.server.flask.application   File "/var/lib/kolla/venv/lib/python3.9/site-packages/keystone/api/roles.py", line 50, in get
2023-03-15 00:17:28.847282 2023-03-15 00:17:28.839 39 ERROR keystone.server.flask.application     return self._get_role(role_id)
2023-03-15 00:17:28.847293 2023-03-15 00:17:28.839 39 ERROR keystone.server.flask.application   File "/var/lib/kolla/venv/lib/python3.9/site-packages/keystone/api/roles.py", line 70, in _get_role
2023-03-15 00:17:28.847305 2023-03-15 00:17:28.839 39 ERROR keystone.server.flask.application     ENFORCER.enforce_call(action='identity:get_role')
2023-03-15 00:17:28.847316 2023-03-15 00:17:28.839 39 ERROR keystone.server.flask.application   File "/var/lib/kolla/venv/lib/python3.9/site-packages/keystone/common/rbac_enforcer/enforcer.py", line 402, in enforce_call
2023-03-15 00:17:28.847328 2023-03-15 00:17:28.839 39 ERROR keystone.server.flask.application     policy_dict.update(cls._extract_member_target_data(
2023-03-15 00:17:28.847364 2023-03-15 00:17:28.839 39 ERROR keystone.server.flask.application   File "/var/lib/kolla/venv/lib/python3.9/site-packages/keystone/common/rbac_enforcer/enforcer.py", line 234, in _extract_member_target_data
2023-03-15 00:17:28.847381 2023-03-15 00:17:28.839 39 ERROR keystone.server.flask.application     member_name: func(flask.request.view_args[key])
2023-03-15 00:17:28.847392 2023-03-15 00:17:28.839 39 ERROR keystone.server.flask.application   File "/var/lib/kolla/venv/lib/python3.9/site-packages/keystone/common/manager.py", line 115, in wrapped
2023-03-15 00:17:28.847403 2023-03-15 00:17:28.839 39 ERROR keystone.server.flask.application     __ret_val = __f(*args, **kwargs)
2023-03-15 00:17:28.847414 2023-03-15 00:17:28.839 39 ERROR keystone.server.flask.application   File "/var/lib/kolla/venv/lib/python3.9/site-packages/decorator.py", line 232, in fun
2023-03-15 00:17:28.847425 2023-03-15 00:17:28.839 39 ERROR keystone.server.flask.application     return caller(func, *(extras + args), **kw)
2023-03-15 00:17:28.847440 2023-03-15 00:17:28.839 39 ERROR keystone.server.flask.application   File "/var/lib/kolla/venv/lib/python3.9/site-packages/dogpile/cache/region.py", line 1577, in get_or_create_for_user_func
2023-03-15 00:17:28.847452 2023-03-15 00:17:28.839 39 ERROR keystone.server.flask.application     return self.get_or_create(
2023-03-15 00:17:28.847462 2023-03-15 00:17:28.839 39 ERROR keystone.server.flask.application   File "/var/lib/kolla/venv/lib/python3.9/site-packages/dogpile/cache/region.py", line 1042, in get_or_create
2023-03-15 00:17:28.847474 2023-03-15 00:17:28.839 39 ERROR keystone.server.flask.application     with Lock(
2023-03-15 00:17:28.847485 2023-03-15 00:17:28.839 39 ERROR keystone.server.flask.application   File "/var/lib/kolla/venv/lib/python3.9/site-packages/dogpile/lock.py", line 185, in __enter__
2023-03-15 00:17:28.847499 2023-03-15 00:17:28.839 39 ERROR keystone.server.flask.application     return self._enter()
2023-03-15 00:17:28.847520 2023-03-15 00:17:28.839 39 ERROR keystone.server.flask.application   File "/var/lib/kolla/venv/lib/python3.9/site-packages/dogpile/lock.py", line 94, in _enter
2023-03-15 00:17:28.847542 2023-03-15 00:17:28.839 39 ERROR keystone.server.flask.application     generated = self._enter_create(value, createdtime)
2023-03-15 00:17:28.847564 2023-03-15 00:17:28.839 39 ERROR keystone.server.flask.application   File "/var/lib/kolla/venv/lib/python3.9/site-packages/dogpile/lock.py", line 178, in _enter_create
2023-03-15 00:17:28.847587 2023-03-15 00:17:28.839 39 ERROR keystone.server.flask.application     return self.creator()
2023-03-15 00:17:28.847609 2023-03-15 00:17:28.839 39 ERROR keystone.server.flask.application   File "/var/lib/kolla/venv/lib/python3.9/site-packages/dogpile/cache/region.py", line 995, in gen_value
2023-03-15 00:17:28.847649 2023-03-15 00:17:28.839 39 ERROR keystone.server.flask.application     created_value = creator(
2023-03-15 00:17:28.847663 2023-03-15 00:17:28.839 39 ERROR keystone.server.flask.application   File "/var/lib/kolla/venv/lib/python3.9/site-packages/keystone/assignment/core.py", line 1276, in get_role
2023-03-15 00:17:28.847675 2023-03-15 00:17:28.839 39 ERROR keystone.server.flask.application     return self.driver.get_role(role_id)
2023-03-15 00:17:28.847686 2023-03-15 00:17:28.839 39 ERROR keystone.server.flask.application   File "/var/lib/kolla/venv/lib/python3.9/site-packages/keystone/assignment/role_backends/sql.py", line 70, in get_role
2023-03-15 00:17:28.847698 2023-03-15 00:17:28.839 39 ERROR keystone.server.flask.application     return self._get_role(session, role_id).to_dict()
2023-03-15 00:17:28.847709 2023-03-15 00:17:28.839 39 ERROR keystone.server.flask.application   File "/var/lib/kolla/venv/lib/python3.9/site-packages/keystone/assignment/role_backends/sql.py", line 65, in _get_role
2023-03-15 00:17:28.847720 2023-03-15 00:17:28.839 39 ERROR keystone.server.flask.application     raise exception.RoleNotFound(role_id=role_id)
2023-03-15 00:17:28.847732 2023-03-15 00:17:28.839 39 ERROR keystone.server.flask.application keystone.exception.RoleNotFound: Could not find role: admin.
2023-03-15 00:17:28.847744 2023-03-15 00:17:28.839 39 ERROR keystone.server.flask.application \x1b[00m
2023-03-15 00:17:30.152986 2023-03-15 00:17:30.146 39 ERROR keystone.server.flask.application [None req-e8517281-8cfd-42c7-97ab-faece476d9e2 1e917c8eefa1409693db319fb971e603 - - all default -] Could not find user: ironic.: keystone.exception.UserNotFound: Could not find user: ironic.
2023-03-15 00:17:30.153027 2023-03-15 00:17:30.146 39 ERROR keystone.server.flask.application Traceback (most recent call last):
2023-03-15 00:17:30.153042 2023-03-15 00:17:30.146 39 ERROR keystone.server.flask.application   File "/var/lib/kolla/venv/lib/python3.9/site-packages/flask/app.py", line 1820, in full_dispatch_request
2023-03-15 00:17:30.153052 2023-03-15 00:17:30.146 39 ERROR keystone.server.flask.application     rv = self.dispatch_request()
2023-03-15 00:17:30.153062 2023-03-15 00:17:30.146 39 ERROR keystone.server.flask.application   File "/var/lib/kolla/venv/lib/python3.9/site-packages/flask/app.py", line 1796, in dispatch_request
2023-03-15 00:17:30.153072 2023-03-15 00:17:30.146 39 ERROR keystone.server.flask.application     return self.ensure_sync(self.view_functions[rule.endpoint])(**view_args)
2023-03-15 00:17:30.153082 2023-03-15 00:17:30.146 39 ERROR keystone.server.flask.application   File "/var/lib/kolla/venv/lib/python3.9/site-packages/flask_restful/__init__.py", line 467, in wrapper
2023-03-15 00:17:30.153092 2023-03-15 00:17:30.146 39 ERROR keystone.server.flask.application     resp = resource(*args, **kwargs)
2023-03-15 00:17:30.153102 2023-03-15 00:17:30.146 39 ERROR keystone.server.flask.application   File "/var/lib/kolla/venv/lib/python3.9/site-packages/flask/views.py", line 107, in view
2023-03-15 00:17:30.153112 2023-03-15 00:17:30.146 39 ERROR keystone.server.flask.application     return current_app.ensure_sync(self.dispatch_request)(**kwargs)
2023-03-15 00:17:30.153122 2023-03-15 00:17:30.146 39 ERROR keystone.server.flask.application   File "/var/lib/kolla/venv/lib/python3.9/site-packages/flask_restful/__init__.py", line 582, in dispatch_request
2023-03-15 00:17:30.153132 2023-03-15 00:17:30.146 39 ERROR keystone.server.flask.application     resp = meth(*args, **kwargs)
2023-03-15 00:17:30.153142 2023-03-15 00:17:30.146 39 ERROR keystone.server.flask.application   File "/var/lib/kolla/venv/lib/python3.9/site-packages/keystone/api/users.py", line 182, in get
2023-03-15 00:17:30.153151 2023-03-15 00:17:30.146 39 ERROR keystone.server.flask.application     return self._get_user(user_id)
2023-03-15 00:17:30.153161 2023-03-15 00:17:30.146 39 ERROR keystone.server.flask.application   File "/var/lib/kolla/venv/lib/python3.9/site-packages/keystone/api/users.py", line 194, in _get_user
2023-03-15 00:17:30.153224 2023-03-15 00:17:30.146 39 ERROR keystone.server.flask.application     ref = PROVIDERS.identity_api.get_user(user_id)
2023-03-15 00:17:30.153236 2023-03-15 00:17:30.146 39 ERROR keystone.server.flask.application   File "/var/lib/kolla/venv/lib/python3.9/site-packages/keystone/common/manager.py", line 115, in wrapped
2023-03-15 00:17:30.153246 2023-03-15 00:17:30.146 39 ERROR keystone.server.flask.application     __ret_val = __f(*args, **kwargs)
2023-03-15 00:17:30.153255 2023-03-15 00:17:30.146 39 ERROR keystone.server.flask.application   File "/var/lib/kolla/venv/lib/python3.9/site-packages/keystone/identity/core.py", line 414, in wrapper
2023-03-15 00:17:30.153265 2023-03-15 00:17:30.146 39 ERROR keystone.server.flask.application     return f(self, *args, **kwargs)
2023-03-15 00:17:30.153277 2023-03-15 00:17:30.146 39 ERROR keystone.server.flask.application   File "/var/lib/kolla/venv/lib/python3.9/site-packages/keystone/identity/core.py", line 424, in wrapper
2023-03-15 00:17:30.153295 2023-03-15 00:17:30.146 39 ERROR keystone.server.flask.application     return f(self, *args, **kwargs)
2023-03-15 00:17:30.153316 2023-03-15 00:17:30.146 39 ERROR keystone.server.flask.application   File "/var/lib/kolla/venv/lib/python3.9/site-packages/decorator.py", line 232, in fun
2023-03-15 00:17:30.153370 2023-03-15 00:17:30.146 39 ERROR keystone.server.flask.application     return caller(func, *(extras + args), **kw)
2023-03-15 00:17:30.153397 2023-03-15 00:17:30.146 39 ERROR keystone.server.flask.application   File "/var/lib/kolla/venv/lib/python3.9/site-packages/dogpile/cache/region.py", line 1577, in get_or_create_for_user_func
2023-03-15 00:17:30.153421 2023-03-15 00:17:30.146 39 ERROR keystone.server.flask.application     return self.get_or_create(
2023-03-15 00:17:30.153460 2023-03-15 00:17:30.146 39 ERROR keystone.server.flask.application   File "/var/lib/kolla/venv/lib/python3.9/site-packages/dogpile/cache/region.py", line 1042, in get_or_create
2023-03-15 00:17:30.153483 2023-03-15 00:17:30.146 39 ERROR keystone.server.flask.application     with Lock(
2023-03-15 00:17:30.153505 2023-03-15 00:17:30.146 39 ERROR keystone.server.flask.application   File "/var/lib/kolla/venv/lib/python3.9/site-packages/dogpile/lock.py", line 185, in __enter__
2023-03-15 00:17:30.153527 2023-03-15 00:17:30.146 39 ERROR keystone.server.flask.application     return self._enter()
2023-03-15 00:17:30.153546 2023-03-15 00:17:30.146 39 ERROR keystone.server.flask.application   File "/var/lib/kolla/venv/lib/python3.9/site-packages/dogpile/lock.py", line 94, in _enter
2023-03-15 00:17:30.153567 2023-03-15 00:17:30.146 39 ERROR keystone.server.flask.application     generated = self._enter_create(value, createdtime)
2023-03-15 00:17:30.153589 2023-03-15 00:17:30.146 39 ERROR keystone.server.flask.application   File "/var/lib/kolla/venv/lib/python3.9/site-packages/dogpile/lock.py", line 178, in _enter_create
2023-03-15 00:17:30.153632 2023-03-15 00:17:30.146 39 ERROR keystone.server.flask.application     return self.creator()
2023-03-15 00:17:30.153650 2023-03-15 00:17:30.146 39 ERROR keystone.server.flask.application   File "/var/lib/kolla/venv/lib/python3.9/site-packages/dogpile/cache/region.py", line 995, in gen_value
2023-03-15 00:17:30.153669 2023-03-15 00:17:30.146 39 ERROR keystone.server.flask.application     created_value = creator(
2023-03-15 00:17:30.153680 2023-03-15 00:17:30.146 39 ERROR keystone.server.flask.application   File "/var/lib/kolla/venv/lib/python3.9/site-packages/keystone/identity/core.py", line 1011, in get_user
2023-03-15 00:17:30.153690 2023-03-15 00:17:30.146 39 ERROR keystone.server.flask.application     ref = driver.get_user(entity_id)
2023-03-15 00:17:30.153700 2023-03-15 00:17:30.146 39 ERROR keystone.server.flask.application   File "/var/lib/kolla/venv/lib/python3.9/site-packages/keystone/identity/backends/sql.py", line 200, in get_user
2023-03-15 00:17:30.153710 2023-03-15 00:17:30.146 39 ERROR keystone.server.flask.application     self._get_user(session, user_id).to_dict())
2023-03-15 00:17:30.153762 2023-03-15 00:17:30.146 39 ERROR keystone.server.flask.application   File "/var/lib/kolla/venv/lib/python3.9/site-packages/keystone/identity/backends/sql.py", line 194, in _get_user
2023-03-15 00:17:30.153774 2023-03-15 00:17:30.146 39 ERROR keystone.server.flask.application     raise exception.UserNotFound(user_id=user_id)
2023-03-15 00:17:30.153783 2023-03-15 00:17:30.146 39 ERROR keystone.server.flask.application keystone.exception.UserNotFound: Could not find user: ironic.
2023-03-15 00:17:30.153793 2023-03-15 00:17:30.146 39 ERROR keystone.server.flask.application \x1b[00m
2023-03-15 00:17:31.030372 2023-03-15 00:17:31.021 38 ERROR keystone.server.flask.application [None req-481dbeb4-7a2a-4678-8c86-9e2a5c4ff8e2 1e917c8eefa1409693db319fb971e603 - - all default -] Could not find project: service.: keystone.exception.ProjectNotFound: Could not find project: service.
2023-03-15 00:17:31.030420 2023-03-15 00:17:31.021 38 ERROR keystone.server.flask.application Traceback (most recent call last):
2023-03-15 00:17:31.030432 2023-03-15 00:17:31.021 38 ERROR keystone.server.flask.application   File "/var/lib/kolla/venv/lib/python3.9/site-packages/flask/app.py", line 1820, in full_dispatch_request
2023-03-15 00:17:31.030442 2023-03-15 00:17:31.021 38 ERROR keystone.server.flask.application     rv = self.dispatch_request()
2023-03-15 00:17:31.030452 2023-03-15 00:17:31.021 38 ERROR keystone.server.flask.application   File "/var/lib/kolla/venv/lib/python3.9/site-packages/flask/app.py", line 1796, in dispatch_request
2023-03-15 00:17:31.030462 2023-03-15 00:17:31.021 38 ERROR keystone.server.flask.application     return self.ensure_sync(self.view_functions[rule.endpoint])(**view_args)
2023-03-15 00:17:31.030472 2023-03-15 00:17:31.021 38 ERROR keystone.server.flask.application   File "/var/lib/kolla/venv/lib/python3.9/site-packages/flask_restful/__init__.py", line 467, in wrapper
2023-03-15 00:17:31.030482 2023-03-15 00:17:31.021 38 ERROR keystone.server.flask.application     resp = resource(*args, **kwargs)
2023-03-15 00:17:31.030501 2023-03-15 00:17:31.021 38 ERROR keystone.server.flask.application   File "/var/lib/kolla/venv/lib/python3.9/site-packages/flask/views.py", line 107, in view
2023-03-15 00:17:31.030514 2023-03-15 00:17:31.021 38 ERROR keystone.server.flask.application     return current_app.ensure_sync(self.dispatch_request)(**kwargs)
2023-03-15 00:17:31.030524 2023-03-15 00:17:31.021 38 ERROR keystone.server.flask.application   File "/var/lib/kolla/venv/lib/python3.9/site-packages/flask_restful/__init__.py", line 582, in dispatch_request
2023-03-15 00:17:31.030534 2023-03-15 00:17:31.021 38 ERROR keystone.server.flask.application     resp = meth(*args, **kwargs)
2023-03-15 00:17:31.030543 2023-03-15 00:17:31.021 38 ERROR keystone.server.flask.application   File "/var/lib/kolla/venv/lib/python3.9/site-packages/keystone/api/projects.py", line 151, in get
2023-03-15 00:17:31.030553 2023-03-15 00:17:31.021 38 ERROR keystone.server.flask.application     return self._get_project(project_id)
2023-03-15 00:17:31.030563 2023-03-15 00:17:31.021 38 ERROR keystone.server.flask.application   File "/var/lib/kolla/venv/lib/python3.9/site-packages/keystone/api/projects.py", line 107, in _get_project
2023-03-15 00:17:31.030573 2023-03-15 00:17:31.021 38 ERROR keystone.server.flask.application     project = PROVIDERS.resource_api.get_project(project_id)
2023-03-15 00:17:31.030582 2023-03-15 00:17:31.021 38 ERROR keystone.server.flask.application   File "/var/lib/kolla/venv/lib/python3.9/site-packages/keystone/common/manager.py", line 115, in wrapped
2023-03-15 00:17:31.030592 2023-03-15 00:17:31.021 38 ERROR keystone.server.flask.application     __ret_val = __f(*args, **kwargs)
2023-03-15 00:17:31.030603 2023-03-15 00:17:31.021 38 ERROR keystone.server.flask.application   File "/var/lib/kolla/venv/lib/python3.9/site-packages/decorator.py", line 232, in fun
2023-03-15 00:17:31.030616 2023-03-15 00:17:31.021 38 ERROR keystone.server.flask.application     return caller(func, *(extras + args), **kw)
2023-03-15 00:17:31.030642 2023-03-15 00:17:31.021 38 ERROR keystone.server.flask.application   File "/var/lib/kolla/venv/lib/python3.9/site-packages/dogpile/cache/region.py", line 1577, in get_or_create_for_user_func
2023-03-15 00:17:31.030653 2023-03-15 00:17:31.021 38 ERROR keystone.server.flask.application     return self.get_or_create(
2023-03-15 00:17:31.030663 2023-03-15 00:17:31.021 38 ERROR keystone.server.flask.application   File "/var/lib/kolla/venv/lib/python3.9/site-packages/dogpile/cache/region.py", line 1042, in get_or_create
2023-03-15 00:17:31.030673 2023-03-15 00:17:31.021 38 ERROR keystone.server.flask.application     with Lock(
2023-03-15 00:17:31.030683 2023-03-15 00:17:31.021 38 ERROR keystone.server.flask.application   File "/var/lib/kolla/venv/lib/python3.9/site-packages/dogpile/lock.py", line 185, in __enter__
2023-03-15 00:17:31.030692 2023-03-15 00:17:31.021 38 ERROR keystone.server.flask.application     return self._enter()
2023-03-15 00:17:31.030702 2023-03-15 00:17:31.021 38 ERROR keystone.server.flask.application   File "/var/lib/kolla/venv/lib/python3.9/site-packages/dogpile/lock.py", line 94, in _enter
2023-03-15 00:17:31.030712 2023-03-15 00:17:31.021 38 ERROR keystone.server.flask.application     generated = self._enter_create(value, createdtime)
2023-03-15 00:17:31.030722 2023-03-15 00:17:31.021 38 ERROR keystone.server.flask.application   File "/var/lib/kolla/venv/lib/python3.9/site-packages/dogpile/lock.py", line 178, in _enter_create
2023-03-15 00:17:31.030731 2023-03-15 00:17:31.021 38 ERROR keystone.server.flask.application     return self.creator()
2023-03-15 00:17:31.030741 2023-03-15 00:17:31.021 38 ERROR keystone.server.flask.application   File "/var/lib/kolla/venv/lib/python3.9/site-packages/dogpile/cache/region.py", line 995, in gen_value
2023-03-15 00:17:31.030751 2023-03-15 00:17:31.021 38 ERROR keystone.server.flask.application     created_value = creator(
2023-03-15 00:17:31.030760 2023-03-15 00:17:31.021 38 ERROR keystone.server.flask.application   File "/var/lib/kolla/venv/lib/python3.9/site-packages/keystone/resource/core.py", line 903, in get_project
2023-03-15 00:17:31.030770 2023-03-15 00:17:31.021 38 ERROR keystone.server.flask.application     return self.driver.get_project(project_id)
2023-03-15 00:17:31.030780 2023-03-15 00:17:31.021 38 ERROR keystone.server.flask.application   File "/var/lib/kolla/venv/lib/python3.9/site-packages/keystone/resource/backends/sql.py", line 49, in get_project
2023-03-15 00:17:31.030789 2023-03-15 00:17:31.021 38 ERROR keystone.server.flask.application     return self._get_project(session, project_id).to_dict()
2023-03-15 00:17:31.030799 2023-03-15 00:17:31.021 38 ERROR keystone.server.flask.application   File "/var/lib/kolla/venv/lib/python3.9/site-packages/keystone/resource/backends/sql.py", line 44, in _get_project
2023-03-15 00:17:31.030809 2023-03-15 00:17:31.021 38 ERROR keystone.server.flask.application     raise exception.ProjectNotFound(project_id=project_id)
2023-03-15 00:17:31.030818 2023-03-15 00:17:31.021 38 ERROR keystone.server.flask.application keystone.exception.ProjectNotFound: Could not find project: service.
2023-03-15 00:17:31.030828 2023-03-15 00:17:31.021 38 ERROR keystone.server.flask.application \x1b[00m
2023-03-15 00:17:41.338664 2023-03-15 00:17:41.332 37 ERROR keystone.server.flask.application [None req-96a6538c-04ac-4329-bac9-82d35601df8e 1e917c8eefa1409693db319fb971e603 - - all default -] Could not find role: admin.: keystone.exception.RoleNotFound: Could not find role: admin.
2023-03-15 00:17:41.338750 2023-03-15 00:17:41.332 37 ERROR keystone.server.flask.application Traceback (most recent call last):
2023-03-15 00:17:41.338762 2023-03-15 00:17:41.332 37 ERROR keystone.server.flask.application   File "/var/lib/kolla/venv/lib/python3.9/site-packages/flask/app.py", line 1820, in full_dispatch_request
2023-03-15 00:17:41.338772 2023-03-15 00:17:41.332 37 ERROR keystone.server.flask.application     rv = self.dispatch_request()
2023-03-15 00:17:41.338782 2023-03-15 00:17:41.332 37 ERROR keystone.server.flask.application   File "/var/lib/kolla/venv/lib/python3.9/site-packages/flask/app.py", line 1796, in dispatch_request
2023-03-15 00:17:41.338829 2023-03-15 00:17:41.332 37 ERROR keystone.server.flask.application     return self.ensure_sync(self.view_functions[rule.endpoint])(**view_args)
2023-03-15 00:17:41.338842 2023-03-15 00:17:41.332 37 ERROR keystone.server.flask.application   File "/var/lib/kolla/venv/lib/python3.9/site-packages/flask_restful/__init__.py", line 467, in wrapper
2023-03-15 00:17:41.338852 2023-03-15 00:17:41.332 37 ERROR keystone.server.flask.application     resp = resource(*args, **kwargs)
2023-03-15 00:17:41.338862 2023-03-15 00:17:41.332 37 ERROR keystone.server.flask.application   File "/var/lib/kolla/venv/lib/python3.9/site-packages/flask/views.py", line 107, in view
2023-03-15 00:17:41.338872 2023-03-15 00:17:41.332 37 ERROR keystone.server.flask.application     return current_app.ensure_sync(self.dispatch_request)(**kwargs)
2023-03-15 00:17:41.338882 2023-03-15 00:17:41.332 37 ERROR keystone.server.flask.application   File "/var/lib/kolla/venv/lib/python3.9/site-packages/flask_restful/__init__.py", line 582, in dispatch_request
2023-03-15 00:17:41.338891 2023-03-15 00:17:41.332 37 ERROR keystone.server.flask.application     resp = meth(*args, **kwargs)
2023-03-15 00:17:41.338924 2023-03-15 00:17:41.332 37 ERROR keystone.server.flask.application   File "/var/lib/kolla/venv/lib/python3.9/site-packages/keystone/api/roles.py", line 50, in get
2023-03-15 00:17:41.338939 2023-03-15 00:17:41.332 37 ERROR keystone.server.flask.application     return self._get_role(role_id)
2023-03-15 00:17:41.338949 2023-03-15 00:17:41.332 37 ERROR keystone.server.flask.application   File "/var/lib/kolla/venv/lib/python3.9/site-packages/keystone/api/roles.py", line 70, in _get_role
2023-03-15 00:17:41.338966 2023-03-15 00:17:41.332 37 ERROR keystone.server.flask.application     ENFORCER.enforce_call(action='identity:get_role')
2023-03-15 00:17:41.338986 2023-03-15 00:17:41.332 37 ERROR keystone.server.flask.application   File "/var/lib/kolla/venv/lib/python3.9/site-packages/keystone/common/rbac_enforcer/enforcer.py", line 402, in enforce_call
2023-03-15 00:17:41.339004 2023-03-15 00:17:41.332 37 ERROR keystone.server.flask.application     policy_dict.update(cls._extract_member_target_data(
2023-03-15 00:17:41.339034 2023-03-15 00:17:41.332 37 ERROR keystone.server.flask.application   File "/var/lib/kolla/venv/lib/python3.9/site-packages/keystone/common/rbac_enforcer/enforcer.py", line 234, in _extract_member_target_data
2023-03-15 00:17:41.339058 2023-03-15 00:17:41.332 37 ERROR keystone.server.flask.application     member_name: func(flask.request.view_args[key])
2023-03-15 00:17:41.339081 2023-03-15 00:17:41.332 37 ERROR keystone.server.flask.application   File "/var/lib/kolla/venv/lib/python3.9/site-packages/keystone/common/manager.py", line 115, in wrapped
2023-03-15 00:17:41.339102 2023-03-15 00:17:41.332 37 ERROR keystone.server.flask.application     __ret_val = __f(*args, **kwargs)
2023-03-15 00:17:41.339122 2023-03-15 00:17:41.332 37 ERROR keystone.server.flask.application   File "/var/lib/kolla/venv/lib/python3.9/site-packages/decorator.py", line 232, in fun
2023-03-15 00:17:41.339144 2023-03-15 00:17:41.332 37 ERROR keystone.server.flask.application     return caller(func, *(extras + args), **kw)
2023-03-15 00:17:41.339166 2023-03-15 00:17:41.332 37 ERROR keystone.server.flask.application   File "/var/lib/kolla/venv/lib/python3.9/site-packages/dogpile/cache/region.py", line 1577, in get_or_create_for_user_func
2023-03-15 00:17:41.339186 2023-03-15 00:17:41.332 37 ERROR keystone.server.flask.application     return self.get_or_create(
2023-03-15 00:17:41.339207 2023-03-15 00:17:41.332 37 ERROR keystone.server.flask.application   File "/var/lib/kolla/venv/lib/python3.9/site-packages/dogpile/cache/region.py", line 1042, in get_or_create
2023-03-15 00:17:41.339231 2023-03-15 00:17:41.332 37 ERROR keystone.server.flask.application     with Lock(
2023-03-15 00:17:41.339281 2023-03-15 00:17:41.332 37 ERROR keystone.server.flask.application   File "/var/lib/kolla/venv/lib/python3.9/site-packages/dogpile/lock.py", line 185, in __enter__
2023-03-15 00:17:41.339301 2023-03-15 00:17:41.332 37 ERROR keystone.server.flask.application     return self._enter()
2023-03-15 00:17:41.339312 2023-03-15 00:17:41.332 37 ERROR keystone.server.flask.application   File "/var/lib/kolla/venv/lib/python3.9/site-packages/dogpile/lock.py", line 94, in _enter
2023-03-15 00:17:41.339321 2023-03-15 00:17:41.332 37 ERROR keystone.server.flask.application     generated = self._enter_create(value, createdtime)
2023-03-15 00:17:41.339331 2023-03-15 00:17:41.332 37 ERROR keystone.server.flask.application   File "/var/lib/kolla/venv/lib/python3.9/site-packages/dogpile/lock.py", line 178, in _enter_create
2023-03-15 00:17:41.339356 2023-03-15 00:17:41.332 37 ERROR keystone.server.flask.application     return self.creator()
2023-03-15 00:17:41.339375 2023-03-15 00:17:41.332 37 ERROR keystone.server.flask.application   File "/var/lib/kolla/venv/lib/python3.9/site-packages/dogpile/cache/region.py", line 995, in gen_value
2023-03-15 00:17:41.339386 2023-03-15 00:17:41.332 37 ERROR keystone.server.flask.application     created_value = creator(
2023-03-15 00:17:41.339395 2023-03-15 00:17:41.332 37 ERROR keystone.server.flask.application   File "/var/lib/kolla/venv/lib/python3.9/site-packages/keystone/assignment/core.py", line 1276, in get_role
2023-03-15 00:17:41.339405 2023-03-15 00:17:41.332 37 ERROR keystone.server.flask.application     return self.driver.get_role(role_id)
2023-03-15 00:17:41.339414 2023-03-15 00:17:41.332 37 ERROR keystone.server.flask.application   File "/var/lib/kolla/venv/lib/python3.9/site-packages/keystone/assignment/role_backends/sql.py", line 70, in get_role
2023-03-15 00:17:41.339424 2023-03-15 00:17:41.332 37 ERROR keystone.server.flask.application     return self._get_role(session, role_id).to_dict()
2023-03-15 00:17:41.339433 2023-03-15 00:17:41.332 37 ERROR keystone.server.flask.application   File "/var/lib/kolla/venv/lib/python3.9/site-packages/keystone/assignment/role_backends/sql.py", line 65, in _get_role
2023-03-15 00:17:41.339443 2023-03-15 00:17:41.332 37 ERROR keystone.server.flask.application     raise exception.RoleNotFound(role_id=role_id)
2023-03-15 00:17:41.339452 2023-03-15 00:17:41.332 37 ERROR keystone.server.flask.application keystone.exception.RoleNotFound: Could not find role: admin.
2023-03-15 00:17:41.339461 2023-03-15 00:17:41.332 37 ERROR keystone.server.flask.application \x1b[00m
2023-03-15 00:17:42.588365 2023-03-15 00:17:42.583 37 ERROR keystone.server.flask.application [None req-7e577ec1-1d1c-4b91-968a-c04b34082b92 1e917c8eefa1409693db319fb971e603 - - all default -] Could not find user: ironic-inspector.: keystone.exception.UserNotFound: Could not find user: ironic-inspector.
2023-03-15 00:17:42.588410 2023-03-15 00:17:42.583 37 ERROR keystone.server.flask.application Traceback (most recent call last):
2023-03-15 00:17:42.588421 2023-03-15 00:17:42.583 37 ERROR keystone.server.flask.application   File "/var/lib/kolla/venv/lib/python3.9/site-packages/flask/app.py", line 1820, in full_dispatch_request
2023-03-15 00:17:42.588432 2023-03-15 00:17:42.583 37 ERROR keystone.server.flask.application     rv = self.dispatch_request()
2023-03-15 00:17:42.588441 2023-03-15 00:17:42.583 37 ERROR keystone.server.flask.application   File "/var/lib/kolla/venv/lib/python3.9/site-packages/flask/app.py", line 1796, in dispatch_request
2023-03-15 00:17:42.588451 2023-03-15 00:17:42.583 37 ERROR keystone.server.flask.application     return self.ensure_sync(self.view_functions[rule.endpoint])(**view_args)
2023-03-15 00:17:42.588461 2023-03-15 00:17:42.583 37 ERROR keystone.server.flask.application   File "/var/lib/kolla/venv/lib/python3.9/site-packages/flask_restful/__init__.py", line 467, in wrapper
2023-03-15 00:17:42.588470 2023-03-15 00:17:42.583 37 ERROR keystone.server.flask.application     resp = resource(*args, **kwargs)
2023-03-15 00:17:42.588480 2023-03-15 00:17:42.583 37 ERROR keystone.server.flask.application   File "/var/lib/kolla/venv/lib/python3.9/site-packages/flask/views.py", line 107, in view
2023-03-15 00:17:42.588507 2023-03-15 00:17:42.583 37 ERROR keystone.server.flask.application     return current_app.ensure_sync(self.dispatch_request)(**kwargs)
2023-03-15 00:17:42.588518 2023-03-15 00:17:42.583 37 ERROR keystone.server.flask.application   File "/var/lib/kolla/venv/lib/python3.9/site-packages/flask_restful/__init__.py", line 582, in dispatch_request
2023-03-15 00:17:42.588528 2023-03-15 00:17:42.583 37 ERROR keystone.server.flask.application     resp = meth(*args, **kwargs)
2023-03-15 00:17:42.588538 2023-03-15 00:17:42.583 37 ERROR keystone.server.flask.application   File "/var/lib/kolla/venv/lib/python3.9/site-packages/keystone/api/users.py", line 182, in get
2023-03-15 00:17:42.588548 2023-03-15 00:17:42.583 37 ERROR keystone.server.flask.application     return self._get_user(user_id)
2023-03-15 00:17:42.588557 2023-03-15 00:17:42.583 37 ERROR keystone.server.flask.application   File "/var/lib/kolla/venv/lib/python3.9/site-packages/keystone/api/users.py", line 194, in _get_user
2023-03-15 00:17:42.588567 2023-03-15 00:17:42.583 37 ERROR keystone.server.flask.application     ref = PROVIDERS.identity_api.get_user(user_id)
2023-03-15 00:17:42.588576 2023-03-15 00:17:42.583 37 ERROR keystone.server.flask.application   File "/var/lib/kolla/venv/lib/python3.9/site-packages/keystone/common/manager.py", line 115, in wrapped
2023-03-15 00:17:42.588586 2023-03-15 00:17:42.583 37 ERROR keystone.server.flask.application     __ret_val = __f(*args, **kwargs)
2023-03-15 00:17:42.588596 2023-03-15 00:17:42.583 37 ERROR keystone.server.flask.application   File "/var/lib/kolla/venv/lib/python3.9/site-packages/keystone/identity/core.py", line 414, in wrapper
2023-03-15 00:17:42.588605 2023-03-15 00:17:42.583 37 ERROR keystone.server.flask.application     return f(self, *args, **kwargs)
2023-03-15 00:17:42.588615 2023-03-15 00:17:42.583 37 ERROR keystone.server.flask.application   File "/var/lib/kolla/venv/lib/python3.9/site-packages/keystone/identity/core.py", line 424, in wrapper
2023-03-15 00:17:42.588624 2023-03-15 00:17:42.583 37 ERROR keystone.server.flask.application     return f(self, *args, **kwargs)
2023-03-15 00:17:42.588634 2023-03-15 00:17:42.583 37 ERROR keystone.server.flask.application   File "/var/lib/kolla/venv/lib/python3.9/site-packages/decorator.py", line 232, in fun
2023-03-15 00:17:42.588643 2023-03-15 00:17:42.583 37 ERROR keystone.server.flask.application     return caller(func, *(extras + args), **kw)
2023-03-15 00:17:42.588653 2023-03-15 00:17:42.583 37 ERROR keystone.server.flask.application   File "/var/lib/kolla/venv/lib/python3.9/site-packages/dogpile/cache/region.py", line 1577, in get_or_create_for_user_func
2023-03-15 00:17:42.588663 2023-03-15 00:17:42.583 37 ERROR keystone.server.flask.application     return self.get_or_create(
2023-03-15 00:17:42.588672 2023-03-15 00:17:42.583 37 ERROR keystone.server.flask.application   File "/var/lib/kolla/venv/lib/python3.9/site-packages/dogpile/cache/region.py", line 1042, in get_or_create
2023-03-15 00:17:42.588683 2023-03-15 00:17:42.583 37 ERROR keystone.server.flask.application     with Lock(
2023-03-15 00:17:42.588692 2023-03-15 00:17:42.583 37 ERROR keystone.server.flask.application   File "/var/lib/kolla/venv/lib/python3.9/site-packages/dogpile/lock.py", line 185, in __enter__
2023-03-15 00:17:42.588701 2023-03-15 00:17:42.583 37 ERROR keystone.server.flask.application     return self._enter()
2023-03-15 00:17:42.588711 2023-03-15 00:17:42.583 37 ERROR keystone.server.flask.application   File "/var/lib/kolla/venv/lib/python3.9/site-packages/dogpile/lock.py", line 94, in _enter
2023-03-15 00:17:42.588720 2023-03-15 00:17:42.583 37 ERROR keystone.server.flask.application     generated = self._enter_create(value, createdtime)
2023-03-15 00:17:42.588730 2023-03-15 00:17:42.583 37 ERROR keystone.server.flask.application   File "/var/lib/kolla/venv/lib/python3.9/site-packages/dogpile/lock.py", line 178, in _enter_create
2023-03-15 00:17:42.588749 2023-03-15 00:17:42.583 37 ERROR keystone.server.flask.application     return self.creator()
2023-03-15 00:17:42.588760 2023-03-15 00:17:42.583 37 ERROR keystone.server.flask.application   File "/var/lib/kolla/venv/lib/python3.9/site-packages/dogpile/cache/region.py", line 995, in gen_value
2023-03-15 00:17:42.588770 2023-03-15 00:17:42.583 37 ERROR keystone.server.flask.application     created_value = creator(
2023-03-15 00:17:42.588779 2023-03-15 00:17:42.583 37 ERROR keystone.server.flask.application   File "/var/lib/kolla/venv/lib/python3.9/site-packages/keystone/identity/core.py", line 1011, in get_user
2023-03-15 00:17:42.588789 2023-03-15 00:17:42.583 37 ERROR keystone.server.flask.application     ref = driver.get_user(entity_id)
2023-03-15 00:17:42.588799 2023-03-15 00:17:42.583 37 ERROR keystone.server.flask.application   File "/var/lib/kolla/venv/lib/python3.9/site-packages/keystone/identity/backends/sql.py", line 200, in get_user
2023-03-15 00:17:42.588808 2023-03-15 00:17:42.583 37 ERROR keystone.server.flask.application     self._get_user(session, user_id).to_dict())
2023-03-15 00:17:42.588818 2023-03-15 00:17:42.583 37 ERROR keystone.server.flask.application   File "/var/lib/kolla/venv/lib/python3.9/site-packages/keystone/identity/backends/sql.py", line 194, in _get_user
2023-03-15 00:17:42.588827 2023-03-15 00:17:42.583 37 ERROR keystone.server.flask.application     raise exception.UserNotFound(user_id=user_id)
2023-03-15 00:17:42.588837 2023-03-15 00:17:42.583 37 ERROR keystone.server.flask.application keystone.exception.UserNotFound: Could not find user: ironic-inspector.
2023-03-15 00:17:42.588846 2023-03-15 00:17:42.583 37 ERROR keystone.server.flask.application \x1b[00m
2023-03-15 00:17:43.535293 2023-03-15 00:17:43.531 39 ERROR keystone.server.flask.application [None req-f9e2aedb-52ea-410c-8921-f7a271943653 1e917c8eefa1409693db319fb971e603 - - all default -] Could not find project: service.: keystone.exception.ProjectNotFound: Could not find project: service.
2023-03-15 00:17:43.535384 2023-03-15 00:17:43.531 39 ERROR keystone.server.flask.application Traceback (most recent call last):
2023-03-15 00:17:43.535408 2023-03-15 00:17:43.531 39 ERROR keystone.server.flask.application   File "/var/lib/kolla/venv/lib/python3.9/site-packages/flask/app.py", line 1820, in full_dispatch_request
2023-03-15 00:17:43.535427 2023-03-15 00:17:43.531 39 ERROR keystone.server.flask.application     rv = self.dispatch_request()
2023-03-15 00:17:43.535450 2023-03-15 00:17:43.531 39 ERROR keystone.server.flask.application   File "/var/lib/kolla/venv/lib/python3.9/site-packages/flask/app.py", line 1796, in dispatch_request
2023-03-15 00:17:43.535474 2023-03-15 00:17:43.531 39 ERROR keystone.server.flask.application     return self.ensure_sync(self.view_functions[rule.endpoint])(**view_args)
2023-03-15 00:17:43.535497 2023-03-15 00:17:43.531 39 ERROR keystone.server.flask.application   File "/var/lib/kolla/venv/lib/python3.9/site-packages/flask_restful/__init__.py", line 467, in wrapper
2023-03-15 00:17:43.535518 2023-03-15 00:17:43.531 39 ERROR keystone.server.flask.application     resp = resource(*args, **kwargs)
2023-03-15 00:17:43.535554 2023-03-15 00:17:43.531 39 ERROR keystone.server.flask.application   File "/var/lib/kolla/venv/lib/python3.9/site-packages/flask/views.py", line 107, in view
2023-03-15 00:17:43.535590 2023-03-15 00:17:43.531 39 ERROR keystone.server.flask.application     return current_app.ensure_sync(self.dispatch_request)(**kwargs)
2023-03-15 00:17:43.535616 2023-03-15 00:17:43.531 39 ERROR keystone.server.flask.application   File "/var/lib/kolla/venv/lib/python3.9/site-packages/flask_restful/__init__.py", line 582, in dispatch_request
2023-03-15 00:17:43.535639 2023-03-15 00:17:43.531 39 ERROR keystone.server.flask.application     resp = meth(*args, **kwargs)
2023-03-15 00:17:43.535660 2023-03-15 00:17:43.531 39 ERROR keystone.server.flask.application   File "/var/lib/kolla/venv/lib/python3.9/site-packages/keystone/api/projects.py", line 151, in get
2023-03-15 00:17:43.535701 2023-03-15 00:17:43.531 39 ERROR keystone.server.flask.application     return self._get_project(project_id)
2023-03-15 00:17:43.535717 2023-03-15 00:17:43.531 39 ERROR keystone.server.flask.application   File "/var/lib/kolla/venv/lib/python3.9/site-packages/keystone/api/projects.py", line 107, in _get_project
2023-03-15 00:17:43.535728 2023-03-15 00:17:43.531 39 ERROR keystone.server.flask.application     project = PROVIDERS.resource_api.get_project(project_id)
2023-03-15 00:17:43.535737 2023-03-15 00:17:43.531 39 ERROR keystone.server.flask.application   File "/var/lib/kolla/venv/lib/python3.9/site-packages/keystone/common/manager.py", line 115, in wrapped
2023-03-15 00:17:43.535747 2023-03-15 00:17:43.531 39 ERROR keystone.server.flask.application     __ret_val = __f(*args, **kwargs)
2023-03-15 00:17:43.535756 2023-03-15 00:17:43.531 39 ERROR keystone.server.flask.application   File "/var/lib/kolla/venv/lib/python3.9/site-packages/decorator.py", line 232, in fun
2023-03-15 00:17:43.535766 2023-03-15 00:17:43.531 39 ERROR keystone.server.flask.application     return caller(func, *(extras + args), **kw)
2023-03-15 00:17:43.535775 2023-03-15 00:17:43.531 39 ERROR keystone.server.flask.application   File "/var/lib/kolla/venv/lib/python3.9/site-packages/dogpile/cache/region.py", line 1577, in get_or_create_for_user_func
2023-03-15 00:17:43.535785 2023-03-15 00:17:43.531 39 ERROR keystone.server.flask.application     return self.get_or_create(
2023-03-15 00:17:43.535795 2023-03-15 00:17:43.531 39 ERROR keystone.server.flask.application   File "/var/lib/kolla/venv/lib/python3.9/site-packages/dogpile/cache/region.py", line 1042, in get_or_create
2023-03-15 00:17:43.535804 2023-03-15 00:17:43.531 39 ERROR keystone.server.flask.application     with Lock(
2023-03-15 00:17:43.535814 2023-03-15 00:17:43.531 39 ERROR keystone.server.flask.application   File "/var/lib/kolla/venv/lib/python3.9/site-packages/dogpile/lock.py", line 185, in __enter__
2023-03-15 00:17:43.535823 2023-03-15 00:17:43.531 39 ERROR keystone.server.flask.application     return self._enter()
2023-03-15 00:17:43.535833 2023-03-15 00:17:43.531 39 ERROR keystone.server.flask.application   File "/var/lib/kolla/venv/lib/python3.9/site-packages/dogpile/lock.py", line 94, in _enter
2023-03-15 00:17:43.535842 2023-03-15 00:17:43.531 39 ERROR keystone.server.flask.application     generated = self._enter_create(value, createdtime)
2023-03-15 00:17:43.535852 2023-03-15 00:17:43.531 39 ERROR keystone.server.flask.application   File "/var/lib/kolla/venv/lib/python3.9/site-packages/dogpile/lock.py", line 178, in _enter_create
2023-03-15 00:17:43.535861 2023-03-15 00:17:43.531 39 ERROR keystone.server.flask.application     return self.creator()
2023-03-15 00:17:43.535871 2023-03-15 00:17:43.531 39 ERROR keystone.server.flask.application   File "/var/lib/kolla/venv/lib/python3.9/site-packages/dogpile/cache/region.py", line 995, in gen_value
2023-03-15 00:17:43.535880 2023-03-15 00:17:43.531 39 ERROR keystone.server.flask.application     created_value = creator(
2023-03-15 00:17:43.535890 2023-03-15 00:17:43.531 39 ERROR keystone.server.flask.application   File "/var/lib/kolla/venv/lib/python3.9/site-packages/keystone/resource/core.py", line 903, in get_project
2023-03-15 00:17:43.535921 2023-03-15 00:17:43.531 39 ERROR keystone.server.flask.application     return self.driver.get_project(project_id)
2023-03-15 00:17:43.535937 2023-03-15 00:17:43.531 39 ERROR keystone.server.flask.application   File "/var/lib/kolla/venv/lib/python3.9/site-packages/keystone/resource/backends/sql.py", line 49, in get_project
2023-03-15 00:17:43.535947 2023-03-15 00:17:43.531 39 ERROR keystone.server.flask.application     return self._get_project(session, project_id).to_dict()
2023-03-15 00:17:43.535957 2023-03-15 00:17:43.531 39 ERROR keystone.server.flask.application   File "/var/lib/kolla/venv/lib/python3.9/site-packages/keystone/resource/backends/sql.py", line 44, in _get_project
2023-03-15 00:17:43.535967 2023-03-15 00:17:43.531 39 ERROR keystone.server.flask.application     raise exception.ProjectNotFound(project_id=project_id)
2023-03-15 00:17:43.535989 2023-03-15 00:17:43.531 39 ERROR keystone.server.flask.application keystone.exception.ProjectNotFound: Could not find project: service.
2023-03-15 00:17:43.536000 2023-03-15 00:17:43.531 39 ERROR keystone.server.flask.application \x1b[00m
2023-03-15 00:20:36.393369 2023-03-15 00:20:36.389 38 ERROR keystone.server.flask.application [None req-9a087ade-16e1-4062-9945-e69396e496a3 1e917c8eefa1409693db319fb971e603 - - all default -] Could not find project: service.: keystone.exception.ProjectNotFound: Could not find project: service.
2023-03-15 00:20:36.393439 2023-03-15 00:20:36.389 38 ERROR keystone.server.flask.application Traceback (most recent call last):
2023-03-15 00:20:36.393454 2023-03-15 00:20:36.389 38 ERROR keystone.server.flask.application   File "/var/lib/kolla/venv/lib/python3.9/site-packages/flask/app.py", line 1820, in full_dispatch_request
2023-03-15 00:20:36.393464 2023-03-15 00:20:36.389 38 ERROR keystone.server.flask.application     rv = self.dispatch_request()
2023-03-15 00:20:36.393474 2023-03-15 00:20:36.389 38 ERROR keystone.server.flask.application   File "/var/lib/kolla/venv/lib/python3.9/site-packages/flask/app.py", line 1796, in dispatch_request
2023-03-15 00:20:36.393484 2023-03-15 00:20:36.389 38 ERROR keystone.server.flask.application     return self.ensure_sync(self.view_functions[rule.endpoint])(**view_args)
2023-03-15 00:20:36.393494 2023-03-15 00:20:36.389 38 ERROR keystone.server.flask.application   File "/var/lib/kolla/venv/lib/python3.9/site-packages/flask_restful/__init__.py", line 467, in wrapper
2023-03-15 00:20:36.393503 2023-03-15 00:20:36.389 38 ERROR keystone.server.flask.application     resp = resource(*args, **kwargs)
2023-03-15 00:20:36.393513 2023-03-15 00:20:36.389 38 ERROR keystone.server.flask.application   File "/var/lib/kolla/venv/lib/python3.9/site-packages/flask/views.py", line 107, in view
2023-03-15 00:20:36.393524 2023-03-15 00:20:36.389 38 ERROR keystone.server.flask.application     return current_app.ensure_sync(self.dispatch_request)(**kwargs)
2023-03-15 00:20:36.393534 2023-03-15 00:20:36.389 38 ERROR keystone.server.flask.application   File "/var/lib/kolla/venv/lib/python3.9/site-packages/flask_restful/__init__.py", line 582, in dispatch_request
2023-03-15 00:20:36.393544 2023-03-15 00:20:36.389 38 ERROR keystone.server.flask.application     resp = meth(*args, **kwargs)
2023-03-15 00:20:36.393553 2023-03-15 00:20:36.389 38 ERROR keystone.server.flask.application   File "/var/lib/kolla/venv/lib/python3.9/site-packages/keystone/api/projects.py", line 151, in get
2023-03-15 00:20:36.393563 2023-03-15 00:20:36.389 38 ERROR keystone.server.flask.application     return self._get_project(project_id)
2023-03-15 00:20:36.393573 2023-03-15 00:20:36.389 38 ERROR keystone.server.flask.application   File "/var/lib/kolla/venv/lib/python3.9/site-packages/keystone/api/projects.py", line 107, in _get_project
2023-03-15 00:20:36.393583 2023-03-15 00:20:36.389 38 ERROR keystone.server.flask.application     project = PROVIDERS.resource_api.get_project(project_id)
2023-03-15 00:20:36.393593 2023-03-15 00:20:36.389 38 ERROR keystone.server.flask.application   File "/var/lib/kolla/venv/lib/python3.9/site-packages/keystone/common/manager.py", line 115, in wrapped
2023-03-15 00:20:36.393603 2023-03-15 00:20:36.389 38 ERROR keystone.server.flask.application     __ret_val = __f(*args, **kwargs)
2023-03-15 00:20:36.393613 2023-03-15 00:20:36.389 38 ERROR keystone.server.flask.application   File "/var/lib/kolla/venv/lib/python3.9/site-packages/decorator.py", line 232, in fun
2023-03-15 00:20:36.393622 2023-03-15 00:20:36.389 38 ERROR keystone.server.flask.application     return caller(func, *(extras + args), **kw)
2023-03-15 00:20:36.393632 2023-03-15 00:20:36.389 38 ERROR keystone.server.flask.application   File "/var/lib/kolla/venv/lib/python3.9/site-packages/dogpile/cache/region.py", line 1577, in get_or_create_for_user_func
2023-03-15 00:20:36.393642 2023-03-15 00:20:36.389 38 ERROR keystone.server.flask.application     return self.get_or_create(
2023-03-15 00:20:36.393697 2023-03-15 00:20:36.389 38 ERROR keystone.server.flask.application   File "/var/lib/kolla/venv/lib/python3.9/site-packages/dogpile/cache/region.py", line 1042, in get_or_create
2023-03-15 00:20:36.393711 2023-03-15 00:20:36.389 38 ERROR keystone.server.flask.application     with Lock(
2023-03-15 00:20:36.393720 2023-03-15 00:20:36.389 38 ERROR keystone.server.flask.application   File "/var/lib/kolla/venv/lib/python3.9/site-packages/dogpile/lock.py", line 185, in __enter__
2023-03-15 00:20:36.393730 2023-03-15 00:20:36.389 38 ERROR keystone.server.flask.application     return self._enter()
2023-03-15 00:20:36.393740 2023-03-15 00:20:36.389 38 ERROR keystone.server.flask.application   File "/var/lib/kolla/venv/lib/python3.9/site-packages/dogpile/lock.py", line 94, in _enter
2023-03-15 00:20:36.393750 2023-03-15 00:20:36.389 38 ERROR keystone.server.flask.application     generated = self._enter_create(value, createdtime)
2023-03-15 00:20:36.393759 2023-03-15 00:20:36.389 38 ERROR keystone.server.flask.application   File "/var/lib/kolla/venv/lib/python3.9/site-packages/dogpile/lock.py", line 178, in _enter_create
2023-03-15 00:20:36.393769 2023-03-15 00:20:36.389 38 ERROR keystone.server.flask.application     return self.creator()
2023-03-15 00:20:36.393778 2023-03-15 00:20:36.389 38 ERROR keystone.server.flask.application   File "/var/lib/kolla/venv/lib/python3.9/site-packages/dogpile/cache/region.py", line 995, in gen_value
2023-03-15 00:20:36.393788 2023-03-15 00:20:36.389 38 ERROR keystone.server.flask.application     created_value = creator(
2023-03-15 00:20:36.393798 2023-03-15 00:20:36.389 38 ERROR keystone.server.flask.application   File "/var/lib/kolla/venv/lib/python3.9/site-packages/keystone/resource/core.py", line 903, in get_project
2023-03-15 00:20:36.393807 2023-03-15 00:20:36.389 38 ERROR keystone.server.flask.application     return self.driver.get_project(project_id)
2023-03-15 00:20:36.393817 2023-03-15 00:20:36.389 38 ERROR keystone.server.flask.application   File "/var/lib/kolla/venv/lib/python3.9/site-packages/keystone/resource/backends/sql.py", line 49, in get_project
2023-03-15 00:20:36.393827 2023-03-15 00:20:36.389 38 ERROR keystone.server.flask.application     return self._get_project(session, project_id).to_dict()
2023-03-15 00:20:36.393836 2023-03-15 00:20:36.389 38 ERROR keystone.server.flask.application   File "/var/lib/kolla/venv/lib/python3.9/site-packages/keystone/resource/backends/sql.py", line 44, in _get_project
2023-03-15 00:20:36.393846 2023-03-15 00:20:36.389 38 ERROR keystone.server.flask.application     raise exception.ProjectNotFound(project_id=project_id)
2023-03-15 00:20:36.393856 2023-03-15 00:20:36.389 38 ERROR keystone.server.flask.application keystone.exception.ProjectNotFound: Could not find project: service.
2023-03-15 00:20:36.393865 2023-03-15 00:20:36.389 38 ERROR keystone.server.flask.application \x1b[00m
2023-03-15 00:20:52.672355 2023-03-15 00:20:52.668 37 ERROR keystone.server.flask.application [None req-9349fba0-036b-4d7e-bc06-965fac94bf2d 1e917c8eefa1409693db319fb971e603 - - all default -] Could not find role: admin.: keystone.exception.RoleNotFound: Could not find role: admin.
2023-03-15 00:20:52.672412 2023-03-15 00:20:52.668 37 ERROR keystone.server.flask.application Traceback (most recent call last):
2023-03-15 00:20:52.672424 2023-03-15 00:20:52.668 37 ERROR keystone.server.flask.application   File "/var/lib/kolla/venv/lib/python3.9/site-packages/flask/app.py", line 1820, in full_dispatch_request
2023-03-15 00:20:52.672435 2023-03-15 00:20:52.668 37 ERROR keystone.server.flask.application     rv = self.dispatch_request()
2023-03-15 00:20:52.672444 2023-03-15 00:20:52.668 37 ERROR keystone.server.flask.application   File "/var/lib/kolla/venv/lib/python3.9/site-packages/flask/app.py", line 1796, in dispatch_request
2023-03-15 00:20:52.672454 2023-03-15 00:20:52.668 37 ERROR keystone.server.flask.application     return self.ensure_sync(self.view_functions[rule.endpoint])(**view_args)
2023-03-15 00:20:52.672464 2023-03-15 00:20:52.668 37 ERROR keystone.server.flask.application   File "/var/lib/kolla/venv/lib/python3.9/site-packages/flask_restful/__init__.py", line 467, in wrapper
2023-03-15 00:20:52.672489 2023-03-15 00:20:52.668 37 ERROR keystone.server.flask.application     resp = resource(*args, **kwargs)
2023-03-15 00:20:52.672500 2023-03-15 00:20:52.668 37 ERROR keystone.server.flask.application   File "/var/lib/kolla/venv/lib/python3.9/site-packages/flask/views.py", line 107, in view
2023-03-15 00:20:52.672510 2023-03-15 00:20:52.668 37 ERROR keystone.server.flask.application     return current_app.ensure_sync(self.dispatch_request)(**kwargs)
2023-03-15 00:20:52.672520 2023-03-15 00:20:52.668 37 ERROR keystone.server.flask.application   File "/var/lib/kolla/venv/lib/python3.9/site-packages/flask_restful/__init__.py", line 582, in dispatch_request
2023-03-15 00:20:52.672530 2023-03-15 00:20:52.668 37 ERROR keystone.server.flask.application     resp = meth(*args, **kwargs)
2023-03-15 00:20:52.672539 2023-03-15 00:20:52.668 37 ERROR keystone.server.flask.application   File "/var/lib/kolla/venv/lib/python3.9/site-packages/keystone/api/roles.py", line 50, in get
2023-03-15 00:20:52.672549 2023-03-15 00:20:52.668 37 ERROR keystone.server.flask.application     return self._get_role(role_id)
2023-03-15 00:20:52.672561 2023-03-15 00:20:52.668 37 ERROR keystone.server.flask.application   File "/var/lib/kolla/venv/lib/python3.9/site-packages/keystone/api/roles.py", line 70, in _get_role
2023-03-15 00:20:52.672582 2023-03-15 00:20:52.668 37 ERROR keystone.server.flask.application     ENFORCER.enforce_call(action='identity:get_role')
2023-03-15 00:20:52.672595 2023-03-15 00:20:52.668 37 ERROR keystone.server.flask.application   File "/var/lib/kolla/venv/lib/python3.9/site-packages/keystone/common/rbac_enforcer/enforcer.py", line 402, in enforce_call
2023-03-15 00:20:52.672605 2023-03-15 00:20:52.668 37 ERROR keystone.server.flask.application     policy_dict.update(cls._extract_member_target_data(
2023-03-15 00:20:52.672615 2023-03-15 00:20:52.668 37 ERROR keystone.server.flask.application   File "/var/lib/kolla/venv/lib/python3.9/site-packages/keystone/common/rbac_enforcer/enforcer.py", line 234, in _extract_member_target_data
2023-03-15 00:20:52.672625 2023-03-15 00:20:52.668 37 ERROR keystone.server.flask.application     member_name: func(flask.request.view_args[key])
2023-03-15 00:20:52.672635 2023-03-15 00:20:52.668 37 ERROR keystone.server.flask.application   File "/var/lib/kolla/venv/lib/python3.9/site-packages/keystone/common/manager.py", line 115, in wrapped
2023-03-15 00:20:52.672644 2023-03-15 00:20:52.668 37 ERROR keystone.server.flask.application     __ret_val = __f(*args, **kwargs)
2023-03-15 00:20:52.672654 2023-03-15 00:20:52.668 37 ERROR keystone.server.flask.application   File "/var/lib/kolla/venv/lib/python3.9/site-packages/decorator.py", line 232, in fun
2023-03-15 00:20:52.672664 2023-03-15 00:20:52.668 37 ERROR keystone.server.flask.application     return caller(func, *(extras + args), **kw)
2023-03-15 00:20:52.672673 2023-03-15 00:20:52.668 37 ERROR keystone.server.flask.application   File "/var/lib/kolla/venv/lib/python3.9/site-packages/dogpile/cache/region.py", line 1577, in get_or_create_for_user_func
2023-03-15 00:20:52.672683 2023-03-15 00:20:52.668 37 ERROR keystone.server.flask.application     return self.get_or_create(
2023-03-15 00:20:52.672692 2023-03-15 00:20:52.668 37 ERROR keystone.server.flask.application   File "/var/lib/kolla/venv/lib/python3.9/site-packages/dogpile/cache/region.py", line 1042, in get_or_create
2023-03-15 00:20:52.672702 2023-03-15 00:20:52.668 37 ERROR keystone.server.flask.application     with Lock(
2023-03-15 00:20:52.672712 2023-03-15 00:20:52.668 37 ERROR keystone.server.flask.application   File "/var/lib/kolla/venv/lib/python3.9/site-packages/dogpile/lock.py", line 185, in __enter__
2023-03-15 00:20:52.672721 2023-03-15 00:20:52.668 37 ERROR keystone.server.flask.application     return self._enter()
2023-03-15 00:20:52.672731 2023-03-15 00:20:52.668 37 ERROR keystone.server.flask.application   File "/var/lib/kolla/venv/lib/python3.9/site-packages/dogpile/lock.py", line 94, in _enter
2023-03-15 00:20:52.672752 2023-03-15 00:20:52.668 37 ERROR keystone.server.flask.application     generated = self._enter_create(value, createdtime)
2023-03-15 00:20:52.672763 2023-03-15 00:20:52.668 37 ERROR keystone.server.flask.application   File "/var/lib/kolla/venv/lib/python3.9/site-packages/dogpile/lock.py", line 178, in _enter_create
2023-03-15 00:20:52.672773 2023-03-15 00:20:52.668 37 ERROR keystone.server.flask.application     return self.creator()
2023-03-15 00:20:52.672782 2023-03-15 00:20:52.668 37 ERROR keystone.server.flask.application   File "/var/lib/kolla/venv/lib/python3.9/site-packages/dogpile/cache/region.py", line 995, in gen_value
2023-03-15 00:20:52.672792 2023-03-15 00:20:52.668 37 ERROR keystone.server.flask.application     created_value = creator(
2023-03-15 00:20:52.672801 2023-03-15 00:20:52.668 37 ERROR keystone.server.flask.application   File "/var/lib/kolla/venv/lib/python3.9/site-packages/keystone/assignment/core.py", line 1276, in get_role
2023-03-15 00:20:52.672811 2023-03-15 00:20:52.668 37 ERROR keystone.server.flask.application     return self.driver.get_role(role_id)
2023-03-15 00:20:52.672820 2023-03-15 00:20:52.668 37 ERROR keystone.server.flask.application   File "/var/lib/kolla/venv/lib/python3.9/site-packages/keystone/assignment/role_backends/sql.py", line 70, in get_role
2023-03-15 00:20:52.672830 2023-03-15 00:20:52.668 37 ERROR keystone.server.flask.application     return self._get_role(session, role_id).to_dict()
2023-03-15 00:20:52.672839 2023-03-15 00:20:52.668 37 ERROR keystone.server.flask.application   File "/var/lib/kolla/venv/lib/python3.9/site-packages/keystone/assignment/role_backends/sql.py", line 65, in _get_role
2023-03-15 00:20:52.672849 2023-03-15 00:20:52.668 37 ERROR keystone.server.flask.application     raise exception.RoleNotFound(role_id=role_id)
2023-03-15 00:20:52.672858 2023-03-15 00:20:52.668 37 ERROR keystone.server.flask.application keystone.exception.RoleNotFound: Could not find role: admin.
2023-03-15 00:20:52.672868 2023-03-15 00:20:52.668 37 ERROR keystone.server.flask.application \x1b[00m
2023-03-15 00:20:53.908881 2023-03-15 00:20:53.903 37 ERROR keystone.server.flask.application [None req-14c6acd0-e76a-46d3-8141-e2a42e6a7165 1e917c8eefa1409693db319fb971e603 - - all default -] Could not find user: neutron.: keystone.exception.UserNotFound: Could not find user: neutron.
2023-03-15 00:20:53.909033 2023-03-15 00:20:53.903 37 ERROR keystone.server.flask.application Traceback (most recent call last):
2023-03-15 00:20:53.909052 2023-03-15 00:20:53.903 37 ERROR keystone.server.flask.application   File "/var/lib/kolla/venv/lib/python3.9/site-packages/flask/app.py", line 1820, in full_dispatch_request
2023-03-15 00:20:53.909069 2023-03-15 00:20:53.903 37 ERROR keystone.server.flask.application     rv = self.dispatch_request()
2023-03-15 00:20:53.909085 2023-03-15 00:20:53.903 37 ERROR keystone.server.flask.application   File "/var/lib/kolla/venv/lib/python3.9/site-packages/flask/app.py", line 1796, in dispatch_request
2023-03-15 00:20:53.909102 2023-03-15 00:20:53.903 37 ERROR keystone.server.flask.application     return self.ensure_sync(self.view_functions[rule.endpoint])(**view_args)
2023-03-15 00:20:53.909118 2023-03-15 00:20:53.903 37 ERROR keystone.server.flask.application   File "/var/lib/kolla/venv/lib/python3.9/site-packages/flask_restful/__init__.py", line 467, in wrapper
2023-03-15 00:20:53.909134 2023-03-15 00:20:53.903 37 ERROR keystone.server.flask.application     resp = resource(*args, **kwargs)
2023-03-15 00:20:53.909150 2023-03-15 00:20:53.903 37 ERROR keystone.server.flask.application   File "/var/lib/kolla/venv/lib/python3.9/site-packages/flask/views.py", line 107, in view
2023-03-15 00:20:53.909167 2023-03-15 00:20:53.903 37 ERROR keystone.server.flask.application     return current_app.ensure_sync(self.dispatch_request)(**kwargs)
2023-03-15 00:20:53.909183 2023-03-15 00:20:53.903 37 ERROR keystone.server.flask.application   File "/var/lib/kolla/venv/lib/python3.9/site-packages/flask_restful/__init__.py", line 582, in dispatch_request
2023-03-15 00:20:53.909261 2023-03-15 00:20:53.903 37 ERROR keystone.server.flask.application     resp = meth(*args, **kwargs)
2023-03-15 00:20:53.909283 2023-03-15 00:20:53.903 37 ERROR keystone.server.flask.application   File "/var/lib/kolla/venv/lib/python3.9/site-packages/keystone/api/users.py", line 182, in get
2023-03-15 00:20:53.909299 2023-03-15 00:20:53.903 37 ERROR keystone.server.flask.application     return self._get_user(user_id)
2023-03-15 00:20:53.909315 2023-03-15 00:20:53.903 37 ERROR keystone.server.flask.application   File "/var/lib/kolla/venv/lib/python3.9/site-packages/keystone/api/users.py", line 194, in _get_user
2023-03-15 00:20:53.909360 2023-03-15 00:20:53.903 37 ERROR keystone.server.flask.application     ref = PROVIDERS.identity_api.get_user(user_id)
2023-03-15 00:20:53.909376 2023-03-15 00:20:53.903 37 ERROR keystone.server.flask.application   File "/var/lib/kolla/venv/lib/python3.9/site-packages/keystone/common/manager.py", line 115, in wrapped
2023-03-15 00:20:53.909392 2023-03-15 00:20:53.903 37 ERROR keystone.server.flask.application     __ret_val = __f(*args, **kwargs)
2023-03-15 00:20:53.909407 2023-03-15 00:20:53.903 37 ERROR keystone.server.flask.application   File "/var/lib/kolla/venv/lib/python3.9/site-packages/keystone/identity/core.py", line 414, in wrapper
2023-03-15 00:20:53.909423 2023-03-15 00:20:53.903 37 ERROR keystone.server.flask.application     return f(self, *args, **kwargs)
2023-03-15 00:20:53.909439 2023-03-15 00:20:53.903 37 ERROR keystone.server.flask.application   File "/var/lib/kolla/venv/lib/python3.9/site-packages/keystone/identity/core.py", line 424, in wrapper
2023-03-15 00:20:53.909455 2023-03-15 00:20:53.903 37 ERROR keystone.server.flask.application     return f(self, *args, **kwargs)
2023-03-15 00:20:53.909470 2023-03-15 00:20:53.903 37 ERROR keystone.server.flask.application   File "/var/lib/kolla/venv/lib/python3.9/site-packages/decorator.py", line 232, in fun
2023-03-15 00:20:53.909486 2023-03-15 00:20:53.903 37 ERROR keystone.server.flask.application     return caller(func, *(extras + args), **kw)
2023-03-15 00:20:53.909502 2023-03-15 00:20:53.903 37 ERROR keystone.server.flask.application   File "/var/lib/kolla/venv/lib/python3.9/site-packages/dogpile/cache/region.py", line 1577, in get_or_create_for_user_func
2023-03-15 00:20:53.909518 2023-03-15 00:20:53.903 37 ERROR keystone.server.flask.application     return self.get_or_create(
2023-03-15 00:20:53.909534 2023-03-15 00:20:53.903 37 ERROR keystone.server.flask.application   File "/var/lib/kolla/venv/lib/python3.9/site-packages/dogpile/cache/region.py", line 1042, in get_or_create
2023-03-15 00:20:53.909550 2023-03-15 00:20:53.903 37 ERROR keystone.server.flask.application     with Lock(
2023-03-15 00:20:53.909565 2023-03-15 00:20:53.903 37 ERROR keystone.server.flask.application   File "/var/lib/kolla/venv/lib/python3.9/site-packages/dogpile/lock.py", line 185, in __enter__
2023-03-15 00:20:53.909581 2023-03-15 00:20:53.903 37 ERROR keystone.server.flask.application     return self._enter()
2023-03-15 00:20:53.909597 2023-03-15 00:20:53.903 37 ERROR keystone.server.flask.application   File "/var/lib/kolla/venv/lib/python3.9/site-packages/dogpile/lock.py", line 94, in _enter
2023-03-15 00:20:53.909613 2023-03-15 00:20:53.903 37 ERROR keystone.server.flask.application     generated = self._enter_create(value, createdtime)
2023-03-15 00:20:53.909628 2023-03-15 00:20:53.903 37 ERROR keystone.server.flask.application   File "/var/lib/kolla/venv/lib/python3.9/site-packages/dogpile/lock.py", line 178, in _enter_create
2023-03-15 00:20:53.909644 2023-03-15 00:20:53.903 37 ERROR keystone.server.flask.application     return self.creator()
2023-03-15 00:20:53.909659 2023-03-15 00:20:53.903 37 ERROR keystone.server.flask.application   File "/var/lib/kolla/venv/lib/python3.9/site-packages/dogpile/cache/region.py", line 995, in gen_value
2023-03-15 00:20:53.909675 2023-03-15 00:20:53.903 37 ERROR keystone.server.flask.application     created_value = creator(
2023-03-15 00:20:53.909719 2023-03-15 00:20:53.903 37 ERROR keystone.server.flask.application   File "/var/lib/kolla/venv/lib/python3.9/site-packages/keystone/identity/core.py", line 1011, in get_user
2023-03-15 00:20:53.909737 2023-03-15 00:20:53.903 37 ERROR keystone.server.flask.application     ref = driver.get_user(entity_id)
2023-03-15 00:20:53.909753 2023-03-15 00:20:53.903 37 ERROR keystone.server.flask.application   File "/var/lib/kolla/venv/lib/python3.9/site-packages/keystone/identity/backends/sql.py", line 200, in get_user
2023-03-15 00:20:53.909769 2023-03-15 00:20:53.903 37 ERROR keystone.server.flask.application     self._get_user(session, user_id).to_dict())
2023-03-15 00:20:53.909785 2023-03-15 00:20:53.903 37 ERROR keystone.server.flask.application   File "/var/lib/kolla/venv/lib/python3.9/site-packages/keystone/identity/backends/sql.py", line 194, in _get_user
2023-03-15 00:20:53.909801 2023-03-15 00:20:53.903 37 ERROR keystone.server.flask.application     raise exception.UserNotFound(user_id=user_id)
2023-03-15 00:20:53.909817 2023-03-15 00:20:53.903 37 ERROR keystone.server.flask.application keystone.exception.UserNotFound: Could not find user: neutron.
2023-03-15 00:20:53.909833 2023-03-15 00:20:53.903 37 ERROR keystone.server.flask.application \x1b[00m
2023-03-15 00:20:54.826714 2023-03-15 00:20:54.821 39 ERROR keystone.server.flask.application [None req-36dc5aad-f0ad-44b2-adaa-2397e67b097c 1e917c8eefa1409693db319fb971e603 - - all default -] Could not find project: service.: keystone.exception.ProjectNotFound: Could not find project: service.
2023-03-15 00:20:54.826769 2023-03-15 00:20:54.821 39 ERROR keystone.server.flask.application Traceback (most recent call last):
2023-03-15 00:20:54.826784 2023-03-15 00:20:54.821 39 ERROR keystone.server.flask.application   File "/var/lib/kolla/venv/lib/python3.9/site-packages/flask/app.py", line 1820, in full_dispatch_request
2023-03-15 00:20:54.826798 2023-03-15 00:20:54.821 39 ERROR keystone.server.flask.application     rv = self.dispatch_request()
2023-03-15 00:20:54.826811 2023-03-15 00:20:54.821 39 ERROR keystone.server.flask.application   File "/var/lib/kolla/venv/lib/python3.9/site-packages/flask/app.py", line 1796, in dispatch_request
2023-03-15 00:20:54.826842 2023-03-15 00:20:54.821 39 ERROR keystone.server.flask.application     return self.ensure_sync(self.view_functions[rule.endpoint])(**view_args)
2023-03-15 00:20:54.827147 2023-03-15 00:20:54.821 39 ERROR keystone.server.flask.application   File "/var/lib/kolla/venv/lib/python3.9/site-packages/flask_restful/__init__.py", line 467, in wrapper
2023-03-15 00:20:54.827173 2023-03-15 00:20:54.821 39 ERROR keystone.server.flask.application     resp = resource(*args, **kwargs)
2023-03-15 00:20:54.827197 2023-03-15 00:20:54.821 39 ERROR keystone.server.flask.application   File "/var/lib/kolla/venv/lib/python3.9/site-packages/flask/views.py", line 107, in view
2023-03-15 00:20:54.827243 2023-03-15 00:20:54.821 39 ERROR keystone.server.flask.application     return current_app.ensure_sync(self.dispatch_request)(**kwargs)
2023-03-15 00:20:54.827274 2023-03-15 00:20:54.821 39 ERROR keystone.server.flask.application   File "/var/lib/kolla/venv/lib/python3.9/site-packages/flask_restful/__init__.py", line 582, in dispatch_request
2023-03-15 00:20:54.827290 2023-03-15 00:20:54.821 39 ERROR keystone.server.flask.application     resp = meth(*args, **kwargs)
2023-03-15 00:20:54.827303 2023-03-15 00:20:54.821 39 ERROR keystone.server.flask.application   File "/var/lib/kolla/venv/lib/python3.9/site-packages/keystone/api/projects.py", line 151, in get
2023-03-15 00:20:54.827351 2023-03-15 00:20:54.821 39 ERROR keystone.server.flask.application     return self._get_project(project_id)
2023-03-15 00:20:54.827365 2023-03-15 00:20:54.821 39 ERROR keystone.server.flask.application   File "/var/lib/kolla/venv/lib/python3.9/site-packages/keystone/api/projects.py", line 107, in _get_project
2023-03-15 00:20:54.827378 2023-03-15 00:20:54.821 39 ERROR keystone.server.flask.application     project = PROVIDERS.resource_api.get_project(project_id)
2023-03-15 00:20:54.827414 2023-03-15 00:20:54.821 39 ERROR keystone.server.flask.application   File "/var/lib/kolla/venv/lib/python3.9/site-packages/keystone/common/manager.py", line 115, in wrapped
2023-03-15 00:20:54.827429 2023-03-15 00:20:54.821 39 ERROR keystone.server.flask.application     __ret_val = __f(*args, **kwargs)
2023-03-15 00:20:54.827442 2023-03-15 00:20:54.821 39 ERROR keystone.server.flask.application   File "/var/lib/kolla/venv/lib/python3.9/site-packages/decorator.py", line 232, in fun
2023-03-15 00:20:54.827455 2023-03-15 00:20:54.821 39 ERROR keystone.server.flask.application     return caller(func, *(extras + args), **kw)
2023-03-15 00:20:54.827468 2023-03-15 00:20:54.821 39 ERROR keystone.server.flask.application   File "/var/lib/kolla/venv/lib/python3.9/site-packages/dogpile/cache/region.py", line 1577, in get_or_create_for_user_func
2023-03-15 00:20:54.827481 2023-03-15 00:20:54.821 39 ERROR keystone.server.flask.application     return self.get_or_create(
2023-03-15 00:20:54.827493 2023-03-15 00:20:54.821 39 ERROR keystone.server.flask.application   File "/var/lib/kolla/venv/lib/python3.9/site-packages/dogpile/cache/region.py", line 1042, in get_or_create
2023-03-15 00:20:54.827506 2023-03-15 00:20:54.821 39 ERROR keystone.server.flask.application     with Lock(
2023-03-15 00:20:54.827519 2023-03-15 00:20:54.821 39 ERROR keystone.server.flask.application   File "/var/lib/kolla/venv/lib/python3.9/site-packages/dogpile/lock.py", line 185, in __enter__
2023-03-15 00:20:54.827531 2023-03-15 00:20:54.821 39 ERROR keystone.server.flask.application     return self._enter()
2023-03-15 00:20:54.827544 2023-03-15 00:20:54.821 39 ERROR keystone.server.flask.application   File "/var/lib/kolla/venv/lib/python3.9/site-packages/dogpile/lock.py", line 94, in _enter
2023-03-15 00:20:54.827557 2023-03-15 00:20:54.821 39 ERROR keystone.server.flask.application     generated = self._enter_create(value, createdtime)
2023-03-15 00:20:54.827569 2023-03-15 00:20:54.821 39 ERROR keystone.server.flask.application   File "/var/lib/kolla/venv/lib/python3.9/site-packages/dogpile/lock.py", line 178, in _enter_create
2023-03-15 00:20:54.827582 2023-03-15 00:20:54.821 39 ERROR keystone.server.flask.application     return self.creator()
2023-03-15 00:20:54.827600 2023-03-15 00:20:54.821 39 ERROR keystone.server.flask.application   File "/var/lib/kolla/venv/lib/python3.9/site-packages/dogpile/cache/region.py", line 995, in gen_value
2023-03-15 00:20:54.827613 2023-03-15 00:20:54.821 39 ERROR keystone.server.flask.application     created_value = creator(
2023-03-15 00:20:54.827625 2023-03-15 00:20:54.821 39 ERROR keystone.server.flask.application   File "/var/lib/kolla/venv/lib/python3.9/site-packages/keystone/resource/core.py", line 903, in get_project
2023-03-15 00:20:54.827638 2023-03-15 00:20:54.821 39 ERROR keystone.server.flask.application     return self.driver.get_project(project_id)
2023-03-15 00:20:54.827650 2023-03-15 00:20:54.821 39 ERROR keystone.server.flask.application   File "/var/lib/kolla/venv/lib/python3.9/site-packages/keystone/resource/backends/sql.py", line 49, in get_project
2023-03-15 00:20:54.827663 2023-03-15 00:20:54.821 39 ERROR keystone.server.flask.application     return self._get_project(session, project_id).to_dict()
2023-03-15 00:20:54.827676 2023-03-15 00:20:54.821 39 ERROR keystone.server.flask.application   File "/var/lib/kolla/venv/lib/python3.9/site-packages/keystone/resource/backends/sql.py", line 44, in _get_project
2023-03-15 00:20:54.827688 2023-03-15 00:20:54.821 39 ERROR keystone.server.flask.application     raise exception.ProjectNotFound(project_id=project_id)
2023-03-15 00:20:54.827701 2023-03-15 00:20:54.821 39 ERROR keystone.server.flask.application keystone.exception.ProjectNotFound: Could not find project: service.
2023-03-15 00:20:54.827713 2023-03-15 00:20:54.821 39 ERROR keystone.server.flask.application \x1b[00m
