2023-04-06 02:29:06.043028 2023-04-06 02:29:06.041 28 WARNING keystone.common.rbac_enforcer.enforcer [None req-9c6f6a5a-f0a5-4d87-9c81-e31e57dcd8c9 2f9bbb60059d4f7b8a2c5bcc145402cd - - all default -] Deprecated policy rules found. Use oslopolicy-policy-generator and oslopolicy-policy-upgrade to detect and resolve deprecated policies in your configuration.\x1b[00m
2023-04-06 02:29:06.900630 2023-04-06 02:29:06.899 27 WARNING keystone.common.rbac_enforcer.enforcer [None req-6aba2b7f-43b8-4caa-92e6-2e85017cf205 2f9bbb60059d4f7b8a2c5bcc145402cd - - all default -] Deprecated policy rules found. Use oslopolicy-policy-generator and oslopolicy-policy-upgrade to detect and resolve deprecated policies in your configuration.\x1b[00m
2023-04-06 02:29:14.922283 2023-04-06 02:29:14.920 26 WARNING keystone.common.rbac_enforcer.enforcer [None req-344bb42f-e7a6-4e95-9e84-1b4b0a6d73d4 2f9bbb60059d4f7b8a2c5bcc145402cd - - all default -] Deprecated policy rules found. Use oslopolicy-policy-generator and oslopolicy-policy-upgrade to detect and resolve deprecated policies in your configuration.\x1b[00m
2023-04-06 02:30:32.257497 2023-04-06 02:30:32.203 26 ERROR keystone.server.flask.application [None req-10232d90-e14b-4173-9073-cf54136c2865 2f9bbb60059d4f7b8a2c5bcc145402cd - - all default -] Could not find project: service.: keystone.exception.ProjectNotFound: Could not find project: service.
2023-04-06 02:30:32.257924 2023-04-06 02:30:32.203 26 ERROR keystone.server.flask.application Traceback (most recent call last):
2023-04-06 02:30:32.257946 2023-04-06 02:30:32.203 26 ERROR keystone.server.flask.application   File "/var/lib/kolla/venv/lib/python3.9/site-packages/flask/app.py", line 1820, in full_dispatch_request
2023-04-06 02:30:32.257957 2023-04-06 02:30:32.203 26 ERROR keystone.server.flask.application     rv = self.dispatch_request()
2023-04-06 02:30:32.257968 2023-04-06 02:30:32.203 26 ERROR keystone.server.flask.application   File "/var/lib/kolla/venv/lib/python3.9/site-packages/flask/app.py", line 1796, in dispatch_request
2023-04-06 02:30:32.257980 2023-04-06 02:30:32.203 26 ERROR keystone.server.flask.application     return self.ensure_sync(self.view_functions[rule.endpoint])(**view_args)
2023-04-06 02:30:32.257991 2023-04-06 02:30:32.203 26 ERROR keystone.server.flask.application   File "/var/lib/kolla/venv/lib/python3.9/site-packages/flask_restful/__init__.py", line 467, in wrapper
2023-04-06 02:30:32.258002 2023-04-06 02:30:32.203 26 ERROR keystone.server.flask.application     resp = resource(*args, **kwargs)
2023-04-06 02:30:32.258021 2023-04-06 02:30:32.203 26 ERROR keystone.server.flask.application   File "/var/lib/kolla/venv/lib/python3.9/site-packages/flask/views.py", line 107, in view
2023-04-06 02:30:32.258035 2023-04-06 02:30:32.203 26 ERROR keystone.server.flask.application     return current_app.ensure_sync(self.dispatch_request)(**kwargs)
2023-04-06 02:30:32.258046 2023-04-06 02:30:32.203 26 ERROR keystone.server.flask.application   File "/var/lib/kolla/venv/lib/python3.9/site-packages/flask_restful/__init__.py", line 582, in dispatch_request
2023-04-06 02:30:32.258057 2023-04-06 02:30:32.203 26 ERROR keystone.server.flask.application     resp = meth(*args, **kwargs)
2023-04-06 02:30:32.258068 2023-04-06 02:30:32.203 26 ERROR keystone.server.flask.application   File "/var/lib/kolla/venv/lib/python3.9/site-packages/keystone/api/projects.py", line 151, in get
2023-04-06 02:30:32.258080 2023-04-06 02:30:32.203 26 ERROR keystone.server.flask.application     return self._get_project(project_id)
2023-04-06 02:30:32.258095 2023-04-06 02:30:32.203 26 ERROR keystone.server.flask.application   File "/var/lib/kolla/venv/lib/python3.9/site-packages/keystone/api/projects.py", line 107, in _get_project
2023-04-06 02:30:32.258109 2023-04-06 02:30:32.203 26 ERROR keystone.server.flask.application     project = PROVIDERS.resource_api.get_project(project_id)
2023-04-06 02:30:32.258127 2023-04-06 02:30:32.203 26 ERROR keystone.server.flask.application   File "/var/lib/kolla/venv/lib/python3.9/site-packages/keystone/common/manager.py", line 115, in wrapped
2023-04-06 02:30:32.258226 2023-04-06 02:30:32.203 26 ERROR keystone.server.flask.application     __ret_val = __f(*args, **kwargs)
2023-04-06 02:30:32.258239 2023-04-06 02:30:32.203 26 ERROR keystone.server.flask.application   File "/var/lib/kolla/venv/lib/python3.9/site-packages/decorator.py", line 232, in fun
2023-04-06 02:30:32.258250 2023-04-06 02:30:32.203 26 ERROR keystone.server.flask.application     return caller(func, *(extras + args), **kw)
2023-04-06 02:30:32.258270 2023-04-06 02:30:32.203 26 ERROR keystone.server.flask.application   File "/var/lib/kolla/venv/lib/python3.9/site-packages/dogpile/cache/region.py", line 1577, in get_or_create_for_user_func
2023-04-06 02:30:32.258284 2023-04-06 02:30:32.203 26 ERROR keystone.server.flask.application     return self.get_or_create(
2023-04-06 02:30:32.258295 2023-04-06 02:30:32.203 26 ERROR keystone.server.flask.application   File "/var/lib/kolla/venv/lib/python3.9/site-packages/dogpile/cache/region.py", line 1042, in get_or_create
2023-04-06 02:30:32.258307 2023-04-06 02:30:32.203 26 ERROR keystone.server.flask.application     with Lock(
2023-04-06 02:30:32.258318 2023-04-06 02:30:32.203 26 ERROR keystone.server.flask.application   File "/var/lib/kolla/venv/lib/python3.9/site-packages/dogpile/lock.py", line 185, in __enter__
2023-04-06 02:30:32.258358 2023-04-06 02:30:32.203 26 ERROR keystone.server.flask.application     return self._enter()
2023-04-06 02:30:32.258372 2023-04-06 02:30:32.203 26 ERROR keystone.server.flask.application   File "/var/lib/kolla/venv/lib/python3.9/site-packages/dogpile/lock.py", line 94, in _enter
2023-04-06 02:30:32.258383 2023-04-06 02:30:32.203 26 ERROR keystone.server.flask.application     generated = self._enter_create(value, createdtime)
2023-04-06 02:30:32.258394 2023-04-06 02:30:32.203 26 ERROR keystone.server.flask.application   File "/var/lib/kolla/venv/lib/python3.9/site-packages/dogpile/lock.py", line 178, in _enter_create
2023-04-06 02:30:32.258405 2023-04-06 02:30:32.203 26 ERROR keystone.server.flask.application     return self.creator()
2023-04-06 02:30:32.258416 2023-04-06 02:30:32.203 26 ERROR keystone.server.flask.application   File "/var/lib/kolla/venv/lib/python3.9/site-packages/dogpile/cache/region.py", line 995, in gen_value
2023-04-06 02:30:32.258427 2023-04-06 02:30:32.203 26 ERROR keystone.server.flask.application     created_value = creator(
2023-04-06 02:30:32.258437 2023-04-06 02:30:32.203 26 ERROR keystone.server.flask.application   File "/var/lib/kolla/venv/lib/python3.9/site-packages/keystone/resource/core.py", line 903, in get_project
2023-04-06 02:30:32.258448 2023-04-06 02:30:32.203 26 ERROR keystone.server.flask.application     return self.driver.get_project(project_id)
2023-04-06 02:30:32.258459 2023-04-06 02:30:32.203 26 ERROR keystone.server.flask.application   File "/var/lib/kolla/venv/lib/python3.9/site-packages/keystone/resource/backends/sql.py", line 49, in get_project
2023-04-06 02:30:32.258476 2023-04-06 02:30:32.203 26 ERROR keystone.server.flask.application     return self._get_project(session, project_id).to_dict()
2023-04-06 02:30:32.258490 2023-04-06 02:30:32.203 26 ERROR keystone.server.flask.application   File "/var/lib/kolla/venv/lib/python3.9/site-packages/keystone/resource/backends/sql.py", line 44, in _get_project
2023-04-06 02:30:32.258501 2023-04-06 02:30:32.203 26 ERROR keystone.server.flask.application     raise exception.ProjectNotFound(project_id=project_id)
2023-04-06 02:30:32.258512 2023-04-06 02:30:32.203 26 ERROR keystone.server.flask.application keystone.exception.ProjectNotFound: Could not find project: service.
2023-04-06 02:30:32.258523 2023-04-06 02:30:32.203 26 ERROR keystone.server.flask.application \x1b[00m
2023-04-06 02:30:41.904119 2023-04-06 02:30:41.894 27 ERROR keystone.server.flask.application [None req-4bf4c566-1942-4ff5-8462-aa26547ffd60 2f9bbb60059d4f7b8a2c5bcc145402cd - - all default -] Could not find project: service.: keystone.exception.ProjectNotFound: Could not find project: service.
2023-04-06 02:30:41.904166 2023-04-06 02:30:41.894 27 ERROR keystone.server.flask.application Traceback (most recent call last):
2023-04-06 02:30:41.904193 2023-04-06 02:30:41.894 27 ERROR keystone.server.flask.application   File "/var/lib/kolla/venv/lib/python3.9/site-packages/flask/app.py", line 1820, in full_dispatch_request
2023-04-06 02:30:41.904206 2023-04-06 02:30:41.894 27 ERROR keystone.server.flask.application     rv = self.dispatch_request()
2023-04-06 02:30:41.904216 2023-04-06 02:30:41.894 27 ERROR keystone.server.flask.application   File "/var/lib/kolla/venv/lib/python3.9/site-packages/flask/app.py", line 1796, in dispatch_request
2023-04-06 02:30:41.904227 2023-04-06 02:30:41.894 27 ERROR keystone.server.flask.application     return self.ensure_sync(self.view_functions[rule.endpoint])(**view_args)
2023-04-06 02:30:41.904237 2023-04-06 02:30:41.894 27 ERROR keystone.server.flask.application   File "/var/lib/kolla/venv/lib/python3.9/site-packages/flask_restful/__init__.py", line 467, in wrapper
2023-04-06 02:30:41.904247 2023-04-06 02:30:41.894 27 ERROR keystone.server.flask.application     resp = resource(*args, **kwargs)
2023-04-06 02:30:41.904260 2023-04-06 02:30:41.894 27 ERROR keystone.server.flask.application   File "/var/lib/kolla/venv/lib/python3.9/site-packages/flask/views.py", line 107, in view
2023-04-06 02:30:41.904283 2023-04-06 02:30:41.894 27 ERROR keystone.server.flask.application     return current_app.ensure_sync(self.dispatch_request)(**kwargs)
2023-04-06 02:30:41.904295 2023-04-06 02:30:41.894 27 ERROR keystone.server.flask.application   File "/var/lib/kolla/venv/lib/python3.9/site-packages/flask_restful/__init__.py", line 582, in dispatch_request
2023-04-06 02:30:41.904305 2023-04-06 02:30:41.894 27 ERROR keystone.server.flask.application     resp = meth(*args, **kwargs)
2023-04-06 02:30:41.904315 2023-04-06 02:30:41.894 27 ERROR keystone.server.flask.application   File "/var/lib/kolla/venv/lib/python3.9/site-packages/keystone/api/projects.py", line 151, in get
2023-04-06 02:30:41.904349 2023-04-06 02:30:41.894 27 ERROR keystone.server.flask.application     return self._get_project(project_id)
2023-04-06 02:30:41.904363 2023-04-06 02:30:41.894 27 ERROR keystone.server.flask.application   File "/var/lib/kolla/venv/lib/python3.9/site-packages/keystone/api/projects.py", line 107, in _get_project
2023-04-06 02:30:41.904374 2023-04-06 02:30:41.894 27 ERROR keystone.server.flask.application     project = PROVIDERS.resource_api.get_project(project_id)
2023-04-06 02:30:41.904383 2023-04-06 02:30:41.894 27 ERROR keystone.server.flask.application   File "/var/lib/kolla/venv/lib/python3.9/site-packages/keystone/common/manager.py", line 115, in wrapped
2023-04-06 02:30:41.904393 2023-04-06 02:30:41.894 27 ERROR keystone.server.flask.application     __ret_val = __f(*args, **kwargs)
2023-04-06 02:30:41.904403 2023-04-06 02:30:41.894 27 ERROR keystone.server.flask.application   File "/var/lib/kolla/venv/lib/python3.9/site-packages/decorator.py", line 232, in fun
2023-04-06 02:30:41.904413 2023-04-06 02:30:41.894 27 ERROR keystone.server.flask.application     return caller(func, *(extras + args), **kw)
2023-04-06 02:30:41.904430 2023-04-06 02:30:41.894 27 ERROR keystone.server.flask.application   File "/var/lib/kolla/venv/lib/python3.9/site-packages/dogpile/cache/region.py", line 1577, in get_or_create_for_user_func
2023-04-06 02:30:41.904442 2023-04-06 02:30:41.894 27 ERROR keystone.server.flask.application     return self.get_or_create(
2023-04-06 02:30:41.904452 2023-04-06 02:30:41.894 27 ERROR keystone.server.flask.application   File "/var/lib/kolla/venv/lib/python3.9/site-packages/dogpile/cache/region.py", line 1042, in get_or_create
2023-04-06 02:30:41.904462 2023-04-06 02:30:41.894 27 ERROR keystone.server.flask.application     with Lock(
2023-04-06 02:30:41.904472 2023-04-06 02:30:41.894 27 ERROR keystone.server.flask.application   File "/var/lib/kolla/venv/lib/python3.9/site-packages/dogpile/lock.py", line 185, in __enter__
2023-04-06 02:30:41.904482 2023-04-06 02:30:41.894 27 ERROR keystone.server.flask.application     return self._enter()
2023-04-06 02:30:41.904504 2023-04-06 02:30:41.894 27 ERROR keystone.server.flask.application   File "/var/lib/kolla/venv/lib/python3.9/site-packages/dogpile/lock.py", line 94, in _enter
2023-04-06 02:30:41.904515 2023-04-06 02:30:41.894 27 ERROR keystone.server.flask.application     generated = self._enter_create(value, createdtime)
2023-04-06 02:30:41.904525 2023-04-06 02:30:41.894 27 ERROR keystone.server.flask.application   File "/var/lib/kolla/venv/lib/python3.9/site-packages/dogpile/lock.py", line 178, in _enter_create
2023-04-06 02:30:41.904535 2023-04-06 02:30:41.894 27 ERROR keystone.server.flask.application     return self.creator()
2023-04-06 02:30:41.904545 2023-04-06 02:30:41.894 27 ERROR keystone.server.flask.application   File "/var/lib/kolla/venv/lib/python3.9/site-packages/dogpile/cache/region.py", line 995, in gen_value
2023-04-06 02:30:41.904555 2023-04-06 02:30:41.894 27 ERROR keystone.server.flask.application     created_value = creator(
2023-04-06 02:30:41.904565 2023-04-06 02:30:41.894 27 ERROR keystone.server.flask.application   File "/var/lib/kolla/venv/lib/python3.9/site-packages/keystone/resource/core.py", line 903, in get_project
2023-04-06 02:30:41.904575 2023-04-06 02:30:41.894 27 ERROR keystone.server.flask.application     return self.driver.get_project(project_id)
2023-04-06 02:30:41.904585 2023-04-06 02:30:41.894 27 ERROR keystone.server.flask.application   File "/var/lib/kolla/venv/lib/python3.9/site-packages/keystone/resource/backends/sql.py", line 49, in get_project
2023-04-06 02:30:41.904601 2023-04-06 02:30:41.894 27 ERROR keystone.server.flask.application     return self._get_project(session, project_id).to_dict()
2023-04-06 02:30:41.904611 2023-04-06 02:30:41.894 27 ERROR keystone.server.flask.application   File "/var/lib/kolla/venv/lib/python3.9/site-packages/keystone/resource/backends/sql.py", line 44, in _get_project
2023-04-06 02:30:41.904621 2023-04-06 02:30:41.894 27 ERROR keystone.server.flask.application     raise exception.ProjectNotFound(project_id=project_id)
2023-04-06 02:30:41.904631 2023-04-06 02:30:41.894 27 ERROR keystone.server.flask.application keystone.exception.ProjectNotFound: Could not find project: service.
2023-04-06 02:30:41.904641 2023-04-06 02:30:41.894 27 ERROR keystone.server.flask.application \x1b[00m
2023-04-06 02:30:56.918693 2023-04-06 02:30:56.909 27 ERROR keystone.server.flask.application [None req-4308f648-95a0-43d1-9114-3f490e66b0f6 2f9bbb60059d4f7b8a2c5bcc145402cd - - all default -] Could not find role: admin.: keystone.exception.RoleNotFound: Could not find role: admin.
2023-04-06 02:30:56.918742 2023-04-06 02:30:56.909 27 ERROR keystone.server.flask.application Traceback (most recent call last):
2023-04-06 02:30:56.918754 2023-04-06 02:30:56.909 27 ERROR keystone.server.flask.application   File "/var/lib/kolla/venv/lib/python3.9/site-packages/flask/app.py", line 1820, in full_dispatch_request
2023-04-06 02:30:56.918782 2023-04-06 02:30:56.909 27 ERROR keystone.server.flask.application     rv = self.dispatch_request()
2023-04-06 02:30:56.918792 2023-04-06 02:30:56.909 27 ERROR keystone.server.flask.application   File "/var/lib/kolla/venv/lib/python3.9/site-packages/flask/app.py", line 1796, in dispatch_request
2023-04-06 02:30:56.918802 2023-04-06 02:30:56.909 27 ERROR keystone.server.flask.application     return self.ensure_sync(self.view_functions[rule.endpoint])(**view_args)
2023-04-06 02:30:56.918812 2023-04-06 02:30:56.909 27 ERROR keystone.server.flask.application   File "/var/lib/kolla/venv/lib/python3.9/site-packages/flask_restful/__init__.py", line 467, in wrapper
2023-04-06 02:30:56.918822 2023-04-06 02:30:56.909 27 ERROR keystone.server.flask.application     resp = resource(*args, **kwargs)
2023-04-06 02:30:56.918885 2023-04-06 02:30:56.909 27 ERROR keystone.server.flask.application   File "/var/lib/kolla/venv/lib/python3.9/site-packages/flask/views.py", line 107, in view
2023-04-06 02:30:56.918906 2023-04-06 02:30:56.909 27 ERROR keystone.server.flask.application     return current_app.ensure_sync(self.dispatch_request)(**kwargs)
2023-04-06 02:30:56.918918 2023-04-06 02:30:56.909 27 ERROR keystone.server.flask.application   File "/var/lib/kolla/venv/lib/python3.9/site-packages/flask_restful/__init__.py", line 582, in dispatch_request
2023-04-06 02:30:56.918949 2023-04-06 02:30:56.909 27 ERROR keystone.server.flask.application     resp = meth(*args, **kwargs)
2023-04-06 02:30:56.918961 2023-04-06 02:30:56.909 27 ERROR keystone.server.flask.application   File "/var/lib/kolla/venv/lib/python3.9/site-packages/keystone/api/roles.py", line 50, in get
2023-04-06 02:30:56.918970 2023-04-06 02:30:56.909 27 ERROR keystone.server.flask.application     return self._get_role(role_id)
2023-04-06 02:30:56.918980 2023-04-06 02:30:56.909 27 ERROR keystone.server.flask.application   File "/var/lib/kolla/venv/lib/python3.9/site-packages/keystone/api/roles.py", line 70, in _get_role
2023-04-06 02:30:56.918990 2023-04-06 02:30:56.909 27 ERROR keystone.server.flask.application     ENFORCER.enforce_call(action='identity:get_role')
2023-04-06 02:30:56.919006 2023-04-06 02:30:56.909 27 ERROR keystone.server.flask.application   File "/var/lib/kolla/venv/lib/python3.9/site-packages/keystone/common/rbac_enforcer/enforcer.py", line 402, in enforce_call
2023-04-06 02:30:56.919018 2023-04-06 02:30:56.909 27 ERROR keystone.server.flask.application     policy_dict.update(cls._extract_member_target_data(
2023-04-06 02:30:56.919034 2023-04-06 02:30:56.909 27 ERROR keystone.server.flask.application   File "/var/lib/kolla/venv/lib/python3.9/site-packages/keystone/common/rbac_enforcer/enforcer.py", line 234, in _extract_member_target_data
2023-04-06 02:30:56.919046 2023-04-06 02:30:56.909 27 ERROR keystone.server.flask.application     member_name: func(flask.request.view_args[key])
2023-04-06 02:30:56.919055 2023-04-06 02:30:56.909 27 ERROR keystone.server.flask.application   File "/var/lib/kolla/venv/lib/python3.9/site-packages/keystone/common/manager.py", line 115, in wrapped
2023-04-06 02:30:56.919065 2023-04-06 02:30:56.909 27 ERROR keystone.server.flask.application     __ret_val = __f(*args, **kwargs)
2023-04-06 02:30:56.919075 2023-04-06 02:30:56.909 27 ERROR keystone.server.flask.application   File "/var/lib/kolla/venv/lib/python3.9/site-packages/decorator.py", line 232, in fun
2023-04-06 02:30:56.919084 2023-04-06 02:30:56.909 27 ERROR keystone.server.flask.application     return caller(func, *(extras + args), **kw)
2023-04-06 02:30:56.919094 2023-04-06 02:30:56.909 27 ERROR keystone.server.flask.application   File "/var/lib/kolla/venv/lib/python3.9/site-packages/dogpile/cache/region.py", line 1577, in get_or_create_for_user_func
2023-04-06 02:30:56.919104 2023-04-06 02:30:56.909 27 ERROR keystone.server.flask.application     return self.get_or_create(
2023-04-06 02:30:56.919113 2023-04-06 02:30:56.909 27 ERROR keystone.server.flask.application   File "/var/lib/kolla/venv/lib/python3.9/site-packages/dogpile/cache/region.py", line 1042, in get_or_create
2023-04-06 02:30:56.919126 2023-04-06 02:30:56.909 27 ERROR keystone.server.flask.application     with Lock(
2023-04-06 02:30:56.919139 2023-04-06 02:30:56.909 27 ERROR keystone.server.flask.application   File "/var/lib/kolla/venv/lib/python3.9/site-packages/dogpile/lock.py", line 185, in __enter__
2023-04-06 02:30:56.919156 2023-04-06 02:30:56.909 27 ERROR keystone.server.flask.application     return self._enter()
2023-04-06 02:30:56.919165 2023-04-06 02:30:56.909 27 ERROR keystone.server.flask.application   File "/var/lib/kolla/venv/lib/python3.9/site-packages/dogpile/lock.py", line 94, in _enter
2023-04-06 02:30:56.919175 2023-04-06 02:30:56.909 27 ERROR keystone.server.flask.application     generated = self._enter_create(value, createdtime)
2023-04-06 02:30:56.919184 2023-04-06 02:30:56.909 27 ERROR keystone.server.flask.application   File "/var/lib/kolla/venv/lib/python3.9/site-packages/dogpile/lock.py", line 178, in _enter_create
2023-04-06 02:30:56.919194 2023-04-06 02:30:56.909 27 ERROR keystone.server.flask.application     return self.creator()
2023-04-06 02:30:56.919203 2023-04-06 02:30:56.909 27 ERROR keystone.server.flask.application   File "/var/lib/kolla/venv/lib/python3.9/site-packages/dogpile/cache/region.py", line 995, in gen_value
2023-04-06 02:30:56.919231 2023-04-06 02:30:56.909 27 ERROR keystone.server.flask.application     created_value = creator(
2023-04-06 02:30:56.919243 2023-04-06 02:30:56.909 27 ERROR keystone.server.flask.application   File "/var/lib/kolla/venv/lib/python3.9/site-packages/keystone/assignment/core.py", line 1276, in get_role
2023-04-06 02:30:56.919253 2023-04-06 02:30:56.909 27 ERROR keystone.server.flask.application     return self.driver.get_role(role_id)
2023-04-06 02:30:56.919263 2023-04-06 02:30:56.909 27 ERROR keystone.server.flask.application   File "/var/lib/kolla/venv/lib/python3.9/site-packages/keystone/assignment/role_backends/sql.py", line 70, in get_role
2023-04-06 02:30:56.919273 2023-04-06 02:30:56.909 27 ERROR keystone.server.flask.application     return self._get_role(session, role_id).to_dict()
2023-04-06 02:30:56.919283 2023-04-06 02:30:56.909 27 ERROR keystone.server.flask.application   File "/var/lib/kolla/venv/lib/python3.9/site-packages/keystone/assignment/role_backends/sql.py", line 65, in _get_role
2023-04-06 02:30:56.919293 2023-04-06 02:30:56.909 27 ERROR keystone.server.flask.application     raise exception.RoleNotFound(role_id=role_id)
2023-04-06 02:30:56.919302 2023-04-06 02:30:56.909 27 ERROR keystone.server.flask.application keystone.exception.RoleNotFound: Could not find role: admin.
2023-04-06 02:30:56.919312 2023-04-06 02:30:56.909 27 ERROR keystone.server.flask.application \x1b[00m
2023-04-06 02:30:58.199909 2023-04-06 02:30:58.187 27 ERROR keystone.server.flask.application [None req-79cc684e-9096-4ef3-9102-6aa3b3ca2dce 2f9bbb60059d4f7b8a2c5bcc145402cd - - all default -] Could not find user: ironic.: keystone.exception.UserNotFound: Could not find user: ironic.
2023-04-06 02:30:58.199953 2023-04-06 02:30:58.187 27 ERROR keystone.server.flask.application Traceback (most recent call last):
2023-04-06 02:30:58.199964 2023-04-06 02:30:58.187 27 ERROR keystone.server.flask.application   File "/var/lib/kolla/venv/lib/python3.9/site-packages/flask/app.py", line 1820, in full_dispatch_request
2023-04-06 02:30:58.199975 2023-04-06 02:30:58.187 27 ERROR keystone.server.flask.application     rv = self.dispatch_request()
2023-04-06 02:30:58.199984 2023-04-06 02:30:58.187 27 ERROR keystone.server.flask.application   File "/var/lib/kolla/venv/lib/python3.9/site-packages/flask/app.py", line 1796, in dispatch_request
2023-04-06 02:30:58.199995 2023-04-06 02:30:58.187 27 ERROR keystone.server.flask.application     return self.ensure_sync(self.view_functions[rule.endpoint])(**view_args)
2023-04-06 02:30:58.200004 2023-04-06 02:30:58.187 27 ERROR keystone.server.flask.application   File "/var/lib/kolla/venv/lib/python3.9/site-packages/flask_restful/__init__.py", line 467, in wrapper
2023-04-06 02:30:58.200014 2023-04-06 02:30:58.187 27 ERROR keystone.server.flask.application     resp = resource(*args, **kwargs)
2023-04-06 02:30:58.200024 2023-04-06 02:30:58.187 27 ERROR keystone.server.flask.application   File "/var/lib/kolla/venv/lib/python3.9/site-packages/flask/views.py", line 107, in view
2023-04-06 02:30:58.200034 2023-04-06 02:30:58.187 27 ERROR keystone.server.flask.application     return current_app.ensure_sync(self.dispatch_request)(**kwargs)
2023-04-06 02:30:58.200044 2023-04-06 02:30:58.187 27 ERROR keystone.server.flask.application   File "/var/lib/kolla/venv/lib/python3.9/site-packages/flask_restful/__init__.py", line 582, in dispatch_request
2023-04-06 02:30:58.200054 2023-04-06 02:30:58.187 27 ERROR keystone.server.flask.application     resp = meth(*args, **kwargs)
2023-04-06 02:30:58.200063 2023-04-06 02:30:58.187 27 ERROR keystone.server.flask.application   File "/var/lib/kolla/venv/lib/python3.9/site-packages/keystone/api/users.py", line 182, in get
2023-04-06 02:30:58.200073 2023-04-06 02:30:58.187 27 ERROR keystone.server.flask.application     return self._get_user(user_id)
2023-04-06 02:30:58.200082 2023-04-06 02:30:58.187 27 ERROR keystone.server.flask.application   File "/var/lib/kolla/venv/lib/python3.9/site-packages/keystone/api/users.py", line 194, in _get_user
2023-04-06 02:30:58.200148 2023-04-06 02:30:58.187 27 ERROR keystone.server.flask.application     ref = PROVIDERS.identity_api.get_user(user_id)
2023-04-06 02:30:58.200160 2023-04-06 02:30:58.187 27 ERROR keystone.server.flask.application   File "/var/lib/kolla/venv/lib/python3.9/site-packages/keystone/common/manager.py", line 115, in wrapped
2023-04-06 02:30:58.200170 2023-04-06 02:30:58.187 27 ERROR keystone.server.flask.application     __ret_val = __f(*args, **kwargs)
2023-04-06 02:30:58.200180 2023-04-06 02:30:58.187 27 ERROR keystone.server.flask.application   File "/var/lib/kolla/venv/lib/python3.9/site-packages/keystone/identity/core.py", line 414, in wrapper
2023-04-06 02:30:58.200189 2023-04-06 02:30:58.187 27 ERROR keystone.server.flask.application     return f(self, *args, **kwargs)
2023-04-06 02:30:58.200199 2023-04-06 02:30:58.187 27 ERROR keystone.server.flask.application   File "/var/lib/kolla/venv/lib/python3.9/site-packages/keystone/identity/core.py", line 424, in wrapper
2023-04-06 02:30:58.200209 2023-04-06 02:30:58.187 27 ERROR keystone.server.flask.application     return f(self, *args, **kwargs)
2023-04-06 02:30:58.200218 2023-04-06 02:30:58.187 27 ERROR keystone.server.flask.application   File "/var/lib/kolla/venv/lib/python3.9/site-packages/decorator.py", line 232, in fun
2023-04-06 02:30:58.200228 2023-04-06 02:30:58.187 27 ERROR keystone.server.flask.application     return caller(func, *(extras + args), **kw)
2023-04-06 02:30:58.200238 2023-04-06 02:30:58.187 27 ERROR keystone.server.flask.application   File "/var/lib/kolla/venv/lib/python3.9/site-packages/dogpile/cache/region.py", line 1577, in get_or_create_for_user_func
2023-04-06 02:30:58.200248 2023-04-06 02:30:58.187 27 ERROR keystone.server.flask.application     return self.get_or_create(
2023-04-06 02:30:58.200257 2023-04-06 02:30:58.187 27 ERROR keystone.server.flask.application   File "/var/lib/kolla/venv/lib/python3.9/site-packages/dogpile/cache/region.py", line 1042, in get_or_create
2023-04-06 02:30:58.200267 2023-04-06 02:30:58.187 27 ERROR keystone.server.flask.application     with Lock(
2023-04-06 02:30:58.200277 2023-04-06 02:30:58.187 27 ERROR keystone.server.flask.application   File "/var/lib/kolla/venv/lib/python3.9/site-packages/dogpile/lock.py", line 185, in __enter__
2023-04-06 02:30:58.200286 2023-04-06 02:30:58.187 27 ERROR keystone.server.flask.application     return self._enter()
2023-04-06 02:30:58.200296 2023-04-06 02:30:58.187 27 ERROR keystone.server.flask.application   File "/var/lib/kolla/venv/lib/python3.9/site-packages/dogpile/lock.py", line 94, in _enter
2023-04-06 02:30:58.200305 2023-04-06 02:30:58.187 27 ERROR keystone.server.flask.application     generated = self._enter_create(value, createdtime)
2023-04-06 02:30:58.200315 2023-04-06 02:30:58.187 27 ERROR keystone.server.flask.application   File "/var/lib/kolla/venv/lib/python3.9/site-packages/dogpile/lock.py", line 178, in _enter_create
2023-04-06 02:30:58.200371 2023-04-06 02:30:58.187 27 ERROR keystone.server.flask.application     return self.creator()
2023-04-06 02:30:58.200386 2023-04-06 02:30:58.187 27 ERROR keystone.server.flask.application   File "/var/lib/kolla/venv/lib/python3.9/site-packages/dogpile/cache/region.py", line 995, in gen_value
2023-04-06 02:30:58.200396 2023-04-06 02:30:58.187 27 ERROR keystone.server.flask.application     created_value = creator(
2023-04-06 02:30:58.200406 2023-04-06 02:30:58.187 27 ERROR keystone.server.flask.application   File "/var/lib/kolla/venv/lib/python3.9/site-packages/keystone/identity/core.py", line 1011, in get_user
2023-04-06 02:30:58.200416 2023-04-06 02:30:58.187 27 ERROR keystone.server.flask.application     ref = driver.get_user(entity_id)
2023-04-06 02:30:58.200426 2023-04-06 02:30:58.187 27 ERROR keystone.server.flask.application   File "/var/lib/kolla/venv/lib/python3.9/site-packages/keystone/identity/backends/sql.py", line 200, in get_user
2023-04-06 02:30:58.200436 2023-04-06 02:30:58.187 27 ERROR keystone.server.flask.application     self._get_user(session, user_id).to_dict())
2023-04-06 02:30:58.200471 2023-04-06 02:30:58.187 27 ERROR keystone.server.flask.application   File "/var/lib/kolla/venv/lib/python3.9/site-packages/keystone/identity/backends/sql.py", line 194, in _get_user
2023-04-06 02:30:58.200484 2023-04-06 02:30:58.187 27 ERROR keystone.server.flask.application     raise exception.UserNotFound(user_id=user_id)
2023-04-06 02:30:58.200494 2023-04-06 02:30:58.187 27 ERROR keystone.server.flask.application keystone.exception.UserNotFound: Could not find user: ironic.
2023-04-06 02:30:58.200503 2023-04-06 02:30:58.187 27 ERROR keystone.server.flask.application \x1b[00m
2023-04-06 02:30:59.185897 2023-04-06 02:30:59.166 28 ERROR keystone.server.flask.application [None req-888e5b24-5ffb-4a44-a679-160ef354b52e 2f9bbb60059d4f7b8a2c5bcc145402cd - - all default -] Could not find project: service.: keystone.exception.ProjectNotFound: Could not find project: service.
2023-04-06 02:30:59.185942 2023-04-06 02:30:59.166 28 ERROR keystone.server.flask.application Traceback (most recent call last):
2023-04-06 02:30:59.185955 2023-04-06 02:30:59.166 28 ERROR keystone.server.flask.application   File "/var/lib/kolla/venv/lib/python3.9/site-packages/flask/app.py", line 1820, in full_dispatch_request
2023-04-06 02:30:59.185967 2023-04-06 02:30:59.166 28 ERROR keystone.server.flask.application     rv = self.dispatch_request()
2023-04-06 02:30:59.185978 2023-04-06 02:30:59.166 28 ERROR keystone.server.flask.application   File "/var/lib/kolla/venv/lib/python3.9/site-packages/flask/app.py", line 1796, in dispatch_request
2023-04-06 02:30:59.185989 2023-04-06 02:30:59.166 28 ERROR keystone.server.flask.application     return self.ensure_sync(self.view_functions[rule.endpoint])(**view_args)
2023-04-06 02:30:59.186000 2023-04-06 02:30:59.166 28 ERROR keystone.server.flask.application   File "/var/lib/kolla/venv/lib/python3.9/site-packages/flask_restful/__init__.py", line 467, in wrapper
2023-04-06 02:30:59.186011 2023-04-06 02:30:59.166 28 ERROR keystone.server.flask.application     resp = resource(*args, **kwargs)
2023-04-06 02:30:59.186030 2023-04-06 02:30:59.166 28 ERROR keystone.server.flask.application   File "/var/lib/kolla/venv/lib/python3.9/site-packages/flask/views.py", line 107, in view
2023-04-06 02:30:59.186045 2023-04-06 02:30:59.166 28 ERROR keystone.server.flask.application     return current_app.ensure_sync(self.dispatch_request)(**kwargs)
2023-04-06 02:30:59.186056 2023-04-06 02:30:59.166 28 ERROR keystone.server.flask.application   File "/var/lib/kolla/venv/lib/python3.9/site-packages/flask_restful/__init__.py", line 582, in dispatch_request
2023-04-06 02:30:59.186067 2023-04-06 02:30:59.166 28 ERROR keystone.server.flask.application     resp = meth(*args, **kwargs)
2023-04-06 02:30:59.186077 2023-04-06 02:30:59.166 28 ERROR keystone.server.flask.application   File "/var/lib/kolla/venv/lib/python3.9/site-packages/keystone/api/projects.py", line 151, in get
2023-04-06 02:30:59.186089 2023-04-06 02:30:59.166 28 ERROR keystone.server.flask.application     return self._get_project(project_id)
2023-04-06 02:30:59.186099 2023-04-06 02:30:59.166 28 ERROR keystone.server.flask.application   File "/var/lib/kolla/venv/lib/python3.9/site-packages/keystone/api/projects.py", line 107, in _get_project
2023-04-06 02:30:59.186110 2023-04-06 02:30:59.166 28 ERROR keystone.server.flask.application     project = PROVIDERS.resource_api.get_project(project_id)
2023-04-06 02:30:59.186121 2023-04-06 02:30:59.166 28 ERROR keystone.server.flask.application   File "/var/lib/kolla/venv/lib/python3.9/site-packages/keystone/common/manager.py", line 115, in wrapped
2023-04-06 02:30:59.186132 2023-04-06 02:30:59.166 28 ERROR keystone.server.flask.application     __ret_val = __f(*args, **kwargs)
2023-04-06 02:30:59.186143 2023-04-06 02:30:59.166 28 ERROR keystone.server.flask.application   File "/var/lib/kolla/venv/lib/python3.9/site-packages/decorator.py", line 232, in fun
2023-04-06 02:30:59.186154 2023-04-06 02:30:59.166 28 ERROR keystone.server.flask.application     return caller(func, *(extras + args), **kw)
2023-04-06 02:30:59.186198 2023-04-06 02:30:59.166 28 ERROR keystone.server.flask.application   File "/var/lib/kolla/venv/lib/python3.9/site-packages/dogpile/cache/region.py", line 1577, in get_or_create_for_user_func
2023-04-06 02:30:59.186211 2023-04-06 02:30:59.166 28 ERROR keystone.server.flask.application     return self.get_or_create(
2023-04-06 02:30:59.186222 2023-04-06 02:30:59.166 28 ERROR keystone.server.flask.application   File "/var/lib/kolla/venv/lib/python3.9/site-packages/dogpile/cache/region.py", line 1042, in get_or_create
2023-04-06 02:30:59.186234 2023-04-06 02:30:59.166 28 ERROR keystone.server.flask.application     with Lock(
2023-04-06 02:30:59.186245 2023-04-06 02:30:59.166 28 ERROR keystone.server.flask.application   File "/var/lib/kolla/venv/lib/python3.9/site-packages/dogpile/lock.py", line 185, in __enter__
2023-04-06 02:30:59.186256 2023-04-06 02:30:59.166 28 ERROR keystone.server.flask.application     return self._enter()
2023-04-06 02:30:59.186266 2023-04-06 02:30:59.166 28 ERROR keystone.server.flask.application   File "/var/lib/kolla/venv/lib/python3.9/site-packages/dogpile/lock.py", line 94, in _enter
2023-04-06 02:30:59.186278 2023-04-06 02:30:59.166 28 ERROR keystone.server.flask.application     generated = self._enter_create(value, createdtime)
2023-04-06 02:30:59.186288 2023-04-06 02:30:59.166 28 ERROR keystone.server.flask.application   File "/var/lib/kolla/venv/lib/python3.9/site-packages/dogpile/lock.py", line 178, in _enter_create
2023-04-06 02:30:59.186299 2023-04-06 02:30:59.166 28 ERROR keystone.server.flask.application     return self.creator()
2023-04-06 02:30:59.186310 2023-04-06 02:30:59.166 28 ERROR keystone.server.flask.application   File "/var/lib/kolla/venv/lib/python3.9/site-packages/dogpile/cache/region.py", line 995, in gen_value
2023-04-06 02:30:59.186347 2023-04-06 02:30:59.166 28 ERROR keystone.server.flask.application     created_value = creator(
2023-04-06 02:30:59.186372 2023-04-06 02:30:59.166 28 ERROR keystone.server.flask.application   File "/var/lib/kolla/venv/lib/python3.9/site-packages/keystone/resource/core.py", line 903, in get_project
2023-04-06 02:30:59.186384 2023-04-06 02:30:59.166 28 ERROR keystone.server.flask.application     return self.driver.get_project(project_id)
2023-04-06 02:30:59.186395 2023-04-06 02:30:59.166 28 ERROR keystone.server.flask.application   File "/var/lib/kolla/venv/lib/python3.9/site-packages/keystone/resource/backends/sql.py", line 49, in get_project
2023-04-06 02:30:59.186406 2023-04-06 02:30:59.166 28 ERROR keystone.server.flask.application     return self._get_project(session, project_id).to_dict()
2023-04-06 02:30:59.186417 2023-04-06 02:30:59.166 28 ERROR keystone.server.flask.application   File "/var/lib/kolla/venv/lib/python3.9/site-packages/keystone/resource/backends/sql.py", line 44, in _get_project
2023-04-06 02:30:59.186428 2023-04-06 02:30:59.166 28 ERROR keystone.server.flask.application     raise exception.ProjectNotFound(project_id=project_id)
2023-04-06 02:30:59.186439 2023-04-06 02:30:59.166 28 ERROR keystone.server.flask.application keystone.exception.ProjectNotFound: Could not find project: service.
2023-04-06 02:30:59.186451 2023-04-06 02:30:59.166 28 ERROR keystone.server.flask.application \x1b[00m
2023-04-06 02:31:08.612349 2023-04-06 02:31:08.599 26 ERROR keystone.server.flask.application [None req-6f4d7a46-6d2e-47c6-9002-023997422ef9 2f9bbb60059d4f7b8a2c5bcc145402cd - - all default -] Could not find role: admin.: keystone.exception.RoleNotFound: Could not find role: admin.
2023-04-06 02:31:08.612403 2023-04-06 02:31:08.599 26 ERROR keystone.server.flask.application Traceback (most recent call last):
2023-04-06 02:31:08.612416 2023-04-06 02:31:08.599 26 ERROR keystone.server.flask.application   File "/var/lib/kolla/venv/lib/python3.9/site-packages/flask/app.py", line 1820, in full_dispatch_request
2023-04-06 02:31:08.612427 2023-04-06 02:31:08.599 26 ERROR keystone.server.flask.application     rv = self.dispatch_request()
2023-04-06 02:31:08.612437 2023-04-06 02:31:08.599 26 ERROR keystone.server.flask.application   File "/var/lib/kolla/venv/lib/python3.9/site-packages/flask/app.py", line 1796, in dispatch_request
2023-04-06 02:31:08.612477 2023-04-06 02:31:08.599 26 ERROR keystone.server.flask.application     return self.ensure_sync(self.view_functions[rule.endpoint])(**view_args)
2023-04-06 02:31:08.612489 2023-04-06 02:31:08.599 26 ERROR keystone.server.flask.application   File "/var/lib/kolla/venv/lib/python3.9/site-packages/flask_restful/__init__.py", line 467, in wrapper
2023-04-06 02:31:08.612500 2023-04-06 02:31:08.599 26 ERROR keystone.server.flask.application     resp = resource(*args, **kwargs)
2023-04-06 02:31:08.612515 2023-04-06 02:31:08.599 26 ERROR keystone.server.flask.application   File "/var/lib/kolla/venv/lib/python3.9/site-packages/flask/views.py", line 107, in view
2023-04-06 02:31:08.612528 2023-04-06 02:31:08.599 26 ERROR keystone.server.flask.application     return current_app.ensure_sync(self.dispatch_request)(**kwargs)
2023-04-06 02:31:08.612538 2023-04-06 02:31:08.599 26 ERROR keystone.server.flask.application   File "/var/lib/kolla/venv/lib/python3.9/site-packages/flask_restful/__init__.py", line 582, in dispatch_request
2023-04-06 02:31:08.612548 2023-04-06 02:31:08.599 26 ERROR keystone.server.flask.application     resp = meth(*args, **kwargs)
2023-04-06 02:31:08.612558 2023-04-06 02:31:08.599 26 ERROR keystone.server.flask.application   File "/var/lib/kolla/venv/lib/python3.9/site-packages/keystone/api/roles.py", line 50, in get
2023-04-06 02:31:08.612568 2023-04-06 02:31:08.599 26 ERROR keystone.server.flask.application     return self._get_role(role_id)
2023-04-06 02:31:08.612578 2023-04-06 02:31:08.599 26 ERROR keystone.server.flask.application   File "/var/lib/kolla/venv/lib/python3.9/site-packages/keystone/api/roles.py", line 70, in _get_role
2023-04-06 02:31:08.612588 2023-04-06 02:31:08.599 26 ERROR keystone.server.flask.application     ENFORCER.enforce_call(action='identity:get_role')
2023-04-06 02:31:08.612604 2023-04-06 02:31:08.599 26 ERROR keystone.server.flask.application   File "/var/lib/kolla/venv/lib/python3.9/site-packages/keystone/common/rbac_enforcer/enforcer.py", line 402, in enforce_call
2023-04-06 02:31:08.612617 2023-04-06 02:31:08.599 26 ERROR keystone.server.flask.application     policy_dict.update(cls._extract_member_target_data(
2023-04-06 02:31:08.612632 2023-04-06 02:31:08.599 26 ERROR keystone.server.flask.application   File "/var/lib/kolla/venv/lib/python3.9/site-packages/keystone/common/rbac_enforcer/enforcer.py", line 234, in _extract_member_target_data
2023-04-06 02:31:08.612655 2023-04-06 02:31:08.599 26 ERROR keystone.server.flask.application     member_name: func(flask.request.view_args[key])
2023-04-06 02:31:08.612665 2023-04-06 02:31:08.599 26 ERROR keystone.server.flask.application   File "/var/lib/kolla/venv/lib/python3.9/site-packages/keystone/common/manager.py", line 115, in wrapped
2023-04-06 02:31:08.612675 2023-04-06 02:31:08.599 26 ERROR keystone.server.flask.application     __ret_val = __f(*args, **kwargs)
2023-04-06 02:31:08.612685 2023-04-06 02:31:08.599 26 ERROR keystone.server.flask.application   File "/var/lib/kolla/venv/lib/python3.9/site-packages/decorator.py", line 232, in fun
2023-04-06 02:31:08.612695 2023-04-06 02:31:08.599 26 ERROR keystone.server.flask.application     return caller(func, *(extras + args), **kw)
2023-04-06 02:31:08.612705 2023-04-06 02:31:08.599 26 ERROR keystone.server.flask.application   File "/var/lib/kolla/venv/lib/python3.9/site-packages/dogpile/cache/region.py", line 1577, in get_or_create_for_user_func
2023-04-06 02:31:08.612744 2023-04-06 02:31:08.599 26 ERROR keystone.server.flask.application     return self.get_or_create(
2023-04-06 02:31:08.612754 2023-04-06 02:31:08.599 26 ERROR keystone.server.flask.application   File "/var/lib/kolla/venv/lib/python3.9/site-packages/dogpile/cache/region.py", line 1042, in get_or_create
2023-04-06 02:31:08.612765 2023-04-06 02:31:08.599 26 ERROR keystone.server.flask.application     with Lock(
2023-04-06 02:31:08.612793 2023-04-06 02:31:08.599 26 ERROR keystone.server.flask.application   File "/var/lib/kolla/venv/lib/python3.9/site-packages/dogpile/lock.py", line 185, in __enter__
2023-04-06 02:31:08.612805 2023-04-06 02:31:08.599 26 ERROR keystone.server.flask.application     return self._enter()
2023-04-06 02:31:08.612815 2023-04-06 02:31:08.599 26 ERROR keystone.server.flask.application   File "/var/lib/kolla/venv/lib/python3.9/site-packages/dogpile/lock.py", line 94, in _enter
2023-04-06 02:31:08.612825 2023-04-06 02:31:08.599 26 ERROR keystone.server.flask.application     generated = self._enter_create(value, createdtime)
2023-04-06 02:31:08.612836 2023-04-06 02:31:08.599 26 ERROR keystone.server.flask.application   File "/var/lib/kolla/venv/lib/python3.9/site-packages/dogpile/lock.py", line 178, in _enter_create
2023-04-06 02:31:08.612870 2023-04-06 02:31:08.599 26 ERROR keystone.server.flask.application     return self.creator()
2023-04-06 02:31:08.612882 2023-04-06 02:31:08.599 26 ERROR keystone.server.flask.application   File "/var/lib/kolla/venv/lib/python3.9/site-packages/dogpile/cache/region.py", line 995, in gen_value
2023-04-06 02:31:08.612892 2023-04-06 02:31:08.599 26 ERROR keystone.server.flask.application     created_value = creator(
2023-04-06 02:31:08.612902 2023-04-06 02:31:08.599 26 ERROR keystone.server.flask.application   File "/var/lib/kolla/venv/lib/python3.9/site-packages/keystone/assignment/core.py", line 1276, in get_role
2023-04-06 02:31:08.612912 2023-04-06 02:31:08.599 26 ERROR keystone.server.flask.application     return self.driver.get_role(role_id)
2023-04-06 02:31:08.612921 2023-04-06 02:31:08.599 26 ERROR keystone.server.flask.application   File "/var/lib/kolla/venv/lib/python3.9/site-packages/keystone/assignment/role_backends/sql.py", line 70, in get_role
2023-04-06 02:31:08.612932 2023-04-06 02:31:08.599 26 ERROR keystone.server.flask.application     return self._get_role(session, role_id).to_dict()
2023-04-06 02:31:08.612942 2023-04-06 02:31:08.599 26 ERROR keystone.server.flask.application   File "/var/lib/kolla/venv/lib/python3.9/site-packages/keystone/assignment/role_backends/sql.py", line 65, in _get_role
2023-04-06 02:31:08.612952 2023-04-06 02:31:08.599 26 ERROR keystone.server.flask.application     raise exception.RoleNotFound(role_id=role_id)
2023-04-06 02:31:08.612962 2023-04-06 02:31:08.599 26 ERROR keystone.server.flask.application keystone.exception.RoleNotFound: Could not find role: admin.
2023-04-06 02:31:08.612972 2023-04-06 02:31:08.599 26 ERROR keystone.server.flask.application \x1b[00m
2023-04-06 02:31:09.730768 2023-04-06 02:31:09.723 26 ERROR keystone.server.flask.application [None req-418d3c26-4680-419c-a61a-a75e76a0b951 2f9bbb60059d4f7b8a2c5bcc145402cd - - all default -] Could not find user: ironic-inspector.: keystone.exception.UserNotFound: Could not find user: ironic-inspector.
2023-04-06 02:31:09.730832 2023-04-06 02:31:09.723 26 ERROR keystone.server.flask.application Traceback (most recent call last):
2023-04-06 02:31:09.730864 2023-04-06 02:31:09.723 26 ERROR keystone.server.flask.application   File "/var/lib/kolla/venv/lib/python3.9/site-packages/flask/app.py", line 1820, in full_dispatch_request
2023-04-06 02:31:09.730889 2023-04-06 02:31:09.723 26 ERROR keystone.server.flask.application     rv = self.dispatch_request()
2023-04-06 02:31:09.730900 2023-04-06 02:31:09.723 26 ERROR keystone.server.flask.application   File "/var/lib/kolla/venv/lib/python3.9/site-packages/flask/app.py", line 1796, in dispatch_request
2023-04-06 02:31:09.730911 2023-04-06 02:31:09.723 26 ERROR keystone.server.flask.application     return self.ensure_sync(self.view_functions[rule.endpoint])(**view_args)
2023-04-06 02:31:09.730921 2023-04-06 02:31:09.723 26 ERROR keystone.server.flask.application   File "/var/lib/kolla/venv/lib/python3.9/site-packages/flask_restful/__init__.py", line 467, in wrapper
2023-04-06 02:31:09.730932 2023-04-06 02:31:09.723 26 ERROR keystone.server.flask.application     resp = resource(*args, **kwargs)
2023-04-06 02:31:09.730943 2023-04-06 02:31:09.723 26 ERROR keystone.server.flask.application   File "/var/lib/kolla/venv/lib/python3.9/site-packages/flask/views.py", line 107, in view
2023-04-06 02:31:09.730983 2023-04-06 02:31:09.723 26 ERROR keystone.server.flask.application     return current_app.ensure_sync(self.dispatch_request)(**kwargs)
2023-04-06 02:31:09.730997 2023-04-06 02:31:09.723 26 ERROR keystone.server.flask.application   File "/var/lib/kolla/venv/lib/python3.9/site-packages/flask_restful/__init__.py", line 582, in dispatch_request
2023-04-06 02:31:09.731007 2023-04-06 02:31:09.723 26 ERROR keystone.server.flask.application     resp = meth(*args, **kwargs)
2023-04-06 02:31:09.731018 2023-04-06 02:31:09.723 26 ERROR keystone.server.flask.application   File "/var/lib/kolla/venv/lib/python3.9/site-packages/keystone/api/users.py", line 182, in get
2023-04-06 02:31:09.731028 2023-04-06 02:31:09.723 26 ERROR keystone.server.flask.application     return self._get_user(user_id)
2023-04-06 02:31:09.731039 2023-04-06 02:31:09.723 26 ERROR keystone.server.flask.application   File "/var/lib/kolla/venv/lib/python3.9/site-packages/keystone/api/users.py", line 194, in _get_user
2023-04-06 02:31:09.731049 2023-04-06 02:31:09.723 26 ERROR keystone.server.flask.application     ref = PROVIDERS.identity_api.get_user(user_id)
2023-04-06 02:31:09.731060 2023-04-06 02:31:09.723 26 ERROR keystone.server.flask.application   File "/var/lib/kolla/venv/lib/python3.9/site-packages/keystone/common/manager.py", line 115, in wrapped
2023-04-06 02:31:09.731070 2023-04-06 02:31:09.723 26 ERROR keystone.server.flask.application     __ret_val = __f(*args, **kwargs)
2023-04-06 02:31:09.731081 2023-04-06 02:31:09.723 26 ERROR keystone.server.flask.application   File "/var/lib/kolla/venv/lib/python3.9/site-packages/keystone/identity/core.py", line 414, in wrapper
2023-04-06 02:31:09.731091 2023-04-06 02:31:09.723 26 ERROR keystone.server.flask.application     return f(self, *args, **kwargs)
2023-04-06 02:31:09.731102 2023-04-06 02:31:09.723 26 ERROR keystone.server.flask.application   File "/var/lib/kolla/venv/lib/python3.9/site-packages/keystone/identity/core.py", line 424, in wrapper
2023-04-06 02:31:09.731113 2023-04-06 02:31:09.723 26 ERROR keystone.server.flask.application     return f(self, *args, **kwargs)
2023-04-06 02:31:09.731123 2023-04-06 02:31:09.723 26 ERROR keystone.server.flask.application   File "/var/lib/kolla/venv/lib/python3.9/site-packages/decorator.py", line 232, in fun
2023-04-06 02:31:09.731134 2023-04-06 02:31:09.723 26 ERROR keystone.server.flask.application     return caller(func, *(extras + args), **kw)
2023-04-06 02:31:09.731158 2023-04-06 02:31:09.723 26 ERROR keystone.server.flask.application   File "/var/lib/kolla/venv/lib/python3.9/site-packages/dogpile/cache/region.py", line 1577, in get_or_create_for_user_func
2023-04-06 02:31:09.731168 2023-04-06 02:31:09.723 26 ERROR keystone.server.flask.application     return self.get_or_create(
2023-04-06 02:31:09.731179 2023-04-06 02:31:09.723 26 ERROR keystone.server.flask.application   File "/var/lib/kolla/venv/lib/python3.9/site-packages/dogpile/cache/region.py", line 1042, in get_or_create
2023-04-06 02:31:09.731198 2023-04-06 02:31:09.723 26 ERROR keystone.server.flask.application     with Lock(
2023-04-06 02:31:09.731221 2023-04-06 02:31:09.723 26 ERROR keystone.server.flask.application   File "/var/lib/kolla/venv/lib/python3.9/site-packages/dogpile/lock.py", line 185, in __enter__
2023-04-06 02:31:09.731239 2023-04-06 02:31:09.723 26 ERROR keystone.server.flask.application     return self._enter()
2023-04-06 02:31:09.731249 2023-04-06 02:31:09.723 26 ERROR keystone.server.flask.application   File "/var/lib/kolla/venv/lib/python3.9/site-packages/dogpile/lock.py", line 94, in _enter
2023-04-06 02:31:09.731260 2023-04-06 02:31:09.723 26 ERROR keystone.server.flask.application     generated = self._enter_create(value, createdtime)
2023-04-06 02:31:09.731270 2023-04-06 02:31:09.723 26 ERROR keystone.server.flask.application   File "/var/lib/kolla/venv/lib/python3.9/site-packages/dogpile/lock.py", line 178, in _enter_create
2023-04-06 02:31:09.731308 2023-04-06 02:31:09.723 26 ERROR keystone.server.flask.application     return self.creator()
2023-04-06 02:31:09.731346 2023-04-06 02:31:09.723 26 ERROR keystone.server.flask.application   File "/var/lib/kolla/venv/lib/python3.9/site-packages/dogpile/cache/region.py", line 995, in gen_value
2023-04-06 02:31:09.731363 2023-04-06 02:31:09.723 26 ERROR keystone.server.flask.application     created_value = creator(
2023-04-06 02:31:09.731374 2023-04-06 02:31:09.723 26 ERROR keystone.server.flask.application   File "/var/lib/kolla/venv/lib/python3.9/site-packages/keystone/identity/core.py", line 1011, in get_user
2023-04-06 02:31:09.731385 2023-04-06 02:31:09.723 26 ERROR keystone.server.flask.application     ref = driver.get_user(entity_id)
2023-04-06 02:31:09.731395 2023-04-06 02:31:09.723 26 ERROR keystone.server.flask.application   File "/var/lib/kolla/venv/lib/python3.9/site-packages/keystone/identity/backends/sql.py", line 200, in get_user
2023-04-06 02:31:09.731406 2023-04-06 02:31:09.723 26 ERROR keystone.server.flask.application     self._get_user(session, user_id).to_dict())
2023-04-06 02:31:09.731416 2023-04-06 02:31:09.723 26 ERROR keystone.server.flask.application   File "/var/lib/kolla/venv/lib/python3.9/site-packages/keystone/identity/backends/sql.py", line 194, in _get_user
2023-04-06 02:31:09.731427 2023-04-06 02:31:09.723 26 ERROR keystone.server.flask.application     raise exception.UserNotFound(user_id=user_id)
2023-04-06 02:31:09.731437 2023-04-06 02:31:09.723 26 ERROR keystone.server.flask.application keystone.exception.UserNotFound: Could not find user: ironic-inspector.
2023-04-06 02:31:09.731448 2023-04-06 02:31:09.723 26 ERROR keystone.server.flask.application \x1b[00m
2023-04-06 02:31:10.515978 2023-04-06 02:31:10.511 27 ERROR keystone.server.flask.application [None req-edc722d3-0850-486f-8703-5cfeb55b6fe6 2f9bbb60059d4f7b8a2c5bcc145402cd - - all default -] Could not find project: service.: keystone.exception.ProjectNotFound: Could not find project: service.
2023-04-06 02:31:10.516071 2023-04-06 02:31:10.511 27 ERROR keystone.server.flask.application Traceback (most recent call last):
2023-04-06 02:31:10.516140 2023-04-06 02:31:10.511 27 ERROR keystone.server.flask.application   File "/var/lib/kolla/venv/lib/python3.9/site-packages/flask/app.py", line 1820, in full_dispatch_request
2023-04-06 02:31:10.516162 2023-04-06 02:31:10.511 27 ERROR keystone.server.flask.application     rv = self.dispatch_request()
2023-04-06 02:31:10.516183 2023-04-06 02:31:10.511 27 ERROR keystone.server.flask.application   File "/var/lib/kolla/venv/lib/python3.9/site-packages/flask/app.py", line 1796, in dispatch_request
2023-04-06 02:31:10.516204 2023-04-06 02:31:10.511 27 ERROR keystone.server.flask.application     return self.ensure_sync(self.view_functions[rule.endpoint])(**view_args)
2023-04-06 02:31:10.516224 2023-04-06 02:31:10.511 27 ERROR keystone.server.flask.application   File "/var/lib/kolla/venv/lib/python3.9/site-packages/flask_restful/__init__.py", line 467, in wrapper
2023-04-06 02:31:10.516236 2023-04-06 02:31:10.511 27 ERROR keystone.server.flask.application     resp = resource(*args, **kwargs)
2023-04-06 02:31:10.516264 2023-04-06 02:31:10.511 27 ERROR keystone.server.flask.application   File "/var/lib/kolla/venv/lib/python3.9/site-packages/flask/views.py", line 107, in view
2023-04-06 02:31:10.516283 2023-04-06 02:31:10.511 27 ERROR keystone.server.flask.application     return current_app.ensure_sync(self.dispatch_request)(**kwargs)
2023-04-06 02:31:10.516295 2023-04-06 02:31:10.511 27 ERROR keystone.server.flask.application   File "/var/lib/kolla/venv/lib/python3.9/site-packages/flask_restful/__init__.py", line 582, in dispatch_request
2023-04-06 02:31:10.516305 2023-04-06 02:31:10.511 27 ERROR keystone.server.flask.application     resp = meth(*args, **kwargs)
2023-04-06 02:31:10.516314 2023-04-06 02:31:10.511 27 ERROR keystone.server.flask.application   File "/var/lib/kolla/venv/lib/python3.9/site-packages/keystone/api/projects.py", line 151, in get
2023-04-06 02:31:10.516400 2023-04-06 02:31:10.511 27 ERROR keystone.server.flask.application     return self._get_project(project_id)
2023-04-06 02:31:10.516416 2023-04-06 02:31:10.511 27 ERROR keystone.server.flask.application   File "/var/lib/kolla/venv/lib/python3.9/site-packages/keystone/api/projects.py", line 107, in _get_project
2023-04-06 02:31:10.516426 2023-04-06 02:31:10.511 27 ERROR keystone.server.flask.application     project = PROVIDERS.resource_api.get_project(project_id)
2023-04-06 02:31:10.516436 2023-04-06 02:31:10.511 27 ERROR keystone.server.flask.application   File "/var/lib/kolla/venv/lib/python3.9/site-packages/keystone/common/manager.py", line 115, in wrapped
2023-04-06 02:31:10.516446 2023-04-06 02:31:10.511 27 ERROR keystone.server.flask.application     __ret_val = __f(*args, **kwargs)
2023-04-06 02:31:10.516456 2023-04-06 02:31:10.511 27 ERROR keystone.server.flask.application   File "/var/lib/kolla/venv/lib/python3.9/site-packages/decorator.py", line 232, in fun
2023-04-06 02:31:10.516466 2023-04-06 02:31:10.511 27 ERROR keystone.server.flask.application     return caller(func, *(extras + args), **kw)
2023-04-06 02:31:10.516484 2023-04-06 02:31:10.511 27 ERROR keystone.server.flask.application   File "/var/lib/kolla/venv/lib/python3.9/site-packages/dogpile/cache/region.py", line 1577, in get_or_create_for_user_func
2023-04-06 02:31:10.516496 2023-04-06 02:31:10.511 27 ERROR keystone.server.flask.application     return self.get_or_create(
2023-04-06 02:31:10.516506 2023-04-06 02:31:10.511 27 ERROR keystone.server.flask.application   File "/var/lib/kolla/venv/lib/python3.9/site-packages/dogpile/cache/region.py", line 1042, in get_or_create
2023-04-06 02:31:10.516516 2023-04-06 02:31:10.511 27 ERROR keystone.server.flask.application     with Lock(
2023-04-06 02:31:10.516526 2023-04-06 02:31:10.511 27 ERROR keystone.server.flask.application   File "/var/lib/kolla/venv/lib/python3.9/site-packages/dogpile/lock.py", line 185, in __enter__
2023-04-06 02:31:10.516536 2023-04-06 02:31:10.511 27 ERROR keystone.server.flask.application     return self._enter()
2023-04-06 02:31:10.516545 2023-04-06 02:31:10.511 27 ERROR keystone.server.flask.application   File "/var/lib/kolla/venv/lib/python3.9/site-packages/dogpile/lock.py", line 94, in _enter
2023-04-06 02:31:10.516555 2023-04-06 02:31:10.511 27 ERROR keystone.server.flask.application     generated = self._enter_create(value, createdtime)
2023-04-06 02:31:10.516565 2023-04-06 02:31:10.511 27 ERROR keystone.server.flask.application   File "/var/lib/kolla/venv/lib/python3.9/site-packages/dogpile/lock.py", line 178, in _enter_create
2023-04-06 02:31:10.516575 2023-04-06 02:31:10.511 27 ERROR keystone.server.flask.application     return self.creator()
2023-04-06 02:31:10.516584 2023-04-06 02:31:10.511 27 ERROR keystone.server.flask.application   File "/var/lib/kolla/venv/lib/python3.9/site-packages/dogpile/cache/region.py", line 995, in gen_value
2023-04-06 02:31:10.516597 2023-04-06 02:31:10.511 27 ERROR keystone.server.flask.application     created_value = creator(
2023-04-06 02:31:10.516618 2023-04-06 02:31:10.511 27 ERROR keystone.server.flask.application   File "/var/lib/kolla/venv/lib/python3.9/site-packages/keystone/resource/core.py", line 903, in get_project
2023-04-06 02:31:10.516637 2023-04-06 02:31:10.511 27 ERROR keystone.server.flask.application     return self.driver.get_project(project_id)
2023-04-06 02:31:10.516660 2023-04-06 02:31:10.511 27 ERROR keystone.server.flask.application   File "/var/lib/kolla/venv/lib/python3.9/site-packages/keystone/resource/backends/sql.py", line 49, in get_project
2023-04-06 02:31:10.516686 2023-04-06 02:31:10.511 27 ERROR keystone.server.flask.application     return self._get_project(session, project_id).to_dict()
2023-04-06 02:31:10.516708 2023-04-06 02:31:10.511 27 ERROR keystone.server.flask.application   File "/var/lib/kolla/venv/lib/python3.9/site-packages/keystone/resource/backends/sql.py", line 44, in _get_project
2023-04-06 02:31:10.516736 2023-04-06 02:31:10.511 27 ERROR keystone.server.flask.application     raise exception.ProjectNotFound(project_id=project_id)
2023-04-06 02:31:10.516790 2023-04-06 02:31:10.511 27 ERROR keystone.server.flask.application keystone.exception.ProjectNotFound: Could not find project: service.
2023-04-06 02:31:10.516812 2023-04-06 02:31:10.511 27 ERROR keystone.server.flask.application \x1b[00m
2023-04-06 02:34:04.170687 2023-04-06 02:34:04.166 28 ERROR keystone.server.flask.application [None req-43425a83-0d47-476c-833c-7ee250fa9916 2f9bbb60059d4f7b8a2c5bcc145402cd - - all default -] Could not find project: service.: keystone.exception.ProjectNotFound: Could not find project: service.
2023-04-06 02:34:04.170763 2023-04-06 02:34:04.166 28 ERROR keystone.server.flask.application Traceback (most recent call last):
2023-04-06 02:34:04.170776 2023-04-06 02:34:04.166 28 ERROR keystone.server.flask.application   File "/var/lib/kolla/venv/lib/python3.9/site-packages/flask/app.py", line 1820, in full_dispatch_request
2023-04-06 02:34:04.170787 2023-04-06 02:34:04.166 28 ERROR keystone.server.flask.application     rv = self.dispatch_request()
2023-04-06 02:34:04.170796 2023-04-06 02:34:04.166 28 ERROR keystone.server.flask.application   File "/var/lib/kolla/venv/lib/python3.9/site-packages/flask/app.py", line 1796, in dispatch_request
2023-04-06 02:34:04.170842 2023-04-06 02:34:04.166 28 ERROR keystone.server.flask.application     return self.ensure_sync(self.view_functions[rule.endpoint])(**view_args)
2023-04-06 02:34:04.170859 2023-04-06 02:34:04.166 28 ERROR keystone.server.flask.application   File "/var/lib/kolla/venv/lib/python3.9/site-packages/flask_restful/__init__.py", line 467, in wrapper
2023-04-06 02:34:04.170869 2023-04-06 02:34:04.166 28 ERROR keystone.server.flask.application     resp = resource(*args, **kwargs)
2023-04-06 02:34:04.170887 2023-04-06 02:34:04.166 28 ERROR keystone.server.flask.application   File "/var/lib/kolla/venv/lib/python3.9/site-packages/flask/views.py", line 107, in view
2023-04-06 02:34:04.170899 2023-04-06 02:34:04.166 28 ERROR keystone.server.flask.application     return current_app.ensure_sync(self.dispatch_request)(**kwargs)
2023-04-06 02:34:04.170909 2023-04-06 02:34:04.166 28 ERROR keystone.server.flask.application   File "/var/lib/kolla/venv/lib/python3.9/site-packages/flask_restful/__init__.py", line 582, in dispatch_request
2023-04-06 02:34:04.170919 2023-04-06 02:34:04.166 28 ERROR keystone.server.flask.application     resp = meth(*args, **kwargs)
2023-04-06 02:34:04.170928 2023-04-06 02:34:04.166 28 ERROR keystone.server.flask.application   File "/var/lib/kolla/venv/lib/python3.9/site-packages/keystone/api/projects.py", line 151, in get
2023-04-06 02:34:04.170939 2023-04-06 02:34:04.166 28 ERROR keystone.server.flask.application     return self._get_project(project_id)
2023-04-06 02:34:04.170948 2023-04-06 02:34:04.166 28 ERROR keystone.server.flask.application   File "/var/lib/kolla/venv/lib/python3.9/site-packages/keystone/api/projects.py", line 107, in _get_project
2023-04-06 02:34:04.170958 2023-04-06 02:34:04.166 28 ERROR keystone.server.flask.application     project = PROVIDERS.resource_api.get_project(project_id)
2023-04-06 02:34:04.170967 2023-04-06 02:34:04.166 28 ERROR keystone.server.flask.application   File "/var/lib/kolla/venv/lib/python3.9/site-packages/keystone/common/manager.py", line 115, in wrapped
2023-04-06 02:34:04.170977 2023-04-06 02:34:04.166 28 ERROR keystone.server.flask.application     __ret_val = __f(*args, **kwargs)
2023-04-06 02:34:04.170986 2023-04-06 02:34:04.166 28 ERROR keystone.server.flask.application   File "/var/lib/kolla/venv/lib/python3.9/site-packages/decorator.py", line 232, in fun
2023-04-06 02:34:04.170996 2023-04-06 02:34:04.166 28 ERROR keystone.server.flask.application     return caller(func, *(extras + args), **kw)
2023-04-06 02:34:04.171007 2023-04-06 02:34:04.166 28 ERROR keystone.server.flask.application   File "/var/lib/kolla/venv/lib/python3.9/site-packages/dogpile/cache/region.py", line 1577, in get_or_create_for_user_func
2023-04-06 02:34:04.171017 2023-04-06 02:34:04.166 28 ERROR keystone.server.flask.application     return self.get_or_create(
2023-04-06 02:34:04.171044 2023-04-06 02:34:04.166 28 ERROR keystone.server.flask.application   File "/var/lib/kolla/venv/lib/python3.9/site-packages/dogpile/cache/region.py", line 1042, in get_or_create
2023-04-06 02:34:04.171064 2023-04-06 02:34:04.166 28 ERROR keystone.server.flask.application     with Lock(
2023-04-06 02:34:04.171091 2023-04-06 02:34:04.166 28 ERROR keystone.server.flask.application   File "/var/lib/kolla/venv/lib/python3.9/site-packages/dogpile/lock.py", line 185, in __enter__
2023-04-06 02:34:04.171101 2023-04-06 02:34:04.166 28 ERROR keystone.server.flask.application     return self._enter()
2023-04-06 02:34:04.171110 2023-04-06 02:34:04.166 28 ERROR keystone.server.flask.application   File "/var/lib/kolla/venv/lib/python3.9/site-packages/dogpile/lock.py", line 94, in _enter
2023-04-06 02:34:04.171120 2023-04-06 02:34:04.166 28 ERROR keystone.server.flask.application     generated = self._enter_create(value, createdtime)
2023-04-06 02:34:04.171130 2023-04-06 02:34:04.166 28 ERROR keystone.server.flask.application   File "/var/lib/kolla/venv/lib/python3.9/site-packages/dogpile/lock.py", line 178, in _enter_create
2023-04-06 02:34:04.171140 2023-04-06 02:34:04.166 28 ERROR keystone.server.flask.application     return self.creator()
2023-04-06 02:34:04.171149 2023-04-06 02:34:04.166 28 ERROR keystone.server.flask.application   File "/var/lib/kolla/venv/lib/python3.9/site-packages/dogpile/cache/region.py", line 995, in gen_value
2023-04-06 02:34:04.171159 2023-04-06 02:34:04.166 28 ERROR keystone.server.flask.application     created_value = creator(
2023-04-06 02:34:04.171168 2023-04-06 02:34:04.166 28 ERROR keystone.server.flask.application   File "/var/lib/kolla/venv/lib/python3.9/site-packages/keystone/resource/core.py", line 903, in get_project
2023-04-06 02:34:04.171178 2023-04-06 02:34:04.166 28 ERROR keystone.server.flask.application     return self.driver.get_project(project_id)
2023-04-06 02:34:04.171188 2023-04-06 02:34:04.166 28 ERROR keystone.server.flask.application   File "/var/lib/kolla/venv/lib/python3.9/site-packages/keystone/resource/backends/sql.py", line 49, in get_project
2023-04-06 02:34:04.171198 2023-04-06 02:34:04.166 28 ERROR keystone.server.flask.application     return self._get_project(session, project_id).to_dict()
2023-04-06 02:34:04.171208 2023-04-06 02:34:04.166 28 ERROR keystone.server.flask.application   File "/var/lib/kolla/venv/lib/python3.9/site-packages/keystone/resource/backends/sql.py", line 44, in _get_project
2023-04-06 02:34:04.171218 2023-04-06 02:34:04.166 28 ERROR keystone.server.flask.application     raise exception.ProjectNotFound(project_id=project_id)
2023-04-06 02:34:04.171227 2023-04-06 02:34:04.166 28 ERROR keystone.server.flask.application keystone.exception.ProjectNotFound: Could not find project: service.
2023-04-06 02:34:04.171237 2023-04-06 02:34:04.166 28 ERROR keystone.server.flask.application \x1b[00m
2023-04-06 02:34:19.694196 2023-04-06 02:34:19.690 27 ERROR keystone.server.flask.application [None req-056b43ad-ce7a-4d30-a399-39300f336038 2f9bbb60059d4f7b8a2c5bcc145402cd - - all default -] Could not find role: admin.: keystone.exception.RoleNotFound: Could not find role: admin.
2023-04-06 02:34:19.694251 2023-04-06 02:34:19.690 27 ERROR keystone.server.flask.application Traceback (most recent call last):
2023-04-06 02:34:19.694263 2023-04-06 02:34:19.690 27 ERROR keystone.server.flask.application   File "/var/lib/kolla/venv/lib/python3.9/site-packages/flask/app.py", line 1820, in full_dispatch_request
2023-04-06 02:34:19.694273 2023-04-06 02:34:19.690 27 ERROR keystone.server.flask.application     rv = self.dispatch_request()
2023-04-06 02:34:19.694283 2023-04-06 02:34:19.690 27 ERROR keystone.server.flask.application   File "/var/lib/kolla/venv/lib/python3.9/site-packages/flask/app.py", line 1796, in dispatch_request
2023-04-06 02:34:19.694293 2023-04-06 02:34:19.690 27 ERROR keystone.server.flask.application     return self.ensure_sync(self.view_functions[rule.endpoint])(**view_args)
2023-04-06 02:34:19.694303 2023-04-06 02:34:19.690 27 ERROR keystone.server.flask.application   File "/var/lib/kolla/venv/lib/python3.9/site-packages/flask_restful/__init__.py", line 467, in wrapper
2023-04-06 02:34:19.694351 2023-04-06 02:34:19.690 27 ERROR keystone.server.flask.application     resp = resource(*args, **kwargs)
2023-04-06 02:34:19.694367 2023-04-06 02:34:19.690 27 ERROR keystone.server.flask.application   File "/var/lib/kolla/venv/lib/python3.9/site-packages/flask/views.py", line 107, in view
2023-04-06 02:34:19.694378 2023-04-06 02:34:19.690 27 ERROR keystone.server.flask.application     return current_app.ensure_sync(self.dispatch_request)(**kwargs)
2023-04-06 02:34:19.694387 2023-04-06 02:34:19.690 27 ERROR keystone.server.flask.application   File "/var/lib/kolla/venv/lib/python3.9/site-packages/flask_restful/__init__.py", line 582, in dispatch_request
2023-04-06 02:34:19.694397 2023-04-06 02:34:19.690 27 ERROR keystone.server.flask.application     resp = meth(*args, **kwargs)
2023-04-06 02:34:19.694407 2023-04-06 02:34:19.690 27 ERROR keystone.server.flask.application   File "/var/lib/kolla/venv/lib/python3.9/site-packages/keystone/api/roles.py", line 50, in get
2023-04-06 02:34:19.694416 2023-04-06 02:34:19.690 27 ERROR keystone.server.flask.application     return self._get_role(role_id)
2023-04-06 02:34:19.694426 2023-04-06 02:34:19.690 27 ERROR keystone.server.flask.application   File "/var/lib/kolla/venv/lib/python3.9/site-packages/keystone/api/roles.py", line 70, in _get_role
2023-04-06 02:34:19.694436 2023-04-06 02:34:19.690 27 ERROR keystone.server.flask.application     ENFORCER.enforce_call(action='identity:get_role')
2023-04-06 02:34:19.694445 2023-04-06 02:34:19.690 27 ERROR keystone.server.flask.application   File "/var/lib/kolla/venv/lib/python3.9/site-packages/keystone/common/rbac_enforcer/enforcer.py", line 402, in enforce_call
2023-04-06 02:34:19.694457 2023-04-06 02:34:19.690 27 ERROR keystone.server.flask.application     policy_dict.update(cls._extract_member_target_data(
2023-04-06 02:34:19.694496 2023-04-06 02:34:19.690 27 ERROR keystone.server.flask.application   File "/var/lib/kolla/venv/lib/python3.9/site-packages/keystone/common/rbac_enforcer/enforcer.py", line 234, in _extract_member_target_data
2023-04-06 02:34:19.694507 2023-04-06 02:34:19.690 27 ERROR keystone.server.flask.application     member_name: func(flask.request.view_args[key])
2023-04-06 02:34:19.694516 2023-04-06 02:34:19.690 27 ERROR keystone.server.flask.application   File "/var/lib/kolla/venv/lib/python3.9/site-packages/keystone/common/manager.py", line 115, in wrapped
2023-04-06 02:34:19.694526 2023-04-06 02:34:19.690 27 ERROR keystone.server.flask.application     __ret_val = __f(*args, **kwargs)
2023-04-06 02:34:19.694535 2023-04-06 02:34:19.690 27 ERROR keystone.server.flask.application   File "/var/lib/kolla/venv/lib/python3.9/site-packages/decorator.py", line 232, in fun
2023-04-06 02:34:19.694545 2023-04-06 02:34:19.690 27 ERROR keystone.server.flask.application     return caller(func, *(extras + args), **kw)
2023-04-06 02:34:19.694557 2023-04-06 02:34:19.690 27 ERROR keystone.server.flask.application   File "/var/lib/kolla/venv/lib/python3.9/site-packages/dogpile/cache/region.py", line 1577, in get_or_create_for_user_func
2023-04-06 02:34:19.694571 2023-04-06 02:34:19.690 27 ERROR keystone.server.flask.application     return self.get_or_create(
2023-04-06 02:34:19.694582 2023-04-06 02:34:19.690 27 ERROR keystone.server.flask.application   File "/var/lib/kolla/venv/lib/python3.9/site-packages/dogpile/cache/region.py", line 1042, in get_or_create
2023-04-06 02:34:19.694592 2023-04-06 02:34:19.690 27 ERROR keystone.server.flask.application     with Lock(
2023-04-06 02:34:19.694601 2023-04-06 02:34:19.690 27 ERROR keystone.server.flask.application   File "/var/lib/kolla/venv/lib/python3.9/site-packages/dogpile/lock.py", line 185, in __enter__
2023-04-06 02:34:19.694611 2023-04-06 02:34:19.690 27 ERROR keystone.server.flask.application     return self._enter()
2023-04-06 02:34:19.694620 2023-04-06 02:34:19.690 27 ERROR keystone.server.flask.application   File "/var/lib/kolla/venv/lib/python3.9/site-packages/dogpile/lock.py", line 94, in _enter
2023-04-06 02:34:19.694645 2023-04-06 02:34:19.690 27 ERROR keystone.server.flask.application     generated = self._enter_create(value, createdtime)
2023-04-06 02:34:19.694656 2023-04-06 02:34:19.690 27 ERROR keystone.server.flask.application   File "/var/lib/kolla/venv/lib/python3.9/site-packages/dogpile/lock.py", line 178, in _enter_create
2023-04-06 02:34:19.694666 2023-04-06 02:34:19.690 27 ERROR keystone.server.flask.application     return self.creator()
2023-04-06 02:34:19.694676 2023-04-06 02:34:19.690 27 ERROR keystone.server.flask.application   File "/var/lib/kolla/venv/lib/python3.9/site-packages/dogpile/cache/region.py", line 995, in gen_value
2023-04-06 02:34:19.694686 2023-04-06 02:34:19.690 27 ERROR keystone.server.flask.application     created_value = creator(
2023-04-06 02:34:19.694695 2023-04-06 02:34:19.690 27 ERROR keystone.server.flask.application   File "/var/lib/kolla/venv/lib/python3.9/site-packages/keystone/assignment/core.py", line 1276, in get_role
2023-04-06 02:34:19.694705 2023-04-06 02:34:19.690 27 ERROR keystone.server.flask.application     return self.driver.get_role(role_id)
2023-04-06 02:34:19.694715 2023-04-06 02:34:19.690 27 ERROR keystone.server.flask.application   File "/var/lib/kolla/venv/lib/python3.9/site-packages/keystone/assignment/role_backends/sql.py", line 70, in get_role
2023-04-06 02:34:19.694725 2023-04-06 02:34:19.690 27 ERROR keystone.server.flask.application     return self._get_role(session, role_id).to_dict()
2023-04-06 02:34:19.694734 2023-04-06 02:34:19.690 27 ERROR keystone.server.flask.application   File "/var/lib/kolla/venv/lib/python3.9/site-packages/keystone/assignment/role_backends/sql.py", line 65, in _get_role
2023-04-06 02:34:19.694744 2023-04-06 02:34:19.690 27 ERROR keystone.server.flask.application     raise exception.RoleNotFound(role_id=role_id)
2023-04-06 02:34:19.694754 2023-04-06 02:34:19.690 27 ERROR keystone.server.flask.application keystone.exception.RoleNotFound: Could not find role: admin.
2023-04-06 02:34:19.694764 2023-04-06 02:34:19.690 27 ERROR keystone.server.flask.application \x1b[00m
2023-04-06 02:34:20.674742 2023-04-06 02:34:20.671 27 ERROR keystone.server.flask.application [None req-62c85b5e-6056-4c1c-8998-d8edd98af7b3 2f9bbb60059d4f7b8a2c5bcc145402cd - - all default -] Could not find user: neutron.: keystone.exception.UserNotFound: Could not find user: neutron.
2023-04-06 02:34:20.674785 2023-04-06 02:34:20.671 27 ERROR keystone.server.flask.application Traceback (most recent call last):
2023-04-06 02:34:20.674796 2023-04-06 02:34:20.671 27 ERROR keystone.server.flask.application   File "/var/lib/kolla/venv/lib/python3.9/site-packages/flask/app.py", line 1820, in full_dispatch_request
2023-04-06 02:34:20.674855 2023-04-06 02:34:20.671 27 ERROR keystone.server.flask.application     rv = self.dispatch_request()
2023-04-06 02:34:20.674871 2023-04-06 02:34:20.671 27 ERROR keystone.server.flask.application   File "/var/lib/kolla/venv/lib/python3.9/site-packages/flask/app.py", line 1796, in dispatch_request
2023-04-06 02:34:20.674881 2023-04-06 02:34:20.671 27 ERROR keystone.server.flask.application     return self.ensure_sync(self.view_functions[rule.endpoint])(**view_args)
2023-04-06 02:34:20.674891 2023-04-06 02:34:20.671 27 ERROR keystone.server.flask.application   File "/var/lib/kolla/venv/lib/python3.9/site-packages/flask_restful/__init__.py", line 467, in wrapper
2023-04-06 02:34:20.674901 2023-04-06 02:34:20.671 27 ERROR keystone.server.flask.application     resp = resource(*args, **kwargs)
2023-04-06 02:34:20.674910 2023-04-06 02:34:20.671 27 ERROR keystone.server.flask.application   File "/var/lib/kolla/venv/lib/python3.9/site-packages/flask/views.py", line 107, in view
2023-04-06 02:34:20.674920 2023-04-06 02:34:20.671 27 ERROR keystone.server.flask.application     return current_app.ensure_sync(self.dispatch_request)(**kwargs)
2023-04-06 02:34:20.674929 2023-04-06 02:34:20.671 27 ERROR keystone.server.flask.application   File "/var/lib/kolla/venv/lib/python3.9/site-packages/flask_restful/__init__.py", line 582, in dispatch_request
2023-04-06 02:34:20.674956 2023-04-06 02:34:20.671 27 ERROR keystone.server.flask.application     resp = meth(*args, **kwargs)
2023-04-06 02:34:20.674968 2023-04-06 02:34:20.671 27 ERROR keystone.server.flask.application   File "/var/lib/kolla/venv/lib/python3.9/site-packages/keystone/api/users.py", line 182, in get
2023-04-06 02:34:20.674977 2023-04-06 02:34:20.671 27 ERROR keystone.server.flask.application     return self._get_user(user_id)
2023-04-06 02:34:20.674987 2023-04-06 02:34:20.671 27 ERROR keystone.server.flask.application   File "/var/lib/kolla/venv/lib/python3.9/site-packages/keystone/api/users.py", line 194, in _get_user
2023-04-06 02:34:20.674997 2023-04-06 02:34:20.671 27 ERROR keystone.server.flask.application     ref = PROVIDERS.identity_api.get_user(user_id)
2023-04-06 02:34:20.675007 2023-04-06 02:34:20.671 27 ERROR keystone.server.flask.application   File "/var/lib/kolla/venv/lib/python3.9/site-packages/keystone/common/manager.py", line 115, in wrapped
2023-04-06 02:34:20.675016 2023-04-06 02:34:20.671 27 ERROR keystone.server.flask.application     __ret_val = __f(*args, **kwargs)
2023-04-06 02:34:20.675026 2023-04-06 02:34:20.671 27 ERROR keystone.server.flask.application   File "/var/lib/kolla/venv/lib/python3.9/site-packages/keystone/identity/core.py", line 414, in wrapper
2023-04-06 02:34:20.675035 2023-04-06 02:34:20.671 27 ERROR keystone.server.flask.application     return f(self, *args, **kwargs)
2023-04-06 02:34:20.675045 2023-04-06 02:34:20.671 27 ERROR keystone.server.flask.application   File "/var/lib/kolla/venv/lib/python3.9/site-packages/keystone/identity/core.py", line 424, in wrapper
2023-04-06 02:34:20.675055 2023-04-06 02:34:20.671 27 ERROR keystone.server.flask.application     return f(self, *args, **kwargs)
2023-04-06 02:34:20.675064 2023-04-06 02:34:20.671 27 ERROR keystone.server.flask.application   File "/var/lib/kolla/venv/lib/python3.9/site-packages/decorator.py", line 232, in fun
2023-04-06 02:34:20.675074 2023-04-06 02:34:20.671 27 ERROR keystone.server.flask.application     return caller(func, *(extras + args), **kw)
2023-04-06 02:34:20.675083 2023-04-06 02:34:20.671 27 ERROR keystone.server.flask.application   File "/var/lib/kolla/venv/lib/python3.9/site-packages/dogpile/cache/region.py", line 1577, in get_or_create_for_user_func
2023-04-06 02:34:20.675093 2023-04-06 02:34:20.671 27 ERROR keystone.server.flask.application     return self.get_or_create(
2023-04-06 02:34:20.675104 2023-04-06 02:34:20.671 27 ERROR keystone.server.flask.application   File "/var/lib/kolla/venv/lib/python3.9/site-packages/dogpile/cache/region.py", line 1042, in get_or_create
2023-04-06 02:34:20.675114 2023-04-06 02:34:20.671 27 ERROR keystone.server.flask.application     with Lock(
2023-04-06 02:34:20.675123 2023-04-06 02:34:20.671 27 ERROR keystone.server.flask.application   File "/var/lib/kolla/venv/lib/python3.9/site-packages/dogpile/lock.py", line 185, in __enter__
2023-04-06 02:34:20.675133 2023-04-06 02:34:20.671 27 ERROR keystone.server.flask.application     return self._enter()
2023-04-06 02:34:20.675143 2023-04-06 02:34:20.671 27 ERROR keystone.server.flask.application   File "/var/lib/kolla/venv/lib/python3.9/site-packages/dogpile/lock.py", line 94, in _enter
2023-04-06 02:34:20.675152 2023-04-06 02:34:20.671 27 ERROR keystone.server.flask.application     generated = self._enter_create(value, createdtime)
2023-04-06 02:34:20.675162 2023-04-06 02:34:20.671 27 ERROR keystone.server.flask.application   File "/var/lib/kolla/venv/lib/python3.9/site-packages/dogpile/lock.py", line 178, in _enter_create
2023-04-06 02:34:20.675171 2023-04-06 02:34:20.671 27 ERROR keystone.server.flask.application     return self.creator()
2023-04-06 02:34:20.675181 2023-04-06 02:34:20.671 27 ERROR keystone.server.flask.application   File "/var/lib/kolla/venv/lib/python3.9/site-packages/dogpile/cache/region.py", line 995, in gen_value
2023-04-06 02:34:20.675190 2023-04-06 02:34:20.671 27 ERROR keystone.server.flask.application     created_value = creator(
2023-04-06 02:34:20.675212 2023-04-06 02:34:20.671 27 ERROR keystone.server.flask.application   File "/var/lib/kolla/venv/lib/python3.9/site-packages/keystone/identity/core.py", line 1011, in get_user
2023-04-06 02:34:20.675223 2023-04-06 02:34:20.671 27 ERROR keystone.server.flask.application     ref = driver.get_user(entity_id)
2023-04-06 02:34:20.675233 2023-04-06 02:34:20.671 27 ERROR keystone.server.flask.application   File "/var/lib/kolla/venv/lib/python3.9/site-packages/keystone/identity/backends/sql.py", line 200, in get_user
2023-04-06 02:34:20.675243 2023-04-06 02:34:20.671 27 ERROR keystone.server.flask.application     self._get_user(session, user_id).to_dict())
2023-04-06 02:34:20.675252 2023-04-06 02:34:20.671 27 ERROR keystone.server.flask.application   File "/var/lib/kolla/venv/lib/python3.9/site-packages/keystone/identity/backends/sql.py", line 194, in _get_user
2023-04-06 02:34:20.675262 2023-04-06 02:34:20.671 27 ERROR keystone.server.flask.application     raise exception.UserNotFound(user_id=user_id)
2023-04-06 02:34:20.675272 2023-04-06 02:34:20.671 27 ERROR keystone.server.flask.application keystone.exception.UserNotFound: Could not find user: neutron.
2023-04-06 02:34:20.675281 2023-04-06 02:34:20.671 27 ERROR keystone.server.flask.application \x1b[00m
2023-04-06 02:34:21.418123 2023-04-06 02:34:21.411 26 ERROR keystone.server.flask.application [None req-85fafe4a-8df6-440e-9f71-7ca3c3aa0bab 2f9bbb60059d4f7b8a2c5bcc145402cd - - all default -] Could not find project: service.: keystone.exception.ProjectNotFound: Could not find project: service.
2023-04-06 02:34:21.418224 2023-04-06 02:34:21.411 26 ERROR keystone.server.flask.application Traceback (most recent call last):
2023-04-06 02:34:21.418249 2023-04-06 02:34:21.411 26 ERROR keystone.server.flask.application   File "/var/lib/kolla/venv/lib/python3.9/site-packages/flask/app.py", line 1820, in full_dispatch_request
2023-04-06 02:34:21.418273 2023-04-06 02:34:21.411 26 ERROR keystone.server.flask.application     rv = self.dispatch_request()
2023-04-06 02:34:21.418298 2023-04-06 02:34:21.411 26 ERROR keystone.server.flask.application   File "/var/lib/kolla/venv/lib/python3.9/site-packages/flask/app.py", line 1796, in dispatch_request
2023-04-06 02:34:21.418322 2023-04-06 02:34:21.411 26 ERROR keystone.server.flask.application     return self.ensure_sync(self.view_functions[rule.endpoint])(**view_args)
2023-04-06 02:34:21.418415 2023-04-06 02:34:21.411 26 ERROR keystone.server.flask.application   File "/var/lib/kolla/venv/lib/python3.9/site-packages/flask_restful/__init__.py", line 467, in wrapper
2023-04-06 02:34:21.418443 2023-04-06 02:34:21.411 26 ERROR keystone.server.flask.application     resp = resource(*args, **kwargs)
2023-04-06 02:34:21.418464 2023-04-06 02:34:21.411 26 ERROR keystone.server.flask.application   File "/var/lib/kolla/venv/lib/python3.9/site-packages/flask/views.py", line 107, in view
2023-04-06 02:34:21.418483 2023-04-06 02:34:21.411 26 ERROR keystone.server.flask.application     return current_app.ensure_sync(self.dispatch_request)(**kwargs)
2023-04-06 02:34:21.418502 2023-04-06 02:34:21.411 26 ERROR keystone.server.flask.application   File "/var/lib/kolla/venv/lib/python3.9/site-packages/flask_restful/__init__.py", line 582, in dispatch_request
2023-04-06 02:34:21.418520 2023-04-06 02:34:21.411 26 ERROR keystone.server.flask.application     resp = meth(*args, **kwargs)
2023-04-06 02:34:21.418539 2023-04-06 02:34:21.411 26 ERROR keystone.server.flask.application   File "/var/lib/kolla/venv/lib/python3.9/site-packages/keystone/api/projects.py", line 151, in get
2023-04-06 02:34:21.418561 2023-04-06 02:34:21.411 26 ERROR keystone.server.flask.application     return self._get_project(project_id)
2023-04-06 02:34:21.418583 2023-04-06 02:34:21.411 26 ERROR keystone.server.flask.application   File "/var/lib/kolla/venv/lib/python3.9/site-packages/keystone/api/projects.py", line 107, in _get_project
2023-04-06 02:34:21.418604 2023-04-06 02:34:21.411 26 ERROR keystone.server.flask.application     project = PROVIDERS.resource_api.get_project(project_id)
2023-04-06 02:34:21.418650 2023-04-06 02:34:21.411 26 ERROR keystone.server.flask.application   File "/var/lib/kolla/venv/lib/python3.9/site-packages/keystone/common/manager.py", line 115, in wrapped
2023-04-06 02:34:21.418674 2023-04-06 02:34:21.411 26 ERROR keystone.server.flask.application     __ret_val = __f(*args, **kwargs)
2023-04-06 02:34:21.418692 2023-04-06 02:34:21.411 26 ERROR keystone.server.flask.application   File "/var/lib/kolla/venv/lib/python3.9/site-packages/decorator.py", line 232, in fun
2023-04-06 02:34:21.418712 2023-04-06 02:34:21.411 26 ERROR keystone.server.flask.application     return caller(func, *(extras + args), **kw)
2023-04-06 02:34:21.418730 2023-04-06 02:34:21.411 26 ERROR keystone.server.flask.application   File "/var/lib/kolla/venv/lib/python3.9/site-packages/dogpile/cache/region.py", line 1577, in get_or_create_for_user_func
2023-04-06 02:34:21.418750 2023-04-06 02:34:21.411 26 ERROR keystone.server.flask.application     return self.get_or_create(
2023-04-06 02:34:21.418774 2023-04-06 02:34:21.411 26 ERROR keystone.server.flask.application   File "/var/lib/kolla/venv/lib/python3.9/site-packages/dogpile/cache/region.py", line 1042, in get_or_create
2023-04-06 02:34:21.418800 2023-04-06 02:34:21.411 26 ERROR keystone.server.flask.application     with Lock(
2023-04-06 02:34:21.418845 2023-04-06 02:34:21.411 26 ERROR keystone.server.flask.application   File "/var/lib/kolla/venv/lib/python3.9/site-packages/dogpile/lock.py", line 185, in __enter__
2023-04-06 02:34:21.418873 2023-04-06 02:34:21.411 26 ERROR keystone.server.flask.application     return self._enter()
2023-04-06 02:34:21.418895 2023-04-06 02:34:21.411 26 ERROR keystone.server.flask.application   File "/var/lib/kolla/venv/lib/python3.9/site-packages/dogpile/lock.py", line 94, in _enter
2023-04-06 02:34:21.418917 2023-04-06 02:34:21.411 26 ERROR keystone.server.flask.application     generated = self._enter_create(value, createdtime)
2023-04-06 02:34:21.418940 2023-04-06 02:34:21.411 26 ERROR keystone.server.flask.application   File "/var/lib/kolla/venv/lib/python3.9/site-packages/dogpile/lock.py", line 178, in _enter_create
2023-04-06 02:34:21.418961 2023-04-06 02:34:21.411 26 ERROR keystone.server.flask.application     return self.creator()
2023-04-06 02:34:21.418984 2023-04-06 02:34:21.411 26 ERROR keystone.server.flask.application   File "/var/lib/kolla/venv/lib/python3.9/site-packages/dogpile/cache/region.py", line 995, in gen_value
2023-04-06 02:34:21.419006 2023-04-06 02:34:21.411 26 ERROR keystone.server.flask.application     created_value = creator(
2023-04-06 02:34:21.419025 2023-04-06 02:34:21.411 26 ERROR keystone.server.flask.application   File "/var/lib/kolla/venv/lib/python3.9/site-packages/keystone/resource/core.py", line 903, in get_project
2023-04-06 02:34:21.419046 2023-04-06 02:34:21.411 26 ERROR keystone.server.flask.application     return self.driver.get_project(project_id)
2023-04-06 02:34:21.419064 2023-04-06 02:34:21.411 26 ERROR keystone.server.flask.application   File "/var/lib/kolla/venv/lib/python3.9/site-packages/keystone/resource/backends/sql.py", line 49, in get_project
2023-04-06 02:34:21.419085 2023-04-06 02:34:21.411 26 ERROR keystone.server.flask.application     return self._get_project(session, project_id).to_dict()
2023-04-06 02:34:21.419105 2023-04-06 02:34:21.411 26 ERROR keystone.server.flask.application   File "/var/lib/kolla/venv/lib/python3.9/site-packages/keystone/resource/backends/sql.py", line 44, in _get_project
2023-04-06 02:34:21.419127 2023-04-06 02:34:21.411 26 ERROR keystone.server.flask.application     raise exception.ProjectNotFound(project_id=project_id)
2023-04-06 02:34:21.419149 2023-04-06 02:34:21.411 26 ERROR keystone.server.flask.application keystone.exception.ProjectNotFound: Could not find project: service.
2023-04-06 02:34:21.419170 2023-04-06 02:34:21.411 26 ERROR keystone.server.flask.application \x1b[00m
2023-04-06 18:42:17.741344 2023-04-06 18:42:17.739 28 WARNING py.warnings [None req-0fc5816a-708f-460f-b2f6-25a4566980ad 2f9bbb60059d4f7b8a2c5bcc145402cd fd89a27de051450ab24b9b6348fb4abc - - default default] /var/lib/kolla/venv/lib/python3.9/site-packages/oslo_policy/policy.py:1129: UserWarning: Policy "identity:list_domains": "role:reader and system_scope:all" failed scope check. The token used to make the request was project scoped but the policy requires ['system'] scope. This behavior may change in the future where using the intended scope is required
2023-04-06 18:42:17.741446   warnings.warn(msg)
2023-04-06 18:42:17.741460 \x1b[00m
2023-04-06 18:42:17.987969 2023-04-06 18:42:17.985 27 WARNING py.warnings [None req-a116f2c8-c0a5-4592-96b4-1c2c0f055817 2f9bbb60059d4f7b8a2c5bcc145402cd fd89a27de051450ab24b9b6348fb4abc - - default default] /var/lib/kolla/venv/lib/python3.9/site-packages/oslo_policy/policy.py:1129: UserWarning: Policy "identity:create_project": "(role:admin and system_scope:all) or (role:admin and domain_id:%(target.project.domain_id)s)" failed scope check. The token used to make the request was project scoped but the policy requires ['system', 'domain'] scope. This behavior may change in the future where using the intended scope is required
2023-04-06 18:42:17.988018   warnings.warn(msg)
2023-04-06 18:42:17.988032 \x1b[00m
2023-04-06 18:42:18.265441 2023-04-06 18:42:18.263 26 WARNING py.warnings [None req-594cd4c2-ea0b-4dec-ae7a-c1fcba6aca0e 2f9bbb60059d4f7b8a2c5bcc145402cd fd89a27de051450ab24b9b6348fb4abc - - default default] /var/lib/kolla/venv/lib/python3.9/site-packages/oslo_policy/policy.py:1129: UserWarning: Policy "identity:create_user": "(role:admin and system_scope:all) or (role:admin and token.domain.id:%(target.user.domain_id)s)" failed scope check. The token used to make the request was project scoped but the policy requires ['system', 'domain'] scope. This behavior may change in the future where using the intended scope is required
2023-04-06 18:42:18.265489   warnings.warn(msg)
2023-04-06 18:42:18.265501 \x1b[00m
2023-04-06 18:42:19.116125 2023-04-06 18:42:19.115 28 WARNING py.warnings [None req-b27f1a19-a6f9-4413-9a7b-16f15649a745 2f9bbb60059d4f7b8a2c5bcc145402cd fd89a27de051450ab24b9b6348fb4abc - - default default] /var/lib/kolla/venv/lib/python3.9/site-packages/oslo_policy/policy.py:1129: UserWarning: Policy "identity:list_roles": "role:reader and system_scope:all" failed scope check. The token used to make the request was project scoped but the policy requires ['system'] scope. This behavior may change in the future where using the intended scope is required
2023-04-06 18:42:19.116169   warnings.warn(msg)
2023-04-06 18:42:19.116181 \x1b[00m
2023-04-06 18:42:19.466165 2023-04-06 18:42:19.465 27 WARNING py.warnings [None req-35edff20-7ddb-4039-b56a-a7e70f35a574 2f9bbb60059d4f7b8a2c5bcc145402cd fd89a27de051450ab24b9b6348fb4abc - - default default] /var/lib/kolla/venv/lib/python3.9/site-packages/oslo_policy/policy.py:1129: UserWarning: Policy "identity:create_grant": "(role:admin and system_scope:all) or ((role:admin and domain_id:%(target.user.domain_id)s and domain_id:%(target.project.domain_id)s) or (role:admin and domain_id:%(target.user.domain_id)s and domain_id:%(target.domain.id)s) or (role:admin and domain_id:%(target.group.domain_id)s and domain_id:%(target.project.domain_id)s) or (role:admin and domain_id:%(target.group.domain_id)s and domain_id:%(target.domain.id)s)) and (domain_id:%(target.role.domain_id)s or None:%(target.role.domain_id)s)" failed scope check. The token used to make the request was project scoped but the policy requires ['system', 'domain'] scope. This behavior may change in the future where using the intended scope is required
2023-04-06 18:42:19.466255   warnings.warn(msg)
2023-04-06 18:42:19.466266 \x1b[00m
2023-04-06 18:42:20.629411 2023-04-06 18:42:20.628 28 WARNING py.warnings [None req-b5dfd418-a491-4692-9db1-8d653dc471c1 2f9bbb60059d4f7b8a2c5bcc145402cd fd89a27de051450ab24b9b6348fb4abc - - default default] /var/lib/kolla/venv/lib/python3.9/site-packages/oslo_policy/policy.py:1129: UserWarning: Policy "identity:create_project": "(role:admin and system_scope:all) or (role:admin and domain_id:%(target.project.domain_id)s)" failed scope check. The token used to make the request was project scoped but the policy requires ['system', 'domain'] scope. This behavior may change in the future where using the intended scope is required
2023-04-06 18:42:20.629486   warnings.warn(msg)
2023-04-06 18:42:20.629500 \x1b[00m
2023-04-06 18:42:21.030754 2023-04-06 18:42:21.029 27 WARNING py.warnings [None req-afd59fd7-cf56-4252-bfd5-e265247a9b37 2f9bbb60059d4f7b8a2c5bcc145402cd fd89a27de051450ab24b9b6348fb4abc - - default default] /var/lib/kolla/venv/lib/python3.9/site-packages/oslo_policy/policy.py:1129: UserWarning: Policy "identity:create_user": "(role:admin and system_scope:all) or (role:admin and token.domain.id:%(target.user.domain_id)s)" failed scope check. The token used to make the request was project scoped but the policy requires ['system', 'domain'] scope. This behavior may change in the future where using the intended scope is required
2023-04-06 18:42:21.030799   warnings.warn(msg)
2023-04-06 18:42:21.030810 \x1b[00m
2023-04-06 18:42:21.965996 2023-04-06 18:42:21.965 26 WARNING py.warnings [None req-1103e02f-622f-479d-ab43-70f1003365a7 2f9bbb60059d4f7b8a2c5bcc145402cd fd89a27de051450ab24b9b6348fb4abc - - default default] /var/lib/kolla/venv/lib/python3.9/site-packages/oslo_policy/policy.py:1129: UserWarning: Policy "identity:list_roles": "role:reader and system_scope:all" failed scope check. The token used to make the request was project scoped but the policy requires ['system'] scope. This behavior may change in the future where using the intended scope is required
2023-04-06 18:42:21.966042   warnings.warn(msg)
2023-04-06 18:42:21.966053 \x1b[00m
2023-04-06 18:42:22.340894 2023-04-06 18:42:22.339 28 WARNING py.warnings [None req-4f9ef1d9-1dfe-445e-aba7-2cb431868d29 2f9bbb60059d4f7b8a2c5bcc145402cd fd89a27de051450ab24b9b6348fb4abc - - default default] /var/lib/kolla/venv/lib/python3.9/site-packages/oslo_policy/policy.py:1129: UserWarning: Policy "identity:create_grant": "(role:admin and system_scope:all) or ((role:admin and domain_id:%(target.user.domain_id)s and domain_id:%(target.project.domain_id)s) or (role:admin and domain_id:%(target.user.domain_id)s and domain_id:%(target.domain.id)s) or (role:admin and domain_id:%(target.group.domain_id)s and domain_id:%(target.project.domain_id)s) or (role:admin and domain_id:%(target.group.domain_id)s and domain_id:%(target.domain.id)s)) and (domain_id:%(target.role.domain_id)s or None:%(target.role.domain_id)s)" failed scope check. The token used to make the request was project scoped but the policy requires ['system', 'domain'] scope. This behavior may change in the future where using the intended scope is required
2023-04-06 18:42:22.340952   warnings.warn(msg)
2023-04-06 18:42:22.340966 \x1b[00m
2023-04-06 18:42:22.624838 2023-04-06 18:42:22.623 27 WARNING py.warnings [None req-33108bae-7bef-4cfe-81dc-0e07422f0728 2f9bbb60059d4f7b8a2c5bcc145402cd fd89a27de051450ab24b9b6348fb4abc - - default default] /var/lib/kolla/venv/lib/python3.9/site-packages/oslo_policy/policy.py:1129: UserWarning: Policy "identity:list_roles": "role:reader and system_scope:all" failed scope check. The token used to make the request was project scoped but the policy requires ['system'] scope. This behavior may change in the future where using the intended scope is required
2023-04-06 18:42:22.624882   warnings.warn(msg)
2023-04-06 18:42:22.624894 \x1b[00m
2023-04-06 18:42:22.940035 2023-04-06 18:42:22.938 26 WARNING py.warnings [None req-fa2a1345-6f8a-41ff-a7a9-1ad979343761 2f9bbb60059d4f7b8a2c5bcc145402cd fd89a27de051450ab24b9b6348fb4abc - - default default] /var/lib/kolla/venv/lib/python3.9/site-packages/oslo_policy/policy.py:1129: UserWarning: Policy "identity:create_grant": "(role:admin and system_scope:all) or ((role:admin and domain_id:%(target.user.domain_id)s and domain_id:%(target.project.domain_id)s) or (role:admin and domain_id:%(target.user.domain_id)s and domain_id:%(target.domain.id)s) or (role:admin and domain_id:%(target.group.domain_id)s and domain_id:%(target.project.domain_id)s) or (role:admin and domain_id:%(target.group.domain_id)s and domain_id:%(target.domain.id)s)) and (domain_id:%(target.role.domain_id)s or None:%(target.role.domain_id)s)" failed scope check. The token used to make the request was project scoped but the policy requires ['system', 'domain'] scope. This behavior may change in the future where using the intended scope is required
2023-04-06 18:42:22.940185   warnings.warn(msg)
2023-04-06 18:42:22.940198 \x1b[00m
2023-04-06 18:42:25.275787 2023-04-06 18:42:25.274 28 WARNING py.warnings [None req-65468cfb-6835-4e17-a8c3-6971c97c7fad 2f9bbb60059d4f7b8a2c5bcc145402cd fd89a27de051450ab24b9b6348fb4abc - - default default] /var/lib/kolla/venv/lib/python3.9/site-packages/oslo_policy/policy.py:1129: UserWarning: Policy "identity:create_system_grant_for_user": "role:admin and system_scope:all" failed scope check. The token used to make the request was project scoped but the policy requires ['system'] scope. This behavior may change in the future where using the intended scope is required
2023-04-06 18:42:25.275832   warnings.warn(msg)
2023-04-06 18:42:25.275843 \x1b[00m
