2023-02-27 10:29:15.189884 2023-02-27 10:29:15.188 39 WARNING keystone.common.rbac_enforcer.enforcer [None req-7170f4cb-dc8c-4293-b912-c2b3ed722c27 af1576daa3da461dbfebe1326fef3fc7 - - all default -] Deprecated policy rules found. Use oslopolicy-policy-generator and oslopolicy-policy-upgrade to detect and resolve deprecated policies in your configuration.\x1b[00m
2023-02-27 10:29:16.054684 2023-02-27 10:29:16.052 37 WARNING keystone.common.rbac_enforcer.enforcer [None req-e19c86aa-c997-4048-9ccd-4c7a17eaa0ca af1576daa3da461dbfebe1326fef3fc7 - - all default -] Deprecated policy rules found. Use oslopolicy-policy-generator and oslopolicy-policy-upgrade to detect and resolve deprecated policies in your configuration.\x1b[00m
2023-02-27 10:29:23.323755 2023-02-27 10:29:23.321 38 WARNING keystone.common.rbac_enforcer.enforcer [None req-1b1322ad-7039-4d1c-9d5a-57ed8c9062f3 af1576daa3da461dbfebe1326fef3fc7 - - all default -] Deprecated policy rules found. Use oslopolicy-policy-generator and oslopolicy-policy-upgrade to detect and resolve deprecated policies in your configuration.\x1b[00m
2023-02-27 10:30:37.925461 2023-02-27 10:30:37.872 39 ERROR keystone.server.flask.application [None req-bca8ebc7-33c8-4ac9-926e-47011041b3cd af1576daa3da461dbfebe1326fef3fc7 - - all default -] Could not find project: service.: keystone.exception.ProjectNotFound: Could not find project: service.
2023-02-27 10:30:37.925534 2023-02-27 10:30:37.872 39 ERROR keystone.server.flask.application Traceback (most recent call last):
2023-02-27 10:30:37.925575 2023-02-27 10:30:37.872 39 ERROR keystone.server.flask.application   File "/var/lib/kolla/venv/lib/python3.9/site-packages/flask/app.py", line 1820, in full_dispatch_request
2023-02-27 10:30:37.925588 2023-02-27 10:30:37.872 39 ERROR keystone.server.flask.application     rv = self.dispatch_request()
2023-02-27 10:30:37.925598 2023-02-27 10:30:37.872 39 ERROR keystone.server.flask.application   File "/var/lib/kolla/venv/lib/python3.9/site-packages/flask/app.py", line 1796, in dispatch_request
2023-02-27 10:30:37.925607 2023-02-27 10:30:37.872 39 ERROR keystone.server.flask.application     return self.ensure_sync(self.view_functions[rule.endpoint])(**view_args)
2023-02-27 10:30:37.925617 2023-02-27 10:30:37.872 39 ERROR keystone.server.flask.application   File "/var/lib/kolla/venv/lib/python3.9/site-packages/flask_restful/__init__.py", line 467, in wrapper
2023-02-27 10:30:37.925626 2023-02-27 10:30:37.872 39 ERROR keystone.server.flask.application     resp = resource(*args, **kwargs)
2023-02-27 10:30:37.925642 2023-02-27 10:30:37.872 39 ERROR keystone.server.flask.application   File "/var/lib/kolla/venv/lib/python3.9/site-packages/flask/views.py", line 107, in view
2023-02-27 10:30:37.925654 2023-02-27 10:30:37.872 39 ERROR keystone.server.flask.application     return current_app.ensure_sync(self.dispatch_request)(**kwargs)
2023-02-27 10:30:37.925664 2023-02-27 10:30:37.872 39 ERROR keystone.server.flask.application   File "/var/lib/kolla/venv/lib/python3.9/site-packages/flask_restful/__init__.py", line 582, in dispatch_request
2023-02-27 10:30:37.925673 2023-02-27 10:30:37.872 39 ERROR keystone.server.flask.application     resp = meth(*args, **kwargs)
2023-02-27 10:30:37.925682 2023-02-27 10:30:37.872 39 ERROR keystone.server.flask.application   File "/var/lib/kolla/venv/lib/python3.9/site-packages/keystone/api/projects.py", line 151, in get
2023-02-27 10:30:37.925692 2023-02-27 10:30:37.872 39 ERROR keystone.server.flask.application     return self._get_project(project_id)
2023-02-27 10:30:37.925701 2023-02-27 10:30:37.872 39 ERROR keystone.server.flask.application   File "/var/lib/kolla/venv/lib/python3.9/site-packages/keystone/api/projects.py", line 107, in _get_project
2023-02-27 10:30:37.925711 2023-02-27 10:30:37.872 39 ERROR keystone.server.flask.application     project = PROVIDERS.resource_api.get_project(project_id)
2023-02-27 10:30:37.925720 2023-02-27 10:30:37.872 39 ERROR keystone.server.flask.application   File "/var/lib/kolla/venv/lib/python3.9/site-packages/keystone/common/manager.py", line 115, in wrapped
2023-02-27 10:30:37.925749 2023-02-27 10:30:37.872 39 ERROR keystone.server.flask.application     __ret_val = __f(*args, **kwargs)
2023-02-27 10:30:37.925761 2023-02-27 10:30:37.872 39 ERROR keystone.server.flask.application   File "/var/lib/kolla/venv/lib/python3.9/site-packages/decorator.py", line 232, in fun
2023-02-27 10:30:37.925771 2023-02-27 10:30:37.872 39 ERROR keystone.server.flask.application     return caller(func, *(extras + args), **kw)
2023-02-27 10:30:37.925780 2023-02-27 10:30:37.872 39 ERROR keystone.server.flask.application   File "/var/lib/kolla/venv/lib/python3.9/site-packages/dogpile/cache/region.py", line 1577, in get_or_create_for_user_func
2023-02-27 10:30:37.925790 2023-02-27 10:30:37.872 39 ERROR keystone.server.flask.application     return self.get_or_create(
2023-02-27 10:30:37.925799 2023-02-27 10:30:37.872 39 ERROR keystone.server.flask.application   File "/var/lib/kolla/venv/lib/python3.9/site-packages/dogpile/cache/region.py", line 1042, in get_or_create
2023-02-27 10:30:37.925990 2023-02-27 10:30:37.872 39 ERROR keystone.server.flask.application     with Lock(
2023-02-27 10:30:37.926011 2023-02-27 10:30:37.872 39 ERROR keystone.server.flask.application   File "/var/lib/kolla/venv/lib/python3.9/site-packages/dogpile/lock.py", line 185, in __enter__
2023-02-27 10:30:37.926021 2023-02-27 10:30:37.872 39 ERROR keystone.server.flask.application     return self._enter()
2023-02-27 10:30:37.926031 2023-02-27 10:30:37.872 39 ERROR keystone.server.flask.application   File "/var/lib/kolla/venv/lib/python3.9/site-packages/dogpile/lock.py", line 94, in _enter
2023-02-27 10:30:37.926045 2023-02-27 10:30:37.872 39 ERROR keystone.server.flask.application     generated = self._enter_create(value, createdtime)
2023-02-27 10:30:37.926055 2023-02-27 10:30:37.872 39 ERROR keystone.server.flask.application   File "/var/lib/kolla/venv/lib/python3.9/site-packages/dogpile/lock.py", line 178, in _enter_create
2023-02-27 10:30:37.926064 2023-02-27 10:30:37.872 39 ERROR keystone.server.flask.application     return self.creator()
2023-02-27 10:30:37.926073 2023-02-27 10:30:37.872 39 ERROR keystone.server.flask.application   File "/var/lib/kolla/venv/lib/python3.9/site-packages/dogpile/cache/region.py", line 995, in gen_value
2023-02-27 10:30:37.926083 2023-02-27 10:30:37.872 39 ERROR keystone.server.flask.application     created_value = creator(
2023-02-27 10:30:37.926092 2023-02-27 10:30:37.872 39 ERROR keystone.server.flask.application   File "/var/lib/kolla/venv/lib/python3.9/site-packages/keystone/resource/core.py", line 903, in get_project
2023-02-27 10:30:37.926102 2023-02-27 10:30:37.872 39 ERROR keystone.server.flask.application     return self.driver.get_project(project_id)
2023-02-27 10:30:37.926111 2023-02-27 10:30:37.872 39 ERROR keystone.server.flask.application   File "/var/lib/kolla/venv/lib/python3.9/site-packages/keystone/resource/backends/sql.py", line 49, in get_project
2023-02-27 10:30:37.926120 2023-02-27 10:30:37.872 39 ERROR keystone.server.flask.application     return self._get_project(session, project_id).to_dict()
2023-02-27 10:30:37.926130 2023-02-27 10:30:37.872 39 ERROR keystone.server.flask.application   File "/var/lib/kolla/venv/lib/python3.9/site-packages/keystone/resource/backends/sql.py", line 44, in _get_project
2023-02-27 10:30:37.926139 2023-02-27 10:30:37.872 39 ERROR keystone.server.flask.application     raise exception.ProjectNotFound(project_id=project_id)
2023-02-27 10:30:37.926149 2023-02-27 10:30:37.872 39 ERROR keystone.server.flask.application keystone.exception.ProjectNotFound: Could not find project: service.
2023-02-27 10:30:37.926158 2023-02-27 10:30:37.872 39 ERROR keystone.server.flask.application \x1b[00m
2023-02-27 10:30:47.002448 2023-02-27 10:30:46.989 38 ERROR keystone.server.flask.application [None req-f49404c9-c72d-4862-a86a-79ce53b92e7e af1576daa3da461dbfebe1326fef3fc7 - - all default -] Could not find project: service.: keystone.exception.ProjectNotFound: Could not find project: service.
2023-02-27 10:30:47.002540 2023-02-27 10:30:46.989 38 ERROR keystone.server.flask.application Traceback (most recent call last):
2023-02-27 10:30:47.002590 2023-02-27 10:30:46.989 38 ERROR keystone.server.flask.application   File "/var/lib/kolla/venv/lib/python3.9/site-packages/flask/app.py", line 1820, in full_dispatch_request
2023-02-27 10:30:47.002604 2023-02-27 10:30:46.989 38 ERROR keystone.server.flask.application     rv = self.dispatch_request()
2023-02-27 10:30:47.002613 2023-02-27 10:30:46.989 38 ERROR keystone.server.flask.application   File "/var/lib/kolla/venv/lib/python3.9/site-packages/flask/app.py", line 1796, in dispatch_request
2023-02-27 10:30:47.002623 2023-02-27 10:30:46.989 38 ERROR keystone.server.flask.application     return self.ensure_sync(self.view_functions[rule.endpoint])(**view_args)
2023-02-27 10:30:47.002633 2023-02-27 10:30:46.989 38 ERROR keystone.server.flask.application   File "/var/lib/kolla/venv/lib/python3.9/site-packages/flask_restful/__init__.py", line 467, in wrapper
2023-02-27 10:30:47.002643 2023-02-27 10:30:46.989 38 ERROR keystone.server.flask.application     resp = resource(*args, **kwargs)
2023-02-27 10:30:47.002660 2023-02-27 10:30:46.989 38 ERROR keystone.server.flask.application   File "/var/lib/kolla/venv/lib/python3.9/site-packages/flask/views.py", line 107, in view
2023-02-27 10:30:47.002672 2023-02-27 10:30:46.989 38 ERROR keystone.server.flask.application     return current_app.ensure_sync(self.dispatch_request)(**kwargs)
2023-02-27 10:30:47.002681 2023-02-27 10:30:46.989 38 ERROR keystone.server.flask.application   File "/var/lib/kolla/venv/lib/python3.9/site-packages/flask_restful/__init__.py", line 582, in dispatch_request
2023-02-27 10:30:47.002691 2023-02-27 10:30:46.989 38 ERROR keystone.server.flask.application     resp = meth(*args, **kwargs)
2023-02-27 10:30:47.002700 2023-02-27 10:30:46.989 38 ERROR keystone.server.flask.application   File "/var/lib/kolla/venv/lib/python3.9/site-packages/keystone/api/projects.py", line 151, in get
2023-02-27 10:30:47.002710 2023-02-27 10:30:46.989 38 ERROR keystone.server.flask.application     return self._get_project(project_id)
2023-02-27 10:30:47.002720 2023-02-27 10:30:46.989 38 ERROR keystone.server.flask.application   File "/var/lib/kolla/venv/lib/python3.9/site-packages/keystone/api/projects.py", line 107, in _get_project
2023-02-27 10:30:47.002729 2023-02-27 10:30:46.989 38 ERROR keystone.server.flask.application     project = PROVIDERS.resource_api.get_project(project_id)
2023-02-27 10:30:47.002738 2023-02-27 10:30:46.989 38 ERROR keystone.server.flask.application   File "/var/lib/kolla/venv/lib/python3.9/site-packages/keystone/common/manager.py", line 115, in wrapped
2023-02-27 10:30:47.002748 2023-02-27 10:30:46.989 38 ERROR keystone.server.flask.application     __ret_val = __f(*args, **kwargs)
2023-02-27 10:30:47.002757 2023-02-27 10:30:46.989 38 ERROR keystone.server.flask.application   File "/var/lib/kolla/venv/lib/python3.9/site-packages/decorator.py", line 232, in fun
2023-02-27 10:30:47.002767 2023-02-27 10:30:46.989 38 ERROR keystone.server.flask.application     return caller(func, *(extras + args), **kw)
2023-02-27 10:30:47.002776 2023-02-27 10:30:46.989 38 ERROR keystone.server.flask.application   File "/var/lib/kolla/venv/lib/python3.9/site-packages/dogpile/cache/region.py", line 1577, in get_or_create_for_user_func
2023-02-27 10:30:47.002786 2023-02-27 10:30:46.989 38 ERROR keystone.server.flask.application     return self.get_or_create(
2023-02-27 10:30:47.002795 2023-02-27 10:30:46.989 38 ERROR keystone.server.flask.application   File "/var/lib/kolla/venv/lib/python3.9/site-packages/dogpile/cache/region.py", line 1042, in get_or_create
2023-02-27 10:30:47.002808 2023-02-27 10:30:46.989 38 ERROR keystone.server.flask.application     with Lock(
2023-02-27 10:30:47.002817 2023-02-27 10:30:46.989 38 ERROR keystone.server.flask.application   File "/var/lib/kolla/venv/lib/python3.9/site-packages/dogpile/lock.py", line 185, in __enter__
2023-02-27 10:30:47.002827 2023-02-27 10:30:46.989 38 ERROR keystone.server.flask.application     return self._enter()
2023-02-27 10:30:47.002847 2023-02-27 10:30:46.989 38 ERROR keystone.server.flask.application   File "/var/lib/kolla/venv/lib/python3.9/site-packages/dogpile/lock.py", line 94, in _enter
2023-02-27 10:30:47.002857 2023-02-27 10:30:46.989 38 ERROR keystone.server.flask.application     generated = self._enter_create(value, createdtime)
2023-02-27 10:30:47.002867 2023-02-27 10:30:46.989 38 ERROR keystone.server.flask.application   File "/var/lib/kolla/venv/lib/python3.9/site-packages/dogpile/lock.py", line 178, in _enter_create
2023-02-27 10:30:47.002876 2023-02-27 10:30:46.989 38 ERROR keystone.server.flask.application     return self.creator()
2023-02-27 10:30:47.002885 2023-02-27 10:30:46.989 38 ERROR keystone.server.flask.application   File "/var/lib/kolla/venv/lib/python3.9/site-packages/dogpile/cache/region.py", line 995, in gen_value
2023-02-27 10:30:47.002895 2023-02-27 10:30:46.989 38 ERROR keystone.server.flask.application     created_value = creator(
2023-02-27 10:30:47.002904 2023-02-27 10:30:46.989 38 ERROR keystone.server.flask.application   File "/var/lib/kolla/venv/lib/python3.9/site-packages/keystone/resource/core.py", line 903, in get_project
2023-02-27 10:30:47.002913 2023-02-27 10:30:46.989 38 ERROR keystone.server.flask.application     return self.driver.get_project(project_id)
2023-02-27 10:30:47.002922 2023-02-27 10:30:46.989 38 ERROR keystone.server.flask.application   File "/var/lib/kolla/venv/lib/python3.9/site-packages/keystone/resource/backends/sql.py", line 49, in get_project
2023-02-27 10:30:47.002931 2023-02-27 10:30:46.989 38 ERROR keystone.server.flask.application     return self._get_project(session, project_id).to_dict()
2023-02-27 10:30:47.002941 2023-02-27 10:30:46.989 38 ERROR keystone.server.flask.application   File "/var/lib/kolla/venv/lib/python3.9/site-packages/keystone/resource/backends/sql.py", line 44, in _get_project
2023-02-27 10:30:47.002950 2023-02-27 10:30:46.989 38 ERROR keystone.server.flask.application     raise exception.ProjectNotFound(project_id=project_id)
2023-02-27 10:30:47.002959 2023-02-27 10:30:46.989 38 ERROR keystone.server.flask.application keystone.exception.ProjectNotFound: Could not find project: service.
2023-02-27 10:30:47.002968 2023-02-27 10:30:46.989 38 ERROR keystone.server.flask.application \x1b[00m
2023-02-27 10:31:02.246468 2023-02-27 10:31:02.240 38 ERROR keystone.server.flask.application [None req-66a9f60f-0883-4866-a523-e930c3f80ae8 af1576daa3da461dbfebe1326fef3fc7 - - all default -] Could not find role: admin.: keystone.exception.RoleNotFound: Could not find role: admin.
2023-02-27 10:31:02.246528 2023-02-27 10:31:02.240 38 ERROR keystone.server.flask.application Traceback (most recent call last):
2023-02-27 10:31:02.246570 2023-02-27 10:31:02.240 38 ERROR keystone.server.flask.application   File "/var/lib/kolla/venv/lib/python3.9/site-packages/flask/app.py", line 1820, in full_dispatch_request
2023-02-27 10:31:02.246584 2023-02-27 10:31:02.240 38 ERROR keystone.server.flask.application     rv = self.dispatch_request()
2023-02-27 10:31:02.246593 2023-02-27 10:31:02.240 38 ERROR keystone.server.flask.application   File "/var/lib/kolla/venv/lib/python3.9/site-packages/flask/app.py", line 1796, in dispatch_request
2023-02-27 10:31:02.246604 2023-02-27 10:31:02.240 38 ERROR keystone.server.flask.application     return self.ensure_sync(self.view_functions[rule.endpoint])(**view_args)
2023-02-27 10:31:02.246614 2023-02-27 10:31:02.240 38 ERROR keystone.server.flask.application   File "/var/lib/kolla/venv/lib/python3.9/site-packages/flask_restful/__init__.py", line 467, in wrapper
2023-02-27 10:31:02.246623 2023-02-27 10:31:02.240 38 ERROR keystone.server.flask.application     resp = resource(*args, **kwargs)
2023-02-27 10:31:02.246633 2023-02-27 10:31:02.240 38 ERROR keystone.server.flask.application   File "/var/lib/kolla/venv/lib/python3.9/site-packages/flask/views.py", line 107, in view
2023-02-27 10:31:02.246643 2023-02-27 10:31:02.240 38 ERROR keystone.server.flask.application     return current_app.ensure_sync(self.dispatch_request)(**kwargs)
2023-02-27 10:31:02.246653 2023-02-27 10:31:02.240 38 ERROR keystone.server.flask.application   File "/var/lib/kolla/venv/lib/python3.9/site-packages/flask_restful/__init__.py", line 582, in dispatch_request
2023-02-27 10:31:02.246688 2023-02-27 10:31:02.240 38 ERROR keystone.server.flask.application     resp = meth(*args, **kwargs)
2023-02-27 10:31:02.246701 2023-02-27 10:31:02.240 38 ERROR keystone.server.flask.application   File "/var/lib/kolla/venv/lib/python3.9/site-packages/keystone/api/roles.py", line 50, in get
2023-02-27 10:31:02.246711 2023-02-27 10:31:02.240 38 ERROR keystone.server.flask.application     return self._get_role(role_id)
2023-02-27 10:31:02.246720 2023-02-27 10:31:02.240 38 ERROR keystone.server.flask.application   File "/var/lib/kolla/venv/lib/python3.9/site-packages/keystone/api/roles.py", line 70, in _get_role
2023-02-27 10:31:02.246730 2023-02-27 10:31:02.240 38 ERROR keystone.server.flask.application     ENFORCER.enforce_call(action='identity:get_role')
2023-02-27 10:31:02.246740 2023-02-27 10:31:02.240 38 ERROR keystone.server.flask.application   File "/var/lib/kolla/venv/lib/python3.9/site-packages/keystone/common/rbac_enforcer/enforcer.py", line 402, in enforce_call
2023-02-27 10:31:02.246750 2023-02-27 10:31:02.240 38 ERROR keystone.server.flask.application     policy_dict.update(cls._extract_member_target_data(
2023-02-27 10:31:02.246766 2023-02-27 10:31:02.240 38 ERROR keystone.server.flask.application   File "/var/lib/kolla/venv/lib/python3.9/site-packages/keystone/common/rbac_enforcer/enforcer.py", line 234, in _extract_member_target_data
2023-02-27 10:31:02.246780 2023-02-27 10:31:02.240 38 ERROR keystone.server.flask.application     member_name: func(flask.request.view_args[key])
2023-02-27 10:31:02.246789 2023-02-27 10:31:02.240 38 ERROR keystone.server.flask.application   File "/var/lib/kolla/venv/lib/python3.9/site-packages/keystone/common/manager.py", line 115, in wrapped
2023-02-27 10:31:02.246799 2023-02-27 10:31:02.240 38 ERROR keystone.server.flask.application     __ret_val = __f(*args, **kwargs)
2023-02-27 10:31:02.246809 2023-02-27 10:31:02.240 38 ERROR keystone.server.flask.application   File "/var/lib/kolla/venv/lib/python3.9/site-packages/decorator.py", line 232, in fun
2023-02-27 10:31:02.246819 2023-02-27 10:31:02.240 38 ERROR keystone.server.flask.application     return caller(func, *(extras + args), **kw)
2023-02-27 10:31:02.246835 2023-02-27 10:31:02.240 38 ERROR keystone.server.flask.application   File "/var/lib/kolla/venv/lib/python3.9/site-packages/dogpile/cache/region.py", line 1577, in get_or_create_for_user_func
2023-02-27 10:31:02.246845 2023-02-27 10:31:02.240 38 ERROR keystone.server.flask.application     return self.get_or_create(
2023-02-27 10:31:02.246854 2023-02-27 10:31:02.240 38 ERROR keystone.server.flask.application   File "/var/lib/kolla/venv/lib/python3.9/site-packages/dogpile/cache/region.py", line 1042, in get_or_create
2023-02-27 10:31:02.246864 2023-02-27 10:31:02.240 38 ERROR keystone.server.flask.application     with Lock(
2023-02-27 10:31:02.246874 2023-02-27 10:31:02.240 38 ERROR keystone.server.flask.application   File "/var/lib/kolla/venv/lib/python3.9/site-packages/dogpile/lock.py", line 185, in __enter__
2023-02-27 10:31:02.246883 2023-02-27 10:31:02.240 38 ERROR keystone.server.flask.application     return self._enter()
2023-02-27 10:31:02.246893 2023-02-27 10:31:02.240 38 ERROR keystone.server.flask.application   File "/var/lib/kolla/venv/lib/python3.9/site-packages/dogpile/lock.py", line 94, in _enter
2023-02-27 10:31:02.246903 2023-02-27 10:31:02.240 38 ERROR keystone.server.flask.application     generated = self._enter_create(value, createdtime)
2023-02-27 10:31:02.246912 2023-02-27 10:31:02.240 38 ERROR keystone.server.flask.application   File "/var/lib/kolla/venv/lib/python3.9/site-packages/dogpile/lock.py", line 178, in _enter_create
2023-02-27 10:31:02.246924 2023-02-27 10:31:02.240 38 ERROR keystone.server.flask.application     return self.creator()
2023-02-27 10:31:02.246957 2023-02-27 10:31:02.240 38 ERROR keystone.server.flask.application   File "/var/lib/kolla/venv/lib/python3.9/site-packages/dogpile/cache/region.py", line 995, in gen_value
2023-02-27 10:31:02.247006 2023-02-27 10:31:02.240 38 ERROR keystone.server.flask.application     created_value = creator(
2023-02-27 10:31:02.247018 2023-02-27 10:31:02.240 38 ERROR keystone.server.flask.application   File "/var/lib/kolla/venv/lib/python3.9/site-packages/keystone/assignment/core.py", line 1276, in get_role
2023-02-27 10:31:02.247028 2023-02-27 10:31:02.240 38 ERROR keystone.server.flask.application     return self.driver.get_role(role_id)
2023-02-27 10:31:02.247038 2023-02-27 10:31:02.240 38 ERROR keystone.server.flask.application   File "/var/lib/kolla/venv/lib/python3.9/site-packages/keystone/assignment/role_backends/sql.py", line 70, in get_role
2023-02-27 10:31:02.247048 2023-02-27 10:31:02.240 38 ERROR keystone.server.flask.application     return self._get_role(session, role_id).to_dict()
2023-02-27 10:31:02.247058 2023-02-27 10:31:02.240 38 ERROR keystone.server.flask.application   File "/var/lib/kolla/venv/lib/python3.9/site-packages/keystone/assignment/role_backends/sql.py", line 65, in _get_role
2023-02-27 10:31:02.247068 2023-02-27 10:31:02.240 38 ERROR keystone.server.flask.application     raise exception.RoleNotFound(role_id=role_id)
2023-02-27 10:31:02.247077 2023-02-27 10:31:02.240 38 ERROR keystone.server.flask.application keystone.exception.RoleNotFound: Could not find role: admin.
2023-02-27 10:31:02.247087 2023-02-27 10:31:02.240 38 ERROR keystone.server.flask.application \x1b[00m
2023-02-27 10:31:03.505244 2023-02-27 10:31:03.499 38 ERROR keystone.server.flask.application [None req-2fc7f362-6b00-4136-9d13-c9de72de1ff2 af1576daa3da461dbfebe1326fef3fc7 - - all default -] Could not find user: ironic.: keystone.exception.UserNotFound: Could not find user: ironic.
2023-02-27 10:31:03.505308 2023-02-27 10:31:03.499 38 ERROR keystone.server.flask.application Traceback (most recent call last):
2023-02-27 10:31:03.505319 2023-02-27 10:31:03.499 38 ERROR keystone.server.flask.application   File "/var/lib/kolla/venv/lib/python3.9/site-packages/flask/app.py", line 1820, in full_dispatch_request
2023-02-27 10:31:03.505329 2023-02-27 10:31:03.499 38 ERROR keystone.server.flask.application     rv = self.dispatch_request()
2023-02-27 10:31:03.505339 2023-02-27 10:31:03.499 38 ERROR keystone.server.flask.application   File "/var/lib/kolla/venv/lib/python3.9/site-packages/flask/app.py", line 1796, in dispatch_request
2023-02-27 10:31:03.505349 2023-02-27 10:31:03.499 38 ERROR keystone.server.flask.application     return self.ensure_sync(self.view_functions[rule.endpoint])(**view_args)
2023-02-27 10:31:03.505359 2023-02-27 10:31:03.499 38 ERROR keystone.server.flask.application   File "/var/lib/kolla/venv/lib/python3.9/site-packages/flask_restful/__init__.py", line 467, in wrapper
2023-02-27 10:31:03.505369 2023-02-27 10:31:03.499 38 ERROR keystone.server.flask.application     resp = resource(*args, **kwargs)
2023-02-27 10:31:03.505378 2023-02-27 10:31:03.499 38 ERROR keystone.server.flask.application   File "/var/lib/kolla/venv/lib/python3.9/site-packages/flask/views.py", line 107, in view
2023-02-27 10:31:03.505396 2023-02-27 10:31:03.499 38 ERROR keystone.server.flask.application     return current_app.ensure_sync(self.dispatch_request)(**kwargs)
2023-02-27 10:31:03.505409 2023-02-27 10:31:03.499 38 ERROR keystone.server.flask.application   File "/var/lib/kolla/venv/lib/python3.9/site-packages/flask_restful/__init__.py", line 582, in dispatch_request
2023-02-27 10:31:03.505418 2023-02-27 10:31:03.499 38 ERROR keystone.server.flask.application     resp = meth(*args, **kwargs)
2023-02-27 10:31:03.505428 2023-02-27 10:31:03.499 38 ERROR keystone.server.flask.application   File "/var/lib/kolla/venv/lib/python3.9/site-packages/keystone/api/users.py", line 182, in get
2023-02-27 10:31:03.505437 2023-02-27 10:31:03.499 38 ERROR keystone.server.flask.application     return self._get_user(user_id)
2023-02-27 10:31:03.505446 2023-02-27 10:31:03.499 38 ERROR keystone.server.flask.application   File "/var/lib/kolla/venv/lib/python3.9/site-packages/keystone/api/users.py", line 194, in _get_user
2023-02-27 10:31:03.505471 2023-02-27 10:31:03.499 38 ERROR keystone.server.flask.application     ref = PROVIDERS.identity_api.get_user(user_id)
2023-02-27 10:31:03.505482 2023-02-27 10:31:03.499 38 ERROR keystone.server.flask.application   File "/var/lib/kolla/venv/lib/python3.9/site-packages/keystone/common/manager.py", line 115, in wrapped
2023-02-27 10:31:03.505491 2023-02-27 10:31:03.499 38 ERROR keystone.server.flask.application     __ret_val = __f(*args, **kwargs)
2023-02-27 10:31:03.505501 2023-02-27 10:31:03.499 38 ERROR keystone.server.flask.application   File "/var/lib/kolla/venv/lib/python3.9/site-packages/keystone/identity/core.py", line 414, in wrapper
2023-02-27 10:31:03.505510 2023-02-27 10:31:03.499 38 ERROR keystone.server.flask.application     return f(self, *args, **kwargs)
2023-02-27 10:31:03.505519 2023-02-27 10:31:03.499 38 ERROR keystone.server.flask.application   File "/var/lib/kolla/venv/lib/python3.9/site-packages/keystone/identity/core.py", line 424, in wrapper
2023-02-27 10:31:03.505528 2023-02-27 10:31:03.499 38 ERROR keystone.server.flask.application     return f(self, *args, **kwargs)
2023-02-27 10:31:03.505538 2023-02-27 10:31:03.499 38 ERROR keystone.server.flask.application   File "/var/lib/kolla/venv/lib/python3.9/site-packages/decorator.py", line 232, in fun
2023-02-27 10:31:03.505572 2023-02-27 10:31:03.499 38 ERROR keystone.server.flask.application     return caller(func, *(extras + args), **kw)
2023-02-27 10:31:03.505588 2023-02-27 10:31:03.499 38 ERROR keystone.server.flask.application   File "/var/lib/kolla/venv/lib/python3.9/site-packages/dogpile/cache/region.py", line 1577, in get_or_create_for_user_func
2023-02-27 10:31:03.505598 2023-02-27 10:31:03.499 38 ERROR keystone.server.flask.application     return self.get_or_create(
2023-02-27 10:31:03.505607 2023-02-27 10:31:03.499 38 ERROR keystone.server.flask.application   File "/var/lib/kolla/venv/lib/python3.9/site-packages/dogpile/cache/region.py", line 1042, in get_or_create
2023-02-27 10:31:03.505616 2023-02-27 10:31:03.499 38 ERROR keystone.server.flask.application     with Lock(
2023-02-27 10:31:03.505625 2023-02-27 10:31:03.499 38 ERROR keystone.server.flask.application   File "/var/lib/kolla/venv/lib/python3.9/site-packages/dogpile/lock.py", line 185, in __enter__
2023-02-27 10:31:03.505635 2023-02-27 10:31:03.499 38 ERROR keystone.server.flask.application     return self._enter()
2023-02-27 10:31:03.505644 2023-02-27 10:31:03.499 38 ERROR keystone.server.flask.application   File "/var/lib/kolla/venv/lib/python3.9/site-packages/dogpile/lock.py", line 94, in _enter
2023-02-27 10:31:03.505653 2023-02-27 10:31:03.499 38 ERROR keystone.server.flask.application     generated = self._enter_create(value, createdtime)
2023-02-27 10:31:03.505662 2023-02-27 10:31:03.499 38 ERROR keystone.server.flask.application   File "/var/lib/kolla/venv/lib/python3.9/site-packages/dogpile/lock.py", line 178, in _enter_create
2023-02-27 10:31:03.505672 2023-02-27 10:31:03.499 38 ERROR keystone.server.flask.application     return self.creator()
2023-02-27 10:31:03.505681 2023-02-27 10:31:03.499 38 ERROR keystone.server.flask.application   File "/var/lib/kolla/venv/lib/python3.9/site-packages/dogpile/cache/region.py", line 995, in gen_value
2023-02-27 10:31:03.505690 2023-02-27 10:31:03.499 38 ERROR keystone.server.flask.application     created_value = creator(
2023-02-27 10:31:03.505699 2023-02-27 10:31:03.499 38 ERROR keystone.server.flask.application   File "/var/lib/kolla/venv/lib/python3.9/site-packages/keystone/identity/core.py", line 1011, in get_user
2023-02-27 10:31:03.505708 2023-02-27 10:31:03.499 38 ERROR keystone.server.flask.application     ref = driver.get_user(entity_id)
2023-02-27 10:31:03.505717 2023-02-27 10:31:03.499 38 ERROR keystone.server.flask.application   File "/var/lib/kolla/venv/lib/python3.9/site-packages/keystone/identity/backends/sql.py", line 200, in get_user
2023-02-27 10:31:03.505727 2023-02-27 10:31:03.499 38 ERROR keystone.server.flask.application     self._get_user(session, user_id).to_dict())
2023-02-27 10:31:03.505746 2023-02-27 10:31:03.499 38 ERROR keystone.server.flask.application   File "/var/lib/kolla/venv/lib/python3.9/site-packages/keystone/identity/backends/sql.py", line 194, in _get_user
2023-02-27 10:31:03.505757 2023-02-27 10:31:03.499 38 ERROR keystone.server.flask.application     raise exception.UserNotFound(user_id=user_id)
2023-02-27 10:31:03.505766 2023-02-27 10:31:03.499 38 ERROR keystone.server.flask.application keystone.exception.UserNotFound: Could not find user: ironic.
2023-02-27 10:31:03.505776 2023-02-27 10:31:03.499 38 ERROR keystone.server.flask.application \x1b[00m
2023-02-27 10:31:04.332539 2023-02-27 10:31:04.322 37 ERROR keystone.server.flask.application [None req-f80ab12b-1d80-4dc0-8b5c-3ba7f1b47866 af1576daa3da461dbfebe1326fef3fc7 - - all default -] Could not find project: service.: keystone.exception.ProjectNotFound: Could not find project: service.
2023-02-27 10:31:04.332603 2023-02-27 10:31:04.322 37 ERROR keystone.server.flask.application Traceback (most recent call last):
2023-02-27 10:31:04.332614 2023-02-27 10:31:04.322 37 ERROR keystone.server.flask.application   File "/var/lib/kolla/venv/lib/python3.9/site-packages/flask/app.py", line 1820, in full_dispatch_request
2023-02-27 10:31:04.332625 2023-02-27 10:31:04.322 37 ERROR keystone.server.flask.application     rv = self.dispatch_request()
2023-02-27 10:31:04.332634 2023-02-27 10:31:04.322 37 ERROR keystone.server.flask.application   File "/var/lib/kolla/venv/lib/python3.9/site-packages/flask/app.py", line 1796, in dispatch_request
2023-02-27 10:31:04.332643 2023-02-27 10:31:04.322 37 ERROR keystone.server.flask.application     return self.ensure_sync(self.view_functions[rule.endpoint])(**view_args)
2023-02-27 10:31:04.332653 2023-02-27 10:31:04.322 37 ERROR keystone.server.flask.application   File "/var/lib/kolla/venv/lib/python3.9/site-packages/flask_restful/__init__.py", line 467, in wrapper
2023-02-27 10:31:04.332662 2023-02-27 10:31:04.322 37 ERROR keystone.server.flask.application     resp = resource(*args, **kwargs)
2023-02-27 10:31:04.332679 2023-02-27 10:31:04.322 37 ERROR keystone.server.flask.application   File "/var/lib/kolla/venv/lib/python3.9/site-packages/flask/views.py", line 107, in view
2023-02-27 10:31:04.332691 2023-02-27 10:31:04.322 37 ERROR keystone.server.flask.application     return current_app.ensure_sync(self.dispatch_request)(**kwargs)
2023-02-27 10:31:04.332700 2023-02-27 10:31:04.322 37 ERROR keystone.server.flask.application   File "/var/lib/kolla/venv/lib/python3.9/site-packages/flask_restful/__init__.py", line 582, in dispatch_request
2023-02-27 10:31:04.332710 2023-02-27 10:31:04.322 37 ERROR keystone.server.flask.application     resp = meth(*args, **kwargs)
2023-02-27 10:31:04.332719 2023-02-27 10:31:04.322 37 ERROR keystone.server.flask.application   File "/var/lib/kolla/venv/lib/python3.9/site-packages/keystone/api/projects.py", line 151, in get
2023-02-27 10:31:04.332729 2023-02-27 10:31:04.322 37 ERROR keystone.server.flask.application     return self._get_project(project_id)
2023-02-27 10:31:04.332738 2023-02-27 10:31:04.322 37 ERROR keystone.server.flask.application   File "/var/lib/kolla/venv/lib/python3.9/site-packages/keystone/api/projects.py", line 107, in _get_project
2023-02-27 10:31:04.332747 2023-02-27 10:31:04.322 37 ERROR keystone.server.flask.application     project = PROVIDERS.resource_api.get_project(project_id)
2023-02-27 10:31:04.332756 2023-02-27 10:31:04.322 37 ERROR keystone.server.flask.application   File "/var/lib/kolla/venv/lib/python3.9/site-packages/keystone/common/manager.py", line 115, in wrapped
2023-02-27 10:31:04.332766 2023-02-27 10:31:04.322 37 ERROR keystone.server.flask.application     __ret_val = __f(*args, **kwargs)
2023-02-27 10:31:04.332775 2023-02-27 10:31:04.322 37 ERROR keystone.server.flask.application   File "/var/lib/kolla/venv/lib/python3.9/site-packages/decorator.py", line 232, in fun
2023-02-27 10:31:04.332789 2023-02-27 10:31:04.322 37 ERROR keystone.server.flask.application     return caller(func, *(extras + args), **kw)
2023-02-27 10:31:04.332832 2023-02-27 10:31:04.322 37 ERROR keystone.server.flask.application   File "/var/lib/kolla/venv/lib/python3.9/site-packages/dogpile/cache/region.py", line 1577, in get_or_create_for_user_func
2023-02-27 10:31:04.332845 2023-02-27 10:31:04.322 37 ERROR keystone.server.flask.application     return self.get_or_create(
2023-02-27 10:31:04.332855 2023-02-27 10:31:04.322 37 ERROR keystone.server.flask.application   File "/var/lib/kolla/venv/lib/python3.9/site-packages/dogpile/cache/region.py", line 1042, in get_or_create
2023-02-27 10:31:04.332865 2023-02-27 10:31:04.322 37 ERROR keystone.server.flask.application     with Lock(
2023-02-27 10:31:04.332874 2023-02-27 10:31:04.322 37 ERROR keystone.server.flask.application   File "/var/lib/kolla/venv/lib/python3.9/site-packages/dogpile/lock.py", line 185, in __enter__
2023-02-27 10:31:04.332883 2023-02-27 10:31:04.322 37 ERROR keystone.server.flask.application     return self._enter()
2023-02-27 10:31:04.332892 2023-02-27 10:31:04.322 37 ERROR keystone.server.flask.application   File "/var/lib/kolla/venv/lib/python3.9/site-packages/dogpile/lock.py", line 94, in _enter
2023-02-27 10:31:04.332902 2023-02-27 10:31:04.322 37 ERROR keystone.server.flask.application     generated = self._enter_create(value, createdtime)
2023-02-27 10:31:04.332911 2023-02-27 10:31:04.322 37 ERROR keystone.server.flask.application   File "/var/lib/kolla/venv/lib/python3.9/site-packages/dogpile/lock.py", line 178, in _enter_create
2023-02-27 10:31:04.332921 2023-02-27 10:31:04.322 37 ERROR keystone.server.flask.application     return self.creator()
2023-02-27 10:31:04.332930 2023-02-27 10:31:04.322 37 ERROR keystone.server.flask.application   File "/var/lib/kolla/venv/lib/python3.9/site-packages/dogpile/cache/region.py", line 995, in gen_value
2023-02-27 10:31:04.332940 2023-02-27 10:31:04.322 37 ERROR keystone.server.flask.application     created_value = creator(
2023-02-27 10:31:04.332949 2023-02-27 10:31:04.322 37 ERROR keystone.server.flask.application   File "/var/lib/kolla/venv/lib/python3.9/site-packages/keystone/resource/core.py", line 903, in get_project
2023-02-27 10:31:04.332958 2023-02-27 10:31:04.322 37 ERROR keystone.server.flask.application     return self.driver.get_project(project_id)
2023-02-27 10:31:04.332967 2023-02-27 10:31:04.322 37 ERROR keystone.server.flask.application   File "/var/lib/kolla/venv/lib/python3.9/site-packages/keystone/resource/backends/sql.py", line 49, in get_project
2023-02-27 10:31:04.332977 2023-02-27 10:31:04.322 37 ERROR keystone.server.flask.application     return self._get_project(session, project_id).to_dict()
2023-02-27 10:31:04.332986 2023-02-27 10:31:04.322 37 ERROR keystone.server.flask.application   File "/var/lib/kolla/venv/lib/python3.9/site-packages/keystone/resource/backends/sql.py", line 44, in _get_project
2023-02-27 10:31:04.332996 2023-02-27 10:31:04.322 37 ERROR keystone.server.flask.application     raise exception.ProjectNotFound(project_id=project_id)
2023-02-27 10:31:04.333005 2023-02-27 10:31:04.322 37 ERROR keystone.server.flask.application keystone.exception.ProjectNotFound: Could not find project: service.
2023-02-27 10:31:04.333014 2023-02-27 10:31:04.322 37 ERROR keystone.server.flask.application \x1b[00m
2023-02-27 10:31:14.637608 2023-02-27 10:31:14.631 39 ERROR keystone.server.flask.application [None req-a794bb01-7664-4e99-a3b0-7ccb819d4f19 af1576daa3da461dbfebe1326fef3fc7 - - all default -] Could not find role: admin.: keystone.exception.RoleNotFound: Could not find role: admin.
2023-02-27 10:31:14.637682 2023-02-27 10:31:14.631 39 ERROR keystone.server.flask.application Traceback (most recent call last):
2023-02-27 10:31:14.637696 2023-02-27 10:31:14.631 39 ERROR keystone.server.flask.application   File "/var/lib/kolla/venv/lib/python3.9/site-packages/flask/app.py", line 1820, in full_dispatch_request
2023-02-27 10:31:14.637706 2023-02-27 10:31:14.631 39 ERROR keystone.server.flask.application     rv = self.dispatch_request()
2023-02-27 10:31:14.637715 2023-02-27 10:31:14.631 39 ERROR keystone.server.flask.application   File "/var/lib/kolla/venv/lib/python3.9/site-packages/flask/app.py", line 1796, in dispatch_request
2023-02-27 10:31:14.637746 2023-02-27 10:31:14.631 39 ERROR keystone.server.flask.application     return self.ensure_sync(self.view_functions[rule.endpoint])(**view_args)
2023-02-27 10:31:14.637757 2023-02-27 10:31:14.631 39 ERROR keystone.server.flask.application   File "/var/lib/kolla/venv/lib/python3.9/site-packages/flask_restful/__init__.py", line 467, in wrapper
2023-02-27 10:31:14.637767 2023-02-27 10:31:14.631 39 ERROR keystone.server.flask.application     resp = resource(*args, **kwargs)
2023-02-27 10:31:14.637782 2023-02-27 10:31:14.631 39 ERROR keystone.server.flask.application   File "/var/lib/kolla/venv/lib/python3.9/site-packages/flask/views.py", line 107, in view
2023-02-27 10:31:14.637794 2023-02-27 10:31:14.631 39 ERROR keystone.server.flask.application     return current_app.ensure_sync(self.dispatch_request)(**kwargs)
2023-02-27 10:31:14.637803 2023-02-27 10:31:14.631 39 ERROR keystone.server.flask.application   File "/var/lib/kolla/venv/lib/python3.9/site-packages/flask_restful/__init__.py", line 582, in dispatch_request
2023-02-27 10:31:14.637812 2023-02-27 10:31:14.631 39 ERROR keystone.server.flask.application     resp = meth(*args, **kwargs)
2023-02-27 10:31:14.637821 2023-02-27 10:31:14.631 39 ERROR keystone.server.flask.application   File "/var/lib/kolla/venv/lib/python3.9/site-packages/keystone/api/roles.py", line 50, in get
2023-02-27 10:31:14.637831 2023-02-27 10:31:14.631 39 ERROR keystone.server.flask.application     return self._get_role(role_id)
2023-02-27 10:31:14.637839 2023-02-27 10:31:14.631 39 ERROR keystone.server.flask.application   File "/var/lib/kolla/venv/lib/python3.9/site-packages/keystone/api/roles.py", line 70, in _get_role
2023-02-27 10:31:14.637849 2023-02-27 10:31:14.631 39 ERROR keystone.server.flask.application     ENFORCER.enforce_call(action='identity:get_role')
2023-02-27 10:31:14.637858 2023-02-27 10:31:14.631 39 ERROR keystone.server.flask.application   File "/var/lib/kolla/venv/lib/python3.9/site-packages/keystone/common/rbac_enforcer/enforcer.py", line 402, in enforce_call
2023-02-27 10:31:14.637868 2023-02-27 10:31:14.631 39 ERROR keystone.server.flask.application     policy_dict.update(cls._extract_member_target_data(
2023-02-27 10:31:14.637877 2023-02-27 10:31:14.631 39 ERROR keystone.server.flask.application   File "/var/lib/kolla/venv/lib/python3.9/site-packages/keystone/common/rbac_enforcer/enforcer.py", line 234, in _extract_member_target_data
2023-02-27 10:31:14.637887 2023-02-27 10:31:14.631 39 ERROR keystone.server.flask.application     member_name: func(flask.request.view_args[key])
2023-02-27 10:31:14.637901 2023-02-27 10:31:14.631 39 ERROR keystone.server.flask.application   File "/var/lib/kolla/venv/lib/python3.9/site-packages/keystone/common/manager.py", line 115, in wrapped
2023-02-27 10:31:14.637912 2023-02-27 10:31:14.631 39 ERROR keystone.server.flask.application     __ret_val = __f(*args, **kwargs)
2023-02-27 10:31:14.637922 2023-02-27 10:31:14.631 39 ERROR keystone.server.flask.application   File "/var/lib/kolla/venv/lib/python3.9/site-packages/decorator.py", line 232, in fun
2023-02-27 10:31:14.637931 2023-02-27 10:31:14.631 39 ERROR keystone.server.flask.application     return caller(func, *(extras + args), **kw)
2023-02-27 10:31:14.637940 2023-02-27 10:31:14.631 39 ERROR keystone.server.flask.application   File "/var/lib/kolla/venv/lib/python3.9/site-packages/dogpile/cache/region.py", line 1577, in get_or_create_for_user_func
2023-02-27 10:31:14.637950 2023-02-27 10:31:14.631 39 ERROR keystone.server.flask.application     return self.get_or_create(
2023-02-27 10:31:14.637958 2023-02-27 10:31:14.631 39 ERROR keystone.server.flask.application   File "/var/lib/kolla/venv/lib/python3.9/site-packages/dogpile/cache/region.py", line 1042, in get_or_create
2023-02-27 10:31:14.637968 2023-02-27 10:31:14.631 39 ERROR keystone.server.flask.application     with Lock(
2023-02-27 10:31:14.637996 2023-02-27 10:31:14.631 39 ERROR keystone.server.flask.application   File "/var/lib/kolla/venv/lib/python3.9/site-packages/dogpile/lock.py", line 185, in __enter__
2023-02-27 10:31:14.638007 2023-02-27 10:31:14.631 39 ERROR keystone.server.flask.application     return self._enter()
2023-02-27 10:31:14.638016 2023-02-27 10:31:14.631 39 ERROR keystone.server.flask.application   File "/var/lib/kolla/venv/lib/python3.9/site-packages/dogpile/lock.py", line 94, in _enter
2023-02-27 10:31:14.638026 2023-02-27 10:31:14.631 39 ERROR keystone.server.flask.application     generated = self._enter_create(value, createdtime)
2023-02-27 10:31:14.638035 2023-02-27 10:31:14.631 39 ERROR keystone.server.flask.application   File "/var/lib/kolla/venv/lib/python3.9/site-packages/dogpile/lock.py", line 178, in _enter_create
2023-02-27 10:31:14.638044 2023-02-27 10:31:14.631 39 ERROR keystone.server.flask.application     return self.creator()
2023-02-27 10:31:14.638053 2023-02-27 10:31:14.631 39 ERROR keystone.server.flask.application   File "/var/lib/kolla/venv/lib/python3.9/site-packages/dogpile/cache/region.py", line 995, in gen_value
2023-02-27 10:31:14.638062 2023-02-27 10:31:14.631 39 ERROR keystone.server.flask.application     created_value = creator(
2023-02-27 10:31:14.638071 2023-02-27 10:31:14.631 39 ERROR keystone.server.flask.application   File "/var/lib/kolla/venv/lib/python3.9/site-packages/keystone/assignment/core.py", line 1276, in get_role
2023-02-27 10:31:14.638081 2023-02-27 10:31:14.631 39 ERROR keystone.server.flask.application     return self.driver.get_role(role_id)
2023-02-27 10:31:14.638090 2023-02-27 10:31:14.631 39 ERROR keystone.server.flask.application   File "/var/lib/kolla/venv/lib/python3.9/site-packages/keystone/assignment/role_backends/sql.py", line 70, in get_role
2023-02-27 10:31:14.638099 2023-02-27 10:31:14.631 39 ERROR keystone.server.flask.application     return self._get_role(session, role_id).to_dict()
2023-02-27 10:31:14.638108 2023-02-27 10:31:14.631 39 ERROR keystone.server.flask.application   File "/var/lib/kolla/venv/lib/python3.9/site-packages/keystone/assignment/role_backends/sql.py", line 65, in _get_role
2023-02-27 10:31:14.638117 2023-02-27 10:31:14.631 39 ERROR keystone.server.flask.application     raise exception.RoleNotFound(role_id=role_id)
2023-02-27 10:31:14.638127 2023-02-27 10:31:14.631 39 ERROR keystone.server.flask.application keystone.exception.RoleNotFound: Could not find role: admin.
2023-02-27 10:31:14.638136 2023-02-27 10:31:14.631 39 ERROR keystone.server.flask.application \x1b[00m
2023-02-27 10:31:15.869691 2023-02-27 10:31:15.861 39 ERROR keystone.server.flask.application [None req-e37d5c58-2e5d-4e6d-9c38-3ba750db70fb af1576daa3da461dbfebe1326fef3fc7 - - all default -] Could not find user: ironic-inspector.: keystone.exception.UserNotFound: Could not find user: ironic-inspector.
2023-02-27 10:31:15.869760 2023-02-27 10:31:15.861 39 ERROR keystone.server.flask.application Traceback (most recent call last):
2023-02-27 10:31:15.869774 2023-02-27 10:31:15.861 39 ERROR keystone.server.flask.application   File "/var/lib/kolla/venv/lib/python3.9/site-packages/flask/app.py", line 1820, in full_dispatch_request
2023-02-27 10:31:15.869788 2023-02-27 10:31:15.861 39 ERROR keystone.server.flask.application     rv = self.dispatch_request()
2023-02-27 10:31:15.869800 2023-02-27 10:31:15.861 39 ERROR keystone.server.flask.application   File "/var/lib/kolla/venv/lib/python3.9/site-packages/flask/app.py", line 1796, in dispatch_request
2023-02-27 10:31:15.869828 2023-02-27 10:31:15.861 39 ERROR keystone.server.flask.application     return self.ensure_sync(self.view_functions[rule.endpoint])(**view_args)
2023-02-27 10:31:15.869840 2023-02-27 10:31:15.861 39 ERROR keystone.server.flask.application   File "/var/lib/kolla/venv/lib/python3.9/site-packages/flask_restful/__init__.py", line 467, in wrapper
2023-02-27 10:31:15.869853 2023-02-27 10:31:15.861 39 ERROR keystone.server.flask.application     resp = resource(*args, **kwargs)
2023-02-27 10:31:15.869865 2023-02-27 10:31:15.861 39 ERROR keystone.server.flask.application   File "/var/lib/kolla/venv/lib/python3.9/site-packages/flask/views.py", line 107, in view
2023-02-27 10:31:15.869900 2023-02-27 10:31:15.861 39 ERROR keystone.server.flask.application     return current_app.ensure_sync(self.dispatch_request)(**kwargs)
2023-02-27 10:31:15.869915 2023-02-27 10:31:15.861 39 ERROR keystone.server.flask.application   File "/var/lib/kolla/venv/lib/python3.9/site-packages/flask_restful/__init__.py", line 582, in dispatch_request
2023-02-27 10:31:15.869928 2023-02-27 10:31:15.861 39 ERROR keystone.server.flask.application     resp = meth(*args, **kwargs)
2023-02-27 10:31:15.869940 2023-02-27 10:31:15.861 39 ERROR keystone.server.flask.application   File "/var/lib/kolla/venv/lib/python3.9/site-packages/keystone/api/users.py", line 182, in get
2023-02-27 10:31:15.869952 2023-02-27 10:31:15.861 39 ERROR keystone.server.flask.application     return self._get_user(user_id)
2023-02-27 10:31:15.869964 2023-02-27 10:31:15.861 39 ERROR keystone.server.flask.application   File "/var/lib/kolla/venv/lib/python3.9/site-packages/keystone/api/users.py", line 194, in _get_user
2023-02-27 10:31:15.869977 2023-02-27 10:31:15.861 39 ERROR keystone.server.flask.application     ref = PROVIDERS.identity_api.get_user(user_id)
2023-02-27 10:31:15.869989 2023-02-27 10:31:15.861 39 ERROR keystone.server.flask.application   File "/var/lib/kolla/venv/lib/python3.9/site-packages/keystone/common/manager.py", line 115, in wrapped
2023-02-27 10:31:15.870002 2023-02-27 10:31:15.861 39 ERROR keystone.server.flask.application     __ret_val = __f(*args, **kwargs)
2023-02-27 10:31:15.870013 2023-02-27 10:31:15.861 39 ERROR keystone.server.flask.application   File "/var/lib/kolla/venv/lib/python3.9/site-packages/keystone/identity/core.py", line 414, in wrapper
2023-02-27 10:31:15.870026 2023-02-27 10:31:15.861 39 ERROR keystone.server.flask.application     return f(self, *args, **kwargs)
2023-02-27 10:31:15.870038 2023-02-27 10:31:15.861 39 ERROR keystone.server.flask.application   File "/var/lib/kolla/venv/lib/python3.9/site-packages/keystone/identity/core.py", line 424, in wrapper
2023-02-27 10:31:15.870050 2023-02-27 10:31:15.861 39 ERROR keystone.server.flask.application     return f(self, *args, **kwargs)
2023-02-27 10:31:15.870062 2023-02-27 10:31:15.861 39 ERROR keystone.server.flask.application   File "/var/lib/kolla/venv/lib/python3.9/site-packages/decorator.py", line 232, in fun
2023-02-27 10:31:15.870074 2023-02-27 10:31:15.861 39 ERROR keystone.server.flask.application     return caller(func, *(extras + args), **kw)
2023-02-27 10:31:15.870087 2023-02-27 10:31:15.861 39 ERROR keystone.server.flask.application   File "/var/lib/kolla/venv/lib/python3.9/site-packages/dogpile/cache/region.py", line 1577, in get_or_create_for_user_func
2023-02-27 10:31:15.870099 2023-02-27 10:31:15.861 39 ERROR keystone.server.flask.application     return self.get_or_create(
2023-02-27 10:31:15.870111 2023-02-27 10:31:15.861 39 ERROR keystone.server.flask.application   File "/var/lib/kolla/venv/lib/python3.9/site-packages/dogpile/cache/region.py", line 1042, in get_or_create
2023-02-27 10:31:15.870124 2023-02-27 10:31:15.861 39 ERROR keystone.server.flask.application     with Lock(
2023-02-27 10:31:15.870136 2023-02-27 10:31:15.861 39 ERROR keystone.server.flask.application   File "/var/lib/kolla/venv/lib/python3.9/site-packages/dogpile/lock.py", line 185, in __enter__
2023-02-27 10:31:15.870148 2023-02-27 10:31:15.861 39 ERROR keystone.server.flask.application     return self._enter()
2023-02-27 10:31:15.870160 2023-02-27 10:31:15.861 39 ERROR keystone.server.flask.application   File "/var/lib/kolla/venv/lib/python3.9/site-packages/dogpile/lock.py", line 94, in _enter
2023-02-27 10:31:15.870173 2023-02-27 10:31:15.861 39 ERROR keystone.server.flask.application     generated = self._enter_create(value, createdtime)
2023-02-27 10:31:15.870185 2023-02-27 10:31:15.861 39 ERROR keystone.server.flask.application   File "/var/lib/kolla/venv/lib/python3.9/site-packages/dogpile/lock.py", line 178, in _enter_create
2023-02-27 10:31:15.870294 2023-02-27 10:31:15.861 39 ERROR keystone.server.flask.application     return self.creator()
2023-02-27 10:31:15.870309 2023-02-27 10:31:15.861 39 ERROR keystone.server.flask.application   File "/var/lib/kolla/venv/lib/python3.9/site-packages/dogpile/cache/region.py", line 995, in gen_value
2023-02-27 10:31:15.870322 2023-02-27 10:31:15.861 39 ERROR keystone.server.flask.application     created_value = creator(
2023-02-27 10:31:15.870334 2023-02-27 10:31:15.861 39 ERROR keystone.server.flask.application   File "/var/lib/kolla/venv/lib/python3.9/site-packages/keystone/identity/core.py", line 1011, in get_user
2023-02-27 10:31:15.870346 2023-02-27 10:31:15.861 39 ERROR keystone.server.flask.application     ref = driver.get_user(entity_id)
2023-02-27 10:31:15.870359 2023-02-27 10:31:15.861 39 ERROR keystone.server.flask.application   File "/var/lib/kolla/venv/lib/python3.9/site-packages/keystone/identity/backends/sql.py", line 200, in get_user
2023-02-27 10:31:15.870371 2023-02-27 10:31:15.861 39 ERROR keystone.server.flask.application     self._get_user(session, user_id).to_dict())
2023-02-27 10:31:15.870384 2023-02-27 10:31:15.861 39 ERROR keystone.server.flask.application   File "/var/lib/kolla/venv/lib/python3.9/site-packages/keystone/identity/backends/sql.py", line 194, in _get_user
2023-02-27 10:31:15.870396 2023-02-27 10:31:15.861 39 ERROR keystone.server.flask.application     raise exception.UserNotFound(user_id=user_id)
2023-02-27 10:31:15.870409 2023-02-27 10:31:15.861 39 ERROR keystone.server.flask.application keystone.exception.UserNotFound: Could not find user: ironic-inspector.
2023-02-27 10:31:15.870421 2023-02-27 10:31:15.861 39 ERROR keystone.server.flask.application \x1b[00m
2023-02-27 10:31:16.831127 2023-02-27 10:31:16.827 38 ERROR keystone.server.flask.application [None req-8dc80607-94bd-4c5c-a069-b303019c45df af1576daa3da461dbfebe1326fef3fc7 - - all default -] Could not find project: service.: keystone.exception.ProjectNotFound: Could not find project: service.
2023-02-27 10:31:16.831173 2023-02-27 10:31:16.827 38 ERROR keystone.server.flask.application Traceback (most recent call last):
2023-02-27 10:31:16.831229 2023-02-27 10:31:16.827 38 ERROR keystone.server.flask.application   File "/var/lib/kolla/venv/lib/python3.9/site-packages/flask/app.py", line 1820, in full_dispatch_request
2023-02-27 10:31:16.831245 2023-02-27 10:31:16.827 38 ERROR keystone.server.flask.application     rv = self.dispatch_request()
2023-02-27 10:31:16.831255 2023-02-27 10:31:16.827 38 ERROR keystone.server.flask.application   File "/var/lib/kolla/venv/lib/python3.9/site-packages/flask/app.py", line 1796, in dispatch_request
2023-02-27 10:31:16.831265 2023-02-27 10:31:16.827 38 ERROR keystone.server.flask.application     return self.ensure_sync(self.view_functions[rule.endpoint])(**view_args)
2023-02-27 10:31:16.831274 2023-02-27 10:31:16.827 38 ERROR keystone.server.flask.application   File "/var/lib/kolla/venv/lib/python3.9/site-packages/flask_restful/__init__.py", line 467, in wrapper
2023-02-27 10:31:16.831284 2023-02-27 10:31:16.827 38 ERROR keystone.server.flask.application     resp = resource(*args, **kwargs)
2023-02-27 10:31:16.831294 2023-02-27 10:31:16.827 38 ERROR keystone.server.flask.application   File "/var/lib/kolla/venv/lib/python3.9/site-packages/flask/views.py", line 107, in view
2023-02-27 10:31:16.831303 2023-02-27 10:31:16.827 38 ERROR keystone.server.flask.application     return current_app.ensure_sync(self.dispatch_request)(**kwargs)
2023-02-27 10:31:16.831313 2023-02-27 10:31:16.827 38 ERROR keystone.server.flask.application   File "/var/lib/kolla/venv/lib/python3.9/site-packages/flask_restful/__init__.py", line 582, in dispatch_request
2023-02-27 10:31:16.831322 2023-02-27 10:31:16.827 38 ERROR keystone.server.flask.application     resp = meth(*args, **kwargs)
2023-02-27 10:31:16.831331 2023-02-27 10:31:16.827 38 ERROR keystone.server.flask.application   File "/var/lib/kolla/venv/lib/python3.9/site-packages/keystone/api/projects.py", line 151, in get
2023-02-27 10:31:16.831366 2023-02-27 10:31:16.827 38 ERROR keystone.server.flask.application     return self._get_project(project_id)
2023-02-27 10:31:16.831378 2023-02-27 10:31:16.827 38 ERROR keystone.server.flask.application   File "/var/lib/kolla/venv/lib/python3.9/site-packages/keystone/api/projects.py", line 107, in _get_project
2023-02-27 10:31:16.831388 2023-02-27 10:31:16.827 38 ERROR keystone.server.flask.application     project = PROVIDERS.resource_api.get_project(project_id)
2023-02-27 10:31:16.831397 2023-02-27 10:31:16.827 38 ERROR keystone.server.flask.application   File "/var/lib/kolla/venv/lib/python3.9/site-packages/keystone/common/manager.py", line 115, in wrapped
2023-02-27 10:31:16.831407 2023-02-27 10:31:16.827 38 ERROR keystone.server.flask.application     __ret_val = __f(*args, **kwargs)
2023-02-27 10:31:16.831416 2023-02-27 10:31:16.827 38 ERROR keystone.server.flask.application   File "/var/lib/kolla/venv/lib/python3.9/site-packages/decorator.py", line 232, in fun
2023-02-27 10:31:16.831426 2023-02-27 10:31:16.827 38 ERROR keystone.server.flask.application     return caller(func, *(extras + args), **kw)
2023-02-27 10:31:16.831435 2023-02-27 10:31:16.827 38 ERROR keystone.server.flask.application   File "/var/lib/kolla/venv/lib/python3.9/site-packages/dogpile/cache/region.py", line 1577, in get_or_create_for_user_func
2023-02-27 10:31:16.831445 2023-02-27 10:31:16.827 38 ERROR keystone.server.flask.application     return self.get_or_create(
2023-02-27 10:31:16.831454 2023-02-27 10:31:16.827 38 ERROR keystone.server.flask.application   File "/var/lib/kolla/venv/lib/python3.9/site-packages/dogpile/cache/region.py", line 1042, in get_or_create
2023-02-27 10:31:16.831464 2023-02-27 10:31:16.827 38 ERROR keystone.server.flask.application     with Lock(
2023-02-27 10:31:16.831473 2023-02-27 10:31:16.827 38 ERROR keystone.server.flask.application   File "/var/lib/kolla/venv/lib/python3.9/site-packages/dogpile/lock.py", line 185, in __enter__
2023-02-27 10:31:16.831482 2023-02-27 10:31:16.827 38 ERROR keystone.server.flask.application     return self._enter()
2023-02-27 10:31:16.831492 2023-02-27 10:31:16.827 38 ERROR keystone.server.flask.application   File "/var/lib/kolla/venv/lib/python3.9/site-packages/dogpile/lock.py", line 94, in _enter
2023-02-27 10:31:16.831501 2023-02-27 10:31:16.827 38 ERROR keystone.server.flask.application     generated = self._enter_create(value, createdtime)
2023-02-27 10:31:16.831510 2023-02-27 10:31:16.827 38 ERROR keystone.server.flask.application   File "/var/lib/kolla/venv/lib/python3.9/site-packages/dogpile/lock.py", line 178, in _enter_create
2023-02-27 10:31:16.831520 2023-02-27 10:31:16.827 38 ERROR keystone.server.flask.application     return self.creator()
2023-02-27 10:31:16.831529 2023-02-27 10:31:16.827 38 ERROR keystone.server.flask.application   File "/var/lib/kolla/venv/lib/python3.9/site-packages/dogpile/cache/region.py", line 995, in gen_value
2023-02-27 10:31:16.831538 2023-02-27 10:31:16.827 38 ERROR keystone.server.flask.application     created_value = creator(
2023-02-27 10:31:16.831548 2023-02-27 10:31:16.827 38 ERROR keystone.server.flask.application   File "/var/lib/kolla/venv/lib/python3.9/site-packages/keystone/resource/core.py", line 903, in get_project
2023-02-27 10:31:16.831581 2023-02-27 10:31:16.827 38 ERROR keystone.server.flask.application     return self.driver.get_project(project_id)
2023-02-27 10:31:16.831591 2023-02-27 10:31:16.827 38 ERROR keystone.server.flask.application   File "/var/lib/kolla/venv/lib/python3.9/site-packages/keystone/resource/backends/sql.py", line 49, in get_project
2023-02-27 10:31:16.831601 2023-02-27 10:31:16.827 38 ERROR keystone.server.flask.application     return self._get_project(session, project_id).to_dict()
2023-02-27 10:31:16.831610 2023-02-27 10:31:16.827 38 ERROR keystone.server.flask.application   File "/var/lib/kolla/venv/lib/python3.9/site-packages/keystone/resource/backends/sql.py", line 44, in _get_project
2023-02-27 10:31:16.831620 2023-02-27 10:31:16.827 38 ERROR keystone.server.flask.application     raise exception.ProjectNotFound(project_id=project_id)
2023-02-27 10:31:16.831648 2023-02-27 10:31:16.827 38 ERROR keystone.server.flask.application keystone.exception.ProjectNotFound: Could not find project: service.
2023-02-27 10:31:16.831660 2023-02-27 10:31:16.827 38 ERROR keystone.server.flask.application \x1b[00m
2023-02-27 10:34:32.331992 2023-02-27 10:34:32.327 39 ERROR keystone.server.flask.application [None req-f2e8e9f0-a966-4cee-8b8f-2f539eb98b26 af1576daa3da461dbfebe1326fef3fc7 - - all default -] Could not find project: service.: keystone.exception.ProjectNotFound: Could not find project: service.
2023-02-27 10:34:32.332061 2023-02-27 10:34:32.327 39 ERROR keystone.server.flask.application Traceback (most recent call last):
2023-02-27 10:34:32.332076 2023-02-27 10:34:32.327 39 ERROR keystone.server.flask.application   File "/var/lib/kolla/venv/lib/python3.9/site-packages/flask/app.py", line 1820, in full_dispatch_request
2023-02-27 10:34:32.332087 2023-02-27 10:34:32.327 39 ERROR keystone.server.flask.application     rv = self.dispatch_request()
2023-02-27 10:34:32.332098 2023-02-27 10:34:32.327 39 ERROR keystone.server.flask.application   File "/var/lib/kolla/venv/lib/python3.9/site-packages/flask/app.py", line 1796, in dispatch_request
2023-02-27 10:34:32.332109 2023-02-27 10:34:32.327 39 ERROR keystone.server.flask.application     return self.ensure_sync(self.view_functions[rule.endpoint])(**view_args)
2023-02-27 10:34:32.332119 2023-02-27 10:34:32.327 39 ERROR keystone.server.flask.application   File "/var/lib/kolla/venv/lib/python3.9/site-packages/flask_restful/__init__.py", line 467, in wrapper
2023-02-27 10:34:32.332130 2023-02-27 10:34:32.327 39 ERROR keystone.server.flask.application     resp = resource(*args, **kwargs)
2023-02-27 10:34:32.332147 2023-02-27 10:34:32.327 39 ERROR keystone.server.flask.application   File "/var/lib/kolla/venv/lib/python3.9/site-packages/flask/views.py", line 107, in view
2023-02-27 10:34:32.332176 2023-02-27 10:34:32.327 39 ERROR keystone.server.flask.application     return current_app.ensure_sync(self.dispatch_request)(**kwargs)
2023-02-27 10:34:32.332224 2023-02-27 10:34:32.327 39 ERROR keystone.server.flask.application   File "/var/lib/kolla/venv/lib/python3.9/site-packages/flask_restful/__init__.py", line 582, in dispatch_request
2023-02-27 10:34:32.332244 2023-02-27 10:34:32.327 39 ERROR keystone.server.flask.application     resp = meth(*args, **kwargs)
2023-02-27 10:34:32.332254 2023-02-27 10:34:32.327 39 ERROR keystone.server.flask.application   File "/var/lib/kolla/venv/lib/python3.9/site-packages/keystone/api/projects.py", line 151, in get
2023-02-27 10:34:32.332265 2023-02-27 10:34:32.327 39 ERROR keystone.server.flask.application     return self._get_project(project_id)
2023-02-27 10:34:32.332276 2023-02-27 10:34:32.327 39 ERROR keystone.server.flask.application   File "/var/lib/kolla/venv/lib/python3.9/site-packages/keystone/api/projects.py", line 107, in _get_project
2023-02-27 10:34:32.332287 2023-02-27 10:34:32.327 39 ERROR keystone.server.flask.application     project = PROVIDERS.resource_api.get_project(project_id)
2023-02-27 10:34:32.332297 2023-02-27 10:34:32.327 39 ERROR keystone.server.flask.application   File "/var/lib/kolla/venv/lib/python3.9/site-packages/keystone/common/manager.py", line 115, in wrapped
2023-02-27 10:34:32.332307 2023-02-27 10:34:32.327 39 ERROR keystone.server.flask.application     __ret_val = __f(*args, **kwargs)
2023-02-27 10:34:32.332317 2023-02-27 10:34:32.327 39 ERROR keystone.server.flask.application   File "/var/lib/kolla/venv/lib/python3.9/site-packages/decorator.py", line 232, in fun
2023-02-27 10:34:32.332328 2023-02-27 10:34:32.327 39 ERROR keystone.server.flask.application     return caller(func, *(extras + args), **kw)
2023-02-27 10:34:32.332338 2023-02-27 10:34:32.327 39 ERROR keystone.server.flask.application   File "/var/lib/kolla/venv/lib/python3.9/site-packages/dogpile/cache/region.py", line 1577, in get_or_create_for_user_func
2023-02-27 10:34:32.332349 2023-02-27 10:34:32.327 39 ERROR keystone.server.flask.application     return self.get_or_create(
2023-02-27 10:34:32.332380 2023-02-27 10:34:32.327 39 ERROR keystone.server.flask.application   File "/var/lib/kolla/venv/lib/python3.9/site-packages/dogpile/cache/region.py", line 1042, in get_or_create
2023-02-27 10:34:32.332396 2023-02-27 10:34:32.327 39 ERROR keystone.server.flask.application     with Lock(
2023-02-27 10:34:32.332407 2023-02-27 10:34:32.327 39 ERROR keystone.server.flask.application   File "/var/lib/kolla/venv/lib/python3.9/site-packages/dogpile/lock.py", line 185, in __enter__
2023-02-27 10:34:32.332418 2023-02-27 10:34:32.327 39 ERROR keystone.server.flask.application     return self._enter()
2023-02-27 10:34:32.332428 2023-02-27 10:34:32.327 39 ERROR keystone.server.flask.application   File "/var/lib/kolla/venv/lib/python3.9/site-packages/dogpile/lock.py", line 94, in _enter
2023-02-27 10:34:32.332439 2023-02-27 10:34:32.327 39 ERROR keystone.server.flask.application     generated = self._enter_create(value, createdtime)
2023-02-27 10:34:32.332449 2023-02-27 10:34:32.327 39 ERROR keystone.server.flask.application   File "/var/lib/kolla/venv/lib/python3.9/site-packages/dogpile/lock.py", line 178, in _enter_create
2023-02-27 10:34:32.332460 2023-02-27 10:34:32.327 39 ERROR keystone.server.flask.application     return self.creator()
2023-02-27 10:34:32.332470 2023-02-27 10:34:32.327 39 ERROR keystone.server.flask.application   File "/var/lib/kolla/venv/lib/python3.9/site-packages/dogpile/cache/region.py", line 995, in gen_value
2023-02-27 10:34:32.332481 2023-02-27 10:34:32.327 39 ERROR keystone.server.flask.application     created_value = creator(
2023-02-27 10:34:32.332491 2023-02-27 10:34:32.327 39 ERROR keystone.server.flask.application   File "/var/lib/kolla/venv/lib/python3.9/site-packages/keystone/resource/core.py", line 903, in get_project
2023-02-27 10:34:32.332502 2023-02-27 10:34:32.327 39 ERROR keystone.server.flask.application     return self.driver.get_project(project_id)
2023-02-27 10:34:32.332512 2023-02-27 10:34:32.327 39 ERROR keystone.server.flask.application   File "/var/lib/kolla/venv/lib/python3.9/site-packages/keystone/resource/backends/sql.py", line 49, in get_project
2023-02-27 10:34:32.332523 2023-02-27 10:34:32.327 39 ERROR keystone.server.flask.application     return self._get_project(session, project_id).to_dict()
2023-02-27 10:34:32.332554 2023-02-27 10:34:32.327 39 ERROR keystone.server.flask.application   File "/var/lib/kolla/venv/lib/python3.9/site-packages/keystone/resource/backends/sql.py", line 44, in _get_project
2023-02-27 10:34:32.332575 2023-02-27 10:34:32.327 39 ERROR keystone.server.flask.application     raise exception.ProjectNotFound(project_id=project_id)
2023-02-27 10:34:32.332591 2023-02-27 10:34:32.327 39 ERROR keystone.server.flask.application keystone.exception.ProjectNotFound: Could not find project: service.
2023-02-27 10:34:32.332601 2023-02-27 10:34:32.327 39 ERROR keystone.server.flask.application \x1b[00m
2023-02-27 10:34:47.323960 2023-02-27 10:34:47.320 38 ERROR keystone.server.flask.application [None req-a331125b-bd6d-49ae-98c1-448fdd303a50 af1576daa3da461dbfebe1326fef3fc7 - - all default -] Could not find role: admin.: keystone.exception.RoleNotFound: Could not find role: admin.
2023-02-27 10:34:47.324021 2023-02-27 10:34:47.320 38 ERROR keystone.server.flask.application Traceback (most recent call last):
2023-02-27 10:34:47.324033 2023-02-27 10:34:47.320 38 ERROR keystone.server.flask.application   File "/var/lib/kolla/venv/lib/python3.9/site-packages/flask/app.py", line 1820, in full_dispatch_request
2023-02-27 10:34:47.324043 2023-02-27 10:34:47.320 38 ERROR keystone.server.flask.application     rv = self.dispatch_request()
2023-02-27 10:34:47.324053 2023-02-27 10:34:47.320 38 ERROR keystone.server.flask.application   File "/var/lib/kolla/venv/lib/python3.9/site-packages/flask/app.py", line 1796, in dispatch_request
2023-02-27 10:34:47.324062 2023-02-27 10:34:47.320 38 ERROR keystone.server.flask.application     return self.ensure_sync(self.view_functions[rule.endpoint])(**view_args)
2023-02-27 10:34:47.324072 2023-02-27 10:34:47.320 38 ERROR keystone.server.flask.application   File "/var/lib/kolla/venv/lib/python3.9/site-packages/flask_restful/__init__.py", line 467, in wrapper
2023-02-27 10:34:47.324105 2023-02-27 10:34:47.320 38 ERROR keystone.server.flask.application     resp = resource(*args, **kwargs)
2023-02-27 10:34:47.324122 2023-02-27 10:34:47.320 38 ERROR keystone.server.flask.application   File "/var/lib/kolla/venv/lib/python3.9/site-packages/flask/views.py", line 107, in view
2023-02-27 10:34:47.324135 2023-02-27 10:34:47.320 38 ERROR keystone.server.flask.application     return current_app.ensure_sync(self.dispatch_request)(**kwargs)
2023-02-27 10:34:47.324147 2023-02-27 10:34:47.320 38 ERROR keystone.server.flask.application   File "/var/lib/kolla/venv/lib/python3.9/site-packages/flask_restful/__init__.py", line 582, in dispatch_request
2023-02-27 10:34:47.324165 2023-02-27 10:34:47.320 38 ERROR keystone.server.flask.application     resp = meth(*args, **kwargs)
2023-02-27 10:34:47.324174 2023-02-27 10:34:47.320 38 ERROR keystone.server.flask.application   File "/var/lib/kolla/venv/lib/python3.9/site-packages/keystone/api/roles.py", line 50, in get
2023-02-27 10:34:47.324184 2023-02-27 10:34:47.320 38 ERROR keystone.server.flask.application     return self._get_role(role_id)
2023-02-27 10:34:47.324233 2023-02-27 10:34:47.320 38 ERROR keystone.server.flask.application   File "/var/lib/kolla/venv/lib/python3.9/site-packages/keystone/api/roles.py", line 70, in _get_role
2023-02-27 10:34:47.324244 2023-02-27 10:34:47.320 38 ERROR keystone.server.flask.application     ENFORCER.enforce_call(action='identity:get_role')
2023-02-27 10:34:47.324254 2023-02-27 10:34:47.320 38 ERROR keystone.server.flask.application   File "/var/lib/kolla/venv/lib/python3.9/site-packages/keystone/common/rbac_enforcer/enforcer.py", line 402, in enforce_call
2023-02-27 10:34:47.324264 2023-02-27 10:34:47.320 38 ERROR keystone.server.flask.application     policy_dict.update(cls._extract_member_target_data(
2023-02-27 10:34:47.324284 2023-02-27 10:34:47.320 38 ERROR keystone.server.flask.application   File "/var/lib/kolla/venv/lib/python3.9/site-packages/keystone/common/rbac_enforcer/enforcer.py", line 234, in _extract_member_target_data
2023-02-27 10:34:47.324296 2023-02-27 10:34:47.320 38 ERROR keystone.server.flask.application     member_name: func(flask.request.view_args[key])
2023-02-27 10:34:47.324306 2023-02-27 10:34:47.320 38 ERROR keystone.server.flask.application   File "/var/lib/kolla/venv/lib/python3.9/site-packages/keystone/common/manager.py", line 115, in wrapped
2023-02-27 10:34:47.324316 2023-02-27 10:34:47.320 38 ERROR keystone.server.flask.application     __ret_val = __f(*args, **kwargs)
2023-02-27 10:34:47.324325 2023-02-27 10:34:47.320 38 ERROR keystone.server.flask.application   File "/var/lib/kolla/venv/lib/python3.9/site-packages/decorator.py", line 232, in fun
2023-02-27 10:34:47.324335 2023-02-27 10:34:47.320 38 ERROR keystone.server.flask.application     return caller(func, *(extras + args), **kw)
2023-02-27 10:34:47.324344 2023-02-27 10:34:47.320 38 ERROR keystone.server.flask.application   File "/var/lib/kolla/venv/lib/python3.9/site-packages/dogpile/cache/region.py", line 1577, in get_or_create_for_user_func
2023-02-27 10:34:47.324353 2023-02-27 10:34:47.320 38 ERROR keystone.server.flask.application     return self.get_or_create(
2023-02-27 10:34:47.324362 2023-02-27 10:34:47.320 38 ERROR keystone.server.flask.application   File "/var/lib/kolla/venv/lib/python3.9/site-packages/dogpile/cache/region.py", line 1042, in get_or_create
2023-02-27 10:34:47.324372 2023-02-27 10:34:47.320 38 ERROR keystone.server.flask.application     with Lock(
2023-02-27 10:34:47.324381 2023-02-27 10:34:47.320 38 ERROR keystone.server.flask.application   File "/var/lib/kolla/venv/lib/python3.9/site-packages/dogpile/lock.py", line 185, in __enter__
2023-02-27 10:34:47.324391 2023-02-27 10:34:47.320 38 ERROR keystone.server.flask.application     return self._enter()
2023-02-27 10:34:47.324400 2023-02-27 10:34:47.320 38 ERROR keystone.server.flask.application   File "/var/lib/kolla/venv/lib/python3.9/site-packages/dogpile/lock.py", line 94, in _enter
2023-02-27 10:34:47.324430 2023-02-27 10:34:47.320 38 ERROR keystone.server.flask.application     generated = self._enter_create(value, createdtime)
2023-02-27 10:34:47.324442 2023-02-27 10:34:47.320 38 ERROR keystone.server.flask.application   File "/var/lib/kolla/venv/lib/python3.9/site-packages/dogpile/lock.py", line 178, in _enter_create
2023-02-27 10:34:47.324451 2023-02-27 10:34:47.320 38 ERROR keystone.server.flask.application     return self.creator()
2023-02-27 10:34:47.324461 2023-02-27 10:34:47.320 38 ERROR keystone.server.flask.application   File "/var/lib/kolla/venv/lib/python3.9/site-packages/dogpile/cache/region.py", line 995, in gen_value
2023-02-27 10:34:47.324470 2023-02-27 10:34:47.320 38 ERROR keystone.server.flask.application     created_value = creator(
2023-02-27 10:34:47.324480 2023-02-27 10:34:47.320 38 ERROR keystone.server.flask.application   File "/var/lib/kolla/venv/lib/python3.9/site-packages/keystone/assignment/core.py", line 1276, in get_role
2023-02-27 10:34:47.324489 2023-02-27 10:34:47.320 38 ERROR keystone.server.flask.application     return self.driver.get_role(role_id)
2023-02-27 10:34:47.324498 2023-02-27 10:34:47.320 38 ERROR keystone.server.flask.application   File "/var/lib/kolla/venv/lib/python3.9/site-packages/keystone/assignment/role_backends/sql.py", line 70, in get_role
2023-02-27 10:34:47.324508 2023-02-27 10:34:47.320 38 ERROR keystone.server.flask.application     return self._get_role(session, role_id).to_dict()
2023-02-27 10:34:47.324517 2023-02-27 10:34:47.320 38 ERROR keystone.server.flask.application   File "/var/lib/kolla/venv/lib/python3.9/site-packages/keystone/assignment/role_backends/sql.py", line 65, in _get_role
2023-02-27 10:34:47.324544 2023-02-27 10:34:47.320 38 ERROR keystone.server.flask.application     raise exception.RoleNotFound(role_id=role_id)
2023-02-27 10:34:47.324557 2023-02-27 10:34:47.320 38 ERROR keystone.server.flask.application keystone.exception.RoleNotFound: Could not find role: admin.
2023-02-27 10:34:47.324566 2023-02-27 10:34:47.320 38 ERROR keystone.server.flask.application \x1b[00m
2023-02-27 10:34:48.576457 2023-02-27 10:34:48.570 38 ERROR keystone.server.flask.application [None req-ddf5e11b-ec8e-420c-82d1-77eddc5ae4b0 af1576daa3da461dbfebe1326fef3fc7 - - all default -] Could not find user: neutron.: keystone.exception.UserNotFound: Could not find user: neutron.
2023-02-27 10:34:48.576557 2023-02-27 10:34:48.570 38 ERROR keystone.server.flask.application Traceback (most recent call last):
2023-02-27 10:34:48.576582 2023-02-27 10:34:48.570 38 ERROR keystone.server.flask.application   File "/var/lib/kolla/venv/lib/python3.9/site-packages/flask/app.py", line 1820, in full_dispatch_request
2023-02-27 10:34:48.576604 2023-02-27 10:34:48.570 38 ERROR keystone.server.flask.application     rv = self.dispatch_request()
2023-02-27 10:34:48.576621 2023-02-27 10:34:48.570 38 ERROR keystone.server.flask.application   File "/var/lib/kolla/venv/lib/python3.9/site-packages/flask/app.py", line 1796, in dispatch_request
2023-02-27 10:34:48.576639 2023-02-27 10:34:48.570 38 ERROR keystone.server.flask.application     return self.ensure_sync(self.view_functions[rule.endpoint])(**view_args)
2023-02-27 10:34:48.576658 2023-02-27 10:34:48.570 38 ERROR keystone.server.flask.application   File "/var/lib/kolla/venv/lib/python3.9/site-packages/flask_restful/__init__.py", line 467, in wrapper
2023-02-27 10:34:48.576677 2023-02-27 10:34:48.570 38 ERROR keystone.server.flask.application     resp = resource(*args, **kwargs)
2023-02-27 10:34:48.576694 2023-02-27 10:34:48.570 38 ERROR keystone.server.flask.application   File "/var/lib/kolla/venv/lib/python3.9/site-packages/flask/views.py", line 107, in view
2023-02-27 10:34:48.576712 2023-02-27 10:34:48.570 38 ERROR keystone.server.flask.application     return current_app.ensure_sync(self.dispatch_request)(**kwargs)
2023-02-27 10:34:48.576732 2023-02-27 10:34:48.570 38 ERROR keystone.server.flask.application   File "/var/lib/kolla/venv/lib/python3.9/site-packages/flask_restful/__init__.py", line 582, in dispatch_request
2023-02-27 10:34:48.576796 2023-02-27 10:34:48.570 38 ERROR keystone.server.flask.application     resp = meth(*args, **kwargs)
2023-02-27 10:34:48.576825 2023-02-27 10:34:48.570 38 ERROR keystone.server.flask.application   File "/var/lib/kolla/venv/lib/python3.9/site-packages/keystone/api/users.py", line 182, in get
2023-02-27 10:34:48.576844 2023-02-27 10:34:48.570 38 ERROR keystone.server.flask.application     return self._get_user(user_id)
2023-02-27 10:34:48.576864 2023-02-27 10:34:48.570 38 ERROR keystone.server.flask.application   File "/var/lib/kolla/venv/lib/python3.9/site-packages/keystone/api/users.py", line 194, in _get_user
2023-02-27 10:34:48.576884 2023-02-27 10:34:48.570 38 ERROR keystone.server.flask.application     ref = PROVIDERS.identity_api.get_user(user_id)
2023-02-27 10:34:48.576903 2023-02-27 10:34:48.570 38 ERROR keystone.server.flask.application   File "/var/lib/kolla/venv/lib/python3.9/site-packages/keystone/common/manager.py", line 115, in wrapped
2023-02-27 10:34:48.576921 2023-02-27 10:34:48.570 38 ERROR keystone.server.flask.application     __ret_val = __f(*args, **kwargs)
2023-02-27 10:34:48.576940 2023-02-27 10:34:48.570 38 ERROR keystone.server.flask.application   File "/var/lib/kolla/venv/lib/python3.9/site-packages/keystone/identity/core.py", line 414, in wrapper
2023-02-27 10:34:48.576962 2023-02-27 10:34:48.570 38 ERROR keystone.server.flask.application     return f(self, *args, **kwargs)
2023-02-27 10:34:48.576982 2023-02-27 10:34:48.570 38 ERROR keystone.server.flask.application   File "/var/lib/kolla/venv/lib/python3.9/site-packages/keystone/identity/core.py", line 424, in wrapper
2023-02-27 10:34:48.577003 2023-02-27 10:34:48.570 38 ERROR keystone.server.flask.application     return f(self, *args, **kwargs)
2023-02-27 10:34:48.577025 2023-02-27 10:34:48.570 38 ERROR keystone.server.flask.application   File "/var/lib/kolla/venv/lib/python3.9/site-packages/decorator.py", line 232, in fun
2023-02-27 10:34:48.577045 2023-02-27 10:34:48.570 38 ERROR keystone.server.flask.application     return caller(func, *(extras + args), **kw)
2023-02-27 10:34:48.577067 2023-02-27 10:34:48.570 38 ERROR keystone.server.flask.application   File "/var/lib/kolla/venv/lib/python3.9/site-packages/dogpile/cache/region.py", line 1577, in get_or_create_for_user_func
2023-02-27 10:34:48.577087 2023-02-27 10:34:48.570 38 ERROR keystone.server.flask.application     return self.get_or_create(
2023-02-27 10:34:48.577106 2023-02-27 10:34:48.570 38 ERROR keystone.server.flask.application   File "/var/lib/kolla/venv/lib/python3.9/site-packages/dogpile/cache/region.py", line 1042, in get_or_create
2023-02-27 10:34:48.577127 2023-02-27 10:34:48.570 38 ERROR keystone.server.flask.application     with Lock(
2023-02-27 10:34:48.577148 2023-02-27 10:34:48.570 38 ERROR keystone.server.flask.application   File "/var/lib/kolla/venv/lib/python3.9/site-packages/dogpile/lock.py", line 185, in __enter__
2023-02-27 10:34:48.577171 2023-02-27 10:34:48.570 38 ERROR keystone.server.flask.application     return self._enter()
2023-02-27 10:34:48.577225 2023-02-27 10:34:48.570 38 ERROR keystone.server.flask.application   File "/var/lib/kolla/venv/lib/python3.9/site-packages/dogpile/lock.py", line 94, in _enter
2023-02-27 10:34:48.577252 2023-02-27 10:34:48.570 38 ERROR keystone.server.flask.application     generated = self._enter_create(value, createdtime)
2023-02-27 10:34:48.577270 2023-02-27 10:34:48.570 38 ERROR keystone.server.flask.application   File "/var/lib/kolla/venv/lib/python3.9/site-packages/dogpile/lock.py", line 178, in _enter_create
2023-02-27 10:34:48.577300 2023-02-27 10:34:48.570 38 ERROR keystone.server.flask.application     return self.creator()
2023-02-27 10:34:48.577317 2023-02-27 10:34:48.570 38 ERROR keystone.server.flask.application   File "/var/lib/kolla/venv/lib/python3.9/site-packages/dogpile/cache/region.py", line 995, in gen_value
2023-02-27 10:34:48.577397 2023-02-27 10:34:48.570 38 ERROR keystone.server.flask.application     created_value = creator(
2023-02-27 10:34:48.577446 2023-02-27 10:34:48.570 38 ERROR keystone.server.flask.application   File "/var/lib/kolla/venv/lib/python3.9/site-packages/keystone/identity/core.py", line 1011, in get_user
2023-02-27 10:34:48.577469 2023-02-27 10:34:48.570 38 ERROR keystone.server.flask.application     ref = driver.get_user(entity_id)
2023-02-27 10:34:48.577485 2023-02-27 10:34:48.570 38 ERROR keystone.server.flask.application   File "/var/lib/kolla/venv/lib/python3.9/site-packages/keystone/identity/backends/sql.py", line 200, in get_user
2023-02-27 10:34:48.577503 2023-02-27 10:34:48.570 38 ERROR keystone.server.flask.application     self._get_user(session, user_id).to_dict())
2023-02-27 10:34:48.577520 2023-02-27 10:34:48.570 38 ERROR keystone.server.flask.application   File "/var/lib/kolla/venv/lib/python3.9/site-packages/keystone/identity/backends/sql.py", line 194, in _get_user
2023-02-27 10:34:48.577573 2023-02-27 10:34:48.570 38 ERROR keystone.server.flask.application     raise exception.UserNotFound(user_id=user_id)
2023-02-27 10:34:48.577591 2023-02-27 10:34:48.570 38 ERROR keystone.server.flask.application keystone.exception.UserNotFound: Could not find user: neutron.
2023-02-27 10:34:48.577608 2023-02-27 10:34:48.570 38 ERROR keystone.server.flask.application \x1b[00m
2023-02-27 10:34:49.494935 2023-02-27 10:34:49.491 37 ERROR keystone.server.flask.application [None req-96f4b926-f275-4362-95e4-09de3d9cb5e6 af1576daa3da461dbfebe1326fef3fc7 - - all default -] Could not find project: service.: keystone.exception.ProjectNotFound: Could not find project: service.
2023-02-27 10:34:49.494981 2023-02-27 10:34:49.491 37 ERROR keystone.server.flask.application Traceback (most recent call last):
2023-02-27 10:34:49.494992 2023-02-27 10:34:49.491 37 ERROR keystone.server.flask.application   File "/var/lib/kolla/venv/lib/python3.9/site-packages/flask/app.py", line 1820, in full_dispatch_request
2023-02-27 10:34:49.495003 2023-02-27 10:34:49.491 37 ERROR keystone.server.flask.application     rv = self.dispatch_request()
2023-02-27 10:34:49.495012 2023-02-27 10:34:49.491 37 ERROR keystone.server.flask.application   File "/var/lib/kolla/venv/lib/python3.9/site-packages/flask/app.py", line 1796, in dispatch_request
2023-02-27 10:34:49.495023 2023-02-27 10:34:49.491 37 ERROR keystone.server.flask.application     return self.ensure_sync(self.view_functions[rule.endpoint])(**view_args)
2023-02-27 10:34:49.495033 2023-02-27 10:34:49.491 37 ERROR keystone.server.flask.application   File "/var/lib/kolla/venv/lib/python3.9/site-packages/flask_restful/__init__.py", line 467, in wrapper
2023-02-27 10:34:49.495042 2023-02-27 10:34:49.491 37 ERROR keystone.server.flask.application     resp = resource(*args, **kwargs)
2023-02-27 10:34:49.495059 2023-02-27 10:34:49.491 37 ERROR keystone.server.flask.application   File "/var/lib/kolla/venv/lib/python3.9/site-packages/flask/views.py", line 107, in view
2023-02-27 10:34:49.495072 2023-02-27 10:34:49.491 37 ERROR keystone.server.flask.application     return current_app.ensure_sync(self.dispatch_request)(**kwargs)
2023-02-27 10:34:49.495082 2023-02-27 10:34:49.491 37 ERROR keystone.server.flask.application   File "/var/lib/kolla/venv/lib/python3.9/site-packages/flask_restful/__init__.py", line 582, in dispatch_request
2023-02-27 10:34:49.495091 2023-02-27 10:34:49.491 37 ERROR keystone.server.flask.application     resp = meth(*args, **kwargs)
2023-02-27 10:34:49.495101 2023-02-27 10:34:49.491 37 ERROR keystone.server.flask.application   File "/var/lib/kolla/venv/lib/python3.9/site-packages/keystone/api/projects.py", line 151, in get
2023-02-27 10:34:49.495112 2023-02-27 10:34:49.491 37 ERROR keystone.server.flask.application     return self._get_project(project_id)
2023-02-27 10:34:49.495121 2023-02-27 10:34:49.491 37 ERROR keystone.server.flask.application   File "/var/lib/kolla/venv/lib/python3.9/site-packages/keystone/api/projects.py", line 107, in _get_project
2023-02-27 10:34:49.495131 2023-02-27 10:34:49.491 37 ERROR keystone.server.flask.application     project = PROVIDERS.resource_api.get_project(project_id)
2023-02-27 10:34:49.495167 2023-02-27 10:34:49.491 37 ERROR keystone.server.flask.application   File "/var/lib/kolla/venv/lib/python3.9/site-packages/keystone/common/manager.py", line 115, in wrapped
2023-02-27 10:34:49.495180 2023-02-27 10:34:49.491 37 ERROR keystone.server.flask.application     __ret_val = __f(*args, **kwargs)
2023-02-27 10:34:49.495216 2023-02-27 10:34:49.491 37 ERROR keystone.server.flask.application   File "/var/lib/kolla/venv/lib/python3.9/site-packages/decorator.py", line 232, in fun
2023-02-27 10:34:49.495232 2023-02-27 10:34:49.491 37 ERROR keystone.server.flask.application     return caller(func, *(extras + args), **kw)
2023-02-27 10:34:49.495249 2023-02-27 10:34:49.491 37 ERROR keystone.server.flask.application   File "/var/lib/kolla/venv/lib/python3.9/site-packages/dogpile/cache/region.py", line 1577, in get_or_create_for_user_func
2023-02-27 10:34:49.495262 2023-02-27 10:34:49.491 37 ERROR keystone.server.flask.application     return self.get_or_create(
2023-02-27 10:34:49.495272 2023-02-27 10:34:49.491 37 ERROR keystone.server.flask.application   File "/var/lib/kolla/venv/lib/python3.9/site-packages/dogpile/cache/region.py", line 1042, in get_or_create
2023-02-27 10:34:49.495282 2023-02-27 10:34:49.491 37 ERROR keystone.server.flask.application     with Lock(
2023-02-27 10:34:49.495292 2023-02-27 10:34:49.491 37 ERROR keystone.server.flask.application   File "/var/lib/kolla/venv/lib/python3.9/site-packages/dogpile/lock.py", line 185, in __enter__
2023-02-27 10:34:49.495302 2023-02-27 10:34:49.491 37 ERROR keystone.server.flask.application     return self._enter()
2023-02-27 10:34:49.495311 2023-02-27 10:34:49.491 37 ERROR keystone.server.flask.application   File "/var/lib/kolla/venv/lib/python3.9/site-packages/dogpile/lock.py", line 94, in _enter
2023-02-27 10:34:49.495321 2023-02-27 10:34:49.491 37 ERROR keystone.server.flask.application     generated = self._enter_create(value, createdtime)
2023-02-27 10:34:49.495331 2023-02-27 10:34:49.491 37 ERROR keystone.server.flask.application   File "/var/lib/kolla/venv/lib/python3.9/site-packages/dogpile/lock.py", line 178, in _enter_create
2023-02-27 10:34:49.495341 2023-02-27 10:34:49.491 37 ERROR keystone.server.flask.application     return self.creator()
2023-02-27 10:34:49.495351 2023-02-27 10:34:49.491 37 ERROR keystone.server.flask.application   File "/var/lib/kolla/venv/lib/python3.9/site-packages/dogpile/cache/region.py", line 995, in gen_value
2023-02-27 10:34:49.495361 2023-02-27 10:34:49.491 37 ERROR keystone.server.flask.application     created_value = creator(
2023-02-27 10:34:49.495370 2023-02-27 10:34:49.491 37 ERROR keystone.server.flask.application   File "/var/lib/kolla/venv/lib/python3.9/site-packages/keystone/resource/core.py", line 903, in get_project
2023-02-27 10:34:49.495380 2023-02-27 10:34:49.491 37 ERROR keystone.server.flask.application     return self.driver.get_project(project_id)
2023-02-27 10:34:49.495390 2023-02-27 10:34:49.491 37 ERROR keystone.server.flask.application   File "/var/lib/kolla/venv/lib/python3.9/site-packages/keystone/resource/backends/sql.py", line 49, in get_project
2023-02-27 10:34:49.495400 2023-02-27 10:34:49.491 37 ERROR keystone.server.flask.application     return self._get_project(session, project_id).to_dict()
2023-02-27 10:34:49.495410 2023-02-27 10:34:49.491 37 ERROR keystone.server.flask.application   File "/var/lib/kolla/venv/lib/python3.9/site-packages/keystone/resource/backends/sql.py", line 44, in _get_project
2023-02-27 10:34:49.495420 2023-02-27 10:34:49.491 37 ERROR keystone.server.flask.application     raise exception.ProjectNotFound(project_id=project_id)
2023-02-27 10:34:49.495429 2023-02-27 10:34:49.491 37 ERROR keystone.server.flask.application keystone.exception.ProjectNotFound: Could not find project: service.
2023-02-27 10:34:49.495439 2023-02-27 10:34:49.491 37 ERROR keystone.server.flask.application \x1b[00m
2023-02-27 10:41:57.120392 2023-02-27 10:41:57.119 37 WARNING py.warnings [None req-d54977f5-0fb3-42f4-8015-9997e92dd703 af1576daa3da461dbfebe1326fef3fc7 029e1b0c3ee54b70a5dd82fdce62c7f4 - - default default] /var/lib/kolla/venv/lib/python3.9/site-packages/oslo_policy/policy.py:1129: UserWarning: Policy "identity:list_domains": "role:reader and system_scope:all" failed scope check. The token used to make the request was project scoped but the policy requires ['system'] scope. This behavior may change in the future where using the intended scope is required
2023-02-27 10:41:57.120513   warnings.warn(msg)
2023-02-27 10:41:57.120534 \x1b[00m
2023-02-27 10:41:57.332216 2023-02-27 10:41:57.330 39 WARNING py.warnings [None req-d847929a-6c4d-4f64-9025-fdf91a545d36 af1576daa3da461dbfebe1326fef3fc7 029e1b0c3ee54b70a5dd82fdce62c7f4 - - default default] /var/lib/kolla/venv/lib/python3.9/site-packages/oslo_policy/policy.py:1129: UserWarning: Policy "identity:create_project": "(role:admin and system_scope:all) or (role:admin and domain_id:%(target.project.domain_id)s)" failed scope check. The token used to make the request was project scoped but the policy requires ['system', 'domain'] scope. This behavior may change in the future where using the intended scope is required
2023-02-27 10:41:57.332259   warnings.warn(msg)
2023-02-27 10:41:57.332269 \x1b[00m
2023-02-27 10:41:57.626755 2023-02-27 10:41:57.624 38 WARNING py.warnings [None req-064a75b8-d843-45af-96a0-f5beb6665bed af1576daa3da461dbfebe1326fef3fc7 029e1b0c3ee54b70a5dd82fdce62c7f4 - - default default] /var/lib/kolla/venv/lib/python3.9/site-packages/oslo_policy/policy.py:1129: UserWarning: Policy "identity:create_user": "(role:admin and system_scope:all) or (role:admin and token.domain.id:%(target.user.domain_id)s)" failed scope check. The token used to make the request was project scoped but the policy requires ['system', 'domain'] scope. This behavior may change in the future where using the intended scope is required
2023-02-27 10:41:57.626812   warnings.warn(msg)
2023-02-27 10:41:57.626822 \x1b[00m
2023-02-27 10:41:58.417060 2023-02-27 10:41:58.416 37 WARNING py.warnings [None req-c9ce8541-35d4-4f10-a7e0-de6f41790c60 af1576daa3da461dbfebe1326fef3fc7 029e1b0c3ee54b70a5dd82fdce62c7f4 - - default default] /var/lib/kolla/venv/lib/python3.9/site-packages/oslo_policy/policy.py:1129: UserWarning: Policy "identity:list_roles": "role:reader and system_scope:all" failed scope check. The token used to make the request was project scoped but the policy requires ['system'] scope. This behavior may change in the future where using the intended scope is required
2023-02-27 10:41:58.417102   warnings.warn(msg)
2023-02-27 10:41:58.417112 \x1b[00m
2023-02-27 10:41:58.706472 2023-02-27 10:41:58.705 39 WARNING py.warnings [None req-778fa7cf-0558-47e0-9b8e-1c598e0420f1 af1576daa3da461dbfebe1326fef3fc7 029e1b0c3ee54b70a5dd82fdce62c7f4 - - default default] /var/lib/kolla/venv/lib/python3.9/site-packages/oslo_policy/policy.py:1129: UserWarning: Policy "identity:create_grant": "(role:admin and system_scope:all) or ((role:admin and domain_id:%(target.user.domain_id)s and domain_id:%(target.project.domain_id)s) or (role:admin and domain_id:%(target.user.domain_id)s and domain_id:%(target.domain.id)s) or (role:admin and domain_id:%(target.group.domain_id)s and domain_id:%(target.project.domain_id)s) or (role:admin and domain_id:%(target.group.domain_id)s and domain_id:%(target.domain.id)s)) and (domain_id:%(target.role.domain_id)s or None:%(target.role.domain_id)s)" failed scope check. The token used to make the request was project scoped but the policy requires ['system', 'domain'] scope. This behavior may change in the future where using the intended scope is required
2023-02-27 10:41:58.706540   warnings.warn(msg)
2023-02-27 10:41:58.706550 \x1b[00m
2023-02-27 10:41:59.779835 2023-02-27 10:41:59.778 37 WARNING py.warnings [None req-d26275ac-94ca-41a6-b861-85b9413449cc af1576daa3da461dbfebe1326fef3fc7 029e1b0c3ee54b70a5dd82fdce62c7f4 - - default default] /var/lib/kolla/venv/lib/python3.9/site-packages/oslo_policy/policy.py:1129: UserWarning: Policy "identity:create_project": "(role:admin and system_scope:all) or (role:admin and domain_id:%(target.project.domain_id)s)" failed scope check. The token used to make the request was project scoped but the policy requires ['system', 'domain'] scope. This behavior may change in the future where using the intended scope is required
2023-02-27 10:41:59.779916   warnings.warn(msg)
2023-02-27 10:41:59.779928 \x1b[00m
2023-02-27 10:42:00.220061 2023-02-27 10:42:00.219 39 WARNING py.warnings [None req-1737e6fb-6a0c-42b5-b150-e16940379293 af1576daa3da461dbfebe1326fef3fc7 029e1b0c3ee54b70a5dd82fdce62c7f4 - - default default] /var/lib/kolla/venv/lib/python3.9/site-packages/oslo_policy/policy.py:1129: UserWarning: Policy "identity:create_user": "(role:admin and system_scope:all) or (role:admin and token.domain.id:%(target.user.domain_id)s)" failed scope check. The token used to make the request was project scoped but the policy requires ['system', 'domain'] scope. This behavior may change in the future where using the intended scope is required
2023-02-27 10:42:00.220102   warnings.warn(msg)
2023-02-27 10:42:00.220112 \x1b[00m
2023-02-27 10:42:01.133413 2023-02-27 10:42:01.132 38 WARNING py.warnings [None req-6fab8b50-4b3f-47bc-99da-f3665930054b af1576daa3da461dbfebe1326fef3fc7 029e1b0c3ee54b70a5dd82fdce62c7f4 - - default default] /var/lib/kolla/venv/lib/python3.9/site-packages/oslo_policy/policy.py:1129: UserWarning: Policy "identity:list_roles": "role:reader and system_scope:all" failed scope check. The token used to make the request was project scoped but the policy requires ['system'] scope. This behavior may change in the future where using the intended scope is required
2023-02-27 10:42:01.133459   warnings.warn(msg)
2023-02-27 10:42:01.133504 \x1b[00m
2023-02-27 10:42:01.428063 2023-02-27 10:42:01.426 37 WARNING py.warnings [None req-00e5c7aa-6620-44d2-92ee-d1c5ccdc5fff af1576daa3da461dbfebe1326fef3fc7 029e1b0c3ee54b70a5dd82fdce62c7f4 - - default default] /var/lib/kolla/venv/lib/python3.9/site-packages/oslo_policy/policy.py:1129: UserWarning: Policy "identity:create_grant": "(role:admin and system_scope:all) or ((role:admin and domain_id:%(target.user.domain_id)s and domain_id:%(target.project.domain_id)s) or (role:admin and domain_id:%(target.user.domain_id)s and domain_id:%(target.domain.id)s) or (role:admin and domain_id:%(target.group.domain_id)s and domain_id:%(target.project.domain_id)s) or (role:admin and domain_id:%(target.group.domain_id)s and domain_id:%(target.domain.id)s)) and (domain_id:%(target.role.domain_id)s or None:%(target.role.domain_id)s)" failed scope check. The token used to make the request was project scoped but the policy requires ['system', 'domain'] scope. This behavior may change in the future where using the intended scope is required
2023-02-27 10:42:01.428155   warnings.warn(msg)
2023-02-27 10:42:01.428177 \x1b[00m
2023-02-27 10:42:01.734219 2023-02-27 10:42:01.733 39 WARNING py.warnings [None req-ec73c601-5522-44b1-b388-916257232d98 af1576daa3da461dbfebe1326fef3fc7 029e1b0c3ee54b70a5dd82fdce62c7f4 - - default default] /var/lib/kolla/venv/lib/python3.9/site-packages/oslo_policy/policy.py:1129: UserWarning: Policy "identity:list_roles": "role:reader and system_scope:all" failed scope check. The token used to make the request was project scoped but the policy requires ['system'] scope. This behavior may change in the future where using the intended scope is required
2023-02-27 10:42:01.734291   warnings.warn(msg)
2023-02-27 10:42:01.734303 \x1b[00m
2023-02-27 10:42:02.030763 2023-02-27 10:42:02.029 38 WARNING py.warnings [None req-fe17a978-efc5-4052-b9c3-472e8172f208 af1576daa3da461dbfebe1326fef3fc7 029e1b0c3ee54b70a5dd82fdce62c7f4 - - default default] /var/lib/kolla/venv/lib/python3.9/site-packages/oslo_policy/policy.py:1129: UserWarning: Policy "identity:create_grant": "(role:admin and system_scope:all) or ((role:admin and domain_id:%(target.user.domain_id)s and domain_id:%(target.project.domain_id)s) or (role:admin and domain_id:%(target.user.domain_id)s and domain_id:%(target.domain.id)s) or (role:admin and domain_id:%(target.group.domain_id)s and domain_id:%(target.project.domain_id)s) or (role:admin and domain_id:%(target.group.domain_id)s and domain_id:%(target.domain.id)s)) and (domain_id:%(target.role.domain_id)s or None:%(target.role.domain_id)s)" failed scope check. The token used to make the request was project scoped but the policy requires ['system', 'domain'] scope. This behavior may change in the future where using the intended scope is required
2023-02-27 10:42:02.030835   warnings.warn(msg)
2023-02-27 10:42:02.030847 \x1b[00m
2023-02-27 10:42:04.254016 2023-02-27 10:42:04.253 37 WARNING py.warnings [None req-91d2bffa-c8c5-47d2-98cf-506af03cb7b8 af1576daa3da461dbfebe1326fef3fc7 029e1b0c3ee54b70a5dd82fdce62c7f4 - - default default] /var/lib/kolla/venv/lib/python3.9/site-packages/oslo_policy/policy.py:1129: UserWarning: Policy "identity:create_system_grant_for_user": "role:admin and system_scope:all" failed scope check. The token used to make the request was project scoped but the policy requires ['system'] scope. This behavior may change in the future where using the intended scope is required
2023-02-27 10:42:04.254070   warnings.warn(msg)
2023-02-27 10:42:04.254080 \x1b[00m
