2023-03-02 18:31:28.388813 2023-03-02 18:31:28.386 38 WARNING keystone.common.rbac_enforcer.enforcer [None req-cac20269-5b81-4f79-aa9c-40ee771d0d89 cf01766d1c3c4f0491c1efd319900764 - - all default -] Deprecated policy rules found. Use oslopolicy-policy-generator and oslopolicy-policy-upgrade to detect and resolve deprecated policies in your configuration.\x1b[00m
2023-03-02 18:31:29.200333 2023-03-02 18:31:29.198 36 WARNING keystone.common.rbac_enforcer.enforcer [None req-a8bf0a23-2485-4ee5-8584-1d3115e6a0a6 cf01766d1c3c4f0491c1efd319900764 - - all default -] Deprecated policy rules found. Use oslopolicy-policy-generator and oslopolicy-policy-upgrade to detect and resolve deprecated policies in your configuration.\x1b[00m
2023-03-02 18:31:36.923029 2023-03-02 18:31:36.921 37 WARNING keystone.common.rbac_enforcer.enforcer [None req-c9e66077-e836-451c-9a12-1220f174f086 cf01766d1c3c4f0491c1efd319900764 - - all default -] Deprecated policy rules found. Use oslopolicy-policy-generator and oslopolicy-policy-upgrade to detect and resolve deprecated policies in your configuration.\x1b[00m
2023-03-02 18:32:58.007623 2023-03-02 18:32:57.992 38 ERROR keystone.server.flask.application [None req-586b19bd-2294-42f5-8942-48a569ab1ffc cf01766d1c3c4f0491c1efd319900764 - - all default -] Could not find project: service.: keystone.exception.ProjectNotFound: Could not find project: service.
2023-03-02 18:32:58.007703 2023-03-02 18:32:57.992 38 ERROR keystone.server.flask.application Traceback (most recent call last):
2023-03-02 18:32:58.007799 2023-03-02 18:32:57.992 38 ERROR keystone.server.flask.application   File "/var/lib/kolla/venv/lib/python3.9/site-packages/flask/app.py", line 1820, in full_dispatch_request
2023-03-02 18:32:58.007829 2023-03-02 18:32:57.992 38 ERROR keystone.server.flask.application     rv = self.dispatch_request()
2023-03-02 18:32:58.007847 2023-03-02 18:32:57.992 38 ERROR keystone.server.flask.application   File "/var/lib/kolla/venv/lib/python3.9/site-packages/flask/app.py", line 1796, in dispatch_request
2023-03-02 18:32:58.007861 2023-03-02 18:32:57.992 38 ERROR keystone.server.flask.application     return self.ensure_sync(self.view_functions[rule.endpoint])(**view_args)
2023-03-02 18:32:58.007873 2023-03-02 18:32:57.992 38 ERROR keystone.server.flask.application   File "/var/lib/kolla/venv/lib/python3.9/site-packages/flask_restful/__init__.py", line 467, in wrapper
2023-03-02 18:32:58.007886 2023-03-02 18:32:57.992 38 ERROR keystone.server.flask.application     resp = resource(*args, **kwargs)
2023-03-02 18:32:58.007909 2023-03-02 18:32:57.992 38 ERROR keystone.server.flask.application   File "/var/lib/kolla/venv/lib/python3.9/site-packages/flask/views.py", line 107, in view
2023-03-02 18:32:58.007925 2023-03-02 18:32:57.992 38 ERROR keystone.server.flask.application     return current_app.ensure_sync(self.dispatch_request)(**kwargs)
2023-03-02 18:32:58.007938 2023-03-02 18:32:57.992 38 ERROR keystone.server.flask.application   File "/var/lib/kolla/venv/lib/python3.9/site-packages/flask_restful/__init__.py", line 582, in dispatch_request
2023-03-02 18:32:58.007951 2023-03-02 18:32:57.992 38 ERROR keystone.server.flask.application     resp = meth(*args, **kwargs)
2023-03-02 18:32:58.007963 2023-03-02 18:32:57.992 38 ERROR keystone.server.flask.application   File "/var/lib/kolla/venv/lib/python3.9/site-packages/keystone/api/projects.py", line 151, in get
2023-03-02 18:32:58.007977 2023-03-02 18:32:57.992 38 ERROR keystone.server.flask.application     return self._get_project(project_id)
2023-03-02 18:32:58.007989 2023-03-02 18:32:57.992 38 ERROR keystone.server.flask.application   File "/var/lib/kolla/venv/lib/python3.9/site-packages/keystone/api/projects.py", line 107, in _get_project
2023-03-02 18:32:58.008002 2023-03-02 18:32:57.992 38 ERROR keystone.server.flask.application     project = PROVIDERS.resource_api.get_project(project_id)
2023-03-02 18:32:58.008014 2023-03-02 18:32:57.992 38 ERROR keystone.server.flask.application   File "/var/lib/kolla/venv/lib/python3.9/site-packages/keystone/common/manager.py", line 115, in wrapped
2023-03-02 18:32:58.008100 2023-03-02 18:32:57.992 38 ERROR keystone.server.flask.application     __ret_val = __f(*args, **kwargs)
2023-03-02 18:32:58.008118 2023-03-02 18:32:57.992 38 ERROR keystone.server.flask.application   File "/var/lib/kolla/venv/lib/python3.9/site-packages/decorator.py", line 232, in fun
2023-03-02 18:32:58.008131 2023-03-02 18:32:57.992 38 ERROR keystone.server.flask.application     return caller(func, *(extras + args), **kw)
2023-03-02 18:32:58.008144 2023-03-02 18:32:57.992 38 ERROR keystone.server.flask.application   File "/var/lib/kolla/venv/lib/python3.9/site-packages/dogpile/cache/region.py", line 1577, in get_or_create_for_user_func
2023-03-02 18:32:58.008157 2023-03-02 18:32:57.992 38 ERROR keystone.server.flask.application     return self.get_or_create(
2023-03-02 18:32:58.008170 2023-03-02 18:32:57.992 38 ERROR keystone.server.flask.application   File "/var/lib/kolla/venv/lib/python3.9/site-packages/dogpile/cache/region.py", line 1042, in get_or_create
2023-03-02 18:32:58.008183 2023-03-02 18:32:57.992 38 ERROR keystone.server.flask.application     with Lock(
2023-03-02 18:32:58.008196 2023-03-02 18:32:57.992 38 ERROR keystone.server.flask.application   File "/var/lib/kolla/venv/lib/python3.9/site-packages/dogpile/lock.py", line 185, in __enter__
2023-03-02 18:32:58.008209 2023-03-02 18:32:57.992 38 ERROR keystone.server.flask.application     return self._enter()
2023-03-02 18:32:58.008221 2023-03-02 18:32:57.992 38 ERROR keystone.server.flask.application   File "/var/lib/kolla/venv/lib/python3.9/site-packages/dogpile/lock.py", line 94, in _enter
2023-03-02 18:32:58.008234 2023-03-02 18:32:57.992 38 ERROR keystone.server.flask.application     generated = self._enter_create(value, createdtime)
2023-03-02 18:32:58.008247 2023-03-02 18:32:57.992 38 ERROR keystone.server.flask.application   File "/var/lib/kolla/venv/lib/python3.9/site-packages/dogpile/lock.py", line 178, in _enter_create
2023-03-02 18:32:58.008260 2023-03-02 18:32:57.992 38 ERROR keystone.server.flask.application     return self.creator()
2023-03-02 18:32:58.008272 2023-03-02 18:32:57.992 38 ERROR keystone.server.flask.application   File "/var/lib/kolla/venv/lib/python3.9/site-packages/dogpile/cache/region.py", line 995, in gen_value
2023-03-02 18:32:58.008285 2023-03-02 18:32:57.992 38 ERROR keystone.server.flask.application     created_value = creator(
2023-03-02 18:32:58.008298 2023-03-02 18:32:57.992 38 ERROR keystone.server.flask.application   File "/var/lib/kolla/venv/lib/python3.9/site-packages/keystone/resource/core.py", line 903, in get_project
2023-03-02 18:32:58.008311 2023-03-02 18:32:57.992 38 ERROR keystone.server.flask.application     return self.driver.get_project(project_id)
2023-03-02 18:32:58.008324 2023-03-02 18:32:57.992 38 ERROR keystone.server.flask.application   File "/var/lib/kolla/venv/lib/python3.9/site-packages/keystone/resource/backends/sql.py", line 49, in get_project
2023-03-02 18:32:58.008337 2023-03-02 18:32:57.992 38 ERROR keystone.server.flask.application     return self._get_project(session, project_id).to_dict()
2023-03-02 18:32:58.008349 2023-03-02 18:32:57.992 38 ERROR keystone.server.flask.application   File "/var/lib/kolla/venv/lib/python3.9/site-packages/keystone/resource/backends/sql.py", line 44, in _get_project
2023-03-02 18:32:58.008363 2023-03-02 18:32:57.992 38 ERROR keystone.server.flask.application     raise exception.ProjectNotFound(project_id=project_id)
2023-03-02 18:32:58.008375 2023-03-02 18:32:57.992 38 ERROR keystone.server.flask.application keystone.exception.ProjectNotFound: Could not find project: service.
2023-03-02 18:32:58.008388 2023-03-02 18:32:57.992 38 ERROR keystone.server.flask.application \x1b[00m
2023-03-02 18:33:07.845511 2023-03-02 18:33:07.831 37 ERROR keystone.server.flask.application [None req-524eb262-b103-40c6-aad9-88c6d3d13a0b cf01766d1c3c4f0491c1efd319900764 - - all default -] Could not find project: service.: keystone.exception.ProjectNotFound: Could not find project: service.
2023-03-02 18:33:07.845563 2023-03-02 18:33:07.831 37 ERROR keystone.server.flask.application Traceback (most recent call last):
2023-03-02 18:33:07.845633 2023-03-02 18:33:07.831 37 ERROR keystone.server.flask.application   File "/var/lib/kolla/venv/lib/python3.9/site-packages/flask/app.py", line 1820, in full_dispatch_request
2023-03-02 18:33:07.845649 2023-03-02 18:33:07.831 37 ERROR keystone.server.flask.application     rv = self.dispatch_request()
2023-03-02 18:33:07.845658 2023-03-02 18:33:07.831 37 ERROR keystone.server.flask.application   File "/var/lib/kolla/venv/lib/python3.9/site-packages/flask/app.py", line 1796, in dispatch_request
2023-03-02 18:33:07.845669 2023-03-02 18:33:07.831 37 ERROR keystone.server.flask.application     return self.ensure_sync(self.view_functions[rule.endpoint])(**view_args)
2023-03-02 18:33:07.845678 2023-03-02 18:33:07.831 37 ERROR keystone.server.flask.application   File "/var/lib/kolla/venv/lib/python3.9/site-packages/flask_restful/__init__.py", line 467, in wrapper
2023-03-02 18:33:07.845688 2023-03-02 18:33:07.831 37 ERROR keystone.server.flask.application     resp = resource(*args, **kwargs)
2023-03-02 18:33:07.845730 2023-03-02 18:33:07.831 37 ERROR keystone.server.flask.application   File "/var/lib/kolla/venv/lib/python3.9/site-packages/flask/views.py", line 107, in view
2023-03-02 18:33:07.845746 2023-03-02 18:33:07.831 37 ERROR keystone.server.flask.application     return current_app.ensure_sync(self.dispatch_request)(**kwargs)
2023-03-02 18:33:07.845756 2023-03-02 18:33:07.831 37 ERROR keystone.server.flask.application   File "/var/lib/kolla/venv/lib/python3.9/site-packages/flask_restful/__init__.py", line 582, in dispatch_request
2023-03-02 18:33:07.845765 2023-03-02 18:33:07.831 37 ERROR keystone.server.flask.application     resp = meth(*args, **kwargs)
2023-03-02 18:33:07.845782 2023-03-02 18:33:07.831 37 ERROR keystone.server.flask.application   File "/var/lib/kolla/venv/lib/python3.9/site-packages/keystone/api/projects.py", line 151, in get
2023-03-02 18:33:07.845792 2023-03-02 18:33:07.831 37 ERROR keystone.server.flask.application     return self._get_project(project_id)
2023-03-02 18:33:07.845802 2023-03-02 18:33:07.831 37 ERROR keystone.server.flask.application   File "/var/lib/kolla/venv/lib/python3.9/site-packages/keystone/api/projects.py", line 107, in _get_project
2023-03-02 18:33:07.845811 2023-03-02 18:33:07.831 37 ERROR keystone.server.flask.application     project = PROVIDERS.resource_api.get_project(project_id)
2023-03-02 18:33:07.845821 2023-03-02 18:33:07.831 37 ERROR keystone.server.flask.application   File "/var/lib/kolla/venv/lib/python3.9/site-packages/keystone/common/manager.py", line 115, in wrapped
2023-03-02 18:33:07.845830 2023-03-02 18:33:07.831 37 ERROR keystone.server.flask.application     __ret_val = __f(*args, **kwargs)
2023-03-02 18:33:07.845840 2023-03-02 18:33:07.831 37 ERROR keystone.server.flask.application   File "/var/lib/kolla/venv/lib/python3.9/site-packages/decorator.py", line 232, in fun
2023-03-02 18:33:07.845849 2023-03-02 18:33:07.831 37 ERROR keystone.server.flask.application     return caller(func, *(extras + args), **kw)
2023-03-02 18:33:07.845859 2023-03-02 18:33:07.831 37 ERROR keystone.server.flask.application   File "/var/lib/kolla/venv/lib/python3.9/site-packages/dogpile/cache/region.py", line 1577, in get_or_create_for_user_func
2023-03-02 18:33:07.845873 2023-03-02 18:33:07.831 37 ERROR keystone.server.flask.application     return self.get_or_create(
2023-03-02 18:33:07.845893 2023-03-02 18:33:07.831 37 ERROR keystone.server.flask.application   File "/var/lib/kolla/venv/lib/python3.9/site-packages/dogpile/cache/region.py", line 1042, in get_or_create
2023-03-02 18:33:07.845912 2023-03-02 18:33:07.831 37 ERROR keystone.server.flask.application     with Lock(
2023-03-02 18:33:07.845931 2023-03-02 18:33:07.831 37 ERROR keystone.server.flask.application   File "/var/lib/kolla/venv/lib/python3.9/site-packages/dogpile/lock.py", line 185, in __enter__
2023-03-02 18:33:07.845951 2023-03-02 18:33:07.831 37 ERROR keystone.server.flask.application     return self._enter()
2023-03-02 18:33:07.846006 2023-03-02 18:33:07.831 37 ERROR keystone.server.flask.application   File "/var/lib/kolla/venv/lib/python3.9/site-packages/dogpile/lock.py", line 94, in _enter
2023-03-02 18:33:07.846050 2023-03-02 18:33:07.831 37 ERROR keystone.server.flask.application     generated = self._enter_create(value, createdtime)
2023-03-02 18:33:07.846068 2023-03-02 18:33:07.831 37 ERROR keystone.server.flask.application   File "/var/lib/kolla/venv/lib/python3.9/site-packages/dogpile/lock.py", line 178, in _enter_create
2023-03-02 18:33:07.846099 2023-03-02 18:33:07.831 37 ERROR keystone.server.flask.application     return self.creator()
2023-03-02 18:33:07.846117 2023-03-02 18:33:07.831 37 ERROR keystone.server.flask.application   File "/var/lib/kolla/venv/lib/python3.9/site-packages/dogpile/cache/region.py", line 995, in gen_value
2023-03-02 18:33:07.846138 2023-03-02 18:33:07.831 37 ERROR keystone.server.flask.application     created_value = creator(
2023-03-02 18:33:07.846157 2023-03-02 18:33:07.831 37 ERROR keystone.server.flask.application   File "/var/lib/kolla/venv/lib/python3.9/site-packages/keystone/resource/core.py", line 903, in get_project
2023-03-02 18:33:07.846176 2023-03-02 18:33:07.831 37 ERROR keystone.server.flask.application     return self.driver.get_project(project_id)
2023-03-02 18:33:07.846194 2023-03-02 18:33:07.831 37 ERROR keystone.server.flask.application   File "/var/lib/kolla/venv/lib/python3.9/site-packages/keystone/resource/backends/sql.py", line 49, in get_project
2023-03-02 18:33:07.846205 2023-03-02 18:33:07.831 37 ERROR keystone.server.flask.application     return self._get_project(session, project_id).to_dict()
2023-03-02 18:33:07.846214 2023-03-02 18:33:07.831 37 ERROR keystone.server.flask.application   File "/var/lib/kolla/venv/lib/python3.9/site-packages/keystone/resource/backends/sql.py", line 44, in _get_project
2023-03-02 18:33:07.846224 2023-03-02 18:33:07.831 37 ERROR keystone.server.flask.application     raise exception.ProjectNotFound(project_id=project_id)
2023-03-02 18:33:07.846233 2023-03-02 18:33:07.831 37 ERROR keystone.server.flask.application keystone.exception.ProjectNotFound: Could not find project: service.
2023-03-02 18:33:07.846242 2023-03-02 18:33:07.831 37 ERROR keystone.server.flask.application \x1b[00m
2023-03-02 18:33:22.672345 2023-03-02 18:33:22.659 37 ERROR keystone.server.flask.application [None req-eca5fdfe-3532-4d3a-934a-746f729e09ea cf01766d1c3c4f0491c1efd319900764 - - all default -] Could not find role: admin.: keystone.exception.RoleNotFound: Could not find role: admin.
2023-03-02 18:33:22.672433 2023-03-02 18:33:22.659 37 ERROR keystone.server.flask.application Traceback (most recent call last):
2023-03-02 18:33:22.672559 2023-03-02 18:33:22.659 37 ERROR keystone.server.flask.application   File "/var/lib/kolla/venv/lib/python3.9/site-packages/flask/app.py", line 1820, in full_dispatch_request
2023-03-02 18:33:22.672699 2023-03-02 18:33:22.659 37 ERROR keystone.server.flask.application     rv = self.dispatch_request()
2023-03-02 18:33:22.672736 2023-03-02 18:33:22.659 37 ERROR keystone.server.flask.application   File "/var/lib/kolla/venv/lib/python3.9/site-packages/flask/app.py", line 1796, in dispatch_request
2023-03-02 18:33:22.672759 2023-03-02 18:33:22.659 37 ERROR keystone.server.flask.application     return self.ensure_sync(self.view_functions[rule.endpoint])(**view_args)
2023-03-02 18:33:22.672780 2023-03-02 18:33:22.659 37 ERROR keystone.server.flask.application   File "/var/lib/kolla/venv/lib/python3.9/site-packages/flask_restful/__init__.py", line 467, in wrapper
2023-03-02 18:33:22.672801 2023-03-02 18:33:22.659 37 ERROR keystone.server.flask.application     resp = resource(*args, **kwargs)
2023-03-02 18:33:22.672838 2023-03-02 18:33:22.659 37 ERROR keystone.server.flask.application   File "/var/lib/kolla/venv/lib/python3.9/site-packages/flask/views.py", line 107, in view
2023-03-02 18:33:22.672868 2023-03-02 18:33:22.659 37 ERROR keystone.server.flask.application     return current_app.ensure_sync(self.dispatch_request)(**kwargs)
2023-03-02 18:33:22.672894 2023-03-02 18:33:22.659 37 ERROR keystone.server.flask.application   File "/var/lib/kolla/venv/lib/python3.9/site-packages/flask_restful/__init__.py", line 582, in dispatch_request
2023-03-02 18:33:22.672950 2023-03-02 18:33:22.659 37 ERROR keystone.server.flask.application     resp = meth(*args, **kwargs)
2023-03-02 18:33:22.673039 2023-03-02 18:33:22.659 37 ERROR keystone.server.flask.application   File "/var/lib/kolla/venv/lib/python3.9/site-packages/keystone/api/roles.py", line 50, in get
2023-03-02 18:33:22.673068 2023-03-02 18:33:22.659 37 ERROR keystone.server.flask.application     return self._get_role(role_id)
2023-03-02 18:33:22.673108 2023-03-02 18:33:22.659 37 ERROR keystone.server.flask.application   File "/var/lib/kolla/venv/lib/python3.9/site-packages/keystone/api/roles.py", line 70, in _get_role
2023-03-02 18:33:22.673137 2023-03-02 18:33:22.659 37 ERROR keystone.server.flask.application     ENFORCER.enforce_call(action='identity:get_role')
2023-03-02 18:33:22.673183 2023-03-02 18:33:22.659 37 ERROR keystone.server.flask.application   File "/var/lib/kolla/venv/lib/python3.9/site-packages/keystone/common/rbac_enforcer/enforcer.py", line 402, in enforce_call
2023-03-02 18:33:22.673218 2023-03-02 18:33:22.659 37 ERROR keystone.server.flask.application     policy_dict.update(cls._extract_member_target_data(
2023-03-02 18:33:22.673265 2023-03-02 18:33:22.659 37 ERROR keystone.server.flask.application   File "/var/lib/kolla/venv/lib/python3.9/site-packages/keystone/common/rbac_enforcer/enforcer.py", line 234, in _extract_member_target_data
2023-03-02 18:33:22.673298 2023-03-02 18:33:22.659 37 ERROR keystone.server.flask.application     member_name: func(flask.request.view_args[key])
2023-03-02 18:33:22.673322 2023-03-02 18:33:22.659 37 ERROR keystone.server.flask.application   File "/var/lib/kolla/venv/lib/python3.9/site-packages/keystone/common/manager.py", line 115, in wrapped
2023-03-02 18:33:22.673337 2023-03-02 18:33:22.659 37 ERROR keystone.server.flask.application     __ret_val = __f(*args, **kwargs)
2023-03-02 18:33:22.673350 2023-03-02 18:33:22.659 37 ERROR keystone.server.flask.application   File "/var/lib/kolla/venv/lib/python3.9/site-packages/decorator.py", line 232, in fun
2023-03-02 18:33:22.673362 2023-03-02 18:33:22.659 37 ERROR keystone.server.flask.application     return caller(func, *(extras + args), **kw)
2023-03-02 18:33:22.673375 2023-03-02 18:33:22.659 37 ERROR keystone.server.flask.application   File "/var/lib/kolla/venv/lib/python3.9/site-packages/dogpile/cache/region.py", line 1577, in get_or_create_for_user_func
2023-03-02 18:33:22.673388 2023-03-02 18:33:22.659 37 ERROR keystone.server.flask.application     return self.get_or_create(
2023-03-02 18:33:22.673400 2023-03-02 18:33:22.659 37 ERROR keystone.server.flask.application   File "/var/lib/kolla/venv/lib/python3.9/site-packages/dogpile/cache/region.py", line 1042, in get_or_create
2023-03-02 18:33:22.673414 2023-03-02 18:33:22.659 37 ERROR keystone.server.flask.application     with Lock(
2023-03-02 18:33:22.673426 2023-03-02 18:33:22.659 37 ERROR keystone.server.flask.application   File "/var/lib/kolla/venv/lib/python3.9/site-packages/dogpile/lock.py", line 185, in __enter__
2023-03-02 18:33:22.673438 2023-03-02 18:33:22.659 37 ERROR keystone.server.flask.application     return self._enter()
2023-03-02 18:33:22.673451 2023-03-02 18:33:22.659 37 ERROR keystone.server.flask.application   File "/var/lib/kolla/venv/lib/python3.9/site-packages/dogpile/lock.py", line 94, in _enter
2023-03-02 18:33:22.673485 2023-03-02 18:33:22.659 37 ERROR keystone.server.flask.application     generated = self._enter_create(value, createdtime)
2023-03-02 18:33:22.673508 2023-03-02 18:33:22.659 37 ERROR keystone.server.flask.application   File "/var/lib/kolla/venv/lib/python3.9/site-packages/dogpile/lock.py", line 178, in _enter_create
2023-03-02 18:33:22.673521 2023-03-02 18:33:22.659 37 ERROR keystone.server.flask.application     return self.creator()
2023-03-02 18:33:22.673534 2023-03-02 18:33:22.659 37 ERROR keystone.server.flask.application   File "/var/lib/kolla/venv/lib/python3.9/site-packages/dogpile/cache/region.py", line 995, in gen_value
2023-03-02 18:33:22.673565 2023-03-02 18:33:22.659 37 ERROR keystone.server.flask.application     created_value = creator(
2023-03-02 18:33:22.673631 2023-03-02 18:33:22.659 37 ERROR keystone.server.flask.application   File "/var/lib/kolla/venv/lib/python3.9/site-packages/keystone/assignment/core.py", line 1276, in get_role
2023-03-02 18:33:22.673665 2023-03-02 18:33:22.659 37 ERROR keystone.server.flask.application     return self.driver.get_role(role_id)
2023-03-02 18:33:22.673681 2023-03-02 18:33:22.659 37 ERROR keystone.server.flask.application   File "/var/lib/kolla/venv/lib/python3.9/site-packages/keystone/assignment/role_backends/sql.py", line 70, in get_role
2023-03-02 18:33:22.673694 2023-03-02 18:33:22.659 37 ERROR keystone.server.flask.application     return self._get_role(session, role_id).to_dict()
2023-03-02 18:33:22.673707 2023-03-02 18:33:22.659 37 ERROR keystone.server.flask.application   File "/var/lib/kolla/venv/lib/python3.9/site-packages/keystone/assignment/role_backends/sql.py", line 65, in _get_role
2023-03-02 18:33:22.673719 2023-03-02 18:33:22.659 37 ERROR keystone.server.flask.application     raise exception.RoleNotFound(role_id=role_id)
2023-03-02 18:33:22.673732 2023-03-02 18:33:22.659 37 ERROR keystone.server.flask.application keystone.exception.RoleNotFound: Could not find role: admin.
2023-03-02 18:33:22.673745 2023-03-02 18:33:22.659 37 ERROR keystone.server.flask.application \x1b[00m
2023-03-02 18:33:24.064130 2023-03-02 18:33:24.058 37 ERROR keystone.server.flask.application [None req-2b9d8054-4ff3-4420-a93b-92f1df990411 cf01766d1c3c4f0491c1efd319900764 - - all default -] Could not find user: ironic.: keystone.exception.UserNotFound: Could not find user: ironic.
2023-03-02 18:33:24.064172 2023-03-02 18:33:24.058 37 ERROR keystone.server.flask.application Traceback (most recent call last):
2023-03-02 18:33:24.064183 2023-03-02 18:33:24.058 37 ERROR keystone.server.flask.application   File "/var/lib/kolla/venv/lib/python3.9/site-packages/flask/app.py", line 1820, in full_dispatch_request
2023-03-02 18:33:24.064197 2023-03-02 18:33:24.058 37 ERROR keystone.server.flask.application     rv = self.dispatch_request()
2023-03-02 18:33:24.064221 2023-03-02 18:33:24.058 37 ERROR keystone.server.flask.application   File "/var/lib/kolla/venv/lib/python3.9/site-packages/flask/app.py", line 1796, in dispatch_request
2023-03-02 18:33:24.064232 2023-03-02 18:33:24.058 37 ERROR keystone.server.flask.application     return self.ensure_sync(self.view_functions[rule.endpoint])(**view_args)
2023-03-02 18:33:24.064241 2023-03-02 18:33:24.058 37 ERROR keystone.server.flask.application   File "/var/lib/kolla/venv/lib/python3.9/site-packages/flask_restful/__init__.py", line 467, in wrapper
2023-03-02 18:33:24.064251 2023-03-02 18:33:24.058 37 ERROR keystone.server.flask.application     resp = resource(*args, **kwargs)
2023-03-02 18:33:24.064261 2023-03-02 18:33:24.058 37 ERROR keystone.server.flask.application   File "/var/lib/kolla/venv/lib/python3.9/site-packages/flask/views.py", line 107, in view
2023-03-02 18:33:24.064272 2023-03-02 18:33:24.058 37 ERROR keystone.server.flask.application     return current_app.ensure_sync(self.dispatch_request)(**kwargs)
2023-03-02 18:33:24.064282 2023-03-02 18:33:24.058 37 ERROR keystone.server.flask.application   File "/var/lib/kolla/venv/lib/python3.9/site-packages/flask_restful/__init__.py", line 582, in dispatch_request
2023-03-02 18:33:24.064291 2023-03-02 18:33:24.058 37 ERROR keystone.server.flask.application     resp = meth(*args, **kwargs)
2023-03-02 18:33:24.064301 2023-03-02 18:33:24.058 37 ERROR keystone.server.flask.application   File "/var/lib/kolla/venv/lib/python3.9/site-packages/keystone/api/users.py", line 182, in get
2023-03-02 18:33:24.064311 2023-03-02 18:33:24.058 37 ERROR keystone.server.flask.application     return self._get_user(user_id)
2023-03-02 18:33:24.064320 2023-03-02 18:33:24.058 37 ERROR keystone.server.flask.application   File "/var/lib/kolla/venv/lib/python3.9/site-packages/keystone/api/users.py", line 194, in _get_user
2023-03-02 18:33:24.064356 2023-03-02 18:33:24.058 37 ERROR keystone.server.flask.application     ref = PROVIDERS.identity_api.get_user(user_id)
2023-03-02 18:33:24.064369 2023-03-02 18:33:24.058 37 ERROR keystone.server.flask.application   File "/var/lib/kolla/venv/lib/python3.9/site-packages/keystone/common/manager.py", line 115, in wrapped
2023-03-02 18:33:24.064379 2023-03-02 18:33:24.058 37 ERROR keystone.server.flask.application     __ret_val = __f(*args, **kwargs)
2023-03-02 18:33:24.064389 2023-03-02 18:33:24.058 37 ERROR keystone.server.flask.application   File "/var/lib/kolla/venv/lib/python3.9/site-packages/keystone/identity/core.py", line 414, in wrapper
2023-03-02 18:33:24.064398 2023-03-02 18:33:24.058 37 ERROR keystone.server.flask.application     return f(self, *args, **kwargs)
2023-03-02 18:33:24.064408 2023-03-02 18:33:24.058 37 ERROR keystone.server.flask.application   File "/var/lib/kolla/venv/lib/python3.9/site-packages/keystone/identity/core.py", line 424, in wrapper
2023-03-02 18:33:24.064418 2023-03-02 18:33:24.058 37 ERROR keystone.server.flask.application     return f(self, *args, **kwargs)
2023-03-02 18:33:24.064427 2023-03-02 18:33:24.058 37 ERROR keystone.server.flask.application   File "/var/lib/kolla/venv/lib/python3.9/site-packages/decorator.py", line 232, in fun
2023-03-02 18:33:24.064437 2023-03-02 18:33:24.058 37 ERROR keystone.server.flask.application     return caller(func, *(extras + args), **kw)
2023-03-02 18:33:24.064447 2023-03-02 18:33:24.058 37 ERROR keystone.server.flask.application   File "/var/lib/kolla/venv/lib/python3.9/site-packages/dogpile/cache/region.py", line 1577, in get_or_create_for_user_func
2023-03-02 18:33:24.064457 2023-03-02 18:33:24.058 37 ERROR keystone.server.flask.application     return self.get_or_create(
2023-03-02 18:33:24.064484 2023-03-02 18:33:24.058 37 ERROR keystone.server.flask.application   File "/var/lib/kolla/venv/lib/python3.9/site-packages/dogpile/cache/region.py", line 1042, in get_or_create
2023-03-02 18:33:24.064498 2023-03-02 18:33:24.058 37 ERROR keystone.server.flask.application     with Lock(
2023-03-02 18:33:24.064507 2023-03-02 18:33:24.058 37 ERROR keystone.server.flask.application   File "/var/lib/kolla/venv/lib/python3.9/site-packages/dogpile/lock.py", line 185, in __enter__
2023-03-02 18:33:24.064516 2023-03-02 18:33:24.058 37 ERROR keystone.server.flask.application     return self._enter()
2023-03-02 18:33:24.064526 2023-03-02 18:33:24.058 37 ERROR keystone.server.flask.application   File "/var/lib/kolla/venv/lib/python3.9/site-packages/dogpile/lock.py", line 94, in _enter
2023-03-02 18:33:24.064535 2023-03-02 18:33:24.058 37 ERROR keystone.server.flask.application     generated = self._enter_create(value, createdtime)
2023-03-02 18:33:24.064544 2023-03-02 18:33:24.058 37 ERROR keystone.server.flask.application   File "/var/lib/kolla/venv/lib/python3.9/site-packages/dogpile/lock.py", line 178, in _enter_create
2023-03-02 18:33:24.064553 2023-03-02 18:33:24.058 37 ERROR keystone.server.flask.application     return self.creator()
2023-03-02 18:33:24.064562 2023-03-02 18:33:24.058 37 ERROR keystone.server.flask.application   File "/var/lib/kolla/venv/lib/python3.9/site-packages/dogpile/cache/region.py", line 995, in gen_value
2023-03-02 18:33:24.064572 2023-03-02 18:33:24.058 37 ERROR keystone.server.flask.application     created_value = creator(
2023-03-02 18:33:24.064609 2023-03-02 18:33:24.058 37 ERROR keystone.server.flask.application   File "/var/lib/kolla/venv/lib/python3.9/site-packages/keystone/identity/core.py", line 1011, in get_user
2023-03-02 18:33:24.064621 2023-03-02 18:33:24.058 37 ERROR keystone.server.flask.application     ref = driver.get_user(entity_id)
2023-03-02 18:33:24.064631 2023-03-02 18:33:24.058 37 ERROR keystone.server.flask.application   File "/var/lib/kolla/venv/lib/python3.9/site-packages/keystone/identity/backends/sql.py", line 200, in get_user
2023-03-02 18:33:24.064640 2023-03-02 18:33:24.058 37 ERROR keystone.server.flask.application     self._get_user(session, user_id).to_dict())
2023-03-02 18:33:24.064783 2023-03-02 18:33:24.058 37 ERROR keystone.server.flask.application   File "/var/lib/kolla/venv/lib/python3.9/site-packages/keystone/identity/backends/sql.py", line 194, in _get_user
2023-03-02 18:33:24.064797 2023-03-02 18:33:24.058 37 ERROR keystone.server.flask.application     raise exception.UserNotFound(user_id=user_id)
2023-03-02 18:33:24.064807 2023-03-02 18:33:24.058 37 ERROR keystone.server.flask.application keystone.exception.UserNotFound: Could not find user: ironic.
2023-03-02 18:33:24.064816 2023-03-02 18:33:24.058 37 ERROR keystone.server.flask.application \x1b[00m
2023-03-02 18:33:24.989079 2023-03-02 18:33:24.977 36 ERROR keystone.server.flask.application [None req-d210c86b-4944-4ab2-9d5d-5fb581a29d1b cf01766d1c3c4f0491c1efd319900764 - - all default -] Could not find project: service.: keystone.exception.ProjectNotFound: Could not find project: service.
2023-03-02 18:33:24.989122 2023-03-02 18:33:24.977 36 ERROR keystone.server.flask.application Traceback (most recent call last):
2023-03-02 18:33:24.989133 2023-03-02 18:33:24.977 36 ERROR keystone.server.flask.application   File "/var/lib/kolla/venv/lib/python3.9/site-packages/flask/app.py", line 1820, in full_dispatch_request
2023-03-02 18:33:24.989158 2023-03-02 18:33:24.977 36 ERROR keystone.server.flask.application     rv = self.dispatch_request()
2023-03-02 18:33:24.989171 2023-03-02 18:33:24.977 36 ERROR keystone.server.flask.application   File "/var/lib/kolla/venv/lib/python3.9/site-packages/flask/app.py", line 1796, in dispatch_request
2023-03-02 18:33:24.989181 2023-03-02 18:33:24.977 36 ERROR keystone.server.flask.application     return self.ensure_sync(self.view_functions[rule.endpoint])(**view_args)
2023-03-02 18:33:24.989201 2023-03-02 18:33:24.977 36 ERROR keystone.server.flask.application   File "/var/lib/kolla/venv/lib/python3.9/site-packages/flask_restful/__init__.py", line 467, in wrapper
2023-03-02 18:33:24.989213 2023-03-02 18:33:24.977 36 ERROR keystone.server.flask.application     resp = resource(*args, **kwargs)
2023-03-02 18:33:24.989230 2023-03-02 18:33:24.977 36 ERROR keystone.server.flask.application   File "/var/lib/kolla/venv/lib/python3.9/site-packages/flask/views.py", line 107, in view
2023-03-02 18:33:24.989243 2023-03-02 18:33:24.977 36 ERROR keystone.server.flask.application     return current_app.ensure_sync(self.dispatch_request)(**kwargs)
2023-03-02 18:33:24.989252 2023-03-02 18:33:24.977 36 ERROR keystone.server.flask.application   File "/var/lib/kolla/venv/lib/python3.9/site-packages/flask_restful/__init__.py", line 582, in dispatch_request
2023-03-02 18:33:24.989262 2023-03-02 18:33:24.977 36 ERROR keystone.server.flask.application     resp = meth(*args, **kwargs)
2023-03-02 18:33:24.989272 2023-03-02 18:33:24.977 36 ERROR keystone.server.flask.application   File "/var/lib/kolla/venv/lib/python3.9/site-packages/keystone/api/projects.py", line 151, in get
2023-03-02 18:33:24.989282 2023-03-02 18:33:24.977 36 ERROR keystone.server.flask.application     return self._get_project(project_id)
2023-03-02 18:33:24.989291 2023-03-02 18:33:24.977 36 ERROR keystone.server.flask.application   File "/var/lib/kolla/venv/lib/python3.9/site-packages/keystone/api/projects.py", line 107, in _get_project
2023-03-02 18:33:24.989301 2023-03-02 18:33:24.977 36 ERROR keystone.server.flask.application     project = PROVIDERS.resource_api.get_project(project_id)
2023-03-02 18:33:24.989310 2023-03-02 18:33:24.977 36 ERROR keystone.server.flask.application   File "/var/lib/kolla/venv/lib/python3.9/site-packages/keystone/common/manager.py", line 115, in wrapped
2023-03-02 18:33:24.989320 2023-03-02 18:33:24.977 36 ERROR keystone.server.flask.application     __ret_val = __f(*args, **kwargs)
2023-03-02 18:33:24.989329 2023-03-02 18:33:24.977 36 ERROR keystone.server.flask.application   File "/var/lib/kolla/venv/lib/python3.9/site-packages/decorator.py", line 232, in fun
2023-03-02 18:33:24.989339 2023-03-02 18:33:24.977 36 ERROR keystone.server.flask.application     return caller(func, *(extras + args), **kw)
2023-03-02 18:33:24.989366 2023-03-02 18:33:24.977 36 ERROR keystone.server.flask.application   File "/var/lib/kolla/venv/lib/python3.9/site-packages/dogpile/cache/region.py", line 1577, in get_or_create_for_user_func
2023-03-02 18:33:24.989377 2023-03-02 18:33:24.977 36 ERROR keystone.server.flask.application     return self.get_or_create(
2023-03-02 18:33:24.989387 2023-03-02 18:33:24.977 36 ERROR keystone.server.flask.application   File "/var/lib/kolla/venv/lib/python3.9/site-packages/dogpile/cache/region.py", line 1042, in get_or_create
2023-03-02 18:33:24.989397 2023-03-02 18:33:24.977 36 ERROR keystone.server.flask.application     with Lock(
2023-03-02 18:33:24.989407 2023-03-02 18:33:24.977 36 ERROR keystone.server.flask.application   File "/var/lib/kolla/venv/lib/python3.9/site-packages/dogpile/lock.py", line 185, in __enter__
2023-03-02 18:33:24.989416 2023-03-02 18:33:24.977 36 ERROR keystone.server.flask.application     return self._enter()
2023-03-02 18:33:24.989426 2023-03-02 18:33:24.977 36 ERROR keystone.server.flask.application   File "/var/lib/kolla/venv/lib/python3.9/site-packages/dogpile/lock.py", line 94, in _enter
2023-03-02 18:33:24.989436 2023-03-02 18:33:24.977 36 ERROR keystone.server.flask.application     generated = self._enter_create(value, createdtime)
2023-03-02 18:33:24.989445 2023-03-02 18:33:24.977 36 ERROR keystone.server.flask.application   File "/var/lib/kolla/venv/lib/python3.9/site-packages/dogpile/lock.py", line 178, in _enter_create
2023-03-02 18:33:24.989455 2023-03-02 18:33:24.977 36 ERROR keystone.server.flask.application     return self.creator()
2023-03-02 18:33:24.989485 2023-03-02 18:33:24.977 36 ERROR keystone.server.flask.application   File "/var/lib/kolla/venv/lib/python3.9/site-packages/dogpile/cache/region.py", line 995, in gen_value
2023-03-02 18:33:24.989503 2023-03-02 18:33:24.977 36 ERROR keystone.server.flask.application     created_value = creator(
2023-03-02 18:33:24.989513 2023-03-02 18:33:24.977 36 ERROR keystone.server.flask.application   File "/var/lib/kolla/venv/lib/python3.9/site-packages/keystone/resource/core.py", line 903, in get_project
2023-03-02 18:33:24.989522 2023-03-02 18:33:24.977 36 ERROR keystone.server.flask.application     return self.driver.get_project(project_id)
2023-03-02 18:33:24.989545 2023-03-02 18:33:24.977 36 ERROR keystone.server.flask.application   File "/var/lib/kolla/venv/lib/python3.9/site-packages/keystone/resource/backends/sql.py", line 49, in get_project
2023-03-02 18:33:24.989555 2023-03-02 18:33:24.977 36 ERROR keystone.server.flask.application     return self._get_project(session, project_id).to_dict()
2023-03-02 18:33:24.989564 2023-03-02 18:33:24.977 36 ERROR keystone.server.flask.application   File "/var/lib/kolla/venv/lib/python3.9/site-packages/keystone/resource/backends/sql.py", line 44, in _get_project
2023-03-02 18:33:24.989574 2023-03-02 18:33:24.977 36 ERROR keystone.server.flask.application     raise exception.ProjectNotFound(project_id=project_id)
2023-03-02 18:33:24.989628 2023-03-02 18:33:24.977 36 ERROR keystone.server.flask.application keystone.exception.ProjectNotFound: Could not find project: service.
2023-03-02 18:33:24.989639 2023-03-02 18:33:24.977 36 ERROR keystone.server.flask.application \x1b[00m
2023-03-02 18:33:34.772552 2023-03-02 18:33:34.765 38 ERROR keystone.server.flask.application [None req-2850e1a6-1ada-4fcd-b0cd-129b346b3d8c cf01766d1c3c4f0491c1efd319900764 - - all default -] Could not find role: admin.: keystone.exception.RoleNotFound: Could not find role: admin.
2023-03-02 18:33:34.772639 2023-03-02 18:33:34.765 38 ERROR keystone.server.flask.application Traceback (most recent call last):
2023-03-02 18:33:34.772652 2023-03-02 18:33:34.765 38 ERROR keystone.server.flask.application   File "/var/lib/kolla/venv/lib/python3.9/site-packages/flask/app.py", line 1820, in full_dispatch_request
2023-03-02 18:33:34.772662 2023-03-02 18:33:34.765 38 ERROR keystone.server.flask.application     rv = self.dispatch_request()
2023-03-02 18:33:34.772672 2023-03-02 18:33:34.765 38 ERROR keystone.server.flask.application   File "/var/lib/kolla/venv/lib/python3.9/site-packages/flask/app.py", line 1796, in dispatch_request
2023-03-02 18:33:34.772697 2023-03-02 18:33:34.765 38 ERROR keystone.server.flask.application     return self.ensure_sync(self.view_functions[rule.endpoint])(**view_args)
2023-03-02 18:33:34.772708 2023-03-02 18:33:34.765 38 ERROR keystone.server.flask.application   File "/var/lib/kolla/venv/lib/python3.9/site-packages/flask_restful/__init__.py", line 467, in wrapper
2023-03-02 18:33:34.772717 2023-03-02 18:33:34.765 38 ERROR keystone.server.flask.application     resp = resource(*args, **kwargs)
2023-03-02 18:33:34.772727 2023-03-02 18:33:34.765 38 ERROR keystone.server.flask.application   File "/var/lib/kolla/venv/lib/python3.9/site-packages/flask/views.py", line 107, in view
2023-03-02 18:33:34.772737 2023-03-02 18:33:34.765 38 ERROR keystone.server.flask.application     return current_app.ensure_sync(self.dispatch_request)(**kwargs)
2023-03-02 18:33:34.772746 2023-03-02 18:33:34.765 38 ERROR keystone.server.flask.application   File "/var/lib/kolla/venv/lib/python3.9/site-packages/flask_restful/__init__.py", line 582, in dispatch_request
2023-03-02 18:33:34.772756 2023-03-02 18:33:34.765 38 ERROR keystone.server.flask.application     resp = meth(*args, **kwargs)
2023-03-02 18:33:34.772766 2023-03-02 18:33:34.765 38 ERROR keystone.server.flask.application   File "/var/lib/kolla/venv/lib/python3.9/site-packages/keystone/api/roles.py", line 50, in get
2023-03-02 18:33:34.772776 2023-03-02 18:33:34.765 38 ERROR keystone.server.flask.application     return self._get_role(role_id)
2023-03-02 18:33:34.772785 2023-03-02 18:33:34.765 38 ERROR keystone.server.flask.application   File "/var/lib/kolla/venv/lib/python3.9/site-packages/keystone/api/roles.py", line 70, in _get_role
2023-03-02 18:33:34.772794 2023-03-02 18:33:34.765 38 ERROR keystone.server.flask.application     ENFORCER.enforce_call(action='identity:get_role')
2023-03-02 18:33:34.772804 2023-03-02 18:33:34.765 38 ERROR keystone.server.flask.application   File "/var/lib/kolla/venv/lib/python3.9/site-packages/keystone/common/rbac_enforcer/enforcer.py", line 402, in enforce_call
2023-03-02 18:33:34.772814 2023-03-02 18:33:34.765 38 ERROR keystone.server.flask.application     policy_dict.update(cls._extract_member_target_data(
2023-03-02 18:33:34.772823 2023-03-02 18:33:34.765 38 ERROR keystone.server.flask.application   File "/var/lib/kolla/venv/lib/python3.9/site-packages/keystone/common/rbac_enforcer/enforcer.py", line 234, in _extract_member_target_data
2023-03-02 18:33:34.772833 2023-03-02 18:33:34.765 38 ERROR keystone.server.flask.application     member_name: func(flask.request.view_args[key])
2023-03-02 18:33:34.772843 2023-03-02 18:33:34.765 38 ERROR keystone.server.flask.application   File "/var/lib/kolla/venv/lib/python3.9/site-packages/keystone/common/manager.py", line 115, in wrapped
2023-03-02 18:33:34.772852 2023-03-02 18:33:34.765 38 ERROR keystone.server.flask.application     __ret_val = __f(*args, **kwargs)
2023-03-02 18:33:34.772862 2023-03-02 18:33:34.765 38 ERROR keystone.server.flask.application   File "/var/lib/kolla/venv/lib/python3.9/site-packages/decorator.py", line 232, in fun
2023-03-02 18:33:34.772871 2023-03-02 18:33:34.765 38 ERROR keystone.server.flask.application     return caller(func, *(extras + args), **kw)
2023-03-02 18:33:34.772880 2023-03-02 18:33:34.765 38 ERROR keystone.server.flask.application   File "/var/lib/kolla/venv/lib/python3.9/site-packages/dogpile/cache/region.py", line 1577, in get_or_create_for_user_func
2023-03-02 18:33:34.772890 2023-03-02 18:33:34.765 38 ERROR keystone.server.flask.application     return self.get_or_create(
2023-03-02 18:33:34.772899 2023-03-02 18:33:34.765 38 ERROR keystone.server.flask.application   File "/var/lib/kolla/venv/lib/python3.9/site-packages/dogpile/cache/region.py", line 1042, in get_or_create
2023-03-02 18:33:34.772909 2023-03-02 18:33:34.765 38 ERROR keystone.server.flask.application     with Lock(
2023-03-02 18:33:34.772928 2023-03-02 18:33:34.765 38 ERROR keystone.server.flask.application   File "/var/lib/kolla/venv/lib/python3.9/site-packages/dogpile/lock.py", line 185, in __enter__
2023-03-02 18:33:34.772939 2023-03-02 18:33:34.765 38 ERROR keystone.server.flask.application     return self._enter()
2023-03-02 18:33:34.772948 2023-03-02 18:33:34.765 38 ERROR keystone.server.flask.application   File "/var/lib/kolla/venv/lib/python3.9/site-packages/dogpile/lock.py", line 94, in _enter
2023-03-02 18:33:34.772958 2023-03-02 18:33:34.765 38 ERROR keystone.server.flask.application     generated = self._enter_create(value, createdtime)
2023-03-02 18:33:34.772967 2023-03-02 18:33:34.765 38 ERROR keystone.server.flask.application   File "/var/lib/kolla/venv/lib/python3.9/site-packages/dogpile/lock.py", line 178, in _enter_create
2023-03-02 18:33:34.772977 2023-03-02 18:33:34.765 38 ERROR keystone.server.flask.application     return self.creator()
2023-03-02 18:33:34.772986 2023-03-02 18:33:34.765 38 ERROR keystone.server.flask.application   File "/var/lib/kolla/venv/lib/python3.9/site-packages/dogpile/cache/region.py", line 995, in gen_value
2023-03-02 18:33:34.772995 2023-03-02 18:33:34.765 38 ERROR keystone.server.flask.application     created_value = creator(
2023-03-02 18:33:34.773004 2023-03-02 18:33:34.765 38 ERROR keystone.server.flask.application   File "/var/lib/kolla/venv/lib/python3.9/site-packages/keystone/assignment/core.py", line 1276, in get_role
2023-03-02 18:33:34.773014 2023-03-02 18:33:34.765 38 ERROR keystone.server.flask.application     return self.driver.get_role(role_id)
2023-03-02 18:33:34.773023 2023-03-02 18:33:34.765 38 ERROR keystone.server.flask.application   File "/var/lib/kolla/venv/lib/python3.9/site-packages/keystone/assignment/role_backends/sql.py", line 70, in get_role
2023-03-02 18:33:34.773033 2023-03-02 18:33:34.765 38 ERROR keystone.server.flask.application     return self._get_role(session, role_id).to_dict()
2023-03-02 18:33:34.773042 2023-03-02 18:33:34.765 38 ERROR keystone.server.flask.application   File "/var/lib/kolla/venv/lib/python3.9/site-packages/keystone/assignment/role_backends/sql.py", line 65, in _get_role
2023-03-02 18:33:34.773052 2023-03-02 18:33:34.765 38 ERROR keystone.server.flask.application     raise exception.RoleNotFound(role_id=role_id)
2023-03-02 18:33:34.773061 2023-03-02 18:33:34.765 38 ERROR keystone.server.flask.application keystone.exception.RoleNotFound: Could not find role: admin.
2023-03-02 18:33:34.773070 2023-03-02 18:33:34.765 38 ERROR keystone.server.flask.application \x1b[00m
2023-03-02 18:33:36.205935 2023-03-02 18:33:36.200 38 ERROR keystone.server.flask.application [None req-06e7c19c-8839-4f90-bfc5-6ab2553f6715 cf01766d1c3c4f0491c1efd319900764 - - all default -] Could not find user: ironic-inspector.: keystone.exception.UserNotFound: Could not find user: ironic-inspector.
2023-03-02 18:33:36.205977 2023-03-02 18:33:36.200 38 ERROR keystone.server.flask.application Traceback (most recent call last):
2023-03-02 18:33:36.205988 2023-03-02 18:33:36.200 38 ERROR keystone.server.flask.application   File "/var/lib/kolla/venv/lib/python3.9/site-packages/flask/app.py", line 1820, in full_dispatch_request
2023-03-02 18:33:36.205998 2023-03-02 18:33:36.200 38 ERROR keystone.server.flask.application     rv = self.dispatch_request()
2023-03-02 18:33:36.206007 2023-03-02 18:33:36.200 38 ERROR keystone.server.flask.application   File "/var/lib/kolla/venv/lib/python3.9/site-packages/flask/app.py", line 1796, in dispatch_request
2023-03-02 18:33:36.206017 2023-03-02 18:33:36.200 38 ERROR keystone.server.flask.application     return self.ensure_sync(self.view_functions[rule.endpoint])(**view_args)
2023-03-02 18:33:36.206027 2023-03-02 18:33:36.200 38 ERROR keystone.server.flask.application   File "/var/lib/kolla/venv/lib/python3.9/site-packages/flask_restful/__init__.py", line 467, in wrapper
2023-03-02 18:33:36.206036 2023-03-02 18:33:36.200 38 ERROR keystone.server.flask.application     resp = resource(*args, **kwargs)
2023-03-02 18:33:36.206053 2023-03-02 18:33:36.200 38 ERROR keystone.server.flask.application   File "/var/lib/kolla/venv/lib/python3.9/site-packages/flask/views.py", line 107, in view
2023-03-02 18:33:36.206080 2023-03-02 18:33:36.200 38 ERROR keystone.server.flask.application     return current_app.ensure_sync(self.dispatch_request)(**kwargs)
2023-03-02 18:33:36.206091 2023-03-02 18:33:36.200 38 ERROR keystone.server.flask.application   File "/var/lib/kolla/venv/lib/python3.9/site-packages/flask_restful/__init__.py", line 582, in dispatch_request
2023-03-02 18:33:36.206101 2023-03-02 18:33:36.200 38 ERROR keystone.server.flask.application     resp = meth(*args, **kwargs)
2023-03-02 18:33:36.206110 2023-03-02 18:33:36.200 38 ERROR keystone.server.flask.application   File "/var/lib/kolla/venv/lib/python3.9/site-packages/keystone/api/users.py", line 182, in get
2023-03-02 18:33:36.206120 2023-03-02 18:33:36.200 38 ERROR keystone.server.flask.application     return self._get_user(user_id)
2023-03-02 18:33:36.206129 2023-03-02 18:33:36.200 38 ERROR keystone.server.flask.application   File "/var/lib/kolla/venv/lib/python3.9/site-packages/keystone/api/users.py", line 194, in _get_user
2023-03-02 18:33:36.206139 2023-03-02 18:33:36.200 38 ERROR keystone.server.flask.application     ref = PROVIDERS.identity_api.get_user(user_id)
2023-03-02 18:33:36.206149 2023-03-02 18:33:36.200 38 ERROR keystone.server.flask.application   File "/var/lib/kolla/venv/lib/python3.9/site-packages/keystone/common/manager.py", line 115, in wrapped
2023-03-02 18:33:36.206158 2023-03-02 18:33:36.200 38 ERROR keystone.server.flask.application     __ret_val = __f(*args, **kwargs)
2023-03-02 18:33:36.206167 2023-03-02 18:33:36.200 38 ERROR keystone.server.flask.application   File "/var/lib/kolla/venv/lib/python3.9/site-packages/keystone/identity/core.py", line 414, in wrapper
2023-03-02 18:33:36.206177 2023-03-02 18:33:36.200 38 ERROR keystone.server.flask.application     return f(self, *args, **kwargs)
2023-03-02 18:33:36.206186 2023-03-02 18:33:36.200 38 ERROR keystone.server.flask.application   File "/var/lib/kolla/venv/lib/python3.9/site-packages/keystone/identity/core.py", line 424, in wrapper
2023-03-02 18:33:36.206196 2023-03-02 18:33:36.200 38 ERROR keystone.server.flask.application     return f(self, *args, **kwargs)
2023-03-02 18:33:36.206205 2023-03-02 18:33:36.200 38 ERROR keystone.server.flask.application   File "/var/lib/kolla/venv/lib/python3.9/site-packages/decorator.py", line 232, in fun
2023-03-02 18:33:36.206215 2023-03-02 18:33:36.200 38 ERROR keystone.server.flask.application     return caller(func, *(extras + args), **kw)
2023-03-02 18:33:36.206224 2023-03-02 18:33:36.200 38 ERROR keystone.server.flask.application   File "/var/lib/kolla/venv/lib/python3.9/site-packages/dogpile/cache/region.py", line 1577, in get_or_create_for_user_func
2023-03-02 18:33:36.206234 2023-03-02 18:33:36.200 38 ERROR keystone.server.flask.application     return self.get_or_create(
2023-03-02 18:33:36.206243 2023-03-02 18:33:36.200 38 ERROR keystone.server.flask.application   File "/var/lib/kolla/venv/lib/python3.9/site-packages/dogpile/cache/region.py", line 1042, in get_or_create
2023-03-02 18:33:36.206253 2023-03-02 18:33:36.200 38 ERROR keystone.server.flask.application     with Lock(
2023-03-02 18:33:36.206263 2023-03-02 18:33:36.200 38 ERROR keystone.server.flask.application   File "/var/lib/kolla/venv/lib/python3.9/site-packages/dogpile/lock.py", line 185, in __enter__
2023-03-02 18:33:36.206272 2023-03-02 18:33:36.200 38 ERROR keystone.server.flask.application     return self._enter()
2023-03-02 18:33:36.206281 2023-03-02 18:33:36.200 38 ERROR keystone.server.flask.application   File "/var/lib/kolla/venv/lib/python3.9/site-packages/dogpile/lock.py", line 94, in _enter
2023-03-02 18:33:36.206291 2023-03-02 18:33:36.200 38 ERROR keystone.server.flask.application     generated = self._enter_create(value, createdtime)
2023-03-02 18:33:36.206300 2023-03-02 18:33:36.200 38 ERROR keystone.server.flask.application   File "/var/lib/kolla/venv/lib/python3.9/site-packages/dogpile/lock.py", line 178, in _enter_create
2023-03-02 18:33:36.206319 2023-03-02 18:33:36.200 38 ERROR keystone.server.flask.application     return self.creator()
2023-03-02 18:33:36.206329 2023-03-02 18:33:36.200 38 ERROR keystone.server.flask.application   File "/var/lib/kolla/venv/lib/python3.9/site-packages/dogpile/cache/region.py", line 995, in gen_value
2023-03-02 18:33:36.206339 2023-03-02 18:33:36.200 38 ERROR keystone.server.flask.application     created_value = creator(
2023-03-02 18:33:36.206348 2023-03-02 18:33:36.200 38 ERROR keystone.server.flask.application   File "/var/lib/kolla/venv/lib/python3.9/site-packages/keystone/identity/core.py", line 1011, in get_user
2023-03-02 18:33:36.206358 2023-03-02 18:33:36.200 38 ERROR keystone.server.flask.application     ref = driver.get_user(entity_id)
2023-03-02 18:33:36.206367 2023-03-02 18:33:36.200 38 ERROR keystone.server.flask.application   File "/var/lib/kolla/venv/lib/python3.9/site-packages/keystone/identity/backends/sql.py", line 200, in get_user
2023-03-02 18:33:36.206377 2023-03-02 18:33:36.200 38 ERROR keystone.server.flask.application     self._get_user(session, user_id).to_dict())
2023-03-02 18:33:36.206386 2023-03-02 18:33:36.200 38 ERROR keystone.server.flask.application   File "/var/lib/kolla/venv/lib/python3.9/site-packages/keystone/identity/backends/sql.py", line 194, in _get_user
2023-03-02 18:33:36.206396 2023-03-02 18:33:36.200 38 ERROR keystone.server.flask.application     raise exception.UserNotFound(user_id=user_id)
2023-03-02 18:33:36.206405 2023-03-02 18:33:36.200 38 ERROR keystone.server.flask.application keystone.exception.UserNotFound: Could not find user: ironic-inspector.
2023-03-02 18:33:36.206414 2023-03-02 18:33:36.200 38 ERROR keystone.server.flask.application \x1b[00m
2023-03-02 18:33:37.354155 2023-03-02 18:33:37.349 37 ERROR keystone.server.flask.application [None req-8fbf56a6-135b-4c2f-a98e-fb396d0fa2c6 cf01766d1c3c4f0491c1efd319900764 - - all default -] Could not find project: service.: keystone.exception.ProjectNotFound: Could not find project: service.
2023-03-02 18:33:37.354200 2023-03-02 18:33:37.349 37 ERROR keystone.server.flask.application Traceback (most recent call last):
2023-03-02 18:33:37.354211 2023-03-02 18:33:37.349 37 ERROR keystone.server.flask.application   File "/var/lib/kolla/venv/lib/python3.9/site-packages/flask/app.py", line 1820, in full_dispatch_request
2023-03-02 18:33:37.354222 2023-03-02 18:33:37.349 37 ERROR keystone.server.flask.application     rv = self.dispatch_request()
2023-03-02 18:33:37.354231 2023-03-02 18:33:37.349 37 ERROR keystone.server.flask.application   File "/var/lib/kolla/venv/lib/python3.9/site-packages/flask/app.py", line 1796, in dispatch_request
2023-03-02 18:33:37.354241 2023-03-02 18:33:37.349 37 ERROR keystone.server.flask.application     return self.ensure_sync(self.view_functions[rule.endpoint])(**view_args)
2023-03-02 18:33:37.354250 2023-03-02 18:33:37.349 37 ERROR keystone.server.flask.application   File "/var/lib/kolla/venv/lib/python3.9/site-packages/flask_restful/__init__.py", line 467, in wrapper
2023-03-02 18:33:37.354259 2023-03-02 18:33:37.349 37 ERROR keystone.server.flask.application     resp = resource(*args, **kwargs)
2023-03-02 18:33:37.354269 2023-03-02 18:33:37.349 37 ERROR keystone.server.flask.application   File "/var/lib/kolla/venv/lib/python3.9/site-packages/flask/views.py", line 107, in view
2023-03-02 18:33:37.354278 2023-03-02 18:33:37.349 37 ERROR keystone.server.flask.application     return current_app.ensure_sync(self.dispatch_request)(**kwargs)
2023-03-02 18:33:37.354287 2023-03-02 18:33:37.349 37 ERROR keystone.server.flask.application   File "/var/lib/kolla/venv/lib/python3.9/site-packages/flask_restful/__init__.py", line 582, in dispatch_request
2023-03-02 18:33:37.354297 2023-03-02 18:33:37.349 37 ERROR keystone.server.flask.application     resp = meth(*args, **kwargs)
2023-03-02 18:33:37.354306 2023-03-02 18:33:37.349 37 ERROR keystone.server.flask.application   File "/var/lib/kolla/venv/lib/python3.9/site-packages/keystone/api/projects.py", line 151, in get
2023-03-02 18:33:37.354334 2023-03-02 18:33:37.349 37 ERROR keystone.server.flask.application     return self._get_project(project_id)
2023-03-02 18:33:37.354345 2023-03-02 18:33:37.349 37 ERROR keystone.server.flask.application   File "/var/lib/kolla/venv/lib/python3.9/site-packages/keystone/api/projects.py", line 107, in _get_project
2023-03-02 18:33:37.354355 2023-03-02 18:33:37.349 37 ERROR keystone.server.flask.application     project = PROVIDERS.resource_api.get_project(project_id)
2023-03-02 18:33:37.354364 2023-03-02 18:33:37.349 37 ERROR keystone.server.flask.application   File "/var/lib/kolla/venv/lib/python3.9/site-packages/keystone/common/manager.py", line 115, in wrapped
2023-03-02 18:33:37.354374 2023-03-02 18:33:37.349 37 ERROR keystone.server.flask.application     __ret_val = __f(*args, **kwargs)
2023-03-02 18:33:37.354383 2023-03-02 18:33:37.349 37 ERROR keystone.server.flask.application   File "/var/lib/kolla/venv/lib/python3.9/site-packages/decorator.py", line 232, in fun
2023-03-02 18:33:37.354392 2023-03-02 18:33:37.349 37 ERROR keystone.server.flask.application     return caller(func, *(extras + args), **kw)
2023-03-02 18:33:37.354401 2023-03-02 18:33:37.349 37 ERROR keystone.server.flask.application   File "/var/lib/kolla/venv/lib/python3.9/site-packages/dogpile/cache/region.py", line 1577, in get_or_create_for_user_func
2023-03-02 18:33:37.354411 2023-03-02 18:33:37.349 37 ERROR keystone.server.flask.application     return self.get_or_create(
2023-03-02 18:33:37.354420 2023-03-02 18:33:37.349 37 ERROR keystone.server.flask.application   File "/var/lib/kolla/venv/lib/python3.9/site-packages/dogpile/cache/region.py", line 1042, in get_or_create
2023-03-02 18:33:37.354430 2023-03-02 18:33:37.349 37 ERROR keystone.server.flask.application     with Lock(
2023-03-02 18:33:37.354439 2023-03-02 18:33:37.349 37 ERROR keystone.server.flask.application   File "/var/lib/kolla/venv/lib/python3.9/site-packages/dogpile/lock.py", line 185, in __enter__
2023-03-02 18:33:37.354454 2023-03-02 18:33:37.349 37 ERROR keystone.server.flask.application     return self._enter()
2023-03-02 18:33:37.354488 2023-03-02 18:33:37.349 37 ERROR keystone.server.flask.application   File "/var/lib/kolla/venv/lib/python3.9/site-packages/dogpile/lock.py", line 94, in _enter
2023-03-02 18:33:37.354501 2023-03-02 18:33:37.349 37 ERROR keystone.server.flask.application     generated = self._enter_create(value, createdtime)
2023-03-02 18:33:37.354510 2023-03-02 18:33:37.349 37 ERROR keystone.server.flask.application   File "/var/lib/kolla/venv/lib/python3.9/site-packages/dogpile/lock.py", line 178, in _enter_create
2023-03-02 18:33:37.354519 2023-03-02 18:33:37.349 37 ERROR keystone.server.flask.application     return self.creator()
2023-03-02 18:33:37.354529 2023-03-02 18:33:37.349 37 ERROR keystone.server.flask.application   File "/var/lib/kolla/venv/lib/python3.9/site-packages/dogpile/cache/region.py", line 995, in gen_value
2023-03-02 18:33:37.354538 2023-03-02 18:33:37.349 37 ERROR keystone.server.flask.application     created_value = creator(
2023-03-02 18:33:37.354547 2023-03-02 18:33:37.349 37 ERROR keystone.server.flask.application   File "/var/lib/kolla/venv/lib/python3.9/site-packages/keystone/resource/core.py", line 903, in get_project
2023-03-02 18:33:37.354556 2023-03-02 18:33:37.349 37 ERROR keystone.server.flask.application     return self.driver.get_project(project_id)
2023-03-02 18:33:37.354565 2023-03-02 18:33:37.349 37 ERROR keystone.server.flask.application   File "/var/lib/kolla/venv/lib/python3.9/site-packages/keystone/resource/backends/sql.py", line 49, in get_project
2023-03-02 18:33:37.354575 2023-03-02 18:33:37.349 37 ERROR keystone.server.flask.application     return self._get_project(session, project_id).to_dict()
2023-03-02 18:33:37.354610 2023-03-02 18:33:37.349 37 ERROR keystone.server.flask.application   File "/var/lib/kolla/venv/lib/python3.9/site-packages/keystone/resource/backends/sql.py", line 44, in _get_project
2023-03-02 18:33:37.354620 2023-03-02 18:33:37.349 37 ERROR keystone.server.flask.application     raise exception.ProjectNotFound(project_id=project_id)
2023-03-02 18:33:37.354643 2023-03-02 18:33:37.349 37 ERROR keystone.server.flask.application keystone.exception.ProjectNotFound: Could not find project: service.
2023-03-02 18:33:37.354654 2023-03-02 18:33:37.349 37 ERROR keystone.server.flask.application \x1b[00m
2023-03-02 18:36:31.358885 2023-03-02 18:36:31.355 37 ERROR keystone.server.flask.application [None req-cb0ad59a-bebc-4d12-b3c6-d73f215d4690 cf01766d1c3c4f0491c1efd319900764 - - all default -] Could not find project: service.: keystone.exception.ProjectNotFound: Could not find project: service.
2023-03-02 18:36:31.358948 2023-03-02 18:36:31.355 37 ERROR keystone.server.flask.application Traceback (most recent call last):
2023-03-02 18:36:31.358961 2023-03-02 18:36:31.355 37 ERROR keystone.server.flask.application   File "/var/lib/kolla/venv/lib/python3.9/site-packages/flask/app.py", line 1820, in full_dispatch_request
2023-03-02 18:36:31.358972 2023-03-02 18:36:31.355 37 ERROR keystone.server.flask.application     rv = self.dispatch_request()
2023-03-02 18:36:31.358982 2023-03-02 18:36:31.355 37 ERROR keystone.server.flask.application   File "/var/lib/kolla/venv/lib/python3.9/site-packages/flask/app.py", line 1796, in dispatch_request
2023-03-02 18:36:31.358993 2023-03-02 18:36:31.355 37 ERROR keystone.server.flask.application     return self.ensure_sync(self.view_functions[rule.endpoint])(**view_args)
2023-03-02 18:36:31.359002 2023-03-02 18:36:31.355 37 ERROR keystone.server.flask.application   File "/var/lib/kolla/venv/lib/python3.9/site-packages/flask_restful/__init__.py", line 467, in wrapper
2023-03-02 18:36:31.359012 2023-03-02 18:36:31.355 37 ERROR keystone.server.flask.application     resp = resource(*args, **kwargs)
2023-03-02 18:36:31.359022 2023-03-02 18:36:31.355 37 ERROR keystone.server.flask.application   File "/var/lib/kolla/venv/lib/python3.9/site-packages/flask/views.py", line 107, in view
2023-03-02 18:36:31.359032 2023-03-02 18:36:31.355 37 ERROR keystone.server.flask.application     return current_app.ensure_sync(self.dispatch_request)(**kwargs)
2023-03-02 18:36:31.359042 2023-03-02 18:36:31.355 37 ERROR keystone.server.flask.application   File "/var/lib/kolla/venv/lib/python3.9/site-packages/flask_restful/__init__.py", line 582, in dispatch_request
2023-03-02 18:36:31.359052 2023-03-02 18:36:31.355 37 ERROR keystone.server.flask.application     resp = meth(*args, **kwargs)
2023-03-02 18:36:31.359062 2023-03-02 18:36:31.355 37 ERROR keystone.server.flask.application   File "/var/lib/kolla/venv/lib/python3.9/site-packages/keystone/api/projects.py", line 151, in get
2023-03-02 18:36:31.359072 2023-03-02 18:36:31.355 37 ERROR keystone.server.flask.application     return self._get_project(project_id)
2023-03-02 18:36:31.359081 2023-03-02 18:36:31.355 37 ERROR keystone.server.flask.application   File "/var/lib/kolla/venv/lib/python3.9/site-packages/keystone/api/projects.py", line 107, in _get_project
2023-03-02 18:36:31.359091 2023-03-02 18:36:31.355 37 ERROR keystone.server.flask.application     project = PROVIDERS.resource_api.get_project(project_id)
2023-03-02 18:36:31.359101 2023-03-02 18:36:31.355 37 ERROR keystone.server.flask.application   File "/var/lib/kolla/venv/lib/python3.9/site-packages/keystone/common/manager.py", line 115, in wrapped
2023-03-02 18:36:31.359111 2023-03-02 18:36:31.355 37 ERROR keystone.server.flask.application     __ret_val = __f(*args, **kwargs)
2023-03-02 18:36:31.359120 2023-03-02 18:36:31.355 37 ERROR keystone.server.flask.application   File "/var/lib/kolla/venv/lib/python3.9/site-packages/decorator.py", line 232, in fun
2023-03-02 18:36:31.359130 2023-03-02 18:36:31.355 37 ERROR keystone.server.flask.application     return caller(func, *(extras + args), **kw)
2023-03-02 18:36:31.359140 2023-03-02 18:36:31.355 37 ERROR keystone.server.flask.application   File "/var/lib/kolla/venv/lib/python3.9/site-packages/dogpile/cache/region.py", line 1577, in get_or_create_for_user_func
2023-03-02 18:36:31.359150 2023-03-02 18:36:31.355 37 ERROR keystone.server.flask.application     return self.get_or_create(
2023-03-02 18:36:31.359197 2023-03-02 18:36:31.355 37 ERROR keystone.server.flask.application   File "/var/lib/kolla/venv/lib/python3.9/site-packages/dogpile/cache/region.py", line 1042, in get_or_create
2023-03-02 18:36:31.359209 2023-03-02 18:36:31.355 37 ERROR keystone.server.flask.application     with Lock(
2023-03-02 18:36:31.359219 2023-03-02 18:36:31.355 37 ERROR keystone.server.flask.application   File "/var/lib/kolla/venv/lib/python3.9/site-packages/dogpile/lock.py", line 185, in __enter__
2023-03-02 18:36:31.359228 2023-03-02 18:36:31.355 37 ERROR keystone.server.flask.application     return self._enter()
2023-03-02 18:36:31.359238 2023-03-02 18:36:31.355 37 ERROR keystone.server.flask.application   File "/var/lib/kolla/venv/lib/python3.9/site-packages/dogpile/lock.py", line 94, in _enter
2023-03-02 18:36:31.359248 2023-03-02 18:36:31.355 37 ERROR keystone.server.flask.application     generated = self._enter_create(value, createdtime)
2023-03-02 18:36:31.359257 2023-03-02 18:36:31.355 37 ERROR keystone.server.flask.application   File "/var/lib/kolla/venv/lib/python3.9/site-packages/dogpile/lock.py", line 178, in _enter_create
2023-03-02 18:36:31.359267 2023-03-02 18:36:31.355 37 ERROR keystone.server.flask.application     return self.creator()
2023-03-02 18:36:31.359277 2023-03-02 18:36:31.355 37 ERROR keystone.server.flask.application   File "/var/lib/kolla/venv/lib/python3.9/site-packages/dogpile/cache/region.py", line 995, in gen_value
2023-03-02 18:36:31.359287 2023-03-02 18:36:31.355 37 ERROR keystone.server.flask.application     created_value = creator(
2023-03-02 18:36:31.359296 2023-03-02 18:36:31.355 37 ERROR keystone.server.flask.application   File "/var/lib/kolla/venv/lib/python3.9/site-packages/keystone/resource/core.py", line 903, in get_project
2023-03-02 18:36:31.359306 2023-03-02 18:36:31.355 37 ERROR keystone.server.flask.application     return self.driver.get_project(project_id)
2023-03-02 18:36:31.359315 2023-03-02 18:36:31.355 37 ERROR keystone.server.flask.application   File "/var/lib/kolla/venv/lib/python3.9/site-packages/keystone/resource/backends/sql.py", line 49, in get_project
2023-03-02 18:36:31.359325 2023-03-02 18:36:31.355 37 ERROR keystone.server.flask.application     return self._get_project(session, project_id).to_dict()
2023-03-02 18:36:31.359335 2023-03-02 18:36:31.355 37 ERROR keystone.server.flask.application   File "/var/lib/kolla/venv/lib/python3.9/site-packages/keystone/resource/backends/sql.py", line 44, in _get_project
2023-03-02 18:36:31.359345 2023-03-02 18:36:31.355 37 ERROR keystone.server.flask.application     raise exception.ProjectNotFound(project_id=project_id)
2023-03-02 18:36:31.359354 2023-03-02 18:36:31.355 37 ERROR keystone.server.flask.application keystone.exception.ProjectNotFound: Could not find project: service.
2023-03-02 18:36:31.359363 2023-03-02 18:36:31.355 37 ERROR keystone.server.flask.application \x1b[00m
2023-03-02 18:36:47.365995 2023-03-02 18:36:47.361 38 ERROR keystone.server.flask.application [None req-710e0ce7-4358-44bf-b208-6ab7d8db8c11 cf01766d1c3c4f0491c1efd319900764 - - all default -] Could not find role: admin.: keystone.exception.RoleNotFound: Could not find role: admin.
2023-03-02 18:36:47.368150 2023-03-02 18:36:47.361 38 ERROR keystone.server.flask.application Traceback (most recent call last):
2023-03-02 18:36:47.368171 2023-03-02 18:36:47.361 38 ERROR keystone.server.flask.application   File "/var/lib/kolla/venv/lib/python3.9/site-packages/flask/app.py", line 1820, in full_dispatch_request
2023-03-02 18:36:47.368182 2023-03-02 18:36:47.361 38 ERROR keystone.server.flask.application     rv = self.dispatch_request()
2023-03-02 18:36:47.368191 2023-03-02 18:36:47.361 38 ERROR keystone.server.flask.application   File "/var/lib/kolla/venv/lib/python3.9/site-packages/flask/app.py", line 1796, in dispatch_request
2023-03-02 18:36:47.368202 2023-03-02 18:36:47.361 38 ERROR keystone.server.flask.application     return self.ensure_sync(self.view_functions[rule.endpoint])(**view_args)
2023-03-02 18:36:47.368211 2023-03-02 18:36:47.361 38 ERROR keystone.server.flask.application   File "/var/lib/kolla/venv/lib/python3.9/site-packages/flask_restful/__init__.py", line 467, in wrapper
2023-03-02 18:36:47.368240 2023-03-02 18:36:47.361 38 ERROR keystone.server.flask.application     resp = resource(*args, **kwargs)
2023-03-02 18:36:47.368260 2023-03-02 18:36:47.361 38 ERROR keystone.server.flask.application   File "/var/lib/kolla/venv/lib/python3.9/site-packages/flask/views.py", line 107, in view
2023-03-02 18:36:47.368273 2023-03-02 18:36:47.361 38 ERROR keystone.server.flask.application     return current_app.ensure_sync(self.dispatch_request)(**kwargs)
2023-03-02 18:36:47.368283 2023-03-02 18:36:47.361 38 ERROR keystone.server.flask.application   File "/var/lib/kolla/venv/lib/python3.9/site-packages/flask_restful/__init__.py", line 582, in dispatch_request
2023-03-02 18:36:47.368292 2023-03-02 18:36:47.361 38 ERROR keystone.server.flask.application     resp = meth(*args, **kwargs)
2023-03-02 18:36:47.368302 2023-03-02 18:36:47.361 38 ERROR keystone.server.flask.application   File "/var/lib/kolla/venv/lib/python3.9/site-packages/keystone/api/roles.py", line 50, in get
2023-03-02 18:36:47.368315 2023-03-02 18:36:47.361 38 ERROR keystone.server.flask.application     return self._get_role(role_id)
2023-03-02 18:36:47.368325 2023-03-02 18:36:47.361 38 ERROR keystone.server.flask.application   File "/var/lib/kolla/venv/lib/python3.9/site-packages/keystone/api/roles.py", line 70, in _get_role
2023-03-02 18:36:47.368334 2023-03-02 18:36:47.361 38 ERROR keystone.server.flask.application     ENFORCER.enforce_call(action='identity:get_role')
2023-03-02 18:36:47.368344 2023-03-02 18:36:47.361 38 ERROR keystone.server.flask.application   File "/var/lib/kolla/venv/lib/python3.9/site-packages/keystone/common/rbac_enforcer/enforcer.py", line 402, in enforce_call
2023-03-02 18:36:47.368354 2023-03-02 18:36:47.361 38 ERROR keystone.server.flask.application     policy_dict.update(cls._extract_member_target_data(
2023-03-02 18:36:47.368364 2023-03-02 18:36:47.361 38 ERROR keystone.server.flask.application   File "/var/lib/kolla/venv/lib/python3.9/site-packages/keystone/common/rbac_enforcer/enforcer.py", line 234, in _extract_member_target_data
2023-03-02 18:36:47.368374 2023-03-02 18:36:47.361 38 ERROR keystone.server.flask.application     member_name: func(flask.request.view_args[key])
2023-03-02 18:36:47.368384 2023-03-02 18:36:47.361 38 ERROR keystone.server.flask.application   File "/var/lib/kolla/venv/lib/python3.9/site-packages/keystone/common/manager.py", line 115, in wrapped
2023-03-02 18:36:47.368393 2023-03-02 18:36:47.361 38 ERROR keystone.server.flask.application     __ret_val = __f(*args, **kwargs)
2023-03-02 18:36:47.368403 2023-03-02 18:36:47.361 38 ERROR keystone.server.flask.application   File "/var/lib/kolla/venv/lib/python3.9/site-packages/decorator.py", line 232, in fun
2023-03-02 18:36:47.368412 2023-03-02 18:36:47.361 38 ERROR keystone.server.flask.application     return caller(func, *(extras + args), **kw)
2023-03-02 18:36:47.368422 2023-03-02 18:36:47.361 38 ERROR keystone.server.flask.application   File "/var/lib/kolla/venv/lib/python3.9/site-packages/dogpile/cache/region.py", line 1577, in get_or_create_for_user_func
2023-03-02 18:36:47.368432 2023-03-02 18:36:47.361 38 ERROR keystone.server.flask.application     return self.get_or_create(
2023-03-02 18:36:47.368460 2023-03-02 18:36:47.361 38 ERROR keystone.server.flask.application   File "/var/lib/kolla/venv/lib/python3.9/site-packages/dogpile/cache/region.py", line 1042, in get_or_create
2023-03-02 18:36:47.368474 2023-03-02 18:36:47.361 38 ERROR keystone.server.flask.application     with Lock(
2023-03-02 18:36:47.368483 2023-03-02 18:36:47.361 38 ERROR keystone.server.flask.application   File "/var/lib/kolla/venv/lib/python3.9/site-packages/dogpile/lock.py", line 185, in __enter__
2023-03-02 18:36:47.368493 2023-03-02 18:36:47.361 38 ERROR keystone.server.flask.application     return self._enter()
2023-03-02 18:36:47.368502 2023-03-02 18:36:47.361 38 ERROR keystone.server.flask.application   File "/var/lib/kolla/venv/lib/python3.9/site-packages/dogpile/lock.py", line 94, in _enter
2023-03-02 18:36:47.368535 2023-03-02 18:36:47.361 38 ERROR keystone.server.flask.application     generated = self._enter_create(value, createdtime)
2023-03-02 18:36:47.368547 2023-03-02 18:36:47.361 38 ERROR keystone.server.flask.application   File "/var/lib/kolla/venv/lib/python3.9/site-packages/dogpile/lock.py", line 178, in _enter_create
2023-03-02 18:36:47.368557 2023-03-02 18:36:47.361 38 ERROR keystone.server.flask.application     return self.creator()
2023-03-02 18:36:47.368566 2023-03-02 18:36:47.361 38 ERROR keystone.server.flask.application   File "/var/lib/kolla/venv/lib/python3.9/site-packages/dogpile/cache/region.py", line 995, in gen_value
2023-03-02 18:36:47.368599 2023-03-02 18:36:47.361 38 ERROR keystone.server.flask.application     created_value = creator(
2023-03-02 18:36:47.368614 2023-03-02 18:36:47.361 38 ERROR keystone.server.flask.application   File "/var/lib/kolla/venv/lib/python3.9/site-packages/keystone/assignment/core.py", line 1276, in get_role
2023-03-02 18:36:47.368625 2023-03-02 18:36:47.361 38 ERROR keystone.server.flask.application     return self.driver.get_role(role_id)
2023-03-02 18:36:47.368634 2023-03-02 18:36:47.361 38 ERROR keystone.server.flask.application   File "/var/lib/kolla/venv/lib/python3.9/site-packages/keystone/assignment/role_backends/sql.py", line 70, in get_role
2023-03-02 18:36:47.368643 2023-03-02 18:36:47.361 38 ERROR keystone.server.flask.application     return self._get_role(session, role_id).to_dict()
2023-03-02 18:36:47.368653 2023-03-02 18:36:47.361 38 ERROR keystone.server.flask.application   File "/var/lib/kolla/venv/lib/python3.9/site-packages/keystone/assignment/role_backends/sql.py", line 65, in _get_role
2023-03-02 18:36:47.368662 2023-03-02 18:36:47.361 38 ERROR keystone.server.flask.application     raise exception.RoleNotFound(role_id=role_id)
2023-03-02 18:36:47.368672 2023-03-02 18:36:47.361 38 ERROR keystone.server.flask.application keystone.exception.RoleNotFound: Could not find role: admin.
2023-03-02 18:36:47.368681 2023-03-02 18:36:47.361 38 ERROR keystone.server.flask.application \x1b[00m
2023-03-02 18:36:48.789194 2023-03-02 18:36:48.785 38 ERROR keystone.server.flask.application [None req-1f0112ee-c228-41f8-93e2-e3b42f1a448c cf01766d1c3c4f0491c1efd319900764 - - all default -] Could not find user: neutron.: keystone.exception.UserNotFound: Could not find user: neutron.
2023-03-02 18:36:48.789240 2023-03-02 18:36:48.785 38 ERROR keystone.server.flask.application Traceback (most recent call last):
2023-03-02 18:36:48.789253 2023-03-02 18:36:48.785 38 ERROR keystone.server.flask.application   File "/var/lib/kolla/venv/lib/python3.9/site-packages/flask/app.py", line 1820, in full_dispatch_request
2023-03-02 18:36:48.789264 2023-03-02 18:36:48.785 38 ERROR keystone.server.flask.application     rv = self.dispatch_request()
2023-03-02 18:36:48.789274 2023-03-02 18:36:48.785 38 ERROR keystone.server.flask.application   File "/var/lib/kolla/venv/lib/python3.9/site-packages/flask/app.py", line 1796, in dispatch_request
2023-03-02 18:36:48.789285 2023-03-02 18:36:48.785 38 ERROR keystone.server.flask.application     return self.ensure_sync(self.view_functions[rule.endpoint])(**view_args)
2023-03-02 18:36:48.789295 2023-03-02 18:36:48.785 38 ERROR keystone.server.flask.application   File "/var/lib/kolla/venv/lib/python3.9/site-packages/flask_restful/__init__.py", line 467, in wrapper
2023-03-02 18:36:48.789306 2023-03-02 18:36:48.785 38 ERROR keystone.server.flask.application     resp = resource(*args, **kwargs)
2023-03-02 18:36:48.789316 2023-03-02 18:36:48.785 38 ERROR keystone.server.flask.application   File "/var/lib/kolla/venv/lib/python3.9/site-packages/flask/views.py", line 107, in view
2023-03-02 18:36:48.789327 2023-03-02 18:36:48.785 38 ERROR keystone.server.flask.application     return current_app.ensure_sync(self.dispatch_request)(**kwargs)
2023-03-02 18:36:48.789338 2023-03-02 18:36:48.785 38 ERROR keystone.server.flask.application   File "/var/lib/kolla/venv/lib/python3.9/site-packages/flask_restful/__init__.py", line 582, in dispatch_request
2023-03-02 18:36:48.789367 2023-03-02 18:36:48.785 38 ERROR keystone.server.flask.application     resp = meth(*args, **kwargs)
2023-03-02 18:36:48.789380 2023-03-02 18:36:48.785 38 ERROR keystone.server.flask.application   File "/var/lib/kolla/venv/lib/python3.9/site-packages/keystone/api/users.py", line 182, in get
2023-03-02 18:36:48.789391 2023-03-02 18:36:48.785 38 ERROR keystone.server.flask.application     return self._get_user(user_id)
2023-03-02 18:36:48.789401 2023-03-02 18:36:48.785 38 ERROR keystone.server.flask.application   File "/var/lib/kolla/venv/lib/python3.9/site-packages/keystone/api/users.py", line 194, in _get_user
2023-03-02 18:36:48.789412 2023-03-02 18:36:48.785 38 ERROR keystone.server.flask.application     ref = PROVIDERS.identity_api.get_user(user_id)
2023-03-02 18:36:48.789422 2023-03-02 18:36:48.785 38 ERROR keystone.server.flask.application   File "/var/lib/kolla/venv/lib/python3.9/site-packages/keystone/common/manager.py", line 115, in wrapped
2023-03-02 18:36:48.789433 2023-03-02 18:36:48.785 38 ERROR keystone.server.flask.application     __ret_val = __f(*args, **kwargs)
2023-03-02 18:36:48.789465 2023-03-02 18:36:48.785 38 ERROR keystone.server.flask.application   File "/var/lib/kolla/venv/lib/python3.9/site-packages/keystone/identity/core.py", line 414, in wrapper
2023-03-02 18:36:48.789479 2023-03-02 18:36:48.785 38 ERROR keystone.server.flask.application     return f(self, *args, **kwargs)
2023-03-02 18:36:48.789489 2023-03-02 18:36:48.785 38 ERROR keystone.server.flask.application   File "/var/lib/kolla/venv/lib/python3.9/site-packages/keystone/identity/core.py", line 424, in wrapper
2023-03-02 18:36:48.789500 2023-03-02 18:36:48.785 38 ERROR keystone.server.flask.application     return f(self, *args, **kwargs)
2023-03-02 18:36:48.789510 2023-03-02 18:36:48.785 38 ERROR keystone.server.flask.application   File "/var/lib/kolla/venv/lib/python3.9/site-packages/decorator.py", line 232, in fun
2023-03-02 18:36:48.789520 2023-03-02 18:36:48.785 38 ERROR keystone.server.flask.application     return caller(func, *(extras + args), **kw)
2023-03-02 18:36:48.789531 2023-03-02 18:36:48.785 38 ERROR keystone.server.flask.application   File "/var/lib/kolla/venv/lib/python3.9/site-packages/dogpile/cache/region.py", line 1577, in get_or_create_for_user_func
2023-03-02 18:36:48.789541 2023-03-02 18:36:48.785 38 ERROR keystone.server.flask.application     return self.get_or_create(
2023-03-02 18:36:48.789551 2023-03-02 18:36:48.785 38 ERROR keystone.server.flask.application   File "/var/lib/kolla/venv/lib/python3.9/site-packages/dogpile/cache/region.py", line 1042, in get_or_create
2023-03-02 18:36:48.789562 2023-03-02 18:36:48.785 38 ERROR keystone.server.flask.application     with Lock(
2023-03-02 18:36:48.789572 2023-03-02 18:36:48.785 38 ERROR keystone.server.flask.application   File "/var/lib/kolla/venv/lib/python3.9/site-packages/dogpile/lock.py", line 185, in __enter__
2023-03-02 18:36:48.789612 2023-03-02 18:36:48.785 38 ERROR keystone.server.flask.application     return self._enter()
2023-03-02 18:36:48.789626 2023-03-02 18:36:48.785 38 ERROR keystone.server.flask.application   File "/var/lib/kolla/venv/lib/python3.9/site-packages/dogpile/lock.py", line 94, in _enter
2023-03-02 18:36:48.789637 2023-03-02 18:36:48.785 38 ERROR keystone.server.flask.application     generated = self._enter_create(value, createdtime)
2023-03-02 18:36:48.789648 2023-03-02 18:36:48.785 38 ERROR keystone.server.flask.application   File "/var/lib/kolla/venv/lib/python3.9/site-packages/dogpile/lock.py", line 178, in _enter_create
2023-03-02 18:36:48.789659 2023-03-02 18:36:48.785 38 ERROR keystone.server.flask.application     return self.creator()
2023-03-02 18:36:48.789669 2023-03-02 18:36:48.785 38 ERROR keystone.server.flask.application   File "/var/lib/kolla/venv/lib/python3.9/site-packages/dogpile/cache/region.py", line 995, in gen_value
2023-03-02 18:36:48.789679 2023-03-02 18:36:48.785 38 ERROR keystone.server.flask.application     created_value = creator(
2023-03-02 18:36:48.789705 2023-03-02 18:36:48.785 38 ERROR keystone.server.flask.application   File "/var/lib/kolla/venv/lib/python3.9/site-packages/keystone/identity/core.py", line 1011, in get_user
2023-03-02 18:36:48.789721 2023-03-02 18:36:48.785 38 ERROR keystone.server.flask.application     ref = driver.get_user(entity_id)
2023-03-02 18:36:48.789732 2023-03-02 18:36:48.785 38 ERROR keystone.server.flask.application   File "/var/lib/kolla/venv/lib/python3.9/site-packages/keystone/identity/backends/sql.py", line 200, in get_user
2023-03-02 18:36:48.789742 2023-03-02 18:36:48.785 38 ERROR keystone.server.flask.application     self._get_user(session, user_id).to_dict())
2023-03-02 18:36:48.789753 2023-03-02 18:36:48.785 38 ERROR keystone.server.flask.application   File "/var/lib/kolla/venv/lib/python3.9/site-packages/keystone/identity/backends/sql.py", line 194, in _get_user
2023-03-02 18:36:48.789763 2023-03-02 18:36:48.785 38 ERROR keystone.server.flask.application     raise exception.UserNotFound(user_id=user_id)
2023-03-02 18:36:48.789774 2023-03-02 18:36:48.785 38 ERROR keystone.server.flask.application keystone.exception.UserNotFound: Could not find user: neutron.
2023-03-02 18:36:48.789784 2023-03-02 18:36:48.785 38 ERROR keystone.server.flask.application \x1b[00m
2023-03-02 18:36:49.535424 2023-03-02 18:36:49.532 36 ERROR keystone.server.flask.application [None req-3f850c93-b49f-480b-8bf7-bcd0b529cb26 cf01766d1c3c4f0491c1efd319900764 - - all default -] Could not find project: service.: keystone.exception.ProjectNotFound: Could not find project: service.
2023-03-02 18:36:49.535525 2023-03-02 18:36:49.532 36 ERROR keystone.server.flask.application Traceback (most recent call last):
2023-03-02 18:36:49.535536 2023-03-02 18:36:49.532 36 ERROR keystone.server.flask.application   File "/var/lib/kolla/venv/lib/python3.9/site-packages/flask/app.py", line 1820, in full_dispatch_request
2023-03-02 18:36:49.535551 2023-03-02 18:36:49.532 36 ERROR keystone.server.flask.application     rv = self.dispatch_request()
2023-03-02 18:36:49.535569 2023-03-02 18:36:49.532 36 ERROR keystone.server.flask.application   File "/var/lib/kolla/venv/lib/python3.9/site-packages/flask/app.py", line 1796, in dispatch_request
2023-03-02 18:36:49.535624 2023-03-02 18:36:49.532 36 ERROR keystone.server.flask.application     return self.ensure_sync(self.view_functions[rule.endpoint])(**view_args)
2023-03-02 18:36:49.535645 2023-03-02 18:36:49.532 36 ERROR keystone.server.flask.application   File "/var/lib/kolla/venv/lib/python3.9/site-packages/flask_restful/__init__.py", line 467, in wrapper
2023-03-02 18:36:49.535664 2023-03-02 18:36:49.532 36 ERROR keystone.server.flask.application     resp = resource(*args, **kwargs)
2023-03-02 18:36:49.535682 2023-03-02 18:36:49.532 36 ERROR keystone.server.flask.application   File "/var/lib/kolla/venv/lib/python3.9/site-packages/flask/views.py", line 107, in view
2023-03-02 18:36:49.535710 2023-03-02 18:36:49.532 36 ERROR keystone.server.flask.application     return current_app.ensure_sync(self.dispatch_request)(**kwargs)
2023-03-02 18:36:49.535728 2023-03-02 18:36:49.532 36 ERROR keystone.server.flask.application   File "/var/lib/kolla/venv/lib/python3.9/site-packages/flask_restful/__init__.py", line 582, in dispatch_request
2023-03-02 18:36:49.535745 2023-03-02 18:36:49.532 36 ERROR keystone.server.flask.application     resp = meth(*args, **kwargs)
2023-03-02 18:36:49.535762 2023-03-02 18:36:49.532 36 ERROR keystone.server.flask.application   File "/var/lib/kolla/venv/lib/python3.9/site-packages/keystone/api/projects.py", line 151, in get
2023-03-02 18:36:49.535781 2023-03-02 18:36:49.532 36 ERROR keystone.server.flask.application     return self._get_project(project_id)
2023-03-02 18:36:49.535799 2023-03-02 18:36:49.532 36 ERROR keystone.server.flask.application   File "/var/lib/kolla/venv/lib/python3.9/site-packages/keystone/api/projects.py", line 107, in _get_project
2023-03-02 18:36:49.535832 2023-03-02 18:36:49.532 36 ERROR keystone.server.flask.application     project = PROVIDERS.resource_api.get_project(project_id)
2023-03-02 18:36:49.535891 2023-03-02 18:36:49.532 36 ERROR keystone.server.flask.application   File "/var/lib/kolla/venv/lib/python3.9/site-packages/keystone/common/manager.py", line 115, in wrapped
2023-03-02 18:36:49.535912 2023-03-02 18:36:49.532 36 ERROR keystone.server.flask.application     __ret_val = __f(*args, **kwargs)
2023-03-02 18:36:49.535922 2023-03-02 18:36:49.532 36 ERROR keystone.server.flask.application   File "/var/lib/kolla/venv/lib/python3.9/site-packages/decorator.py", line 232, in fun
2023-03-02 18:36:49.535936 2023-03-02 18:36:49.532 36 ERROR keystone.server.flask.application     return caller(func, *(extras + args), **kw)
2023-03-02 18:36:49.535969 2023-03-02 18:36:49.532 36 ERROR keystone.server.flask.application   File "/var/lib/kolla/venv/lib/python3.9/site-packages/dogpile/cache/region.py", line 1577, in get_or_create_for_user_func
2023-03-02 18:36:49.535989 2023-03-02 18:36:49.532 36 ERROR keystone.server.flask.application     return self.get_or_create(
2023-03-02 18:36:49.536007 2023-03-02 18:36:49.532 36 ERROR keystone.server.flask.application   File "/var/lib/kolla/venv/lib/python3.9/site-packages/dogpile/cache/region.py", line 1042, in get_or_create
2023-03-02 18:36:49.536018 2023-03-02 18:36:49.532 36 ERROR keystone.server.flask.application     with Lock(
2023-03-02 18:36:49.536028 2023-03-02 18:36:49.532 36 ERROR keystone.server.flask.application   File "/var/lib/kolla/venv/lib/python3.9/site-packages/dogpile/lock.py", line 185, in __enter__
2023-03-02 18:36:49.536038 2023-03-02 18:36:49.532 36 ERROR keystone.server.flask.application     return self._enter()
2023-03-02 18:36:49.536047 2023-03-02 18:36:49.532 36 ERROR keystone.server.flask.application   File "/var/lib/kolla/venv/lib/python3.9/site-packages/dogpile/lock.py", line 94, in _enter
2023-03-02 18:36:49.536057 2023-03-02 18:36:49.532 36 ERROR keystone.server.flask.application     generated = self._enter_create(value, createdtime)
2023-03-02 18:36:49.536067 2023-03-02 18:36:49.532 36 ERROR keystone.server.flask.application   File "/var/lib/kolla/venv/lib/python3.9/site-packages/dogpile/lock.py", line 178, in _enter_create
2023-03-02 18:36:49.536077 2023-03-02 18:36:49.532 36 ERROR keystone.server.flask.application     return self.creator()
2023-03-02 18:36:49.536087 2023-03-02 18:36:49.532 36 ERROR keystone.server.flask.application   File "/var/lib/kolla/venv/lib/python3.9/site-packages/dogpile/cache/region.py", line 995, in gen_value
2023-03-02 18:36:49.536097 2023-03-02 18:36:49.532 36 ERROR keystone.server.flask.application     created_value = creator(
2023-03-02 18:36:49.536107 2023-03-02 18:36:49.532 36 ERROR keystone.server.flask.application   File "/var/lib/kolla/venv/lib/python3.9/site-packages/keystone/resource/core.py", line 903, in get_project
2023-03-02 18:36:49.536116 2023-03-02 18:36:49.532 36 ERROR keystone.server.flask.application     return self.driver.get_project(project_id)
2023-03-02 18:36:49.536126 2023-03-02 18:36:49.532 36 ERROR keystone.server.flask.application   File "/var/lib/kolla/venv/lib/python3.9/site-packages/keystone/resource/backends/sql.py", line 49, in get_project
2023-03-02 18:36:49.536136 2023-03-02 18:36:49.532 36 ERROR keystone.server.flask.application     return self._get_project(session, project_id).to_dict()
2023-03-02 18:36:49.536146 2023-03-02 18:36:49.532 36 ERROR keystone.server.flask.application   File "/var/lib/kolla/venv/lib/python3.9/site-packages/keystone/resource/backends/sql.py", line 44, in _get_project
2023-03-02 18:36:49.536156 2023-03-02 18:36:49.532 36 ERROR keystone.server.flask.application     raise exception.ProjectNotFound(project_id=project_id)
2023-03-02 18:36:49.536166 2023-03-02 18:36:49.532 36 ERROR keystone.server.flask.application keystone.exception.ProjectNotFound: Could not find project: service.
2023-03-02 18:36:49.536176 2023-03-02 18:36:49.532 36 ERROR keystone.server.flask.application \x1b[00m
2023-03-02 18:47:30.009847 2023-03-02 18:47:30.008 36 WARNING py.warnings [None req-8fd43a19-5089-40b7-a015-3490f85ae01e cf01766d1c3c4f0491c1efd319900764 145b81034ad74c36a049462e8520bb6b - - default default] /var/lib/kolla/venv/lib/python3.9/site-packages/oslo_policy/policy.py:1129: UserWarning: Policy "identity:list_domains": "role:reader and system_scope:all" failed scope check. The token used to make the request was project scoped but the policy requires ['system'] scope. This behavior may change in the future where using the intended scope is required
2023-03-02 18:47:30.009995   warnings.warn(msg)
2023-03-02 18:47:30.010010 \x1b[00m
2023-03-02 18:47:30.263475 2023-03-02 18:47:30.261 37 WARNING py.warnings [None req-575e4b1d-5aae-4fd2-b42c-a6c493e2a486 cf01766d1c3c4f0491c1efd319900764 145b81034ad74c36a049462e8520bb6b - - default default] /var/lib/kolla/venv/lib/python3.9/site-packages/oslo_policy/policy.py:1129: UserWarning: Policy "identity:create_project": "(role:admin and system_scope:all) or (role:admin and domain_id:%(target.project.domain_id)s)" failed scope check. The token used to make the request was project scoped but the policy requires ['system', 'domain'] scope. This behavior may change in the future where using the intended scope is required
2023-03-02 18:47:30.263518   warnings.warn(msg)
2023-03-02 18:47:30.263529 \x1b[00m
2023-03-02 18:47:30.546664 2023-03-02 18:47:30.545 38 WARNING py.warnings [None req-fcb86c51-f0a4-401a-a07c-c2a6ee8e7b18 cf01766d1c3c4f0491c1efd319900764 145b81034ad74c36a049462e8520bb6b - - default default] /var/lib/kolla/venv/lib/python3.9/site-packages/oslo_policy/policy.py:1129: UserWarning: Policy "identity:create_user": "(role:admin and system_scope:all) or (role:admin and token.domain.id:%(target.user.domain_id)s)" failed scope check. The token used to make the request was project scoped but the policy requires ['system', 'domain'] scope. This behavior may change in the future where using the intended scope is required
2023-03-02 18:47:30.546705   warnings.warn(msg)
2023-03-02 18:47:30.546715 \x1b[00m
2023-03-02 18:47:31.332109 2023-03-02 18:47:31.331 36 WARNING py.warnings [None req-6433d2bc-2906-40cd-b975-9771bc6460a9 cf01766d1c3c4f0491c1efd319900764 145b81034ad74c36a049462e8520bb6b - - default default] /var/lib/kolla/venv/lib/python3.9/site-packages/oslo_policy/policy.py:1129: UserWarning: Policy "identity:list_roles": "role:reader and system_scope:all" failed scope check. The token used to make the request was project scoped but the policy requires ['system'] scope. This behavior may change in the future where using the intended scope is required
2023-03-02 18:47:31.332150   warnings.warn(msg)
2023-03-02 18:47:31.332160 \x1b[00m
2023-03-02 18:47:31.627718 2023-03-02 18:47:31.626 37 WARNING py.warnings [None req-71520997-7d5d-4a9e-ad60-26b3c61ded0e cf01766d1c3c4f0491c1efd319900764 145b81034ad74c36a049462e8520bb6b - - default default] /var/lib/kolla/venv/lib/python3.9/site-packages/oslo_policy/policy.py:1129: UserWarning: Policy "identity:create_grant": "(role:admin and system_scope:all) or ((role:admin and domain_id:%(target.user.domain_id)s and domain_id:%(target.project.domain_id)s) or (role:admin and domain_id:%(target.user.domain_id)s and domain_id:%(target.domain.id)s) or (role:admin and domain_id:%(target.group.domain_id)s and domain_id:%(target.project.domain_id)s) or (role:admin and domain_id:%(target.group.domain_id)s and domain_id:%(target.domain.id)s)) and (domain_id:%(target.role.domain_id)s or None:%(target.role.domain_id)s)" failed scope check. The token used to make the request was project scoped but the policy requires ['system', 'domain'] scope. This behavior may change in the future where using the intended scope is required
2023-03-02 18:47:31.627764   warnings.warn(msg)
2023-03-02 18:47:31.627774 \x1b[00m
2023-03-02 18:47:32.729728 2023-03-02 18:47:32.728 36 WARNING py.warnings [None req-cb92c1a4-879a-418e-ab4b-bfa154b72720 cf01766d1c3c4f0491c1efd319900764 145b81034ad74c36a049462e8520bb6b - - default default] /var/lib/kolla/venv/lib/python3.9/site-packages/oslo_policy/policy.py:1129: UserWarning: Policy "identity:create_project": "(role:admin and system_scope:all) or (role:admin and domain_id:%(target.project.domain_id)s)" failed scope check. The token used to make the request was project scoped but the policy requires ['system', 'domain'] scope. This behavior may change in the future where using the intended scope is required
2023-03-02 18:47:32.729827   warnings.warn(msg)
2023-03-02 18:47:32.729840 \x1b[00m
2023-03-02 18:47:33.048025 2023-03-02 18:47:33.047 37 WARNING py.warnings [None req-f6569223-e901-45cd-8915-3ba2cc333d14 cf01766d1c3c4f0491c1efd319900764 145b81034ad74c36a049462e8520bb6b - - default default] /var/lib/kolla/venv/lib/python3.9/site-packages/oslo_policy/policy.py:1129: UserWarning: Policy "identity:create_user": "(role:admin and system_scope:all) or (role:admin and token.domain.id:%(target.user.domain_id)s)" failed scope check. The token used to make the request was project scoped but the policy requires ['system', 'domain'] scope. This behavior may change in the future where using the intended scope is required
2023-03-02 18:47:33.048066   warnings.warn(msg)
2023-03-02 18:47:33.048076 \x1b[00m
2023-03-02 18:47:33.938011 2023-03-02 18:47:33.936 38 WARNING py.warnings [None req-eb855673-d6bd-4672-8c07-1e270919ecb9 cf01766d1c3c4f0491c1efd319900764 145b81034ad74c36a049462e8520bb6b - - default default] /var/lib/kolla/venv/lib/python3.9/site-packages/oslo_policy/policy.py:1129: UserWarning: Policy "identity:list_roles": "role:reader and system_scope:all" failed scope check. The token used to make the request was project scoped but the policy requires ['system'] scope. This behavior may change in the future where using the intended scope is required
2023-03-02 18:47:33.938062   warnings.warn(msg)
2023-03-02 18:47:33.938084 \x1b[00m
2023-03-02 18:47:34.281804 2023-03-02 18:47:34.280 36 WARNING py.warnings [None req-baebc78c-ceaf-4a86-b552-1e9e913d3dfc cf01766d1c3c4f0491c1efd319900764 145b81034ad74c36a049462e8520bb6b - - default default] /var/lib/kolla/venv/lib/python3.9/site-packages/oslo_policy/policy.py:1129: UserWarning: Policy "identity:create_grant": "(role:admin and system_scope:all) or ((role:admin and domain_id:%(target.user.domain_id)s and domain_id:%(target.project.domain_id)s) or (role:admin and domain_id:%(target.user.domain_id)s and domain_id:%(target.domain.id)s) or (role:admin and domain_id:%(target.group.domain_id)s and domain_id:%(target.project.domain_id)s) or (role:admin and domain_id:%(target.group.domain_id)s and domain_id:%(target.domain.id)s)) and (domain_id:%(target.role.domain_id)s or None:%(target.role.domain_id)s)" failed scope check. The token used to make the request was project scoped but the policy requires ['system', 'domain'] scope. This behavior may change in the future where using the intended scope is required
2023-03-02 18:47:34.281850   warnings.warn(msg)
2023-03-02 18:47:34.281861 \x1b[00m
2023-03-02 18:47:34.545551 2023-03-02 18:47:34.544 37 WARNING py.warnings [None req-6a864c42-c983-4b83-a757-3d76f42f890a cf01766d1c3c4f0491c1efd319900764 145b81034ad74c36a049462e8520bb6b - - default default] /var/lib/kolla/venv/lib/python3.9/site-packages/oslo_policy/policy.py:1129: UserWarning: Policy "identity:list_roles": "role:reader and system_scope:all" failed scope check. The token used to make the request was project scoped but the policy requires ['system'] scope. This behavior may change in the future where using the intended scope is required
2023-03-02 18:47:34.545635   warnings.warn(msg)
2023-03-02 18:47:34.545659 \x1b[00m
2023-03-02 18:47:34.815508 2023-03-02 18:47:34.814 38 WARNING py.warnings [None req-007af4c6-5b7a-4673-8f91-31dc0d802408 cf01766d1c3c4f0491c1efd319900764 145b81034ad74c36a049462e8520bb6b - - default default] /var/lib/kolla/venv/lib/python3.9/site-packages/oslo_policy/policy.py:1129: UserWarning: Policy "identity:create_grant": "(role:admin and system_scope:all) or ((role:admin and domain_id:%(target.user.domain_id)s and domain_id:%(target.project.domain_id)s) or (role:admin and domain_id:%(target.user.domain_id)s and domain_id:%(target.domain.id)s) or (role:admin and domain_id:%(target.group.domain_id)s and domain_id:%(target.project.domain_id)s) or (role:admin and domain_id:%(target.group.domain_id)s and domain_id:%(target.domain.id)s)) and (domain_id:%(target.role.domain_id)s or None:%(target.role.domain_id)s)" failed scope check. The token used to make the request was project scoped but the policy requires ['system', 'domain'] scope. This behavior may change in the future where using the intended scope is required
2023-03-02 18:47:34.815607   warnings.warn(msg)
2023-03-02 18:47:34.815624 \x1b[00m
2023-03-02 18:47:37.376737 2023-03-02 18:47:37.375 37 WARNING py.warnings [None req-292b48ea-91bd-4736-822f-af214bdcb3fc cf01766d1c3c4f0491c1efd319900764 145b81034ad74c36a049462e8520bb6b - - default default] /var/lib/kolla/venv/lib/python3.9/site-packages/oslo_policy/policy.py:1129: UserWarning: Policy "identity:create_system_grant_for_user": "role:admin and system_scope:all" failed scope check. The token used to make the request was project scoped but the policy requires ['system'] scope. This behavior may change in the future where using the intended scope is required
2023-03-02 18:47:37.376783   warnings.warn(msg)
2023-03-02 18:47:37.376793 \x1b[00m
