2023-02-17 06:09:44.673 23 INFO alembic.runtime.migration [-] Context impl MySQLImpl.
2023-02-17 06:09:44.675 23 INFO alembic.runtime.migration [-] Will assume non-transactional DDL.
2023-02-17 06:09:44.713 23 INFO alembic.runtime.migration [-] Context impl MySQLImpl.
2023-02-17 06:09:44.714 23 INFO alembic.runtime.migration [-] Will assume non-transactional DDL.
2023-02-17 06:09:44.760 23 INFO alembic.runtime.migration [-] Running upgrade  -> 27e647c0fad4, Initial version.
2023-02-17 06:09:45.896 23 INFO alembic.runtime.migration [-] Running upgrade 27e647c0fad4 -> e25ffa003242, Initial no-op Yoga contract migration.
2023-02-17 06:09:45.911 23 INFO alembic.runtime.migration [-] Running upgrade 27e647c0fad4 -> 29e87d24a316, Initial no-op Yoga expand migration.
2023-02-17 06:09:53.822 7 INFO keystone.common.fernet_utils [-] Created a new temporary key: /etc/keystone/fernet-keys/0.tmp
2023-02-17 06:09:53.826 7 INFO keystone.common.fernet_utils [-] Become a valid new key: /etc/keystone/fernet-keys/0
2023-02-17 06:09:53.828 7 INFO keystone.common.fernet_utils [-] Starting key rotation with 1 key files: ['/etc/keystone/fernet-keys/0']
2023-02-17 06:09:53.828 7 INFO keystone.common.fernet_utils [-] Created a new temporary key: /etc/keystone/fernet-keys/0.tmp
2023-02-17 06:09:53.829 7 INFO keystone.common.fernet_utils [-] Current primary key is: 0
2023-02-17 06:09:53.830 7 INFO keystone.common.fernet_utils [-] Next primary key will be: 1
2023-02-17 06:09:53.831 7 INFO keystone.common.fernet_utils [-] Promoted key 0 to be the primary: 1
2023-02-17 06:09:53.831 7 INFO keystone.common.fernet_utils [-] Become a valid new key: /etc/keystone/fernet-keys/0
2023-02-17 06:10:11.847 33 INFO keystone.cmd.bootstrap [None req-66fc9d08-4f3b-4592-9cb9-ad8dfafda4bf - - - - - -] Created domain default
2023-02-17 06:10:11.928 33 INFO keystone.cmd.bootstrap [None req-66fc9d08-4f3b-4592-9cb9-ad8dfafda4bf - - - - - -] Created project admin
2023-02-17 06:10:12.582 33 INFO keystone.cmd.bootstrap [None req-66fc9d08-4f3b-4592-9cb9-ad8dfafda4bf - - - - - -] Created user admin
2023-02-17 06:10:12.607 33 INFO keystone.cmd.bootstrap [None req-66fc9d08-4f3b-4592-9cb9-ad8dfafda4bf - - - - - -] Created role reader
2023-02-17 06:10:12.629 33 INFO keystone.cmd.bootstrap [None req-66fc9d08-4f3b-4592-9cb9-ad8dfafda4bf - - - - - -] Created role member
2023-02-17 06:10:12.670 33 INFO keystone.cmd.bootstrap [None req-66fc9d08-4f3b-4592-9cb9-ad8dfafda4bf - - - - - -] Created implied role where 62847075b6034f23bae7e9fd9c35b869 implies 150f0193be1b41909771367a2aad21af
2023-02-17 06:10:12.690 33 INFO keystone.cmd.bootstrap [None req-66fc9d08-4f3b-4592-9cb9-ad8dfafda4bf - - - - - -] Created role admin
2023-02-17 06:10:12.730 33 INFO keystone.cmd.bootstrap [None req-66fc9d08-4f3b-4592-9cb9-ad8dfafda4bf - - - - - -] Created implied role where 3c1f1c9f2e9a4c5c8eccdc9322b9a608 implies 62847075b6034f23bae7e9fd9c35b869
2023-02-17 06:10:12.752 33 INFO keystone.cmd.bootstrap [None req-66fc9d08-4f3b-4592-9cb9-ad8dfafda4bf - - - - - -] Granted role admin on project admin to user admin.
2023-02-17 06:10:12.765 33 INFO keystone.cmd.bootstrap [None req-66fc9d08-4f3b-4592-9cb9-ad8dfafda4bf - - - - - -] Granted role admin on the system to user admin.
2023-02-17 06:10:12.799 33 WARNING py.warnings [None req-66fc9d08-4f3b-4592-9cb9-ad8dfafda4bf - - - - - -] /var/lib/kolla/venv/lib/python3.9/site-packages/pycadf/identifier.py:71: UserWarning: Invalid uuid: RegionOne. To ensure interoperability, identifiers should be a valid uuid.
  warnings.warn(('Invalid uuid: %s. To ensure interoperability, '

2023-02-17 06:10:12.808 33 INFO keystone.cmd.bootstrap [None req-66fc9d08-4f3b-4592-9cb9-ad8dfafda4bf - - - - - -] Created region RegionOne
2023-02-17 06:10:12.869 33 INFO keystone.cmd.bootstrap [None req-66fc9d08-4f3b-4592-9cb9-ad8dfafda4bf - - - - - -] Created public endpoint http://169.16.1.158:5000
2023-02-17 06:10:12.886 33 INFO keystone.cmd.bootstrap [None req-66fc9d08-4f3b-4592-9cb9-ad8dfafda4bf - - - - - -] Created internal endpoint http://169.16.1.158:5000
2023-02-17 06:10:37.517 40 WARNING keystone.common.rbac_enforcer.enforcer [None req-7d5ac7d1-5c70-45de-aecd-23a71efcdecf 716d238b4ce449dd9f65ebb57f427216 - - all default -] Deprecated policy rules found. Use oslopolicy-policy-generator and oslopolicy-policy-upgrade to detect and resolve deprecated policies in your configuration.
2023-02-17 06:10:38.266 39 WARNING keystone.common.rbac_enforcer.enforcer [None req-d189540b-d889-47a0-82fb-923794ef2e23 716d238b4ce449dd9f65ebb57f427216 - - all default -] Deprecated policy rules found. Use oslopolicy-policy-generator and oslopolicy-policy-upgrade to detect and resolve deprecated policies in your configuration.
2023-02-17 06:10:45.642 38 WARNING keystone.common.rbac_enforcer.enforcer [None req-61230589-830f-4c75-9f46-388fac14010d 716d238b4ce449dd9f65ebb57f427216 - - all default -] Deprecated policy rules found. Use oslopolicy-policy-generator and oslopolicy-policy-upgrade to detect and resolve deprecated policies in your configuration.
2023-02-17 06:12:00.752 40 ERROR keystone.server.flask.application [None req-97f254a8-f572-430a-ab02-54b9b5ebdb6f 716d238b4ce449dd9f65ebb57f427216 - - all default -] Could not find project: service.: keystone.exception.ProjectNotFound: Could not find project: service.
2023-02-17 06:12:00.752 40 ERROR keystone.server.flask.application Traceback (most recent call last):
2023-02-17 06:12:00.752 40 ERROR keystone.server.flask.application   File "/var/lib/kolla/venv/lib/python3.9/site-packages/flask/app.py", line 1820, in full_dispatch_request
2023-02-17 06:12:00.752 40 ERROR keystone.server.flask.application     rv = self.dispatch_request()
2023-02-17 06:12:00.752 40 ERROR keystone.server.flask.application   File "/var/lib/kolla/venv/lib/python3.9/site-packages/flask/app.py", line 1796, in dispatch_request
2023-02-17 06:12:00.752 40 ERROR keystone.server.flask.application     return self.ensure_sync(self.view_functions[rule.endpoint])(**view_args)
2023-02-17 06:12:00.752 40 ERROR keystone.server.flask.application   File "/var/lib/kolla/venv/lib/python3.9/site-packages/flask_restful/__init__.py", line 467, in wrapper
2023-02-17 06:12:00.752 40 ERROR keystone.server.flask.application     resp = resource(*args, **kwargs)
2023-02-17 06:12:00.752 40 ERROR keystone.server.flask.application   File "/var/lib/kolla/venv/lib/python3.9/site-packages/flask/views.py", line 107, in view
2023-02-17 06:12:00.752 40 ERROR keystone.server.flask.application     return current_app.ensure_sync(self.dispatch_request)(**kwargs)
2023-02-17 06:12:00.752 40 ERROR keystone.server.flask.application   File "/var/lib/kolla/venv/lib/python3.9/site-packages/flask_restful/__init__.py", line 582, in dispatch_request
2023-02-17 06:12:00.752 40 ERROR keystone.server.flask.application     resp = meth(*args, **kwargs)
2023-02-17 06:12:00.752 40 ERROR keystone.server.flask.application   File "/var/lib/kolla/venv/lib/python3.9/site-packages/keystone/api/projects.py", line 151, in get
2023-02-17 06:12:00.752 40 ERROR keystone.server.flask.application     return self._get_project(project_id)
2023-02-17 06:12:00.752 40 ERROR keystone.server.flask.application   File "/var/lib/kolla/venv/lib/python3.9/site-packages/keystone/api/projects.py", line 107, in _get_project
2023-02-17 06:12:00.752 40 ERROR keystone.server.flask.application     project = PROVIDERS.resource_api.get_project(project_id)
2023-02-17 06:12:00.752 40 ERROR keystone.server.flask.application   File "/var/lib/kolla/venv/lib/python3.9/site-packages/keystone/common/manager.py", line 115, in wrapped
2023-02-17 06:12:00.752 40 ERROR keystone.server.flask.application     __ret_val = __f(*args, **kwargs)
2023-02-17 06:12:00.752 40 ERROR keystone.server.flask.application   File "/var/lib/kolla/venv/lib/python3.9/site-packages/decorator.py", line 232, in fun
2023-02-17 06:12:00.752 40 ERROR keystone.server.flask.application     return caller(func, *(extras + args), **kw)
2023-02-17 06:12:00.752 40 ERROR keystone.server.flask.application   File "/var/lib/kolla/venv/lib/python3.9/site-packages/dogpile/cache/region.py", line 1577, in get_or_create_for_user_func
2023-02-17 06:12:00.752 40 ERROR keystone.server.flask.application     return self.get_or_create(
2023-02-17 06:12:00.752 40 ERROR keystone.server.flask.application   File "/var/lib/kolla/venv/lib/python3.9/site-packages/dogpile/cache/region.py", line 1042, in get_or_create
2023-02-17 06:12:00.752 40 ERROR keystone.server.flask.application     with Lock(
2023-02-17 06:12:00.752 40 ERROR keystone.server.flask.application   File "/var/lib/kolla/venv/lib/python3.9/site-packages/dogpile/lock.py", line 185, in __enter__
2023-02-17 06:12:00.752 40 ERROR keystone.server.flask.application     return self._enter()
2023-02-17 06:12:00.752 40 ERROR keystone.server.flask.application   File "/var/lib/kolla/venv/lib/python3.9/site-packages/dogpile/lock.py", line 94, in _enter
2023-02-17 06:12:00.752 40 ERROR keystone.server.flask.application     generated = self._enter_create(value, createdtime)
2023-02-17 06:12:00.752 40 ERROR keystone.server.flask.application   File "/var/lib/kolla/venv/lib/python3.9/site-packages/dogpile/lock.py", line 178, in _enter_create
2023-02-17 06:12:00.752 40 ERROR keystone.server.flask.application     return self.creator()
2023-02-17 06:12:00.752 40 ERROR keystone.server.flask.application   File "/var/lib/kolla/venv/lib/python3.9/site-packages/dogpile/cache/region.py", line 995, in gen_value
2023-02-17 06:12:00.752 40 ERROR keystone.server.flask.application     created_value = creator(
2023-02-17 06:12:00.752 40 ERROR keystone.server.flask.application   File "/var/lib/kolla/venv/lib/python3.9/site-packages/keystone/resource/core.py", line 903, in get_project
2023-02-17 06:12:00.752 40 ERROR keystone.server.flask.application     return self.driver.get_project(project_id)
2023-02-17 06:12:00.752 40 ERROR keystone.server.flask.application   File "/var/lib/kolla/venv/lib/python3.9/site-packages/keystone/resource/backends/sql.py", line 49, in get_project
2023-02-17 06:12:00.752 40 ERROR keystone.server.flask.application     return self._get_project(session, project_id).to_dict()
2023-02-17 06:12:00.752 40 ERROR keystone.server.flask.application   File "/var/lib/kolla/venv/lib/python3.9/site-packages/keystone/resource/backends/sql.py", line 44, in _get_project
2023-02-17 06:12:00.752 40 ERROR keystone.server.flask.application     raise exception.ProjectNotFound(project_id=project_id)
2023-02-17 06:12:00.752 40 ERROR keystone.server.flask.application keystone.exception.ProjectNotFound: Could not find project: service.
2023-02-17 06:12:00.752 40 ERROR keystone.server.flask.application 
2023-02-17 06:12:09.791 38 ERROR keystone.server.flask.application [None req-d11ef4da-c531-4f46-84c0-29fe2b0fffb5 716d238b4ce449dd9f65ebb57f427216 - - all default -] Could not find project: service.: keystone.exception.ProjectNotFound: Could not find project: service.
2023-02-17 06:12:09.791 38 ERROR keystone.server.flask.application Traceback (most recent call last):
2023-02-17 06:12:09.791 38 ERROR keystone.server.flask.application   File "/var/lib/kolla/venv/lib/python3.9/site-packages/flask/app.py", line 1820, in full_dispatch_request
2023-02-17 06:12:09.791 38 ERROR keystone.server.flask.application     rv = self.dispatch_request()
2023-02-17 06:12:09.791 38 ERROR keystone.server.flask.application   File "/var/lib/kolla/venv/lib/python3.9/site-packages/flask/app.py", line 1796, in dispatch_request
2023-02-17 06:12:09.791 38 ERROR keystone.server.flask.application     return self.ensure_sync(self.view_functions[rule.endpoint])(**view_args)
2023-02-17 06:12:09.791 38 ERROR keystone.server.flask.application   File "/var/lib/kolla/venv/lib/python3.9/site-packages/flask_restful/__init__.py", line 467, in wrapper
2023-02-17 06:12:09.791 38 ERROR keystone.server.flask.application     resp = resource(*args, **kwargs)
2023-02-17 06:12:09.791 38 ERROR keystone.server.flask.application   File "/var/lib/kolla/venv/lib/python3.9/site-packages/flask/views.py", line 107, in view
2023-02-17 06:12:09.791 38 ERROR keystone.server.flask.application     return current_app.ensure_sync(self.dispatch_request)(**kwargs)
2023-02-17 06:12:09.791 38 ERROR keystone.server.flask.application   File "/var/lib/kolla/venv/lib/python3.9/site-packages/flask_restful/__init__.py", line 582, in dispatch_request
2023-02-17 06:12:09.791 38 ERROR keystone.server.flask.application     resp = meth(*args, **kwargs)
2023-02-17 06:12:09.791 38 ERROR keystone.server.flask.application   File "/var/lib/kolla/venv/lib/python3.9/site-packages/keystone/api/projects.py", line 151, in get
2023-02-17 06:12:09.791 38 ERROR keystone.server.flask.application     return self._get_project(project_id)
2023-02-17 06:12:09.791 38 ERROR keystone.server.flask.application   File "/var/lib/kolla/venv/lib/python3.9/site-packages/keystone/api/projects.py", line 107, in _get_project
2023-02-17 06:12:09.791 38 ERROR keystone.server.flask.application     project = PROVIDERS.resource_api.get_project(project_id)
2023-02-17 06:12:09.791 38 ERROR keystone.server.flask.application   File "/var/lib/kolla/venv/lib/python3.9/site-packages/keystone/common/manager.py", line 115, in wrapped
2023-02-17 06:12:09.791 38 ERROR keystone.server.flask.application     __ret_val = __f(*args, **kwargs)
2023-02-17 06:12:09.791 38 ERROR keystone.server.flask.application   File "/var/lib/kolla/venv/lib/python3.9/site-packages/decorator.py", line 232, in fun
2023-02-17 06:12:09.791 38 ERROR keystone.server.flask.application     return caller(func, *(extras + args), **kw)
2023-02-17 06:12:09.791 38 ERROR keystone.server.flask.application   File "/var/lib/kolla/venv/lib/python3.9/site-packages/dogpile/cache/region.py", line 1577, in get_or_create_for_user_func
2023-02-17 06:12:09.791 38 ERROR keystone.server.flask.application     return self.get_or_create(
2023-02-17 06:12:09.791 38 ERROR keystone.server.flask.application   File "/var/lib/kolla/venv/lib/python3.9/site-packages/dogpile/cache/region.py", line 1042, in get_or_create
2023-02-17 06:12:09.791 38 ERROR keystone.server.flask.application     with Lock(
2023-02-17 06:12:09.791 38 ERROR keystone.server.flask.application   File "/var/lib/kolla/venv/lib/python3.9/site-packages/dogpile/lock.py", line 185, in __enter__
2023-02-17 06:12:09.791 38 ERROR keystone.server.flask.application     return self._enter()
2023-02-17 06:12:09.791 38 ERROR keystone.server.flask.application   File "/var/lib/kolla/venv/lib/python3.9/site-packages/dogpile/lock.py", line 94, in _enter
2023-02-17 06:12:09.791 38 ERROR keystone.server.flask.application     generated = self._enter_create(value, createdtime)
2023-02-17 06:12:09.791 38 ERROR keystone.server.flask.application   File "/var/lib/kolla/venv/lib/python3.9/site-packages/dogpile/lock.py", line 178, in _enter_create
2023-02-17 06:12:09.791 38 ERROR keystone.server.flask.application     return self.creator()
2023-02-17 06:12:09.791 38 ERROR keystone.server.flask.application   File "/var/lib/kolla/venv/lib/python3.9/site-packages/dogpile/cache/region.py", line 995, in gen_value
2023-02-17 06:12:09.791 38 ERROR keystone.server.flask.application     created_value = creator(
2023-02-17 06:12:09.791 38 ERROR keystone.server.flask.application   File "/var/lib/kolla/venv/lib/python3.9/site-packages/keystone/resource/core.py", line 903, in get_project
2023-02-17 06:12:09.791 38 ERROR keystone.server.flask.application     return self.driver.get_project(project_id)
2023-02-17 06:12:09.791 38 ERROR keystone.server.flask.application   File "/var/lib/kolla/venv/lib/python3.9/site-packages/keystone/resource/backends/sql.py", line 49, in get_project
2023-02-17 06:12:09.791 38 ERROR keystone.server.flask.application     return self._get_project(session, project_id).to_dict()
2023-02-17 06:12:09.791 38 ERROR keystone.server.flask.application   File "/var/lib/kolla/venv/lib/python3.9/site-packages/keystone/resource/backends/sql.py", line 44, in _get_project
2023-02-17 06:12:09.791 38 ERROR keystone.server.flask.application     raise exception.ProjectNotFound(project_id=project_id)
2023-02-17 06:12:09.791 38 ERROR keystone.server.flask.application keystone.exception.ProjectNotFound: Could not find project: service.
2023-02-17 06:12:09.791 38 ERROR keystone.server.flask.application 
2023-02-17 06:12:24.388 38 ERROR keystone.server.flask.application [None req-e3815762-81c5-48d2-9bc8-90e9a533c88e 716d238b4ce449dd9f65ebb57f427216 - - all default -] Could not find role: admin.: keystone.exception.RoleNotFound: Could not find role: admin.
2023-02-17 06:12:24.388 38 ERROR keystone.server.flask.application Traceback (most recent call last):
2023-02-17 06:12:24.388 38 ERROR keystone.server.flask.application   File "/var/lib/kolla/venv/lib/python3.9/site-packages/flask/app.py", line 1820, in full_dispatch_request
2023-02-17 06:12:24.388 38 ERROR keystone.server.flask.application     rv = self.dispatch_request()
2023-02-17 06:12:24.388 38 ERROR keystone.server.flask.application   File "/var/lib/kolla/venv/lib/python3.9/site-packages/flask/app.py", line 1796, in dispatch_request
2023-02-17 06:12:24.388 38 ERROR keystone.server.flask.application     return self.ensure_sync(self.view_functions[rule.endpoint])(**view_args)
2023-02-17 06:12:24.388 38 ERROR keystone.server.flask.application   File "/var/lib/kolla/venv/lib/python3.9/site-packages/flask_restful/__init__.py", line 467, in wrapper
2023-02-17 06:12:24.388 38 ERROR keystone.server.flask.application     resp = resource(*args, **kwargs)
2023-02-17 06:12:24.388 38 ERROR keystone.server.flask.application   File "/var/lib/kolla/venv/lib/python3.9/site-packages/flask/views.py", line 107, in view
2023-02-17 06:12:24.388 38 ERROR keystone.server.flask.application     return current_app.ensure_sync(self.dispatch_request)(**kwargs)
2023-02-17 06:12:24.388 38 ERROR keystone.server.flask.application   File "/var/lib/kolla/venv/lib/python3.9/site-packages/flask_restful/__init__.py", line 582, in dispatch_request
2023-02-17 06:12:24.388 38 ERROR keystone.server.flask.application     resp = meth(*args, **kwargs)
2023-02-17 06:12:24.388 38 ERROR keystone.server.flask.application   File "/var/lib/kolla/venv/lib/python3.9/site-packages/keystone/api/roles.py", line 50, in get
2023-02-17 06:12:24.388 38 ERROR keystone.server.flask.application     return self._get_role(role_id)
2023-02-17 06:12:24.388 38 ERROR keystone.server.flask.application   File "/var/lib/kolla/venv/lib/python3.9/site-packages/keystone/api/roles.py", line 70, in _get_role
2023-02-17 06:12:24.388 38 ERROR keystone.server.flask.application     ENFORCER.enforce_call(action='identity:get_role')
2023-02-17 06:12:24.388 38 ERROR keystone.server.flask.application   File "/var/lib/kolla/venv/lib/python3.9/site-packages/keystone/common/rbac_enforcer/enforcer.py", line 402, in enforce_call
2023-02-17 06:12:24.388 38 ERROR keystone.server.flask.application     policy_dict.update(cls._extract_member_target_data(
2023-02-17 06:12:24.388 38 ERROR keystone.server.flask.application   File "/var/lib/kolla/venv/lib/python3.9/site-packages/keystone/common/rbac_enforcer/enforcer.py", line 234, in _extract_member_target_data
2023-02-17 06:12:24.388 38 ERROR keystone.server.flask.application     member_name: func(flask.request.view_args[key])
2023-02-17 06:12:24.388 38 ERROR keystone.server.flask.application   File "/var/lib/kolla/venv/lib/python3.9/site-packages/keystone/common/manager.py", line 115, in wrapped
2023-02-17 06:12:24.388 38 ERROR keystone.server.flask.application     __ret_val = __f(*args, **kwargs)
2023-02-17 06:12:24.388 38 ERROR keystone.server.flask.application   File "/var/lib/kolla/venv/lib/python3.9/site-packages/decorator.py", line 232, in fun
2023-02-17 06:12:24.388 38 ERROR keystone.server.flask.application     return caller(func, *(extras + args), **kw)
2023-02-17 06:12:24.388 38 ERROR keystone.server.flask.application   File "/var/lib/kolla/venv/lib/python3.9/site-packages/dogpile/cache/region.py", line 1577, in get_or_create_for_user_func
2023-02-17 06:12:24.388 38 ERROR keystone.server.flask.application     return self.get_or_create(
2023-02-17 06:12:24.388 38 ERROR keystone.server.flask.application   File "/var/lib/kolla/venv/lib/python3.9/site-packages/dogpile/cache/region.py", line 1042, in get_or_create
2023-02-17 06:12:24.388 38 ERROR keystone.server.flask.application     with Lock(
2023-02-17 06:12:24.388 38 ERROR keystone.server.flask.application   File "/var/lib/kolla/venv/lib/python3.9/site-packages/dogpile/lock.py", line 185, in __enter__
2023-02-17 06:12:24.388 38 ERROR keystone.server.flask.application     return self._enter()
2023-02-17 06:12:24.388 38 ERROR keystone.server.flask.application   File "/var/lib/kolla/venv/lib/python3.9/site-packages/dogpile/lock.py", line 94, in _enter
2023-02-17 06:12:24.388 38 ERROR keystone.server.flask.application     generated = self._enter_create(value, createdtime)
2023-02-17 06:12:24.388 38 ERROR keystone.server.flask.application   File "/var/lib/kolla/venv/lib/python3.9/site-packages/dogpile/lock.py", line 178, in _enter_create
2023-02-17 06:12:24.388 38 ERROR keystone.server.flask.application     return self.creator()
2023-02-17 06:12:24.388 38 ERROR keystone.server.flask.application   File "/var/lib/kolla/venv/lib/python3.9/site-packages/dogpile/cache/region.py", line 995, in gen_value
2023-02-17 06:12:24.388 38 ERROR keystone.server.flask.application     created_value = creator(
2023-02-17 06:12:24.388 38 ERROR keystone.server.flask.application   File "/var/lib/kolla/venv/lib/python3.9/site-packages/keystone/assignment/core.py", line 1276, in get_role
2023-02-17 06:12:24.388 38 ERROR keystone.server.flask.application     return self.driver.get_role(role_id)
2023-02-17 06:12:24.388 38 ERROR keystone.server.flask.application   File "/var/lib/kolla/venv/lib/python3.9/site-packages/keystone/assignment/role_backends/sql.py", line 70, in get_role
2023-02-17 06:12:24.388 38 ERROR keystone.server.flask.application     return self._get_role(session, role_id).to_dict()
2023-02-17 06:12:24.388 38 ERROR keystone.server.flask.application   File "/var/lib/kolla/venv/lib/python3.9/site-packages/keystone/assignment/role_backends/sql.py", line 65, in _get_role
2023-02-17 06:12:24.388 38 ERROR keystone.server.flask.application     raise exception.RoleNotFound(role_id=role_id)
2023-02-17 06:12:24.388 38 ERROR keystone.server.flask.application keystone.exception.RoleNotFound: Could not find role: admin.
2023-02-17 06:12:24.388 38 ERROR keystone.server.flask.application 
2023-02-17 06:12:25.556 38 ERROR keystone.server.flask.application [None req-5dee0c8d-665f-4ddc-8c2d-cc6e9ddea56d 716d238b4ce449dd9f65ebb57f427216 - - all default -] Could not find user: ironic.: keystone.exception.UserNotFound: Could not find user: ironic.
2023-02-17 06:12:25.556 38 ERROR keystone.server.flask.application Traceback (most recent call last):
2023-02-17 06:12:25.556 38 ERROR keystone.server.flask.application   File "/var/lib/kolla/venv/lib/python3.9/site-packages/flask/app.py", line 1820, in full_dispatch_request
2023-02-17 06:12:25.556 38 ERROR keystone.server.flask.application     rv = self.dispatch_request()
2023-02-17 06:12:25.556 38 ERROR keystone.server.flask.application   File "/var/lib/kolla/venv/lib/python3.9/site-packages/flask/app.py", line 1796, in dispatch_request
2023-02-17 06:12:25.556 38 ERROR keystone.server.flask.application     return self.ensure_sync(self.view_functions[rule.endpoint])(**view_args)
2023-02-17 06:12:25.556 38 ERROR keystone.server.flask.application   File "/var/lib/kolla/venv/lib/python3.9/site-packages/flask_restful/__init__.py", line 467, in wrapper
2023-02-17 06:12:25.556 38 ERROR keystone.server.flask.application     resp = resource(*args, **kwargs)
2023-02-17 06:12:25.556 38 ERROR keystone.server.flask.application   File "/var/lib/kolla/venv/lib/python3.9/site-packages/flask/views.py", line 107, in view
2023-02-17 06:12:25.556 38 ERROR keystone.server.flask.application     return current_app.ensure_sync(self.dispatch_request)(**kwargs)
2023-02-17 06:12:25.556 38 ERROR keystone.server.flask.application   File "/var/lib/kolla/venv/lib/python3.9/site-packages/flask_restful/__init__.py", line 582, in dispatch_request
2023-02-17 06:12:25.556 38 ERROR keystone.server.flask.application     resp = meth(*args, **kwargs)
2023-02-17 06:12:25.556 38 ERROR keystone.server.flask.application   File "/var/lib/kolla/venv/lib/python3.9/site-packages/keystone/api/users.py", line 182, in get
2023-02-17 06:12:25.556 38 ERROR keystone.server.flask.application     return self._get_user(user_id)
2023-02-17 06:12:25.556 38 ERROR keystone.server.flask.application   File "/var/lib/kolla/venv/lib/python3.9/site-packages/keystone/api/users.py", line 194, in _get_user
2023-02-17 06:12:25.556 38 ERROR keystone.server.flask.application     ref = PROVIDERS.identity_api.get_user(user_id)
2023-02-17 06:12:25.556 38 ERROR keystone.server.flask.application   File "/var/lib/kolla/venv/lib/python3.9/site-packages/keystone/common/manager.py", line 115, in wrapped
2023-02-17 06:12:25.556 38 ERROR keystone.server.flask.application     __ret_val = __f(*args, **kwargs)
2023-02-17 06:12:25.556 38 ERROR keystone.server.flask.application   File "/var/lib/kolla/venv/lib/python3.9/site-packages/keystone/identity/core.py", line 414, in wrapper
2023-02-17 06:12:25.556 38 ERROR keystone.server.flask.application     return f(self, *args, **kwargs)
2023-02-17 06:12:25.556 38 ERROR keystone.server.flask.application   File "/var/lib/kolla/venv/lib/python3.9/site-packages/keystone/identity/core.py", line 424, in wrapper
2023-02-17 06:12:25.556 38 ERROR keystone.server.flask.application     return f(self, *args, **kwargs)
2023-02-17 06:12:25.556 38 ERROR keystone.server.flask.application   File "/var/lib/kolla/venv/lib/python3.9/site-packages/decorator.py", line 232, in fun
2023-02-17 06:12:25.556 38 ERROR keystone.server.flask.application     return caller(func, *(extras + args), **kw)
2023-02-17 06:12:25.556 38 ERROR keystone.server.flask.application   File "/var/lib/kolla/venv/lib/python3.9/site-packages/dogpile/cache/region.py", line 1577, in get_or_create_for_user_func
2023-02-17 06:12:25.556 38 ERROR keystone.server.flask.application     return self.get_or_create(
2023-02-17 06:12:25.556 38 ERROR keystone.server.flask.application   File "/var/lib/kolla/venv/lib/python3.9/site-packages/dogpile/cache/region.py", line 1042, in get_or_create
2023-02-17 06:12:25.556 38 ERROR keystone.server.flask.application     with Lock(
2023-02-17 06:12:25.556 38 ERROR keystone.server.flask.application   File "/var/lib/kolla/venv/lib/python3.9/site-packages/dogpile/lock.py", line 185, in __enter__
2023-02-17 06:12:25.556 38 ERROR keystone.server.flask.application     return self._enter()
2023-02-17 06:12:25.556 38 ERROR keystone.server.flask.application   File "/var/lib/kolla/venv/lib/python3.9/site-packages/dogpile/lock.py", line 94, in _enter
2023-02-17 06:12:25.556 38 ERROR keystone.server.flask.application     generated = self._enter_create(value, createdtime)
2023-02-17 06:12:25.556 38 ERROR keystone.server.flask.application   File "/var/lib/kolla/venv/lib/python3.9/site-packages/dogpile/lock.py", line 178, in _enter_create
2023-02-17 06:12:25.556 38 ERROR keystone.server.flask.application     return self.creator()
2023-02-17 06:12:25.556 38 ERROR keystone.server.flask.application   File "/var/lib/kolla/venv/lib/python3.9/site-packages/dogpile/cache/region.py", line 995, in gen_value
2023-02-17 06:12:25.556 38 ERROR keystone.server.flask.application     created_value = creator(
2023-02-17 06:12:25.556 38 ERROR keystone.server.flask.application   File "/var/lib/kolla/venv/lib/python3.9/site-packages/keystone/identity/core.py", line 1011, in get_user
2023-02-17 06:12:25.556 38 ERROR keystone.server.flask.application     ref = driver.get_user(entity_id)
2023-02-17 06:12:25.556 38 ERROR keystone.server.flask.application   File "/var/lib/kolla/venv/lib/python3.9/site-packages/keystone/identity/backends/sql.py", line 200, in get_user
2023-02-17 06:12:25.556 38 ERROR keystone.server.flask.application     self._get_user(session, user_id).to_dict())
2023-02-17 06:12:25.556 38 ERROR keystone.server.flask.application   File "/var/lib/kolla/venv/lib/python3.9/site-packages/keystone/identity/backends/sql.py", line 194, in _get_user
2023-02-17 06:12:25.556 38 ERROR keystone.server.flask.application     raise exception.UserNotFound(user_id=user_id)
2023-02-17 06:12:25.556 38 ERROR keystone.server.flask.application keystone.exception.UserNotFound: Could not find user: ironic.
2023-02-17 06:12:25.556 38 ERROR keystone.server.flask.application 
2023-02-17 06:12:26.509 39 ERROR keystone.server.flask.application [None req-06799001-b86b-4a7a-9baa-3219d171959c 716d238b4ce449dd9f65ebb57f427216 - - all default -] Could not find project: service.: keystone.exception.ProjectNotFound: Could not find project: service.
2023-02-17 06:12:26.509 39 ERROR keystone.server.flask.application Traceback (most recent call last):
2023-02-17 06:12:26.509 39 ERROR keystone.server.flask.application   File "/var/lib/kolla/venv/lib/python3.9/site-packages/flask/app.py", line 1820, in full_dispatch_request
2023-02-17 06:12:26.509 39 ERROR keystone.server.flask.application     rv = self.dispatch_request()
2023-02-17 06:12:26.509 39 ERROR keystone.server.flask.application   File "/var/lib/kolla/venv/lib/python3.9/site-packages/flask/app.py", line 1796, in dispatch_request
2023-02-17 06:12:26.509 39 ERROR keystone.server.flask.application     return self.ensure_sync(self.view_functions[rule.endpoint])(**view_args)
2023-02-17 06:12:26.509 39 ERROR keystone.server.flask.application   File "/var/lib/kolla/venv/lib/python3.9/site-packages/flask_restful/__init__.py", line 467, in wrapper
2023-02-17 06:12:26.509 39 ERROR keystone.server.flask.application     resp = resource(*args, **kwargs)
2023-02-17 06:12:26.509 39 ERROR keystone.server.flask.application   File "/var/lib/kolla/venv/lib/python3.9/site-packages/flask/views.py", line 107, in view
2023-02-17 06:12:26.509 39 ERROR keystone.server.flask.application     return current_app.ensure_sync(self.dispatch_request)(**kwargs)
2023-02-17 06:12:26.509 39 ERROR keystone.server.flask.application   File "/var/lib/kolla/venv/lib/python3.9/site-packages/flask_restful/__init__.py", line 582, in dispatch_request
2023-02-17 06:12:26.509 39 ERROR keystone.server.flask.application     resp = meth(*args, **kwargs)
2023-02-17 06:12:26.509 39 ERROR keystone.server.flask.application   File "/var/lib/kolla/venv/lib/python3.9/site-packages/keystone/api/projects.py", line 151, in get
2023-02-17 06:12:26.509 39 ERROR keystone.server.flask.application     return self._get_project(project_id)
2023-02-17 06:12:26.509 39 ERROR keystone.server.flask.application   File "/var/lib/kolla/venv/lib/python3.9/site-packages/keystone/api/projects.py", line 107, in _get_project
2023-02-17 06:12:26.509 39 ERROR keystone.server.flask.application     project = PROVIDERS.resource_api.get_project(project_id)
2023-02-17 06:12:26.509 39 ERROR keystone.server.flask.application   File "/var/lib/kolla/venv/lib/python3.9/site-packages/keystone/common/manager.py", line 115, in wrapped
2023-02-17 06:12:26.509 39 ERROR keystone.server.flask.application     __ret_val = __f(*args, **kwargs)
2023-02-17 06:12:26.509 39 ERROR keystone.server.flask.application   File "/var/lib/kolla/venv/lib/python3.9/site-packages/decorator.py", line 232, in fun
2023-02-17 06:12:26.509 39 ERROR keystone.server.flask.application     return caller(func, *(extras + args), **kw)
2023-02-17 06:12:26.509 39 ERROR keystone.server.flask.application   File "/var/lib/kolla/venv/lib/python3.9/site-packages/dogpile/cache/region.py", line 1577, in get_or_create_for_user_func
2023-02-17 06:12:26.509 39 ERROR keystone.server.flask.application     return self.get_or_create(
2023-02-17 06:12:26.509 39 ERROR keystone.server.flask.application   File "/var/lib/kolla/venv/lib/python3.9/site-packages/dogpile/cache/region.py", line 1042, in get_or_create
2023-02-17 06:12:26.509 39 ERROR keystone.server.flask.application     with Lock(
2023-02-17 06:12:26.509 39 ERROR keystone.server.flask.application   File "/var/lib/kolla/venv/lib/python3.9/site-packages/dogpile/lock.py", line 185, in __enter__
2023-02-17 06:12:26.509 39 ERROR keystone.server.flask.application     return self._enter()
2023-02-17 06:12:26.509 39 ERROR keystone.server.flask.application   File "/var/lib/kolla/venv/lib/python3.9/site-packages/dogpile/lock.py", line 94, in _enter
2023-02-17 06:12:26.509 39 ERROR keystone.server.flask.application     generated = self._enter_create(value, createdtime)
2023-02-17 06:12:26.509 39 ERROR keystone.server.flask.application   File "/var/lib/kolla/venv/lib/python3.9/site-packages/dogpile/lock.py", line 178, in _enter_create
2023-02-17 06:12:26.509 39 ERROR keystone.server.flask.application     return self.creator()
2023-02-17 06:12:26.509 39 ERROR keystone.server.flask.application   File "/var/lib/kolla/venv/lib/python3.9/site-packages/dogpile/cache/region.py", line 995, in gen_value
2023-02-17 06:12:26.509 39 ERROR keystone.server.flask.application     created_value = creator(
2023-02-17 06:12:26.509 39 ERROR keystone.server.flask.application   File "/var/lib/kolla/venv/lib/python3.9/site-packages/keystone/resource/core.py", line 903, in get_project
2023-02-17 06:12:26.509 39 ERROR keystone.server.flask.application     return self.driver.get_project(project_id)
2023-02-17 06:12:26.509 39 ERROR keystone.server.flask.application   File "/var/lib/kolla/venv/lib/python3.9/site-packages/keystone/resource/backends/sql.py", line 49, in get_project
2023-02-17 06:12:26.509 39 ERROR keystone.server.flask.application     return self._get_project(session, project_id).to_dict()
2023-02-17 06:12:26.509 39 ERROR keystone.server.flask.application   File "/var/lib/kolla/venv/lib/python3.9/site-packages/keystone/resource/backends/sql.py", line 44, in _get_project
2023-02-17 06:12:26.509 39 ERROR keystone.server.flask.application     raise exception.ProjectNotFound(project_id=project_id)
2023-02-17 06:12:26.509 39 ERROR keystone.server.flask.application keystone.exception.ProjectNotFound: Could not find project: service.
2023-02-17 06:12:26.509 39 ERROR keystone.server.flask.application 
2023-02-17 06:12:35.568 40 ERROR keystone.server.flask.application [None req-adabf980-872f-4eeb-9ed1-290149f5a935 716d238b4ce449dd9f65ebb57f427216 - - all default -] Could not find role: admin.: keystone.exception.RoleNotFound: Could not find role: admin.
2023-02-17 06:12:35.568 40 ERROR keystone.server.flask.application Traceback (most recent call last):
2023-02-17 06:12:35.568 40 ERROR keystone.server.flask.application   File "/var/lib/kolla/venv/lib/python3.9/site-packages/flask/app.py", line 1820, in full_dispatch_request
2023-02-17 06:12:35.568 40 ERROR keystone.server.flask.application     rv = self.dispatch_request()
2023-02-17 06:12:35.568 40 ERROR keystone.server.flask.application   File "/var/lib/kolla/venv/lib/python3.9/site-packages/flask/app.py", line 1796, in dispatch_request
2023-02-17 06:12:35.568 40 ERROR keystone.server.flask.application     return self.ensure_sync(self.view_functions[rule.endpoint])(**view_args)
2023-02-17 06:12:35.568 40 ERROR keystone.server.flask.application   File "/var/lib/kolla/venv/lib/python3.9/site-packages/flask_restful/__init__.py", line 467, in wrapper
2023-02-17 06:12:35.568 40 ERROR keystone.server.flask.application     resp = resource(*args, **kwargs)
2023-02-17 06:12:35.568 40 ERROR keystone.server.flask.application   File "/var/lib/kolla/venv/lib/python3.9/site-packages/flask/views.py", line 107, in view
2023-02-17 06:12:35.568 40 ERROR keystone.server.flask.application     return current_app.ensure_sync(self.dispatch_request)(**kwargs)
2023-02-17 06:12:35.568 40 ERROR keystone.server.flask.application   File "/var/lib/kolla/venv/lib/python3.9/site-packages/flask_restful/__init__.py", line 582, in dispatch_request
2023-02-17 06:12:35.568 40 ERROR keystone.server.flask.application     resp = meth(*args, **kwargs)
2023-02-17 06:12:35.568 40 ERROR keystone.server.flask.application   File "/var/lib/kolla/venv/lib/python3.9/site-packages/keystone/api/roles.py", line 50, in get
2023-02-17 06:12:35.568 40 ERROR keystone.server.flask.application     return self._get_role(role_id)
2023-02-17 06:12:35.568 40 ERROR keystone.server.flask.application   File "/var/lib/kolla/venv/lib/python3.9/site-packages/keystone/api/roles.py", line 70, in _get_role
2023-02-17 06:12:35.568 40 ERROR keystone.server.flask.application     ENFORCER.enforce_call(action='identity:get_role')
2023-02-17 06:12:35.568 40 ERROR keystone.server.flask.application   File "/var/lib/kolla/venv/lib/python3.9/site-packages/keystone/common/rbac_enforcer/enforcer.py", line 402, in enforce_call
2023-02-17 06:12:35.568 40 ERROR keystone.server.flask.application     policy_dict.update(cls._extract_member_target_data(
2023-02-17 06:12:35.568 40 ERROR keystone.server.flask.application   File "/var/lib/kolla/venv/lib/python3.9/site-packages/keystone/common/rbac_enforcer/enforcer.py", line 234, in _extract_member_target_data
2023-02-17 06:12:35.568 40 ERROR keystone.server.flask.application     member_name: func(flask.request.view_args[key])
2023-02-17 06:12:35.568 40 ERROR keystone.server.flask.application   File "/var/lib/kolla/venv/lib/python3.9/site-packages/keystone/common/manager.py", line 115, in wrapped
2023-02-17 06:12:35.568 40 ERROR keystone.server.flask.application     __ret_val = __f(*args, **kwargs)
2023-02-17 06:12:35.568 40 ERROR keystone.server.flask.application   File "/var/lib/kolla/venv/lib/python3.9/site-packages/decorator.py", line 232, in fun
2023-02-17 06:12:35.568 40 ERROR keystone.server.flask.application     return caller(func, *(extras + args), **kw)
2023-02-17 06:12:35.568 40 ERROR keystone.server.flask.application   File "/var/lib/kolla/venv/lib/python3.9/site-packages/dogpile/cache/region.py", line 1577, in get_or_create_for_user_func
2023-02-17 06:12:35.568 40 ERROR keystone.server.flask.application     return self.get_or_create(
2023-02-17 06:12:35.568 40 ERROR keystone.server.flask.application   File "/var/lib/kolla/venv/lib/python3.9/site-packages/dogpile/cache/region.py", line 1042, in get_or_create
2023-02-17 06:12:35.568 40 ERROR keystone.server.flask.application     with Lock(
2023-02-17 06:12:35.568 40 ERROR keystone.server.flask.application   File "/var/lib/kolla/venv/lib/python3.9/site-packages/dogpile/lock.py", line 185, in __enter__
2023-02-17 06:12:35.568 40 ERROR keystone.server.flask.application     return self._enter()
2023-02-17 06:12:35.568 40 ERROR keystone.server.flask.application   File "/var/lib/kolla/venv/lib/python3.9/site-packages/dogpile/lock.py", line 94, in _enter
2023-02-17 06:12:35.568 40 ERROR keystone.server.flask.application     generated = self._enter_create(value, createdtime)
2023-02-17 06:12:35.568 40 ERROR keystone.server.flask.application   File "/var/lib/kolla/venv/lib/python3.9/site-packages/dogpile/lock.py", line 178, in _enter_create
2023-02-17 06:12:35.568 40 ERROR keystone.server.flask.application     return self.creator()
2023-02-17 06:12:35.568 40 ERROR keystone.server.flask.application   File "/var/lib/kolla/venv/lib/python3.9/site-packages/dogpile/cache/region.py", line 995, in gen_value
2023-02-17 06:12:35.568 40 ERROR keystone.server.flask.application     created_value = creator(
2023-02-17 06:12:35.568 40 ERROR keystone.server.flask.application   File "/var/lib/kolla/venv/lib/python3.9/site-packages/keystone/assignment/core.py", line 1276, in get_role
2023-02-17 06:12:35.568 40 ERROR keystone.server.flask.application     return self.driver.get_role(role_id)
2023-02-17 06:12:35.568 40 ERROR keystone.server.flask.application   File "/var/lib/kolla/venv/lib/python3.9/site-packages/keystone/assignment/role_backends/sql.py", line 70, in get_role
2023-02-17 06:12:35.568 40 ERROR keystone.server.flask.application     return self._get_role(session, role_id).to_dict()
2023-02-17 06:12:35.568 40 ERROR keystone.server.flask.application   File "/var/lib/kolla/venv/lib/python3.9/site-packages/keystone/assignment/role_backends/sql.py", line 65, in _get_role
2023-02-17 06:12:35.568 40 ERROR keystone.server.flask.application     raise exception.RoleNotFound(role_id=role_id)
2023-02-17 06:12:35.568 40 ERROR keystone.server.flask.application keystone.exception.RoleNotFound: Could not find role: admin.
2023-02-17 06:12:35.568 40 ERROR keystone.server.flask.application 
2023-02-17 06:12:36.874 40 ERROR keystone.server.flask.application [None req-ea54db0c-06de-4cbd-90a1-997c8d3f1f25 716d238b4ce449dd9f65ebb57f427216 - - all default -] Could not find user: ironic-inspector.: keystone.exception.UserNotFound: Could not find user: ironic-inspector.
2023-02-17 06:12:36.874 40 ERROR keystone.server.flask.application Traceback (most recent call last):
2023-02-17 06:12:36.874 40 ERROR keystone.server.flask.application   File "/var/lib/kolla/venv/lib/python3.9/site-packages/flask/app.py", line 1820, in full_dispatch_request
2023-02-17 06:12:36.874 40 ERROR keystone.server.flask.application     rv = self.dispatch_request()
2023-02-17 06:12:36.874 40 ERROR keystone.server.flask.application   File "/var/lib/kolla/venv/lib/python3.9/site-packages/flask/app.py", line 1796, in dispatch_request
2023-02-17 06:12:36.874 40 ERROR keystone.server.flask.application     return self.ensure_sync(self.view_functions[rule.endpoint])(**view_args)
2023-02-17 06:12:36.874 40 ERROR keystone.server.flask.application   File "/var/lib/kolla/venv/lib/python3.9/site-packages/flask_restful/__init__.py", line 467, in wrapper
2023-02-17 06:12:36.874 40 ERROR keystone.server.flask.application     resp = resource(*args, **kwargs)
2023-02-17 06:12:36.874 40 ERROR keystone.server.flask.application   File "/var/lib/kolla/venv/lib/python3.9/site-packages/flask/views.py", line 107, in view
2023-02-17 06:12:36.874 40 ERROR keystone.server.flask.application     return current_app.ensure_sync(self.dispatch_request)(**kwargs)
2023-02-17 06:12:36.874 40 ERROR keystone.server.flask.application   File "/var/lib/kolla/venv/lib/python3.9/site-packages/flask_restful/__init__.py", line 582, in dispatch_request
2023-02-17 06:12:36.874 40 ERROR keystone.server.flask.application     resp = meth(*args, **kwargs)
2023-02-17 06:12:36.874 40 ERROR keystone.server.flask.application   File "/var/lib/kolla/venv/lib/python3.9/site-packages/keystone/api/users.py", line 182, in get
2023-02-17 06:12:36.874 40 ERROR keystone.server.flask.application     return self._get_user(user_id)
2023-02-17 06:12:36.874 40 ERROR keystone.server.flask.application   File "/var/lib/kolla/venv/lib/python3.9/site-packages/keystone/api/users.py", line 194, in _get_user
2023-02-17 06:12:36.874 40 ERROR keystone.server.flask.application     ref = PROVIDERS.identity_api.get_user(user_id)
2023-02-17 06:12:36.874 40 ERROR keystone.server.flask.application   File "/var/lib/kolla/venv/lib/python3.9/site-packages/keystone/common/manager.py", line 115, in wrapped
2023-02-17 06:12:36.874 40 ERROR keystone.server.flask.application     __ret_val = __f(*args, **kwargs)
2023-02-17 06:12:36.874 40 ERROR keystone.server.flask.application   File "/var/lib/kolla/venv/lib/python3.9/site-packages/keystone/identity/core.py", line 414, in wrapper
2023-02-17 06:12:36.874 40 ERROR keystone.server.flask.application     return f(self, *args, **kwargs)
2023-02-17 06:12:36.874 40 ERROR keystone.server.flask.application   File "/var/lib/kolla/venv/lib/python3.9/site-packages/keystone/identity/core.py", line 424, in wrapper
2023-02-17 06:12:36.874 40 ERROR keystone.server.flask.application     return f(self, *args, **kwargs)
2023-02-17 06:12:36.874 40 ERROR keystone.server.flask.application   File "/var/lib/kolla/venv/lib/python3.9/site-packages/decorator.py", line 232, in fun
2023-02-17 06:12:36.874 40 ERROR keystone.server.flask.application     return caller(func, *(extras + args), **kw)
2023-02-17 06:12:36.874 40 ERROR keystone.server.flask.application   File "/var/lib/kolla/venv/lib/python3.9/site-packages/dogpile/cache/region.py", line 1577, in get_or_create_for_user_func
2023-02-17 06:12:36.874 40 ERROR keystone.server.flask.application     return self.get_or_create(
2023-02-17 06:12:36.874 40 ERROR keystone.server.flask.application   File "/var/lib/kolla/venv/lib/python3.9/site-packages/dogpile/cache/region.py", line 1042, in get_or_create
2023-02-17 06:12:36.874 40 ERROR keystone.server.flask.application     with Lock(
2023-02-17 06:12:36.874 40 ERROR keystone.server.flask.application   File "/var/lib/kolla/venv/lib/python3.9/site-packages/dogpile/lock.py", line 185, in __enter__
2023-02-17 06:12:36.874 40 ERROR keystone.server.flask.application     return self._enter()
2023-02-17 06:12:36.874 40 ERROR keystone.server.flask.application   File "/var/lib/kolla/venv/lib/python3.9/site-packages/dogpile/lock.py", line 94, in _enter
2023-02-17 06:12:36.874 40 ERROR keystone.server.flask.application     generated = self._enter_create(value, createdtime)
2023-02-17 06:12:36.874 40 ERROR keystone.server.flask.application   File "/var/lib/kolla/venv/lib/python3.9/site-packages/dogpile/lock.py", line 178, in _enter_create
2023-02-17 06:12:36.874 40 ERROR keystone.server.flask.application     return self.creator()
2023-02-17 06:12:36.874 40 ERROR keystone.server.flask.application   File "/var/lib/kolla/venv/lib/python3.9/site-packages/dogpile/cache/region.py", line 995, in gen_value
2023-02-17 06:12:36.874 40 ERROR keystone.server.flask.application     created_value = creator(
2023-02-17 06:12:36.874 40 ERROR keystone.server.flask.application   File "/var/lib/kolla/venv/lib/python3.9/site-packages/keystone/identity/core.py", line 1011, in get_user
2023-02-17 06:12:36.874 40 ERROR keystone.server.flask.application     ref = driver.get_user(entity_id)
2023-02-17 06:12:36.874 40 ERROR keystone.server.flask.application   File "/var/lib/kolla/venv/lib/python3.9/site-packages/keystone/identity/backends/sql.py", line 200, in get_user
2023-02-17 06:12:36.874 40 ERROR keystone.server.flask.application     self._get_user(session, user_id).to_dict())
2023-02-17 06:12:36.874 40 ERROR keystone.server.flask.application   File "/var/lib/kolla/venv/lib/python3.9/site-packages/keystone/identity/backends/sql.py", line 194, in _get_user
2023-02-17 06:12:36.874 40 ERROR keystone.server.flask.application     raise exception.UserNotFound(user_id=user_id)
2023-02-17 06:12:36.874 40 ERROR keystone.server.flask.application keystone.exception.UserNotFound: Could not find user: ironic-inspector.
2023-02-17 06:12:36.874 40 ERROR keystone.server.flask.application 
2023-02-17 06:12:37.610 38 ERROR keystone.server.flask.application [None req-badbbfef-49c1-49ff-bc24-a963d2beae2d 716d238b4ce449dd9f65ebb57f427216 - - all default -] Could not find project: service.: keystone.exception.ProjectNotFound: Could not find project: service.
2023-02-17 06:12:37.610 38 ERROR keystone.server.flask.application Traceback (most recent call last):
2023-02-17 06:12:37.610 38 ERROR keystone.server.flask.application   File "/var/lib/kolla/venv/lib/python3.9/site-packages/flask/app.py", line 1820, in full_dispatch_request
2023-02-17 06:12:37.610 38 ERROR keystone.server.flask.application     rv = self.dispatch_request()
2023-02-17 06:12:37.610 38 ERROR keystone.server.flask.application   File "/var/lib/kolla/venv/lib/python3.9/site-packages/flask/app.py", line 1796, in dispatch_request
2023-02-17 06:12:37.610 38 ERROR keystone.server.flask.application     return self.ensure_sync(self.view_functions[rule.endpoint])(**view_args)
2023-02-17 06:12:37.610 38 ERROR keystone.server.flask.application   File "/var/lib/kolla/venv/lib/python3.9/site-packages/flask_restful/__init__.py", line 467, in wrapper
2023-02-17 06:12:37.610 38 ERROR keystone.server.flask.application     resp = resource(*args, **kwargs)
2023-02-17 06:12:37.610 38 ERROR keystone.server.flask.application   File "/var/lib/kolla/venv/lib/python3.9/site-packages/flask/views.py", line 107, in view
2023-02-17 06:12:37.610 38 ERROR keystone.server.flask.application     return current_app.ensure_sync(self.dispatch_request)(**kwargs)
2023-02-17 06:12:37.610 38 ERROR keystone.server.flask.application   File "/var/lib/kolla/venv/lib/python3.9/site-packages/flask_restful/__init__.py", line 582, in dispatch_request
2023-02-17 06:12:37.610 38 ERROR keystone.server.flask.application     resp = meth(*args, **kwargs)
2023-02-17 06:12:37.610 38 ERROR keystone.server.flask.application   File "/var/lib/kolla/venv/lib/python3.9/site-packages/keystone/api/projects.py", line 151, in get
2023-02-17 06:12:37.610 38 ERROR keystone.server.flask.application     return self._get_project(project_id)
2023-02-17 06:12:37.610 38 ERROR keystone.server.flask.application   File "/var/lib/kolla/venv/lib/python3.9/site-packages/keystone/api/projects.py", line 107, in _get_project
2023-02-17 06:12:37.610 38 ERROR keystone.server.flask.application     project = PROVIDERS.resource_api.get_project(project_id)
2023-02-17 06:12:37.610 38 ERROR keystone.server.flask.application   File "/var/lib/kolla/venv/lib/python3.9/site-packages/keystone/common/manager.py", line 115, in wrapped
2023-02-17 06:12:37.610 38 ERROR keystone.server.flask.application     __ret_val = __f(*args, **kwargs)
2023-02-17 06:12:37.610 38 ERROR keystone.server.flask.application   File "/var/lib/kolla/venv/lib/python3.9/site-packages/decorator.py", line 232, in fun
2023-02-17 06:12:37.610 38 ERROR keystone.server.flask.application     return caller(func, *(extras + args), **kw)
2023-02-17 06:12:37.610 38 ERROR keystone.server.flask.application   File "/var/lib/kolla/venv/lib/python3.9/site-packages/dogpile/cache/region.py", line 1577, in get_or_create_for_user_func
2023-02-17 06:12:37.610 38 ERROR keystone.server.flask.application     return self.get_or_create(
2023-02-17 06:12:37.610 38 ERROR keystone.server.flask.application   File "/var/lib/kolla/venv/lib/python3.9/site-packages/dogpile/cache/region.py", line 1042, in get_or_create
2023-02-17 06:12:37.610 38 ERROR keystone.server.flask.application     with Lock(
2023-02-17 06:12:37.610 38 ERROR keystone.server.flask.application   File "/var/lib/kolla/venv/lib/python3.9/site-packages/dogpile/lock.py", line 185, in __enter__
2023-02-17 06:12:37.610 38 ERROR keystone.server.flask.application     return self._enter()
2023-02-17 06:12:37.610 38 ERROR keystone.server.flask.application   File "/var/lib/kolla/venv/lib/python3.9/site-packages/dogpile/lock.py", line 94, in _enter
2023-02-17 06:12:37.610 38 ERROR keystone.server.flask.application     generated = self._enter_create(value, createdtime)
2023-02-17 06:12:37.610 38 ERROR keystone.server.flask.application   File "/var/lib/kolla/venv/lib/python3.9/site-packages/dogpile/lock.py", line 178, in _enter_create
2023-02-17 06:12:37.610 38 ERROR keystone.server.flask.application     return self.creator()
2023-02-17 06:12:37.610 38 ERROR keystone.server.flask.application   File "/var/lib/kolla/venv/lib/python3.9/site-packages/dogpile/cache/region.py", line 995, in gen_value
2023-02-17 06:12:37.610 38 ERROR keystone.server.flask.application     created_value = creator(
2023-02-17 06:12:37.610 38 ERROR keystone.server.flask.application   File "/var/lib/kolla/venv/lib/python3.9/site-packages/keystone/resource/core.py", line 903, in get_project
2023-02-17 06:12:37.610 38 ERROR keystone.server.flask.application     return self.driver.get_project(project_id)
2023-02-17 06:12:37.610 38 ERROR keystone.server.flask.application   File "/var/lib/kolla/venv/lib/python3.9/site-packages/keystone/resource/backends/sql.py", line 49, in get_project
2023-02-17 06:12:37.610 38 ERROR keystone.server.flask.application     return self._get_project(session, project_id).to_dict()
2023-02-17 06:12:37.610 38 ERROR keystone.server.flask.application   File "/var/lib/kolla/venv/lib/python3.9/site-packages/keystone/resource/backends/sql.py", line 44, in _get_project
2023-02-17 06:12:37.610 38 ERROR keystone.server.flask.application     raise exception.ProjectNotFound(project_id=project_id)
2023-02-17 06:12:37.610 38 ERROR keystone.server.flask.application keystone.exception.ProjectNotFound: Could not find project: service.
2023-02-17 06:12:37.610 38 ERROR keystone.server.flask.application 
2023-02-17 06:15:24.801 38 ERROR keystone.server.flask.application [None req-11c1f1a4-0131-4bec-ba93-b8261ec5d929 716d238b4ce449dd9f65ebb57f427216 - - all default -] Could not find project: service.: keystone.exception.ProjectNotFound: Could not find project: service.
2023-02-17 06:15:24.801 38 ERROR keystone.server.flask.application Traceback (most recent call last):
2023-02-17 06:15:24.801 38 ERROR keystone.server.flask.application   File "/var/lib/kolla/venv/lib/python3.9/site-packages/flask/app.py", line 1820, in full_dispatch_request
2023-02-17 06:15:24.801 38 ERROR keystone.server.flask.application     rv = self.dispatch_request()
2023-02-17 06:15:24.801 38 ERROR keystone.server.flask.application   File "/var/lib/kolla/venv/lib/python3.9/site-packages/flask/app.py", line 1796, in dispatch_request
2023-02-17 06:15:24.801 38 ERROR keystone.server.flask.application     return self.ensure_sync(self.view_functions[rule.endpoint])(**view_args)
2023-02-17 06:15:24.801 38 ERROR keystone.server.flask.application   File "/var/lib/kolla/venv/lib/python3.9/site-packages/flask_restful/__init__.py", line 467, in wrapper
2023-02-17 06:15:24.801 38 ERROR keystone.server.flask.application     resp = resource(*args, **kwargs)
2023-02-17 06:15:24.801 38 ERROR keystone.server.flask.application   File "/var/lib/kolla/venv/lib/python3.9/site-packages/flask/views.py", line 107, in view
2023-02-17 06:15:24.801 38 ERROR keystone.server.flask.application     return current_app.ensure_sync(self.dispatch_request)(**kwargs)
2023-02-17 06:15:24.801 38 ERROR keystone.server.flask.application   File "/var/lib/kolla/venv/lib/python3.9/site-packages/flask_restful/__init__.py", line 582, in dispatch_request
2023-02-17 06:15:24.801 38 ERROR keystone.server.flask.application     resp = meth(*args, **kwargs)
2023-02-17 06:15:24.801 38 ERROR keystone.server.flask.application   File "/var/lib/kolla/venv/lib/python3.9/site-packages/keystone/api/projects.py", line 151, in get
2023-02-17 06:15:24.801 38 ERROR keystone.server.flask.application     return self._get_project(project_id)
2023-02-17 06:15:24.801 38 ERROR keystone.server.flask.application   File "/var/lib/kolla/venv/lib/python3.9/site-packages/keystone/api/projects.py", line 107, in _get_project
2023-02-17 06:15:24.801 38 ERROR keystone.server.flask.application     project = PROVIDERS.resource_api.get_project(project_id)
2023-02-17 06:15:24.801 38 ERROR keystone.server.flask.application   File "/var/lib/kolla/venv/lib/python3.9/site-packages/keystone/common/manager.py", line 115, in wrapped
2023-02-17 06:15:24.801 38 ERROR keystone.server.flask.application     __ret_val = __f(*args, **kwargs)
2023-02-17 06:15:24.801 38 ERROR keystone.server.flask.application   File "/var/lib/kolla/venv/lib/python3.9/site-packages/decorator.py", line 232, in fun
2023-02-17 06:15:24.801 38 ERROR keystone.server.flask.application     return caller(func, *(extras + args), **kw)
2023-02-17 06:15:24.801 38 ERROR keystone.server.flask.application   File "/var/lib/kolla/venv/lib/python3.9/site-packages/dogpile/cache/region.py", line 1577, in get_or_create_for_user_func
2023-02-17 06:15:24.801 38 ERROR keystone.server.flask.application     return self.get_or_create(
2023-02-17 06:15:24.801 38 ERROR keystone.server.flask.application   File "/var/lib/kolla/venv/lib/python3.9/site-packages/dogpile/cache/region.py", line 1042, in get_or_create
2023-02-17 06:15:24.801 38 ERROR keystone.server.flask.application     with Lock(
2023-02-17 06:15:24.801 38 ERROR keystone.server.flask.application   File "/var/lib/kolla/venv/lib/python3.9/site-packages/dogpile/lock.py", line 185, in __enter__
2023-02-17 06:15:24.801 38 ERROR keystone.server.flask.application     return self._enter()
2023-02-17 06:15:24.801 38 ERROR keystone.server.flask.application   File "/var/lib/kolla/venv/lib/python3.9/site-packages/dogpile/lock.py", line 94, in _enter
2023-02-17 06:15:24.801 38 ERROR keystone.server.flask.application     generated = self._enter_create(value, createdtime)
2023-02-17 06:15:24.801 38 ERROR keystone.server.flask.application   File "/var/lib/kolla/venv/lib/python3.9/site-packages/dogpile/lock.py", line 178, in _enter_create
2023-02-17 06:15:24.801 38 ERROR keystone.server.flask.application     return self.creator()
2023-02-17 06:15:24.801 38 ERROR keystone.server.flask.application   File "/var/lib/kolla/venv/lib/python3.9/site-packages/dogpile/cache/region.py", line 995, in gen_value
2023-02-17 06:15:24.801 38 ERROR keystone.server.flask.application     created_value = creator(
2023-02-17 06:15:24.801 38 ERROR keystone.server.flask.application   File "/var/lib/kolla/venv/lib/python3.9/site-packages/keystone/resource/core.py", line 903, in get_project
2023-02-17 06:15:24.801 38 ERROR keystone.server.flask.application     return self.driver.get_project(project_id)
2023-02-17 06:15:24.801 38 ERROR keystone.server.flask.application   File "/var/lib/kolla/venv/lib/python3.9/site-packages/keystone/resource/backends/sql.py", line 49, in get_project
2023-02-17 06:15:24.801 38 ERROR keystone.server.flask.application     return self._get_project(session, project_id).to_dict()
2023-02-17 06:15:24.801 38 ERROR keystone.server.flask.application   File "/var/lib/kolla/venv/lib/python3.9/site-packages/keystone/resource/backends/sql.py", line 44, in _get_project
2023-02-17 06:15:24.801 38 ERROR keystone.server.flask.application     raise exception.ProjectNotFound(project_id=project_id)
2023-02-17 06:15:24.801 38 ERROR keystone.server.flask.application keystone.exception.ProjectNotFound: Could not find project: service.
2023-02-17 06:15:24.801 38 ERROR keystone.server.flask.application 
2023-02-17 06:15:39.574 40 ERROR keystone.server.flask.application [None req-74b1bb7b-46d9-4304-990c-4818dd862d9b 716d238b4ce449dd9f65ebb57f427216 - - all default -] Could not find role: admin.: keystone.exception.RoleNotFound: Could not find role: admin.
2023-02-17 06:15:39.574 40 ERROR keystone.server.flask.application Traceback (most recent call last):
2023-02-17 06:15:39.574 40 ERROR keystone.server.flask.application   File "/var/lib/kolla/venv/lib/python3.9/site-packages/flask/app.py", line 1820, in full_dispatch_request
2023-02-17 06:15:39.574 40 ERROR keystone.server.flask.application     rv = self.dispatch_request()
2023-02-17 06:15:39.574 40 ERROR keystone.server.flask.application   File "/var/lib/kolla/venv/lib/python3.9/site-packages/flask/app.py", line 1796, in dispatch_request
2023-02-17 06:15:39.574 40 ERROR keystone.server.flask.application     return self.ensure_sync(self.view_functions[rule.endpoint])(**view_args)
2023-02-17 06:15:39.574 40 ERROR keystone.server.flask.application   File "/var/lib/kolla/venv/lib/python3.9/site-packages/flask_restful/__init__.py", line 467, in wrapper
2023-02-17 06:15:39.574 40 ERROR keystone.server.flask.application     resp = resource(*args, **kwargs)
2023-02-17 06:15:39.574 40 ERROR keystone.server.flask.application   File "/var/lib/kolla/venv/lib/python3.9/site-packages/flask/views.py", line 107, in view
2023-02-17 06:15:39.574 40 ERROR keystone.server.flask.application     return current_app.ensure_sync(self.dispatch_request)(**kwargs)
2023-02-17 06:15:39.574 40 ERROR keystone.server.flask.application   File "/var/lib/kolla/venv/lib/python3.9/site-packages/flask_restful/__init__.py", line 582, in dispatch_request
2023-02-17 06:15:39.574 40 ERROR keystone.server.flask.application     resp = meth(*args, **kwargs)
2023-02-17 06:15:39.574 40 ERROR keystone.server.flask.application   File "/var/lib/kolla/venv/lib/python3.9/site-packages/keystone/api/roles.py", line 50, in get
2023-02-17 06:15:39.574 40 ERROR keystone.server.flask.application     return self._get_role(role_id)
2023-02-17 06:15:39.574 40 ERROR keystone.server.flask.application   File "/var/lib/kolla/venv/lib/python3.9/site-packages/keystone/api/roles.py", line 70, in _get_role
2023-02-17 06:15:39.574 40 ERROR keystone.server.flask.application     ENFORCER.enforce_call(action='identity:get_role')
2023-02-17 06:15:39.574 40 ERROR keystone.server.flask.application   File "/var/lib/kolla/venv/lib/python3.9/site-packages/keystone/common/rbac_enforcer/enforcer.py", line 402, in enforce_call
2023-02-17 06:15:39.574 40 ERROR keystone.server.flask.application     policy_dict.update(cls._extract_member_target_data(
2023-02-17 06:15:39.574 40 ERROR keystone.server.flask.application   File "/var/lib/kolla/venv/lib/python3.9/site-packages/keystone/common/rbac_enforcer/enforcer.py", line 234, in _extract_member_target_data
2023-02-17 06:15:39.574 40 ERROR keystone.server.flask.application     member_name: func(flask.request.view_args[key])
2023-02-17 06:15:39.574 40 ERROR keystone.server.flask.application   File "/var/lib/kolla/venv/lib/python3.9/site-packages/keystone/common/manager.py", line 115, in wrapped
2023-02-17 06:15:39.574 40 ERROR keystone.server.flask.application     __ret_val = __f(*args, **kwargs)
2023-02-17 06:15:39.574 40 ERROR keystone.server.flask.application   File "/var/lib/kolla/venv/lib/python3.9/site-packages/decorator.py", line 232, in fun
2023-02-17 06:15:39.574 40 ERROR keystone.server.flask.application     return caller(func, *(extras + args), **kw)
2023-02-17 06:15:39.574 40 ERROR keystone.server.flask.application   File "/var/lib/kolla/venv/lib/python3.9/site-packages/dogpile/cache/region.py", line 1577, in get_or_create_for_user_func
2023-02-17 06:15:39.574 40 ERROR keystone.server.flask.application     return self.get_or_create(
2023-02-17 06:15:39.574 40 ERROR keystone.server.flask.application   File "/var/lib/kolla/venv/lib/python3.9/site-packages/dogpile/cache/region.py", line 1042, in get_or_create
2023-02-17 06:15:39.574 40 ERROR keystone.server.flask.application     with Lock(
2023-02-17 06:15:39.574 40 ERROR keystone.server.flask.application   File "/var/lib/kolla/venv/lib/python3.9/site-packages/dogpile/lock.py", line 185, in __enter__
2023-02-17 06:15:39.574 40 ERROR keystone.server.flask.application     return self._enter()
2023-02-17 06:15:39.574 40 ERROR keystone.server.flask.application   File "/var/lib/kolla/venv/lib/python3.9/site-packages/dogpile/lock.py", line 94, in _enter
2023-02-17 06:15:39.574 40 ERROR keystone.server.flask.application     generated = self._enter_create(value, createdtime)
2023-02-17 06:15:39.574 40 ERROR keystone.server.flask.application   File "/var/lib/kolla/venv/lib/python3.9/site-packages/dogpile/lock.py", line 178, in _enter_create
2023-02-17 06:15:39.574 40 ERROR keystone.server.flask.application     return self.creator()
2023-02-17 06:15:39.574 40 ERROR keystone.server.flask.application   File "/var/lib/kolla/venv/lib/python3.9/site-packages/dogpile/cache/region.py", line 995, in gen_value
2023-02-17 06:15:39.574 40 ERROR keystone.server.flask.application     created_value = creator(
2023-02-17 06:15:39.574 40 ERROR keystone.server.flask.application   File "/var/lib/kolla/venv/lib/python3.9/site-packages/keystone/assignment/core.py", line 1276, in get_role
2023-02-17 06:15:39.574 40 ERROR keystone.server.flask.application     return self.driver.get_role(role_id)
2023-02-17 06:15:39.574 40 ERROR keystone.server.flask.application   File "/var/lib/kolla/venv/lib/python3.9/site-packages/keystone/assignment/role_backends/sql.py", line 70, in get_role
2023-02-17 06:15:39.574 40 ERROR keystone.server.flask.application     return self._get_role(session, role_id).to_dict()
2023-02-17 06:15:39.574 40 ERROR keystone.server.flask.application   File "/var/lib/kolla/venv/lib/python3.9/site-packages/keystone/assignment/role_backends/sql.py", line 65, in _get_role
2023-02-17 06:15:39.574 40 ERROR keystone.server.flask.application     raise exception.RoleNotFound(role_id=role_id)
2023-02-17 06:15:39.574 40 ERROR keystone.server.flask.application keystone.exception.RoleNotFound: Could not find role: admin.
2023-02-17 06:15:39.574 40 ERROR keystone.server.flask.application 
2023-02-17 06:15:40.620 40 ERROR keystone.server.flask.application [None req-4eb9274d-b51e-48e1-9349-ce946b7efe43 716d238b4ce449dd9f65ebb57f427216 - - all default -] Could not find user: neutron.: keystone.exception.UserNotFound: Could not find user: neutron.
2023-02-17 06:15:40.620 40 ERROR keystone.server.flask.application Traceback (most recent call last):
2023-02-17 06:15:40.620 40 ERROR keystone.server.flask.application   File "/var/lib/kolla/venv/lib/python3.9/site-packages/flask/app.py", line 1820, in full_dispatch_request
2023-02-17 06:15:40.620 40 ERROR keystone.server.flask.application     rv = self.dispatch_request()
2023-02-17 06:15:40.620 40 ERROR keystone.server.flask.application   File "/var/lib/kolla/venv/lib/python3.9/site-packages/flask/app.py", line 1796, in dispatch_request
2023-02-17 06:15:40.620 40 ERROR keystone.server.flask.application     return self.ensure_sync(self.view_functions[rule.endpoint])(**view_args)
2023-02-17 06:15:40.620 40 ERROR keystone.server.flask.application   File "/var/lib/kolla/venv/lib/python3.9/site-packages/flask_restful/__init__.py", line 467, in wrapper
2023-02-17 06:15:40.620 40 ERROR keystone.server.flask.application     resp = resource(*args, **kwargs)
2023-02-17 06:15:40.620 40 ERROR keystone.server.flask.application   File "/var/lib/kolla/venv/lib/python3.9/site-packages/flask/views.py", line 107, in view
2023-02-17 06:15:40.620 40 ERROR keystone.server.flask.application     return current_app.ensure_sync(self.dispatch_request)(**kwargs)
2023-02-17 06:15:40.620 40 ERROR keystone.server.flask.application   File "/var/lib/kolla/venv/lib/python3.9/site-packages/flask_restful/__init__.py", line 582, in dispatch_request
2023-02-17 06:15:40.620 40 ERROR keystone.server.flask.application     resp = meth(*args, **kwargs)
2023-02-17 06:15:40.620 40 ERROR keystone.server.flask.application   File "/var/lib/kolla/venv/lib/python3.9/site-packages/keystone/api/users.py", line 182, in get
2023-02-17 06:15:40.620 40 ERROR keystone.server.flask.application     return self._get_user(user_id)
2023-02-17 06:15:40.620 40 ERROR keystone.server.flask.application   File "/var/lib/kolla/venv/lib/python3.9/site-packages/keystone/api/users.py", line 194, in _get_user
2023-02-17 06:15:40.620 40 ERROR keystone.server.flask.application     ref = PROVIDERS.identity_api.get_user(user_id)
2023-02-17 06:15:40.620 40 ERROR keystone.server.flask.application   File "/var/lib/kolla/venv/lib/python3.9/site-packages/keystone/common/manager.py", line 115, in wrapped
2023-02-17 06:15:40.620 40 ERROR keystone.server.flask.application     __ret_val = __f(*args, **kwargs)
2023-02-17 06:15:40.620 40 ERROR keystone.server.flask.application   File "/var/lib/kolla/venv/lib/python3.9/site-packages/keystone/identity/core.py", line 414, in wrapper
2023-02-17 06:15:40.620 40 ERROR keystone.server.flask.application     return f(self, *args, **kwargs)
2023-02-17 06:15:40.620 40 ERROR keystone.server.flask.application   File "/var/lib/kolla/venv/lib/python3.9/site-packages/keystone/identity/core.py", line 424, in wrapper
2023-02-17 06:15:40.620 40 ERROR keystone.server.flask.application     return f(self, *args, **kwargs)
2023-02-17 06:15:40.620 40 ERROR keystone.server.flask.application   File "/var/lib/kolla/venv/lib/python3.9/site-packages/decorator.py", line 232, in fun
2023-02-17 06:15:40.620 40 ERROR keystone.server.flask.application     return caller(func, *(extras + args), **kw)
2023-02-17 06:15:40.620 40 ERROR keystone.server.flask.application   File "/var/lib/kolla/venv/lib/python3.9/site-packages/dogpile/cache/region.py", line 1577, in get_or_create_for_user_func
2023-02-17 06:15:40.620 40 ERROR keystone.server.flask.application     return self.get_or_create(
2023-02-17 06:15:40.620 40 ERROR keystone.server.flask.application   File "/var/lib/kolla/venv/lib/python3.9/site-packages/dogpile/cache/region.py", line 1042, in get_or_create
2023-02-17 06:15:40.620 40 ERROR keystone.server.flask.application     with Lock(
2023-02-17 06:15:40.620 40 ERROR keystone.server.flask.application   File "/var/lib/kolla/venv/lib/python3.9/site-packages/dogpile/lock.py", line 185, in __enter__
2023-02-17 06:15:40.620 40 ERROR keystone.server.flask.application     return self._enter()
2023-02-17 06:15:40.620 40 ERROR keystone.server.flask.application   File "/var/lib/kolla/venv/lib/python3.9/site-packages/dogpile/lock.py", line 94, in _enter
2023-02-17 06:15:40.620 40 ERROR keystone.server.flask.application     generated = self._enter_create(value, createdtime)
2023-02-17 06:15:40.620 40 ERROR keystone.server.flask.application   File "/var/lib/kolla/venv/lib/python3.9/site-packages/dogpile/lock.py", line 178, in _enter_create
2023-02-17 06:15:40.620 40 ERROR keystone.server.flask.application     return self.creator()
2023-02-17 06:15:40.620 40 ERROR keystone.server.flask.application   File "/var/lib/kolla/venv/lib/python3.9/site-packages/dogpile/cache/region.py", line 995, in gen_value
2023-02-17 06:15:40.620 40 ERROR keystone.server.flask.application     created_value = creator(
2023-02-17 06:15:40.620 40 ERROR keystone.server.flask.application   File "/var/lib/kolla/venv/lib/python3.9/site-packages/keystone/identity/core.py", line 1011, in get_user
2023-02-17 06:15:40.620 40 ERROR keystone.server.flask.application     ref = driver.get_user(entity_id)
2023-02-17 06:15:40.620 40 ERROR keystone.server.flask.application   File "/var/lib/kolla/venv/lib/python3.9/site-packages/keystone/identity/backends/sql.py", line 200, in get_user
2023-02-17 06:15:40.620 40 ERROR keystone.server.flask.application     self._get_user(session, user_id).to_dict())
2023-02-17 06:15:40.620 40 ERROR keystone.server.flask.application   File "/var/lib/kolla/venv/lib/python3.9/site-packages/keystone/identity/backends/sql.py", line 194, in _get_user
2023-02-17 06:15:40.620 40 ERROR keystone.server.flask.application     raise exception.UserNotFound(user_id=user_id)
2023-02-17 06:15:40.620 40 ERROR keystone.server.flask.application keystone.exception.UserNotFound: Could not find user: neutron.
2023-02-17 06:15:40.620 40 ERROR keystone.server.flask.application 
2023-02-17 06:15:41.293 39 ERROR keystone.server.flask.application [None req-fc33e51f-feb5-4a59-9a28-ec9ea0df649a 716d238b4ce449dd9f65ebb57f427216 - - all default -] Could not find project: service.: keystone.exception.ProjectNotFound: Could not find project: service.
2023-02-17 06:15:41.293 39 ERROR keystone.server.flask.application Traceback (most recent call last):
2023-02-17 06:15:41.293 39 ERROR keystone.server.flask.application   File "/var/lib/kolla/venv/lib/python3.9/site-packages/flask/app.py", line 1820, in full_dispatch_request
2023-02-17 06:15:41.293 39 ERROR keystone.server.flask.application     rv = self.dispatch_request()
2023-02-17 06:15:41.293 39 ERROR keystone.server.flask.application   File "/var/lib/kolla/venv/lib/python3.9/site-packages/flask/app.py", line 1796, in dispatch_request
2023-02-17 06:15:41.293 39 ERROR keystone.server.flask.application     return self.ensure_sync(self.view_functions[rule.endpoint])(**view_args)
2023-02-17 06:15:41.293 39 ERROR keystone.server.flask.application   File "/var/lib/kolla/venv/lib/python3.9/site-packages/flask_restful/__init__.py", line 467, in wrapper
2023-02-17 06:15:41.293 39 ERROR keystone.server.flask.application     resp = resource(*args, **kwargs)
2023-02-17 06:15:41.293 39 ERROR keystone.server.flask.application   File "/var/lib/kolla/venv/lib/python3.9/site-packages/flask/views.py", line 107, in view
2023-02-17 06:15:41.293 39 ERROR keystone.server.flask.application     return current_app.ensure_sync(self.dispatch_request)(**kwargs)
2023-02-17 06:15:41.293 39 ERROR keystone.server.flask.application   File "/var/lib/kolla/venv/lib/python3.9/site-packages/flask_restful/__init__.py", line 582, in dispatch_request
2023-02-17 06:15:41.293 39 ERROR keystone.server.flask.application     resp = meth(*args, **kwargs)
2023-02-17 06:15:41.293 39 ERROR keystone.server.flask.application   File "/var/lib/kolla/venv/lib/python3.9/site-packages/keystone/api/projects.py", line 151, in get
2023-02-17 06:15:41.293 39 ERROR keystone.server.flask.application     return self._get_project(project_id)
2023-02-17 06:15:41.293 39 ERROR keystone.server.flask.application   File "/var/lib/kolla/venv/lib/python3.9/site-packages/keystone/api/projects.py", line 107, in _get_project
2023-02-17 06:15:41.293 39 ERROR keystone.server.flask.application     project = PROVIDERS.resource_api.get_project(project_id)
2023-02-17 06:15:41.293 39 ERROR keystone.server.flask.application   File "/var/lib/kolla/venv/lib/python3.9/site-packages/keystone/common/manager.py", line 115, in wrapped
2023-02-17 06:15:41.293 39 ERROR keystone.server.flask.application     __ret_val = __f(*args, **kwargs)
2023-02-17 06:15:41.293 39 ERROR keystone.server.flask.application   File "/var/lib/kolla/venv/lib/python3.9/site-packages/decorator.py", line 232, in fun
2023-02-17 06:15:41.293 39 ERROR keystone.server.flask.application     return caller(func, *(extras + args), **kw)
2023-02-17 06:15:41.293 39 ERROR keystone.server.flask.application   File "/var/lib/kolla/venv/lib/python3.9/site-packages/dogpile/cache/region.py", line 1577, in get_or_create_for_user_func
2023-02-17 06:15:41.293 39 ERROR keystone.server.flask.application     return self.get_or_create(
2023-02-17 06:15:41.293 39 ERROR keystone.server.flask.application   File "/var/lib/kolla/venv/lib/python3.9/site-packages/dogpile/cache/region.py", line 1042, in get_or_create
2023-02-17 06:15:41.293 39 ERROR keystone.server.flask.application     with Lock(
2023-02-17 06:15:41.293 39 ERROR keystone.server.flask.application   File "/var/lib/kolla/venv/lib/python3.9/site-packages/dogpile/lock.py", line 185, in __enter__
2023-02-17 06:15:41.293 39 ERROR keystone.server.flask.application     return self._enter()
2023-02-17 06:15:41.293 39 ERROR keystone.server.flask.application   File "/var/lib/kolla/venv/lib/python3.9/site-packages/dogpile/lock.py", line 94, in _enter
2023-02-17 06:15:41.293 39 ERROR keystone.server.flask.application     generated = self._enter_create(value, createdtime)
2023-02-17 06:15:41.293 39 ERROR keystone.server.flask.application   File "/var/lib/kolla/venv/lib/python3.9/site-packages/dogpile/lock.py", line 178, in _enter_create
2023-02-17 06:15:41.293 39 ERROR keystone.server.flask.application     return self.creator()
2023-02-17 06:15:41.293 39 ERROR keystone.server.flask.application   File "/var/lib/kolla/venv/lib/python3.9/site-packages/dogpile/cache/region.py", line 995, in gen_value
2023-02-17 06:15:41.293 39 ERROR keystone.server.flask.application     created_value = creator(
2023-02-17 06:15:41.293 39 ERROR keystone.server.flask.application   File "/var/lib/kolla/venv/lib/python3.9/site-packages/keystone/resource/core.py", line 903, in get_project
2023-02-17 06:15:41.293 39 ERROR keystone.server.flask.application     return self.driver.get_project(project_id)
2023-02-17 06:15:41.293 39 ERROR keystone.server.flask.application   File "/var/lib/kolla/venv/lib/python3.9/site-packages/keystone/resource/backends/sql.py", line 49, in get_project
2023-02-17 06:15:41.293 39 ERROR keystone.server.flask.application     return self._get_project(session, project_id).to_dict()
2023-02-17 06:15:41.293 39 ERROR keystone.server.flask.application   File "/var/lib/kolla/venv/lib/python3.9/site-packages/keystone/resource/backends/sql.py", line 44, in _get_project
2023-02-17 06:15:41.293 39 ERROR keystone.server.flask.application     raise exception.ProjectNotFound(project_id=project_id)
2023-02-17 06:15:41.293 39 ERROR keystone.server.flask.application keystone.exception.ProjectNotFound: Could not find project: service.
2023-02-17 06:15:41.293 39 ERROR keystone.server.flask.application 
2023-02-17 07:12:34.462 40 WARNING py.warnings [None req-9dc1d7d1-4726-4cf2-8fbc-712aedb0f8b1 716d238b4ce449dd9f65ebb57f427216 103f9129a32a46d880a786431d791e6e - - default default] /var/lib/kolla/venv/lib/python3.9/site-packages/oslo_policy/policy.py:1129: UserWarning: Policy "identity:list_domains": "role:reader and system_scope:all" failed scope check. The token used to make the request was project scoped but the policy requires ['system'] scope. This behavior may change in the future where using the intended scope is required
  warnings.warn(msg)

2023-02-17 07:12:34.708 38 WARNING py.warnings [None req-17b8ae76-e092-4b8e-bf39-03082c84711a 716d238b4ce449dd9f65ebb57f427216 103f9129a32a46d880a786431d791e6e - - default default] /var/lib/kolla/venv/lib/python3.9/site-packages/oslo_policy/policy.py:1129: UserWarning: Policy "identity:create_project": "(role:admin and system_scope:all) or (role:admin and domain_id:%(target.project.domain_id)s)" failed scope check. The token used to make the request was project scoped but the policy requires ['system', 'domain'] scope. This behavior may change in the future where using the intended scope is required
  warnings.warn(msg)

2023-02-17 07:12:35.056 39 WARNING py.warnings [None req-bac0dbfd-10ed-432a-9f16-9e7817118138 716d238b4ce449dd9f65ebb57f427216 103f9129a32a46d880a786431d791e6e - - default default] /var/lib/kolla/venv/lib/python3.9/site-packages/oslo_policy/policy.py:1129: UserWarning: Policy "identity:create_user": "(role:admin and system_scope:all) or (role:admin and token.domain.id:%(target.user.domain_id)s)" failed scope check. The token used to make the request was project scoped but the policy requires ['system', 'domain'] scope. This behavior may change in the future where using the intended scope is required
  warnings.warn(msg)

2023-02-17 07:12:35.943 40 WARNING py.warnings [None req-607be339-4fd3-4f1b-8eee-1da7d1a7223d 716d238b4ce449dd9f65ebb57f427216 103f9129a32a46d880a786431d791e6e - - default default] /var/lib/kolla/venv/lib/python3.9/site-packages/oslo_policy/policy.py:1129: UserWarning: Policy "identity:list_roles": "role:reader and system_scope:all" failed scope check. The token used to make the request was project scoped but the policy requires ['system'] scope. This behavior may change in the future where using the intended scope is required
  warnings.warn(msg)

2023-02-17 07:12:36.219 38 WARNING py.warnings [None req-9d9c8eb4-5919-464e-9fbf-8e1a37987ede 716d238b4ce449dd9f65ebb57f427216 103f9129a32a46d880a786431d791e6e - - default default] /var/lib/kolla/venv/lib/python3.9/site-packages/oslo_policy/policy.py:1129: UserWarning: Policy "identity:list_roles": "role:reader and system_scope:all" failed scope check. The token used to make the request was project scoped but the policy requires ['system'] scope. This behavior may change in the future where using the intended scope is required
  warnings.warn(msg)

2023-02-17 07:12:36.455 39 WARNING py.warnings [None req-a8c6f597-78bc-4c3f-a10e-58ed2ffb5e56 716d238b4ce449dd9f65ebb57f427216 103f9129a32a46d880a786431d791e6e - - default default] /var/lib/kolla/venv/lib/python3.9/site-packages/oslo_policy/policy.py:1129: UserWarning: Policy "identity:create_grant": "(role:admin and system_scope:all) or ((role:admin and domain_id:%(target.user.domain_id)s and domain_id:%(target.project.domain_id)s) or (role:admin and domain_id:%(target.user.domain_id)s and domain_id:%(target.domain.id)s) or (role:admin and domain_id:%(target.group.domain_id)s and domain_id:%(target.project.domain_id)s) or (role:admin and domain_id:%(target.group.domain_id)s and domain_id:%(target.domain.id)s)) and (domain_id:%(target.role.domain_id)s or None:%(target.role.domain_id)s)" failed scope check. The token used to make the request was project scoped but the policy requires ['system', 'domain'] scope. This behavior may change in the future where using the intended scope is required
  warnings.warn(msg)

2023-02-17 07:12:39.100 38 WARNING py.warnings [None req-30e5d354-758c-43ad-94d6-5d4d8036716a 716d238b4ce449dd9f65ebb57f427216 103f9129a32a46d880a786431d791e6e - - default default] /var/lib/kolla/venv/lib/python3.9/site-packages/oslo_policy/policy.py:1129: UserWarning: Policy "identity:create_grant": "(role:admin and system_scope:all) or ((role:admin and domain_id:%(target.user.domain_id)s and domain_id:%(target.project.domain_id)s) or (role:admin and domain_id:%(target.user.domain_id)s and domain_id:%(target.domain.id)s) or (role:admin and domain_id:%(target.group.domain_id)s and domain_id:%(target.project.domain_id)s) or (role:admin and domain_id:%(target.group.domain_id)s and domain_id:%(target.domain.id)s)) and (domain_id:%(target.role.domain_id)s or None:%(target.role.domain_id)s)" failed scope check. The token used to make the request was project scoped but the policy requires ['system', 'domain'] scope. This behavior may change in the future where using the intended scope is required
  warnings.warn(msg)

2023-02-17 07:12:39.303 39 WARNING py.warnings [None req-0b0e2cfd-b1fd-412b-86b5-0c7eff2f88aa 716d238b4ce449dd9f65ebb57f427216 103f9129a32a46d880a786431d791e6e - - default default] /var/lib/kolla/venv/lib/python3.9/site-packages/oslo_policy/policy.py:1129: UserWarning: Policy "identity:list_roles": "role:reader and system_scope:all" failed scope check. The token used to make the request was project scoped but the policy requires ['system'] scope. This behavior may change in the future where using the intended scope is required
  warnings.warn(msg)

2023-02-17 07:12:39.600 40 WARNING py.warnings [None req-2c663112-f2e1-4f0a-bb7d-5f1dfe582af4 716d238b4ce449dd9f65ebb57f427216 103f9129a32a46d880a786431d791e6e - - default default] /var/lib/kolla/venv/lib/python3.9/site-packages/oslo_policy/policy.py:1129: UserWarning: Policy "identity:create_grant": "(role:admin and system_scope:all) or ((role:admin and domain_id:%(target.user.domain_id)s and domain_id:%(target.project.domain_id)s) or (role:admin and domain_id:%(target.user.domain_id)s and domain_id:%(target.domain.id)s) or (role:admin and domain_id:%(target.group.domain_id)s and domain_id:%(target.project.domain_id)s) or (role:admin and domain_id:%(target.group.domain_id)s and domain_id:%(target.domain.id)s)) and (domain_id:%(target.role.domain_id)s or None:%(target.role.domain_id)s)" failed scope check. The token used to make the request was project scoped but the policy requires ['system', 'domain'] scope. This behavior may change in the future where using the intended scope is required
  warnings.warn(msg)

2023-02-17 07:12:41.743 38 WARNING py.warnings [None req-d8e7b22e-fe34-4ccb-aed2-65471abec4a9 716d238b4ce449dd9f65ebb57f427216 103f9129a32a46d880a786431d791e6e - - default default] /var/lib/kolla/venv/lib/python3.9/site-packages/oslo_policy/policy.py:1129: UserWarning: Policy "identity:create_system_grant_for_user": "role:admin and system_scope:all" failed scope check. The token used to make the request was project scoped but the policy requires ['system'] scope. This behavior may change in the future where using the intended scope is required
  warnings.warn(msg)

