2023-03-13 22:58:10.968912 2023-03-13 22:58:10.966 28 WARNING keystone.common.rbac_enforcer.enforcer [None req-8fb55f4e-9826-4234-ac6e-c0eb9cb8b4b0 2f52da95b5904fb7821d1158394f777c - - all default -] Deprecated policy rules found. Use oslopolicy-policy-generator and oslopolicy-policy-upgrade to detect and resolve deprecated policies in your configuration.\x1b[00m
2023-03-13 22:58:12.004499 2023-03-13 22:58:12.002 26 WARNING keystone.common.rbac_enforcer.enforcer [None req-fe0830db-4f26-42a7-98b1-60a8a4599149 2f52da95b5904fb7821d1158394f777c - - all default -] Deprecated policy rules found. Use oslopolicy-policy-generator and oslopolicy-policy-upgrade to detect and resolve deprecated policies in your configuration.\x1b[00m
2023-03-13 22:58:20.069398 2023-03-13 22:58:20.067 27 WARNING keystone.common.rbac_enforcer.enforcer [None req-9b1696a5-9bb3-4001-b79c-a974c0a0a695 2f52da95b5904fb7821d1158394f777c - - all default -] Deprecated policy rules found. Use oslopolicy-policy-generator and oslopolicy-policy-upgrade to detect and resolve deprecated policies in your configuration.\x1b[00m
2023-03-13 22:59:40.487348 2023-03-13 22:59:40.456 28 ERROR keystone.server.flask.application [None req-77242c92-0a4b-44e3-97c8-6b98cdb79562 2f52da95b5904fb7821d1158394f777c - - all default -] Could not find project: service.: keystone.exception.ProjectNotFound: Could not find project: service.
2023-03-13 22:59:40.487404 2023-03-13 22:59:40.456 28 ERROR keystone.server.flask.application Traceback (most recent call last):
2023-03-13 22:59:40.487417 2023-03-13 22:59:40.456 28 ERROR keystone.server.flask.application   File "/var/lib/kolla/venv/lib/python3.9/site-packages/flask/app.py", line 1820, in full_dispatch_request
2023-03-13 22:59:40.487427 2023-03-13 22:59:40.456 28 ERROR keystone.server.flask.application     rv = self.dispatch_request()
2023-03-13 22:59:40.487437 2023-03-13 22:59:40.456 28 ERROR keystone.server.flask.application   File "/var/lib/kolla/venv/lib/python3.9/site-packages/flask/app.py", line 1796, in dispatch_request
2023-03-13 22:59:40.487448 2023-03-13 22:59:40.456 28 ERROR keystone.server.flask.application     return self.ensure_sync(self.view_functions[rule.endpoint])(**view_args)
2023-03-13 22:59:40.487458 2023-03-13 22:59:40.456 28 ERROR keystone.server.flask.application   File "/var/lib/kolla/venv/lib/python3.9/site-packages/flask_restful/__init__.py", line 467, in wrapper
2023-03-13 22:59:40.487467 2023-03-13 22:59:40.456 28 ERROR keystone.server.flask.application     resp = resource(*args, **kwargs)
2023-03-13 22:59:40.487483 2023-03-13 22:59:40.456 28 ERROR keystone.server.flask.application   File "/var/lib/kolla/venv/lib/python3.9/site-packages/flask/views.py", line 107, in view
2023-03-13 22:59:40.487500 2023-03-13 22:59:40.456 28 ERROR keystone.server.flask.application     return current_app.ensure_sync(self.dispatch_request)(**kwargs)
2023-03-13 22:59:40.487511 2023-03-13 22:59:40.456 28 ERROR keystone.server.flask.application   File "/var/lib/kolla/venv/lib/python3.9/site-packages/flask_restful/__init__.py", line 582, in dispatch_request
2023-03-13 22:59:40.487521 2023-03-13 22:59:40.456 28 ERROR keystone.server.flask.application     resp = meth(*args, **kwargs)
2023-03-13 22:59:40.487531 2023-03-13 22:59:40.456 28 ERROR keystone.server.flask.application   File "/var/lib/kolla/venv/lib/python3.9/site-packages/keystone/api/projects.py", line 151, in get
2023-03-13 22:59:40.487542 2023-03-13 22:59:40.456 28 ERROR keystone.server.flask.application     return self._get_project(project_id)
2023-03-13 22:59:40.487720 2023-03-13 22:59:40.456 28 ERROR keystone.server.flask.application   File "/var/lib/kolla/venv/lib/python3.9/site-packages/keystone/api/projects.py", line 107, in _get_project
2023-03-13 22:59:40.487741 2023-03-13 22:59:40.456 28 ERROR keystone.server.flask.application     project = PROVIDERS.resource_api.get_project(project_id)
2023-03-13 22:59:40.487752 2023-03-13 22:59:40.456 28 ERROR keystone.server.flask.application   File "/var/lib/kolla/venv/lib/python3.9/site-packages/keystone/common/manager.py", line 115, in wrapped
2023-03-13 22:59:40.487839 2023-03-13 22:59:40.456 28 ERROR keystone.server.flask.application     __ret_val = __f(*args, **kwargs)
2023-03-13 22:59:40.487855 2023-03-13 22:59:40.456 28 ERROR keystone.server.flask.application   File "/var/lib/kolla/venv/lib/python3.9/site-packages/decorator.py", line 232, in fun
2023-03-13 22:59:40.487865 2023-03-13 22:59:40.456 28 ERROR keystone.server.flask.application     return caller(func, *(extras + args), **kw)
2023-03-13 22:59:40.487875 2023-03-13 22:59:40.456 28 ERROR keystone.server.flask.application   File "/var/lib/kolla/venv/lib/python3.9/site-packages/dogpile/cache/region.py", line 1577, in get_or_create_for_user_func
2023-03-13 22:59:40.487885 2023-03-13 22:59:40.456 28 ERROR keystone.server.flask.application     return self.get_or_create(
2023-03-13 22:59:40.487895 2023-03-13 22:59:40.456 28 ERROR keystone.server.flask.application   File "/var/lib/kolla/venv/lib/python3.9/site-packages/dogpile/cache/region.py", line 1042, in get_or_create
2023-03-13 22:59:40.487905 2023-03-13 22:59:40.456 28 ERROR keystone.server.flask.application     with Lock(
2023-03-13 22:59:40.487915 2023-03-13 22:59:40.456 28 ERROR keystone.server.flask.application   File "/var/lib/kolla/venv/lib/python3.9/site-packages/dogpile/lock.py", line 185, in __enter__
2023-03-13 22:59:40.487925 2023-03-13 22:59:40.456 28 ERROR keystone.server.flask.application     return self._enter()
2023-03-13 22:59:40.487934 2023-03-13 22:59:40.456 28 ERROR keystone.server.flask.application   File "/var/lib/kolla/venv/lib/python3.9/site-packages/dogpile/lock.py", line 94, in _enter
2023-03-13 22:59:40.487944 2023-03-13 22:59:40.456 28 ERROR keystone.server.flask.application     generated = self._enter_create(value, createdtime)
2023-03-13 22:59:40.487954 2023-03-13 22:59:40.456 28 ERROR keystone.server.flask.application   File "/var/lib/kolla/venv/lib/python3.9/site-packages/dogpile/lock.py", line 178, in _enter_create
2023-03-13 22:59:40.487964 2023-03-13 22:59:40.456 28 ERROR keystone.server.flask.application     return self.creator()
2023-03-13 22:59:40.487973 2023-03-13 22:59:40.456 28 ERROR keystone.server.flask.application   File "/var/lib/kolla/venv/lib/python3.9/site-packages/dogpile/cache/region.py", line 995, in gen_value
2023-03-13 22:59:40.487983 2023-03-13 22:59:40.456 28 ERROR keystone.server.flask.application     created_value = creator(
2023-03-13 22:59:40.487993 2023-03-13 22:59:40.456 28 ERROR keystone.server.flask.application   File "/var/lib/kolla/venv/lib/python3.9/site-packages/keystone/resource/core.py", line 903, in get_project
2023-03-13 22:59:40.488002 2023-03-13 22:59:40.456 28 ERROR keystone.server.flask.application     return self.driver.get_project(project_id)
2023-03-13 22:59:40.488012 2023-03-13 22:59:40.456 28 ERROR keystone.server.flask.application   File "/var/lib/kolla/venv/lib/python3.9/site-packages/keystone/resource/backends/sql.py", line 49, in get_project
2023-03-13 22:59:40.488022 2023-03-13 22:59:40.456 28 ERROR keystone.server.flask.application     return self._get_project(session, project_id).to_dict()
2023-03-13 22:59:40.488032 2023-03-13 22:59:40.456 28 ERROR keystone.server.flask.application   File "/var/lib/kolla/venv/lib/python3.9/site-packages/keystone/resource/backends/sql.py", line 44, in _get_project
2023-03-13 22:59:40.488041 2023-03-13 22:59:40.456 28 ERROR keystone.server.flask.application     raise exception.ProjectNotFound(project_id=project_id)
2023-03-13 22:59:40.488051 2023-03-13 22:59:40.456 28 ERROR keystone.server.flask.application keystone.exception.ProjectNotFound: Could not find project: service.
2023-03-13 22:59:40.488060 2023-03-13 22:59:40.456 28 ERROR keystone.server.flask.application \x1b[00m
2023-03-13 22:59:49.814279 2023-03-13 22:59:49.803 27 ERROR keystone.server.flask.application [None req-cd7589b5-445c-4db8-9b8c-dd9af12662b2 2f52da95b5904fb7821d1158394f777c - - all default -] Could not find project: service.: keystone.exception.ProjectNotFound: Could not find project: service.
2023-03-13 22:59:49.814330 2023-03-13 22:59:49.803 27 ERROR keystone.server.flask.application Traceback (most recent call last):
2023-03-13 22:59:49.814358 2023-03-13 22:59:49.803 27 ERROR keystone.server.flask.application   File "/var/lib/kolla/venv/lib/python3.9/site-packages/flask/app.py", line 1820, in full_dispatch_request
2023-03-13 22:59:49.814370 2023-03-13 22:59:49.803 27 ERROR keystone.server.flask.application     rv = self.dispatch_request()
2023-03-13 22:59:49.814379 2023-03-13 22:59:49.803 27 ERROR keystone.server.flask.application   File "/var/lib/kolla/venv/lib/python3.9/site-packages/flask/app.py", line 1796, in dispatch_request
2023-03-13 22:59:49.814390 2023-03-13 22:59:49.803 27 ERROR keystone.server.flask.application     return self.ensure_sync(self.view_functions[rule.endpoint])(**view_args)
2023-03-13 22:59:49.814400 2023-03-13 22:59:49.803 27 ERROR keystone.server.flask.application   File "/var/lib/kolla/venv/lib/python3.9/site-packages/flask_restful/__init__.py", line 467, in wrapper
2023-03-13 22:59:49.814410 2023-03-13 22:59:49.803 27 ERROR keystone.server.flask.application     resp = resource(*args, **kwargs)
2023-03-13 22:59:49.814427 2023-03-13 22:59:49.803 27 ERROR keystone.server.flask.application   File "/var/lib/kolla/venv/lib/python3.9/site-packages/flask/views.py", line 107, in view
2023-03-13 22:59:49.814445 2023-03-13 22:59:49.803 27 ERROR keystone.server.flask.application     return current_app.ensure_sync(self.dispatch_request)(**kwargs)
2023-03-13 22:59:49.814456 2023-03-13 22:59:49.803 27 ERROR keystone.server.flask.application   File "/var/lib/kolla/venv/lib/python3.9/site-packages/flask_restful/__init__.py", line 582, in dispatch_request
2023-03-13 22:59:49.814466 2023-03-13 22:59:49.803 27 ERROR keystone.server.flask.application     resp = meth(*args, **kwargs)
2023-03-13 22:59:49.814475 2023-03-13 22:59:49.803 27 ERROR keystone.server.flask.application   File "/var/lib/kolla/venv/lib/python3.9/site-packages/keystone/api/projects.py", line 151, in get
2023-03-13 22:59:49.814486 2023-03-13 22:59:49.803 27 ERROR keystone.server.flask.application     return self._get_project(project_id)
2023-03-13 22:59:49.814496 2023-03-13 22:59:49.803 27 ERROR keystone.server.flask.application   File "/var/lib/kolla/venv/lib/python3.9/site-packages/keystone/api/projects.py", line 107, in _get_project
2023-03-13 22:59:49.814506 2023-03-13 22:59:49.803 27 ERROR keystone.server.flask.application     project = PROVIDERS.resource_api.get_project(project_id)
2023-03-13 22:59:49.814524 2023-03-13 22:59:49.803 27 ERROR keystone.server.flask.application   File "/var/lib/kolla/venv/lib/python3.9/site-packages/keystone/common/manager.py", line 115, in wrapped
2023-03-13 22:59:49.814538 2023-03-13 22:59:49.803 27 ERROR keystone.server.flask.application     __ret_val = __f(*args, **kwargs)
2023-03-13 22:59:49.814550 2023-03-13 22:59:49.803 27 ERROR keystone.server.flask.application   File "/var/lib/kolla/venv/lib/python3.9/site-packages/decorator.py", line 232, in fun
2023-03-13 22:59:49.814563 2023-03-13 22:59:49.803 27 ERROR keystone.server.flask.application     return caller(func, *(extras + args), **kw)
2023-03-13 22:59:49.814582 2023-03-13 22:59:49.803 27 ERROR keystone.server.flask.application   File "/var/lib/kolla/venv/lib/python3.9/site-packages/dogpile/cache/region.py", line 1577, in get_or_create_for_user_func
2023-03-13 22:59:49.814592 2023-03-13 22:59:49.803 27 ERROR keystone.server.flask.application     return self.get_or_create(
2023-03-13 22:59:49.814602 2023-03-13 22:59:49.803 27 ERROR keystone.server.flask.application   File "/var/lib/kolla/venv/lib/python3.9/site-packages/dogpile/cache/region.py", line 1042, in get_or_create
2023-03-13 22:59:49.814612 2023-03-13 22:59:49.803 27 ERROR keystone.server.flask.application     with Lock(
2023-03-13 22:59:49.814622 2023-03-13 22:59:49.803 27 ERROR keystone.server.flask.application   File "/var/lib/kolla/venv/lib/python3.9/site-packages/dogpile/lock.py", line 185, in __enter__
2023-03-13 22:59:49.814631 2023-03-13 22:59:49.803 27 ERROR keystone.server.flask.application     return self._enter()
2023-03-13 22:59:49.814652 2023-03-13 22:59:49.803 27 ERROR keystone.server.flask.application   File "/var/lib/kolla/venv/lib/python3.9/site-packages/dogpile/lock.py", line 94, in _enter
2023-03-13 22:59:49.814663 2023-03-13 22:59:49.803 27 ERROR keystone.server.flask.application     generated = self._enter_create(value, createdtime)
2023-03-13 22:59:49.814673 2023-03-13 22:59:49.803 27 ERROR keystone.server.flask.application   File "/var/lib/kolla/venv/lib/python3.9/site-packages/dogpile/lock.py", line 178, in _enter_create
2023-03-13 22:59:49.814683 2023-03-13 22:59:49.803 27 ERROR keystone.server.flask.application     return self.creator()
2023-03-13 22:59:49.814692 2023-03-13 22:59:49.803 27 ERROR keystone.server.flask.application   File "/var/lib/kolla/venv/lib/python3.9/site-packages/dogpile/cache/region.py", line 995, in gen_value
2023-03-13 22:59:49.814702 2023-03-13 22:59:49.803 27 ERROR keystone.server.flask.application     created_value = creator(
2023-03-13 22:59:49.814712 2023-03-13 22:59:49.803 27 ERROR keystone.server.flask.application   File "/var/lib/kolla/venv/lib/python3.9/site-packages/keystone/resource/core.py", line 903, in get_project
2023-03-13 22:59:49.814721 2023-03-13 22:59:49.803 27 ERROR keystone.server.flask.application     return self.driver.get_project(project_id)
2023-03-13 22:59:49.814731 2023-03-13 22:59:49.803 27 ERROR keystone.server.flask.application   File "/var/lib/kolla/venv/lib/python3.9/site-packages/keystone/resource/backends/sql.py", line 49, in get_project
2023-03-13 22:59:49.814741 2023-03-13 22:59:49.803 27 ERROR keystone.server.flask.application     return self._get_project(session, project_id).to_dict()
2023-03-13 22:59:49.814750 2023-03-13 22:59:49.803 27 ERROR keystone.server.flask.application   File "/var/lib/kolla/venv/lib/python3.9/site-packages/keystone/resource/backends/sql.py", line 44, in _get_project
2023-03-13 22:59:49.814760 2023-03-13 22:59:49.803 27 ERROR keystone.server.flask.application     raise exception.ProjectNotFound(project_id=project_id)
2023-03-13 22:59:49.814770 2023-03-13 22:59:49.803 27 ERROR keystone.server.flask.application keystone.exception.ProjectNotFound: Could not find project: service.
2023-03-13 22:59:49.814779 2023-03-13 22:59:49.803 27 ERROR keystone.server.flask.application \x1b[00m
2023-03-13 23:00:05.798916 2023-03-13 23:00:05.791 27 ERROR keystone.server.flask.application [None req-23bad481-f5d6-4942-bf9c-5fc49aa9f8ae 2f52da95b5904fb7821d1158394f777c - - all default -] Could not find role: admin.: keystone.exception.RoleNotFound: Could not find role: admin.
2023-03-13 23:00:05.799010 2023-03-13 23:00:05.791 27 ERROR keystone.server.flask.application Traceback (most recent call last):
2023-03-13 23:00:05.799027 2023-03-13 23:00:05.791 27 ERROR keystone.server.flask.application   File "/var/lib/kolla/venv/lib/python3.9/site-packages/flask/app.py", line 1820, in full_dispatch_request
2023-03-13 23:00:05.799045 2023-03-13 23:00:05.791 27 ERROR keystone.server.flask.application     rv = self.dispatch_request()
2023-03-13 23:00:05.799598 2023-03-13 23:00:05.791 27 ERROR keystone.server.flask.application   File "/var/lib/kolla/venv/lib/python3.9/site-packages/flask/app.py", line 1796, in dispatch_request
2023-03-13 23:00:05.799627 2023-03-13 23:00:05.791 27 ERROR keystone.server.flask.application     return self.ensure_sync(self.view_functions[rule.endpoint])(**view_args)
2023-03-13 23:00:05.799640 2023-03-13 23:00:05.791 27 ERROR keystone.server.flask.application   File "/var/lib/kolla/venv/lib/python3.9/site-packages/flask_restful/__init__.py", line 467, in wrapper
2023-03-13 23:00:05.799653 2023-03-13 23:00:05.791 27 ERROR keystone.server.flask.application     resp = resource(*args, **kwargs)
2023-03-13 23:00:05.799676 2023-03-13 23:00:05.791 27 ERROR keystone.server.flask.application   File "/var/lib/kolla/venv/lib/python3.9/site-packages/flask/views.py", line 107, in view
2023-03-13 23:00:05.799692 2023-03-13 23:00:05.791 27 ERROR keystone.server.flask.application     return current_app.ensure_sync(self.dispatch_request)(**kwargs)
2023-03-13 23:00:05.799705 2023-03-13 23:00:05.791 27 ERROR keystone.server.flask.application   File "/var/lib/kolla/venv/lib/python3.9/site-packages/flask_restful/__init__.py", line 582, in dispatch_request
2023-03-13 23:00:05.799744 2023-03-13 23:00:05.791 27 ERROR keystone.server.flask.application     resp = meth(*args, **kwargs)
2023-03-13 23:00:05.799758 2023-03-13 23:00:05.791 27 ERROR keystone.server.flask.application   File "/var/lib/kolla/venv/lib/python3.9/site-packages/keystone/api/roles.py", line 50, in get
2023-03-13 23:00:05.799771 2023-03-13 23:00:05.791 27 ERROR keystone.server.flask.application     return self._get_role(role_id)
2023-03-13 23:00:05.799784 2023-03-13 23:00:05.791 27 ERROR keystone.server.flask.application   File "/var/lib/kolla/venv/lib/python3.9/site-packages/keystone/api/roles.py", line 70, in _get_role
2023-03-13 23:00:05.799827 2023-03-13 23:00:05.791 27 ERROR keystone.server.flask.application     ENFORCER.enforce_call(action='identity:get_role')
2023-03-13 23:00:05.799845 2023-03-13 23:00:05.791 27 ERROR keystone.server.flask.application   File "/var/lib/kolla/venv/lib/python3.9/site-packages/keystone/common/rbac_enforcer/enforcer.py", line 402, in enforce_call
2023-03-13 23:00:05.799857 2023-03-13 23:00:05.791 27 ERROR keystone.server.flask.application     policy_dict.update(cls._extract_member_target_data(
2023-03-13 23:00:05.799883 2023-03-13 23:00:05.791 27 ERROR keystone.server.flask.application   File "/var/lib/kolla/venv/lib/python3.9/site-packages/keystone/common/rbac_enforcer/enforcer.py", line 234, in _extract_member_target_data
2023-03-13 23:00:05.799898 2023-03-13 23:00:05.791 27 ERROR keystone.server.flask.application     member_name: func(flask.request.view_args[key])
2023-03-13 23:00:05.799911 2023-03-13 23:00:05.791 27 ERROR keystone.server.flask.application   File "/var/lib/kolla/venv/lib/python3.9/site-packages/keystone/common/manager.py", line 115, in wrapped
2023-03-13 23:00:05.799923 2023-03-13 23:00:05.791 27 ERROR keystone.server.flask.application     __ret_val = __f(*args, **kwargs)
2023-03-13 23:00:05.799935 2023-03-13 23:00:05.791 27 ERROR keystone.server.flask.application   File "/var/lib/kolla/venv/lib/python3.9/site-packages/decorator.py", line 232, in fun
2023-03-13 23:00:05.799947 2023-03-13 23:00:05.791 27 ERROR keystone.server.flask.application     return caller(func, *(extras + args), **kw)
2023-03-13 23:00:05.799959 2023-03-13 23:00:05.791 27 ERROR keystone.server.flask.application   File "/var/lib/kolla/venv/lib/python3.9/site-packages/dogpile/cache/region.py", line 1577, in get_or_create_for_user_func
2023-03-13 23:00:05.799971 2023-03-13 23:00:05.791 27 ERROR keystone.server.flask.application     return self.get_or_create(
2023-03-13 23:00:05.799983 2023-03-13 23:00:05.791 27 ERROR keystone.server.flask.application   File "/var/lib/kolla/venv/lib/python3.9/site-packages/dogpile/cache/region.py", line 1042, in get_or_create
2023-03-13 23:00:05.799996 2023-03-13 23:00:05.791 27 ERROR keystone.server.flask.application     with Lock(
2023-03-13 23:00:05.800008 2023-03-13 23:00:05.791 27 ERROR keystone.server.flask.application   File "/var/lib/kolla/venv/lib/python3.9/site-packages/dogpile/lock.py", line 185, in __enter__
2023-03-13 23:00:05.800020 2023-03-13 23:00:05.791 27 ERROR keystone.server.flask.application     return self._enter()
2023-03-13 23:00:05.800032 2023-03-13 23:00:05.791 27 ERROR keystone.server.flask.application   File "/var/lib/kolla/venv/lib/python3.9/site-packages/dogpile/lock.py", line 94, in _enter
2023-03-13 23:00:05.800044 2023-03-13 23:00:05.791 27 ERROR keystone.server.flask.application     generated = self._enter_create(value, createdtime)
2023-03-13 23:00:05.800056 2023-03-13 23:00:05.791 27 ERROR keystone.server.flask.application   File "/var/lib/kolla/venv/lib/python3.9/site-packages/dogpile/lock.py", line 178, in _enter_create
2023-03-13 23:00:05.800068 2023-03-13 23:00:05.791 27 ERROR keystone.server.flask.application     return self.creator()
2023-03-13 23:00:05.800080 2023-03-13 23:00:05.791 27 ERROR keystone.server.flask.application   File "/var/lib/kolla/venv/lib/python3.9/site-packages/dogpile/cache/region.py", line 995, in gen_value
2023-03-13 23:00:05.800147 2023-03-13 23:00:05.791 27 ERROR keystone.server.flask.application     created_value = creator(
2023-03-13 23:00:05.800167 2023-03-13 23:00:05.791 27 ERROR keystone.server.flask.application   File "/var/lib/kolla/venv/lib/python3.9/site-packages/keystone/assignment/core.py", line 1276, in get_role
2023-03-13 23:00:05.800179 2023-03-13 23:00:05.791 27 ERROR keystone.server.flask.application     return self.driver.get_role(role_id)
2023-03-13 23:00:05.800192 2023-03-13 23:00:05.791 27 ERROR keystone.server.flask.application   File "/var/lib/kolla/venv/lib/python3.9/site-packages/keystone/assignment/role_backends/sql.py", line 70, in get_role
2023-03-13 23:00:05.800207 2023-03-13 23:00:05.791 27 ERROR keystone.server.flask.application     return self._get_role(session, role_id).to_dict()
2023-03-13 23:00:05.800219 2023-03-13 23:00:05.791 27 ERROR keystone.server.flask.application   File "/var/lib/kolla/venv/lib/python3.9/site-packages/keystone/assignment/role_backends/sql.py", line 65, in _get_role
2023-03-13 23:00:05.800232 2023-03-13 23:00:05.791 27 ERROR keystone.server.flask.application     raise exception.RoleNotFound(role_id=role_id)
2023-03-13 23:00:05.800244 2023-03-13 23:00:05.791 27 ERROR keystone.server.flask.application keystone.exception.RoleNotFound: Could not find role: admin.
2023-03-13 23:00:05.800256 2023-03-13 23:00:05.791 27 ERROR keystone.server.flask.application \x1b[00m
2023-03-13 23:00:07.344196 2023-03-13 23:00:07.330 27 ERROR keystone.server.flask.application [None req-50eb26e3-9043-4cb3-8843-ee119e2fc71a 2f52da95b5904fb7821d1158394f777c - - all default -] Could not find user: ironic.: keystone.exception.UserNotFound: Could not find user: ironic.
2023-03-13 23:00:07.344254 2023-03-13 23:00:07.330 27 ERROR keystone.server.flask.application Traceback (most recent call last):
2023-03-13 23:00:07.344268 2023-03-13 23:00:07.330 27 ERROR keystone.server.flask.application   File "/var/lib/kolla/venv/lib/python3.9/site-packages/flask/app.py", line 1820, in full_dispatch_request
2023-03-13 23:00:07.344306 2023-03-13 23:00:07.330 27 ERROR keystone.server.flask.application     rv = self.dispatch_request()
2023-03-13 23:00:07.344328 2023-03-13 23:00:07.330 27 ERROR keystone.server.flask.application   File "/var/lib/kolla/venv/lib/python3.9/site-packages/flask/app.py", line 1796, in dispatch_request
2023-03-13 23:00:07.344350 2023-03-13 23:00:07.330 27 ERROR keystone.server.flask.application     return self.ensure_sync(self.view_functions[rule.endpoint])(**view_args)
2023-03-13 23:00:07.344369 2023-03-13 23:00:07.330 27 ERROR keystone.server.flask.application   File "/var/lib/kolla/venv/lib/python3.9/site-packages/flask_restful/__init__.py", line 467, in wrapper
2023-03-13 23:00:07.344388 2023-03-13 23:00:07.330 27 ERROR keystone.server.flask.application     resp = resource(*args, **kwargs)
2023-03-13 23:00:07.344408 2023-03-13 23:00:07.330 27 ERROR keystone.server.flask.application   File "/var/lib/kolla/venv/lib/python3.9/site-packages/flask/views.py", line 107, in view
2023-03-13 23:00:07.344423 2023-03-13 23:00:07.330 27 ERROR keystone.server.flask.application     return current_app.ensure_sync(self.dispatch_request)(**kwargs)
2023-03-13 23:00:07.344434 2023-03-13 23:00:07.330 27 ERROR keystone.server.flask.application   File "/var/lib/kolla/venv/lib/python3.9/site-packages/flask_restful/__init__.py", line 582, in dispatch_request
2023-03-13 23:00:07.344444 2023-03-13 23:00:07.330 27 ERROR keystone.server.flask.application     resp = meth(*args, **kwargs)
2023-03-13 23:00:07.344453 2023-03-13 23:00:07.330 27 ERROR keystone.server.flask.application   File "/var/lib/kolla/venv/lib/python3.9/site-packages/keystone/api/users.py", line 182, in get
2023-03-13 23:00:07.344463 2023-03-13 23:00:07.330 27 ERROR keystone.server.flask.application     return self._get_user(user_id)
2023-03-13 23:00:07.344473 2023-03-13 23:00:07.330 27 ERROR keystone.server.flask.application   File "/var/lib/kolla/venv/lib/python3.9/site-packages/keystone/api/users.py", line 194, in _get_user
2023-03-13 23:00:07.344500 2023-03-13 23:00:07.330 27 ERROR keystone.server.flask.application     ref = PROVIDERS.identity_api.get_user(user_id)
2023-03-13 23:00:07.344512 2023-03-13 23:00:07.330 27 ERROR keystone.server.flask.application   File "/var/lib/kolla/venv/lib/python3.9/site-packages/keystone/common/manager.py", line 115, in wrapped
2023-03-13 23:00:07.344521 2023-03-13 23:00:07.330 27 ERROR keystone.server.flask.application     __ret_val = __f(*args, **kwargs)
2023-03-13 23:00:07.344531 2023-03-13 23:00:07.330 27 ERROR keystone.server.flask.application   File "/var/lib/kolla/venv/lib/python3.9/site-packages/keystone/identity/core.py", line 414, in wrapper
2023-03-13 23:00:07.344541 2023-03-13 23:00:07.330 27 ERROR keystone.server.flask.application     return f(self, *args, **kwargs)
2023-03-13 23:00:07.344550 2023-03-13 23:00:07.330 27 ERROR keystone.server.flask.application   File "/var/lib/kolla/venv/lib/python3.9/site-packages/keystone/identity/core.py", line 424, in wrapper
2023-03-13 23:00:07.344560 2023-03-13 23:00:07.330 27 ERROR keystone.server.flask.application     return f(self, *args, **kwargs)
2023-03-13 23:00:07.344569 2023-03-13 23:00:07.330 27 ERROR keystone.server.flask.application   File "/var/lib/kolla/venv/lib/python3.9/site-packages/decorator.py", line 232, in fun
2023-03-13 23:00:07.344579 2023-03-13 23:00:07.330 27 ERROR keystone.server.flask.application     return caller(func, *(extras + args), **kw)
2023-03-13 23:00:07.344589 2023-03-13 23:00:07.330 27 ERROR keystone.server.flask.application   File "/var/lib/kolla/venv/lib/python3.9/site-packages/dogpile/cache/region.py", line 1577, in get_or_create_for_user_func
2023-03-13 23:00:07.344599 2023-03-13 23:00:07.330 27 ERROR keystone.server.flask.application     return self.get_or_create(
2023-03-13 23:00:07.344608 2023-03-13 23:00:07.330 27 ERROR keystone.server.flask.application   File "/var/lib/kolla/venv/lib/python3.9/site-packages/dogpile/cache/region.py", line 1042, in get_or_create
2023-03-13 23:00:07.344631 2023-03-13 23:00:07.330 27 ERROR keystone.server.flask.application     with Lock(
2023-03-13 23:00:07.344641 2023-03-13 23:00:07.330 27 ERROR keystone.server.flask.application   File "/var/lib/kolla/venv/lib/python3.9/site-packages/dogpile/lock.py", line 185, in __enter__
2023-03-13 23:00:07.344650 2023-03-13 23:00:07.330 27 ERROR keystone.server.flask.application     return self._enter()
2023-03-13 23:00:07.344660 2023-03-13 23:00:07.330 27 ERROR keystone.server.flask.application   File "/var/lib/kolla/venv/lib/python3.9/site-packages/dogpile/lock.py", line 94, in _enter
2023-03-13 23:00:07.344670 2023-03-13 23:00:07.330 27 ERROR keystone.server.flask.application     generated = self._enter_create(value, createdtime)
2023-03-13 23:00:07.344679 2023-03-13 23:00:07.330 27 ERROR keystone.server.flask.application   File "/var/lib/kolla/venv/lib/python3.9/site-packages/dogpile/lock.py", line 178, in _enter_create
2023-03-13 23:00:07.344689 2023-03-13 23:00:07.330 27 ERROR keystone.server.flask.application     return self.creator()
2023-03-13 23:00:07.344699 2023-03-13 23:00:07.330 27 ERROR keystone.server.flask.application   File "/var/lib/kolla/venv/lib/python3.9/site-packages/dogpile/cache/region.py", line 995, in gen_value
2023-03-13 23:00:07.344710 2023-03-13 23:00:07.330 27 ERROR keystone.server.flask.application     created_value = creator(
2023-03-13 23:00:07.344719 2023-03-13 23:00:07.330 27 ERROR keystone.server.flask.application   File "/var/lib/kolla/venv/lib/python3.9/site-packages/keystone/identity/core.py", line 1011, in get_user
2023-03-13 23:00:07.344729 2023-03-13 23:00:07.330 27 ERROR keystone.server.flask.application     ref = driver.get_user(entity_id)
2023-03-13 23:00:07.344738 2023-03-13 23:00:07.330 27 ERROR keystone.server.flask.application   File "/var/lib/kolla/venv/lib/python3.9/site-packages/keystone/identity/backends/sql.py", line 200, in get_user
2023-03-13 23:00:07.344748 2023-03-13 23:00:07.330 27 ERROR keystone.server.flask.application     self._get_user(session, user_id).to_dict())
2023-03-13 23:00:07.344769 2023-03-13 23:00:07.330 27 ERROR keystone.server.flask.application   File "/var/lib/kolla/venv/lib/python3.9/site-packages/keystone/identity/backends/sql.py", line 194, in _get_user
2023-03-13 23:00:07.344780 2023-03-13 23:00:07.330 27 ERROR keystone.server.flask.application     raise exception.UserNotFound(user_id=user_id)
2023-03-13 23:00:07.344790 2023-03-13 23:00:07.330 27 ERROR keystone.server.flask.application keystone.exception.UserNotFound: Could not find user: ironic.
2023-03-13 23:00:07.344817 2023-03-13 23:00:07.330 27 ERROR keystone.server.flask.application \x1b[00m
2023-03-13 23:00:08.262312 2023-03-13 23:00:08.250 26 ERROR keystone.server.flask.application [None req-15d48308-3fa9-487b-a472-392e3faa4296 2f52da95b5904fb7821d1158394f777c - - all default -] Could not find project: service.: keystone.exception.ProjectNotFound: Could not find project: service.
2023-03-13 23:00:08.262359 2023-03-13 23:00:08.250 26 ERROR keystone.server.flask.application Traceback (most recent call last):
2023-03-13 23:00:08.262370 2023-03-13 23:00:08.250 26 ERROR keystone.server.flask.application   File "/var/lib/kolla/venv/lib/python3.9/site-packages/flask/app.py", line 1820, in full_dispatch_request
2023-03-13 23:00:08.262380 2023-03-13 23:00:08.250 26 ERROR keystone.server.flask.application     rv = self.dispatch_request()
2023-03-13 23:00:08.262390 2023-03-13 23:00:08.250 26 ERROR keystone.server.flask.application   File "/var/lib/kolla/venv/lib/python3.9/site-packages/flask/app.py", line 1796, in dispatch_request
2023-03-13 23:00:08.262400 2023-03-13 23:00:08.250 26 ERROR keystone.server.flask.application     return self.ensure_sync(self.view_functions[rule.endpoint])(**view_args)
2023-03-13 23:00:08.262409 2023-03-13 23:00:08.250 26 ERROR keystone.server.flask.application   File "/var/lib/kolla/venv/lib/python3.9/site-packages/flask_restful/__init__.py", line 467, in wrapper
2023-03-13 23:00:08.262419 2023-03-13 23:00:08.250 26 ERROR keystone.server.flask.application     resp = resource(*args, **kwargs)
2023-03-13 23:00:08.262429 2023-03-13 23:00:08.250 26 ERROR keystone.server.flask.application   File "/var/lib/kolla/venv/lib/python3.9/site-packages/flask/views.py", line 107, in view
2023-03-13 23:00:08.262439 2023-03-13 23:00:08.250 26 ERROR keystone.server.flask.application     return current_app.ensure_sync(self.dispatch_request)(**kwargs)
2023-03-13 23:00:08.262449 2023-03-13 23:00:08.250 26 ERROR keystone.server.flask.application   File "/var/lib/kolla/venv/lib/python3.9/site-packages/flask_restful/__init__.py", line 582, in dispatch_request
2023-03-13 23:00:08.262459 2023-03-13 23:00:08.250 26 ERROR keystone.server.flask.application     resp = meth(*args, **kwargs)
2023-03-13 23:00:08.262468 2023-03-13 23:00:08.250 26 ERROR keystone.server.flask.application   File "/var/lib/kolla/venv/lib/python3.9/site-packages/keystone/api/projects.py", line 151, in get
2023-03-13 23:00:08.262478 2023-03-13 23:00:08.250 26 ERROR keystone.server.flask.application     return self._get_project(project_id)
2023-03-13 23:00:08.262488 2023-03-13 23:00:08.250 26 ERROR keystone.server.flask.application   File "/var/lib/kolla/venv/lib/python3.9/site-packages/keystone/api/projects.py", line 107, in _get_project
2023-03-13 23:00:08.262497 2023-03-13 23:00:08.250 26 ERROR keystone.server.flask.application     project = PROVIDERS.resource_api.get_project(project_id)
2023-03-13 23:00:08.262507 2023-03-13 23:00:08.250 26 ERROR keystone.server.flask.application   File "/var/lib/kolla/venv/lib/python3.9/site-packages/keystone/common/manager.py", line 115, in wrapped
2023-03-13 23:00:08.262516 2023-03-13 23:00:08.250 26 ERROR keystone.server.flask.application     __ret_val = __f(*args, **kwargs)
2023-03-13 23:00:08.262526 2023-03-13 23:00:08.250 26 ERROR keystone.server.flask.application   File "/var/lib/kolla/venv/lib/python3.9/site-packages/decorator.py", line 232, in fun
2023-03-13 23:00:08.262535 2023-03-13 23:00:08.250 26 ERROR keystone.server.flask.application     return caller(func, *(extras + args), **kw)
2023-03-13 23:00:08.262562 2023-03-13 23:00:08.250 26 ERROR keystone.server.flask.application   File "/var/lib/kolla/venv/lib/python3.9/site-packages/dogpile/cache/region.py", line 1577, in get_or_create_for_user_func
2023-03-13 23:00:08.262577 2023-03-13 23:00:08.250 26 ERROR keystone.server.flask.application     return self.get_or_create(
2023-03-13 23:00:08.262586 2023-03-13 23:00:08.250 26 ERROR keystone.server.flask.application   File "/var/lib/kolla/venv/lib/python3.9/site-packages/dogpile/cache/region.py", line 1042, in get_or_create
2023-03-13 23:00:08.262599 2023-03-13 23:00:08.250 26 ERROR keystone.server.flask.application     with Lock(
2023-03-13 23:00:08.262608 2023-03-13 23:00:08.250 26 ERROR keystone.server.flask.application   File "/var/lib/kolla/venv/lib/python3.9/site-packages/dogpile/lock.py", line 185, in __enter__
2023-03-13 23:00:08.262618 2023-03-13 23:00:08.250 26 ERROR keystone.server.flask.application     return self._enter()
2023-03-13 23:00:08.262627 2023-03-13 23:00:08.250 26 ERROR keystone.server.flask.application   File "/var/lib/kolla/venv/lib/python3.9/site-packages/dogpile/lock.py", line 94, in _enter
2023-03-13 23:00:08.262641 2023-03-13 23:00:08.250 26 ERROR keystone.server.flask.application     generated = self._enter_create(value, createdtime)
2023-03-13 23:00:08.262660 2023-03-13 23:00:08.250 26 ERROR keystone.server.flask.application   File "/var/lib/kolla/venv/lib/python3.9/site-packages/dogpile/lock.py", line 178, in _enter_create
2023-03-13 23:00:08.262680 2023-03-13 23:00:08.250 26 ERROR keystone.server.flask.application     return self.creator()
2023-03-13 23:00:08.262700 2023-03-13 23:00:08.250 26 ERROR keystone.server.flask.application   File "/var/lib/kolla/venv/lib/python3.9/site-packages/dogpile/cache/region.py", line 995, in gen_value
2023-03-13 23:00:08.262722 2023-03-13 23:00:08.250 26 ERROR keystone.server.flask.application     created_value = creator(
2023-03-13 23:00:08.262744 2023-03-13 23:00:08.250 26 ERROR keystone.server.flask.application   File "/var/lib/kolla/venv/lib/python3.9/site-packages/keystone/resource/core.py", line 903, in get_project
2023-03-13 23:00:08.262765 2023-03-13 23:00:08.250 26 ERROR keystone.server.flask.application     return self.driver.get_project(project_id)
2023-03-13 23:00:08.262819 2023-03-13 23:00:08.250 26 ERROR keystone.server.flask.application   File "/var/lib/kolla/venv/lib/python3.9/site-packages/keystone/resource/backends/sql.py", line 49, in get_project
2023-03-13 23:00:08.262847 2023-03-13 23:00:08.250 26 ERROR keystone.server.flask.application     return self._get_project(session, project_id).to_dict()
2023-03-13 23:00:08.262867 2023-03-13 23:00:08.250 26 ERROR keystone.server.flask.application   File "/var/lib/kolla/venv/lib/python3.9/site-packages/keystone/resource/backends/sql.py", line 44, in _get_project
2023-03-13 23:00:08.262889 2023-03-13 23:00:08.250 26 ERROR keystone.server.flask.application     raise exception.ProjectNotFound(project_id=project_id)
2023-03-13 23:00:08.262910 2023-03-13 23:00:08.250 26 ERROR keystone.server.flask.application keystone.exception.ProjectNotFound: Could not find project: service.
2023-03-13 23:00:08.262932 2023-03-13 23:00:08.250 26 ERROR keystone.server.flask.application \x1b[00m
2023-03-13 23:00:19.252861 2023-03-13 23:00:19.245 28 ERROR keystone.server.flask.application [None req-886f6075-5898-4acd-89a6-89f403927cbb 2f52da95b5904fb7821d1158394f777c - - all default -] Could not find role: admin.: keystone.exception.RoleNotFound: Could not find role: admin.
2023-03-13 23:00:19.252922 2023-03-13 23:00:19.245 28 ERROR keystone.server.flask.application Traceback (most recent call last):
2023-03-13 23:00:19.252935 2023-03-13 23:00:19.245 28 ERROR keystone.server.flask.application   File "/var/lib/kolla/venv/lib/python3.9/site-packages/flask/app.py", line 1820, in full_dispatch_request
2023-03-13 23:00:19.252945 2023-03-13 23:00:19.245 28 ERROR keystone.server.flask.application     rv = self.dispatch_request()
2023-03-13 23:00:19.252955 2023-03-13 23:00:19.245 28 ERROR keystone.server.flask.application   File "/var/lib/kolla/venv/lib/python3.9/site-packages/flask/app.py", line 1796, in dispatch_request
2023-03-13 23:00:19.252979 2023-03-13 23:00:19.245 28 ERROR keystone.server.flask.application     return self.ensure_sync(self.view_functions[rule.endpoint])(**view_args)
2023-03-13 23:00:19.252990 2023-03-13 23:00:19.245 28 ERROR keystone.server.flask.application   File "/var/lib/kolla/venv/lib/python3.9/site-packages/flask_restful/__init__.py", line 467, in wrapper
2023-03-13 23:00:19.253000 2023-03-13 23:00:19.245 28 ERROR keystone.server.flask.application     resp = resource(*args, **kwargs)
2023-03-13 23:00:19.253024 2023-03-13 23:00:19.245 28 ERROR keystone.server.flask.application   File "/var/lib/kolla/venv/lib/python3.9/site-packages/flask/views.py", line 107, in view
2023-03-13 23:00:19.253036 2023-03-13 23:00:19.245 28 ERROR keystone.server.flask.application     return current_app.ensure_sync(self.dispatch_request)(**kwargs)
2023-03-13 23:00:19.253046 2023-03-13 23:00:19.245 28 ERROR keystone.server.flask.application   File "/var/lib/kolla/venv/lib/python3.9/site-packages/flask_restful/__init__.py", line 582, in dispatch_request
2023-03-13 23:00:19.253056 2023-03-13 23:00:19.245 28 ERROR keystone.server.flask.application     resp = meth(*args, **kwargs)
2023-03-13 23:00:19.253066 2023-03-13 23:00:19.245 28 ERROR keystone.server.flask.application   File "/var/lib/kolla/venv/lib/python3.9/site-packages/keystone/api/roles.py", line 50, in get
2023-03-13 23:00:19.253076 2023-03-13 23:00:19.245 28 ERROR keystone.server.flask.application     return self._get_role(role_id)
2023-03-13 23:00:19.253085 2023-03-13 23:00:19.245 28 ERROR keystone.server.flask.application   File "/var/lib/kolla/venv/lib/python3.9/site-packages/keystone/api/roles.py", line 70, in _get_role
2023-03-13 23:00:19.253095 2023-03-13 23:00:19.245 28 ERROR keystone.server.flask.application     ENFORCER.enforce_call(action='identity:get_role')
2023-03-13 23:00:19.253135 2023-03-13 23:00:19.245 28 ERROR keystone.server.flask.application   File "/var/lib/kolla/venv/lib/python3.9/site-packages/keystone/common/rbac_enforcer/enforcer.py", line 402, in enforce_call
2023-03-13 23:00:19.253152 2023-03-13 23:00:19.245 28 ERROR keystone.server.flask.application     policy_dict.update(cls._extract_member_target_data(
2023-03-13 23:00:19.253163 2023-03-13 23:00:19.245 28 ERROR keystone.server.flask.application   File "/var/lib/kolla/venv/lib/python3.9/site-packages/keystone/common/rbac_enforcer/enforcer.py", line 234, in _extract_member_target_data
2023-03-13 23:00:19.253174 2023-03-13 23:00:19.245 28 ERROR keystone.server.flask.application     member_name: func(flask.request.view_args[key])
2023-03-13 23:00:19.253184 2023-03-13 23:00:19.245 28 ERROR keystone.server.flask.application   File "/var/lib/kolla/venv/lib/python3.9/site-packages/keystone/common/manager.py", line 115, in wrapped
2023-03-13 23:00:19.253193 2023-03-13 23:00:19.245 28 ERROR keystone.server.flask.application     __ret_val = __f(*args, **kwargs)
2023-03-13 23:00:19.253203 2023-03-13 23:00:19.245 28 ERROR keystone.server.flask.application   File "/var/lib/kolla/venv/lib/python3.9/site-packages/decorator.py", line 232, in fun
2023-03-13 23:00:19.253213 2023-03-13 23:00:19.245 28 ERROR keystone.server.flask.application     return caller(func, *(extras + args), **kw)
2023-03-13 23:00:19.253223 2023-03-13 23:00:19.245 28 ERROR keystone.server.flask.application   File "/var/lib/kolla/venv/lib/python3.9/site-packages/dogpile/cache/region.py", line 1577, in get_or_create_for_user_func
2023-03-13 23:00:19.253232 2023-03-13 23:00:19.245 28 ERROR keystone.server.flask.application     return self.get_or_create(
2023-03-13 23:00:19.253242 2023-03-13 23:00:19.245 28 ERROR keystone.server.flask.application   File "/var/lib/kolla/venv/lib/python3.9/site-packages/dogpile/cache/region.py", line 1042, in get_or_create
2023-03-13 23:00:19.253252 2023-03-13 23:00:19.245 28 ERROR keystone.server.flask.application     with Lock(
2023-03-13 23:00:19.253274 2023-03-13 23:00:19.245 28 ERROR keystone.server.flask.application   File "/var/lib/kolla/venv/lib/python3.9/site-packages/dogpile/lock.py", line 185, in __enter__
2023-03-13 23:00:19.253286 2023-03-13 23:00:19.245 28 ERROR keystone.server.flask.application     return self._enter()
2023-03-13 23:00:19.253295 2023-03-13 23:00:19.245 28 ERROR keystone.server.flask.application   File "/var/lib/kolla/venv/lib/python3.9/site-packages/dogpile/lock.py", line 94, in _enter
2023-03-13 23:00:19.253305 2023-03-13 23:00:19.245 28 ERROR keystone.server.flask.application     generated = self._enter_create(value, createdtime)
2023-03-13 23:00:19.253315 2023-03-13 23:00:19.245 28 ERROR keystone.server.flask.application   File "/var/lib/kolla/venv/lib/python3.9/site-packages/dogpile/lock.py", line 178, in _enter_create
2023-03-13 23:00:19.253325 2023-03-13 23:00:19.245 28 ERROR keystone.server.flask.application     return self.creator()
2023-03-13 23:00:19.253334 2023-03-13 23:00:19.245 28 ERROR keystone.server.flask.application   File "/var/lib/kolla/venv/lib/python3.9/site-packages/dogpile/cache/region.py", line 995, in gen_value
2023-03-13 23:00:19.253344 2023-03-13 23:00:19.245 28 ERROR keystone.server.flask.application     created_value = creator(
2023-03-13 23:00:19.253353 2023-03-13 23:00:19.245 28 ERROR keystone.server.flask.application   File "/var/lib/kolla/venv/lib/python3.9/site-packages/keystone/assignment/core.py", line 1276, in get_role
2023-03-13 23:00:19.253363 2023-03-13 23:00:19.245 28 ERROR keystone.server.flask.application     return self.driver.get_role(role_id)
2023-03-13 23:00:19.253373 2023-03-13 23:00:19.245 28 ERROR keystone.server.flask.application   File "/var/lib/kolla/venv/lib/python3.9/site-packages/keystone/assignment/role_backends/sql.py", line 70, in get_role
2023-03-13 23:00:19.253383 2023-03-13 23:00:19.245 28 ERROR keystone.server.flask.application     return self._get_role(session, role_id).to_dict()
2023-03-13 23:00:19.253393 2023-03-13 23:00:19.245 28 ERROR keystone.server.flask.application   File "/var/lib/kolla/venv/lib/python3.9/site-packages/keystone/assignment/role_backends/sql.py", line 65, in _get_role
2023-03-13 23:00:19.253403 2023-03-13 23:00:19.245 28 ERROR keystone.server.flask.application     raise exception.RoleNotFound(role_id=role_id)
2023-03-13 23:00:19.253412 2023-03-13 23:00:19.245 28 ERROR keystone.server.flask.application keystone.exception.RoleNotFound: Could not find role: admin.
2023-03-13 23:00:19.253422 2023-03-13 23:00:19.245 28 ERROR keystone.server.flask.application \x1b[00m
2023-03-13 23:00:20.885617 2023-03-13 23:00:20.878 28 ERROR keystone.server.flask.application [None req-86bf0287-4006-4f15-aee3-2a429a1f28cc 2f52da95b5904fb7821d1158394f777c - - all default -] Could not find user: ironic-inspector.: keystone.exception.UserNotFound: Could not find user: ironic-inspector.
2023-03-13 23:00:20.885687 2023-03-13 23:00:20.878 28 ERROR keystone.server.flask.application Traceback (most recent call last):
2023-03-13 23:00:20.885720 2023-03-13 23:00:20.878 28 ERROR keystone.server.flask.application   File "/var/lib/kolla/venv/lib/python3.9/site-packages/flask/app.py", line 1820, in full_dispatch_request
2023-03-13 23:00:20.885730 2023-03-13 23:00:20.878 28 ERROR keystone.server.flask.application     rv = self.dispatch_request()
2023-03-13 23:00:20.885741 2023-03-13 23:00:20.878 28 ERROR keystone.server.flask.application   File "/var/lib/kolla/venv/lib/python3.9/site-packages/flask/app.py", line 1796, in dispatch_request
2023-03-13 23:00:20.885753 2023-03-13 23:00:20.878 28 ERROR keystone.server.flask.application     return self.ensure_sync(self.view_functions[rule.endpoint])(**view_args)
2023-03-13 23:00:20.885762 2023-03-13 23:00:20.878 28 ERROR keystone.server.flask.application   File "/var/lib/kolla/venv/lib/python3.9/site-packages/flask_restful/__init__.py", line 467, in wrapper
2023-03-13 23:00:20.885772 2023-03-13 23:00:20.878 28 ERROR keystone.server.flask.application     resp = resource(*args, **kwargs)
2023-03-13 23:00:20.885813 2023-03-13 23:00:20.878 28 ERROR keystone.server.flask.application   File "/var/lib/kolla/venv/lib/python3.9/site-packages/flask/views.py", line 107, in view
2023-03-13 23:00:20.885851 2023-03-13 23:00:20.878 28 ERROR keystone.server.flask.application     return current_app.ensure_sync(self.dispatch_request)(**kwargs)
2023-03-13 23:00:20.885864 2023-03-13 23:00:20.878 28 ERROR keystone.server.flask.application   File "/var/lib/kolla/venv/lib/python3.9/site-packages/flask_restful/__init__.py", line 582, in dispatch_request
2023-03-13 23:00:20.885874 2023-03-13 23:00:20.878 28 ERROR keystone.server.flask.application     resp = meth(*args, **kwargs)
2023-03-13 23:00:20.885884 2023-03-13 23:00:20.878 28 ERROR keystone.server.flask.application   File "/var/lib/kolla/venv/lib/python3.9/site-packages/keystone/api/users.py", line 182, in get
2023-03-13 23:00:20.885893 2023-03-13 23:00:20.878 28 ERROR keystone.server.flask.application     return self._get_user(user_id)
2023-03-13 23:00:20.885903 2023-03-13 23:00:20.878 28 ERROR keystone.server.flask.application   File "/var/lib/kolla/venv/lib/python3.9/site-packages/keystone/api/users.py", line 194, in _get_user
2023-03-13 23:00:20.885913 2023-03-13 23:00:20.878 28 ERROR keystone.server.flask.application     ref = PROVIDERS.identity_api.get_user(user_id)
2023-03-13 23:00:20.885923 2023-03-13 23:00:20.878 28 ERROR keystone.server.flask.application   File "/var/lib/kolla/venv/lib/python3.9/site-packages/keystone/common/manager.py", line 115, in wrapped
2023-03-13 23:00:20.885933 2023-03-13 23:00:20.878 28 ERROR keystone.server.flask.application     __ret_val = __f(*args, **kwargs)
2023-03-13 23:00:20.885942 2023-03-13 23:00:20.878 28 ERROR keystone.server.flask.application   File "/var/lib/kolla/venv/lib/python3.9/site-packages/keystone/identity/core.py", line 414, in wrapper
2023-03-13 23:00:20.885952 2023-03-13 23:00:20.878 28 ERROR keystone.server.flask.application     return f(self, *args, **kwargs)
2023-03-13 23:00:20.885962 2023-03-13 23:00:20.878 28 ERROR keystone.server.flask.application   File "/var/lib/kolla/venv/lib/python3.9/site-packages/keystone/identity/core.py", line 424, in wrapper
2023-03-13 23:00:20.885971 2023-03-13 23:00:20.878 28 ERROR keystone.server.flask.application     return f(self, *args, **kwargs)
2023-03-13 23:00:20.885981 2023-03-13 23:00:20.878 28 ERROR keystone.server.flask.application   File "/var/lib/kolla/venv/lib/python3.9/site-packages/decorator.py", line 232, in fun
2023-03-13 23:00:20.885990 2023-03-13 23:00:20.878 28 ERROR keystone.server.flask.application     return caller(func, *(extras + args), **kw)
2023-03-13 23:00:20.886001 2023-03-13 23:00:20.878 28 ERROR keystone.server.flask.application   File "/var/lib/kolla/venv/lib/python3.9/site-packages/dogpile/cache/region.py", line 1577, in get_or_create_for_user_func
2023-03-13 23:00:20.886011 2023-03-13 23:00:20.878 28 ERROR keystone.server.flask.application     return self.get_or_create(
2023-03-13 23:00:20.886021 2023-03-13 23:00:20.878 28 ERROR keystone.server.flask.application   File "/var/lib/kolla/venv/lib/python3.9/site-packages/dogpile/cache/region.py", line 1042, in get_or_create
2023-03-13 23:00:20.886040 2023-03-13 23:00:20.878 28 ERROR keystone.server.flask.application     with Lock(
2023-03-13 23:00:20.886051 2023-03-13 23:00:20.878 28 ERROR keystone.server.flask.application   File "/var/lib/kolla/venv/lib/python3.9/site-packages/dogpile/lock.py", line 185, in __enter__
2023-03-13 23:00:20.886070 2023-03-13 23:00:20.878 28 ERROR keystone.server.flask.application     return self._enter()
2023-03-13 23:00:20.886104 2023-03-13 23:00:20.878 28 ERROR keystone.server.flask.application   File "/var/lib/kolla/venv/lib/python3.9/site-packages/dogpile/lock.py", line 94, in _enter
2023-03-13 23:00:20.886166 2023-03-13 23:00:20.878 28 ERROR keystone.server.flask.application     generated = self._enter_create(value, createdtime)
2023-03-13 23:00:20.886177 2023-03-13 23:00:20.878 28 ERROR keystone.server.flask.application   File "/var/lib/kolla/venv/lib/python3.9/site-packages/dogpile/lock.py", line 178, in _enter_create
2023-03-13 23:00:20.886209 2023-03-13 23:00:20.878 28 ERROR keystone.server.flask.application     return self.creator()
2023-03-13 23:00:20.886222 2023-03-13 23:00:20.878 28 ERROR keystone.server.flask.application   File "/var/lib/kolla/venv/lib/python3.9/site-packages/dogpile/cache/region.py", line 995, in gen_value
2023-03-13 23:00:20.886232 2023-03-13 23:00:20.878 28 ERROR keystone.server.flask.application     created_value = creator(
2023-03-13 23:00:20.886241 2023-03-13 23:00:20.878 28 ERROR keystone.server.flask.application   File "/var/lib/kolla/venv/lib/python3.9/site-packages/keystone/identity/core.py", line 1011, in get_user
2023-03-13 23:00:20.886251 2023-03-13 23:00:20.878 28 ERROR keystone.server.flask.application     ref = driver.get_user(entity_id)
2023-03-13 23:00:20.886261 2023-03-13 23:00:20.878 28 ERROR keystone.server.flask.application   File "/var/lib/kolla/venv/lib/python3.9/site-packages/keystone/identity/backends/sql.py", line 200, in get_user
2023-03-13 23:00:20.886271 2023-03-13 23:00:20.878 28 ERROR keystone.server.flask.application     self._get_user(session, user_id).to_dict())
2023-03-13 23:00:20.886280 2023-03-13 23:00:20.878 28 ERROR keystone.server.flask.application   File "/var/lib/kolla/venv/lib/python3.9/site-packages/keystone/identity/backends/sql.py", line 194, in _get_user
2023-03-13 23:00:20.886290 2023-03-13 23:00:20.878 28 ERROR keystone.server.flask.application     raise exception.UserNotFound(user_id=user_id)
2023-03-13 23:00:20.886300 2023-03-13 23:00:20.878 28 ERROR keystone.server.flask.application keystone.exception.UserNotFound: Could not find user: ironic-inspector.
2023-03-13 23:00:20.886314 2023-03-13 23:00:20.878 28 ERROR keystone.server.flask.application \x1b[00m
2023-03-13 23:00:21.878066 2023-03-13 23:00:21.872 27 ERROR keystone.server.flask.application [None req-eff6ca0c-0d8e-4aef-8cd8-8894e44af1d5 2f52da95b5904fb7821d1158394f777c - - all default -] Could not find project: service.: keystone.exception.ProjectNotFound: Could not find project: service.
2023-03-13 23:00:21.878307 2023-03-13 23:00:21.872 27 ERROR keystone.server.flask.application Traceback (most recent call last):
2023-03-13 23:00:21.878343 2023-03-13 23:00:21.872 27 ERROR keystone.server.flask.application   File "/var/lib/kolla/venv/lib/python3.9/site-packages/flask/app.py", line 1820, in full_dispatch_request
2023-03-13 23:00:21.878375 2023-03-13 23:00:21.872 27 ERROR keystone.server.flask.application     rv = self.dispatch_request()
2023-03-13 23:00:21.878405 2023-03-13 23:00:21.872 27 ERROR keystone.server.flask.application   File "/var/lib/kolla/venv/lib/python3.9/site-packages/flask/app.py", line 1796, in dispatch_request
2023-03-13 23:00:21.878435 2023-03-13 23:00:21.872 27 ERROR keystone.server.flask.application     return self.ensure_sync(self.view_functions[rule.endpoint])(**view_args)
2023-03-13 23:00:21.878463 2023-03-13 23:00:21.872 27 ERROR keystone.server.flask.application   File "/var/lib/kolla/venv/lib/python3.9/site-packages/flask_restful/__init__.py", line 467, in wrapper
2023-03-13 23:00:21.878492 2023-03-13 23:00:21.872 27 ERROR keystone.server.flask.application     resp = resource(*args, **kwargs)
2023-03-13 23:00:21.878538 2023-03-13 23:00:21.872 27 ERROR keystone.server.flask.application   File "/var/lib/kolla/venv/lib/python3.9/site-packages/flask/views.py", line 107, in view
2023-03-13 23:00:21.878589 2023-03-13 23:00:21.872 27 ERROR keystone.server.flask.application     return current_app.ensure_sync(self.dispatch_request)(**kwargs)
2023-03-13 23:00:21.878642 2023-03-13 23:00:21.872 27 ERROR keystone.server.flask.application   File "/var/lib/kolla/venv/lib/python3.9/site-packages/flask_restful/__init__.py", line 582, in dispatch_request
2023-03-13 23:00:21.878664 2023-03-13 23:00:21.872 27 ERROR keystone.server.flask.application     resp = meth(*args, **kwargs)
2023-03-13 23:00:21.878687 2023-03-13 23:00:21.872 27 ERROR keystone.server.flask.application   File "/var/lib/kolla/venv/lib/python3.9/site-packages/keystone/api/projects.py", line 151, in get
2023-03-13 23:00:21.878747 2023-03-13 23:00:21.872 27 ERROR keystone.server.flask.application     return self._get_project(project_id)
2023-03-13 23:00:21.878772 2023-03-13 23:00:21.872 27 ERROR keystone.server.flask.application   File "/var/lib/kolla/venv/lib/python3.9/site-packages/keystone/api/projects.py", line 107, in _get_project
2023-03-13 23:00:21.878792 2023-03-13 23:00:21.872 27 ERROR keystone.server.flask.application     project = PROVIDERS.resource_api.get_project(project_id)
2023-03-13 23:00:21.878858 2023-03-13 23:00:21.872 27 ERROR keystone.server.flask.application   File "/var/lib/kolla/venv/lib/python3.9/site-packages/keystone/common/manager.py", line 115, in wrapped
2023-03-13 23:00:21.878889 2023-03-13 23:00:21.872 27 ERROR keystone.server.flask.application     __ret_val = __f(*args, **kwargs)
2023-03-13 23:00:21.878919 2023-03-13 23:00:21.872 27 ERROR keystone.server.flask.application   File "/var/lib/kolla/venv/lib/python3.9/site-packages/decorator.py", line 232, in fun
2023-03-13 23:00:21.878947 2023-03-13 23:00:21.872 27 ERROR keystone.server.flask.application     return caller(func, *(extras + args), **kw)
2023-03-13 23:00:21.878977 2023-03-13 23:00:21.872 27 ERROR keystone.server.flask.application   File "/var/lib/kolla/venv/lib/python3.9/site-packages/dogpile/cache/region.py", line 1577, in get_or_create_for_user_func
2023-03-13 23:00:21.879006 2023-03-13 23:00:21.872 27 ERROR keystone.server.flask.application     return self.get_or_create(
2023-03-13 23:00:21.879036 2023-03-13 23:00:21.872 27 ERROR keystone.server.flask.application   File "/var/lib/kolla/venv/lib/python3.9/site-packages/dogpile/cache/region.py", line 1042, in get_or_create
2023-03-13 23:00:21.879056 2023-03-13 23:00:21.872 27 ERROR keystone.server.flask.application     with Lock(
2023-03-13 23:00:21.879076 2023-03-13 23:00:21.872 27 ERROR keystone.server.flask.application   File "/var/lib/kolla/venv/lib/python3.9/site-packages/dogpile/lock.py", line 185, in __enter__
2023-03-13 23:00:21.879607 2023-03-13 23:00:21.872 27 ERROR keystone.server.flask.application     return self._enter()
2023-03-13 23:00:21.879640 2023-03-13 23:00:21.872 27 ERROR keystone.server.flask.application   File "/var/lib/kolla/venv/lib/python3.9/site-packages/dogpile/lock.py", line 94, in _enter
2023-03-13 23:00:21.879669 2023-03-13 23:00:21.872 27 ERROR keystone.server.flask.application     generated = self._enter_create(value, createdtime)
2023-03-13 23:00:21.879698 2023-03-13 23:00:21.872 27 ERROR keystone.server.flask.application   File "/var/lib/kolla/venv/lib/python3.9/site-packages/dogpile/lock.py", line 178, in _enter_create
2023-03-13 23:00:21.879733 2023-03-13 23:00:21.872 27 ERROR keystone.server.flask.application     return self.creator()
2023-03-13 23:00:21.879761 2023-03-13 23:00:21.872 27 ERROR keystone.server.flask.application   File "/var/lib/kolla/venv/lib/python3.9/site-packages/dogpile/cache/region.py", line 995, in gen_value
2023-03-13 23:00:21.879824 2023-03-13 23:00:21.872 27 ERROR keystone.server.flask.application     created_value = creator(
2023-03-13 23:00:21.879896 2023-03-13 23:00:21.872 27 ERROR keystone.server.flask.application   File "/var/lib/kolla/venv/lib/python3.9/site-packages/keystone/resource/core.py", line 903, in get_project
2023-03-13 23:00:21.879919 2023-03-13 23:00:21.872 27 ERROR keystone.server.flask.application     return self.driver.get_project(project_id)
2023-03-13 23:00:21.879945 2023-03-13 23:00:21.872 27 ERROR keystone.server.flask.application   File "/var/lib/kolla/venv/lib/python3.9/site-packages/keystone/resource/backends/sql.py", line 49, in get_project
2023-03-13 23:00:21.879965 2023-03-13 23:00:21.872 27 ERROR keystone.server.flask.application     return self._get_project(session, project_id).to_dict()
2023-03-13 23:00:21.879984 2023-03-13 23:00:21.872 27 ERROR keystone.server.flask.application   File "/var/lib/kolla/venv/lib/python3.9/site-packages/keystone/resource/backends/sql.py", line 44, in _get_project
2023-03-13 23:00:21.880006 2023-03-13 23:00:21.872 27 ERROR keystone.server.flask.application     raise exception.ProjectNotFound(project_id=project_id)
2023-03-13 23:00:21.880064 2023-03-13 23:00:21.872 27 ERROR keystone.server.flask.application keystone.exception.ProjectNotFound: Could not find project: service.
2023-03-13 23:00:21.880084 2023-03-13 23:00:21.872 27 ERROR keystone.server.flask.application \x1b[00m
2023-03-13 23:03:24.533285 2023-03-13 23:03:24.529 27 ERROR keystone.server.flask.application [None req-1103e4ca-7b86-45df-8b6c-d3d1749fc640 2f52da95b5904fb7821d1158394f777c - - all default -] Could not find project: service.: keystone.exception.ProjectNotFound: Could not find project: service.
2023-03-13 23:03:24.533356 2023-03-13 23:03:24.529 27 ERROR keystone.server.flask.application Traceback (most recent call last):
2023-03-13 23:03:24.533372 2023-03-13 23:03:24.529 27 ERROR keystone.server.flask.application   File "/var/lib/kolla/venv/lib/python3.9/site-packages/flask/app.py", line 1820, in full_dispatch_request
2023-03-13 23:03:24.533385 2023-03-13 23:03:24.529 27 ERROR keystone.server.flask.application     rv = self.dispatch_request()
2023-03-13 23:03:24.533397 2023-03-13 23:03:24.529 27 ERROR keystone.server.flask.application   File "/var/lib/kolla/venv/lib/python3.9/site-packages/flask/app.py", line 1796, in dispatch_request
2023-03-13 23:03:24.533410 2023-03-13 23:03:24.529 27 ERROR keystone.server.flask.application     return self.ensure_sync(self.view_functions[rule.endpoint])(**view_args)
2023-03-13 23:03:24.533422 2023-03-13 23:03:24.529 27 ERROR keystone.server.flask.application   File "/var/lib/kolla/venv/lib/python3.9/site-packages/flask_restful/__init__.py", line 467, in wrapper
2023-03-13 23:03:24.533448 2023-03-13 23:03:24.529 27 ERROR keystone.server.flask.application     resp = resource(*args, **kwargs)
2023-03-13 23:03:24.533460 2023-03-13 23:03:24.529 27 ERROR keystone.server.flask.application   File "/var/lib/kolla/venv/lib/python3.9/site-packages/flask/views.py", line 107, in view
2023-03-13 23:03:24.533472 2023-03-13 23:03:24.529 27 ERROR keystone.server.flask.application     return current_app.ensure_sync(self.dispatch_request)(**kwargs)
2023-03-13 23:03:24.533484 2023-03-13 23:03:24.529 27 ERROR keystone.server.flask.application   File "/var/lib/kolla/venv/lib/python3.9/site-packages/flask_restful/__init__.py", line 582, in dispatch_request
2023-03-13 23:03:24.533496 2023-03-13 23:03:24.529 27 ERROR keystone.server.flask.application     resp = meth(*args, **kwargs)
2023-03-13 23:03:24.533508 2023-03-13 23:03:24.529 27 ERROR keystone.server.flask.application   File "/var/lib/kolla/venv/lib/python3.9/site-packages/keystone/api/projects.py", line 151, in get
2023-03-13 23:03:24.533521 2023-03-13 23:03:24.529 27 ERROR keystone.server.flask.application     return self._get_project(project_id)
2023-03-13 23:03:24.533533 2023-03-13 23:03:24.529 27 ERROR keystone.server.flask.application   File "/var/lib/kolla/venv/lib/python3.9/site-packages/keystone/api/projects.py", line 107, in _get_project
2023-03-13 23:03:24.533545 2023-03-13 23:03:24.529 27 ERROR keystone.server.flask.application     project = PROVIDERS.resource_api.get_project(project_id)
2023-03-13 23:03:24.533557 2023-03-13 23:03:24.529 27 ERROR keystone.server.flask.application   File "/var/lib/kolla/venv/lib/python3.9/site-packages/keystone/common/manager.py", line 115, in wrapped
2023-03-13 23:03:24.533569 2023-03-13 23:03:24.529 27 ERROR keystone.server.flask.application     __ret_val = __f(*args, **kwargs)
2023-03-13 23:03:24.533581 2023-03-13 23:03:24.529 27 ERROR keystone.server.flask.application   File "/var/lib/kolla/venv/lib/python3.9/site-packages/decorator.py", line 232, in fun
2023-03-13 23:03:24.533593 2023-03-13 23:03:24.529 27 ERROR keystone.server.flask.application     return caller(func, *(extras + args), **kw)
2023-03-13 23:03:24.533605 2023-03-13 23:03:24.529 27 ERROR keystone.server.flask.application   File "/var/lib/kolla/venv/lib/python3.9/site-packages/dogpile/cache/region.py", line 1577, in get_or_create_for_user_func
2023-03-13 23:03:24.533618 2023-03-13 23:03:24.529 27 ERROR keystone.server.flask.application     return self.get_or_create(
2023-03-13 23:03:24.533659 2023-03-13 23:03:24.529 27 ERROR keystone.server.flask.application   File "/var/lib/kolla/venv/lib/python3.9/site-packages/dogpile/cache/region.py", line 1042, in get_or_create
2023-03-13 23:03:24.533674 2023-03-13 23:03:24.529 27 ERROR keystone.server.flask.application     with Lock(
2023-03-13 23:03:24.533686 2023-03-13 23:03:24.529 27 ERROR keystone.server.flask.application   File "/var/lib/kolla/venv/lib/python3.9/site-packages/dogpile/lock.py", line 185, in __enter__
2023-03-13 23:03:24.533699 2023-03-13 23:03:24.529 27 ERROR keystone.server.flask.application     return self._enter()
2023-03-13 23:03:24.533710 2023-03-13 23:03:24.529 27 ERROR keystone.server.flask.application   File "/var/lib/kolla/venv/lib/python3.9/site-packages/dogpile/lock.py", line 94, in _enter
2023-03-13 23:03:24.533723 2023-03-13 23:03:24.529 27 ERROR keystone.server.flask.application     generated = self._enter_create(value, createdtime)
2023-03-13 23:03:24.533735 2023-03-13 23:03:24.529 27 ERROR keystone.server.flask.application   File "/var/lib/kolla/venv/lib/python3.9/site-packages/dogpile/lock.py", line 178, in _enter_create
2023-03-13 23:03:24.533747 2023-03-13 23:03:24.529 27 ERROR keystone.server.flask.application     return self.creator()
2023-03-13 23:03:24.533759 2023-03-13 23:03:24.529 27 ERROR keystone.server.flask.application   File "/var/lib/kolla/venv/lib/python3.9/site-packages/dogpile/cache/region.py", line 995, in gen_value
2023-03-13 23:03:24.533771 2023-03-13 23:03:24.529 27 ERROR keystone.server.flask.application     created_value = creator(
2023-03-13 23:03:24.533806 2023-03-13 23:03:24.529 27 ERROR keystone.server.flask.application   File "/var/lib/kolla/venv/lib/python3.9/site-packages/keystone/resource/core.py", line 903, in get_project
2023-03-13 23:03:24.533819 2023-03-13 23:03:24.529 27 ERROR keystone.server.flask.application     return self.driver.get_project(project_id)
2023-03-13 23:03:24.533831 2023-03-13 23:03:24.529 27 ERROR keystone.server.flask.application   File "/var/lib/kolla/venv/lib/python3.9/site-packages/keystone/resource/backends/sql.py", line 49, in get_project
2023-03-13 23:03:24.533843 2023-03-13 23:03:24.529 27 ERROR keystone.server.flask.application     return self._get_project(session, project_id).to_dict()
2023-03-13 23:03:24.533855 2023-03-13 23:03:24.529 27 ERROR keystone.server.flask.application   File "/var/lib/kolla/venv/lib/python3.9/site-packages/keystone/resource/backends/sql.py", line 44, in _get_project
2023-03-13 23:03:24.533867 2023-03-13 23:03:24.529 27 ERROR keystone.server.flask.application     raise exception.ProjectNotFound(project_id=project_id)
2023-03-13 23:03:24.533879 2023-03-13 23:03:24.529 27 ERROR keystone.server.flask.application keystone.exception.ProjectNotFound: Could not find project: service.
2023-03-13 23:03:24.533890 2023-03-13 23:03:24.529 27 ERROR keystone.server.flask.application \x1b[00m
2023-03-13 23:03:39.183209 2023-03-13 23:03:39.171 26 ERROR keystone.server.flask.application [None req-aa53a5ae-d1ba-476f-a8c5-e893ea3a16f6 2f52da95b5904fb7821d1158394f777c - - all default -] Could not find role: admin.: keystone.exception.RoleNotFound: Could not find role: admin.
2023-03-13 23:03:39.183288 2023-03-13 23:03:39.171 26 ERROR keystone.server.flask.application Traceback (most recent call last):
2023-03-13 23:03:39.183303 2023-03-13 23:03:39.171 26 ERROR keystone.server.flask.application   File "/var/lib/kolla/venv/lib/python3.9/site-packages/flask/app.py", line 1820, in full_dispatch_request
2023-03-13 23:03:39.183317 2023-03-13 23:03:39.171 26 ERROR keystone.server.flask.application     rv = self.dispatch_request()
2023-03-13 23:03:39.183329 2023-03-13 23:03:39.171 26 ERROR keystone.server.flask.application   File "/var/lib/kolla/venv/lib/python3.9/site-packages/flask/app.py", line 1796, in dispatch_request
2023-03-13 23:03:39.183342 2023-03-13 23:03:39.171 26 ERROR keystone.server.flask.application     return self.ensure_sync(self.view_functions[rule.endpoint])(**view_args)
2023-03-13 23:03:39.183354 2023-03-13 23:03:39.171 26 ERROR keystone.server.flask.application   File "/var/lib/kolla/venv/lib/python3.9/site-packages/flask_restful/__init__.py", line 467, in wrapper
2023-03-13 23:03:39.183400 2023-03-13 23:03:39.171 26 ERROR keystone.server.flask.application     resp = resource(*args, **kwargs)
2023-03-13 23:03:39.183413 2023-03-13 23:03:39.171 26 ERROR keystone.server.flask.application   File "/var/lib/kolla/venv/lib/python3.9/site-packages/flask/views.py", line 107, in view
2023-03-13 23:03:39.183426 2023-03-13 23:03:39.171 26 ERROR keystone.server.flask.application     return current_app.ensure_sync(self.dispatch_request)(**kwargs)
2023-03-13 23:03:39.183438 2023-03-13 23:03:39.171 26 ERROR keystone.server.flask.application   File "/var/lib/kolla/venv/lib/python3.9/site-packages/flask_restful/__init__.py", line 582, in dispatch_request
2023-03-13 23:03:39.183451 2023-03-13 23:03:39.171 26 ERROR keystone.server.flask.application     resp = meth(*args, **kwargs)
2023-03-13 23:03:39.183463 2023-03-13 23:03:39.171 26 ERROR keystone.server.flask.application   File "/var/lib/kolla/venv/lib/python3.9/site-packages/keystone/api/roles.py", line 50, in get
2023-03-13 23:03:39.183482 2023-03-13 23:03:39.171 26 ERROR keystone.server.flask.application     return self._get_role(role_id)
2023-03-13 23:03:39.183494 2023-03-13 23:03:39.171 26 ERROR keystone.server.flask.application   File "/var/lib/kolla/venv/lib/python3.9/site-packages/keystone/api/roles.py", line 70, in _get_role
2023-03-13 23:03:39.183506 2023-03-13 23:03:39.171 26 ERROR keystone.server.flask.application     ENFORCER.enforce_call(action='identity:get_role')
2023-03-13 23:03:39.183518 2023-03-13 23:03:39.171 26 ERROR keystone.server.flask.application   File "/var/lib/kolla/venv/lib/python3.9/site-packages/keystone/common/rbac_enforcer/enforcer.py", line 402, in enforce_call
2023-03-13 23:03:39.183531 2023-03-13 23:03:39.171 26 ERROR keystone.server.flask.application     policy_dict.update(cls._extract_member_target_data(
2023-03-13 23:03:39.183543 2023-03-13 23:03:39.171 26 ERROR keystone.server.flask.application   File "/var/lib/kolla/venv/lib/python3.9/site-packages/keystone/common/rbac_enforcer/enforcer.py", line 234, in _extract_member_target_data
2023-03-13 23:03:39.183556 2023-03-13 23:03:39.171 26 ERROR keystone.server.flask.application     member_name: func(flask.request.view_args[key])
2023-03-13 23:03:39.183568 2023-03-13 23:03:39.171 26 ERROR keystone.server.flask.application   File "/var/lib/kolla/venv/lib/python3.9/site-packages/keystone/common/manager.py", line 115, in wrapped
2023-03-13 23:03:39.183580 2023-03-13 23:03:39.171 26 ERROR keystone.server.flask.application     __ret_val = __f(*args, **kwargs)
2023-03-13 23:03:39.183592 2023-03-13 23:03:39.171 26 ERROR keystone.server.flask.application   File "/var/lib/kolla/venv/lib/python3.9/site-packages/decorator.py", line 232, in fun
2023-03-13 23:03:39.183604 2023-03-13 23:03:39.171 26 ERROR keystone.server.flask.application     return caller(func, *(extras + args), **kw)
2023-03-13 23:03:39.183616 2023-03-13 23:03:39.171 26 ERROR keystone.server.flask.application   File "/var/lib/kolla/venv/lib/python3.9/site-packages/dogpile/cache/region.py", line 1577, in get_or_create_for_user_func
2023-03-13 23:03:39.183628 2023-03-13 23:03:39.171 26 ERROR keystone.server.flask.application     return self.get_or_create(
2023-03-13 23:03:39.183641 2023-03-13 23:03:39.171 26 ERROR keystone.server.flask.application   File "/var/lib/kolla/venv/lib/python3.9/site-packages/dogpile/cache/region.py", line 1042, in get_or_create
2023-03-13 23:03:39.183653 2023-03-13 23:03:39.171 26 ERROR keystone.server.flask.application     with Lock(
2023-03-13 23:03:39.183665 2023-03-13 23:03:39.171 26 ERROR keystone.server.flask.application   File "/var/lib/kolla/venv/lib/python3.9/site-packages/dogpile/lock.py", line 185, in __enter__
2023-03-13 23:03:39.183678 2023-03-13 23:03:39.171 26 ERROR keystone.server.flask.application     return self._enter()
2023-03-13 23:03:39.183690 2023-03-13 23:03:39.171 26 ERROR keystone.server.flask.application   File "/var/lib/kolla/venv/lib/python3.9/site-packages/dogpile/lock.py", line 94, in _enter
2023-03-13 23:03:39.183714 2023-03-13 23:03:39.171 26 ERROR keystone.server.flask.application     generated = self._enter_create(value, createdtime)
2023-03-13 23:03:39.183728 2023-03-13 23:03:39.171 26 ERROR keystone.server.flask.application   File "/var/lib/kolla/venv/lib/python3.9/site-packages/dogpile/lock.py", line 178, in _enter_create
2023-03-13 23:03:39.183741 2023-03-13 23:03:39.171 26 ERROR keystone.server.flask.application     return self.creator()
2023-03-13 23:03:39.183753 2023-03-13 23:03:39.171 26 ERROR keystone.server.flask.application   File "/var/lib/kolla/venv/lib/python3.9/site-packages/dogpile/cache/region.py", line 995, in gen_value
2023-03-13 23:03:39.183765 2023-03-13 23:03:39.171 26 ERROR keystone.server.flask.application     created_value = creator(
2023-03-13 23:03:39.183797 2023-03-13 23:03:39.171 26 ERROR keystone.server.flask.application   File "/var/lib/kolla/venv/lib/python3.9/site-packages/keystone/assignment/core.py", line 1276, in get_role
2023-03-13 23:03:39.183813 2023-03-13 23:03:39.171 26 ERROR keystone.server.flask.application     return self.driver.get_role(role_id)
2023-03-13 23:03:39.183825 2023-03-13 23:03:39.171 26 ERROR keystone.server.flask.application   File "/var/lib/kolla/venv/lib/python3.9/site-packages/keystone/assignment/role_backends/sql.py", line 70, in get_role
2023-03-13 23:03:39.183837 2023-03-13 23:03:39.171 26 ERROR keystone.server.flask.application     return self._get_role(session, role_id).to_dict()
2023-03-13 23:03:39.183849 2023-03-13 23:03:39.171 26 ERROR keystone.server.flask.application   File "/var/lib/kolla/venv/lib/python3.9/site-packages/keystone/assignment/role_backends/sql.py", line 65, in _get_role
2023-03-13 23:03:39.183861 2023-03-13 23:03:39.171 26 ERROR keystone.server.flask.application     raise exception.RoleNotFound(role_id=role_id)
2023-03-13 23:03:39.183873 2023-03-13 23:03:39.171 26 ERROR keystone.server.flask.application keystone.exception.RoleNotFound: Could not find role: admin.
2023-03-13 23:03:39.183884 2023-03-13 23:03:39.171 26 ERROR keystone.server.flask.application \x1b[00m
2023-03-13 23:03:40.476221 2023-03-13 23:03:40.470 26 ERROR keystone.server.flask.application [None req-dff7c437-7f7d-4344-a229-c63a95e7cb2b 2f52da95b5904fb7821d1158394f777c - - all default -] Could not find user: neutron.: keystone.exception.UserNotFound: Could not find user: neutron.
2023-03-13 23:03:40.476270 2023-03-13 23:03:40.470 26 ERROR keystone.server.flask.application Traceback (most recent call last):
2023-03-13 23:03:40.476282 2023-03-13 23:03:40.470 26 ERROR keystone.server.flask.application   File "/var/lib/kolla/venv/lib/python3.9/site-packages/flask/app.py", line 1820, in full_dispatch_request
2023-03-13 23:03:40.476293 2023-03-13 23:03:40.470 26 ERROR keystone.server.flask.application     rv = self.dispatch_request()
2023-03-13 23:03:40.476302 2023-03-13 23:03:40.470 26 ERROR keystone.server.flask.application   File "/var/lib/kolla/venv/lib/python3.9/site-packages/flask/app.py", line 1796, in dispatch_request
2023-03-13 23:03:40.476313 2023-03-13 23:03:40.470 26 ERROR keystone.server.flask.application     return self.ensure_sync(self.view_functions[rule.endpoint])(**view_args)
2023-03-13 23:03:40.476323 2023-03-13 23:03:40.470 26 ERROR keystone.server.flask.application   File "/var/lib/kolla/venv/lib/python3.9/site-packages/flask_restful/__init__.py", line 467, in wrapper
2023-03-13 23:03:40.476333 2023-03-13 23:03:40.470 26 ERROR keystone.server.flask.application     resp = resource(*args, **kwargs)
2023-03-13 23:03:40.476343 2023-03-13 23:03:40.470 26 ERROR keystone.server.flask.application   File "/var/lib/kolla/venv/lib/python3.9/site-packages/flask/views.py", line 107, in view
2023-03-13 23:03:40.476353 2023-03-13 23:03:40.470 26 ERROR keystone.server.flask.application     return current_app.ensure_sync(self.dispatch_request)(**kwargs)
2023-03-13 23:03:40.476363 2023-03-13 23:03:40.470 26 ERROR keystone.server.flask.application   File "/var/lib/kolla/venv/lib/python3.9/site-packages/flask_restful/__init__.py", line 582, in dispatch_request
2023-03-13 23:03:40.476425 2023-03-13 23:03:40.470 26 ERROR keystone.server.flask.application     resp = meth(*args, **kwargs)
2023-03-13 23:03:40.476436 2023-03-13 23:03:40.470 26 ERROR keystone.server.flask.application   File "/var/lib/kolla/venv/lib/python3.9/site-packages/keystone/api/users.py", line 182, in get
2023-03-13 23:03:40.476446 2023-03-13 23:03:40.470 26 ERROR keystone.server.flask.application     return self._get_user(user_id)
2023-03-13 23:03:40.476456 2023-03-13 23:03:40.470 26 ERROR keystone.server.flask.application   File "/var/lib/kolla/venv/lib/python3.9/site-packages/keystone/api/users.py", line 194, in _get_user
2023-03-13 23:03:40.476466 2023-03-13 23:03:40.470 26 ERROR keystone.server.flask.application     ref = PROVIDERS.identity_api.get_user(user_id)
2023-03-13 23:03:40.476475 2023-03-13 23:03:40.470 26 ERROR keystone.server.flask.application   File "/var/lib/kolla/venv/lib/python3.9/site-packages/keystone/common/manager.py", line 115, in wrapped
2023-03-13 23:03:40.476485 2023-03-13 23:03:40.470 26 ERROR keystone.server.flask.application     __ret_val = __f(*args, **kwargs)
2023-03-13 23:03:40.476494 2023-03-13 23:03:40.470 26 ERROR keystone.server.flask.application   File "/var/lib/kolla/venv/lib/python3.9/site-packages/keystone/identity/core.py", line 414, in wrapper
2023-03-13 23:03:40.476504 2023-03-13 23:03:40.470 26 ERROR keystone.server.flask.application     return f(self, *args, **kwargs)
2023-03-13 23:03:40.476514 2023-03-13 23:03:40.470 26 ERROR keystone.server.flask.application   File "/var/lib/kolla/venv/lib/python3.9/site-packages/keystone/identity/core.py", line 424, in wrapper
2023-03-13 23:03:40.476523 2023-03-13 23:03:40.470 26 ERROR keystone.server.flask.application     return f(self, *args, **kwargs)
2023-03-13 23:03:40.476533 2023-03-13 23:03:40.470 26 ERROR keystone.server.flask.application   File "/var/lib/kolla/venv/lib/python3.9/site-packages/decorator.py", line 232, in fun
2023-03-13 23:03:40.476542 2023-03-13 23:03:40.470 26 ERROR keystone.server.flask.application     return caller(func, *(extras + args), **kw)
2023-03-13 23:03:40.476552 2023-03-13 23:03:40.470 26 ERROR keystone.server.flask.application   File "/var/lib/kolla/venv/lib/python3.9/site-packages/dogpile/cache/region.py", line 1577, in get_or_create_for_user_func
2023-03-13 23:03:40.476562 2023-03-13 23:03:40.470 26 ERROR keystone.server.flask.application     return self.get_or_create(
2023-03-13 23:03:40.476572 2023-03-13 23:03:40.470 26 ERROR keystone.server.flask.application   File "/var/lib/kolla/venv/lib/python3.9/site-packages/dogpile/cache/region.py", line 1042, in get_or_create
2023-03-13 23:03:40.476582 2023-03-13 23:03:40.470 26 ERROR keystone.server.flask.application     with Lock(
2023-03-13 23:03:40.476591 2023-03-13 23:03:40.470 26 ERROR keystone.server.flask.application   File "/var/lib/kolla/venv/lib/python3.9/site-packages/dogpile/lock.py", line 185, in __enter__
2023-03-13 23:03:40.476601 2023-03-13 23:03:40.470 26 ERROR keystone.server.flask.application     return self._enter()
2023-03-13 23:03:40.476610 2023-03-13 23:03:40.470 26 ERROR keystone.server.flask.application   File "/var/lib/kolla/venv/lib/python3.9/site-packages/dogpile/lock.py", line 94, in _enter
2023-03-13 23:03:40.476620 2023-03-13 23:03:40.470 26 ERROR keystone.server.flask.application     generated = self._enter_create(value, createdtime)
2023-03-13 23:03:40.476630 2023-03-13 23:03:40.470 26 ERROR keystone.server.flask.application   File "/var/lib/kolla/venv/lib/python3.9/site-packages/dogpile/lock.py", line 178, in _enter_create
2023-03-13 23:03:40.476639 2023-03-13 23:03:40.470 26 ERROR keystone.server.flask.application     return self.creator()
2023-03-13 23:03:40.476649 2023-03-13 23:03:40.470 26 ERROR keystone.server.flask.application   File "/var/lib/kolla/venv/lib/python3.9/site-packages/dogpile/cache/region.py", line 995, in gen_value
2023-03-13 23:03:40.476659 2023-03-13 23:03:40.470 26 ERROR keystone.server.flask.application     created_value = creator(
2023-03-13 23:03:40.476678 2023-03-13 23:03:40.470 26 ERROR keystone.server.flask.application   File "/var/lib/kolla/venv/lib/python3.9/site-packages/keystone/identity/core.py", line 1011, in get_user
2023-03-13 23:03:40.476690 2023-03-13 23:03:40.470 26 ERROR keystone.server.flask.application     ref = driver.get_user(entity_id)
2023-03-13 23:03:40.476699 2023-03-13 23:03:40.470 26 ERROR keystone.server.flask.application   File "/var/lib/kolla/venv/lib/python3.9/site-packages/keystone/identity/backends/sql.py", line 200, in get_user
2023-03-13 23:03:40.476709 2023-03-13 23:03:40.470 26 ERROR keystone.server.flask.application     self._get_user(session, user_id).to_dict())
2023-03-13 23:03:40.476719 2023-03-13 23:03:40.470 26 ERROR keystone.server.flask.application   File "/var/lib/kolla/venv/lib/python3.9/site-packages/keystone/identity/backends/sql.py", line 194, in _get_user
2023-03-13 23:03:40.476731 2023-03-13 23:03:40.470 26 ERROR keystone.server.flask.application     raise exception.UserNotFound(user_id=user_id)
2023-03-13 23:03:40.476744 2023-03-13 23:03:40.470 26 ERROR keystone.server.flask.application keystone.exception.UserNotFound: Could not find user: neutron.
2023-03-13 23:03:40.476753 2023-03-13 23:03:40.470 26 ERROR keystone.server.flask.application \x1b[00m
2023-03-13 23:03:41.489593 2023-03-13 23:03:41.485 28 ERROR keystone.server.flask.application [None req-f05bfc8c-a644-4300-b2f9-20f40dac50fc 2f52da95b5904fb7821d1158394f777c - - all default -] Could not find project: service.: keystone.exception.ProjectNotFound: Could not find project: service.
2023-03-13 23:03:41.489673 2023-03-13 23:03:41.485 28 ERROR keystone.server.flask.application Traceback (most recent call last):
2023-03-13 23:03:41.489697 2023-03-13 23:03:41.485 28 ERROR keystone.server.flask.application   File "/var/lib/kolla/venv/lib/python3.9/site-packages/flask/app.py", line 1820, in full_dispatch_request
2023-03-13 23:03:41.489714 2023-03-13 23:03:41.485 28 ERROR keystone.server.flask.application     rv = self.dispatch_request()
2023-03-13 23:03:41.489736 2023-03-13 23:03:41.485 28 ERROR keystone.server.flask.application   File "/var/lib/kolla/venv/lib/python3.9/site-packages/flask/app.py", line 1796, in dispatch_request
2023-03-13 23:03:41.489768 2023-03-13 23:03:41.485 28 ERROR keystone.server.flask.application     return self.ensure_sync(self.view_functions[rule.endpoint])(**view_args)
2023-03-13 23:03:41.489812 2023-03-13 23:03:41.485 28 ERROR keystone.server.flask.application   File "/var/lib/kolla/venv/lib/python3.9/site-packages/flask_restful/__init__.py", line 467, in wrapper
2023-03-13 23:03:41.489830 2023-03-13 23:03:41.485 28 ERROR keystone.server.flask.application     resp = resource(*args, **kwargs)
2023-03-13 23:03:41.489840 2023-03-13 23:03:41.485 28 ERROR keystone.server.flask.application   File "/var/lib/kolla/venv/lib/python3.9/site-packages/flask/views.py", line 107, in view
2023-03-13 23:03:41.489852 2023-03-13 23:03:41.485 28 ERROR keystone.server.flask.application     return current_app.ensure_sync(self.dispatch_request)(**kwargs)
2023-03-13 23:03:41.489867 2023-03-13 23:03:41.485 28 ERROR keystone.server.flask.application   File "/var/lib/kolla/venv/lib/python3.9/site-packages/flask_restful/__init__.py", line 582, in dispatch_request
2023-03-13 23:03:41.489885 2023-03-13 23:03:41.485 28 ERROR keystone.server.flask.application     resp = meth(*args, **kwargs)
2023-03-13 23:03:41.489896 2023-03-13 23:03:41.485 28 ERROR keystone.server.flask.application   File "/var/lib/kolla/venv/lib/python3.9/site-packages/keystone/api/projects.py", line 151, in get
2023-03-13 23:03:41.489906 2023-03-13 23:03:41.485 28 ERROR keystone.server.flask.application     return self._get_project(project_id)
2023-03-13 23:03:41.489917 2023-03-13 23:03:41.485 28 ERROR keystone.server.flask.application   File "/var/lib/kolla/venv/lib/python3.9/site-packages/keystone/api/projects.py", line 107, in _get_project
2023-03-13 23:03:41.489935 2023-03-13 23:03:41.485 28 ERROR keystone.server.flask.application     project = PROVIDERS.resource_api.get_project(project_id)
2023-03-13 23:03:41.489968 2023-03-13 23:03:41.485 28 ERROR keystone.server.flask.application   File "/var/lib/kolla/venv/lib/python3.9/site-packages/keystone/common/manager.py", line 115, in wrapped
2023-03-13 23:03:41.489982 2023-03-13 23:03:41.485 28 ERROR keystone.server.flask.application     __ret_val = __f(*args, **kwargs)
2023-03-13 23:03:41.490001 2023-03-13 23:03:41.485 28 ERROR keystone.server.flask.application   File "/var/lib/kolla/venv/lib/python3.9/site-packages/decorator.py", line 232, in fun
2023-03-13 23:03:41.490017 2023-03-13 23:03:41.485 28 ERROR keystone.server.flask.application     return caller(func, *(extras + args), **kw)
2023-03-13 23:03:41.490027 2023-03-13 23:03:41.485 28 ERROR keystone.server.flask.application   File "/var/lib/kolla/venv/lib/python3.9/site-packages/dogpile/cache/region.py", line 1577, in get_or_create_for_user_func
2023-03-13 23:03:41.490038 2023-03-13 23:03:41.485 28 ERROR keystone.server.flask.application     return self.get_or_create(
2023-03-13 23:03:41.490054 2023-03-13 23:03:41.485 28 ERROR keystone.server.flask.application   File "/var/lib/kolla/venv/lib/python3.9/site-packages/dogpile/cache/region.py", line 1042, in get_or_create
2023-03-13 23:03:41.490071 2023-03-13 23:03:41.485 28 ERROR keystone.server.flask.application     with Lock(
2023-03-13 23:03:41.490081 2023-03-13 23:03:41.485 28 ERROR keystone.server.flask.application   File "/var/lib/kolla/venv/lib/python3.9/site-packages/dogpile/lock.py", line 185, in __enter__
2023-03-13 23:03:41.490091 2023-03-13 23:03:41.485 28 ERROR keystone.server.flask.application     return self._enter()
2023-03-13 23:03:41.490100 2023-03-13 23:03:41.485 28 ERROR keystone.server.flask.application   File "/var/lib/kolla/venv/lib/python3.9/site-packages/dogpile/lock.py", line 94, in _enter
2023-03-13 23:03:41.490148 2023-03-13 23:03:41.485 28 ERROR keystone.server.flask.application     generated = self._enter_create(value, createdtime)
2023-03-13 23:03:41.490167 2023-03-13 23:03:41.485 28 ERROR keystone.server.flask.application   File "/var/lib/kolla/venv/lib/python3.9/site-packages/dogpile/lock.py", line 178, in _enter_create
2023-03-13 23:03:41.490185 2023-03-13 23:03:41.485 28 ERROR keystone.server.flask.application     return self.creator()
2023-03-13 23:03:41.490200 2023-03-13 23:03:41.485 28 ERROR keystone.server.flask.application   File "/var/lib/kolla/venv/lib/python3.9/site-packages/dogpile/cache/region.py", line 995, in gen_value
2023-03-13 23:03:41.490210 2023-03-13 23:03:41.485 28 ERROR keystone.server.flask.application     created_value = creator(
2023-03-13 23:03:41.490219 2023-03-13 23:03:41.485 28 ERROR keystone.server.flask.application   File "/var/lib/kolla/venv/lib/python3.9/site-packages/keystone/resource/core.py", line 903, in get_project
2023-03-13 23:03:41.490235 2023-03-13 23:03:41.485 28 ERROR keystone.server.flask.application     return self.driver.get_project(project_id)
2023-03-13 23:03:41.490254 2023-03-13 23:03:41.485 28 ERROR keystone.server.flask.application   File "/var/lib/kolla/venv/lib/python3.9/site-packages/keystone/resource/backends/sql.py", line 49, in get_project
2023-03-13 23:03:41.490267 2023-03-13 23:03:41.485 28 ERROR keystone.server.flask.application     return self._get_project(session, project_id).to_dict()
2023-03-13 23:03:41.490277 2023-03-13 23:03:41.485 28 ERROR keystone.server.flask.application   File "/var/lib/kolla/venv/lib/python3.9/site-packages/keystone/resource/backends/sql.py", line 44, in _get_project
2023-03-13 23:03:41.490290 2023-03-13 23:03:41.485 28 ERROR keystone.server.flask.application     raise exception.ProjectNotFound(project_id=project_id)
2023-03-13 23:03:41.490309 2023-03-13 23:03:41.485 28 ERROR keystone.server.flask.application keystone.exception.ProjectNotFound: Could not find project: service.
2023-03-13 23:03:41.490323 2023-03-13 23:03:41.485 28 ERROR keystone.server.flask.application \x1b[00m
2023-03-13 23:14:32.743777 2023-03-13 23:14:32.742 28 WARNING py.warnings [None req-9a60fbb9-6029-44dc-93dd-640781db5163 2f52da95b5904fb7821d1158394f777c c9a3fa39b4e745d79249098aaa4d1c4f - - default default] /var/lib/kolla/venv/lib/python3.9/site-packages/oslo_policy/policy.py:1129: UserWarning: Policy "identity:list_domains": "role:reader and system_scope:all" failed scope check. The token used to make the request was project scoped but the policy requires ['system'] scope. This behavior may change in the future where using the intended scope is required
2023-03-13 23:14:32.743885   warnings.warn(msg)
2023-03-13 23:14:32.743899 \x1b[00m
2023-03-13 23:14:33.111224 2023-03-13 23:14:33.109 26 WARNING py.warnings [None req-92fdf92c-d988-4336-b407-318d2a27ccb2 2f52da95b5904fb7821d1158394f777c c9a3fa39b4e745d79249098aaa4d1c4f - - default default] /var/lib/kolla/venv/lib/python3.9/site-packages/oslo_policy/policy.py:1129: UserWarning: Policy "identity:create_project": "(role:admin and system_scope:all) or (role:admin and domain_id:%(target.project.domain_id)s)" failed scope check. The token used to make the request was project scoped but the policy requires ['system', 'domain'] scope. This behavior may change in the future where using the intended scope is required
2023-03-13 23:14:33.111271   warnings.warn(msg)
2023-03-13 23:14:33.111283 \x1b[00m
2023-03-13 23:14:33.399441 2023-03-13 23:14:33.397 27 WARNING py.warnings [None req-69b3abb5-3be4-4dce-a4ae-7c57cada2aaf 2f52da95b5904fb7821d1158394f777c c9a3fa39b4e745d79249098aaa4d1c4f - - default default] /var/lib/kolla/venv/lib/python3.9/site-packages/oslo_policy/policy.py:1129: UserWarning: Policy "identity:create_user": "(role:admin and system_scope:all) or (role:admin and token.domain.id:%(target.user.domain_id)s)" failed scope check. The token used to make the request was project scoped but the policy requires ['system', 'domain'] scope. This behavior may change in the future where using the intended scope is required
2023-03-13 23:14:33.399486   warnings.warn(msg)
2023-03-13 23:14:33.399497 \x1b[00m
2023-03-13 23:14:34.376080 2023-03-13 23:14:34.375 28 WARNING py.warnings [None req-6a6453bc-c96c-4993-93fb-9f43b9d7433d 2f52da95b5904fb7821d1158394f777c c9a3fa39b4e745d79249098aaa4d1c4f - - default default] /var/lib/kolla/venv/lib/python3.9/site-packages/oslo_policy/policy.py:1129: UserWarning: Policy "identity:list_roles": "role:reader and system_scope:all" failed scope check. The token used to make the request was project scoped but the policy requires ['system'] scope. This behavior may change in the future where using the intended scope is required
2023-03-13 23:14:34.376204   warnings.warn(msg)
2023-03-13 23:14:34.376215 \x1b[00m
2023-03-13 23:14:34.678081 2023-03-13 23:14:34.677 26 WARNING py.warnings [None req-54bf85cd-405c-43d1-b6cd-dce1da93134b 2f52da95b5904fb7821d1158394f777c c9a3fa39b4e745d79249098aaa4d1c4f - - default default] /var/lib/kolla/venv/lib/python3.9/site-packages/oslo_policy/policy.py:1129: UserWarning: Policy "identity:create_grant": "(role:admin and system_scope:all) or ((role:admin and domain_id:%(target.user.domain_id)s and domain_id:%(target.project.domain_id)s) or (role:admin and domain_id:%(target.user.domain_id)s and domain_id:%(target.domain.id)s) or (role:admin and domain_id:%(target.group.domain_id)s and domain_id:%(target.project.domain_id)s) or (role:admin and domain_id:%(target.group.domain_id)s and domain_id:%(target.domain.id)s)) and (domain_id:%(target.role.domain_id)s or None:%(target.role.domain_id)s)" failed scope check. The token used to make the request was project scoped but the policy requires ['system', 'domain'] scope. This behavior may change in the future where using the intended scope is required
2023-03-13 23:14:34.678150   warnings.warn(msg)
2023-03-13 23:14:34.678164 \x1b[00m
2023-03-13 23:14:35.837655 2023-03-13 23:14:35.836 28 WARNING py.warnings [None req-89b256d1-a0a0-4a3c-95d9-ed02d34dbdf9 2f52da95b5904fb7821d1158394f777c c9a3fa39b4e745d79249098aaa4d1c4f - - default default] /var/lib/kolla/venv/lib/python3.9/site-packages/oslo_policy/policy.py:1129: UserWarning: Policy "identity:create_project": "(role:admin and system_scope:all) or (role:admin and domain_id:%(target.project.domain_id)s)" failed scope check. The token used to make the request was project scoped but the policy requires ['system', 'domain'] scope. This behavior may change in the future where using the intended scope is required
2023-03-13 23:14:35.837788   warnings.warn(msg)
2023-03-13 23:14:35.837803 \x1b[00m
2023-03-13 23:14:36.234072 2023-03-13 23:14:36.233 26 WARNING py.warnings [None req-5722859c-180f-4a22-9659-56590951ecc3 2f52da95b5904fb7821d1158394f777c c9a3fa39b4e745d79249098aaa4d1c4f - - default default] /var/lib/kolla/venv/lib/python3.9/site-packages/oslo_policy/policy.py:1129: UserWarning: Policy "identity:create_user": "(role:admin and system_scope:all) or (role:admin and token.domain.id:%(target.user.domain_id)s)" failed scope check. The token used to make the request was project scoped but the policy requires ['system', 'domain'] scope. This behavior may change in the future where using the intended scope is required
2023-03-13 23:14:36.234154   warnings.warn(msg)
2023-03-13 23:14:36.234168 \x1b[00m
2023-03-13 23:14:37.210030 2023-03-13 23:14:37.207 27 WARNING py.warnings [None req-3f35f17a-e350-4cac-81ea-1c71d4407201 2f52da95b5904fb7821d1158394f777c c9a3fa39b4e745d79249098aaa4d1c4f - - default default] /var/lib/kolla/venv/lib/python3.9/site-packages/oslo_policy/policy.py:1129: UserWarning: Policy "identity:list_roles": "role:reader and system_scope:all" failed scope check. The token used to make the request was project scoped but the policy requires ['system'] scope. This behavior may change in the future where using the intended scope is required
2023-03-13 23:14:37.210184   warnings.warn(msg)
2023-03-13 23:14:37.210292 \x1b[00m
2023-03-13 23:14:37.645493 2023-03-13 23:14:37.644 28 WARNING py.warnings [None req-55d6d2e9-1bbb-432f-a464-0e6d9f439b64 2f52da95b5904fb7821d1158394f777c c9a3fa39b4e745d79249098aaa4d1c4f - - default default] /var/lib/kolla/venv/lib/python3.9/site-packages/oslo_policy/policy.py:1129: UserWarning: Policy "identity:create_grant": "(role:admin and system_scope:all) or ((role:admin and domain_id:%(target.user.domain_id)s and domain_id:%(target.project.domain_id)s) or (role:admin and domain_id:%(target.user.domain_id)s and domain_id:%(target.domain.id)s) or (role:admin and domain_id:%(target.group.domain_id)s and domain_id:%(target.project.domain_id)s) or (role:admin and domain_id:%(target.group.domain_id)s and domain_id:%(target.domain.id)s)) and (domain_id:%(target.role.domain_id)s or None:%(target.role.domain_id)s)" failed scope check. The token used to make the request was project scoped but the policy requires ['system', 'domain'] scope. This behavior may change in the future where using the intended scope is required
2023-03-13 23:14:37.645592   warnings.warn(msg)
2023-03-13 23:14:37.645606 \x1b[00m
2023-03-13 23:14:37.938613 2023-03-13 23:14:37.937 26 WARNING py.warnings [None req-bf82a445-81fa-47d7-9f92-2f496402c70f 2f52da95b5904fb7821d1158394f777c c9a3fa39b4e745d79249098aaa4d1c4f - - default default] /var/lib/kolla/venv/lib/python3.9/site-packages/oslo_policy/policy.py:1129: UserWarning: Policy "identity:list_roles": "role:reader and system_scope:all" failed scope check. The token used to make the request was project scoped but the policy requires ['system'] scope. This behavior may change in the future where using the intended scope is required
2023-03-13 23:14:37.938660   warnings.warn(msg)
2023-03-13 23:14:37.938672 \x1b[00m
2023-03-13 23:14:38.296655 2023-03-13 23:14:38.295 27 WARNING py.warnings [None req-94590327-51ae-4a2b-975b-69fe98392062 2f52da95b5904fb7821d1158394f777c c9a3fa39b4e745d79249098aaa4d1c4f - - default default] /var/lib/kolla/venv/lib/python3.9/site-packages/oslo_policy/policy.py:1129: UserWarning: Policy "identity:create_grant": "(role:admin and system_scope:all) or ((role:admin and domain_id:%(target.user.domain_id)s and domain_id:%(target.project.domain_id)s) or (role:admin and domain_id:%(target.user.domain_id)s and domain_id:%(target.domain.id)s) or (role:admin and domain_id:%(target.group.domain_id)s and domain_id:%(target.project.domain_id)s) or (role:admin and domain_id:%(target.group.domain_id)s and domain_id:%(target.domain.id)s)) and (domain_id:%(target.role.domain_id)s or None:%(target.role.domain_id)s)" failed scope check. The token used to make the request was project scoped but the policy requires ['system', 'domain'] scope. This behavior may change in the future where using the intended scope is required
2023-03-13 23:14:38.296863   warnings.warn(msg)
2023-03-13 23:14:38.296903 \x1b[00m
2023-03-13 23:14:40.927096 2023-03-13 23:14:40.926 28 WARNING py.warnings [None req-d5a89095-24aa-46b0-b590-e4eba44ff926 2f52da95b5904fb7821d1158394f777c c9a3fa39b4e745d79249098aaa4d1c4f - - default default] /var/lib/kolla/venv/lib/python3.9/site-packages/oslo_policy/policy.py:1129: UserWarning: Policy "identity:create_system_grant_for_user": "role:admin and system_scope:all" failed scope check. The token used to make the request was project scoped but the policy requires ['system'] scope. This behavior may change in the future where using the intended scope is required
2023-03-13 23:14:40.927190   warnings.warn(msg)
2023-03-13 23:14:40.927202 \x1b[00m
