2023-03-17 09:16:05.440 23 INFO alembic.runtime.migration [-] Context impl MySQLImpl.
2023-03-17 09:16:05.441 23 INFO alembic.runtime.migration [-] Will assume non-transactional DDL.
2023-03-17 09:16:05.478 23 INFO alembic.runtime.migration [-] Context impl MySQLImpl.
2023-03-17 09:16:05.479 23 INFO alembic.runtime.migration [-] Will assume non-transactional DDL.
2023-03-17 09:16:05.530 23 INFO alembic.runtime.migration [-] Running upgrade  -> 27e647c0fad4, Initial version.
2023-03-17 09:16:06.913 23 INFO alembic.runtime.migration [-] Running upgrade 27e647c0fad4 -> e25ffa003242, Initial no-op Yoga contract migration.
2023-03-17 09:16:06.919 23 INFO alembic.runtime.migration [-] Running upgrade 27e647c0fad4 -> 29e87d24a316, Initial no-op Yoga expand migration.
2023-03-17 09:16:15.718 7 INFO keystone.common.fernet_utils [-] Created a new temporary key: /etc/keystone/fernet-keys/0.tmp
2023-03-17 09:16:15.724 7 INFO keystone.common.fernet_utils [-] Become a valid new key: /etc/keystone/fernet-keys/0
2023-03-17 09:16:15.726 7 INFO keystone.common.fernet_utils [-] Starting key rotation with 1 key files: ['/etc/keystone/fernet-keys/0']
2023-03-17 09:16:15.727 7 INFO keystone.common.fernet_utils [-] Created a new temporary key: /etc/keystone/fernet-keys/0.tmp
2023-03-17 09:16:15.728 7 INFO keystone.common.fernet_utils [-] Current primary key is: 0
2023-03-17 09:16:15.728 7 INFO keystone.common.fernet_utils [-] Next primary key will be: 1
2023-03-17 09:16:15.729 7 INFO keystone.common.fernet_utils [-] Promoted key 0 to be the primary: 1
2023-03-17 09:16:15.730 7 INFO keystone.common.fernet_utils [-] Become a valid new key: /etc/keystone/fernet-keys/0
2023-03-17 09:16:34.318 32 INFO keystone.cmd.bootstrap [None req-df161798-9c7d-4262-bd4e-e2bd409f293d - - - - - -] Created domain default
2023-03-17 09:16:34.385 32 INFO keystone.cmd.bootstrap [None req-df161798-9c7d-4262-bd4e-e2bd409f293d - - - - - -] Created project admin
2023-03-17 09:16:34.994 32 INFO keystone.cmd.bootstrap [None req-df161798-9c7d-4262-bd4e-e2bd409f293d - - - - - -] Created user admin
2023-03-17 09:16:35.019 32 INFO keystone.cmd.bootstrap [None req-df161798-9c7d-4262-bd4e-e2bd409f293d - - - - - -] Created role reader
2023-03-17 09:16:35.039 32 INFO keystone.cmd.bootstrap [None req-df161798-9c7d-4262-bd4e-e2bd409f293d - - - - - -] Created role member
2023-03-17 09:16:35.073 32 INFO keystone.cmd.bootstrap [None req-df161798-9c7d-4262-bd4e-e2bd409f293d - - - - - -] Created implied role where c311d145fca14d80a30caa0e93566234 implies f3c5770a88d6467986a21dc8f90defb4
2023-03-17 09:16:35.090 32 INFO keystone.cmd.bootstrap [None req-df161798-9c7d-4262-bd4e-e2bd409f293d - - - - - -] Created role admin
2023-03-17 09:16:35.124 32 INFO keystone.cmd.bootstrap [None req-df161798-9c7d-4262-bd4e-e2bd409f293d - - - - - -] Created implied role where cc8ad8eefb9042338c7aee7fa74c3cfd implies c311d145fca14d80a30caa0e93566234
2023-03-17 09:16:35.145 32 INFO keystone.cmd.bootstrap [None req-df161798-9c7d-4262-bd4e-e2bd409f293d - - - - - -] Granted role admin on project admin to user admin.
2023-03-17 09:16:35.156 32 INFO keystone.cmd.bootstrap [None req-df161798-9c7d-4262-bd4e-e2bd409f293d - - - - - -] Granted role admin on the system to user admin.
2023-03-17 09:16:35.179 32 WARNING py.warnings [None req-df161798-9c7d-4262-bd4e-e2bd409f293d - - - - - -] /var/lib/kolla/venv/lib/python3.9/site-packages/pycadf/identifier.py:71: UserWarning: Invalid uuid: RegionOne. To ensure interoperability, identifiers should be a valid uuid.
  warnings.warn(('Invalid uuid: %s. To ensure interoperability, '

2023-03-17 09:16:35.187 32 INFO keystone.cmd.bootstrap [None req-df161798-9c7d-4262-bd4e-e2bd409f293d - - - - - -] Created region RegionOne
2023-03-17 09:16:35.246 32 INFO keystone.cmd.bootstrap [None req-df161798-9c7d-4262-bd4e-e2bd409f293d - - - - - -] Created public endpoint http://169.16.1.182:5000
2023-03-17 09:16:35.262 32 INFO keystone.cmd.bootstrap [None req-df161798-9c7d-4262-bd4e-e2bd409f293d - - - - - -] Created internal endpoint http://169.16.1.182:5000
2023-03-17 09:17:01.111 39 WARNING keystone.common.rbac_enforcer.enforcer [None req-babbf1de-9966-4678-b798-004e880c2f84 1d19bbf56d5f40c9b529281d0c1e72a5 - - all default -] Deprecated policy rules found. Use oslopolicy-policy-generator and oslopolicy-policy-upgrade to detect and resolve deprecated policies in your configuration.
2023-03-17 09:17:01.850 38 WARNING keystone.common.rbac_enforcer.enforcer [None req-ef8368a7-c149-402f-bf27-91c62bdb9597 1d19bbf56d5f40c9b529281d0c1e72a5 - - all default -] Deprecated policy rules found. Use oslopolicy-policy-generator and oslopolicy-policy-upgrade to detect and resolve deprecated policies in your configuration.
2023-03-17 09:17:09.424 37 WARNING keystone.common.rbac_enforcer.enforcer [None req-be287d40-d3ed-4fe0-9234-e2f9f8ee37f7 1d19bbf56d5f40c9b529281d0c1e72a5 - - all default -] Deprecated policy rules found. Use oslopolicy-policy-generator and oslopolicy-policy-upgrade to detect and resolve deprecated policies in your configuration.
2023-03-17 09:18:26.806 39 ERROR keystone.server.flask.application [None req-90c054b7-78ae-42c4-8ead-4a7d1dd629c6 1d19bbf56d5f40c9b529281d0c1e72a5 - - all default -] Could not find project: service.: keystone.exception.ProjectNotFound: Could not find project: service.
2023-03-17 09:18:26.806 39 ERROR keystone.server.flask.application Traceback (most recent call last):
2023-03-17 09:18:26.806 39 ERROR keystone.server.flask.application   File "/var/lib/kolla/venv/lib/python3.9/site-packages/flask/app.py", line 1820, in full_dispatch_request
2023-03-17 09:18:26.806 39 ERROR keystone.server.flask.application     rv = self.dispatch_request()
2023-03-17 09:18:26.806 39 ERROR keystone.server.flask.application   File "/var/lib/kolla/venv/lib/python3.9/site-packages/flask/app.py", line 1796, in dispatch_request
2023-03-17 09:18:26.806 39 ERROR keystone.server.flask.application     return self.ensure_sync(self.view_functions[rule.endpoint])(**view_args)
2023-03-17 09:18:26.806 39 ERROR keystone.server.flask.application   File "/var/lib/kolla/venv/lib/python3.9/site-packages/flask_restful/__init__.py", line 467, in wrapper
2023-03-17 09:18:26.806 39 ERROR keystone.server.flask.application     resp = resource(*args, **kwargs)
2023-03-17 09:18:26.806 39 ERROR keystone.server.flask.application   File "/var/lib/kolla/venv/lib/python3.9/site-packages/flask/views.py", line 107, in view
2023-03-17 09:18:26.806 39 ERROR keystone.server.flask.application     return current_app.ensure_sync(self.dispatch_request)(**kwargs)
2023-03-17 09:18:26.806 39 ERROR keystone.server.flask.application   File "/var/lib/kolla/venv/lib/python3.9/site-packages/flask_restful/__init__.py", line 582, in dispatch_request
2023-03-17 09:18:26.806 39 ERROR keystone.server.flask.application     resp = meth(*args, **kwargs)
2023-03-17 09:18:26.806 39 ERROR keystone.server.flask.application   File "/var/lib/kolla/venv/lib/python3.9/site-packages/keystone/api/projects.py", line 151, in get
2023-03-17 09:18:26.806 39 ERROR keystone.server.flask.application     return self._get_project(project_id)
2023-03-17 09:18:26.806 39 ERROR keystone.server.flask.application   File "/var/lib/kolla/venv/lib/python3.9/site-packages/keystone/api/projects.py", line 107, in _get_project
2023-03-17 09:18:26.806 39 ERROR keystone.server.flask.application     project = PROVIDERS.resource_api.get_project(project_id)
2023-03-17 09:18:26.806 39 ERROR keystone.server.flask.application   File "/var/lib/kolla/venv/lib/python3.9/site-packages/keystone/common/manager.py", line 115, in wrapped
2023-03-17 09:18:26.806 39 ERROR keystone.server.flask.application     __ret_val = __f(*args, **kwargs)
2023-03-17 09:18:26.806 39 ERROR keystone.server.flask.application   File "/var/lib/kolla/venv/lib/python3.9/site-packages/decorator.py", line 232, in fun
2023-03-17 09:18:26.806 39 ERROR keystone.server.flask.application     return caller(func, *(extras + args), **kw)
2023-03-17 09:18:26.806 39 ERROR keystone.server.flask.application   File "/var/lib/kolla/venv/lib/python3.9/site-packages/dogpile/cache/region.py", line 1577, in get_or_create_for_user_func
2023-03-17 09:18:26.806 39 ERROR keystone.server.flask.application     return self.get_or_create(
2023-03-17 09:18:26.806 39 ERROR keystone.server.flask.application   File "/var/lib/kolla/venv/lib/python3.9/site-packages/dogpile/cache/region.py", line 1042, in get_or_create
2023-03-17 09:18:26.806 39 ERROR keystone.server.flask.application     with Lock(
2023-03-17 09:18:26.806 39 ERROR keystone.server.flask.application   File "/var/lib/kolla/venv/lib/python3.9/site-packages/dogpile/lock.py", line 185, in __enter__
2023-03-17 09:18:26.806 39 ERROR keystone.server.flask.application     return self._enter()
2023-03-17 09:18:26.806 39 ERROR keystone.server.flask.application   File "/var/lib/kolla/venv/lib/python3.9/site-packages/dogpile/lock.py", line 94, in _enter
2023-03-17 09:18:26.806 39 ERROR keystone.server.flask.application     generated = self._enter_create(value, createdtime)
2023-03-17 09:18:26.806 39 ERROR keystone.server.flask.application   File "/var/lib/kolla/venv/lib/python3.9/site-packages/dogpile/lock.py", line 178, in _enter_create
2023-03-17 09:18:26.806 39 ERROR keystone.server.flask.application     return self.creator()
2023-03-17 09:18:26.806 39 ERROR keystone.server.flask.application   File "/var/lib/kolla/venv/lib/python3.9/site-packages/dogpile/cache/region.py", line 995, in gen_value
2023-03-17 09:18:26.806 39 ERROR keystone.server.flask.application     created_value = creator(
2023-03-17 09:18:26.806 39 ERROR keystone.server.flask.application   File "/var/lib/kolla/venv/lib/python3.9/site-packages/keystone/resource/core.py", line 903, in get_project
2023-03-17 09:18:26.806 39 ERROR keystone.server.flask.application     return self.driver.get_project(project_id)
2023-03-17 09:18:26.806 39 ERROR keystone.server.flask.application   File "/var/lib/kolla/venv/lib/python3.9/site-packages/keystone/resource/backends/sql.py", line 49, in get_project
2023-03-17 09:18:26.806 39 ERROR keystone.server.flask.application     return self._get_project(session, project_id).to_dict()
2023-03-17 09:18:26.806 39 ERROR keystone.server.flask.application   File "/var/lib/kolla/venv/lib/python3.9/site-packages/keystone/resource/backends/sql.py", line 44, in _get_project
2023-03-17 09:18:26.806 39 ERROR keystone.server.flask.application     raise exception.ProjectNotFound(project_id=project_id)
2023-03-17 09:18:26.806 39 ERROR keystone.server.flask.application keystone.exception.ProjectNotFound: Could not find project: service.
2023-03-17 09:18:26.806 39 ERROR keystone.server.flask.application 
2023-03-17 09:18:35.377 37 ERROR keystone.server.flask.application [None req-b4189f1f-1a8a-419b-b3fd-b326040bd729 1d19bbf56d5f40c9b529281d0c1e72a5 - - all default -] Could not find project: service.: keystone.exception.ProjectNotFound: Could not find project: service.
2023-03-17 09:18:35.377 37 ERROR keystone.server.flask.application Traceback (most recent call last):
2023-03-17 09:18:35.377 37 ERROR keystone.server.flask.application   File "/var/lib/kolla/venv/lib/python3.9/site-packages/flask/app.py", line 1820, in full_dispatch_request
2023-03-17 09:18:35.377 37 ERROR keystone.server.flask.application     rv = self.dispatch_request()
2023-03-17 09:18:35.377 37 ERROR keystone.server.flask.application   File "/var/lib/kolla/venv/lib/python3.9/site-packages/flask/app.py", line 1796, in dispatch_request
2023-03-17 09:18:35.377 37 ERROR keystone.server.flask.application     return self.ensure_sync(self.view_functions[rule.endpoint])(**view_args)
2023-03-17 09:18:35.377 37 ERROR keystone.server.flask.application   File "/var/lib/kolla/venv/lib/python3.9/site-packages/flask_restful/__init__.py", line 467, in wrapper
2023-03-17 09:18:35.377 37 ERROR keystone.server.flask.application     resp = resource(*args, **kwargs)
2023-03-17 09:18:35.377 37 ERROR keystone.server.flask.application   File "/var/lib/kolla/venv/lib/python3.9/site-packages/flask/views.py", line 107, in view
2023-03-17 09:18:35.377 37 ERROR keystone.server.flask.application     return current_app.ensure_sync(self.dispatch_request)(**kwargs)
2023-03-17 09:18:35.377 37 ERROR keystone.server.flask.application   File "/var/lib/kolla/venv/lib/python3.9/site-packages/flask_restful/__init__.py", line 582, in dispatch_request
2023-03-17 09:18:35.377 37 ERROR keystone.server.flask.application     resp = meth(*args, **kwargs)
2023-03-17 09:18:35.377 37 ERROR keystone.server.flask.application   File "/var/lib/kolla/venv/lib/python3.9/site-packages/keystone/api/projects.py", line 151, in get
2023-03-17 09:18:35.377 37 ERROR keystone.server.flask.application     return self._get_project(project_id)
2023-03-17 09:18:35.377 37 ERROR keystone.server.flask.application   File "/var/lib/kolla/venv/lib/python3.9/site-packages/keystone/api/projects.py", line 107, in _get_project
2023-03-17 09:18:35.377 37 ERROR keystone.server.flask.application     project = PROVIDERS.resource_api.get_project(project_id)
2023-03-17 09:18:35.377 37 ERROR keystone.server.flask.application   File "/var/lib/kolla/venv/lib/python3.9/site-packages/keystone/common/manager.py", line 115, in wrapped
2023-03-17 09:18:35.377 37 ERROR keystone.server.flask.application     __ret_val = __f(*args, **kwargs)
2023-03-17 09:18:35.377 37 ERROR keystone.server.flask.application   File "/var/lib/kolla/venv/lib/python3.9/site-packages/decorator.py", line 232, in fun
2023-03-17 09:18:35.377 37 ERROR keystone.server.flask.application     return caller(func, *(extras + args), **kw)
2023-03-17 09:18:35.377 37 ERROR keystone.server.flask.application   File "/var/lib/kolla/venv/lib/python3.9/site-packages/dogpile/cache/region.py", line 1577, in get_or_create_for_user_func
2023-03-17 09:18:35.377 37 ERROR keystone.server.flask.application     return self.get_or_create(
2023-03-17 09:18:35.377 37 ERROR keystone.server.flask.application   File "/var/lib/kolla/venv/lib/python3.9/site-packages/dogpile/cache/region.py", line 1042, in get_or_create
2023-03-17 09:18:35.377 37 ERROR keystone.server.flask.application     with Lock(
2023-03-17 09:18:35.377 37 ERROR keystone.server.flask.application   File "/var/lib/kolla/venv/lib/python3.9/site-packages/dogpile/lock.py", line 185, in __enter__
2023-03-17 09:18:35.377 37 ERROR keystone.server.flask.application     return self._enter()
2023-03-17 09:18:35.377 37 ERROR keystone.server.flask.application   File "/var/lib/kolla/venv/lib/python3.9/site-packages/dogpile/lock.py", line 94, in _enter
2023-03-17 09:18:35.377 37 ERROR keystone.server.flask.application     generated = self._enter_create(value, createdtime)
2023-03-17 09:18:35.377 37 ERROR keystone.server.flask.application   File "/var/lib/kolla/venv/lib/python3.9/site-packages/dogpile/lock.py", line 178, in _enter_create
2023-03-17 09:18:35.377 37 ERROR keystone.server.flask.application     return self.creator()
2023-03-17 09:18:35.377 37 ERROR keystone.server.flask.application   File "/var/lib/kolla/venv/lib/python3.9/site-packages/dogpile/cache/region.py", line 995, in gen_value
2023-03-17 09:18:35.377 37 ERROR keystone.server.flask.application     created_value = creator(
2023-03-17 09:18:35.377 37 ERROR keystone.server.flask.application   File "/var/lib/kolla/venv/lib/python3.9/site-packages/keystone/resource/core.py", line 903, in get_project
2023-03-17 09:18:35.377 37 ERROR keystone.server.flask.application     return self.driver.get_project(project_id)
2023-03-17 09:18:35.377 37 ERROR keystone.server.flask.application   File "/var/lib/kolla/venv/lib/python3.9/site-packages/keystone/resource/backends/sql.py", line 49, in get_project
2023-03-17 09:18:35.377 37 ERROR keystone.server.flask.application     return self._get_project(session, project_id).to_dict()
2023-03-17 09:18:35.377 37 ERROR keystone.server.flask.application   File "/var/lib/kolla/venv/lib/python3.9/site-packages/keystone/resource/backends/sql.py", line 44, in _get_project
2023-03-17 09:18:35.377 37 ERROR keystone.server.flask.application     raise exception.ProjectNotFound(project_id=project_id)
2023-03-17 09:18:35.377 37 ERROR keystone.server.flask.application keystone.exception.ProjectNotFound: Could not find project: service.
2023-03-17 09:18:35.377 37 ERROR keystone.server.flask.application 
2023-03-17 09:18:49.592 37 ERROR keystone.server.flask.application [None req-ee750978-468f-4e0f-95ec-f0c853e45b51 1d19bbf56d5f40c9b529281d0c1e72a5 - - all default -] Could not find role: admin.: keystone.exception.RoleNotFound: Could not find role: admin.
2023-03-17 09:18:49.592 37 ERROR keystone.server.flask.application Traceback (most recent call last):
2023-03-17 09:18:49.592 37 ERROR keystone.server.flask.application   File "/var/lib/kolla/venv/lib/python3.9/site-packages/flask/app.py", line 1820, in full_dispatch_request
2023-03-17 09:18:49.592 37 ERROR keystone.server.flask.application     rv = self.dispatch_request()
2023-03-17 09:18:49.592 37 ERROR keystone.server.flask.application   File "/var/lib/kolla/venv/lib/python3.9/site-packages/flask/app.py", line 1796, in dispatch_request
2023-03-17 09:18:49.592 37 ERROR keystone.server.flask.application     return self.ensure_sync(self.view_functions[rule.endpoint])(**view_args)
2023-03-17 09:18:49.592 37 ERROR keystone.server.flask.application   File "/var/lib/kolla/venv/lib/python3.9/site-packages/flask_restful/__init__.py", line 467, in wrapper
2023-03-17 09:18:49.592 37 ERROR keystone.server.flask.application     resp = resource(*args, **kwargs)
2023-03-17 09:18:49.592 37 ERROR keystone.server.flask.application   File "/var/lib/kolla/venv/lib/python3.9/site-packages/flask/views.py", line 107, in view
2023-03-17 09:18:49.592 37 ERROR keystone.server.flask.application     return current_app.ensure_sync(self.dispatch_request)(**kwargs)
2023-03-17 09:18:49.592 37 ERROR keystone.server.flask.application   File "/var/lib/kolla/venv/lib/python3.9/site-packages/flask_restful/__init__.py", line 582, in dispatch_request
2023-03-17 09:18:49.592 37 ERROR keystone.server.flask.application     resp = meth(*args, **kwargs)
2023-03-17 09:18:49.592 37 ERROR keystone.server.flask.application   File "/var/lib/kolla/venv/lib/python3.9/site-packages/keystone/api/roles.py", line 50, in get
2023-03-17 09:18:49.592 37 ERROR keystone.server.flask.application     return self._get_role(role_id)
2023-03-17 09:18:49.592 37 ERROR keystone.server.flask.application   File "/var/lib/kolla/venv/lib/python3.9/site-packages/keystone/api/roles.py", line 70, in _get_role
2023-03-17 09:18:49.592 37 ERROR keystone.server.flask.application     ENFORCER.enforce_call(action='identity:get_role')
2023-03-17 09:18:49.592 37 ERROR keystone.server.flask.application   File "/var/lib/kolla/venv/lib/python3.9/site-packages/keystone/common/rbac_enforcer/enforcer.py", line 402, in enforce_call
2023-03-17 09:18:49.592 37 ERROR keystone.server.flask.application     policy_dict.update(cls._extract_member_target_data(
2023-03-17 09:18:49.592 37 ERROR keystone.server.flask.application   File "/var/lib/kolla/venv/lib/python3.9/site-packages/keystone/common/rbac_enforcer/enforcer.py", line 234, in _extract_member_target_data
2023-03-17 09:18:49.592 37 ERROR keystone.server.flask.application     member_name: func(flask.request.view_args[key])
2023-03-17 09:18:49.592 37 ERROR keystone.server.flask.application   File "/var/lib/kolla/venv/lib/python3.9/site-packages/keystone/common/manager.py", line 115, in wrapped
2023-03-17 09:18:49.592 37 ERROR keystone.server.flask.application     __ret_val = __f(*args, **kwargs)
2023-03-17 09:18:49.592 37 ERROR keystone.server.flask.application   File "/var/lib/kolla/venv/lib/python3.9/site-packages/decorator.py", line 232, in fun
2023-03-17 09:18:49.592 37 ERROR keystone.server.flask.application     return caller(func, *(extras + args), **kw)
2023-03-17 09:18:49.592 37 ERROR keystone.server.flask.application   File "/var/lib/kolla/venv/lib/python3.9/site-packages/dogpile/cache/region.py", line 1577, in get_or_create_for_user_func
2023-03-17 09:18:49.592 37 ERROR keystone.server.flask.application     return self.get_or_create(
2023-03-17 09:18:49.592 37 ERROR keystone.server.flask.application   File "/var/lib/kolla/venv/lib/python3.9/site-packages/dogpile/cache/region.py", line 1042, in get_or_create
2023-03-17 09:18:49.592 37 ERROR keystone.server.flask.application     with Lock(
2023-03-17 09:18:49.592 37 ERROR keystone.server.flask.application   File "/var/lib/kolla/venv/lib/python3.9/site-packages/dogpile/lock.py", line 185, in __enter__
2023-03-17 09:18:49.592 37 ERROR keystone.server.flask.application     return self._enter()
2023-03-17 09:18:49.592 37 ERROR keystone.server.flask.application   File "/var/lib/kolla/venv/lib/python3.9/site-packages/dogpile/lock.py", line 94, in _enter
2023-03-17 09:18:49.592 37 ERROR keystone.server.flask.application     generated = self._enter_create(value, createdtime)
2023-03-17 09:18:49.592 37 ERROR keystone.server.flask.application   File "/var/lib/kolla/venv/lib/python3.9/site-packages/dogpile/lock.py", line 178, in _enter_create
2023-03-17 09:18:49.592 37 ERROR keystone.server.flask.application     return self.creator()
2023-03-17 09:18:49.592 37 ERROR keystone.server.flask.application   File "/var/lib/kolla/venv/lib/python3.9/site-packages/dogpile/cache/region.py", line 995, in gen_value
2023-03-17 09:18:49.592 37 ERROR keystone.server.flask.application     created_value = creator(
2023-03-17 09:18:49.592 37 ERROR keystone.server.flask.application   File "/var/lib/kolla/venv/lib/python3.9/site-packages/keystone/assignment/core.py", line 1276, in get_role
2023-03-17 09:18:49.592 37 ERROR keystone.server.flask.application     return self.driver.get_role(role_id)
2023-03-17 09:18:49.592 37 ERROR keystone.server.flask.application   File "/var/lib/kolla/venv/lib/python3.9/site-packages/keystone/assignment/role_backends/sql.py", line 70, in get_role
2023-03-17 09:18:49.592 37 ERROR keystone.server.flask.application     return self._get_role(session, role_id).to_dict()
2023-03-17 09:18:49.592 37 ERROR keystone.server.flask.application   File "/var/lib/kolla/venv/lib/python3.9/site-packages/keystone/assignment/role_backends/sql.py", line 65, in _get_role
2023-03-17 09:18:49.592 37 ERROR keystone.server.flask.application     raise exception.RoleNotFound(role_id=role_id)
2023-03-17 09:18:49.592 37 ERROR keystone.server.flask.application keystone.exception.RoleNotFound: Could not find role: admin.
2023-03-17 09:18:49.592 37 ERROR keystone.server.flask.application 
2023-03-17 09:18:50.732 37 ERROR keystone.server.flask.application [None req-75224906-5e09-4061-b8d5-567001798473 1d19bbf56d5f40c9b529281d0c1e72a5 - - all default -] Could not find user: ironic.: keystone.exception.UserNotFound: Could not find user: ironic.
2023-03-17 09:18:50.732 37 ERROR keystone.server.flask.application Traceback (most recent call last):
2023-03-17 09:18:50.732 37 ERROR keystone.server.flask.application   File "/var/lib/kolla/venv/lib/python3.9/site-packages/flask/app.py", line 1820, in full_dispatch_request
2023-03-17 09:18:50.732 37 ERROR keystone.server.flask.application     rv = self.dispatch_request()
2023-03-17 09:18:50.732 37 ERROR keystone.server.flask.application   File "/var/lib/kolla/venv/lib/python3.9/site-packages/flask/app.py", line 1796, in dispatch_request
2023-03-17 09:18:50.732 37 ERROR keystone.server.flask.application     return self.ensure_sync(self.view_functions[rule.endpoint])(**view_args)
2023-03-17 09:18:50.732 37 ERROR keystone.server.flask.application   File "/var/lib/kolla/venv/lib/python3.9/site-packages/flask_restful/__init__.py", line 467, in wrapper
2023-03-17 09:18:50.732 37 ERROR keystone.server.flask.application     resp = resource(*args, **kwargs)
2023-03-17 09:18:50.732 37 ERROR keystone.server.flask.application   File "/var/lib/kolla/venv/lib/python3.9/site-packages/flask/views.py", line 107, in view
2023-03-17 09:18:50.732 37 ERROR keystone.server.flask.application     return current_app.ensure_sync(self.dispatch_request)(**kwargs)
2023-03-17 09:18:50.732 37 ERROR keystone.server.flask.application   File "/var/lib/kolla/venv/lib/python3.9/site-packages/flask_restful/__init__.py", line 582, in dispatch_request
2023-03-17 09:18:50.732 37 ERROR keystone.server.flask.application     resp = meth(*args, **kwargs)
2023-03-17 09:18:50.732 37 ERROR keystone.server.flask.application   File "/var/lib/kolla/venv/lib/python3.9/site-packages/keystone/api/users.py", line 182, in get
2023-03-17 09:18:50.732 37 ERROR keystone.server.flask.application     return self._get_user(user_id)
2023-03-17 09:18:50.732 37 ERROR keystone.server.flask.application   File "/var/lib/kolla/venv/lib/python3.9/site-packages/keystone/api/users.py", line 194, in _get_user
2023-03-17 09:18:50.732 37 ERROR keystone.server.flask.application     ref = PROVIDERS.identity_api.get_user(user_id)
2023-03-17 09:18:50.732 37 ERROR keystone.server.flask.application   File "/var/lib/kolla/venv/lib/python3.9/site-packages/keystone/common/manager.py", line 115, in wrapped
2023-03-17 09:18:50.732 37 ERROR keystone.server.flask.application     __ret_val = __f(*args, **kwargs)
2023-03-17 09:18:50.732 37 ERROR keystone.server.flask.application   File "/var/lib/kolla/venv/lib/python3.9/site-packages/keystone/identity/core.py", line 414, in wrapper
2023-03-17 09:18:50.732 37 ERROR keystone.server.flask.application     return f(self, *args, **kwargs)
2023-03-17 09:18:50.732 37 ERROR keystone.server.flask.application   File "/var/lib/kolla/venv/lib/python3.9/site-packages/keystone/identity/core.py", line 424, in wrapper
2023-03-17 09:18:50.732 37 ERROR keystone.server.flask.application     return f(self, *args, **kwargs)
2023-03-17 09:18:50.732 37 ERROR keystone.server.flask.application   File "/var/lib/kolla/venv/lib/python3.9/site-packages/decorator.py", line 232, in fun
2023-03-17 09:18:50.732 37 ERROR keystone.server.flask.application     return caller(func, *(extras + args), **kw)
2023-03-17 09:18:50.732 37 ERROR keystone.server.flask.application   File "/var/lib/kolla/venv/lib/python3.9/site-packages/dogpile/cache/region.py", line 1577, in get_or_create_for_user_func
2023-03-17 09:18:50.732 37 ERROR keystone.server.flask.application     return self.get_or_create(
2023-03-17 09:18:50.732 37 ERROR keystone.server.flask.application   File "/var/lib/kolla/venv/lib/python3.9/site-packages/dogpile/cache/region.py", line 1042, in get_or_create
2023-03-17 09:18:50.732 37 ERROR keystone.server.flask.application     with Lock(
2023-03-17 09:18:50.732 37 ERROR keystone.server.flask.application   File "/var/lib/kolla/venv/lib/python3.9/site-packages/dogpile/lock.py", line 185, in __enter__
2023-03-17 09:18:50.732 37 ERROR keystone.server.flask.application     return self._enter()
2023-03-17 09:18:50.732 37 ERROR keystone.server.flask.application   File "/var/lib/kolla/venv/lib/python3.9/site-packages/dogpile/lock.py", line 94, in _enter
2023-03-17 09:18:50.732 37 ERROR keystone.server.flask.application     generated = self._enter_create(value, createdtime)
2023-03-17 09:18:50.732 37 ERROR keystone.server.flask.application   File "/var/lib/kolla/venv/lib/python3.9/site-packages/dogpile/lock.py", line 178, in _enter_create
2023-03-17 09:18:50.732 37 ERROR keystone.server.flask.application     return self.creator()
2023-03-17 09:18:50.732 37 ERROR keystone.server.flask.application   File "/var/lib/kolla/venv/lib/python3.9/site-packages/dogpile/cache/region.py", line 995, in gen_value
2023-03-17 09:18:50.732 37 ERROR keystone.server.flask.application     created_value = creator(
2023-03-17 09:18:50.732 37 ERROR keystone.server.flask.application   File "/var/lib/kolla/venv/lib/python3.9/site-packages/keystone/identity/core.py", line 1011, in get_user
2023-03-17 09:18:50.732 37 ERROR keystone.server.flask.application     ref = driver.get_user(entity_id)
2023-03-17 09:18:50.732 37 ERROR keystone.server.flask.application   File "/var/lib/kolla/venv/lib/python3.9/site-packages/keystone/identity/backends/sql.py", line 200, in get_user
2023-03-17 09:18:50.732 37 ERROR keystone.server.flask.application     self._get_user(session, user_id).to_dict())
2023-03-17 09:18:50.732 37 ERROR keystone.server.flask.application   File "/var/lib/kolla/venv/lib/python3.9/site-packages/keystone/identity/backends/sql.py", line 194, in _get_user
2023-03-17 09:18:50.732 37 ERROR keystone.server.flask.application     raise exception.UserNotFound(user_id=user_id)
2023-03-17 09:18:50.732 37 ERROR keystone.server.flask.application keystone.exception.UserNotFound: Could not find user: ironic.
2023-03-17 09:18:50.732 37 ERROR keystone.server.flask.application 
2023-03-17 09:18:51.425 38 ERROR keystone.server.flask.application [None req-be8e102c-f65d-4329-be40-08e5735717fb 1d19bbf56d5f40c9b529281d0c1e72a5 - - all default -] Could not find project: service.: keystone.exception.ProjectNotFound: Could not find project: service.
2023-03-17 09:18:51.425 38 ERROR keystone.server.flask.application Traceback (most recent call last):
2023-03-17 09:18:51.425 38 ERROR keystone.server.flask.application   File "/var/lib/kolla/venv/lib/python3.9/site-packages/flask/app.py", line 1820, in full_dispatch_request
2023-03-17 09:18:51.425 38 ERROR keystone.server.flask.application     rv = self.dispatch_request()
2023-03-17 09:18:51.425 38 ERROR keystone.server.flask.application   File "/var/lib/kolla/venv/lib/python3.9/site-packages/flask/app.py", line 1796, in dispatch_request
2023-03-17 09:18:51.425 38 ERROR keystone.server.flask.application     return self.ensure_sync(self.view_functions[rule.endpoint])(**view_args)
2023-03-17 09:18:51.425 38 ERROR keystone.server.flask.application   File "/var/lib/kolla/venv/lib/python3.9/site-packages/flask_restful/__init__.py", line 467, in wrapper
2023-03-17 09:18:51.425 38 ERROR keystone.server.flask.application     resp = resource(*args, **kwargs)
2023-03-17 09:18:51.425 38 ERROR keystone.server.flask.application   File "/var/lib/kolla/venv/lib/python3.9/site-packages/flask/views.py", line 107, in view
2023-03-17 09:18:51.425 38 ERROR keystone.server.flask.application     return current_app.ensure_sync(self.dispatch_request)(**kwargs)
2023-03-17 09:18:51.425 38 ERROR keystone.server.flask.application   File "/var/lib/kolla/venv/lib/python3.9/site-packages/flask_restful/__init__.py", line 582, in dispatch_request
2023-03-17 09:18:51.425 38 ERROR keystone.server.flask.application     resp = meth(*args, **kwargs)
2023-03-17 09:18:51.425 38 ERROR keystone.server.flask.application   File "/var/lib/kolla/venv/lib/python3.9/site-packages/keystone/api/projects.py", line 151, in get
2023-03-17 09:18:51.425 38 ERROR keystone.server.flask.application     return self._get_project(project_id)
2023-03-17 09:18:51.425 38 ERROR keystone.server.flask.application   File "/var/lib/kolla/venv/lib/python3.9/site-packages/keystone/api/projects.py", line 107, in _get_project
2023-03-17 09:18:51.425 38 ERROR keystone.server.flask.application     project = PROVIDERS.resource_api.get_project(project_id)
2023-03-17 09:18:51.425 38 ERROR keystone.server.flask.application   File "/var/lib/kolla/venv/lib/python3.9/site-packages/keystone/common/manager.py", line 115, in wrapped
2023-03-17 09:18:51.425 38 ERROR keystone.server.flask.application     __ret_val = __f(*args, **kwargs)
2023-03-17 09:18:51.425 38 ERROR keystone.server.flask.application   File "/var/lib/kolla/venv/lib/python3.9/site-packages/decorator.py", line 232, in fun
2023-03-17 09:18:51.425 38 ERROR keystone.server.flask.application     return caller(func, *(extras + args), **kw)
2023-03-17 09:18:51.425 38 ERROR keystone.server.flask.application   File "/var/lib/kolla/venv/lib/python3.9/site-packages/dogpile/cache/region.py", line 1577, in get_or_create_for_user_func
2023-03-17 09:18:51.425 38 ERROR keystone.server.flask.application     return self.get_or_create(
2023-03-17 09:18:51.425 38 ERROR keystone.server.flask.application   File "/var/lib/kolla/venv/lib/python3.9/site-packages/dogpile/cache/region.py", line 1042, in get_or_create
2023-03-17 09:18:51.425 38 ERROR keystone.server.flask.application     with Lock(
2023-03-17 09:18:51.425 38 ERROR keystone.server.flask.application   File "/var/lib/kolla/venv/lib/python3.9/site-packages/dogpile/lock.py", line 185, in __enter__
2023-03-17 09:18:51.425 38 ERROR keystone.server.flask.application     return self._enter()
2023-03-17 09:18:51.425 38 ERROR keystone.server.flask.application   File "/var/lib/kolla/venv/lib/python3.9/site-packages/dogpile/lock.py", line 94, in _enter
2023-03-17 09:18:51.425 38 ERROR keystone.server.flask.application     generated = self._enter_create(value, createdtime)
2023-03-17 09:18:51.425 38 ERROR keystone.server.flask.application   File "/var/lib/kolla/venv/lib/python3.9/site-packages/dogpile/lock.py", line 178, in _enter_create
2023-03-17 09:18:51.425 38 ERROR keystone.server.flask.application     return self.creator()
2023-03-17 09:18:51.425 38 ERROR keystone.server.flask.application   File "/var/lib/kolla/venv/lib/python3.9/site-packages/dogpile/cache/region.py", line 995, in gen_value
2023-03-17 09:18:51.425 38 ERROR keystone.server.flask.application     created_value = creator(
2023-03-17 09:18:51.425 38 ERROR keystone.server.flask.application   File "/var/lib/kolla/venv/lib/python3.9/site-packages/keystone/resource/core.py", line 903, in get_project
2023-03-17 09:18:51.425 38 ERROR keystone.server.flask.application     return self.driver.get_project(project_id)
2023-03-17 09:18:51.425 38 ERROR keystone.server.flask.application   File "/var/lib/kolla/venv/lib/python3.9/site-packages/keystone/resource/backends/sql.py", line 49, in get_project
2023-03-17 09:18:51.425 38 ERROR keystone.server.flask.application     return self._get_project(session, project_id).to_dict()
2023-03-17 09:18:51.425 38 ERROR keystone.server.flask.application   File "/var/lib/kolla/venv/lib/python3.9/site-packages/keystone/resource/backends/sql.py", line 44, in _get_project
2023-03-17 09:18:51.425 38 ERROR keystone.server.flask.application     raise exception.ProjectNotFound(project_id=project_id)
2023-03-17 09:18:51.425 38 ERROR keystone.server.flask.application keystone.exception.ProjectNotFound: Could not find project: service.
2023-03-17 09:18:51.425 38 ERROR keystone.server.flask.application 
2023-03-17 09:19:00.519 39 ERROR keystone.server.flask.application [None req-b957f24e-b11c-4b0d-9b89-798fe2faa05a 1d19bbf56d5f40c9b529281d0c1e72a5 - - all default -] Could not find role: admin.: keystone.exception.RoleNotFound: Could not find role: admin.
2023-03-17 09:19:00.519 39 ERROR keystone.server.flask.application Traceback (most recent call last):
2023-03-17 09:19:00.519 39 ERROR keystone.server.flask.application   File "/var/lib/kolla/venv/lib/python3.9/site-packages/flask/app.py", line 1820, in full_dispatch_request
2023-03-17 09:19:00.519 39 ERROR keystone.server.flask.application     rv = self.dispatch_request()
2023-03-17 09:19:00.519 39 ERROR keystone.server.flask.application   File "/var/lib/kolla/venv/lib/python3.9/site-packages/flask/app.py", line 1796, in dispatch_request
2023-03-17 09:19:00.519 39 ERROR keystone.server.flask.application     return self.ensure_sync(self.view_functions[rule.endpoint])(**view_args)
2023-03-17 09:19:00.519 39 ERROR keystone.server.flask.application   File "/var/lib/kolla/venv/lib/python3.9/site-packages/flask_restful/__init__.py", line 467, in wrapper
2023-03-17 09:19:00.519 39 ERROR keystone.server.flask.application     resp = resource(*args, **kwargs)
2023-03-17 09:19:00.519 39 ERROR keystone.server.flask.application   File "/var/lib/kolla/venv/lib/python3.9/site-packages/flask/views.py", line 107, in view
2023-03-17 09:19:00.519 39 ERROR keystone.server.flask.application     return current_app.ensure_sync(self.dispatch_request)(**kwargs)
2023-03-17 09:19:00.519 39 ERROR keystone.server.flask.application   File "/var/lib/kolla/venv/lib/python3.9/site-packages/flask_restful/__init__.py", line 582, in dispatch_request
2023-03-17 09:19:00.519 39 ERROR keystone.server.flask.application     resp = meth(*args, **kwargs)
2023-03-17 09:19:00.519 39 ERROR keystone.server.flask.application   File "/var/lib/kolla/venv/lib/python3.9/site-packages/keystone/api/roles.py", line 50, in get
2023-03-17 09:19:00.519 39 ERROR keystone.server.flask.application     return self._get_role(role_id)
2023-03-17 09:19:00.519 39 ERROR keystone.server.flask.application   File "/var/lib/kolla/venv/lib/python3.9/site-packages/keystone/api/roles.py", line 70, in _get_role
2023-03-17 09:19:00.519 39 ERROR keystone.server.flask.application     ENFORCER.enforce_call(action='identity:get_role')
2023-03-17 09:19:00.519 39 ERROR keystone.server.flask.application   File "/var/lib/kolla/venv/lib/python3.9/site-packages/keystone/common/rbac_enforcer/enforcer.py", line 402, in enforce_call
2023-03-17 09:19:00.519 39 ERROR keystone.server.flask.application     policy_dict.update(cls._extract_member_target_data(
2023-03-17 09:19:00.519 39 ERROR keystone.server.flask.application   File "/var/lib/kolla/venv/lib/python3.9/site-packages/keystone/common/rbac_enforcer/enforcer.py", line 234, in _extract_member_target_data
2023-03-17 09:19:00.519 39 ERROR keystone.server.flask.application     member_name: func(flask.request.view_args[key])
2023-03-17 09:19:00.519 39 ERROR keystone.server.flask.application   File "/var/lib/kolla/venv/lib/python3.9/site-packages/keystone/common/manager.py", line 115, in wrapped
2023-03-17 09:19:00.519 39 ERROR keystone.server.flask.application     __ret_val = __f(*args, **kwargs)
2023-03-17 09:19:00.519 39 ERROR keystone.server.flask.application   File "/var/lib/kolla/venv/lib/python3.9/site-packages/decorator.py", line 232, in fun
2023-03-17 09:19:00.519 39 ERROR keystone.server.flask.application     return caller(func, *(extras + args), **kw)
2023-03-17 09:19:00.519 39 ERROR keystone.server.flask.application   File "/var/lib/kolla/venv/lib/python3.9/site-packages/dogpile/cache/region.py", line 1577, in get_or_create_for_user_func
2023-03-17 09:19:00.519 39 ERROR keystone.server.flask.application     return self.get_or_create(
2023-03-17 09:19:00.519 39 ERROR keystone.server.flask.application   File "/var/lib/kolla/venv/lib/python3.9/site-packages/dogpile/cache/region.py", line 1042, in get_or_create
2023-03-17 09:19:00.519 39 ERROR keystone.server.flask.application     with Lock(
2023-03-17 09:19:00.519 39 ERROR keystone.server.flask.application   File "/var/lib/kolla/venv/lib/python3.9/site-packages/dogpile/lock.py", line 185, in __enter__
2023-03-17 09:19:00.519 39 ERROR keystone.server.flask.application     return self._enter()
2023-03-17 09:19:00.519 39 ERROR keystone.server.flask.application   File "/var/lib/kolla/venv/lib/python3.9/site-packages/dogpile/lock.py", line 94, in _enter
2023-03-17 09:19:00.519 39 ERROR keystone.server.flask.application     generated = self._enter_create(value, createdtime)
2023-03-17 09:19:00.519 39 ERROR keystone.server.flask.application   File "/var/lib/kolla/venv/lib/python3.9/site-packages/dogpile/lock.py", line 178, in _enter_create
2023-03-17 09:19:00.519 39 ERROR keystone.server.flask.application     return self.creator()
2023-03-17 09:19:00.519 39 ERROR keystone.server.flask.application   File "/var/lib/kolla/venv/lib/python3.9/site-packages/dogpile/cache/region.py", line 995, in gen_value
2023-03-17 09:19:00.519 39 ERROR keystone.server.flask.application     created_value = creator(
2023-03-17 09:19:00.519 39 ERROR keystone.server.flask.application   File "/var/lib/kolla/venv/lib/python3.9/site-packages/keystone/assignment/core.py", line 1276, in get_role
2023-03-17 09:19:00.519 39 ERROR keystone.server.flask.application     return self.driver.get_role(role_id)
2023-03-17 09:19:00.519 39 ERROR keystone.server.flask.application   File "/var/lib/kolla/venv/lib/python3.9/site-packages/keystone/assignment/role_backends/sql.py", line 70, in get_role
2023-03-17 09:19:00.519 39 ERROR keystone.server.flask.application     return self._get_role(session, role_id).to_dict()
2023-03-17 09:19:00.519 39 ERROR keystone.server.flask.application   File "/var/lib/kolla/venv/lib/python3.9/site-packages/keystone/assignment/role_backends/sql.py", line 65, in _get_role
2023-03-17 09:19:00.519 39 ERROR keystone.server.flask.application     raise exception.RoleNotFound(role_id=role_id)
2023-03-17 09:19:00.519 39 ERROR keystone.server.flask.application keystone.exception.RoleNotFound: Could not find role: admin.
2023-03-17 09:19:00.519 39 ERROR keystone.server.flask.application 
2023-03-17 09:19:01.676 39 ERROR keystone.server.flask.application [None req-8bd47806-8cf0-4330-8bf3-65a0baaebf3d 1d19bbf56d5f40c9b529281d0c1e72a5 - - all default -] Could not find user: ironic-inspector.: keystone.exception.UserNotFound: Could not find user: ironic-inspector.
2023-03-17 09:19:01.676 39 ERROR keystone.server.flask.application Traceback (most recent call last):
2023-03-17 09:19:01.676 39 ERROR keystone.server.flask.application   File "/var/lib/kolla/venv/lib/python3.9/site-packages/flask/app.py", line 1820, in full_dispatch_request
2023-03-17 09:19:01.676 39 ERROR keystone.server.flask.application     rv = self.dispatch_request()
2023-03-17 09:19:01.676 39 ERROR keystone.server.flask.application   File "/var/lib/kolla/venv/lib/python3.9/site-packages/flask/app.py", line 1796, in dispatch_request
2023-03-17 09:19:01.676 39 ERROR keystone.server.flask.application     return self.ensure_sync(self.view_functions[rule.endpoint])(**view_args)
2023-03-17 09:19:01.676 39 ERROR keystone.server.flask.application   File "/var/lib/kolla/venv/lib/python3.9/site-packages/flask_restful/__init__.py", line 467, in wrapper
2023-03-17 09:19:01.676 39 ERROR keystone.server.flask.application     resp = resource(*args, **kwargs)
2023-03-17 09:19:01.676 39 ERROR keystone.server.flask.application   File "/var/lib/kolla/venv/lib/python3.9/site-packages/flask/views.py", line 107, in view
2023-03-17 09:19:01.676 39 ERROR keystone.server.flask.application     return current_app.ensure_sync(self.dispatch_request)(**kwargs)
2023-03-17 09:19:01.676 39 ERROR keystone.server.flask.application   File "/var/lib/kolla/venv/lib/python3.9/site-packages/flask_restful/__init__.py", line 582, in dispatch_request
2023-03-17 09:19:01.676 39 ERROR keystone.server.flask.application     resp = meth(*args, **kwargs)
2023-03-17 09:19:01.676 39 ERROR keystone.server.flask.application   File "/var/lib/kolla/venv/lib/python3.9/site-packages/keystone/api/users.py", line 182, in get
2023-03-17 09:19:01.676 39 ERROR keystone.server.flask.application     return self._get_user(user_id)
2023-03-17 09:19:01.676 39 ERROR keystone.server.flask.application   File "/var/lib/kolla/venv/lib/python3.9/site-packages/keystone/api/users.py", line 194, in _get_user
2023-03-17 09:19:01.676 39 ERROR keystone.server.flask.application     ref = PROVIDERS.identity_api.get_user(user_id)
2023-03-17 09:19:01.676 39 ERROR keystone.server.flask.application   File "/var/lib/kolla/venv/lib/python3.9/site-packages/keystone/common/manager.py", line 115, in wrapped
2023-03-17 09:19:01.676 39 ERROR keystone.server.flask.application     __ret_val = __f(*args, **kwargs)
2023-03-17 09:19:01.676 39 ERROR keystone.server.flask.application   File "/var/lib/kolla/venv/lib/python3.9/site-packages/keystone/identity/core.py", line 414, in wrapper
2023-03-17 09:19:01.676 39 ERROR keystone.server.flask.application     return f(self, *args, **kwargs)
2023-03-17 09:19:01.676 39 ERROR keystone.server.flask.application   File "/var/lib/kolla/venv/lib/python3.9/site-packages/keystone/identity/core.py", line 424, in wrapper
2023-03-17 09:19:01.676 39 ERROR keystone.server.flask.application     return f(self, *args, **kwargs)
2023-03-17 09:19:01.676 39 ERROR keystone.server.flask.application   File "/var/lib/kolla/venv/lib/python3.9/site-packages/decorator.py", line 232, in fun
2023-03-17 09:19:01.676 39 ERROR keystone.server.flask.application     return caller(func, *(extras + args), **kw)
2023-03-17 09:19:01.676 39 ERROR keystone.server.flask.application   File "/var/lib/kolla/venv/lib/python3.9/site-packages/dogpile/cache/region.py", line 1577, in get_or_create_for_user_func
2023-03-17 09:19:01.676 39 ERROR keystone.server.flask.application     return self.get_or_create(
2023-03-17 09:19:01.676 39 ERROR keystone.server.flask.application   File "/var/lib/kolla/venv/lib/python3.9/site-packages/dogpile/cache/region.py", line 1042, in get_or_create
2023-03-17 09:19:01.676 39 ERROR keystone.server.flask.application     with Lock(
2023-03-17 09:19:01.676 39 ERROR keystone.server.flask.application   File "/var/lib/kolla/venv/lib/python3.9/site-packages/dogpile/lock.py", line 185, in __enter__
2023-03-17 09:19:01.676 39 ERROR keystone.server.flask.application     return self._enter()
2023-03-17 09:19:01.676 39 ERROR keystone.server.flask.application   File "/var/lib/kolla/venv/lib/python3.9/site-packages/dogpile/lock.py", line 94, in _enter
2023-03-17 09:19:01.676 39 ERROR keystone.server.flask.application     generated = self._enter_create(value, createdtime)
2023-03-17 09:19:01.676 39 ERROR keystone.server.flask.application   File "/var/lib/kolla/venv/lib/python3.9/site-packages/dogpile/lock.py", line 178, in _enter_create
2023-03-17 09:19:01.676 39 ERROR keystone.server.flask.application     return self.creator()
2023-03-17 09:19:01.676 39 ERROR keystone.server.flask.application   File "/var/lib/kolla/venv/lib/python3.9/site-packages/dogpile/cache/region.py", line 995, in gen_value
2023-03-17 09:19:01.676 39 ERROR keystone.server.flask.application     created_value = creator(
2023-03-17 09:19:01.676 39 ERROR keystone.server.flask.application   File "/var/lib/kolla/venv/lib/python3.9/site-packages/keystone/identity/core.py", line 1011, in get_user
2023-03-17 09:19:01.676 39 ERROR keystone.server.flask.application     ref = driver.get_user(entity_id)
2023-03-17 09:19:01.676 39 ERROR keystone.server.flask.application   File "/var/lib/kolla/venv/lib/python3.9/site-packages/keystone/identity/backends/sql.py", line 200, in get_user
2023-03-17 09:19:01.676 39 ERROR keystone.server.flask.application     self._get_user(session, user_id).to_dict())
2023-03-17 09:19:01.676 39 ERROR keystone.server.flask.application   File "/var/lib/kolla/venv/lib/python3.9/site-packages/keystone/identity/backends/sql.py", line 194, in _get_user
2023-03-17 09:19:01.676 39 ERROR keystone.server.flask.application     raise exception.UserNotFound(user_id=user_id)
2023-03-17 09:19:01.676 39 ERROR keystone.server.flask.application keystone.exception.UserNotFound: Could not find user: ironic-inspector.
2023-03-17 09:19:01.676 39 ERROR keystone.server.flask.application 
2023-03-17 09:19:02.428 37 ERROR keystone.server.flask.application [None req-d4926ef9-e32e-4be4-aa4f-3c0d0590847b 1d19bbf56d5f40c9b529281d0c1e72a5 - - all default -] Could not find project: service.: keystone.exception.ProjectNotFound: Could not find project: service.
2023-03-17 09:19:02.428 37 ERROR keystone.server.flask.application Traceback (most recent call last):
2023-03-17 09:19:02.428 37 ERROR keystone.server.flask.application   File "/var/lib/kolla/venv/lib/python3.9/site-packages/flask/app.py", line 1820, in full_dispatch_request
2023-03-17 09:19:02.428 37 ERROR keystone.server.flask.application     rv = self.dispatch_request()
2023-03-17 09:19:02.428 37 ERROR keystone.server.flask.application   File "/var/lib/kolla/venv/lib/python3.9/site-packages/flask/app.py", line 1796, in dispatch_request
2023-03-17 09:19:02.428 37 ERROR keystone.server.flask.application     return self.ensure_sync(self.view_functions[rule.endpoint])(**view_args)
2023-03-17 09:19:02.428 37 ERROR keystone.server.flask.application   File "/var/lib/kolla/venv/lib/python3.9/site-packages/flask_restful/__init__.py", line 467, in wrapper
2023-03-17 09:19:02.428 37 ERROR keystone.server.flask.application     resp = resource(*args, **kwargs)
2023-03-17 09:19:02.428 37 ERROR keystone.server.flask.application   File "/var/lib/kolla/venv/lib/python3.9/site-packages/flask/views.py", line 107, in view
2023-03-17 09:19:02.428 37 ERROR keystone.server.flask.application     return current_app.ensure_sync(self.dispatch_request)(**kwargs)
2023-03-17 09:19:02.428 37 ERROR keystone.server.flask.application   File "/var/lib/kolla/venv/lib/python3.9/site-packages/flask_restful/__init__.py", line 582, in dispatch_request
2023-03-17 09:19:02.428 37 ERROR keystone.server.flask.application     resp = meth(*args, **kwargs)
2023-03-17 09:19:02.428 37 ERROR keystone.server.flask.application   File "/var/lib/kolla/venv/lib/python3.9/site-packages/keystone/api/projects.py", line 151, in get
2023-03-17 09:19:02.428 37 ERROR keystone.server.flask.application     return self._get_project(project_id)
2023-03-17 09:19:02.428 37 ERROR keystone.server.flask.application   File "/var/lib/kolla/venv/lib/python3.9/site-packages/keystone/api/projects.py", line 107, in _get_project
2023-03-17 09:19:02.428 37 ERROR keystone.server.flask.application     project = PROVIDERS.resource_api.get_project(project_id)
2023-03-17 09:19:02.428 37 ERROR keystone.server.flask.application   File "/var/lib/kolla/venv/lib/python3.9/site-packages/keystone/common/manager.py", line 115, in wrapped
2023-03-17 09:19:02.428 37 ERROR keystone.server.flask.application     __ret_val = __f(*args, **kwargs)
2023-03-17 09:19:02.428 37 ERROR keystone.server.flask.application   File "/var/lib/kolla/venv/lib/python3.9/site-packages/decorator.py", line 232, in fun
2023-03-17 09:19:02.428 37 ERROR keystone.server.flask.application     return caller(func, *(extras + args), **kw)
2023-03-17 09:19:02.428 37 ERROR keystone.server.flask.application   File "/var/lib/kolla/venv/lib/python3.9/site-packages/dogpile/cache/region.py", line 1577, in get_or_create_for_user_func
2023-03-17 09:19:02.428 37 ERROR keystone.server.flask.application     return self.get_or_create(
2023-03-17 09:19:02.428 37 ERROR keystone.server.flask.application   File "/var/lib/kolla/venv/lib/python3.9/site-packages/dogpile/cache/region.py", line 1042, in get_or_create
2023-03-17 09:19:02.428 37 ERROR keystone.server.flask.application     with Lock(
2023-03-17 09:19:02.428 37 ERROR keystone.server.flask.application   File "/var/lib/kolla/venv/lib/python3.9/site-packages/dogpile/lock.py", line 185, in __enter__
2023-03-17 09:19:02.428 37 ERROR keystone.server.flask.application     return self._enter()
2023-03-17 09:19:02.428 37 ERROR keystone.server.flask.application   File "/var/lib/kolla/venv/lib/python3.9/site-packages/dogpile/lock.py", line 94, in _enter
2023-03-17 09:19:02.428 37 ERROR keystone.server.flask.application     generated = self._enter_create(value, createdtime)
2023-03-17 09:19:02.428 37 ERROR keystone.server.flask.application   File "/var/lib/kolla/venv/lib/python3.9/site-packages/dogpile/lock.py", line 178, in _enter_create
2023-03-17 09:19:02.428 37 ERROR keystone.server.flask.application     return self.creator()
2023-03-17 09:19:02.428 37 ERROR keystone.server.flask.application   File "/var/lib/kolla/venv/lib/python3.9/site-packages/dogpile/cache/region.py", line 995, in gen_value
2023-03-17 09:19:02.428 37 ERROR keystone.server.flask.application     created_value = creator(
2023-03-17 09:19:02.428 37 ERROR keystone.server.flask.application   File "/var/lib/kolla/venv/lib/python3.9/site-packages/keystone/resource/core.py", line 903, in get_project
2023-03-17 09:19:02.428 37 ERROR keystone.server.flask.application     return self.driver.get_project(project_id)
2023-03-17 09:19:02.428 37 ERROR keystone.server.flask.application   File "/var/lib/kolla/venv/lib/python3.9/site-packages/keystone/resource/backends/sql.py", line 49, in get_project
2023-03-17 09:19:02.428 37 ERROR keystone.server.flask.application     return self._get_project(session, project_id).to_dict()
2023-03-17 09:19:02.428 37 ERROR keystone.server.flask.application   File "/var/lib/kolla/venv/lib/python3.9/site-packages/keystone/resource/backends/sql.py", line 44, in _get_project
2023-03-17 09:19:02.428 37 ERROR keystone.server.flask.application     raise exception.ProjectNotFound(project_id=project_id)
2023-03-17 09:19:02.428 37 ERROR keystone.server.flask.application keystone.exception.ProjectNotFound: Could not find project: service.
2023-03-17 09:19:02.428 37 ERROR keystone.server.flask.application 
2023-03-17 09:21:49.832 37 ERROR keystone.server.flask.application [None req-42663634-30ca-4c5c-aa10-53a5b56a92ad 1d19bbf56d5f40c9b529281d0c1e72a5 - - all default -] Could not find project: service.: keystone.exception.ProjectNotFound: Could not find project: service.
2023-03-17 09:21:49.832 37 ERROR keystone.server.flask.application Traceback (most recent call last):
2023-03-17 09:21:49.832 37 ERROR keystone.server.flask.application   File "/var/lib/kolla/venv/lib/python3.9/site-packages/flask/app.py", line 1820, in full_dispatch_request
2023-03-17 09:21:49.832 37 ERROR keystone.server.flask.application     rv = self.dispatch_request()
2023-03-17 09:21:49.832 37 ERROR keystone.server.flask.application   File "/var/lib/kolla/venv/lib/python3.9/site-packages/flask/app.py", line 1796, in dispatch_request
2023-03-17 09:21:49.832 37 ERROR keystone.server.flask.application     return self.ensure_sync(self.view_functions[rule.endpoint])(**view_args)
2023-03-17 09:21:49.832 37 ERROR keystone.server.flask.application   File "/var/lib/kolla/venv/lib/python3.9/site-packages/flask_restful/__init__.py", line 467, in wrapper
2023-03-17 09:21:49.832 37 ERROR keystone.server.flask.application     resp = resource(*args, **kwargs)
2023-03-17 09:21:49.832 37 ERROR keystone.server.flask.application   File "/var/lib/kolla/venv/lib/python3.9/site-packages/flask/views.py", line 107, in view
2023-03-17 09:21:49.832 37 ERROR keystone.server.flask.application     return current_app.ensure_sync(self.dispatch_request)(**kwargs)
2023-03-17 09:21:49.832 37 ERROR keystone.server.flask.application   File "/var/lib/kolla/venv/lib/python3.9/site-packages/flask_restful/__init__.py", line 582, in dispatch_request
2023-03-17 09:21:49.832 37 ERROR keystone.server.flask.application     resp = meth(*args, **kwargs)
2023-03-17 09:21:49.832 37 ERROR keystone.server.flask.application   File "/var/lib/kolla/venv/lib/python3.9/site-packages/keystone/api/projects.py", line 151, in get
2023-03-17 09:21:49.832 37 ERROR keystone.server.flask.application     return self._get_project(project_id)
2023-03-17 09:21:49.832 37 ERROR keystone.server.flask.application   File "/var/lib/kolla/venv/lib/python3.9/site-packages/keystone/api/projects.py", line 107, in _get_project
2023-03-17 09:21:49.832 37 ERROR keystone.server.flask.application     project = PROVIDERS.resource_api.get_project(project_id)
2023-03-17 09:21:49.832 37 ERROR keystone.server.flask.application   File "/var/lib/kolla/venv/lib/python3.9/site-packages/keystone/common/manager.py", line 115, in wrapped
2023-03-17 09:21:49.832 37 ERROR keystone.server.flask.application     __ret_val = __f(*args, **kwargs)
2023-03-17 09:21:49.832 37 ERROR keystone.server.flask.application   File "/var/lib/kolla/venv/lib/python3.9/site-packages/decorator.py", line 232, in fun
2023-03-17 09:21:49.832 37 ERROR keystone.server.flask.application     return caller(func, *(extras + args), **kw)
2023-03-17 09:21:49.832 37 ERROR keystone.server.flask.application   File "/var/lib/kolla/venv/lib/python3.9/site-packages/dogpile/cache/region.py", line 1577, in get_or_create_for_user_func
2023-03-17 09:21:49.832 37 ERROR keystone.server.flask.application     return self.get_or_create(
2023-03-17 09:21:49.832 37 ERROR keystone.server.flask.application   File "/var/lib/kolla/venv/lib/python3.9/site-packages/dogpile/cache/region.py", line 1042, in get_or_create
2023-03-17 09:21:49.832 37 ERROR keystone.server.flask.application     with Lock(
2023-03-17 09:21:49.832 37 ERROR keystone.server.flask.application   File "/var/lib/kolla/venv/lib/python3.9/site-packages/dogpile/lock.py", line 185, in __enter__
2023-03-17 09:21:49.832 37 ERROR keystone.server.flask.application     return self._enter()
2023-03-17 09:21:49.832 37 ERROR keystone.server.flask.application   File "/var/lib/kolla/venv/lib/python3.9/site-packages/dogpile/lock.py", line 94, in _enter
2023-03-17 09:21:49.832 37 ERROR keystone.server.flask.application     generated = self._enter_create(value, createdtime)
2023-03-17 09:21:49.832 37 ERROR keystone.server.flask.application   File "/var/lib/kolla/venv/lib/python3.9/site-packages/dogpile/lock.py", line 178, in _enter_create
2023-03-17 09:21:49.832 37 ERROR keystone.server.flask.application     return self.creator()
2023-03-17 09:21:49.832 37 ERROR keystone.server.flask.application   File "/var/lib/kolla/venv/lib/python3.9/site-packages/dogpile/cache/region.py", line 995, in gen_value
2023-03-17 09:21:49.832 37 ERROR keystone.server.flask.application     created_value = creator(
2023-03-17 09:21:49.832 37 ERROR keystone.server.flask.application   File "/var/lib/kolla/venv/lib/python3.9/site-packages/keystone/resource/core.py", line 903, in get_project
2023-03-17 09:21:49.832 37 ERROR keystone.server.flask.application     return self.driver.get_project(project_id)
2023-03-17 09:21:49.832 37 ERROR keystone.server.flask.application   File "/var/lib/kolla/venv/lib/python3.9/site-packages/keystone/resource/backends/sql.py", line 49, in get_project
2023-03-17 09:21:49.832 37 ERROR keystone.server.flask.application     return self._get_project(session, project_id).to_dict()
2023-03-17 09:21:49.832 37 ERROR keystone.server.flask.application   File "/var/lib/kolla/venv/lib/python3.9/site-packages/keystone/resource/backends/sql.py", line 44, in _get_project
2023-03-17 09:21:49.832 37 ERROR keystone.server.flask.application     raise exception.ProjectNotFound(project_id=project_id)
2023-03-17 09:21:49.832 37 ERROR keystone.server.flask.application keystone.exception.ProjectNotFound: Could not find project: service.
2023-03-17 09:21:49.832 37 ERROR keystone.server.flask.application 
2023-03-17 09:22:03.743 39 ERROR keystone.server.flask.application [None req-013e41d0-f5b1-40de-bb22-27e4e3d85a33 1d19bbf56d5f40c9b529281d0c1e72a5 - - all default -] Could not find role: admin.: keystone.exception.RoleNotFound: Could not find role: admin.
2023-03-17 09:22:03.743 39 ERROR keystone.server.flask.application Traceback (most recent call last):
2023-03-17 09:22:03.743 39 ERROR keystone.server.flask.application   File "/var/lib/kolla/venv/lib/python3.9/site-packages/flask/app.py", line 1820, in full_dispatch_request
2023-03-17 09:22:03.743 39 ERROR keystone.server.flask.application     rv = self.dispatch_request()
2023-03-17 09:22:03.743 39 ERROR keystone.server.flask.application   File "/var/lib/kolla/venv/lib/python3.9/site-packages/flask/app.py", line 1796, in dispatch_request
2023-03-17 09:22:03.743 39 ERROR keystone.server.flask.application     return self.ensure_sync(self.view_functions[rule.endpoint])(**view_args)
2023-03-17 09:22:03.743 39 ERROR keystone.server.flask.application   File "/var/lib/kolla/venv/lib/python3.9/site-packages/flask_restful/__init__.py", line 467, in wrapper
2023-03-17 09:22:03.743 39 ERROR keystone.server.flask.application     resp = resource(*args, **kwargs)
2023-03-17 09:22:03.743 39 ERROR keystone.server.flask.application   File "/var/lib/kolla/venv/lib/python3.9/site-packages/flask/views.py", line 107, in view
2023-03-17 09:22:03.743 39 ERROR keystone.server.flask.application     return current_app.ensure_sync(self.dispatch_request)(**kwargs)
2023-03-17 09:22:03.743 39 ERROR keystone.server.flask.application   File "/var/lib/kolla/venv/lib/python3.9/site-packages/flask_restful/__init__.py", line 582, in dispatch_request
2023-03-17 09:22:03.743 39 ERROR keystone.server.flask.application     resp = meth(*args, **kwargs)
2023-03-17 09:22:03.743 39 ERROR keystone.server.flask.application   File "/var/lib/kolla/venv/lib/python3.9/site-packages/keystone/api/roles.py", line 50, in get
2023-03-17 09:22:03.743 39 ERROR keystone.server.flask.application     return self._get_role(role_id)
2023-03-17 09:22:03.743 39 ERROR keystone.server.flask.application   File "/var/lib/kolla/venv/lib/python3.9/site-packages/keystone/api/roles.py", line 70, in _get_role
2023-03-17 09:22:03.743 39 ERROR keystone.server.flask.application     ENFORCER.enforce_call(action='identity:get_role')
2023-03-17 09:22:03.743 39 ERROR keystone.server.flask.application   File "/var/lib/kolla/venv/lib/python3.9/site-packages/keystone/common/rbac_enforcer/enforcer.py", line 402, in enforce_call
2023-03-17 09:22:03.743 39 ERROR keystone.server.flask.application     policy_dict.update(cls._extract_member_target_data(
2023-03-17 09:22:03.743 39 ERROR keystone.server.flask.application   File "/var/lib/kolla/venv/lib/python3.9/site-packages/keystone/common/rbac_enforcer/enforcer.py", line 234, in _extract_member_target_data
2023-03-17 09:22:03.743 39 ERROR keystone.server.flask.application     member_name: func(flask.request.view_args[key])
2023-03-17 09:22:03.743 39 ERROR keystone.server.flask.application   File "/var/lib/kolla/venv/lib/python3.9/site-packages/keystone/common/manager.py", line 115, in wrapped
2023-03-17 09:22:03.743 39 ERROR keystone.server.flask.application     __ret_val = __f(*args, **kwargs)
2023-03-17 09:22:03.743 39 ERROR keystone.server.flask.application   File "/var/lib/kolla/venv/lib/python3.9/site-packages/decorator.py", line 232, in fun
2023-03-17 09:22:03.743 39 ERROR keystone.server.flask.application     return caller(func, *(extras + args), **kw)
2023-03-17 09:22:03.743 39 ERROR keystone.server.flask.application   File "/var/lib/kolla/venv/lib/python3.9/site-packages/dogpile/cache/region.py", line 1577, in get_or_create_for_user_func
2023-03-17 09:22:03.743 39 ERROR keystone.server.flask.application     return self.get_or_create(
2023-03-17 09:22:03.743 39 ERROR keystone.server.flask.application   File "/var/lib/kolla/venv/lib/python3.9/site-packages/dogpile/cache/region.py", line 1042, in get_or_create
2023-03-17 09:22:03.743 39 ERROR keystone.server.flask.application     with Lock(
2023-03-17 09:22:03.743 39 ERROR keystone.server.flask.application   File "/var/lib/kolla/venv/lib/python3.9/site-packages/dogpile/lock.py", line 185, in __enter__
2023-03-17 09:22:03.743 39 ERROR keystone.server.flask.application     return self._enter()
2023-03-17 09:22:03.743 39 ERROR keystone.server.flask.application   File "/var/lib/kolla/venv/lib/python3.9/site-packages/dogpile/lock.py", line 94, in _enter
2023-03-17 09:22:03.743 39 ERROR keystone.server.flask.application     generated = self._enter_create(value, createdtime)
2023-03-17 09:22:03.743 39 ERROR keystone.server.flask.application   File "/var/lib/kolla/venv/lib/python3.9/site-packages/dogpile/lock.py", line 178, in _enter_create
2023-03-17 09:22:03.743 39 ERROR keystone.server.flask.application     return self.creator()
2023-03-17 09:22:03.743 39 ERROR keystone.server.flask.application   File "/var/lib/kolla/venv/lib/python3.9/site-packages/dogpile/cache/region.py", line 995, in gen_value
2023-03-17 09:22:03.743 39 ERROR keystone.server.flask.application     created_value = creator(
2023-03-17 09:22:03.743 39 ERROR keystone.server.flask.application   File "/var/lib/kolla/venv/lib/python3.9/site-packages/keystone/assignment/core.py", line 1276, in get_role
2023-03-17 09:22:03.743 39 ERROR keystone.server.flask.application     return self.driver.get_role(role_id)
2023-03-17 09:22:03.743 39 ERROR keystone.server.flask.application   File "/var/lib/kolla/venv/lib/python3.9/site-packages/keystone/assignment/role_backends/sql.py", line 70, in get_role
2023-03-17 09:22:03.743 39 ERROR keystone.server.flask.application     return self._get_role(session, role_id).to_dict()
2023-03-17 09:22:03.743 39 ERROR keystone.server.flask.application   File "/var/lib/kolla/venv/lib/python3.9/site-packages/keystone/assignment/role_backends/sql.py", line 65, in _get_role
2023-03-17 09:22:03.743 39 ERROR keystone.server.flask.application     raise exception.RoleNotFound(role_id=role_id)
2023-03-17 09:22:03.743 39 ERROR keystone.server.flask.application keystone.exception.RoleNotFound: Could not find role: admin.
2023-03-17 09:22:03.743 39 ERROR keystone.server.flask.application 
2023-03-17 09:22:04.875 39 ERROR keystone.server.flask.application [None req-31396f0e-6815-4eb7-9585-fec65ac4692d 1d19bbf56d5f40c9b529281d0c1e72a5 - - all default -] Could not find user: neutron.: keystone.exception.UserNotFound: Could not find user: neutron.
2023-03-17 09:22:04.875 39 ERROR keystone.server.flask.application Traceback (most recent call last):
2023-03-17 09:22:04.875 39 ERROR keystone.server.flask.application   File "/var/lib/kolla/venv/lib/python3.9/site-packages/flask/app.py", line 1820, in full_dispatch_request
2023-03-17 09:22:04.875 39 ERROR keystone.server.flask.application     rv = self.dispatch_request()
2023-03-17 09:22:04.875 39 ERROR keystone.server.flask.application   File "/var/lib/kolla/venv/lib/python3.9/site-packages/flask/app.py", line 1796, in dispatch_request
2023-03-17 09:22:04.875 39 ERROR keystone.server.flask.application     return self.ensure_sync(self.view_functions[rule.endpoint])(**view_args)
2023-03-17 09:22:04.875 39 ERROR keystone.server.flask.application   File "/var/lib/kolla/venv/lib/python3.9/site-packages/flask_restful/__init__.py", line 467, in wrapper
2023-03-17 09:22:04.875 39 ERROR keystone.server.flask.application     resp = resource(*args, **kwargs)
2023-03-17 09:22:04.875 39 ERROR keystone.server.flask.application   File "/var/lib/kolla/venv/lib/python3.9/site-packages/flask/views.py", line 107, in view
2023-03-17 09:22:04.875 39 ERROR keystone.server.flask.application     return current_app.ensure_sync(self.dispatch_request)(**kwargs)
2023-03-17 09:22:04.875 39 ERROR keystone.server.flask.application   File "/var/lib/kolla/venv/lib/python3.9/site-packages/flask_restful/__init__.py", line 582, in dispatch_request
2023-03-17 09:22:04.875 39 ERROR keystone.server.flask.application     resp = meth(*args, **kwargs)
2023-03-17 09:22:04.875 39 ERROR keystone.server.flask.application   File "/var/lib/kolla/venv/lib/python3.9/site-packages/keystone/api/users.py", line 182, in get
2023-03-17 09:22:04.875 39 ERROR keystone.server.flask.application     return self._get_user(user_id)
2023-03-17 09:22:04.875 39 ERROR keystone.server.flask.application   File "/var/lib/kolla/venv/lib/python3.9/site-packages/keystone/api/users.py", line 194, in _get_user
2023-03-17 09:22:04.875 39 ERROR keystone.server.flask.application     ref = PROVIDERS.identity_api.get_user(user_id)
2023-03-17 09:22:04.875 39 ERROR keystone.server.flask.application   File "/var/lib/kolla/venv/lib/python3.9/site-packages/keystone/common/manager.py", line 115, in wrapped
2023-03-17 09:22:04.875 39 ERROR keystone.server.flask.application     __ret_val = __f(*args, **kwargs)
2023-03-17 09:22:04.875 39 ERROR keystone.server.flask.application   File "/var/lib/kolla/venv/lib/python3.9/site-packages/keystone/identity/core.py", line 414, in wrapper
2023-03-17 09:22:04.875 39 ERROR keystone.server.flask.application     return f(self, *args, **kwargs)
2023-03-17 09:22:04.875 39 ERROR keystone.server.flask.application   File "/var/lib/kolla/venv/lib/python3.9/site-packages/keystone/identity/core.py", line 424, in wrapper
2023-03-17 09:22:04.875 39 ERROR keystone.server.flask.application     return f(self, *args, **kwargs)
2023-03-17 09:22:04.875 39 ERROR keystone.server.flask.application   File "/var/lib/kolla/venv/lib/python3.9/site-packages/decorator.py", line 232, in fun
2023-03-17 09:22:04.875 39 ERROR keystone.server.flask.application     return caller(func, *(extras + args), **kw)
2023-03-17 09:22:04.875 39 ERROR keystone.server.flask.application   File "/var/lib/kolla/venv/lib/python3.9/site-packages/dogpile/cache/region.py", line 1577, in get_or_create_for_user_func
2023-03-17 09:22:04.875 39 ERROR keystone.server.flask.application     return self.get_or_create(
2023-03-17 09:22:04.875 39 ERROR keystone.server.flask.application   File "/var/lib/kolla/venv/lib/python3.9/site-packages/dogpile/cache/region.py", line 1042, in get_or_create
2023-03-17 09:22:04.875 39 ERROR keystone.server.flask.application     with Lock(
2023-03-17 09:22:04.875 39 ERROR keystone.server.flask.application   File "/var/lib/kolla/venv/lib/python3.9/site-packages/dogpile/lock.py", line 185, in __enter__
2023-03-17 09:22:04.875 39 ERROR keystone.server.flask.application     return self._enter()
2023-03-17 09:22:04.875 39 ERROR keystone.server.flask.application   File "/var/lib/kolla/venv/lib/python3.9/site-packages/dogpile/lock.py", line 94, in _enter
2023-03-17 09:22:04.875 39 ERROR keystone.server.flask.application     generated = self._enter_create(value, createdtime)
2023-03-17 09:22:04.875 39 ERROR keystone.server.flask.application   File "/var/lib/kolla/venv/lib/python3.9/site-packages/dogpile/lock.py", line 178, in _enter_create
2023-03-17 09:22:04.875 39 ERROR keystone.server.flask.application     return self.creator()
2023-03-17 09:22:04.875 39 ERROR keystone.server.flask.application   File "/var/lib/kolla/venv/lib/python3.9/site-packages/dogpile/cache/region.py", line 995, in gen_value
2023-03-17 09:22:04.875 39 ERROR keystone.server.flask.application     created_value = creator(
2023-03-17 09:22:04.875 39 ERROR keystone.server.flask.application   File "/var/lib/kolla/venv/lib/python3.9/site-packages/keystone/identity/core.py", line 1011, in get_user
2023-03-17 09:22:04.875 39 ERROR keystone.server.flask.application     ref = driver.get_user(entity_id)
2023-03-17 09:22:04.875 39 ERROR keystone.server.flask.application   File "/var/lib/kolla/venv/lib/python3.9/site-packages/keystone/identity/backends/sql.py", line 200, in get_user
2023-03-17 09:22:04.875 39 ERROR keystone.server.flask.application     self._get_user(session, user_id).to_dict())
2023-03-17 09:22:04.875 39 ERROR keystone.server.flask.application   File "/var/lib/kolla/venv/lib/python3.9/site-packages/keystone/identity/backends/sql.py", line 194, in _get_user
2023-03-17 09:22:04.875 39 ERROR keystone.server.flask.application     raise exception.UserNotFound(user_id=user_id)
2023-03-17 09:22:04.875 39 ERROR keystone.server.flask.application keystone.exception.UserNotFound: Could not find user: neutron.
2023-03-17 09:22:04.875 39 ERROR keystone.server.flask.application 
2023-03-17 09:22:05.643 38 ERROR keystone.server.flask.application [None req-5ee496f2-c548-404e-ae11-aac4662a0b7d 1d19bbf56d5f40c9b529281d0c1e72a5 - - all default -] Could not find project: service.: keystone.exception.ProjectNotFound: Could not find project: service.
2023-03-17 09:22:05.643 38 ERROR keystone.server.flask.application Traceback (most recent call last):
2023-03-17 09:22:05.643 38 ERROR keystone.server.flask.application   File "/var/lib/kolla/venv/lib/python3.9/site-packages/flask/app.py", line 1820, in full_dispatch_request
2023-03-17 09:22:05.643 38 ERROR keystone.server.flask.application     rv = self.dispatch_request()
2023-03-17 09:22:05.643 38 ERROR keystone.server.flask.application   File "/var/lib/kolla/venv/lib/python3.9/site-packages/flask/app.py", line 1796, in dispatch_request
2023-03-17 09:22:05.643 38 ERROR keystone.server.flask.application     return self.ensure_sync(self.view_functions[rule.endpoint])(**view_args)
2023-03-17 09:22:05.643 38 ERROR keystone.server.flask.application   File "/var/lib/kolla/venv/lib/python3.9/site-packages/flask_restful/__init__.py", line 467, in wrapper
2023-03-17 09:22:05.643 38 ERROR keystone.server.flask.application     resp = resource(*args, **kwargs)
2023-03-17 09:22:05.643 38 ERROR keystone.server.flask.application   File "/var/lib/kolla/venv/lib/python3.9/site-packages/flask/views.py", line 107, in view
2023-03-17 09:22:05.643 38 ERROR keystone.server.flask.application     return current_app.ensure_sync(self.dispatch_request)(**kwargs)
2023-03-17 09:22:05.643 38 ERROR keystone.server.flask.application   File "/var/lib/kolla/venv/lib/python3.9/site-packages/flask_restful/__init__.py", line 582, in dispatch_request
2023-03-17 09:22:05.643 38 ERROR keystone.server.flask.application     resp = meth(*args, **kwargs)
2023-03-17 09:22:05.643 38 ERROR keystone.server.flask.application   File "/var/lib/kolla/venv/lib/python3.9/site-packages/keystone/api/projects.py", line 151, in get
2023-03-17 09:22:05.643 38 ERROR keystone.server.flask.application     return self._get_project(project_id)
2023-03-17 09:22:05.643 38 ERROR keystone.server.flask.application   File "/var/lib/kolla/venv/lib/python3.9/site-packages/keystone/api/projects.py", line 107, in _get_project
2023-03-17 09:22:05.643 38 ERROR keystone.server.flask.application     project = PROVIDERS.resource_api.get_project(project_id)
2023-03-17 09:22:05.643 38 ERROR keystone.server.flask.application   File "/var/lib/kolla/venv/lib/python3.9/site-packages/keystone/common/manager.py", line 115, in wrapped
2023-03-17 09:22:05.643 38 ERROR keystone.server.flask.application     __ret_val = __f(*args, **kwargs)
2023-03-17 09:22:05.643 38 ERROR keystone.server.flask.application   File "/var/lib/kolla/venv/lib/python3.9/site-packages/decorator.py", line 232, in fun
2023-03-17 09:22:05.643 38 ERROR keystone.server.flask.application     return caller(func, *(extras + args), **kw)
2023-03-17 09:22:05.643 38 ERROR keystone.server.flask.application   File "/var/lib/kolla/venv/lib/python3.9/site-packages/dogpile/cache/region.py", line 1577, in get_or_create_for_user_func
2023-03-17 09:22:05.643 38 ERROR keystone.server.flask.application     return self.get_or_create(
2023-03-17 09:22:05.643 38 ERROR keystone.server.flask.application   File "/var/lib/kolla/venv/lib/python3.9/site-packages/dogpile/cache/region.py", line 1042, in get_or_create
2023-03-17 09:22:05.643 38 ERROR keystone.server.flask.application     with Lock(
2023-03-17 09:22:05.643 38 ERROR keystone.server.flask.application   File "/var/lib/kolla/venv/lib/python3.9/site-packages/dogpile/lock.py", line 185, in __enter__
2023-03-17 09:22:05.643 38 ERROR keystone.server.flask.application     return self._enter()
2023-03-17 09:22:05.643 38 ERROR keystone.server.flask.application   File "/var/lib/kolla/venv/lib/python3.9/site-packages/dogpile/lock.py", line 94, in _enter
2023-03-17 09:22:05.643 38 ERROR keystone.server.flask.application     generated = self._enter_create(value, createdtime)
2023-03-17 09:22:05.643 38 ERROR keystone.server.flask.application   File "/var/lib/kolla/venv/lib/python3.9/site-packages/dogpile/lock.py", line 178, in _enter_create
2023-03-17 09:22:05.643 38 ERROR keystone.server.flask.application     return self.creator()
2023-03-17 09:22:05.643 38 ERROR keystone.server.flask.application   File "/var/lib/kolla/venv/lib/python3.9/site-packages/dogpile/cache/region.py", line 995, in gen_value
2023-03-17 09:22:05.643 38 ERROR keystone.server.flask.application     created_value = creator(
2023-03-17 09:22:05.643 38 ERROR keystone.server.flask.application   File "/var/lib/kolla/venv/lib/python3.9/site-packages/keystone/resource/core.py", line 903, in get_project
2023-03-17 09:22:05.643 38 ERROR keystone.server.flask.application     return self.driver.get_project(project_id)
2023-03-17 09:22:05.643 38 ERROR keystone.server.flask.application   File "/var/lib/kolla/venv/lib/python3.9/site-packages/keystone/resource/backends/sql.py", line 49, in get_project
2023-03-17 09:22:05.643 38 ERROR keystone.server.flask.application     return self._get_project(session, project_id).to_dict()
2023-03-17 09:22:05.643 38 ERROR keystone.server.flask.application   File "/var/lib/kolla/venv/lib/python3.9/site-packages/keystone/resource/backends/sql.py", line 44, in _get_project
2023-03-17 09:22:05.643 38 ERROR keystone.server.flask.application     raise exception.ProjectNotFound(project_id=project_id)
2023-03-17 09:22:05.643 38 ERROR keystone.server.flask.application keystone.exception.ProjectNotFound: Could not find project: service.
2023-03-17 09:22:05.643 38 ERROR keystone.server.flask.application 
2023-03-17 10:46:18.390 39 WARNING py.warnings [None req-409446eb-7050-46b0-8a26-92c5057af3d8 1d19bbf56d5f40c9b529281d0c1e72a5 9206716707b74a55b789ac17ddc66873 - - default default] /var/lib/kolla/venv/lib/python3.9/site-packages/oslo_policy/policy.py:1129: UserWarning: Policy "identity:list_domains": "role:reader and system_scope:all" failed scope check. The token used to make the request was project scoped but the policy requires ['system'] scope. This behavior may change in the future where using the intended scope is required
  warnings.warn(msg)

2023-03-17 10:46:18.640 38 WARNING py.warnings [None req-e7ed9ff1-eb7a-493a-9861-dcf8a4586fa6 1d19bbf56d5f40c9b529281d0c1e72a5 9206716707b74a55b789ac17ddc66873 - - default default] /var/lib/kolla/venv/lib/python3.9/site-packages/oslo_policy/policy.py:1129: UserWarning: Policy "identity:create_project": "(role:admin and system_scope:all) or (role:admin and domain_id:%(target.project.domain_id)s)" failed scope check. The token used to make the request was project scoped but the policy requires ['system', 'domain'] scope. This behavior may change in the future where using the intended scope is required
  warnings.warn(msg)

2023-03-17 10:46:18.951 37 WARNING py.warnings [None req-0a586c47-a150-4faa-b4b1-dde9c12fae9e 1d19bbf56d5f40c9b529281d0c1e72a5 9206716707b74a55b789ac17ddc66873 - - default default] /var/lib/kolla/venv/lib/python3.9/site-packages/oslo_policy/policy.py:1129: UserWarning: Policy "identity:create_user": "(role:admin and system_scope:all) or (role:admin and token.domain.id:%(target.user.domain_id)s)" failed scope check. The token used to make the request was project scoped but the policy requires ['system', 'domain'] scope. This behavior may change in the future where using the intended scope is required
  warnings.warn(msg)

2023-03-17 10:46:19.776 39 WARNING py.warnings [None req-b2a06975-b99d-4dc4-8bb0-cea727bba080 1d19bbf56d5f40c9b529281d0c1e72a5 9206716707b74a55b789ac17ddc66873 - - default default] /var/lib/kolla/venv/lib/python3.9/site-packages/oslo_policy/policy.py:1129: UserWarning: Policy "identity:list_roles": "role:reader and system_scope:all" failed scope check. The token used to make the request was project scoped but the policy requires ['system'] scope. This behavior may change in the future where using the intended scope is required
  warnings.warn(msg)

2023-03-17 10:46:20.084 37 WARNING py.warnings [None req-670744b2-9df6-4751-82d1-c8e5ce5ab4b0 1d19bbf56d5f40c9b529281d0c1e72a5 9206716707b74a55b789ac17ddc66873 - - default default] /var/lib/kolla/venv/lib/python3.9/site-packages/oslo_policy/policy.py:1129: UserWarning: Policy "identity:create_grant": "(role:admin and system_scope:all) or ((role:admin and domain_id:%(target.user.domain_id)s and domain_id:%(target.project.domain_id)s) or (role:admin and domain_id:%(target.user.domain_id)s and domain_id:%(target.domain.id)s) or (role:admin and domain_id:%(target.group.domain_id)s and domain_id:%(target.project.domain_id)s) or (role:admin and domain_id:%(target.group.domain_id)s and domain_id:%(target.domain.id)s)) and (domain_id:%(target.role.domain_id)s or None:%(target.role.domain_id)s)" failed scope check. The token used to make the request was project scoped but the policy requires ['system', 'domain'] scope. This behavior may change in the future where using the intended scope is required
  warnings.warn(msg)

2023-03-17 10:46:23.730 38 WARNING py.warnings [None req-09e4790c-8a70-45e3-a907-041e14e2a70e 1d19bbf56d5f40c9b529281d0c1e72a5 9206716707b74a55b789ac17ddc66873 - - default default] /var/lib/kolla/venv/lib/python3.9/site-packages/oslo_policy/policy.py:1129: UserWarning: Policy "identity:create_grant": "(role:admin and system_scope:all) or ((role:admin and domain_id:%(target.user.domain_id)s and domain_id:%(target.project.domain_id)s) or (role:admin and domain_id:%(target.user.domain_id)s and domain_id:%(target.domain.id)s) or (role:admin and domain_id:%(target.group.domain_id)s and domain_id:%(target.project.domain_id)s) or (role:admin and domain_id:%(target.group.domain_id)s and domain_id:%(target.domain.id)s)) and (domain_id:%(target.role.domain_id)s or None:%(target.role.domain_id)s)" failed scope check. The token used to make the request was project scoped but the policy requires ['system', 'domain'] scope. This behavior may change in the future where using the intended scope is required
  warnings.warn(msg)

2023-03-17 10:46:23.962 37 WARNING py.warnings [None req-a74ac4b8-23f9-4c06-85ea-8cfba2b2c1ae 1d19bbf56d5f40c9b529281d0c1e72a5 9206716707b74a55b789ac17ddc66873 - - default default] /var/lib/kolla/venv/lib/python3.9/site-packages/oslo_policy/policy.py:1129: UserWarning: Policy "identity:list_roles": "role:reader and system_scope:all" failed scope check. The token used to make the request was project scoped but the policy requires ['system'] scope. This behavior may change in the future where using the intended scope is required
  warnings.warn(msg)

2023-03-17 10:46:24.211 39 WARNING py.warnings [None req-bb7ea5ad-5033-42a6-8b32-14d825323e21 1d19bbf56d5f40c9b529281d0c1e72a5 9206716707b74a55b789ac17ddc66873 - - default default] /var/lib/kolla/venv/lib/python3.9/site-packages/oslo_policy/policy.py:1129: UserWarning: Policy "identity:create_grant": "(role:admin and system_scope:all) or ((role:admin and domain_id:%(target.user.domain_id)s and domain_id:%(target.project.domain_id)s) or (role:admin and domain_id:%(target.user.domain_id)s and domain_id:%(target.domain.id)s) or (role:admin and domain_id:%(target.group.domain_id)s and domain_id:%(target.project.domain_id)s) or (role:admin and domain_id:%(target.group.domain_id)s and domain_id:%(target.domain.id)s)) and (domain_id:%(target.role.domain_id)s or None:%(target.role.domain_id)s)" failed scope check. The token used to make the request was project scoped but the policy requires ['system', 'domain'] scope. This behavior may change in the future where using the intended scope is required
  warnings.warn(msg)

2023-03-17 10:46:26.562 38 WARNING py.warnings [None req-8672384e-7f31-404b-a125-e17bb43e0547 1d19bbf56d5f40c9b529281d0c1e72a5 9206716707b74a55b789ac17ddc66873 - - default default] /var/lib/kolla/venv/lib/python3.9/site-packages/oslo_policy/policy.py:1129: UserWarning: Policy "identity:create_system_grant_for_user": "role:admin and system_scope:all" failed scope check. The token used to make the request was project scoped but the policy requires ['system'] scope. This behavior may change in the future where using the intended scope is required
  warnings.warn(msg)

