2023-03-02 16:43:05.386 8 WARNING keystonemiddleware.auth_token [-] AuthToken middleware is set with keystone_authtoken.service_token_roles_required set to False. This is backwards compatible but deprecated behaviour. Please set this to True.
2023-03-02 16:43:05.397 8 INFO oslo.service.wsgi [-] ironic_inspector listening on 169.16.1.184:5050
2023-03-02 16:43:05.427 8 INFO eventlet.wsgi.server [-] (8) wsgi starting up on http://169.16.1.184:5050
2023-03-02 16:43:05.496 8 WARNING ironic_inspector.conductor.manager [-] Introspection data will not be stored. Change "[processing] store_data" option if this is not the desired behavior
2023-03-02 16:43:05.563 8 INFO ironic_inspector.conductor.manager [-] Coordination backend cannot be started, assuming no other instances are running. Error: [Errno 111] ECONNREFUSED (with errno ECONNREFUSED [111])
2023-03-02 16:43:05.568 8 INFO ironic_inspector.conductor.manager [-] Enabled processing hooks: ['ramdisk_error', 'root_disk_selection', 'scheduler', 'validate_interfaces', 'capabilities', 'pci_devices']
2023-03-02 16:43:30.602 8 INFO ironic_inspector.pxe_filter.dnsmasq [-] The dnsmasq PXE filter was initialized
2023-03-02 16:43:30.605 8 INFO ironic_inspector.common.rpc_service [-] Created RPC server for service ironic_inspector.conductor on host host-169-16-1-184.
2023-03-02 17:56:57.912 8 ERROR ironic_inspector.pxe_filter.dnsmasq [-] Could not list ironic ports, can not sync dnsmasq PXE filter: keystoneauth1.exceptions.connection.ConnectFailure: Unable to establish connection to http://169.16.1.184:6385/v1/ports: ('Connection aborted.', RemoteDisconnected('Remote end closed connection without response'))
2023-03-02 17:56:57.912 8 ERROR ironic_inspector.pxe_filter.dnsmasq Traceback (most recent call last):
2023-03-02 17:56:57.912 8 ERROR ironic_inspector.pxe_filter.dnsmasq   File "/var/lib/kolla/venv/lib/python3.9/site-packages/urllib3/connectionpool.py", line 703, in urlopen
2023-03-02 17:56:57.912 8 ERROR ironic_inspector.pxe_filter.dnsmasq     httplib_response = self._make_request(
2023-03-02 17:56:57.912 8 ERROR ironic_inspector.pxe_filter.dnsmasq   File "/var/lib/kolla/venv/lib/python3.9/site-packages/urllib3/connectionpool.py", line 449, in _make_request
2023-03-02 17:56:57.912 8 ERROR ironic_inspector.pxe_filter.dnsmasq     six.raise_from(e, None)
2023-03-02 17:56:57.912 8 ERROR ironic_inspector.pxe_filter.dnsmasq   File "<string>", line 3, in raise_from
2023-03-02 17:56:57.912 8 ERROR ironic_inspector.pxe_filter.dnsmasq   File "/var/lib/kolla/venv/lib/python3.9/site-packages/urllib3/connectionpool.py", line 444, in _make_request
2023-03-02 17:56:57.912 8 ERROR ironic_inspector.pxe_filter.dnsmasq     httplib_response = conn.getresponse()
2023-03-02 17:56:57.912 8 ERROR ironic_inspector.pxe_filter.dnsmasq   File "/usr/lib64/python3.9/http/client.py", line 1377, in getresponse
2023-03-02 17:56:57.912 8 ERROR ironic_inspector.pxe_filter.dnsmasq     response.begin()
2023-03-02 17:56:57.912 8 ERROR ironic_inspector.pxe_filter.dnsmasq   File "/usr/lib64/python3.9/http/client.py", line 320, in begin
2023-03-02 17:56:57.912 8 ERROR ironic_inspector.pxe_filter.dnsmasq     version, status, reason = self._read_status()
2023-03-02 17:56:57.912 8 ERROR ironic_inspector.pxe_filter.dnsmasq   File "/usr/lib64/python3.9/http/client.py", line 289, in _read_status
2023-03-02 17:56:57.912 8 ERROR ironic_inspector.pxe_filter.dnsmasq     raise RemoteDisconnected("Remote end closed connection without"
2023-03-02 17:56:57.912 8 ERROR ironic_inspector.pxe_filter.dnsmasq http.client.RemoteDisconnected: Remote end closed connection without response
2023-03-02 17:56:57.912 8 ERROR ironic_inspector.pxe_filter.dnsmasq 
2023-03-02 17:56:57.912 8 ERROR ironic_inspector.pxe_filter.dnsmasq During handling of the above exception, another exception occurred:
2023-03-02 17:56:57.912 8 ERROR ironic_inspector.pxe_filter.dnsmasq 
2023-03-02 17:56:57.912 8 ERROR ironic_inspector.pxe_filter.dnsmasq Traceback (most recent call last):
2023-03-02 17:56:57.912 8 ERROR ironic_inspector.pxe_filter.dnsmasq   File "/var/lib/kolla/venv/lib/python3.9/site-packages/requests/adapters.py", line 489, in send
2023-03-02 17:56:57.912 8 ERROR ironic_inspector.pxe_filter.dnsmasq     resp = conn.urlopen(
2023-03-02 17:56:57.912 8 ERROR ironic_inspector.pxe_filter.dnsmasq   File "/var/lib/kolla/venv/lib/python3.9/site-packages/urllib3/connectionpool.py", line 787, in urlopen
2023-03-02 17:56:57.912 8 ERROR ironic_inspector.pxe_filter.dnsmasq     retries = retries.increment(
2023-03-02 17:56:57.912 8 ERROR ironic_inspector.pxe_filter.dnsmasq   File "/var/lib/kolla/venv/lib/python3.9/site-packages/urllib3/util/retry.py", line 550, in increment
2023-03-02 17:56:57.912 8 ERROR ironic_inspector.pxe_filter.dnsmasq     raise six.reraise(type(error), error, _stacktrace)
2023-03-02 17:56:57.912 8 ERROR ironic_inspector.pxe_filter.dnsmasq   File "/var/lib/kolla/venv/lib/python3.9/site-packages/urllib3/packages/six.py", line 769, in reraise
2023-03-02 17:56:57.912 8 ERROR ironic_inspector.pxe_filter.dnsmasq     raise value.with_traceback(tb)
2023-03-02 17:56:57.912 8 ERROR ironic_inspector.pxe_filter.dnsmasq   File "/var/lib/kolla/venv/lib/python3.9/site-packages/urllib3/connectionpool.py", line 703, in urlopen
2023-03-02 17:56:57.912 8 ERROR ironic_inspector.pxe_filter.dnsmasq     httplib_response = self._make_request(
2023-03-02 17:56:57.912 8 ERROR ironic_inspector.pxe_filter.dnsmasq   File "/var/lib/kolla/venv/lib/python3.9/site-packages/urllib3/connectionpool.py", line 449, in _make_request
2023-03-02 17:56:57.912 8 ERROR ironic_inspector.pxe_filter.dnsmasq     six.raise_from(e, None)
2023-03-02 17:56:57.912 8 ERROR ironic_inspector.pxe_filter.dnsmasq   File "<string>", line 3, in raise_from
2023-03-02 17:56:57.912 8 ERROR ironic_inspector.pxe_filter.dnsmasq   File "/var/lib/kolla/venv/lib/python3.9/site-packages/urllib3/connectionpool.py", line 444, in _make_request
2023-03-02 17:56:57.912 8 ERROR ironic_inspector.pxe_filter.dnsmasq     httplib_response = conn.getresponse()
2023-03-02 17:56:57.912 8 ERROR ironic_inspector.pxe_filter.dnsmasq   File "/usr/lib64/python3.9/http/client.py", line 1377, in getresponse
2023-03-02 17:56:57.912 8 ERROR ironic_inspector.pxe_filter.dnsmasq     response.begin()
2023-03-02 17:56:57.912 8 ERROR ironic_inspector.pxe_filter.dnsmasq   File "/usr/lib64/python3.9/http/client.py", line 320, in begin
2023-03-02 17:56:57.912 8 ERROR ironic_inspector.pxe_filter.dnsmasq     version, status, reason = self._read_status()
2023-03-02 17:56:57.912 8 ERROR ironic_inspector.pxe_filter.dnsmasq   File "/usr/lib64/python3.9/http/client.py", line 289, in _read_status
2023-03-02 17:56:57.912 8 ERROR ironic_inspector.pxe_filter.dnsmasq     raise RemoteDisconnected("Remote end closed connection without"
2023-03-02 17:56:57.912 8 ERROR ironic_inspector.pxe_filter.dnsmasq urllib3.exceptions.ProtocolError: ('Connection aborted.', RemoteDisconnected('Remote end closed connection without response'))
2023-03-02 17:56:57.912 8 ERROR ironic_inspector.pxe_filter.dnsmasq 
2023-03-02 17:56:57.912 8 ERROR ironic_inspector.pxe_filter.dnsmasq During handling of the above exception, another exception occurred:
2023-03-02 17:56:57.912 8 ERROR ironic_inspector.pxe_filter.dnsmasq 
2023-03-02 17:56:57.912 8 ERROR ironic_inspector.pxe_filter.dnsmasq Traceback (most recent call last):
2023-03-02 17:56:57.912 8 ERROR ironic_inspector.pxe_filter.dnsmasq   File "/var/lib/kolla/venv/lib/python3.9/site-packages/keystoneauth1/session.py", line 1022, in _send_request
2023-03-02 17:56:57.912 8 ERROR ironic_inspector.pxe_filter.dnsmasq     resp = self.session.request(method, url, **kwargs)
2023-03-02 17:56:57.912 8 ERROR ironic_inspector.pxe_filter.dnsmasq   File "/var/lib/kolla/venv/lib/python3.9/site-packages/requests/sessions.py", line 587, in request
2023-03-02 17:56:57.912 8 ERROR ironic_inspector.pxe_filter.dnsmasq     resp = self.send(prep, **send_kwargs)
2023-03-02 17:56:57.912 8 ERROR ironic_inspector.pxe_filter.dnsmasq   File "/var/lib/kolla/venv/lib/python3.9/site-packages/requests/sessions.py", line 701, in send
2023-03-02 17:56:57.912 8 ERROR ironic_inspector.pxe_filter.dnsmasq     r = adapter.send(request, **kwargs)
2023-03-02 17:56:57.912 8 ERROR ironic_inspector.pxe_filter.dnsmasq   File "/var/lib/kolla/venv/lib/python3.9/site-packages/requests/adapters.py", line 547, in send
2023-03-02 17:56:57.912 8 ERROR ironic_inspector.pxe_filter.dnsmasq     raise ConnectionError(err, request=request)
2023-03-02 17:56:57.912 8 ERROR ironic_inspector.pxe_filter.dnsmasq requests.exceptions.ConnectionError: ('Connection aborted.', RemoteDisconnected('Remote end closed connection without response'))
2023-03-02 17:56:57.912 8 ERROR ironic_inspector.pxe_filter.dnsmasq 
2023-03-02 17:56:57.912 8 ERROR ironic_inspector.pxe_filter.dnsmasq During handling of the above exception, another exception occurred:
2023-03-02 17:56:57.912 8 ERROR ironic_inspector.pxe_filter.dnsmasq 
2023-03-02 17:56:57.912 8 ERROR ironic_inspector.pxe_filter.dnsmasq Traceback (most recent call last):
2023-03-02 17:56:57.912 8 ERROR ironic_inspector.pxe_filter.dnsmasq   File "/var/lib/kolla/venv/lib/python3.9/site-packages/ironic_inspector/pxe_filter/dnsmasq.py", line 93, in _sync
2023-03-02 17:56:57.912 8 ERROR ironic_inspector.pxe_filter.dnsmasq     ironic_macs = pxe_filter.get_ironic_macs(ironic)
2023-03-02 17:56:57.912 8 ERROR ironic_inspector.pxe_filter.dnsmasq   File "/var/lib/kolla/venv/lib/python3.9/site-packages/ironic_inspector/pxe_filter/base.py", line 292, in get_ironic_macs
2023-03-02 17:56:57.912 8 ERROR ironic_inspector.pxe_filter.dnsmasq     ports = [port for port in
2023-03-02 17:56:57.912 8 ERROR ironic_inspector.pxe_filter.dnsmasq   File "/var/lib/kolla/venv/lib/python3.9/site-packages/ironic_inspector/pxe_filter/base.py", line 292, in <listcomp>
2023-03-02 17:56:57.912 8 ERROR ironic_inspector.pxe_filter.dnsmasq     ports = [port for port in
2023-03-02 17:56:57.912 8 ERROR ironic_inspector.pxe_filter.dnsmasq   File "/var/lib/kolla/venv/lib/python3.9/site-packages/openstack/resource.py", line 2025, in list
2023-03-02 17:56:57.912 8 ERROR ironic_inspector.pxe_filter.dnsmasq     response = session.get(
2023-03-02 17:56:57.912 8 ERROR ironic_inspector.pxe_filter.dnsmasq   File "/var/lib/kolla/venv/lib/python3.9/site-packages/keystoneauth1/adapter.py", line 395, in get
2023-03-02 17:56:57.912 8 ERROR ironic_inspector.pxe_filter.dnsmasq     return self.request(url, 'GET', **kwargs)
2023-03-02 17:56:57.912 8 ERROR ironic_inspector.pxe_filter.dnsmasq   File "/var/lib/kolla/venv/lib/python3.9/site-packages/openstack/proxy.py", line 186, in request
2023-03-02 17:56:57.912 8 ERROR ironic_inspector.pxe_filter.dnsmasq     response = super(Proxy, self).request(
2023-03-02 17:56:57.912 8 ERROR ironic_inspector.pxe_filter.dnsmasq   File "/var/lib/kolla/venv/lib/python3.9/site-packages/keystoneauth1/adapter.py", line 257, in request
2023-03-02 17:56:57.912 8 ERROR ironic_inspector.pxe_filter.dnsmasq     return self.session.request(url, method, **kwargs)
2023-03-02 17:56:57.912 8 ERROR ironic_inspector.pxe_filter.dnsmasq   File "/var/lib/kolla/venv/lib/python3.9/site-packages/keystoneauth1/session.py", line 931, in request
2023-03-02 17:56:57.912 8 ERROR ironic_inspector.pxe_filter.dnsmasq     resp = send(**kwargs)
2023-03-02 17:56:57.912 8 ERROR ironic_inspector.pxe_filter.dnsmasq   File "/var/lib/kolla/venv/lib/python3.9/site-packages/keystoneauth1/session.py", line 1053, in _send_request
2023-03-02 17:56:57.912 8 ERROR ironic_inspector.pxe_filter.dnsmasq     return self._send_request(
2023-03-02 17:56:57.912 8 ERROR ironic_inspector.pxe_filter.dnsmasq   File "/var/lib/kolla/venv/lib/python3.9/site-packages/keystoneauth1/session.py", line 1038, in _send_request
2023-03-02 17:56:57.912 8 ERROR ironic_inspector.pxe_filter.dnsmasq     raise exceptions.ConnectFailure(msg)
2023-03-02 17:56:57.912 8 ERROR ironic_inspector.pxe_filter.dnsmasq keystoneauth1.exceptions.connection.ConnectFailure: Unable to establish connection to http://169.16.1.184:6385/v1/ports: ('Connection aborted.', RemoteDisconnected('Remote end closed connection without response'))
2023-03-02 17:56:57.912 8 ERROR ironic_inspector.pxe_filter.dnsmasq 
