2023-04-14 00:32:48.833 23 INFO alembic.runtime.migration [-] Context impl MySQLImpl.
2023-04-14 00:32:48.835 23 INFO alembic.runtime.migration [-] Will assume non-transactional DDL.
2023-04-14 00:32:48.869 23 INFO alembic.runtime.migration [-] Context impl MySQLImpl.
2023-04-14 00:32:48.870 23 INFO alembic.runtime.migration [-] Will assume non-transactional DDL.
2023-04-14 00:32:48.915 23 INFO alembic.runtime.migration [-] Running upgrade  -> 27e647c0fad4, Initial version.
2023-04-14 00:32:50.010 23 INFO alembic.runtime.migration [-] Running upgrade 27e647c0fad4 -> e25ffa003242, Initial no-op Yoga contract migration.
2023-04-14 00:32:50.024 23 INFO alembic.runtime.migration [-] Running upgrade 27e647c0fad4 -> 29e87d24a316, Initial no-op Yoga expand migration.
2023-04-14 00:32:57.972 7 INFO keystone.common.fernet_utils [-] Created a new temporary key: /etc/keystone/fernet-keys/0.tmp
2023-04-14 00:32:57.977 7 INFO keystone.common.fernet_utils [-] Become a valid new key: /etc/keystone/fernet-keys/0
2023-04-14 00:32:57.978 7 INFO keystone.common.fernet_utils [-] Starting key rotation with 1 key files: ['/etc/keystone/fernet-keys/0']
2023-04-14 00:32:57.979 7 INFO keystone.common.fernet_utils [-] Created a new temporary key: /etc/keystone/fernet-keys/0.tmp
2023-04-14 00:32:57.980 7 INFO keystone.common.fernet_utils [-] Current primary key is: 0
2023-04-14 00:32:57.980 7 INFO keystone.common.fernet_utils [-] Next primary key will be: 1
2023-04-14 00:32:57.981 7 INFO keystone.common.fernet_utils [-] Promoted key 0 to be the primary: 1
2023-04-14 00:32:57.982 7 INFO keystone.common.fernet_utils [-] Become a valid new key: /etc/keystone/fernet-keys/0
2023-04-14 00:33:15.029 32 INFO keystone.cmd.bootstrap [None req-7a3c87f9-bdc3-4500-95df-b60d46959594 - - - - - -] Created domain default
2023-04-14 00:33:15.099 32 INFO keystone.cmd.bootstrap [None req-7a3c87f9-bdc3-4500-95df-b60d46959594 - - - - - -] Created project admin
2023-04-14 00:33:15.708 32 INFO keystone.cmd.bootstrap [None req-7a3c87f9-bdc3-4500-95df-b60d46959594 - - - - - -] Created user admin
2023-04-14 00:33:15.730 32 INFO keystone.cmd.bootstrap [None req-7a3c87f9-bdc3-4500-95df-b60d46959594 - - - - - -] Created role reader
2023-04-14 00:33:15.746 32 INFO keystone.cmd.bootstrap [None req-7a3c87f9-bdc3-4500-95df-b60d46959594 - - - - - -] Created role member
2023-04-14 00:33:15.780 32 INFO keystone.cmd.bootstrap [None req-7a3c87f9-bdc3-4500-95df-b60d46959594 - - - - - -] Created implied role where 9fd7d81a66984d32879b33e479c01495 implies ed947c42e6b54cc19f5043bd1d803228
2023-04-14 00:33:15.802 32 INFO keystone.cmd.bootstrap [None req-7a3c87f9-bdc3-4500-95df-b60d46959594 - - - - - -] Created role admin
2023-04-14 00:33:15.836 32 INFO keystone.cmd.bootstrap [None req-7a3c87f9-bdc3-4500-95df-b60d46959594 - - - - - -] Created implied role where 57a09573317d4362b0cd78968fd17569 implies 9fd7d81a66984d32879b33e479c01495
2023-04-14 00:33:15.855 32 INFO keystone.cmd.bootstrap [None req-7a3c87f9-bdc3-4500-95df-b60d46959594 - - - - - -] Granted role admin on project admin to user admin.
2023-04-14 00:33:15.866 32 INFO keystone.cmd.bootstrap [None req-7a3c87f9-bdc3-4500-95df-b60d46959594 - - - - - -] Granted role admin on the system to user admin.
2023-04-14 00:33:15.892 32 WARNING py.warnings [None req-7a3c87f9-bdc3-4500-95df-b60d46959594 - - - - - -] /var/lib/kolla/venv/lib/python3.9/site-packages/pycadf/identifier.py:71: UserWarning: Invalid uuid: RegionOne. To ensure interoperability, identifiers should be a valid uuid.
  warnings.warn(('Invalid uuid: %s. To ensure interoperability, '

2023-04-14 00:33:15.899 32 INFO keystone.cmd.bootstrap [None req-7a3c87f9-bdc3-4500-95df-b60d46959594 - - - - - -] Created region RegionOne
2023-04-14 00:33:15.952 32 INFO keystone.cmd.bootstrap [None req-7a3c87f9-bdc3-4500-95df-b60d46959594 - - - - - -] Created public endpoint http://169.16.1.150:5000
2023-04-14 00:33:15.968 32 INFO keystone.cmd.bootstrap [None req-7a3c87f9-bdc3-4500-95df-b60d46959594 - - - - - -] Created internal endpoint http://169.16.1.150:5000
2023-04-14 00:33:40.642 37 WARNING keystone.common.rbac_enforcer.enforcer [None req-8edf2112-9018-423f-bd16-892b8b811894 6f184208ce274855a4122f6b366bf412 - - all default -] Deprecated policy rules found. Use oslopolicy-policy-generator and oslopolicy-policy-upgrade to detect and resolve deprecated policies in your configuration.
2023-04-14 00:33:41.455 38 WARNING keystone.common.rbac_enforcer.enforcer [None req-e67349cb-86b8-492b-ae77-d3f5da459689 6f184208ce274855a4122f6b366bf412 - - all default -] Deprecated policy rules found. Use oslopolicy-policy-generator and oslopolicy-policy-upgrade to detect and resolve deprecated policies in your configuration.
2023-04-14 00:33:48.834 39 WARNING keystone.common.rbac_enforcer.enforcer [None req-3b5c7ebd-c033-4540-8359-3a0391d99a44 6f184208ce274855a4122f6b366bf412 - - all default -] Deprecated policy rules found. Use oslopolicy-policy-generator and oslopolicy-policy-upgrade to detect and resolve deprecated policies in your configuration.
2023-04-14 00:35:03.801 37 ERROR keystone.server.flask.application [None req-720906ec-42f7-42e3-b363-2bab77158a22 6f184208ce274855a4122f6b366bf412 - - all default -] Could not find project: service.: keystone.exception.ProjectNotFound: Could not find project: service.
2023-04-14 00:35:03.801 37 ERROR keystone.server.flask.application Traceback (most recent call last):
2023-04-14 00:35:03.801 37 ERROR keystone.server.flask.application   File "/var/lib/kolla/venv/lib/python3.9/site-packages/flask/app.py", line 1820, in full_dispatch_request
2023-04-14 00:35:03.801 37 ERROR keystone.server.flask.application     rv = self.dispatch_request()
2023-04-14 00:35:03.801 37 ERROR keystone.server.flask.application   File "/var/lib/kolla/venv/lib/python3.9/site-packages/flask/app.py", line 1796, in dispatch_request
2023-04-14 00:35:03.801 37 ERROR keystone.server.flask.application     return self.ensure_sync(self.view_functions[rule.endpoint])(**view_args)
2023-04-14 00:35:03.801 37 ERROR keystone.server.flask.application   File "/var/lib/kolla/venv/lib/python3.9/site-packages/flask_restful/__init__.py", line 467, in wrapper
2023-04-14 00:35:03.801 37 ERROR keystone.server.flask.application     resp = resource(*args, **kwargs)
2023-04-14 00:35:03.801 37 ERROR keystone.server.flask.application   File "/var/lib/kolla/venv/lib/python3.9/site-packages/flask/views.py", line 107, in view
2023-04-14 00:35:03.801 37 ERROR keystone.server.flask.application     return current_app.ensure_sync(self.dispatch_request)(**kwargs)
2023-04-14 00:35:03.801 37 ERROR keystone.server.flask.application   File "/var/lib/kolla/venv/lib/python3.9/site-packages/flask_restful/__init__.py", line 582, in dispatch_request
2023-04-14 00:35:03.801 37 ERROR keystone.server.flask.application     resp = meth(*args, **kwargs)
2023-04-14 00:35:03.801 37 ERROR keystone.server.flask.application   File "/var/lib/kolla/venv/lib/python3.9/site-packages/keystone/api/projects.py", line 151, in get
2023-04-14 00:35:03.801 37 ERROR keystone.server.flask.application     return self._get_project(project_id)
2023-04-14 00:35:03.801 37 ERROR keystone.server.flask.application   File "/var/lib/kolla/venv/lib/python3.9/site-packages/keystone/api/projects.py", line 107, in _get_project
2023-04-14 00:35:03.801 37 ERROR keystone.server.flask.application     project = PROVIDERS.resource_api.get_project(project_id)
2023-04-14 00:35:03.801 37 ERROR keystone.server.flask.application   File "/var/lib/kolla/venv/lib/python3.9/site-packages/keystone/common/manager.py", line 115, in wrapped
2023-04-14 00:35:03.801 37 ERROR keystone.server.flask.application     __ret_val = __f(*args, **kwargs)
2023-04-14 00:35:03.801 37 ERROR keystone.server.flask.application   File "/var/lib/kolla/venv/lib/python3.9/site-packages/decorator.py", line 232, in fun
2023-04-14 00:35:03.801 37 ERROR keystone.server.flask.application     return caller(func, *(extras + args), **kw)
2023-04-14 00:35:03.801 37 ERROR keystone.server.flask.application   File "/var/lib/kolla/venv/lib/python3.9/site-packages/dogpile/cache/region.py", line 1577, in get_or_create_for_user_func
2023-04-14 00:35:03.801 37 ERROR keystone.server.flask.application     return self.get_or_create(
2023-04-14 00:35:03.801 37 ERROR keystone.server.flask.application   File "/var/lib/kolla/venv/lib/python3.9/site-packages/dogpile/cache/region.py", line 1042, in get_or_create
2023-04-14 00:35:03.801 37 ERROR keystone.server.flask.application     with Lock(
2023-04-14 00:35:03.801 37 ERROR keystone.server.flask.application   File "/var/lib/kolla/venv/lib/python3.9/site-packages/dogpile/lock.py", line 185, in __enter__
2023-04-14 00:35:03.801 37 ERROR keystone.server.flask.application     return self._enter()
2023-04-14 00:35:03.801 37 ERROR keystone.server.flask.application   File "/var/lib/kolla/venv/lib/python3.9/site-packages/dogpile/lock.py", line 94, in _enter
2023-04-14 00:35:03.801 37 ERROR keystone.server.flask.application     generated = self._enter_create(value, createdtime)
2023-04-14 00:35:03.801 37 ERROR keystone.server.flask.application   File "/var/lib/kolla/venv/lib/python3.9/site-packages/dogpile/lock.py", line 178, in _enter_create
2023-04-14 00:35:03.801 37 ERROR keystone.server.flask.application     return self.creator()
2023-04-14 00:35:03.801 37 ERROR keystone.server.flask.application   File "/var/lib/kolla/venv/lib/python3.9/site-packages/dogpile/cache/region.py", line 995, in gen_value
2023-04-14 00:35:03.801 37 ERROR keystone.server.flask.application     created_value = creator(
2023-04-14 00:35:03.801 37 ERROR keystone.server.flask.application   File "/var/lib/kolla/venv/lib/python3.9/site-packages/keystone/resource/core.py", line 903, in get_project
2023-04-14 00:35:03.801 37 ERROR keystone.server.flask.application     return self.driver.get_project(project_id)
2023-04-14 00:35:03.801 37 ERROR keystone.server.flask.application   File "/var/lib/kolla/venv/lib/python3.9/site-packages/keystone/resource/backends/sql.py", line 49, in get_project
2023-04-14 00:35:03.801 37 ERROR keystone.server.flask.application     return self._get_project(session, project_id).to_dict()
2023-04-14 00:35:03.801 37 ERROR keystone.server.flask.application   File "/var/lib/kolla/venv/lib/python3.9/site-packages/keystone/resource/backends/sql.py", line 44, in _get_project
2023-04-14 00:35:03.801 37 ERROR keystone.server.flask.application     raise exception.ProjectNotFound(project_id=project_id)
2023-04-14 00:35:03.801 37 ERROR keystone.server.flask.application keystone.exception.ProjectNotFound: Could not find project: service.
2023-04-14 00:35:03.801 37 ERROR keystone.server.flask.application 
2023-04-14 00:35:12.558 39 ERROR keystone.server.flask.application [None req-0befef45-cf35-4ca3-861d-20eed3fce22a 6f184208ce274855a4122f6b366bf412 - - all default -] Could not find project: service.: keystone.exception.ProjectNotFound: Could not find project: service.
2023-04-14 00:35:12.558 39 ERROR keystone.server.flask.application Traceback (most recent call last):
2023-04-14 00:35:12.558 39 ERROR keystone.server.flask.application   File "/var/lib/kolla/venv/lib/python3.9/site-packages/flask/app.py", line 1820, in full_dispatch_request
2023-04-14 00:35:12.558 39 ERROR keystone.server.flask.application     rv = self.dispatch_request()
2023-04-14 00:35:12.558 39 ERROR keystone.server.flask.application   File "/var/lib/kolla/venv/lib/python3.9/site-packages/flask/app.py", line 1796, in dispatch_request
2023-04-14 00:35:12.558 39 ERROR keystone.server.flask.application     return self.ensure_sync(self.view_functions[rule.endpoint])(**view_args)
2023-04-14 00:35:12.558 39 ERROR keystone.server.flask.application   File "/var/lib/kolla/venv/lib/python3.9/site-packages/flask_restful/__init__.py", line 467, in wrapper
2023-04-14 00:35:12.558 39 ERROR keystone.server.flask.application     resp = resource(*args, **kwargs)
2023-04-14 00:35:12.558 39 ERROR keystone.server.flask.application   File "/var/lib/kolla/venv/lib/python3.9/site-packages/flask/views.py", line 107, in view
2023-04-14 00:35:12.558 39 ERROR keystone.server.flask.application     return current_app.ensure_sync(self.dispatch_request)(**kwargs)
2023-04-14 00:35:12.558 39 ERROR keystone.server.flask.application   File "/var/lib/kolla/venv/lib/python3.9/site-packages/flask_restful/__init__.py", line 582, in dispatch_request
2023-04-14 00:35:12.558 39 ERROR keystone.server.flask.application     resp = meth(*args, **kwargs)
2023-04-14 00:35:12.558 39 ERROR keystone.server.flask.application   File "/var/lib/kolla/venv/lib/python3.9/site-packages/keystone/api/projects.py", line 151, in get
2023-04-14 00:35:12.558 39 ERROR keystone.server.flask.application     return self._get_project(project_id)
2023-04-14 00:35:12.558 39 ERROR keystone.server.flask.application   File "/var/lib/kolla/venv/lib/python3.9/site-packages/keystone/api/projects.py", line 107, in _get_project
2023-04-14 00:35:12.558 39 ERROR keystone.server.flask.application     project = PROVIDERS.resource_api.get_project(project_id)
2023-04-14 00:35:12.558 39 ERROR keystone.server.flask.application   File "/var/lib/kolla/venv/lib/python3.9/site-packages/keystone/common/manager.py", line 115, in wrapped
2023-04-14 00:35:12.558 39 ERROR keystone.server.flask.application     __ret_val = __f(*args, **kwargs)
2023-04-14 00:35:12.558 39 ERROR keystone.server.flask.application   File "/var/lib/kolla/venv/lib/python3.9/site-packages/decorator.py", line 232, in fun
2023-04-14 00:35:12.558 39 ERROR keystone.server.flask.application     return caller(func, *(extras + args), **kw)
2023-04-14 00:35:12.558 39 ERROR keystone.server.flask.application   File "/var/lib/kolla/venv/lib/python3.9/site-packages/dogpile/cache/region.py", line 1577, in get_or_create_for_user_func
2023-04-14 00:35:12.558 39 ERROR keystone.server.flask.application     return self.get_or_create(
2023-04-14 00:35:12.558 39 ERROR keystone.server.flask.application   File "/var/lib/kolla/venv/lib/python3.9/site-packages/dogpile/cache/region.py", line 1042, in get_or_create
2023-04-14 00:35:12.558 39 ERROR keystone.server.flask.application     with Lock(
2023-04-14 00:35:12.558 39 ERROR keystone.server.flask.application   File "/var/lib/kolla/venv/lib/python3.9/site-packages/dogpile/lock.py", line 185, in __enter__
2023-04-14 00:35:12.558 39 ERROR keystone.server.flask.application     return self._enter()
2023-04-14 00:35:12.558 39 ERROR keystone.server.flask.application   File "/var/lib/kolla/venv/lib/python3.9/site-packages/dogpile/lock.py", line 94, in _enter
2023-04-14 00:35:12.558 39 ERROR keystone.server.flask.application     generated = self._enter_create(value, createdtime)
2023-04-14 00:35:12.558 39 ERROR keystone.server.flask.application   File "/var/lib/kolla/venv/lib/python3.9/site-packages/dogpile/lock.py", line 178, in _enter_create
2023-04-14 00:35:12.558 39 ERROR keystone.server.flask.application     return self.creator()
2023-04-14 00:35:12.558 39 ERROR keystone.server.flask.application   File "/var/lib/kolla/venv/lib/python3.9/site-packages/dogpile/cache/region.py", line 995, in gen_value
2023-04-14 00:35:12.558 39 ERROR keystone.server.flask.application     created_value = creator(
2023-04-14 00:35:12.558 39 ERROR keystone.server.flask.application   File "/var/lib/kolla/venv/lib/python3.9/site-packages/keystone/resource/core.py", line 903, in get_project
2023-04-14 00:35:12.558 39 ERROR keystone.server.flask.application     return self.driver.get_project(project_id)
2023-04-14 00:35:12.558 39 ERROR keystone.server.flask.application   File "/var/lib/kolla/venv/lib/python3.9/site-packages/keystone/resource/backends/sql.py", line 49, in get_project
2023-04-14 00:35:12.558 39 ERROR keystone.server.flask.application     return self._get_project(session, project_id).to_dict()
2023-04-14 00:35:12.558 39 ERROR keystone.server.flask.application   File "/var/lib/kolla/venv/lib/python3.9/site-packages/keystone/resource/backends/sql.py", line 44, in _get_project
2023-04-14 00:35:12.558 39 ERROR keystone.server.flask.application     raise exception.ProjectNotFound(project_id=project_id)
2023-04-14 00:35:12.558 39 ERROR keystone.server.flask.application keystone.exception.ProjectNotFound: Could not find project: service.
2023-04-14 00:35:12.558 39 ERROR keystone.server.flask.application 
2023-04-14 00:35:27.876 39 ERROR keystone.server.flask.application [None req-9896ebfc-2ec4-4cba-883a-2d4d3d1df997 6f184208ce274855a4122f6b366bf412 - - all default -] Could not find role: admin.: keystone.exception.RoleNotFound: Could not find role: admin.
2023-04-14 00:35:27.876 39 ERROR keystone.server.flask.application Traceback (most recent call last):
2023-04-14 00:35:27.876 39 ERROR keystone.server.flask.application   File "/var/lib/kolla/venv/lib/python3.9/site-packages/flask/app.py", line 1820, in full_dispatch_request
2023-04-14 00:35:27.876 39 ERROR keystone.server.flask.application     rv = self.dispatch_request()
2023-04-14 00:35:27.876 39 ERROR keystone.server.flask.application   File "/var/lib/kolla/venv/lib/python3.9/site-packages/flask/app.py", line 1796, in dispatch_request
2023-04-14 00:35:27.876 39 ERROR keystone.server.flask.application     return self.ensure_sync(self.view_functions[rule.endpoint])(**view_args)
2023-04-14 00:35:27.876 39 ERROR keystone.server.flask.application   File "/var/lib/kolla/venv/lib/python3.9/site-packages/flask_restful/__init__.py", line 467, in wrapper
2023-04-14 00:35:27.876 39 ERROR keystone.server.flask.application     resp = resource(*args, **kwargs)
2023-04-14 00:35:27.876 39 ERROR keystone.server.flask.application   File "/var/lib/kolla/venv/lib/python3.9/site-packages/flask/views.py", line 107, in view
2023-04-14 00:35:27.876 39 ERROR keystone.server.flask.application     return current_app.ensure_sync(self.dispatch_request)(**kwargs)
2023-04-14 00:35:27.876 39 ERROR keystone.server.flask.application   File "/var/lib/kolla/venv/lib/python3.9/site-packages/flask_restful/__init__.py", line 582, in dispatch_request
2023-04-14 00:35:27.876 39 ERROR keystone.server.flask.application     resp = meth(*args, **kwargs)
2023-04-14 00:35:27.876 39 ERROR keystone.server.flask.application   File "/var/lib/kolla/venv/lib/python3.9/site-packages/keystone/api/roles.py", line 50, in get
2023-04-14 00:35:27.876 39 ERROR keystone.server.flask.application     return self._get_role(role_id)
2023-04-14 00:35:27.876 39 ERROR keystone.server.flask.application   File "/var/lib/kolla/venv/lib/python3.9/site-packages/keystone/api/roles.py", line 70, in _get_role
2023-04-14 00:35:27.876 39 ERROR keystone.server.flask.application     ENFORCER.enforce_call(action='identity:get_role')
2023-04-14 00:35:27.876 39 ERROR keystone.server.flask.application   File "/var/lib/kolla/venv/lib/python3.9/site-packages/keystone/common/rbac_enforcer/enforcer.py", line 402, in enforce_call
2023-04-14 00:35:27.876 39 ERROR keystone.server.flask.application     policy_dict.update(cls._extract_member_target_data(
2023-04-14 00:35:27.876 39 ERROR keystone.server.flask.application   File "/var/lib/kolla/venv/lib/python3.9/site-packages/keystone/common/rbac_enforcer/enforcer.py", line 234, in _extract_member_target_data
2023-04-14 00:35:27.876 39 ERROR keystone.server.flask.application     member_name: func(flask.request.view_args[key])
2023-04-14 00:35:27.876 39 ERROR keystone.server.flask.application   File "/var/lib/kolla/venv/lib/python3.9/site-packages/keystone/common/manager.py", line 115, in wrapped
2023-04-14 00:35:27.876 39 ERROR keystone.server.flask.application     __ret_val = __f(*args, **kwargs)
2023-04-14 00:35:27.876 39 ERROR keystone.server.flask.application   File "/var/lib/kolla/venv/lib/python3.9/site-packages/decorator.py", line 232, in fun
2023-04-14 00:35:27.876 39 ERROR keystone.server.flask.application     return caller(func, *(extras + args), **kw)
2023-04-14 00:35:27.876 39 ERROR keystone.server.flask.application   File "/var/lib/kolla/venv/lib/python3.9/site-packages/dogpile/cache/region.py", line 1577, in get_or_create_for_user_func
2023-04-14 00:35:27.876 39 ERROR keystone.server.flask.application     return self.get_or_create(
2023-04-14 00:35:27.876 39 ERROR keystone.server.flask.application   File "/var/lib/kolla/venv/lib/python3.9/site-packages/dogpile/cache/region.py", line 1042, in get_or_create
2023-04-14 00:35:27.876 39 ERROR keystone.server.flask.application     with Lock(
2023-04-14 00:35:27.876 39 ERROR keystone.server.flask.application   File "/var/lib/kolla/venv/lib/python3.9/site-packages/dogpile/lock.py", line 185, in __enter__
2023-04-14 00:35:27.876 39 ERROR keystone.server.flask.application     return self._enter()
2023-04-14 00:35:27.876 39 ERROR keystone.server.flask.application   File "/var/lib/kolla/venv/lib/python3.9/site-packages/dogpile/lock.py", line 94, in _enter
2023-04-14 00:35:27.876 39 ERROR keystone.server.flask.application     generated = self._enter_create(value, createdtime)
2023-04-14 00:35:27.876 39 ERROR keystone.server.flask.application   File "/var/lib/kolla/venv/lib/python3.9/site-packages/dogpile/lock.py", line 178, in _enter_create
2023-04-14 00:35:27.876 39 ERROR keystone.server.flask.application     return self.creator()
2023-04-14 00:35:27.876 39 ERROR keystone.server.flask.application   File "/var/lib/kolla/venv/lib/python3.9/site-packages/dogpile/cache/region.py", line 995, in gen_value
2023-04-14 00:35:27.876 39 ERROR keystone.server.flask.application     created_value = creator(
2023-04-14 00:35:27.876 39 ERROR keystone.server.flask.application   File "/var/lib/kolla/venv/lib/python3.9/site-packages/keystone/assignment/core.py", line 1276, in get_role
2023-04-14 00:35:27.876 39 ERROR keystone.server.flask.application     return self.driver.get_role(role_id)
2023-04-14 00:35:27.876 39 ERROR keystone.server.flask.application   File "/var/lib/kolla/venv/lib/python3.9/site-packages/keystone/assignment/role_backends/sql.py", line 70, in get_role
2023-04-14 00:35:27.876 39 ERROR keystone.server.flask.application     return self._get_role(session, role_id).to_dict()
2023-04-14 00:35:27.876 39 ERROR keystone.server.flask.application   File "/var/lib/kolla/venv/lib/python3.9/site-packages/keystone/assignment/role_backends/sql.py", line 65, in _get_role
2023-04-14 00:35:27.876 39 ERROR keystone.server.flask.application     raise exception.RoleNotFound(role_id=role_id)
2023-04-14 00:35:27.876 39 ERROR keystone.server.flask.application keystone.exception.RoleNotFound: Could not find role: admin.
2023-04-14 00:35:27.876 39 ERROR keystone.server.flask.application 
2023-04-14 00:35:29.170 39 ERROR keystone.server.flask.application [None req-fd1f03d0-c563-49a3-aeed-875275b95faf 6f184208ce274855a4122f6b366bf412 - - all default -] Could not find user: ironic.: keystone.exception.UserNotFound: Could not find user: ironic.
2023-04-14 00:35:29.170 39 ERROR keystone.server.flask.application Traceback (most recent call last):
2023-04-14 00:35:29.170 39 ERROR keystone.server.flask.application   File "/var/lib/kolla/venv/lib/python3.9/site-packages/flask/app.py", line 1820, in full_dispatch_request
2023-04-14 00:35:29.170 39 ERROR keystone.server.flask.application     rv = self.dispatch_request()
2023-04-14 00:35:29.170 39 ERROR keystone.server.flask.application   File "/var/lib/kolla/venv/lib/python3.9/site-packages/flask/app.py", line 1796, in dispatch_request
2023-04-14 00:35:29.170 39 ERROR keystone.server.flask.application     return self.ensure_sync(self.view_functions[rule.endpoint])(**view_args)
2023-04-14 00:35:29.170 39 ERROR keystone.server.flask.application   File "/var/lib/kolla/venv/lib/python3.9/site-packages/flask_restful/__init__.py", line 467, in wrapper
2023-04-14 00:35:29.170 39 ERROR keystone.server.flask.application     resp = resource(*args, **kwargs)
2023-04-14 00:35:29.170 39 ERROR keystone.server.flask.application   File "/var/lib/kolla/venv/lib/python3.9/site-packages/flask/views.py", line 107, in view
2023-04-14 00:35:29.170 39 ERROR keystone.server.flask.application     return current_app.ensure_sync(self.dispatch_request)(**kwargs)
2023-04-14 00:35:29.170 39 ERROR keystone.server.flask.application   File "/var/lib/kolla/venv/lib/python3.9/site-packages/flask_restful/__init__.py", line 582, in dispatch_request
2023-04-14 00:35:29.170 39 ERROR keystone.server.flask.application     resp = meth(*args, **kwargs)
2023-04-14 00:35:29.170 39 ERROR keystone.server.flask.application   File "/var/lib/kolla/venv/lib/python3.9/site-packages/keystone/api/users.py", line 182, in get
2023-04-14 00:35:29.170 39 ERROR keystone.server.flask.application     return self._get_user(user_id)
2023-04-14 00:35:29.170 39 ERROR keystone.server.flask.application   File "/var/lib/kolla/venv/lib/python3.9/site-packages/keystone/api/users.py", line 194, in _get_user
2023-04-14 00:35:29.170 39 ERROR keystone.server.flask.application     ref = PROVIDERS.identity_api.get_user(user_id)
2023-04-14 00:35:29.170 39 ERROR keystone.server.flask.application   File "/var/lib/kolla/venv/lib/python3.9/site-packages/keystone/common/manager.py", line 115, in wrapped
2023-04-14 00:35:29.170 39 ERROR keystone.server.flask.application     __ret_val = __f(*args, **kwargs)
2023-04-14 00:35:29.170 39 ERROR keystone.server.flask.application   File "/var/lib/kolla/venv/lib/python3.9/site-packages/keystone/identity/core.py", line 414, in wrapper
2023-04-14 00:35:29.170 39 ERROR keystone.server.flask.application     return f(self, *args, **kwargs)
2023-04-14 00:35:29.170 39 ERROR keystone.server.flask.application   File "/var/lib/kolla/venv/lib/python3.9/site-packages/keystone/identity/core.py", line 424, in wrapper
2023-04-14 00:35:29.170 39 ERROR keystone.server.flask.application     return f(self, *args, **kwargs)
2023-04-14 00:35:29.170 39 ERROR keystone.server.flask.application   File "/var/lib/kolla/venv/lib/python3.9/site-packages/decorator.py", line 232, in fun
2023-04-14 00:35:29.170 39 ERROR keystone.server.flask.application     return caller(func, *(extras + args), **kw)
2023-04-14 00:35:29.170 39 ERROR keystone.server.flask.application   File "/var/lib/kolla/venv/lib/python3.9/site-packages/dogpile/cache/region.py", line 1577, in get_or_create_for_user_func
2023-04-14 00:35:29.170 39 ERROR keystone.server.flask.application     return self.get_or_create(
2023-04-14 00:35:29.170 39 ERROR keystone.server.flask.application   File "/var/lib/kolla/venv/lib/python3.9/site-packages/dogpile/cache/region.py", line 1042, in get_or_create
2023-04-14 00:35:29.170 39 ERROR keystone.server.flask.application     with Lock(
2023-04-14 00:35:29.170 39 ERROR keystone.server.flask.application   File "/var/lib/kolla/venv/lib/python3.9/site-packages/dogpile/lock.py", line 185, in __enter__
2023-04-14 00:35:29.170 39 ERROR keystone.server.flask.application     return self._enter()
2023-04-14 00:35:29.170 39 ERROR keystone.server.flask.application   File "/var/lib/kolla/venv/lib/python3.9/site-packages/dogpile/lock.py", line 94, in _enter
2023-04-14 00:35:29.170 39 ERROR keystone.server.flask.application     generated = self._enter_create(value, createdtime)
2023-04-14 00:35:29.170 39 ERROR keystone.server.flask.application   File "/var/lib/kolla/venv/lib/python3.9/site-packages/dogpile/lock.py", line 178, in _enter_create
2023-04-14 00:35:29.170 39 ERROR keystone.server.flask.application     return self.creator()
2023-04-14 00:35:29.170 39 ERROR keystone.server.flask.application   File "/var/lib/kolla/venv/lib/python3.9/site-packages/dogpile/cache/region.py", line 995, in gen_value
2023-04-14 00:35:29.170 39 ERROR keystone.server.flask.application     created_value = creator(
2023-04-14 00:35:29.170 39 ERROR keystone.server.flask.application   File "/var/lib/kolla/venv/lib/python3.9/site-packages/keystone/identity/core.py", line 1011, in get_user
2023-04-14 00:35:29.170 39 ERROR keystone.server.flask.application     ref = driver.get_user(entity_id)
2023-04-14 00:35:29.170 39 ERROR keystone.server.flask.application   File "/var/lib/kolla/venv/lib/python3.9/site-packages/keystone/identity/backends/sql.py", line 200, in get_user
2023-04-14 00:35:29.170 39 ERROR keystone.server.flask.application     self._get_user(session, user_id).to_dict())
2023-04-14 00:35:29.170 39 ERROR keystone.server.flask.application   File "/var/lib/kolla/venv/lib/python3.9/site-packages/keystone/identity/backends/sql.py", line 194, in _get_user
2023-04-14 00:35:29.170 39 ERROR keystone.server.flask.application     raise exception.UserNotFound(user_id=user_id)
2023-04-14 00:35:29.170 39 ERROR keystone.server.flask.application keystone.exception.UserNotFound: Could not find user: ironic.
2023-04-14 00:35:29.170 39 ERROR keystone.server.flask.application 
2023-04-14 00:35:30.128 38 ERROR keystone.server.flask.application [None req-2f82dae8-d7a1-41b6-8597-5050439b6085 6f184208ce274855a4122f6b366bf412 - - all default -] Could not find project: service.: keystone.exception.ProjectNotFound: Could not find project: service.
2023-04-14 00:35:30.128 38 ERROR keystone.server.flask.application Traceback (most recent call last):
2023-04-14 00:35:30.128 38 ERROR keystone.server.flask.application   File "/var/lib/kolla/venv/lib/python3.9/site-packages/flask/app.py", line 1820, in full_dispatch_request
2023-04-14 00:35:30.128 38 ERROR keystone.server.flask.application     rv = self.dispatch_request()
2023-04-14 00:35:30.128 38 ERROR keystone.server.flask.application   File "/var/lib/kolla/venv/lib/python3.9/site-packages/flask/app.py", line 1796, in dispatch_request
2023-04-14 00:35:30.128 38 ERROR keystone.server.flask.application     return self.ensure_sync(self.view_functions[rule.endpoint])(**view_args)
2023-04-14 00:35:30.128 38 ERROR keystone.server.flask.application   File "/var/lib/kolla/venv/lib/python3.9/site-packages/flask_restful/__init__.py", line 467, in wrapper
2023-04-14 00:35:30.128 38 ERROR keystone.server.flask.application     resp = resource(*args, **kwargs)
2023-04-14 00:35:30.128 38 ERROR keystone.server.flask.application   File "/var/lib/kolla/venv/lib/python3.9/site-packages/flask/views.py", line 107, in view
2023-04-14 00:35:30.128 38 ERROR keystone.server.flask.application     return current_app.ensure_sync(self.dispatch_request)(**kwargs)
2023-04-14 00:35:30.128 38 ERROR keystone.server.flask.application   File "/var/lib/kolla/venv/lib/python3.9/site-packages/flask_restful/__init__.py", line 582, in dispatch_request
2023-04-14 00:35:30.128 38 ERROR keystone.server.flask.application     resp = meth(*args, **kwargs)
2023-04-14 00:35:30.128 38 ERROR keystone.server.flask.application   File "/var/lib/kolla/venv/lib/python3.9/site-packages/keystone/api/projects.py", line 151, in get
2023-04-14 00:35:30.128 38 ERROR keystone.server.flask.application     return self._get_project(project_id)
2023-04-14 00:35:30.128 38 ERROR keystone.server.flask.application   File "/var/lib/kolla/venv/lib/python3.9/site-packages/keystone/api/projects.py", line 107, in _get_project
2023-04-14 00:35:30.128 38 ERROR keystone.server.flask.application     project = PROVIDERS.resource_api.get_project(project_id)
2023-04-14 00:35:30.128 38 ERROR keystone.server.flask.application   File "/var/lib/kolla/venv/lib/python3.9/site-packages/keystone/common/manager.py", line 115, in wrapped
2023-04-14 00:35:30.128 38 ERROR keystone.server.flask.application     __ret_val = __f(*args, **kwargs)
2023-04-14 00:35:30.128 38 ERROR keystone.server.flask.application   File "/var/lib/kolla/venv/lib/python3.9/site-packages/decorator.py", line 232, in fun
2023-04-14 00:35:30.128 38 ERROR keystone.server.flask.application     return caller(func, *(extras + args), **kw)
2023-04-14 00:35:30.128 38 ERROR keystone.server.flask.application   File "/var/lib/kolla/venv/lib/python3.9/site-packages/dogpile/cache/region.py", line 1577, in get_or_create_for_user_func
2023-04-14 00:35:30.128 38 ERROR keystone.server.flask.application     return self.get_or_create(
2023-04-14 00:35:30.128 38 ERROR keystone.server.flask.application   File "/var/lib/kolla/venv/lib/python3.9/site-packages/dogpile/cache/region.py", line 1042, in get_or_create
2023-04-14 00:35:30.128 38 ERROR keystone.server.flask.application     with Lock(
2023-04-14 00:35:30.128 38 ERROR keystone.server.flask.application   File "/var/lib/kolla/venv/lib/python3.9/site-packages/dogpile/lock.py", line 185, in __enter__
2023-04-14 00:35:30.128 38 ERROR keystone.server.flask.application     return self._enter()
2023-04-14 00:35:30.128 38 ERROR keystone.server.flask.application   File "/var/lib/kolla/venv/lib/python3.9/site-packages/dogpile/lock.py", line 94, in _enter
2023-04-14 00:35:30.128 38 ERROR keystone.server.flask.application     generated = self._enter_create(value, createdtime)
2023-04-14 00:35:30.128 38 ERROR keystone.server.flask.application   File "/var/lib/kolla/venv/lib/python3.9/site-packages/dogpile/lock.py", line 178, in _enter_create
2023-04-14 00:35:30.128 38 ERROR keystone.server.flask.application     return self.creator()
2023-04-14 00:35:30.128 38 ERROR keystone.server.flask.application   File "/var/lib/kolla/venv/lib/python3.9/site-packages/dogpile/cache/region.py", line 995, in gen_value
2023-04-14 00:35:30.128 38 ERROR keystone.server.flask.application     created_value = creator(
2023-04-14 00:35:30.128 38 ERROR keystone.server.flask.application   File "/var/lib/kolla/venv/lib/python3.9/site-packages/keystone/resource/core.py", line 903, in get_project
2023-04-14 00:35:30.128 38 ERROR keystone.server.flask.application     return self.driver.get_project(project_id)
2023-04-14 00:35:30.128 38 ERROR keystone.server.flask.application   File "/var/lib/kolla/venv/lib/python3.9/site-packages/keystone/resource/backends/sql.py", line 49, in get_project
2023-04-14 00:35:30.128 38 ERROR keystone.server.flask.application     return self._get_project(session, project_id).to_dict()
2023-04-14 00:35:30.128 38 ERROR keystone.server.flask.application   File "/var/lib/kolla/venv/lib/python3.9/site-packages/keystone/resource/backends/sql.py", line 44, in _get_project
2023-04-14 00:35:30.128 38 ERROR keystone.server.flask.application     raise exception.ProjectNotFound(project_id=project_id)
2023-04-14 00:35:30.128 38 ERROR keystone.server.flask.application keystone.exception.ProjectNotFound: Could not find project: service.
2023-04-14 00:35:30.128 38 ERROR keystone.server.flask.application 
2023-04-14 00:35:40.378 37 ERROR keystone.server.flask.application [None req-b98b544d-bd0c-4f4a-85f1-b1b14e21f9d4 6f184208ce274855a4122f6b366bf412 - - all default -] Could not find role: admin.: keystone.exception.RoleNotFound: Could not find role: admin.
2023-04-14 00:35:40.378 37 ERROR keystone.server.flask.application Traceback (most recent call last):
2023-04-14 00:35:40.378 37 ERROR keystone.server.flask.application   File "/var/lib/kolla/venv/lib/python3.9/site-packages/flask/app.py", line 1820, in full_dispatch_request
2023-04-14 00:35:40.378 37 ERROR keystone.server.flask.application     rv = self.dispatch_request()
2023-04-14 00:35:40.378 37 ERROR keystone.server.flask.application   File "/var/lib/kolla/venv/lib/python3.9/site-packages/flask/app.py", line 1796, in dispatch_request
2023-04-14 00:35:40.378 37 ERROR keystone.server.flask.application     return self.ensure_sync(self.view_functions[rule.endpoint])(**view_args)
2023-04-14 00:35:40.378 37 ERROR keystone.server.flask.application   File "/var/lib/kolla/venv/lib/python3.9/site-packages/flask_restful/__init__.py", line 467, in wrapper
2023-04-14 00:35:40.378 37 ERROR keystone.server.flask.application     resp = resource(*args, **kwargs)
2023-04-14 00:35:40.378 37 ERROR keystone.server.flask.application   File "/var/lib/kolla/venv/lib/python3.9/site-packages/flask/views.py", line 107, in view
2023-04-14 00:35:40.378 37 ERROR keystone.server.flask.application     return current_app.ensure_sync(self.dispatch_request)(**kwargs)
2023-04-14 00:35:40.378 37 ERROR keystone.server.flask.application   File "/var/lib/kolla/venv/lib/python3.9/site-packages/flask_restful/__init__.py", line 582, in dispatch_request
2023-04-14 00:35:40.378 37 ERROR keystone.server.flask.application     resp = meth(*args, **kwargs)
2023-04-14 00:35:40.378 37 ERROR keystone.server.flask.application   File "/var/lib/kolla/venv/lib/python3.9/site-packages/keystone/api/roles.py", line 50, in get
2023-04-14 00:35:40.378 37 ERROR keystone.server.flask.application     return self._get_role(role_id)
2023-04-14 00:35:40.378 37 ERROR keystone.server.flask.application   File "/var/lib/kolla/venv/lib/python3.9/site-packages/keystone/api/roles.py", line 70, in _get_role
2023-04-14 00:35:40.378 37 ERROR keystone.server.flask.application     ENFORCER.enforce_call(action='identity:get_role')
2023-04-14 00:35:40.378 37 ERROR keystone.server.flask.application   File "/var/lib/kolla/venv/lib/python3.9/site-packages/keystone/common/rbac_enforcer/enforcer.py", line 402, in enforce_call
2023-04-14 00:35:40.378 37 ERROR keystone.server.flask.application     policy_dict.update(cls._extract_member_target_data(
2023-04-14 00:35:40.378 37 ERROR keystone.server.flask.application   File "/var/lib/kolla/venv/lib/python3.9/site-packages/keystone/common/rbac_enforcer/enforcer.py", line 234, in _extract_member_target_data
2023-04-14 00:35:40.378 37 ERROR keystone.server.flask.application     member_name: func(flask.request.view_args[key])
2023-04-14 00:35:40.378 37 ERROR keystone.server.flask.application   File "/var/lib/kolla/venv/lib/python3.9/site-packages/keystone/common/manager.py", line 115, in wrapped
2023-04-14 00:35:40.378 37 ERROR keystone.server.flask.application     __ret_val = __f(*args, **kwargs)
2023-04-14 00:35:40.378 37 ERROR keystone.server.flask.application   File "/var/lib/kolla/venv/lib/python3.9/site-packages/decorator.py", line 232, in fun
2023-04-14 00:35:40.378 37 ERROR keystone.server.flask.application     return caller(func, *(extras + args), **kw)
2023-04-14 00:35:40.378 37 ERROR keystone.server.flask.application   File "/var/lib/kolla/venv/lib/python3.9/site-packages/dogpile/cache/region.py", line 1577, in get_or_create_for_user_func
2023-04-14 00:35:40.378 37 ERROR keystone.server.flask.application     return self.get_or_create(
2023-04-14 00:35:40.378 37 ERROR keystone.server.flask.application   File "/var/lib/kolla/venv/lib/python3.9/site-packages/dogpile/cache/region.py", line 1042, in get_or_create
2023-04-14 00:35:40.378 37 ERROR keystone.server.flask.application     with Lock(
2023-04-14 00:35:40.378 37 ERROR keystone.server.flask.application   File "/var/lib/kolla/venv/lib/python3.9/site-packages/dogpile/lock.py", line 185, in __enter__
2023-04-14 00:35:40.378 37 ERROR keystone.server.flask.application     return self._enter()
2023-04-14 00:35:40.378 37 ERROR keystone.server.flask.application   File "/var/lib/kolla/venv/lib/python3.9/site-packages/dogpile/lock.py", line 94, in _enter
2023-04-14 00:35:40.378 37 ERROR keystone.server.flask.application     generated = self._enter_create(value, createdtime)
2023-04-14 00:35:40.378 37 ERROR keystone.server.flask.application   File "/var/lib/kolla/venv/lib/python3.9/site-packages/dogpile/lock.py", line 178, in _enter_create
2023-04-14 00:35:40.378 37 ERROR keystone.server.flask.application     return self.creator()
2023-04-14 00:35:40.378 37 ERROR keystone.server.flask.application   File "/var/lib/kolla/venv/lib/python3.9/site-packages/dogpile/cache/region.py", line 995, in gen_value
2023-04-14 00:35:40.378 37 ERROR keystone.server.flask.application     created_value = creator(
2023-04-14 00:35:40.378 37 ERROR keystone.server.flask.application   File "/var/lib/kolla/venv/lib/python3.9/site-packages/keystone/assignment/core.py", line 1276, in get_role
2023-04-14 00:35:40.378 37 ERROR keystone.server.flask.application     return self.driver.get_role(role_id)
2023-04-14 00:35:40.378 37 ERROR keystone.server.flask.application   File "/var/lib/kolla/venv/lib/python3.9/site-packages/keystone/assignment/role_backends/sql.py", line 70, in get_role
2023-04-14 00:35:40.378 37 ERROR keystone.server.flask.application     return self._get_role(session, role_id).to_dict()
2023-04-14 00:35:40.378 37 ERROR keystone.server.flask.application   File "/var/lib/kolla/venv/lib/python3.9/site-packages/keystone/assignment/role_backends/sql.py", line 65, in _get_role
2023-04-14 00:35:40.378 37 ERROR keystone.server.flask.application     raise exception.RoleNotFound(role_id=role_id)
2023-04-14 00:35:40.378 37 ERROR keystone.server.flask.application keystone.exception.RoleNotFound: Could not find role: admin.
2023-04-14 00:35:40.378 37 ERROR keystone.server.flask.application 
2023-04-14 00:35:41.589 37 ERROR keystone.server.flask.application [None req-a897cc84-c12c-4b8b-b681-30e7e54e7415 6f184208ce274855a4122f6b366bf412 - - all default -] Could not find user: ironic-inspector.: keystone.exception.UserNotFound: Could not find user: ironic-inspector.
2023-04-14 00:35:41.589 37 ERROR keystone.server.flask.application Traceback (most recent call last):
2023-04-14 00:35:41.589 37 ERROR keystone.server.flask.application   File "/var/lib/kolla/venv/lib/python3.9/site-packages/flask/app.py", line 1820, in full_dispatch_request
2023-04-14 00:35:41.589 37 ERROR keystone.server.flask.application     rv = self.dispatch_request()
2023-04-14 00:35:41.589 37 ERROR keystone.server.flask.application   File "/var/lib/kolla/venv/lib/python3.9/site-packages/flask/app.py", line 1796, in dispatch_request
2023-04-14 00:35:41.589 37 ERROR keystone.server.flask.application     return self.ensure_sync(self.view_functions[rule.endpoint])(**view_args)
2023-04-14 00:35:41.589 37 ERROR keystone.server.flask.application   File "/var/lib/kolla/venv/lib/python3.9/site-packages/flask_restful/__init__.py", line 467, in wrapper
2023-04-14 00:35:41.589 37 ERROR keystone.server.flask.application     resp = resource(*args, **kwargs)
2023-04-14 00:35:41.589 37 ERROR keystone.server.flask.application   File "/var/lib/kolla/venv/lib/python3.9/site-packages/flask/views.py", line 107, in view
2023-04-14 00:35:41.589 37 ERROR keystone.server.flask.application     return current_app.ensure_sync(self.dispatch_request)(**kwargs)
2023-04-14 00:35:41.589 37 ERROR keystone.server.flask.application   File "/var/lib/kolla/venv/lib/python3.9/site-packages/flask_restful/__init__.py", line 582, in dispatch_request
2023-04-14 00:35:41.589 37 ERROR keystone.server.flask.application     resp = meth(*args, **kwargs)
2023-04-14 00:35:41.589 37 ERROR keystone.server.flask.application   File "/var/lib/kolla/venv/lib/python3.9/site-packages/keystone/api/users.py", line 182, in get
2023-04-14 00:35:41.589 37 ERROR keystone.server.flask.application     return self._get_user(user_id)
2023-04-14 00:35:41.589 37 ERROR keystone.server.flask.application   File "/var/lib/kolla/venv/lib/python3.9/site-packages/keystone/api/users.py", line 194, in _get_user
2023-04-14 00:35:41.589 37 ERROR keystone.server.flask.application     ref = PROVIDERS.identity_api.get_user(user_id)
2023-04-14 00:35:41.589 37 ERROR keystone.server.flask.application   File "/var/lib/kolla/venv/lib/python3.9/site-packages/keystone/common/manager.py", line 115, in wrapped
2023-04-14 00:35:41.589 37 ERROR keystone.server.flask.application     __ret_val = __f(*args, **kwargs)
2023-04-14 00:35:41.589 37 ERROR keystone.server.flask.application   File "/var/lib/kolla/venv/lib/python3.9/site-packages/keystone/identity/core.py", line 414, in wrapper
2023-04-14 00:35:41.589 37 ERROR keystone.server.flask.application     return f(self, *args, **kwargs)
2023-04-14 00:35:41.589 37 ERROR keystone.server.flask.application   File "/var/lib/kolla/venv/lib/python3.9/site-packages/keystone/identity/core.py", line 424, in wrapper
2023-04-14 00:35:41.589 37 ERROR keystone.server.flask.application     return f(self, *args, **kwargs)
2023-04-14 00:35:41.589 37 ERROR keystone.server.flask.application   File "/var/lib/kolla/venv/lib/python3.9/site-packages/decorator.py", line 232, in fun
2023-04-14 00:35:41.589 37 ERROR keystone.server.flask.application     return caller(func, *(extras + args), **kw)
2023-04-14 00:35:41.589 37 ERROR keystone.server.flask.application   File "/var/lib/kolla/venv/lib/python3.9/site-packages/dogpile/cache/region.py", line 1577, in get_or_create_for_user_func
2023-04-14 00:35:41.589 37 ERROR keystone.server.flask.application     return self.get_or_create(
2023-04-14 00:35:41.589 37 ERROR keystone.server.flask.application   File "/var/lib/kolla/venv/lib/python3.9/site-packages/dogpile/cache/region.py", line 1042, in get_or_create
2023-04-14 00:35:41.589 37 ERROR keystone.server.flask.application     with Lock(
2023-04-14 00:35:41.589 37 ERROR keystone.server.flask.application   File "/var/lib/kolla/venv/lib/python3.9/site-packages/dogpile/lock.py", line 185, in __enter__
2023-04-14 00:35:41.589 37 ERROR keystone.server.flask.application     return self._enter()
2023-04-14 00:35:41.589 37 ERROR keystone.server.flask.application   File "/var/lib/kolla/venv/lib/python3.9/site-packages/dogpile/lock.py", line 94, in _enter
2023-04-14 00:35:41.589 37 ERROR keystone.server.flask.application     generated = self._enter_create(value, createdtime)
2023-04-14 00:35:41.589 37 ERROR keystone.server.flask.application   File "/var/lib/kolla/venv/lib/python3.9/site-packages/dogpile/lock.py", line 178, in _enter_create
2023-04-14 00:35:41.589 37 ERROR keystone.server.flask.application     return self.creator()
2023-04-14 00:35:41.589 37 ERROR keystone.server.flask.application   File "/var/lib/kolla/venv/lib/python3.9/site-packages/dogpile/cache/region.py", line 995, in gen_value
2023-04-14 00:35:41.589 37 ERROR keystone.server.flask.application     created_value = creator(
2023-04-14 00:35:41.589 37 ERROR keystone.server.flask.application   File "/var/lib/kolla/venv/lib/python3.9/site-packages/keystone/identity/core.py", line 1011, in get_user
2023-04-14 00:35:41.589 37 ERROR keystone.server.flask.application     ref = driver.get_user(entity_id)
2023-04-14 00:35:41.589 37 ERROR keystone.server.flask.application   File "/var/lib/kolla/venv/lib/python3.9/site-packages/keystone/identity/backends/sql.py", line 200, in get_user
2023-04-14 00:35:41.589 37 ERROR keystone.server.flask.application     self._get_user(session, user_id).to_dict())
2023-04-14 00:35:41.589 37 ERROR keystone.server.flask.application   File "/var/lib/kolla/venv/lib/python3.9/site-packages/keystone/identity/backends/sql.py", line 194, in _get_user
2023-04-14 00:35:41.589 37 ERROR keystone.server.flask.application     raise exception.UserNotFound(user_id=user_id)
2023-04-14 00:35:41.589 37 ERROR keystone.server.flask.application keystone.exception.UserNotFound: Could not find user: ironic-inspector.
2023-04-14 00:35:41.589 37 ERROR keystone.server.flask.application 
2023-04-14 00:35:42.399 39 ERROR keystone.server.flask.application [None req-d19d0ffd-ad89-4567-b49c-678bb76bca7c 6f184208ce274855a4122f6b366bf412 - - all default -] Could not find project: service.: keystone.exception.ProjectNotFound: Could not find project: service.
2023-04-14 00:35:42.399 39 ERROR keystone.server.flask.application Traceback (most recent call last):
2023-04-14 00:35:42.399 39 ERROR keystone.server.flask.application   File "/var/lib/kolla/venv/lib/python3.9/site-packages/flask/app.py", line 1820, in full_dispatch_request
2023-04-14 00:35:42.399 39 ERROR keystone.server.flask.application     rv = self.dispatch_request()
2023-04-14 00:35:42.399 39 ERROR keystone.server.flask.application   File "/var/lib/kolla/venv/lib/python3.9/site-packages/flask/app.py", line 1796, in dispatch_request
2023-04-14 00:35:42.399 39 ERROR keystone.server.flask.application     return self.ensure_sync(self.view_functions[rule.endpoint])(**view_args)
2023-04-14 00:35:42.399 39 ERROR keystone.server.flask.application   File "/var/lib/kolla/venv/lib/python3.9/site-packages/flask_restful/__init__.py", line 467, in wrapper
2023-04-14 00:35:42.399 39 ERROR keystone.server.flask.application     resp = resource(*args, **kwargs)
2023-04-14 00:35:42.399 39 ERROR keystone.server.flask.application   File "/var/lib/kolla/venv/lib/python3.9/site-packages/flask/views.py", line 107, in view
2023-04-14 00:35:42.399 39 ERROR keystone.server.flask.application     return current_app.ensure_sync(self.dispatch_request)(**kwargs)
2023-04-14 00:35:42.399 39 ERROR keystone.server.flask.application   File "/var/lib/kolla/venv/lib/python3.9/site-packages/flask_restful/__init__.py", line 582, in dispatch_request
2023-04-14 00:35:42.399 39 ERROR keystone.server.flask.application     resp = meth(*args, **kwargs)
2023-04-14 00:35:42.399 39 ERROR keystone.server.flask.application   File "/var/lib/kolla/venv/lib/python3.9/site-packages/keystone/api/projects.py", line 151, in get
2023-04-14 00:35:42.399 39 ERROR keystone.server.flask.application     return self._get_project(project_id)
2023-04-14 00:35:42.399 39 ERROR keystone.server.flask.application   File "/var/lib/kolla/venv/lib/python3.9/site-packages/keystone/api/projects.py", line 107, in _get_project
2023-04-14 00:35:42.399 39 ERROR keystone.server.flask.application     project = PROVIDERS.resource_api.get_project(project_id)
2023-04-14 00:35:42.399 39 ERROR keystone.server.flask.application   File "/var/lib/kolla/venv/lib/python3.9/site-packages/keystone/common/manager.py", line 115, in wrapped
2023-04-14 00:35:42.399 39 ERROR keystone.server.flask.application     __ret_val = __f(*args, **kwargs)
2023-04-14 00:35:42.399 39 ERROR keystone.server.flask.application   File "/var/lib/kolla/venv/lib/python3.9/site-packages/decorator.py", line 232, in fun
2023-04-14 00:35:42.399 39 ERROR keystone.server.flask.application     return caller(func, *(extras + args), **kw)
2023-04-14 00:35:42.399 39 ERROR keystone.server.flask.application   File "/var/lib/kolla/venv/lib/python3.9/site-packages/dogpile/cache/region.py", line 1577, in get_or_create_for_user_func
2023-04-14 00:35:42.399 39 ERROR keystone.server.flask.application     return self.get_or_create(
2023-04-14 00:35:42.399 39 ERROR keystone.server.flask.application   File "/var/lib/kolla/venv/lib/python3.9/site-packages/dogpile/cache/region.py", line 1042, in get_or_create
2023-04-14 00:35:42.399 39 ERROR keystone.server.flask.application     with Lock(
2023-04-14 00:35:42.399 39 ERROR keystone.server.flask.application   File "/var/lib/kolla/venv/lib/python3.9/site-packages/dogpile/lock.py", line 185, in __enter__
2023-04-14 00:35:42.399 39 ERROR keystone.server.flask.application     return self._enter()
2023-04-14 00:35:42.399 39 ERROR keystone.server.flask.application   File "/var/lib/kolla/venv/lib/python3.9/site-packages/dogpile/lock.py", line 94, in _enter
2023-04-14 00:35:42.399 39 ERROR keystone.server.flask.application     generated = self._enter_create(value, createdtime)
2023-04-14 00:35:42.399 39 ERROR keystone.server.flask.application   File "/var/lib/kolla/venv/lib/python3.9/site-packages/dogpile/lock.py", line 178, in _enter_create
2023-04-14 00:35:42.399 39 ERROR keystone.server.flask.application     return self.creator()
2023-04-14 00:35:42.399 39 ERROR keystone.server.flask.application   File "/var/lib/kolla/venv/lib/python3.9/site-packages/dogpile/cache/region.py", line 995, in gen_value
2023-04-14 00:35:42.399 39 ERROR keystone.server.flask.application     created_value = creator(
2023-04-14 00:35:42.399 39 ERROR keystone.server.flask.application   File "/var/lib/kolla/venv/lib/python3.9/site-packages/keystone/resource/core.py", line 903, in get_project
2023-04-14 00:35:42.399 39 ERROR keystone.server.flask.application     return self.driver.get_project(project_id)
2023-04-14 00:35:42.399 39 ERROR keystone.server.flask.application   File "/var/lib/kolla/venv/lib/python3.9/site-packages/keystone/resource/backends/sql.py", line 49, in get_project
2023-04-14 00:35:42.399 39 ERROR keystone.server.flask.application     return self._get_project(session, project_id).to_dict()
2023-04-14 00:35:42.399 39 ERROR keystone.server.flask.application   File "/var/lib/kolla/venv/lib/python3.9/site-packages/keystone/resource/backends/sql.py", line 44, in _get_project
2023-04-14 00:35:42.399 39 ERROR keystone.server.flask.application     raise exception.ProjectNotFound(project_id=project_id)
2023-04-14 00:35:42.399 39 ERROR keystone.server.flask.application keystone.exception.ProjectNotFound: Could not find project: service.
2023-04-14 00:35:42.399 39 ERROR keystone.server.flask.application 
2023-04-14 00:38:29.662 39 ERROR keystone.server.flask.application [None req-85f83f2e-52b0-4ee4-bfa6-f6700b354120 6f184208ce274855a4122f6b366bf412 - - all default -] Could not find project: service.: keystone.exception.ProjectNotFound: Could not find project: service.
2023-04-14 00:38:29.662 39 ERROR keystone.server.flask.application Traceback (most recent call last):
2023-04-14 00:38:29.662 39 ERROR keystone.server.flask.application   File "/var/lib/kolla/venv/lib/python3.9/site-packages/flask/app.py", line 1820, in full_dispatch_request
2023-04-14 00:38:29.662 39 ERROR keystone.server.flask.application     rv = self.dispatch_request()
2023-04-14 00:38:29.662 39 ERROR keystone.server.flask.application   File "/var/lib/kolla/venv/lib/python3.9/site-packages/flask/app.py", line 1796, in dispatch_request
2023-04-14 00:38:29.662 39 ERROR keystone.server.flask.application     return self.ensure_sync(self.view_functions[rule.endpoint])(**view_args)
2023-04-14 00:38:29.662 39 ERROR keystone.server.flask.application   File "/var/lib/kolla/venv/lib/python3.9/site-packages/flask_restful/__init__.py", line 467, in wrapper
2023-04-14 00:38:29.662 39 ERROR keystone.server.flask.application     resp = resource(*args, **kwargs)
2023-04-14 00:38:29.662 39 ERROR keystone.server.flask.application   File "/var/lib/kolla/venv/lib/python3.9/site-packages/flask/views.py", line 107, in view
2023-04-14 00:38:29.662 39 ERROR keystone.server.flask.application     return current_app.ensure_sync(self.dispatch_request)(**kwargs)
2023-04-14 00:38:29.662 39 ERROR keystone.server.flask.application   File "/var/lib/kolla/venv/lib/python3.9/site-packages/flask_restful/__init__.py", line 582, in dispatch_request
2023-04-14 00:38:29.662 39 ERROR keystone.server.flask.application     resp = meth(*args, **kwargs)
2023-04-14 00:38:29.662 39 ERROR keystone.server.flask.application   File "/var/lib/kolla/venv/lib/python3.9/site-packages/keystone/api/projects.py", line 151, in get
2023-04-14 00:38:29.662 39 ERROR keystone.server.flask.application     return self._get_project(project_id)
2023-04-14 00:38:29.662 39 ERROR keystone.server.flask.application   File "/var/lib/kolla/venv/lib/python3.9/site-packages/keystone/api/projects.py", line 107, in _get_project
2023-04-14 00:38:29.662 39 ERROR keystone.server.flask.application     project = PROVIDERS.resource_api.get_project(project_id)
2023-04-14 00:38:29.662 39 ERROR keystone.server.flask.application   File "/var/lib/kolla/venv/lib/python3.9/site-packages/keystone/common/manager.py", line 115, in wrapped
2023-04-14 00:38:29.662 39 ERROR keystone.server.flask.application     __ret_val = __f(*args, **kwargs)
2023-04-14 00:38:29.662 39 ERROR keystone.server.flask.application   File "/var/lib/kolla/venv/lib/python3.9/site-packages/decorator.py", line 232, in fun
2023-04-14 00:38:29.662 39 ERROR keystone.server.flask.application     return caller(func, *(extras + args), **kw)
2023-04-14 00:38:29.662 39 ERROR keystone.server.flask.application   File "/var/lib/kolla/venv/lib/python3.9/site-packages/dogpile/cache/region.py", line 1577, in get_or_create_for_user_func
2023-04-14 00:38:29.662 39 ERROR keystone.server.flask.application     return self.get_or_create(
2023-04-14 00:38:29.662 39 ERROR keystone.server.flask.application   File "/var/lib/kolla/venv/lib/python3.9/site-packages/dogpile/cache/region.py", line 1042, in get_or_create
2023-04-14 00:38:29.662 39 ERROR keystone.server.flask.application     with Lock(
2023-04-14 00:38:29.662 39 ERROR keystone.server.flask.application   File "/var/lib/kolla/venv/lib/python3.9/site-packages/dogpile/lock.py", line 185, in __enter__
2023-04-14 00:38:29.662 39 ERROR keystone.server.flask.application     return self._enter()
2023-04-14 00:38:29.662 39 ERROR keystone.server.flask.application   File "/var/lib/kolla/venv/lib/python3.9/site-packages/dogpile/lock.py", line 94, in _enter
2023-04-14 00:38:29.662 39 ERROR keystone.server.flask.application     generated = self._enter_create(value, createdtime)
2023-04-14 00:38:29.662 39 ERROR keystone.server.flask.application   File "/var/lib/kolla/venv/lib/python3.9/site-packages/dogpile/lock.py", line 178, in _enter_create
2023-04-14 00:38:29.662 39 ERROR keystone.server.flask.application     return self.creator()
2023-04-14 00:38:29.662 39 ERROR keystone.server.flask.application   File "/var/lib/kolla/venv/lib/python3.9/site-packages/dogpile/cache/region.py", line 995, in gen_value
2023-04-14 00:38:29.662 39 ERROR keystone.server.flask.application     created_value = creator(
2023-04-14 00:38:29.662 39 ERROR keystone.server.flask.application   File "/var/lib/kolla/venv/lib/python3.9/site-packages/keystone/resource/core.py", line 903, in get_project
2023-04-14 00:38:29.662 39 ERROR keystone.server.flask.application     return self.driver.get_project(project_id)
2023-04-14 00:38:29.662 39 ERROR keystone.server.flask.application   File "/var/lib/kolla/venv/lib/python3.9/site-packages/keystone/resource/backends/sql.py", line 49, in get_project
2023-04-14 00:38:29.662 39 ERROR keystone.server.flask.application     return self._get_project(session, project_id).to_dict()
2023-04-14 00:38:29.662 39 ERROR keystone.server.flask.application   File "/var/lib/kolla/venv/lib/python3.9/site-packages/keystone/resource/backends/sql.py", line 44, in _get_project
2023-04-14 00:38:29.662 39 ERROR keystone.server.flask.application     raise exception.ProjectNotFound(project_id=project_id)
2023-04-14 00:38:29.662 39 ERROR keystone.server.flask.application keystone.exception.ProjectNotFound: Could not find project: service.
2023-04-14 00:38:29.662 39 ERROR keystone.server.flask.application 
2023-04-14 00:38:43.896 38 ERROR keystone.server.flask.application [None req-91fa12a4-8c83-442c-981f-20e0db0acf03 6f184208ce274855a4122f6b366bf412 - - all default -] Could not find role: admin.: keystone.exception.RoleNotFound: Could not find role: admin.
2023-04-14 00:38:43.896 38 ERROR keystone.server.flask.application Traceback (most recent call last):
2023-04-14 00:38:43.896 38 ERROR keystone.server.flask.application   File "/var/lib/kolla/venv/lib/python3.9/site-packages/flask/app.py", line 1820, in full_dispatch_request
2023-04-14 00:38:43.896 38 ERROR keystone.server.flask.application     rv = self.dispatch_request()
2023-04-14 00:38:43.896 38 ERROR keystone.server.flask.application   File "/var/lib/kolla/venv/lib/python3.9/site-packages/flask/app.py", line 1796, in dispatch_request
2023-04-14 00:38:43.896 38 ERROR keystone.server.flask.application     return self.ensure_sync(self.view_functions[rule.endpoint])(**view_args)
2023-04-14 00:38:43.896 38 ERROR keystone.server.flask.application   File "/var/lib/kolla/venv/lib/python3.9/site-packages/flask_restful/__init__.py", line 467, in wrapper
2023-04-14 00:38:43.896 38 ERROR keystone.server.flask.application     resp = resource(*args, **kwargs)
2023-04-14 00:38:43.896 38 ERROR keystone.server.flask.application   File "/var/lib/kolla/venv/lib/python3.9/site-packages/flask/views.py", line 107, in view
2023-04-14 00:38:43.896 38 ERROR keystone.server.flask.application     return current_app.ensure_sync(self.dispatch_request)(**kwargs)
2023-04-14 00:38:43.896 38 ERROR keystone.server.flask.application   File "/var/lib/kolla/venv/lib/python3.9/site-packages/flask_restful/__init__.py", line 582, in dispatch_request
2023-04-14 00:38:43.896 38 ERROR keystone.server.flask.application     resp = meth(*args, **kwargs)
2023-04-14 00:38:43.896 38 ERROR keystone.server.flask.application   File "/var/lib/kolla/venv/lib/python3.9/site-packages/keystone/api/roles.py", line 50, in get
2023-04-14 00:38:43.896 38 ERROR keystone.server.flask.application     return self._get_role(role_id)
2023-04-14 00:38:43.896 38 ERROR keystone.server.flask.application   File "/var/lib/kolla/venv/lib/python3.9/site-packages/keystone/api/roles.py", line 70, in _get_role
2023-04-14 00:38:43.896 38 ERROR keystone.server.flask.application     ENFORCER.enforce_call(action='identity:get_role')
2023-04-14 00:38:43.896 38 ERROR keystone.server.flask.application   File "/var/lib/kolla/venv/lib/python3.9/site-packages/keystone/common/rbac_enforcer/enforcer.py", line 402, in enforce_call
2023-04-14 00:38:43.896 38 ERROR keystone.server.flask.application     policy_dict.update(cls._extract_member_target_data(
2023-04-14 00:38:43.896 38 ERROR keystone.server.flask.application   File "/var/lib/kolla/venv/lib/python3.9/site-packages/keystone/common/rbac_enforcer/enforcer.py", line 234, in _extract_member_target_data
2023-04-14 00:38:43.896 38 ERROR keystone.server.flask.application     member_name: func(flask.request.view_args[key])
2023-04-14 00:38:43.896 38 ERROR keystone.server.flask.application   File "/var/lib/kolla/venv/lib/python3.9/site-packages/keystone/common/manager.py", line 115, in wrapped
2023-04-14 00:38:43.896 38 ERROR keystone.server.flask.application     __ret_val = __f(*args, **kwargs)
2023-04-14 00:38:43.896 38 ERROR keystone.server.flask.application   File "/var/lib/kolla/venv/lib/python3.9/site-packages/decorator.py", line 232, in fun
2023-04-14 00:38:43.896 38 ERROR keystone.server.flask.application     return caller(func, *(extras + args), **kw)
2023-04-14 00:38:43.896 38 ERROR keystone.server.flask.application   File "/var/lib/kolla/venv/lib/python3.9/site-packages/dogpile/cache/region.py", line 1577, in get_or_create_for_user_func
2023-04-14 00:38:43.896 38 ERROR keystone.server.flask.application     return self.get_or_create(
2023-04-14 00:38:43.896 38 ERROR keystone.server.flask.application   File "/var/lib/kolla/venv/lib/python3.9/site-packages/dogpile/cache/region.py", line 1042, in get_or_create
2023-04-14 00:38:43.896 38 ERROR keystone.server.flask.application     with Lock(
2023-04-14 00:38:43.896 38 ERROR keystone.server.flask.application   File "/var/lib/kolla/venv/lib/python3.9/site-packages/dogpile/lock.py", line 185, in __enter__
2023-04-14 00:38:43.896 38 ERROR keystone.server.flask.application     return self._enter()
2023-04-14 00:38:43.896 38 ERROR keystone.server.flask.application   File "/var/lib/kolla/venv/lib/python3.9/site-packages/dogpile/lock.py", line 94, in _enter
2023-04-14 00:38:43.896 38 ERROR keystone.server.flask.application     generated = self._enter_create(value, createdtime)
2023-04-14 00:38:43.896 38 ERROR keystone.server.flask.application   File "/var/lib/kolla/venv/lib/python3.9/site-packages/dogpile/lock.py", line 178, in _enter_create
2023-04-14 00:38:43.896 38 ERROR keystone.server.flask.application     return self.creator()
2023-04-14 00:38:43.896 38 ERROR keystone.server.flask.application   File "/var/lib/kolla/venv/lib/python3.9/site-packages/dogpile/cache/region.py", line 995, in gen_value
2023-04-14 00:38:43.896 38 ERROR keystone.server.flask.application     created_value = creator(
2023-04-14 00:38:43.896 38 ERROR keystone.server.flask.application   File "/var/lib/kolla/venv/lib/python3.9/site-packages/keystone/assignment/core.py", line 1276, in get_role
2023-04-14 00:38:43.896 38 ERROR keystone.server.flask.application     return self.driver.get_role(role_id)
2023-04-14 00:38:43.896 38 ERROR keystone.server.flask.application   File "/var/lib/kolla/venv/lib/python3.9/site-packages/keystone/assignment/role_backends/sql.py", line 70, in get_role
2023-04-14 00:38:43.896 38 ERROR keystone.server.flask.application     return self._get_role(session, role_id).to_dict()
2023-04-14 00:38:43.896 38 ERROR keystone.server.flask.application   File "/var/lib/kolla/venv/lib/python3.9/site-packages/keystone/assignment/role_backends/sql.py", line 65, in _get_role
2023-04-14 00:38:43.896 38 ERROR keystone.server.flask.application     raise exception.RoleNotFound(role_id=role_id)
2023-04-14 00:38:43.896 38 ERROR keystone.server.flask.application keystone.exception.RoleNotFound: Could not find role: admin.
2023-04-14 00:38:43.896 38 ERROR keystone.server.flask.application 
2023-04-14 00:38:44.851 38 ERROR keystone.server.flask.application [None req-1025de43-1162-4b7d-9b77-2885acc475f4 6f184208ce274855a4122f6b366bf412 - - all default -] Could not find user: neutron.: keystone.exception.UserNotFound: Could not find user: neutron.
2023-04-14 00:38:44.851 38 ERROR keystone.server.flask.application Traceback (most recent call last):
2023-04-14 00:38:44.851 38 ERROR keystone.server.flask.application   File "/var/lib/kolla/venv/lib/python3.9/site-packages/flask/app.py", line 1820, in full_dispatch_request
2023-04-14 00:38:44.851 38 ERROR keystone.server.flask.application     rv = self.dispatch_request()
2023-04-14 00:38:44.851 38 ERROR keystone.server.flask.application   File "/var/lib/kolla/venv/lib/python3.9/site-packages/flask/app.py", line 1796, in dispatch_request
2023-04-14 00:38:44.851 38 ERROR keystone.server.flask.application     return self.ensure_sync(self.view_functions[rule.endpoint])(**view_args)
2023-04-14 00:38:44.851 38 ERROR keystone.server.flask.application   File "/var/lib/kolla/venv/lib/python3.9/site-packages/flask_restful/__init__.py", line 467, in wrapper
2023-04-14 00:38:44.851 38 ERROR keystone.server.flask.application     resp = resource(*args, **kwargs)
2023-04-14 00:38:44.851 38 ERROR keystone.server.flask.application   File "/var/lib/kolla/venv/lib/python3.9/site-packages/flask/views.py", line 107, in view
2023-04-14 00:38:44.851 38 ERROR keystone.server.flask.application     return current_app.ensure_sync(self.dispatch_request)(**kwargs)
2023-04-14 00:38:44.851 38 ERROR keystone.server.flask.application   File "/var/lib/kolla/venv/lib/python3.9/site-packages/flask_restful/__init__.py", line 582, in dispatch_request
2023-04-14 00:38:44.851 38 ERROR keystone.server.flask.application     resp = meth(*args, **kwargs)
2023-04-14 00:38:44.851 38 ERROR keystone.server.flask.application   File "/var/lib/kolla/venv/lib/python3.9/site-packages/keystone/api/users.py", line 182, in get
2023-04-14 00:38:44.851 38 ERROR keystone.server.flask.application     return self._get_user(user_id)
2023-04-14 00:38:44.851 38 ERROR keystone.server.flask.application   File "/var/lib/kolla/venv/lib/python3.9/site-packages/keystone/api/users.py", line 194, in _get_user
2023-04-14 00:38:44.851 38 ERROR keystone.server.flask.application     ref = PROVIDERS.identity_api.get_user(user_id)
2023-04-14 00:38:44.851 38 ERROR keystone.server.flask.application   File "/var/lib/kolla/venv/lib/python3.9/site-packages/keystone/common/manager.py", line 115, in wrapped
2023-04-14 00:38:44.851 38 ERROR keystone.server.flask.application     __ret_val = __f(*args, **kwargs)
2023-04-14 00:38:44.851 38 ERROR keystone.server.flask.application   File "/var/lib/kolla/venv/lib/python3.9/site-packages/keystone/identity/core.py", line 414, in wrapper
2023-04-14 00:38:44.851 38 ERROR keystone.server.flask.application     return f(self, *args, **kwargs)
2023-04-14 00:38:44.851 38 ERROR keystone.server.flask.application   File "/var/lib/kolla/venv/lib/python3.9/site-packages/keystone/identity/core.py", line 424, in wrapper
2023-04-14 00:38:44.851 38 ERROR keystone.server.flask.application     return f(self, *args, **kwargs)
2023-04-14 00:38:44.851 38 ERROR keystone.server.flask.application   File "/var/lib/kolla/venv/lib/python3.9/site-packages/decorator.py", line 232, in fun
2023-04-14 00:38:44.851 38 ERROR keystone.server.flask.application     return caller(func, *(extras + args), **kw)
2023-04-14 00:38:44.851 38 ERROR keystone.server.flask.application   File "/var/lib/kolla/venv/lib/python3.9/site-packages/dogpile/cache/region.py", line 1577, in get_or_create_for_user_func
2023-04-14 00:38:44.851 38 ERROR keystone.server.flask.application     return self.get_or_create(
2023-04-14 00:38:44.851 38 ERROR keystone.server.flask.application   File "/var/lib/kolla/venv/lib/python3.9/site-packages/dogpile/cache/region.py", line 1042, in get_or_create
2023-04-14 00:38:44.851 38 ERROR keystone.server.flask.application     with Lock(
2023-04-14 00:38:44.851 38 ERROR keystone.server.flask.application   File "/var/lib/kolla/venv/lib/python3.9/site-packages/dogpile/lock.py", line 185, in __enter__
2023-04-14 00:38:44.851 38 ERROR keystone.server.flask.application     return self._enter()
2023-04-14 00:38:44.851 38 ERROR keystone.server.flask.application   File "/var/lib/kolla/venv/lib/python3.9/site-packages/dogpile/lock.py", line 94, in _enter
2023-04-14 00:38:44.851 38 ERROR keystone.server.flask.application     generated = self._enter_create(value, createdtime)
2023-04-14 00:38:44.851 38 ERROR keystone.server.flask.application   File "/var/lib/kolla/venv/lib/python3.9/site-packages/dogpile/lock.py", line 178, in _enter_create
2023-04-14 00:38:44.851 38 ERROR keystone.server.flask.application     return self.creator()
2023-04-14 00:38:44.851 38 ERROR keystone.server.flask.application   File "/var/lib/kolla/venv/lib/python3.9/site-packages/dogpile/cache/region.py", line 995, in gen_value
2023-04-14 00:38:44.851 38 ERROR keystone.server.flask.application     created_value = creator(
2023-04-14 00:38:44.851 38 ERROR keystone.server.flask.application   File "/var/lib/kolla/venv/lib/python3.9/site-packages/keystone/identity/core.py", line 1011, in get_user
2023-04-14 00:38:44.851 38 ERROR keystone.server.flask.application     ref = driver.get_user(entity_id)
2023-04-14 00:38:44.851 38 ERROR keystone.server.flask.application   File "/var/lib/kolla/venv/lib/python3.9/site-packages/keystone/identity/backends/sql.py", line 200, in get_user
2023-04-14 00:38:44.851 38 ERROR keystone.server.flask.application     self._get_user(session, user_id).to_dict())
2023-04-14 00:38:44.851 38 ERROR keystone.server.flask.application   File "/var/lib/kolla/venv/lib/python3.9/site-packages/keystone/identity/backends/sql.py", line 194, in _get_user
2023-04-14 00:38:44.851 38 ERROR keystone.server.flask.application     raise exception.UserNotFound(user_id=user_id)
2023-04-14 00:38:44.851 38 ERROR keystone.server.flask.application keystone.exception.UserNotFound: Could not find user: neutron.
2023-04-14 00:38:44.851 38 ERROR keystone.server.flask.application 
2023-04-14 00:38:45.503 37 ERROR keystone.server.flask.application [None req-1d986e91-96ca-4e37-ab05-48561ff67091 6f184208ce274855a4122f6b366bf412 - - all default -] Could not find project: service.: keystone.exception.ProjectNotFound: Could not find project: service.
2023-04-14 00:38:45.503 37 ERROR keystone.server.flask.application Traceback (most recent call last):
2023-04-14 00:38:45.503 37 ERROR keystone.server.flask.application   File "/var/lib/kolla/venv/lib/python3.9/site-packages/flask/app.py", line 1820, in full_dispatch_request
2023-04-14 00:38:45.503 37 ERROR keystone.server.flask.application     rv = self.dispatch_request()
2023-04-14 00:38:45.503 37 ERROR keystone.server.flask.application   File "/var/lib/kolla/venv/lib/python3.9/site-packages/flask/app.py", line 1796, in dispatch_request
2023-04-14 00:38:45.503 37 ERROR keystone.server.flask.application     return self.ensure_sync(self.view_functions[rule.endpoint])(**view_args)
2023-04-14 00:38:45.503 37 ERROR keystone.server.flask.application   File "/var/lib/kolla/venv/lib/python3.9/site-packages/flask_restful/__init__.py", line 467, in wrapper
2023-04-14 00:38:45.503 37 ERROR keystone.server.flask.application     resp = resource(*args, **kwargs)
2023-04-14 00:38:45.503 37 ERROR keystone.server.flask.application   File "/var/lib/kolla/venv/lib/python3.9/site-packages/flask/views.py", line 107, in view
2023-04-14 00:38:45.503 37 ERROR keystone.server.flask.application     return current_app.ensure_sync(self.dispatch_request)(**kwargs)
2023-04-14 00:38:45.503 37 ERROR keystone.server.flask.application   File "/var/lib/kolla/venv/lib/python3.9/site-packages/flask_restful/__init__.py", line 582, in dispatch_request
2023-04-14 00:38:45.503 37 ERROR keystone.server.flask.application     resp = meth(*args, **kwargs)
2023-04-14 00:38:45.503 37 ERROR keystone.server.flask.application   File "/var/lib/kolla/venv/lib/python3.9/site-packages/keystone/api/projects.py", line 151, in get
2023-04-14 00:38:45.503 37 ERROR keystone.server.flask.application     return self._get_project(project_id)
2023-04-14 00:38:45.503 37 ERROR keystone.server.flask.application   File "/var/lib/kolla/venv/lib/python3.9/site-packages/keystone/api/projects.py", line 107, in _get_project
2023-04-14 00:38:45.503 37 ERROR keystone.server.flask.application     project = PROVIDERS.resource_api.get_project(project_id)
2023-04-14 00:38:45.503 37 ERROR keystone.server.flask.application   File "/var/lib/kolla/venv/lib/python3.9/site-packages/keystone/common/manager.py", line 115, in wrapped
2023-04-14 00:38:45.503 37 ERROR keystone.server.flask.application     __ret_val = __f(*args, **kwargs)
2023-04-14 00:38:45.503 37 ERROR keystone.server.flask.application   File "/var/lib/kolla/venv/lib/python3.9/site-packages/decorator.py", line 232, in fun
2023-04-14 00:38:45.503 37 ERROR keystone.server.flask.application     return caller(func, *(extras + args), **kw)
2023-04-14 00:38:45.503 37 ERROR keystone.server.flask.application   File "/var/lib/kolla/venv/lib/python3.9/site-packages/dogpile/cache/region.py", line 1577, in get_or_create_for_user_func
2023-04-14 00:38:45.503 37 ERROR keystone.server.flask.application     return self.get_or_create(
2023-04-14 00:38:45.503 37 ERROR keystone.server.flask.application   File "/var/lib/kolla/venv/lib/python3.9/site-packages/dogpile/cache/region.py", line 1042, in get_or_create
2023-04-14 00:38:45.503 37 ERROR keystone.server.flask.application     with Lock(
2023-04-14 00:38:45.503 37 ERROR keystone.server.flask.application   File "/var/lib/kolla/venv/lib/python3.9/site-packages/dogpile/lock.py", line 185, in __enter__
2023-04-14 00:38:45.503 37 ERROR keystone.server.flask.application     return self._enter()
2023-04-14 00:38:45.503 37 ERROR keystone.server.flask.application   File "/var/lib/kolla/venv/lib/python3.9/site-packages/dogpile/lock.py", line 94, in _enter
2023-04-14 00:38:45.503 37 ERROR keystone.server.flask.application     generated = self._enter_create(value, createdtime)
2023-04-14 00:38:45.503 37 ERROR keystone.server.flask.application   File "/var/lib/kolla/venv/lib/python3.9/site-packages/dogpile/lock.py", line 178, in _enter_create
2023-04-14 00:38:45.503 37 ERROR keystone.server.flask.application     return self.creator()
2023-04-14 00:38:45.503 37 ERROR keystone.server.flask.application   File "/var/lib/kolla/venv/lib/python3.9/site-packages/dogpile/cache/region.py", line 995, in gen_value
2023-04-14 00:38:45.503 37 ERROR keystone.server.flask.application     created_value = creator(
2023-04-14 00:38:45.503 37 ERROR keystone.server.flask.application   File "/var/lib/kolla/venv/lib/python3.9/site-packages/keystone/resource/core.py", line 903, in get_project
2023-04-14 00:38:45.503 37 ERROR keystone.server.flask.application     return self.driver.get_project(project_id)
2023-04-14 00:38:45.503 37 ERROR keystone.server.flask.application   File "/var/lib/kolla/venv/lib/python3.9/site-packages/keystone/resource/backends/sql.py", line 49, in get_project
2023-04-14 00:38:45.503 37 ERROR keystone.server.flask.application     return self._get_project(session, project_id).to_dict()
2023-04-14 00:38:45.503 37 ERROR keystone.server.flask.application   File "/var/lib/kolla/venv/lib/python3.9/site-packages/keystone/resource/backends/sql.py", line 44, in _get_project
2023-04-14 00:38:45.503 37 ERROR keystone.server.flask.application     raise exception.ProjectNotFound(project_id=project_id)
2023-04-14 00:38:45.503 37 ERROR keystone.server.flask.application keystone.exception.ProjectNotFound: Could not find project: service.
2023-04-14 00:38:45.503 37 ERROR keystone.server.flask.application 
