2023-02-21 21:29:02.092762 2023-02-21 21:29:02.091 28 WARNING keystone.common.rbac_enforcer.enforcer [None req-9b612eae-1c9e-41fc-b23b-aa13b28c06e8 d0baa17cc04d45d091397605ff97a2c4 - - all default -] Deprecated policy rules found. Use oslopolicy-policy-generator and oslopolicy-policy-upgrade to detect and resolve deprecated policies in your configuration.\x1b[00m
2023-02-21 21:29:02.965063 2023-02-21 21:29:02.963 26 WARNING keystone.common.rbac_enforcer.enforcer [None req-ba8ccdd3-eccf-46b7-bec5-79190ab8201f d0baa17cc04d45d091397605ff97a2c4 - - all default -] Deprecated policy rules found. Use oslopolicy-policy-generator and oslopolicy-policy-upgrade to detect and resolve deprecated policies in your configuration.\x1b[00m
2023-02-21 21:29:10.489572 2023-02-21 21:29:10.487 27 WARNING keystone.common.rbac_enforcer.enforcer [None req-336d2ec3-7166-4b7f-812f-198c1fff5fe5 d0baa17cc04d45d091397605ff97a2c4 - - all default -] Deprecated policy rules found. Use oslopolicy-policy-generator and oslopolicy-policy-upgrade to detect and resolve deprecated policies in your configuration.\x1b[00m
2023-02-21 21:30:22.614289 2023-02-21 21:30:22.584 26 ERROR keystone.server.flask.application [None req-299dde93-aa0b-46cc-a11f-cd24650baeb5 d0baa17cc04d45d091397605ff97a2c4 - - all default -] Could not find project: service.: keystone.exception.ProjectNotFound: Could not find project: service.
2023-02-21 21:30:22.614359 2023-02-21 21:30:22.584 26 ERROR keystone.server.flask.application Traceback (most recent call last):
2023-02-21 21:30:22.614373 2023-02-21 21:30:22.584 26 ERROR keystone.server.flask.application   File "/var/lib/kolla/venv/lib/python3.9/site-packages/flask/app.py", line 1820, in full_dispatch_request
2023-02-21 21:30:22.614385 2023-02-21 21:30:22.584 26 ERROR keystone.server.flask.application     rv = self.dispatch_request()
2023-02-21 21:30:22.614396 2023-02-21 21:30:22.584 26 ERROR keystone.server.flask.application   File "/var/lib/kolla/venv/lib/python3.9/site-packages/flask/app.py", line 1796, in dispatch_request
2023-02-21 21:30:22.614407 2023-02-21 21:30:22.584 26 ERROR keystone.server.flask.application     return self.ensure_sync(self.view_functions[rule.endpoint])(**view_args)
2023-02-21 21:30:22.614418 2023-02-21 21:30:22.584 26 ERROR keystone.server.flask.application   File "/var/lib/kolla/venv/lib/python3.9/site-packages/flask_restful/__init__.py", line 467, in wrapper
2023-02-21 21:30:22.614429 2023-02-21 21:30:22.584 26 ERROR keystone.server.flask.application     resp = resource(*args, **kwargs)
2023-02-21 21:30:22.614447 2023-02-21 21:30:22.584 26 ERROR keystone.server.flask.application   File "/var/lib/kolla/venv/lib/python3.9/site-packages/flask/views.py", line 107, in view
2023-02-21 21:30:22.614461 2023-02-21 21:30:22.584 26 ERROR keystone.server.flask.application     return current_app.ensure_sync(self.dispatch_request)(**kwargs)
2023-02-21 21:30:22.614472 2023-02-21 21:30:22.584 26 ERROR keystone.server.flask.application   File "/var/lib/kolla/venv/lib/python3.9/site-packages/flask_restful/__init__.py", line 582, in dispatch_request
2023-02-21 21:30:22.614483 2023-02-21 21:30:22.584 26 ERROR keystone.server.flask.application     resp = meth(*args, **kwargs)
2023-02-21 21:30:22.614493 2023-02-21 21:30:22.584 26 ERROR keystone.server.flask.application   File "/var/lib/kolla/venv/lib/python3.9/site-packages/keystone/api/projects.py", line 151, in get
2023-02-21 21:30:22.614505 2023-02-21 21:30:22.584 26 ERROR keystone.server.flask.application     return self._get_project(project_id)
2023-02-21 21:30:22.614516 2023-02-21 21:30:22.584 26 ERROR keystone.server.flask.application   File "/var/lib/kolla/venv/lib/python3.9/site-packages/keystone/api/projects.py", line 107, in _get_project
2023-02-21 21:30:22.614527 2023-02-21 21:30:22.584 26 ERROR keystone.server.flask.application     project = PROVIDERS.resource_api.get_project(project_id)
2023-02-21 21:30:22.614537 2023-02-21 21:30:22.584 26 ERROR keystone.server.flask.application   File "/var/lib/kolla/venv/lib/python3.9/site-packages/keystone/common/manager.py", line 115, in wrapped
2023-02-21 21:30:22.614578 2023-02-21 21:30:22.584 26 ERROR keystone.server.flask.application     __ret_val = __f(*args, **kwargs)
2023-02-21 21:30:22.614592 2023-02-21 21:30:22.584 26 ERROR keystone.server.flask.application   File "/var/lib/kolla/venv/lib/python3.9/site-packages/decorator.py", line 232, in fun
2023-02-21 21:30:22.614603 2023-02-21 21:30:22.584 26 ERROR keystone.server.flask.application     return caller(func, *(extras + args), **kw)
2023-02-21 21:30:22.614632 2023-02-21 21:30:22.584 26 ERROR keystone.server.flask.application   File "/var/lib/kolla/venv/lib/python3.9/site-packages/dogpile/cache/region.py", line 1577, in get_or_create_for_user_func
2023-02-21 21:30:22.614645 2023-02-21 21:30:22.584 26 ERROR keystone.server.flask.application     return self.get_or_create(
2023-02-21 21:30:22.614656 2023-02-21 21:30:22.584 26 ERROR keystone.server.flask.application   File "/var/lib/kolla/venv/lib/python3.9/site-packages/dogpile/cache/region.py", line 1042, in get_or_create
2023-02-21 21:30:22.614667 2023-02-21 21:30:22.584 26 ERROR keystone.server.flask.application     with Lock(
2023-02-21 21:30:22.614678 2023-02-21 21:30:22.584 26 ERROR keystone.server.flask.application   File "/var/lib/kolla/venv/lib/python3.9/site-packages/dogpile/lock.py", line 185, in __enter__
2023-02-21 21:30:22.614688 2023-02-21 21:30:22.584 26 ERROR keystone.server.flask.application     return self._enter()
2023-02-21 21:30:22.614699 2023-02-21 21:30:22.584 26 ERROR keystone.server.flask.application   File "/var/lib/kolla/venv/lib/python3.9/site-packages/dogpile/lock.py", line 94, in _enter
2023-02-21 21:30:22.614709 2023-02-21 21:30:22.584 26 ERROR keystone.server.flask.application     generated = self._enter_create(value, createdtime)
2023-02-21 21:30:22.614720 2023-02-21 21:30:22.584 26 ERROR keystone.server.flask.application   File "/var/lib/kolla/venv/lib/python3.9/site-packages/dogpile/lock.py", line 178, in _enter_create
2023-02-21 21:30:22.614731 2023-02-21 21:30:22.584 26 ERROR keystone.server.flask.application     return self.creator()
2023-02-21 21:30:22.614741 2023-02-21 21:30:22.584 26 ERROR keystone.server.flask.application   File "/var/lib/kolla/venv/lib/python3.9/site-packages/dogpile/cache/region.py", line 995, in gen_value
2023-02-21 21:30:22.614752 2023-02-21 21:30:22.584 26 ERROR keystone.server.flask.application     created_value = creator(
2023-02-21 21:30:22.614762 2023-02-21 21:30:22.584 26 ERROR keystone.server.flask.application   File "/var/lib/kolla/venv/lib/python3.9/site-packages/keystone/resource/core.py", line 903, in get_project
2023-02-21 21:30:22.614773 2023-02-21 21:30:22.584 26 ERROR keystone.server.flask.application     return self.driver.get_project(project_id)
2023-02-21 21:30:22.614784 2023-02-21 21:30:22.584 26 ERROR keystone.server.flask.application   File "/var/lib/kolla/venv/lib/python3.9/site-packages/keystone/resource/backends/sql.py", line 49, in get_project
2023-02-21 21:30:22.614795 2023-02-21 21:30:22.584 26 ERROR keystone.server.flask.application     return self._get_project(session, project_id).to_dict()
2023-02-21 21:30:22.614805 2023-02-21 21:30:22.584 26 ERROR keystone.server.flask.application   File "/var/lib/kolla/venv/lib/python3.9/site-packages/keystone/resource/backends/sql.py", line 44, in _get_project
2023-02-21 21:30:22.614816 2023-02-21 21:30:22.584 26 ERROR keystone.server.flask.application     raise exception.ProjectNotFound(project_id=project_id)
2023-02-21 21:30:22.614827 2023-02-21 21:30:22.584 26 ERROR keystone.server.flask.application keystone.exception.ProjectNotFound: Could not find project: service.
2023-02-21 21:30:22.614838 2023-02-21 21:30:22.584 26 ERROR keystone.server.flask.application \x1b[00m
2023-02-21 21:30:31.067586 2023-02-21 21:30:31.052 28 ERROR keystone.server.flask.application [None req-7bc914c3-e31a-42fe-a145-bc37236b0f7a d0baa17cc04d45d091397605ff97a2c4 - - all default -] Could not find project: service.: keystone.exception.ProjectNotFound: Could not find project: service.
2023-02-21 21:30:31.067662 2023-02-21 21:30:31.052 28 ERROR keystone.server.flask.application Traceback (most recent call last):
2023-02-21 21:30:31.067701 2023-02-21 21:30:31.052 28 ERROR keystone.server.flask.application   File "/var/lib/kolla/venv/lib/python3.9/site-packages/flask/app.py", line 1820, in full_dispatch_request
2023-02-21 21:30:31.067714 2023-02-21 21:30:31.052 28 ERROR keystone.server.flask.application     rv = self.dispatch_request()
2023-02-21 21:30:31.067724 2023-02-21 21:30:31.052 28 ERROR keystone.server.flask.application   File "/var/lib/kolla/venv/lib/python3.9/site-packages/flask/app.py", line 1796, in dispatch_request
2023-02-21 21:30:31.067734 2023-02-21 21:30:31.052 28 ERROR keystone.server.flask.application     return self.ensure_sync(self.view_functions[rule.endpoint])(**view_args)
2023-02-21 21:30:31.067743 2023-02-21 21:30:31.052 28 ERROR keystone.server.flask.application   File "/var/lib/kolla/venv/lib/python3.9/site-packages/flask_restful/__init__.py", line 467, in wrapper
2023-02-21 21:30:31.067753 2023-02-21 21:30:31.052 28 ERROR keystone.server.flask.application     resp = resource(*args, **kwargs)
2023-02-21 21:30:31.067769 2023-02-21 21:30:31.052 28 ERROR keystone.server.flask.application   File "/var/lib/kolla/venv/lib/python3.9/site-packages/flask/views.py", line 107, in view
2023-02-21 21:30:31.067782 2023-02-21 21:30:31.052 28 ERROR keystone.server.flask.application     return current_app.ensure_sync(self.dispatch_request)(**kwargs)
2023-02-21 21:30:31.067791 2023-02-21 21:30:31.052 28 ERROR keystone.server.flask.application   File "/var/lib/kolla/venv/lib/python3.9/site-packages/flask_restful/__init__.py", line 582, in dispatch_request
2023-02-21 21:30:31.067801 2023-02-21 21:30:31.052 28 ERROR keystone.server.flask.application     resp = meth(*args, **kwargs)
2023-02-21 21:30:31.067810 2023-02-21 21:30:31.052 28 ERROR keystone.server.flask.application   File "/var/lib/kolla/venv/lib/python3.9/site-packages/keystone/api/projects.py", line 151, in get
2023-02-21 21:30:31.067820 2023-02-21 21:30:31.052 28 ERROR keystone.server.flask.application     return self._get_project(project_id)
2023-02-21 21:30:31.067829 2023-02-21 21:30:31.052 28 ERROR keystone.server.flask.application   File "/var/lib/kolla/venv/lib/python3.9/site-packages/keystone/api/projects.py", line 107, in _get_project
2023-02-21 21:30:31.067839 2023-02-21 21:30:31.052 28 ERROR keystone.server.flask.application     project = PROVIDERS.resource_api.get_project(project_id)
2023-02-21 21:30:31.067848 2023-02-21 21:30:31.052 28 ERROR keystone.server.flask.application   File "/var/lib/kolla/venv/lib/python3.9/site-packages/keystone/common/manager.py", line 115, in wrapped
2023-02-21 21:30:31.067868 2023-02-21 21:30:31.052 28 ERROR keystone.server.flask.application     __ret_val = __f(*args, **kwargs)
2023-02-21 21:30:31.067911 2023-02-21 21:30:31.052 28 ERROR keystone.server.flask.application   File "/var/lib/kolla/venv/lib/python3.9/site-packages/decorator.py", line 232, in fun
2023-02-21 21:30:31.067927 2023-02-21 21:30:31.052 28 ERROR keystone.server.flask.application     return caller(func, *(extras + args), **kw)
2023-02-21 21:30:31.067966 2023-02-21 21:30:31.052 28 ERROR keystone.server.flask.application   File "/var/lib/kolla/venv/lib/python3.9/site-packages/dogpile/cache/region.py", line 1577, in get_or_create_for_user_func
2023-02-21 21:30:31.067976 2023-02-21 21:30:31.052 28 ERROR keystone.server.flask.application     return self.get_or_create(
2023-02-21 21:30:31.067985 2023-02-21 21:30:31.052 28 ERROR keystone.server.flask.application   File "/var/lib/kolla/venv/lib/python3.9/site-packages/dogpile/cache/region.py", line 1042, in get_or_create
2023-02-21 21:30:31.067995 2023-02-21 21:30:31.052 28 ERROR keystone.server.flask.application     with Lock(
2023-02-21 21:30:31.068005 2023-02-21 21:30:31.052 28 ERROR keystone.server.flask.application   File "/var/lib/kolla/venv/lib/python3.9/site-packages/dogpile/lock.py", line 185, in __enter__
2023-02-21 21:30:31.068014 2023-02-21 21:30:31.052 28 ERROR keystone.server.flask.application     return self._enter()
2023-02-21 21:30:31.068046 2023-02-21 21:30:31.052 28 ERROR keystone.server.flask.application   File "/var/lib/kolla/venv/lib/python3.9/site-packages/dogpile/lock.py", line 94, in _enter
2023-02-21 21:30:31.068059 2023-02-21 21:30:31.052 28 ERROR keystone.server.flask.application     generated = self._enter_create(value, createdtime)
2023-02-21 21:30:31.068069 2023-02-21 21:30:31.052 28 ERROR keystone.server.flask.application   File "/var/lib/kolla/venv/lib/python3.9/site-packages/dogpile/lock.py", line 178, in _enter_create
2023-02-21 21:30:31.068078 2023-02-21 21:30:31.052 28 ERROR keystone.server.flask.application     return self.creator()
2023-02-21 21:30:31.068088 2023-02-21 21:30:31.052 28 ERROR keystone.server.flask.application   File "/var/lib/kolla/venv/lib/python3.9/site-packages/dogpile/cache/region.py", line 995, in gen_value
2023-02-21 21:30:31.068097 2023-02-21 21:30:31.052 28 ERROR keystone.server.flask.application     created_value = creator(
2023-02-21 21:30:31.068106 2023-02-21 21:30:31.052 28 ERROR keystone.server.flask.application   File "/var/lib/kolla/venv/lib/python3.9/site-packages/keystone/resource/core.py", line 903, in get_project
2023-02-21 21:30:31.068116 2023-02-21 21:30:31.052 28 ERROR keystone.server.flask.application     return self.driver.get_project(project_id)
2023-02-21 21:30:31.068125 2023-02-21 21:30:31.052 28 ERROR keystone.server.flask.application   File "/var/lib/kolla/venv/lib/python3.9/site-packages/keystone/resource/backends/sql.py", line 49, in get_project
2023-02-21 21:30:31.068135 2023-02-21 21:30:31.052 28 ERROR keystone.server.flask.application     return self._get_project(session, project_id).to_dict()
2023-02-21 21:30:31.068145 2023-02-21 21:30:31.052 28 ERROR keystone.server.flask.application   File "/var/lib/kolla/venv/lib/python3.9/site-packages/keystone/resource/backends/sql.py", line 44, in _get_project
2023-02-21 21:30:31.068154 2023-02-21 21:30:31.052 28 ERROR keystone.server.flask.application     raise exception.ProjectNotFound(project_id=project_id)
2023-02-21 21:30:31.068164 2023-02-21 21:30:31.052 28 ERROR keystone.server.flask.application keystone.exception.ProjectNotFound: Could not find project: service.
2023-02-21 21:30:31.068173 2023-02-21 21:30:31.052 28 ERROR keystone.server.flask.application \x1b[00m
2023-02-21 21:30:45.249164 2023-02-21 21:30:45.241 28 ERROR keystone.server.flask.application [None req-17e3f566-5190-4a85-92e2-073aac9bdae3 d0baa17cc04d45d091397605ff97a2c4 - - all default -] Could not find role: admin.: keystone.exception.RoleNotFound: Could not find role: admin.
2023-02-21 21:30:45.249209 2023-02-21 21:30:45.241 28 ERROR keystone.server.flask.application Traceback (most recent call last):
2023-02-21 21:30:45.249220 2023-02-21 21:30:45.241 28 ERROR keystone.server.flask.application   File "/var/lib/kolla/venv/lib/python3.9/site-packages/flask/app.py", line 1820, in full_dispatch_request
2023-02-21 21:30:45.249230 2023-02-21 21:30:45.241 28 ERROR keystone.server.flask.application     rv = self.dispatch_request()
2023-02-21 21:30:45.249240 2023-02-21 21:30:45.241 28 ERROR keystone.server.flask.application   File "/var/lib/kolla/venv/lib/python3.9/site-packages/flask/app.py", line 1796, in dispatch_request
2023-02-21 21:30:45.249250 2023-02-21 21:30:45.241 28 ERROR keystone.server.flask.application     return self.ensure_sync(self.view_functions[rule.endpoint])(**view_args)
2023-02-21 21:30:45.249259 2023-02-21 21:30:45.241 28 ERROR keystone.server.flask.application   File "/var/lib/kolla/venv/lib/python3.9/site-packages/flask_restful/__init__.py", line 467, in wrapper
2023-02-21 21:30:45.249269 2023-02-21 21:30:45.241 28 ERROR keystone.server.flask.application     resp = resource(*args, **kwargs)
2023-02-21 21:30:45.249279 2023-02-21 21:30:45.241 28 ERROR keystone.server.flask.application   File "/var/lib/kolla/venv/lib/python3.9/site-packages/flask/views.py", line 107, in view
2023-02-21 21:30:45.249288 2023-02-21 21:30:45.241 28 ERROR keystone.server.flask.application     return current_app.ensure_sync(self.dispatch_request)(**kwargs)
2023-02-21 21:30:45.249298 2023-02-21 21:30:45.241 28 ERROR keystone.server.flask.application   File "/var/lib/kolla/venv/lib/python3.9/site-packages/flask_restful/__init__.py", line 582, in dispatch_request
2023-02-21 21:30:45.249330 2023-02-21 21:30:45.241 28 ERROR keystone.server.flask.application     resp = meth(*args, **kwargs)
2023-02-21 21:30:45.249342 2023-02-21 21:30:45.241 28 ERROR keystone.server.flask.application   File "/var/lib/kolla/venv/lib/python3.9/site-packages/keystone/api/roles.py", line 50, in get
2023-02-21 21:30:45.249352 2023-02-21 21:30:45.241 28 ERROR keystone.server.flask.application     return self._get_role(role_id)
2023-02-21 21:30:45.249361 2023-02-21 21:30:45.241 28 ERROR keystone.server.flask.application   File "/var/lib/kolla/venv/lib/python3.9/site-packages/keystone/api/roles.py", line 70, in _get_role
2023-02-21 21:30:45.249371 2023-02-21 21:30:45.241 28 ERROR keystone.server.flask.application     ENFORCER.enforce_call(action='identity:get_role')
2023-02-21 21:30:45.249381 2023-02-21 21:30:45.241 28 ERROR keystone.server.flask.application   File "/var/lib/kolla/venv/lib/python3.9/site-packages/keystone/common/rbac_enforcer/enforcer.py", line 402, in enforce_call
2023-02-21 21:30:45.249391 2023-02-21 21:30:45.241 28 ERROR keystone.server.flask.application     policy_dict.update(cls._extract_member_target_data(
2023-02-21 21:30:45.249401 2023-02-21 21:30:45.241 28 ERROR keystone.server.flask.application   File "/var/lib/kolla/venv/lib/python3.9/site-packages/keystone/common/rbac_enforcer/enforcer.py", line 234, in _extract_member_target_data
2023-02-21 21:30:45.249411 2023-02-21 21:30:45.241 28 ERROR keystone.server.flask.application     member_name: func(flask.request.view_args[key])
2023-02-21 21:30:45.249420 2023-02-21 21:30:45.241 28 ERROR keystone.server.flask.application   File "/var/lib/kolla/venv/lib/python3.9/site-packages/keystone/common/manager.py", line 115, in wrapped
2023-02-21 21:30:45.249430 2023-02-21 21:30:45.241 28 ERROR keystone.server.flask.application     __ret_val = __f(*args, **kwargs)
2023-02-21 21:30:45.249440 2023-02-21 21:30:45.241 28 ERROR keystone.server.flask.application   File "/var/lib/kolla/venv/lib/python3.9/site-packages/decorator.py", line 232, in fun
2023-02-21 21:30:45.249449 2023-02-21 21:30:45.241 28 ERROR keystone.server.flask.application     return caller(func, *(extras + args), **kw)
2023-02-21 21:30:45.249459 2023-02-21 21:30:45.241 28 ERROR keystone.server.flask.application   File "/var/lib/kolla/venv/lib/python3.9/site-packages/dogpile/cache/region.py", line 1577, in get_or_create_for_user_func
2023-02-21 21:30:45.249469 2023-02-21 21:30:45.241 28 ERROR keystone.server.flask.application     return self.get_or_create(
2023-02-21 21:30:45.249478 2023-02-21 21:30:45.241 28 ERROR keystone.server.flask.application   File "/var/lib/kolla/venv/lib/python3.9/site-packages/dogpile/cache/region.py", line 1042, in get_or_create
2023-02-21 21:30:45.249488 2023-02-21 21:30:45.241 28 ERROR keystone.server.flask.application     with Lock(
2023-02-21 21:30:45.249498 2023-02-21 21:30:45.241 28 ERROR keystone.server.flask.application   File "/var/lib/kolla/venv/lib/python3.9/site-packages/dogpile/lock.py", line 185, in __enter__
2023-02-21 21:30:45.249507 2023-02-21 21:30:45.241 28 ERROR keystone.server.flask.application     return self._enter()
2023-02-21 21:30:45.249517 2023-02-21 21:30:45.241 28 ERROR keystone.server.flask.application   File "/var/lib/kolla/venv/lib/python3.9/site-packages/dogpile/lock.py", line 94, in _enter
2023-02-21 21:30:45.249722 2023-02-21 21:30:45.241 28 ERROR keystone.server.flask.application     generated = self._enter_create(value, createdtime)
2023-02-21 21:30:45.249743 2023-02-21 21:30:45.241 28 ERROR keystone.server.flask.application   File "/var/lib/kolla/venv/lib/python3.9/site-packages/dogpile/lock.py", line 178, in _enter_create
2023-02-21 21:30:45.249753 2023-02-21 21:30:45.241 28 ERROR keystone.server.flask.application     return self.creator()
2023-02-21 21:30:45.249763 2023-02-21 21:30:45.241 28 ERROR keystone.server.flask.application   File "/var/lib/kolla/venv/lib/python3.9/site-packages/dogpile/cache/region.py", line 995, in gen_value
2023-02-21 21:30:45.249799 2023-02-21 21:30:45.241 28 ERROR keystone.server.flask.application     created_value = creator(
2023-02-21 21:30:45.249811 2023-02-21 21:30:45.241 28 ERROR keystone.server.flask.application   File "/var/lib/kolla/venv/lib/python3.9/site-packages/keystone/assignment/core.py", line 1276, in get_role
2023-02-21 21:30:45.249821 2023-02-21 21:30:45.241 28 ERROR keystone.server.flask.application     return self.driver.get_role(role_id)
2023-02-21 21:30:45.249831 2023-02-21 21:30:45.241 28 ERROR keystone.server.flask.application   File "/var/lib/kolla/venv/lib/python3.9/site-packages/keystone/assignment/role_backends/sql.py", line 70, in get_role
2023-02-21 21:30:45.249840 2023-02-21 21:30:45.241 28 ERROR keystone.server.flask.application     return self._get_role(session, role_id).to_dict()
2023-02-21 21:30:45.249850 2023-02-21 21:30:45.241 28 ERROR keystone.server.flask.application   File "/var/lib/kolla/venv/lib/python3.9/site-packages/keystone/assignment/role_backends/sql.py", line 65, in _get_role
2023-02-21 21:30:45.249860 2023-02-21 21:30:45.241 28 ERROR keystone.server.flask.application     raise exception.RoleNotFound(role_id=role_id)
2023-02-21 21:30:45.249869 2023-02-21 21:30:45.241 28 ERROR keystone.server.flask.application keystone.exception.RoleNotFound: Could not find role: admin.
2023-02-21 21:30:45.249879 2023-02-21 21:30:45.241 28 ERROR keystone.server.flask.application \x1b[00m
2023-02-21 21:30:46.435266 2023-02-21 21:30:46.427 28 ERROR keystone.server.flask.application [None req-93ea7da8-4ad9-4b01-b0a2-3bb5f52960df d0baa17cc04d45d091397605ff97a2c4 - - all default -] Could not find user: ironic.: keystone.exception.UserNotFound: Could not find user: ironic.
2023-02-21 21:30:46.435344 2023-02-21 21:30:46.427 28 ERROR keystone.server.flask.application Traceback (most recent call last):
2023-02-21 21:30:46.435357 2023-02-21 21:30:46.427 28 ERROR keystone.server.flask.application   File "/var/lib/kolla/venv/lib/python3.9/site-packages/flask/app.py", line 1820, in full_dispatch_request
2023-02-21 21:30:46.435373 2023-02-21 21:30:46.427 28 ERROR keystone.server.flask.application     rv = self.dispatch_request()
2023-02-21 21:30:46.435388 2023-02-21 21:30:46.427 28 ERROR keystone.server.flask.application   File "/var/lib/kolla/venv/lib/python3.9/site-packages/flask/app.py", line 1796, in dispatch_request
2023-02-21 21:30:46.435400 2023-02-21 21:30:46.427 28 ERROR keystone.server.flask.application     return self.ensure_sync(self.view_functions[rule.endpoint])(**view_args)
2023-02-21 21:30:46.435411 2023-02-21 21:30:46.427 28 ERROR keystone.server.flask.application   File "/var/lib/kolla/venv/lib/python3.9/site-packages/flask_restful/__init__.py", line 467, in wrapper
2023-02-21 21:30:46.435422 2023-02-21 21:30:46.427 28 ERROR keystone.server.flask.application     resp = resource(*args, **kwargs)
2023-02-21 21:30:46.435434 2023-02-21 21:30:46.427 28 ERROR keystone.server.flask.application   File "/var/lib/kolla/venv/lib/python3.9/site-packages/flask/views.py", line 107, in view
2023-02-21 21:30:46.435445 2023-02-21 21:30:46.427 28 ERROR keystone.server.flask.application     return current_app.ensure_sync(self.dispatch_request)(**kwargs)
2023-02-21 21:30:46.435456 2023-02-21 21:30:46.427 28 ERROR keystone.server.flask.application   File "/var/lib/kolla/venv/lib/python3.9/site-packages/flask_restful/__init__.py", line 582, in dispatch_request
2023-02-21 21:30:46.435467 2023-02-21 21:30:46.427 28 ERROR keystone.server.flask.application     resp = meth(*args, **kwargs)
2023-02-21 21:30:46.435478 2023-02-21 21:30:46.427 28 ERROR keystone.server.flask.application   File "/var/lib/kolla/venv/lib/python3.9/site-packages/keystone/api/users.py", line 182, in get
2023-02-21 21:30:46.435489 2023-02-21 21:30:46.427 28 ERROR keystone.server.flask.application     return self._get_user(user_id)
2023-02-21 21:30:46.435500 2023-02-21 21:30:46.427 28 ERROR keystone.server.flask.application   File "/var/lib/kolla/venv/lib/python3.9/site-packages/keystone/api/users.py", line 194, in _get_user
2023-02-21 21:30:46.435546 2023-02-21 21:30:46.427 28 ERROR keystone.server.flask.application     ref = PROVIDERS.identity_api.get_user(user_id)
2023-02-21 21:30:46.435561 2023-02-21 21:30:46.427 28 ERROR keystone.server.flask.application   File "/var/lib/kolla/venv/lib/python3.9/site-packages/keystone/common/manager.py", line 115, in wrapped
2023-02-21 21:30:46.435573 2023-02-21 21:30:46.427 28 ERROR keystone.server.flask.application     __ret_val = __f(*args, **kwargs)
2023-02-21 21:30:46.435584 2023-02-21 21:30:46.427 28 ERROR keystone.server.flask.application   File "/var/lib/kolla/venv/lib/python3.9/site-packages/keystone/identity/core.py", line 414, in wrapper
2023-02-21 21:30:46.435595 2023-02-21 21:30:46.427 28 ERROR keystone.server.flask.application     return f(self, *args, **kwargs)
2023-02-21 21:30:46.435607 2023-02-21 21:30:46.427 28 ERROR keystone.server.flask.application   File "/var/lib/kolla/venv/lib/python3.9/site-packages/keystone/identity/core.py", line 424, in wrapper
2023-02-21 21:30:46.435649 2023-02-21 21:30:46.427 28 ERROR keystone.server.flask.application     return f(self, *args, **kwargs)
2023-02-21 21:30:46.435661 2023-02-21 21:30:46.427 28 ERROR keystone.server.flask.application   File "/var/lib/kolla/venv/lib/python3.9/site-packages/decorator.py", line 232, in fun
2023-02-21 21:30:46.435672 2023-02-21 21:30:46.427 28 ERROR keystone.server.flask.application     return caller(func, *(extras + args), **kw)
2023-02-21 21:30:46.435683 2023-02-21 21:30:46.427 28 ERROR keystone.server.flask.application   File "/var/lib/kolla/venv/lib/python3.9/site-packages/dogpile/cache/region.py", line 1577, in get_or_create_for_user_func
2023-02-21 21:30:46.435694 2023-02-21 21:30:46.427 28 ERROR keystone.server.flask.application     return self.get_or_create(
2023-02-21 21:30:46.435704 2023-02-21 21:30:46.427 28 ERROR keystone.server.flask.application   File "/var/lib/kolla/venv/lib/python3.9/site-packages/dogpile/cache/region.py", line 1042, in get_or_create
2023-02-21 21:30:46.435716 2023-02-21 21:30:46.427 28 ERROR keystone.server.flask.application     with Lock(
2023-02-21 21:30:46.435726 2023-02-21 21:30:46.427 28 ERROR keystone.server.flask.application   File "/var/lib/kolla/venv/lib/python3.9/site-packages/dogpile/lock.py", line 185, in __enter__
2023-02-21 21:30:46.435737 2023-02-21 21:30:46.427 28 ERROR keystone.server.flask.application     return self._enter()
2023-02-21 21:30:46.435748 2023-02-21 21:30:46.427 28 ERROR keystone.server.flask.application   File "/var/lib/kolla/venv/lib/python3.9/site-packages/dogpile/lock.py", line 94, in _enter
2023-02-21 21:30:46.435759 2023-02-21 21:30:46.427 28 ERROR keystone.server.flask.application     generated = self._enter_create(value, createdtime)
2023-02-21 21:30:46.435770 2023-02-21 21:30:46.427 28 ERROR keystone.server.flask.application   File "/var/lib/kolla/venv/lib/python3.9/site-packages/dogpile/lock.py", line 178, in _enter_create
2023-02-21 21:30:46.435781 2023-02-21 21:30:46.427 28 ERROR keystone.server.flask.application     return self.creator()
2023-02-21 21:30:46.435791 2023-02-21 21:30:46.427 28 ERROR keystone.server.flask.application   File "/var/lib/kolla/venv/lib/python3.9/site-packages/dogpile/cache/region.py", line 995, in gen_value
2023-02-21 21:30:46.435802 2023-02-21 21:30:46.427 28 ERROR keystone.server.flask.application     created_value = creator(
2023-02-21 21:30:46.435813 2023-02-21 21:30:46.427 28 ERROR keystone.server.flask.application   File "/var/lib/kolla/venv/lib/python3.9/site-packages/keystone/identity/core.py", line 1011, in get_user
2023-02-21 21:30:46.435824 2023-02-21 21:30:46.427 28 ERROR keystone.server.flask.application     ref = driver.get_user(entity_id)
2023-02-21 21:30:46.435835 2023-02-21 21:30:46.427 28 ERROR keystone.server.flask.application   File "/var/lib/kolla/venv/lib/python3.9/site-packages/keystone/identity/backends/sql.py", line 200, in get_user
2023-02-21 21:30:46.435846 2023-02-21 21:30:46.427 28 ERROR keystone.server.flask.application     self._get_user(session, user_id).to_dict())
2023-02-21 21:30:46.435948 2023-02-21 21:30:46.427 28 ERROR keystone.server.flask.application   File "/var/lib/kolla/venv/lib/python3.9/site-packages/keystone/identity/backends/sql.py", line 194, in _get_user
2023-02-21 21:30:46.435982 2023-02-21 21:30:46.427 28 ERROR keystone.server.flask.application     raise exception.UserNotFound(user_id=user_id)
2023-02-21 21:30:46.436009 2023-02-21 21:30:46.427 28 ERROR keystone.server.flask.application keystone.exception.UserNotFound: Could not find user: ironic.
2023-02-21 21:30:46.436034 2023-02-21 21:30:46.427 28 ERROR keystone.server.flask.application \x1b[00m
2023-02-21 21:30:47.496472 2023-02-21 21:30:47.475 27 ERROR keystone.server.flask.application [None req-9e9e2ffd-c610-4c96-9571-10a44c865bb7 d0baa17cc04d45d091397605ff97a2c4 - - all default -] Could not find project: service.: keystone.exception.ProjectNotFound: Could not find project: service.
2023-02-21 21:30:47.496543 2023-02-21 21:30:47.475 27 ERROR keystone.server.flask.application Traceback (most recent call last):
2023-02-21 21:30:47.496566 2023-02-21 21:30:47.475 27 ERROR keystone.server.flask.application   File "/var/lib/kolla/venv/lib/python3.9/site-packages/flask/app.py", line 1820, in full_dispatch_request
2023-02-21 21:30:47.496589 2023-02-21 21:30:47.475 27 ERROR keystone.server.flask.application     rv = self.dispatch_request()
2023-02-21 21:30:47.496639 2023-02-21 21:30:47.475 27 ERROR keystone.server.flask.application   File "/var/lib/kolla/venv/lib/python3.9/site-packages/flask/app.py", line 1796, in dispatch_request
2023-02-21 21:30:47.496667 2023-02-21 21:30:47.475 27 ERROR keystone.server.flask.application     return self.ensure_sync(self.view_functions[rule.endpoint])(**view_args)
2023-02-21 21:30:47.496687 2023-02-21 21:30:47.475 27 ERROR keystone.server.flask.application   File "/var/lib/kolla/venv/lib/python3.9/site-packages/flask_restful/__init__.py", line 467, in wrapper
2023-02-21 21:30:47.496707 2023-02-21 21:30:47.475 27 ERROR keystone.server.flask.application     resp = resource(*args, **kwargs)
2023-02-21 21:30:47.496729 2023-02-21 21:30:47.475 27 ERROR keystone.server.flask.application   File "/var/lib/kolla/venv/lib/python3.9/site-packages/flask/views.py", line 107, in view
2023-02-21 21:30:47.496752 2023-02-21 21:30:47.475 27 ERROR keystone.server.flask.application     return current_app.ensure_sync(self.dispatch_request)(**kwargs)
2023-02-21 21:30:47.496774 2023-02-21 21:30:47.475 27 ERROR keystone.server.flask.application   File "/var/lib/kolla/venv/lib/python3.9/site-packages/flask_restful/__init__.py", line 582, in dispatch_request
2023-02-21 21:30:47.496794 2023-02-21 21:30:47.475 27 ERROR keystone.server.flask.application     resp = meth(*args, **kwargs)
2023-02-21 21:30:47.496813 2023-02-21 21:30:47.475 27 ERROR keystone.server.flask.application   File "/var/lib/kolla/venv/lib/python3.9/site-packages/keystone/api/projects.py", line 151, in get
2023-02-21 21:30:47.496831 2023-02-21 21:30:47.475 27 ERROR keystone.server.flask.application     return self._get_project(project_id)
2023-02-21 21:30:47.496849 2023-02-21 21:30:47.475 27 ERROR keystone.server.flask.application   File "/var/lib/kolla/venv/lib/python3.9/site-packages/keystone/api/projects.py", line 107, in _get_project
2023-02-21 21:30:47.496872 2023-02-21 21:30:47.475 27 ERROR keystone.server.flask.application     project = PROVIDERS.resource_api.get_project(project_id)
2023-02-21 21:30:47.496924 2023-02-21 21:30:47.475 27 ERROR keystone.server.flask.application   File "/var/lib/kolla/venv/lib/python3.9/site-packages/keystone/common/manager.py", line 115, in wrapped
2023-02-21 21:30:47.496954 2023-02-21 21:30:47.475 27 ERROR keystone.server.flask.application     __ret_val = __f(*args, **kwargs)
2023-02-21 21:30:47.496976 2023-02-21 21:30:47.475 27 ERROR keystone.server.flask.application   File "/var/lib/kolla/venv/lib/python3.9/site-packages/decorator.py", line 232, in fun
2023-02-21 21:30:47.496999 2023-02-21 21:30:47.475 27 ERROR keystone.server.flask.application     return caller(func, *(extras + args), **kw)
2023-02-21 21:30:47.497065 2023-02-21 21:30:47.475 27 ERROR keystone.server.flask.application   File "/var/lib/kolla/venv/lib/python3.9/site-packages/dogpile/cache/region.py", line 1577, in get_or_create_for_user_func
2023-02-21 21:30:47.497092 2023-02-21 21:30:47.475 27 ERROR keystone.server.flask.application     return self.get_or_create(
2023-02-21 21:30:47.497114 2023-02-21 21:30:47.475 27 ERROR keystone.server.flask.application   File "/var/lib/kolla/venv/lib/python3.9/site-packages/dogpile/cache/region.py", line 1042, in get_or_create
2023-02-21 21:30:47.497143 2023-02-21 21:30:47.475 27 ERROR keystone.server.flask.application     with Lock(
2023-02-21 21:30:47.497165 2023-02-21 21:30:47.475 27 ERROR keystone.server.flask.application   File "/var/lib/kolla/venv/lib/python3.9/site-packages/dogpile/lock.py", line 185, in __enter__
2023-02-21 21:30:47.497186 2023-02-21 21:30:47.475 27 ERROR keystone.server.flask.application     return self._enter()
2023-02-21 21:30:47.497206 2023-02-21 21:30:47.475 27 ERROR keystone.server.flask.application   File "/var/lib/kolla/venv/lib/python3.9/site-packages/dogpile/lock.py", line 94, in _enter
2023-02-21 21:30:47.497228 2023-02-21 21:30:47.475 27 ERROR keystone.server.flask.application     generated = self._enter_create(value, createdtime)
2023-02-21 21:30:47.497251 2023-02-21 21:30:47.475 27 ERROR keystone.server.flask.application   File "/var/lib/kolla/venv/lib/python3.9/site-packages/dogpile/lock.py", line 178, in _enter_create
2023-02-21 21:30:47.497273 2023-02-21 21:30:47.475 27 ERROR keystone.server.flask.application     return self.creator()
2023-02-21 21:30:47.497294 2023-02-21 21:30:47.475 27 ERROR keystone.server.flask.application   File "/var/lib/kolla/venv/lib/python3.9/site-packages/dogpile/cache/region.py", line 995, in gen_value
2023-02-21 21:30:47.497316 2023-02-21 21:30:47.475 27 ERROR keystone.server.flask.application     created_value = creator(
2023-02-21 21:30:47.497339 2023-02-21 21:30:47.475 27 ERROR keystone.server.flask.application   File "/var/lib/kolla/venv/lib/python3.9/site-packages/keystone/resource/core.py", line 903, in get_project
2023-02-21 21:30:47.497361 2023-02-21 21:30:47.475 27 ERROR keystone.server.flask.application     return self.driver.get_project(project_id)
2023-02-21 21:30:47.497385 2023-02-21 21:30:47.475 27 ERROR keystone.server.flask.application   File "/var/lib/kolla/venv/lib/python3.9/site-packages/keystone/resource/backends/sql.py", line 49, in get_project
2023-02-21 21:30:47.497408 2023-02-21 21:30:47.475 27 ERROR keystone.server.flask.application     return self._get_project(session, project_id).to_dict()
2023-02-21 21:30:47.497429 2023-02-21 21:30:47.475 27 ERROR keystone.server.flask.application   File "/var/lib/kolla/venv/lib/python3.9/site-packages/keystone/resource/backends/sql.py", line 44, in _get_project
2023-02-21 21:30:47.497452 2023-02-21 21:30:47.475 27 ERROR keystone.server.flask.application     raise exception.ProjectNotFound(project_id=project_id)
2023-02-21 21:30:47.497473 2023-02-21 21:30:47.475 27 ERROR keystone.server.flask.application keystone.exception.ProjectNotFound: Could not find project: service.
2023-02-21 21:30:47.497496 2023-02-21 21:30:47.475 27 ERROR keystone.server.flask.application \x1b[00m
2023-02-21 21:30:56.580383 2023-02-21 21:30:56.572 26 ERROR keystone.server.flask.application [None req-f10de3de-03ba-4074-aed6-e2e51c6773fb d0baa17cc04d45d091397605ff97a2c4 - - all default -] Could not find role: admin.: keystone.exception.RoleNotFound: Could not find role: admin.
2023-02-21 21:30:56.580469 2023-02-21 21:30:56.572 26 ERROR keystone.server.flask.application Traceback (most recent call last):
2023-02-21 21:30:56.580483 2023-02-21 21:30:56.572 26 ERROR keystone.server.flask.application   File "/var/lib/kolla/venv/lib/python3.9/site-packages/flask/app.py", line 1820, in full_dispatch_request
2023-02-21 21:30:56.580495 2023-02-21 21:30:56.572 26 ERROR keystone.server.flask.application     rv = self.dispatch_request()
2023-02-21 21:30:56.580506 2023-02-21 21:30:56.572 26 ERROR keystone.server.flask.application   File "/var/lib/kolla/venv/lib/python3.9/site-packages/flask/app.py", line 1796, in dispatch_request
2023-02-21 21:30:56.580541 2023-02-21 21:30:56.572 26 ERROR keystone.server.flask.application     return self.ensure_sync(self.view_functions[rule.endpoint])(**view_args)
2023-02-21 21:30:56.580554 2023-02-21 21:30:56.572 26 ERROR keystone.server.flask.application   File "/var/lib/kolla/venv/lib/python3.9/site-packages/flask_restful/__init__.py", line 467, in wrapper
2023-02-21 21:30:56.580566 2023-02-21 21:30:56.572 26 ERROR keystone.server.flask.application     resp = resource(*args, **kwargs)
2023-02-21 21:30:56.580577 2023-02-21 21:30:56.572 26 ERROR keystone.server.flask.application   File "/var/lib/kolla/venv/lib/python3.9/site-packages/flask/views.py", line 107, in view
2023-02-21 21:30:56.580599 2023-02-21 21:30:56.572 26 ERROR keystone.server.flask.application     return current_app.ensure_sync(self.dispatch_request)(**kwargs)
2023-02-21 21:30:56.580638 2023-02-21 21:30:56.572 26 ERROR keystone.server.flask.application   File "/var/lib/kolla/venv/lib/python3.9/site-packages/flask_restful/__init__.py", line 582, in dispatch_request
2023-02-21 21:30:56.580651 2023-02-21 21:30:56.572 26 ERROR keystone.server.flask.application     resp = meth(*args, **kwargs)
2023-02-21 21:30:56.580662 2023-02-21 21:30:56.572 26 ERROR keystone.server.flask.application   File "/var/lib/kolla/venv/lib/python3.9/site-packages/keystone/api/roles.py", line 50, in get
2023-02-21 21:30:56.580672 2023-02-21 21:30:56.572 26 ERROR keystone.server.flask.application     return self._get_role(role_id)
2023-02-21 21:30:56.580683 2023-02-21 21:30:56.572 26 ERROR keystone.server.flask.application   File "/var/lib/kolla/venv/lib/python3.9/site-packages/keystone/api/roles.py", line 70, in _get_role
2023-02-21 21:30:56.580693 2023-02-21 21:30:56.572 26 ERROR keystone.server.flask.application     ENFORCER.enforce_call(action='identity:get_role')
2023-02-21 21:30:56.580721 2023-02-21 21:30:56.572 26 ERROR keystone.server.flask.application   File "/var/lib/kolla/venv/lib/python3.9/site-packages/keystone/common/rbac_enforcer/enforcer.py", line 402, in enforce_call
2023-02-21 21:30:56.580732 2023-02-21 21:30:56.572 26 ERROR keystone.server.flask.application     policy_dict.update(cls._extract_member_target_data(
2023-02-21 21:30:56.580750 2023-02-21 21:30:56.572 26 ERROR keystone.server.flask.application   File "/var/lib/kolla/venv/lib/python3.9/site-packages/keystone/common/rbac_enforcer/enforcer.py", line 234, in _extract_member_target_data
2023-02-21 21:30:56.580765 2023-02-21 21:30:56.572 26 ERROR keystone.server.flask.application     member_name: func(flask.request.view_args[key])
2023-02-21 21:30:56.580776 2023-02-21 21:30:56.572 26 ERROR keystone.server.flask.application   File "/var/lib/kolla/venv/lib/python3.9/site-packages/keystone/common/manager.py", line 115, in wrapped
2023-02-21 21:30:56.580787 2023-02-21 21:30:56.572 26 ERROR keystone.server.flask.application     __ret_val = __f(*args, **kwargs)
2023-02-21 21:30:56.580797 2023-02-21 21:30:56.572 26 ERROR keystone.server.flask.application   File "/var/lib/kolla/venv/lib/python3.9/site-packages/decorator.py", line 232, in fun
2023-02-21 21:30:56.580808 2023-02-21 21:30:56.572 26 ERROR keystone.server.flask.application     return caller(func, *(extras + args), **kw)
2023-02-21 21:30:56.580818 2023-02-21 21:30:56.572 26 ERROR keystone.server.flask.application   File "/var/lib/kolla/venv/lib/python3.9/site-packages/dogpile/cache/region.py", line 1577, in get_or_create_for_user_func
2023-02-21 21:30:56.580829 2023-02-21 21:30:56.572 26 ERROR keystone.server.flask.application     return self.get_or_create(
2023-02-21 21:30:56.580839 2023-02-21 21:30:56.572 26 ERROR keystone.server.flask.application   File "/var/lib/kolla/venv/lib/python3.9/site-packages/dogpile/cache/region.py", line 1042, in get_or_create
2023-02-21 21:30:56.580850 2023-02-21 21:30:56.572 26 ERROR keystone.server.flask.application     with Lock(
2023-02-21 21:30:56.580953 2023-02-21 21:30:56.572 26 ERROR keystone.server.flask.application   File "/var/lib/kolla/venv/lib/python3.9/site-packages/dogpile/lock.py", line 185, in __enter__
2023-02-21 21:30:56.580971 2023-02-21 21:30:56.572 26 ERROR keystone.server.flask.application     return self._enter()
2023-02-21 21:30:56.580982 2023-02-21 21:30:56.572 26 ERROR keystone.server.flask.application   File "/var/lib/kolla/venv/lib/python3.9/site-packages/dogpile/lock.py", line 94, in _enter
2023-02-21 21:30:56.580993 2023-02-21 21:30:56.572 26 ERROR keystone.server.flask.application     generated = self._enter_create(value, createdtime)
2023-02-21 21:30:56.581004 2023-02-21 21:30:56.572 26 ERROR keystone.server.flask.application   File "/var/lib/kolla/venv/lib/python3.9/site-packages/dogpile/lock.py", line 178, in _enter_create
2023-02-21 21:30:56.581016 2023-02-21 21:30:56.572 26 ERROR keystone.server.flask.application     return self.creator()
2023-02-21 21:30:56.581026 2023-02-21 21:30:56.572 26 ERROR keystone.server.flask.application   File "/var/lib/kolla/venv/lib/python3.9/site-packages/dogpile/cache/region.py", line 995, in gen_value
2023-02-21 21:30:56.581038 2023-02-21 21:30:56.572 26 ERROR keystone.server.flask.application     created_value = creator(
2023-02-21 21:30:56.581048 2023-02-21 21:30:56.572 26 ERROR keystone.server.flask.application   File "/var/lib/kolla/venv/lib/python3.9/site-packages/keystone/assignment/core.py", line 1276, in get_role
2023-02-21 21:30:56.581060 2023-02-21 21:30:56.572 26 ERROR keystone.server.flask.application     return self.driver.get_role(role_id)
2023-02-21 21:30:56.581071 2023-02-21 21:30:56.572 26 ERROR keystone.server.flask.application   File "/var/lib/kolla/venv/lib/python3.9/site-packages/keystone/assignment/role_backends/sql.py", line 70, in get_role
2023-02-21 21:30:56.581082 2023-02-21 21:30:56.572 26 ERROR keystone.server.flask.application     return self._get_role(session, role_id).to_dict()
2023-02-21 21:30:56.581093 2023-02-21 21:30:56.572 26 ERROR keystone.server.flask.application   File "/var/lib/kolla/venv/lib/python3.9/site-packages/keystone/assignment/role_backends/sql.py", line 65, in _get_role
2023-02-21 21:30:56.581105 2023-02-21 21:30:56.572 26 ERROR keystone.server.flask.application     raise exception.RoleNotFound(role_id=role_id)
2023-02-21 21:30:56.581116 2023-02-21 21:30:56.572 26 ERROR keystone.server.flask.application keystone.exception.RoleNotFound: Could not find role: admin.
2023-02-21 21:30:56.581128 2023-02-21 21:30:56.572 26 ERROR keystone.server.flask.application \x1b[00m
2023-02-21 21:30:57.722397 2023-02-21 21:30:57.715 26 ERROR keystone.server.flask.application [None req-096cb393-dee5-473e-901f-9b7f5e0512f3 d0baa17cc04d45d091397605ff97a2c4 - - all default -] Could not find user: ironic-inspector.: keystone.exception.UserNotFound: Could not find user: ironic-inspector.
2023-02-21 21:30:57.722439 2023-02-21 21:30:57.715 26 ERROR keystone.server.flask.application Traceback (most recent call last):
2023-02-21 21:30:57.722451 2023-02-21 21:30:57.715 26 ERROR keystone.server.flask.application   File "/var/lib/kolla/venv/lib/python3.9/site-packages/flask/app.py", line 1820, in full_dispatch_request
2023-02-21 21:30:57.722461 2023-02-21 21:30:57.715 26 ERROR keystone.server.flask.application     rv = self.dispatch_request()
2023-02-21 21:30:57.722471 2023-02-21 21:30:57.715 26 ERROR keystone.server.flask.application   File "/var/lib/kolla/venv/lib/python3.9/site-packages/flask/app.py", line 1796, in dispatch_request
2023-02-21 21:30:57.722499 2023-02-21 21:30:57.715 26 ERROR keystone.server.flask.application     return self.ensure_sync(self.view_functions[rule.endpoint])(**view_args)
2023-02-21 21:30:57.722508 2023-02-21 21:30:57.715 26 ERROR keystone.server.flask.application   File "/var/lib/kolla/venv/lib/python3.9/site-packages/flask_restful/__init__.py", line 467, in wrapper
2023-02-21 21:30:57.722518 2023-02-21 21:30:57.715 26 ERROR keystone.server.flask.application     resp = resource(*args, **kwargs)
2023-02-21 21:30:57.722528 2023-02-21 21:30:57.715 26 ERROR keystone.server.flask.application   File "/var/lib/kolla/venv/lib/python3.9/site-packages/flask/views.py", line 107, in view
2023-02-21 21:30:57.722564 2023-02-21 21:30:57.715 26 ERROR keystone.server.flask.application     return current_app.ensure_sync(self.dispatch_request)(**kwargs)
2023-02-21 21:30:57.722576 2023-02-21 21:30:57.715 26 ERROR keystone.server.flask.application   File "/var/lib/kolla/venv/lib/python3.9/site-packages/flask_restful/__init__.py", line 582, in dispatch_request
2023-02-21 21:30:57.722587 2023-02-21 21:30:57.715 26 ERROR keystone.server.flask.application     resp = meth(*args, **kwargs)
2023-02-21 21:30:57.722596 2023-02-21 21:30:57.715 26 ERROR keystone.server.flask.application   File "/var/lib/kolla/venv/lib/python3.9/site-packages/keystone/api/users.py", line 182, in get
2023-02-21 21:30:57.722622 2023-02-21 21:30:57.715 26 ERROR keystone.server.flask.application     return self._get_user(user_id)
2023-02-21 21:30:57.722634 2023-02-21 21:30:57.715 26 ERROR keystone.server.flask.application   File "/var/lib/kolla/venv/lib/python3.9/site-packages/keystone/api/users.py", line 194, in _get_user
2023-02-21 21:30:57.722645 2023-02-21 21:30:57.715 26 ERROR keystone.server.flask.application     ref = PROVIDERS.identity_api.get_user(user_id)
2023-02-21 21:30:57.722654 2023-02-21 21:30:57.715 26 ERROR keystone.server.flask.application   File "/var/lib/kolla/venv/lib/python3.9/site-packages/keystone/common/manager.py", line 115, in wrapped
2023-02-21 21:30:57.722664 2023-02-21 21:30:57.715 26 ERROR keystone.server.flask.application     __ret_val = __f(*args, **kwargs)
2023-02-21 21:30:57.722674 2023-02-21 21:30:57.715 26 ERROR keystone.server.flask.application   File "/var/lib/kolla/venv/lib/python3.9/site-packages/keystone/identity/core.py", line 414, in wrapper
2023-02-21 21:30:57.722684 2023-02-21 21:30:57.715 26 ERROR keystone.server.flask.application     return f(self, *args, **kwargs)
2023-02-21 21:30:57.722693 2023-02-21 21:30:57.715 26 ERROR keystone.server.flask.application   File "/var/lib/kolla/venv/lib/python3.9/site-packages/keystone/identity/core.py", line 424, in wrapper
2023-02-21 21:30:57.722703 2023-02-21 21:30:57.715 26 ERROR keystone.server.flask.application     return f(self, *args, **kwargs)
2023-02-21 21:30:57.722712 2023-02-21 21:30:57.715 26 ERROR keystone.server.flask.application   File "/var/lib/kolla/venv/lib/python3.9/site-packages/decorator.py", line 232, in fun
2023-02-21 21:30:57.722722 2023-02-21 21:30:57.715 26 ERROR keystone.server.flask.application     return caller(func, *(extras + args), **kw)
2023-02-21 21:30:57.722732 2023-02-21 21:30:57.715 26 ERROR keystone.server.flask.application   File "/var/lib/kolla/venv/lib/python3.9/site-packages/dogpile/cache/region.py", line 1577, in get_or_create_for_user_func
2023-02-21 21:30:57.722742 2023-02-21 21:30:57.715 26 ERROR keystone.server.flask.application     return self.get_or_create(
2023-02-21 21:30:57.722751 2023-02-21 21:30:57.715 26 ERROR keystone.server.flask.application   File "/var/lib/kolla/venv/lib/python3.9/site-packages/dogpile/cache/region.py", line 1042, in get_or_create
2023-02-21 21:30:57.722762 2023-02-21 21:30:57.715 26 ERROR keystone.server.flask.application     with Lock(
2023-02-21 21:30:57.722771 2023-02-21 21:30:57.715 26 ERROR keystone.server.flask.application   File "/var/lib/kolla/venv/lib/python3.9/site-packages/dogpile/lock.py", line 185, in __enter__
2023-02-21 21:30:57.722781 2023-02-21 21:30:57.715 26 ERROR keystone.server.flask.application     return self._enter()
2023-02-21 21:30:57.722790 2023-02-21 21:30:57.715 26 ERROR keystone.server.flask.application   File "/var/lib/kolla/venv/lib/python3.9/site-packages/dogpile/lock.py", line 94, in _enter
2023-02-21 21:30:57.722800 2023-02-21 21:30:57.715 26 ERROR keystone.server.flask.application     generated = self._enter_create(value, createdtime)
2023-02-21 21:30:57.722810 2023-02-21 21:30:57.715 26 ERROR keystone.server.flask.application   File "/var/lib/kolla/venv/lib/python3.9/site-packages/dogpile/lock.py", line 178, in _enter_create
2023-02-21 21:30:57.722840 2023-02-21 21:30:57.715 26 ERROR keystone.server.flask.application     return self.creator()
2023-02-21 21:30:57.722852 2023-02-21 21:30:57.715 26 ERROR keystone.server.flask.application   File "/var/lib/kolla/venv/lib/python3.9/site-packages/dogpile/cache/region.py", line 995, in gen_value
2023-02-21 21:30:57.722862 2023-02-21 21:30:57.715 26 ERROR keystone.server.flask.application     created_value = creator(
2023-02-21 21:30:57.722872 2023-02-21 21:30:57.715 26 ERROR keystone.server.flask.application   File "/var/lib/kolla/venv/lib/python3.9/site-packages/keystone/identity/core.py", line 1011, in get_user
2023-02-21 21:30:57.722904 2023-02-21 21:30:57.715 26 ERROR keystone.server.flask.application     ref = driver.get_user(entity_id)
2023-02-21 21:30:57.722919 2023-02-21 21:30:57.715 26 ERROR keystone.server.flask.application   File "/var/lib/kolla/venv/lib/python3.9/site-packages/keystone/identity/backends/sql.py", line 200, in get_user
2023-02-21 21:30:57.722930 2023-02-21 21:30:57.715 26 ERROR keystone.server.flask.application     self._get_user(session, user_id).to_dict())
2023-02-21 21:30:57.722939 2023-02-21 21:30:57.715 26 ERROR keystone.server.flask.application   File "/var/lib/kolla/venv/lib/python3.9/site-packages/keystone/identity/backends/sql.py", line 194, in _get_user
2023-02-21 21:30:57.722952 2023-02-21 21:30:57.715 26 ERROR keystone.server.flask.application     raise exception.UserNotFound(user_id=user_id)
2023-02-21 21:30:57.722963 2023-02-21 21:30:57.715 26 ERROR keystone.server.flask.application keystone.exception.UserNotFound: Could not find user: ironic-inspector.
2023-02-21 21:30:57.722973 2023-02-21 21:30:57.715 26 ERROR keystone.server.flask.application \x1b[00m
2023-02-21 21:30:58.744652 2023-02-21 21:30:58.741 28 ERROR keystone.server.flask.application [None req-84961d51-01f8-4142-a97d-0925faa0e6ac d0baa17cc04d45d091397605ff97a2c4 - - all default -] Could not find project: service.: keystone.exception.ProjectNotFound: Could not find project: service.
2023-02-21 21:30:58.744706 2023-02-21 21:30:58.741 28 ERROR keystone.server.flask.application Traceback (most recent call last):
2023-02-21 21:30:58.744731 2023-02-21 21:30:58.741 28 ERROR keystone.server.flask.application   File "/var/lib/kolla/venv/lib/python3.9/site-packages/flask/app.py", line 1820, in full_dispatch_request
2023-02-21 21:30:58.744765 2023-02-21 21:30:58.741 28 ERROR keystone.server.flask.application     rv = self.dispatch_request()
2023-02-21 21:30:58.744785 2023-02-21 21:30:58.741 28 ERROR keystone.server.flask.application   File "/var/lib/kolla/venv/lib/python3.9/site-packages/flask/app.py", line 1796, in dispatch_request
2023-02-21 21:30:58.744806 2023-02-21 21:30:58.741 28 ERROR keystone.server.flask.application     return self.ensure_sync(self.view_functions[rule.endpoint])(**view_args)
2023-02-21 21:30:58.744825 2023-02-21 21:30:58.741 28 ERROR keystone.server.flask.application   File "/var/lib/kolla/venv/lib/python3.9/site-packages/flask_restful/__init__.py", line 467, in wrapper
2023-02-21 21:30:58.744847 2023-02-21 21:30:58.741 28 ERROR keystone.server.flask.application     resp = resource(*args, **kwargs)
2023-02-21 21:30:58.744873 2023-02-21 21:30:58.741 28 ERROR keystone.server.flask.application   File "/var/lib/kolla/venv/lib/python3.9/site-packages/flask/views.py", line 107, in view
2023-02-21 21:30:58.744945 2023-02-21 21:30:58.741 28 ERROR keystone.server.flask.application     return current_app.ensure_sync(self.dispatch_request)(**kwargs)
2023-02-21 21:30:58.744966 2023-02-21 21:30:58.741 28 ERROR keystone.server.flask.application   File "/var/lib/kolla/venv/lib/python3.9/site-packages/flask_restful/__init__.py", line 582, in dispatch_request
2023-02-21 21:30:58.744976 2023-02-21 21:30:58.741 28 ERROR keystone.server.flask.application     resp = meth(*args, **kwargs)
2023-02-21 21:30:58.744986 2023-02-21 21:30:58.741 28 ERROR keystone.server.flask.application   File "/var/lib/kolla/venv/lib/python3.9/site-packages/keystone/api/projects.py", line 151, in get
2023-02-21 21:30:58.745024 2023-02-21 21:30:58.741 28 ERROR keystone.server.flask.application     return self._get_project(project_id)
2023-02-21 21:30:58.745037 2023-02-21 21:30:58.741 28 ERROR keystone.server.flask.application   File "/var/lib/kolla/venv/lib/python3.9/site-packages/keystone/api/projects.py", line 107, in _get_project
2023-02-21 21:30:58.745047 2023-02-21 21:30:58.741 28 ERROR keystone.server.flask.application     project = PROVIDERS.resource_api.get_project(project_id)
2023-02-21 21:30:58.745057 2023-02-21 21:30:58.741 28 ERROR keystone.server.flask.application   File "/var/lib/kolla/venv/lib/python3.9/site-packages/keystone/common/manager.py", line 115, in wrapped
2023-02-21 21:30:58.745066 2023-02-21 21:30:58.741 28 ERROR keystone.server.flask.application     __ret_val = __f(*args, **kwargs)
2023-02-21 21:30:58.745076 2023-02-21 21:30:58.741 28 ERROR keystone.server.flask.application   File "/var/lib/kolla/venv/lib/python3.9/site-packages/decorator.py", line 232, in fun
2023-02-21 21:30:58.745085 2023-02-21 21:30:58.741 28 ERROR keystone.server.flask.application     return caller(func, *(extras + args), **kw)
2023-02-21 21:30:58.745095 2023-02-21 21:30:58.741 28 ERROR keystone.server.flask.application   File "/var/lib/kolla/venv/lib/python3.9/site-packages/dogpile/cache/region.py", line 1577, in get_or_create_for_user_func
2023-02-21 21:30:58.745105 2023-02-21 21:30:58.741 28 ERROR keystone.server.flask.application     return self.get_or_create(
2023-02-21 21:30:58.745114 2023-02-21 21:30:58.741 28 ERROR keystone.server.flask.application   File "/var/lib/kolla/venv/lib/python3.9/site-packages/dogpile/cache/region.py", line 1042, in get_or_create
2023-02-21 21:30:58.745124 2023-02-21 21:30:58.741 28 ERROR keystone.server.flask.application     with Lock(
2023-02-21 21:30:58.745133 2023-02-21 21:30:58.741 28 ERROR keystone.server.flask.application   File "/var/lib/kolla/venv/lib/python3.9/site-packages/dogpile/lock.py", line 185, in __enter__
2023-02-21 21:30:58.745143 2023-02-21 21:30:58.741 28 ERROR keystone.server.flask.application     return self._enter()
2023-02-21 21:30:58.745152 2023-02-21 21:30:58.741 28 ERROR keystone.server.flask.application   File "/var/lib/kolla/venv/lib/python3.9/site-packages/dogpile/lock.py", line 94, in _enter
2023-02-21 21:30:58.745161 2023-02-21 21:30:58.741 28 ERROR keystone.server.flask.application     generated = self._enter_create(value, createdtime)
2023-02-21 21:30:58.745171 2023-02-21 21:30:58.741 28 ERROR keystone.server.flask.application   File "/var/lib/kolla/venv/lib/python3.9/site-packages/dogpile/lock.py", line 178, in _enter_create
2023-02-21 21:30:58.745180 2023-02-21 21:30:58.741 28 ERROR keystone.server.flask.application     return self.creator()
2023-02-21 21:30:58.745190 2023-02-21 21:30:58.741 28 ERROR keystone.server.flask.application   File "/var/lib/kolla/venv/lib/python3.9/site-packages/dogpile/cache/region.py", line 995, in gen_value
2023-02-21 21:30:58.745199 2023-02-21 21:30:58.741 28 ERROR keystone.server.flask.application     created_value = creator(
2023-02-21 21:30:58.745209 2023-02-21 21:30:58.741 28 ERROR keystone.server.flask.application   File "/var/lib/kolla/venv/lib/python3.9/site-packages/keystone/resource/core.py", line 903, in get_project
2023-02-21 21:30:58.745218 2023-02-21 21:30:58.741 28 ERROR keystone.server.flask.application     return self.driver.get_project(project_id)
2023-02-21 21:30:58.745228 2023-02-21 21:30:58.741 28 ERROR keystone.server.flask.application   File "/var/lib/kolla/venv/lib/python3.9/site-packages/keystone/resource/backends/sql.py", line 49, in get_project
2023-02-21 21:30:58.745398 2023-02-21 21:30:58.741 28 ERROR keystone.server.flask.application     return self._get_project(session, project_id).to_dict()
2023-02-21 21:30:58.745418 2023-02-21 21:30:58.741 28 ERROR keystone.server.flask.application   File "/var/lib/kolla/venv/lib/python3.9/site-packages/keystone/resource/backends/sql.py", line 44, in _get_project
2023-02-21 21:30:58.745429 2023-02-21 21:30:58.741 28 ERROR keystone.server.flask.application     raise exception.ProjectNotFound(project_id=project_id)
2023-02-21 21:30:58.745463 2023-02-21 21:30:58.741 28 ERROR keystone.server.flask.application keystone.exception.ProjectNotFound: Could not find project: service.
2023-02-21 21:30:58.745476 2023-02-21 21:30:58.741 28 ERROR keystone.server.flask.application \x1b[00m
2023-02-21 21:33:42.867242 2023-02-21 21:33:42.864 28 ERROR keystone.server.flask.application [None req-4875184c-7038-4774-986b-779fc8da2198 d0baa17cc04d45d091397605ff97a2c4 - - all default -] Could not find project: service.: keystone.exception.ProjectNotFound: Could not find project: service.
2023-02-21 21:33:42.867293 2023-02-21 21:33:42.864 28 ERROR keystone.server.flask.application Traceback (most recent call last):
2023-02-21 21:33:42.867323 2023-02-21 21:33:42.864 28 ERROR keystone.server.flask.application   File "/var/lib/kolla/venv/lib/python3.9/site-packages/flask/app.py", line 1820, in full_dispatch_request
2023-02-21 21:33:42.867333 2023-02-21 21:33:42.864 28 ERROR keystone.server.flask.application     rv = self.dispatch_request()
2023-02-21 21:33:42.867343 2023-02-21 21:33:42.864 28 ERROR keystone.server.flask.application   File "/var/lib/kolla/venv/lib/python3.9/site-packages/flask/app.py", line 1796, in dispatch_request
2023-02-21 21:33:42.867353 2023-02-21 21:33:42.864 28 ERROR keystone.server.flask.application     return self.ensure_sync(self.view_functions[rule.endpoint])(**view_args)
2023-02-21 21:33:42.867363 2023-02-21 21:33:42.864 28 ERROR keystone.server.flask.application   File "/var/lib/kolla/venv/lib/python3.9/site-packages/flask_restful/__init__.py", line 467, in wrapper
2023-02-21 21:33:42.867372 2023-02-21 21:33:42.864 28 ERROR keystone.server.flask.application     resp = resource(*args, **kwargs)
2023-02-21 21:33:42.867396 2023-02-21 21:33:42.864 28 ERROR keystone.server.flask.application   File "/var/lib/kolla/venv/lib/python3.9/site-packages/flask/views.py", line 107, in view
2023-02-21 21:33:42.867406 2023-02-21 21:33:42.864 28 ERROR keystone.server.flask.application     return current_app.ensure_sync(self.dispatch_request)(**kwargs)
2023-02-21 21:33:42.867415 2023-02-21 21:33:42.864 28 ERROR keystone.server.flask.application   File "/var/lib/kolla/venv/lib/python3.9/site-packages/flask_restful/__init__.py", line 582, in dispatch_request
2023-02-21 21:33:42.867425 2023-02-21 21:33:42.864 28 ERROR keystone.server.flask.application     resp = meth(*args, **kwargs)
2023-02-21 21:33:42.867434 2023-02-21 21:33:42.864 28 ERROR keystone.server.flask.application   File "/var/lib/kolla/venv/lib/python3.9/site-packages/keystone/api/projects.py", line 151, in get
2023-02-21 21:33:42.867444 2023-02-21 21:33:42.864 28 ERROR keystone.server.flask.application     return self._get_project(project_id)
2023-02-21 21:33:42.867454 2023-02-21 21:33:42.864 28 ERROR keystone.server.flask.application   File "/var/lib/kolla/venv/lib/python3.9/site-packages/keystone/api/projects.py", line 107, in _get_project
2023-02-21 21:33:42.867463 2023-02-21 21:33:42.864 28 ERROR keystone.server.flask.application     project = PROVIDERS.resource_api.get_project(project_id)
2023-02-21 21:33:42.867473 2023-02-21 21:33:42.864 28 ERROR keystone.server.flask.application   File "/var/lib/kolla/venv/lib/python3.9/site-packages/keystone/common/manager.py", line 115, in wrapped
2023-02-21 21:33:42.867482 2023-02-21 21:33:42.864 28 ERROR keystone.server.flask.application     __ret_val = __f(*args, **kwargs)
2023-02-21 21:33:42.867492 2023-02-21 21:33:42.864 28 ERROR keystone.server.flask.application   File "/var/lib/kolla/venv/lib/python3.9/site-packages/decorator.py", line 232, in fun
2023-02-21 21:33:42.867501 2023-02-21 21:33:42.864 28 ERROR keystone.server.flask.application     return caller(func, *(extras + args), **kw)
2023-02-21 21:33:42.867511 2023-02-21 21:33:42.864 28 ERROR keystone.server.flask.application   File "/var/lib/kolla/venv/lib/python3.9/site-packages/dogpile/cache/region.py", line 1577, in get_or_create_for_user_func
2023-02-21 21:33:42.867521 2023-02-21 21:33:42.864 28 ERROR keystone.server.flask.application     return self.get_or_create(
2023-02-21 21:33:42.867546 2023-02-21 21:33:42.864 28 ERROR keystone.server.flask.application   File "/var/lib/kolla/venv/lib/python3.9/site-packages/dogpile/cache/region.py", line 1042, in get_or_create
2023-02-21 21:33:42.867558 2023-02-21 21:33:42.864 28 ERROR keystone.server.flask.application     with Lock(
2023-02-21 21:33:42.867568 2023-02-21 21:33:42.864 28 ERROR keystone.server.flask.application   File "/var/lib/kolla/venv/lib/python3.9/site-packages/dogpile/lock.py", line 185, in __enter__
2023-02-21 21:33:42.867578 2023-02-21 21:33:42.864 28 ERROR keystone.server.flask.application     return self._enter()
2023-02-21 21:33:42.867602 2023-02-21 21:33:42.864 28 ERROR keystone.server.flask.application   File "/var/lib/kolla/venv/lib/python3.9/site-packages/dogpile/lock.py", line 94, in _enter
2023-02-21 21:33:42.867616 2023-02-21 21:33:42.864 28 ERROR keystone.server.flask.application     generated = self._enter_create(value, createdtime)
2023-02-21 21:33:42.867625 2023-02-21 21:33:42.864 28 ERROR keystone.server.flask.application   File "/var/lib/kolla/venv/lib/python3.9/site-packages/dogpile/lock.py", line 178, in _enter_create
2023-02-21 21:33:42.867635 2023-02-21 21:33:42.864 28 ERROR keystone.server.flask.application     return self.creator()
2023-02-21 21:33:42.867644 2023-02-21 21:33:42.864 28 ERROR keystone.server.flask.application   File "/var/lib/kolla/venv/lib/python3.9/site-packages/dogpile/cache/region.py", line 995, in gen_value
2023-02-21 21:33:42.867654 2023-02-21 21:33:42.864 28 ERROR keystone.server.flask.application     created_value = creator(
2023-02-21 21:33:42.867663 2023-02-21 21:33:42.864 28 ERROR keystone.server.flask.application   File "/var/lib/kolla/venv/lib/python3.9/site-packages/keystone/resource/core.py", line 903, in get_project
2023-02-21 21:33:42.867673 2023-02-21 21:33:42.864 28 ERROR keystone.server.flask.application     return self.driver.get_project(project_id)
2023-02-21 21:33:42.867682 2023-02-21 21:33:42.864 28 ERROR keystone.server.flask.application   File "/var/lib/kolla/venv/lib/python3.9/site-packages/keystone/resource/backends/sql.py", line 49, in get_project
2023-02-21 21:33:42.867692 2023-02-21 21:33:42.864 28 ERROR keystone.server.flask.application     return self._get_project(session, project_id).to_dict()
2023-02-21 21:33:42.867701 2023-02-21 21:33:42.864 28 ERROR keystone.server.flask.application   File "/var/lib/kolla/venv/lib/python3.9/site-packages/keystone/resource/backends/sql.py", line 44, in _get_project
2023-02-21 21:33:42.867711 2023-02-21 21:33:42.864 28 ERROR keystone.server.flask.application     raise exception.ProjectNotFound(project_id=project_id)
2023-02-21 21:33:42.867720 2023-02-21 21:33:42.864 28 ERROR keystone.server.flask.application keystone.exception.ProjectNotFound: Could not find project: service.
2023-02-21 21:33:42.867729 2023-02-21 21:33:42.864 28 ERROR keystone.server.flask.application \x1b[00m
2023-02-21 21:33:56.874789 2023-02-21 21:33:56.871 26 ERROR keystone.server.flask.application [None req-a81e5f55-f4bc-46b7-a4e3-5013848e248f d0baa17cc04d45d091397605ff97a2c4 - - all default -] Could not find role: admin.: keystone.exception.RoleNotFound: Could not find role: admin.
2023-02-21 21:33:56.874865 2023-02-21 21:33:56.871 26 ERROR keystone.server.flask.application Traceback (most recent call last):
2023-02-21 21:33:56.874876 2023-02-21 21:33:56.871 26 ERROR keystone.server.flask.application   File "/var/lib/kolla/venv/lib/python3.9/site-packages/flask/app.py", line 1820, in full_dispatch_request
2023-02-21 21:33:56.874933 2023-02-21 21:33:56.871 26 ERROR keystone.server.flask.application     rv = self.dispatch_request()
2023-02-21 21:33:56.874944 2023-02-21 21:33:56.871 26 ERROR keystone.server.flask.application   File "/var/lib/kolla/venv/lib/python3.9/site-packages/flask/app.py", line 1796, in dispatch_request
2023-02-21 21:33:56.874955 2023-02-21 21:33:56.871 26 ERROR keystone.server.flask.application     return self.ensure_sync(self.view_functions[rule.endpoint])(**view_args)
2023-02-21 21:33:56.874965 2023-02-21 21:33:56.871 26 ERROR keystone.server.flask.application   File "/var/lib/kolla/venv/lib/python3.9/site-packages/flask_restful/__init__.py", line 467, in wrapper
2023-02-21 21:33:56.875000 2023-02-21 21:33:56.871 26 ERROR keystone.server.flask.application     resp = resource(*args, **kwargs)
2023-02-21 21:33:56.875011 2023-02-21 21:33:56.871 26 ERROR keystone.server.flask.application   File "/var/lib/kolla/venv/lib/python3.9/site-packages/flask/views.py", line 107, in view
2023-02-21 21:33:56.875021 2023-02-21 21:33:56.871 26 ERROR keystone.server.flask.application     return current_app.ensure_sync(self.dispatch_request)(**kwargs)
2023-02-21 21:33:56.875031 2023-02-21 21:33:56.871 26 ERROR keystone.server.flask.application   File "/var/lib/kolla/venv/lib/python3.9/site-packages/flask_restful/__init__.py", line 582, in dispatch_request
2023-02-21 21:33:56.875041 2023-02-21 21:33:56.871 26 ERROR keystone.server.flask.application     resp = meth(*args, **kwargs)
2023-02-21 21:33:56.875050 2023-02-21 21:33:56.871 26 ERROR keystone.server.flask.application   File "/var/lib/kolla/venv/lib/python3.9/site-packages/keystone/api/roles.py", line 50, in get
2023-02-21 21:33:56.875060 2023-02-21 21:33:56.871 26 ERROR keystone.server.flask.application     return self._get_role(role_id)
2023-02-21 21:33:56.875070 2023-02-21 21:33:56.871 26 ERROR keystone.server.flask.application   File "/var/lib/kolla/venv/lib/python3.9/site-packages/keystone/api/roles.py", line 70, in _get_role
2023-02-21 21:33:56.875079 2023-02-21 21:33:56.871 26 ERROR keystone.server.flask.application     ENFORCER.enforce_call(action='identity:get_role')
2023-02-21 21:33:56.875105 2023-02-21 21:33:56.871 26 ERROR keystone.server.flask.application   File "/var/lib/kolla/venv/lib/python3.9/site-packages/keystone/common/rbac_enforcer/enforcer.py", line 402, in enforce_call
2023-02-21 21:33:56.875115 2023-02-21 21:33:56.871 26 ERROR keystone.server.flask.application     policy_dict.update(cls._extract_member_target_data(
2023-02-21 21:33:56.875124 2023-02-21 21:33:56.871 26 ERROR keystone.server.flask.application   File "/var/lib/kolla/venv/lib/python3.9/site-packages/keystone/common/rbac_enforcer/enforcer.py", line 234, in _extract_member_target_data
2023-02-21 21:33:56.875135 2023-02-21 21:33:56.871 26 ERROR keystone.server.flask.application     member_name: func(flask.request.view_args[key])
2023-02-21 21:33:56.875144 2023-02-21 21:33:56.871 26 ERROR keystone.server.flask.application   File "/var/lib/kolla/venv/lib/python3.9/site-packages/keystone/common/manager.py", line 115, in wrapped
2023-02-21 21:33:56.875154 2023-02-21 21:33:56.871 26 ERROR keystone.server.flask.application     __ret_val = __f(*args, **kwargs)
2023-02-21 21:33:56.875163 2023-02-21 21:33:56.871 26 ERROR keystone.server.flask.application   File "/var/lib/kolla/venv/lib/python3.9/site-packages/decorator.py", line 232, in fun
2023-02-21 21:33:56.875173 2023-02-21 21:33:56.871 26 ERROR keystone.server.flask.application     return caller(func, *(extras + args), **kw)
2023-02-21 21:33:56.875183 2023-02-21 21:33:56.871 26 ERROR keystone.server.flask.application   File "/var/lib/kolla/venv/lib/python3.9/site-packages/dogpile/cache/region.py", line 1577, in get_or_create_for_user_func
2023-02-21 21:33:56.875193 2023-02-21 21:33:56.871 26 ERROR keystone.server.flask.application     return self.get_or_create(
2023-02-21 21:33:56.875202 2023-02-21 21:33:56.871 26 ERROR keystone.server.flask.application   File "/var/lib/kolla/venv/lib/python3.9/site-packages/dogpile/cache/region.py", line 1042, in get_or_create
2023-02-21 21:33:56.875212 2023-02-21 21:33:56.871 26 ERROR keystone.server.flask.application     with Lock(
2023-02-21 21:33:56.875221 2023-02-21 21:33:56.871 26 ERROR keystone.server.flask.application   File "/var/lib/kolla/venv/lib/python3.9/site-packages/dogpile/lock.py", line 185, in __enter__
2023-02-21 21:33:56.875231 2023-02-21 21:33:56.871 26 ERROR keystone.server.flask.application     return self._enter()
2023-02-21 21:33:56.875241 2023-02-21 21:33:56.871 26 ERROR keystone.server.flask.application   File "/var/lib/kolla/venv/lib/python3.9/site-packages/dogpile/lock.py", line 94, in _enter
2023-02-21 21:33:56.875261 2023-02-21 21:33:56.871 26 ERROR keystone.server.flask.application     generated = self._enter_create(value, createdtime)
2023-02-21 21:33:56.875272 2023-02-21 21:33:56.871 26 ERROR keystone.server.flask.application   File "/var/lib/kolla/venv/lib/python3.9/site-packages/dogpile/lock.py", line 178, in _enter_create
2023-02-21 21:33:56.875282 2023-02-21 21:33:56.871 26 ERROR keystone.server.flask.application     return self.creator()
2023-02-21 21:33:56.875291 2023-02-21 21:33:56.871 26 ERROR keystone.server.flask.application   File "/var/lib/kolla/venv/lib/python3.9/site-packages/dogpile/cache/region.py", line 995, in gen_value
2023-02-21 21:33:56.875301 2023-02-21 21:33:56.871 26 ERROR keystone.server.flask.application     created_value = creator(
2023-02-21 21:33:56.875310 2023-02-21 21:33:56.871 26 ERROR keystone.server.flask.application   File "/var/lib/kolla/venv/lib/python3.9/site-packages/keystone/assignment/core.py", line 1276, in get_role
2023-02-21 21:33:56.875320 2023-02-21 21:33:56.871 26 ERROR keystone.server.flask.application     return self.driver.get_role(role_id)
2023-02-21 21:33:56.875329 2023-02-21 21:33:56.871 26 ERROR keystone.server.flask.application   File "/var/lib/kolla/venv/lib/python3.9/site-packages/keystone/assignment/role_backends/sql.py", line 70, in get_role
2023-02-21 21:33:56.875339 2023-02-21 21:33:56.871 26 ERROR keystone.server.flask.application     return self._get_role(session, role_id).to_dict()
2023-02-21 21:33:56.875349 2023-02-21 21:33:56.871 26 ERROR keystone.server.flask.application   File "/var/lib/kolla/venv/lib/python3.9/site-packages/keystone/assignment/role_backends/sql.py", line 65, in _get_role
2023-02-21 21:33:56.875359 2023-02-21 21:33:56.871 26 ERROR keystone.server.flask.application     raise exception.RoleNotFound(role_id=role_id)
2023-02-21 21:33:56.875368 2023-02-21 21:33:56.871 26 ERROR keystone.server.flask.application keystone.exception.RoleNotFound: Could not find role: admin.
2023-02-21 21:33:56.875377 2023-02-21 21:33:56.871 26 ERROR keystone.server.flask.application \x1b[00m
2023-02-21 21:33:57.911237 2023-02-21 21:33:57.908 26 ERROR keystone.server.flask.application [None req-6ab4a833-2833-4e70-a50a-6440f1e04d28 d0baa17cc04d45d091397605ff97a2c4 - - all default -] Could not find user: neutron.: keystone.exception.UserNotFound: Could not find user: neutron.
2023-02-21 21:33:57.911347 2023-02-21 21:33:57.908 26 ERROR keystone.server.flask.application Traceback (most recent call last):
2023-02-21 21:33:57.911359 2023-02-21 21:33:57.908 26 ERROR keystone.server.flask.application   File "/var/lib/kolla/venv/lib/python3.9/site-packages/flask/app.py", line 1820, in full_dispatch_request
2023-02-21 21:33:57.911369 2023-02-21 21:33:57.908 26 ERROR keystone.server.flask.application     rv = self.dispatch_request()
2023-02-21 21:33:57.911379 2023-02-21 21:33:57.908 26 ERROR keystone.server.flask.application   File "/var/lib/kolla/venv/lib/python3.9/site-packages/flask/app.py", line 1796, in dispatch_request
2023-02-21 21:33:57.911389 2023-02-21 21:33:57.908 26 ERROR keystone.server.flask.application     return self.ensure_sync(self.view_functions[rule.endpoint])(**view_args)
2023-02-21 21:33:57.911399 2023-02-21 21:33:57.908 26 ERROR keystone.server.flask.application   File "/var/lib/kolla/venv/lib/python3.9/site-packages/flask_restful/__init__.py", line 467, in wrapper
2023-02-21 21:33:57.911408 2023-02-21 21:33:57.908 26 ERROR keystone.server.flask.application     resp = resource(*args, **kwargs)
2023-02-21 21:33:57.911418 2023-02-21 21:33:57.908 26 ERROR keystone.server.flask.application   File "/var/lib/kolla/venv/lib/python3.9/site-packages/flask/views.py", line 107, in view
2023-02-21 21:33:57.911428 2023-02-21 21:33:57.908 26 ERROR keystone.server.flask.application     return current_app.ensure_sync(self.dispatch_request)(**kwargs)
2023-02-21 21:33:57.911437 2023-02-21 21:33:57.908 26 ERROR keystone.server.flask.application   File "/var/lib/kolla/venv/lib/python3.9/site-packages/flask_restful/__init__.py", line 582, in dispatch_request
2023-02-21 21:33:57.911489 2023-02-21 21:33:57.908 26 ERROR keystone.server.flask.application     resp = meth(*args, **kwargs)
2023-02-21 21:33:57.911500 2023-02-21 21:33:57.908 26 ERROR keystone.server.flask.application   File "/var/lib/kolla/venv/lib/python3.9/site-packages/keystone/api/users.py", line 182, in get
2023-02-21 21:33:57.911510 2023-02-21 21:33:57.908 26 ERROR keystone.server.flask.application     return self._get_user(user_id)
2023-02-21 21:33:57.911520 2023-02-21 21:33:57.908 26 ERROR keystone.server.flask.application   File "/var/lib/kolla/venv/lib/python3.9/site-packages/keystone/api/users.py", line 194, in _get_user
2023-02-21 21:33:57.911530 2023-02-21 21:33:57.908 26 ERROR keystone.server.flask.application     ref = PROVIDERS.identity_api.get_user(user_id)
2023-02-21 21:33:57.911539 2023-02-21 21:33:57.908 26 ERROR keystone.server.flask.application   File "/var/lib/kolla/venv/lib/python3.9/site-packages/keystone/common/manager.py", line 115, in wrapped
2023-02-21 21:33:57.911549 2023-02-21 21:33:57.908 26 ERROR keystone.server.flask.application     __ret_val = __f(*args, **kwargs)
2023-02-21 21:33:57.911559 2023-02-21 21:33:57.908 26 ERROR keystone.server.flask.application   File "/var/lib/kolla/venv/lib/python3.9/site-packages/keystone/identity/core.py", line 414, in wrapper
2023-02-21 21:33:57.911574 2023-02-21 21:33:57.908 26 ERROR keystone.server.flask.application     return f(self, *args, **kwargs)
2023-02-21 21:33:57.911607 2023-02-21 21:33:57.908 26 ERROR keystone.server.flask.application   File "/var/lib/kolla/venv/lib/python3.9/site-packages/keystone/identity/core.py", line 424, in wrapper
2023-02-21 21:33:57.911620 2023-02-21 21:33:57.908 26 ERROR keystone.server.flask.application     return f(self, *args, **kwargs)
2023-02-21 21:33:57.911630 2023-02-21 21:33:57.908 26 ERROR keystone.server.flask.application   File "/var/lib/kolla/venv/lib/python3.9/site-packages/decorator.py", line 232, in fun
2023-02-21 21:33:57.911639 2023-02-21 21:33:57.908 26 ERROR keystone.server.flask.application     return caller(func, *(extras + args), **kw)
2023-02-21 21:33:57.911649 2023-02-21 21:33:57.908 26 ERROR keystone.server.flask.application   File "/var/lib/kolla/venv/lib/python3.9/site-packages/dogpile/cache/region.py", line 1577, in get_or_create_for_user_func
2023-02-21 21:33:57.911659 2023-02-21 21:33:57.908 26 ERROR keystone.server.flask.application     return self.get_or_create(
2023-02-21 21:33:57.911668 2023-02-21 21:33:57.908 26 ERROR keystone.server.flask.application   File "/var/lib/kolla/venv/lib/python3.9/site-packages/dogpile/cache/region.py", line 1042, in get_or_create
2023-02-21 21:33:57.911678 2023-02-21 21:33:57.908 26 ERROR keystone.server.flask.application     with Lock(
2023-02-21 21:33:57.911687 2023-02-21 21:33:57.908 26 ERROR keystone.server.flask.application   File "/var/lib/kolla/venv/lib/python3.9/site-packages/dogpile/lock.py", line 185, in __enter__
2023-02-21 21:33:57.911697 2023-02-21 21:33:57.908 26 ERROR keystone.server.flask.application     return self._enter()
2023-02-21 21:33:57.911706 2023-02-21 21:33:57.908 26 ERROR keystone.server.flask.application   File "/var/lib/kolla/venv/lib/python3.9/site-packages/dogpile/lock.py", line 94, in _enter
2023-02-21 21:33:57.911716 2023-02-21 21:33:57.908 26 ERROR keystone.server.flask.application     generated = self._enter_create(value, createdtime)
2023-02-21 21:33:57.911725 2023-02-21 21:33:57.908 26 ERROR keystone.server.flask.application   File "/var/lib/kolla/venv/lib/python3.9/site-packages/dogpile/lock.py", line 178, in _enter_create
2023-02-21 21:33:57.911735 2023-02-21 21:33:57.908 26 ERROR keystone.server.flask.application     return self.creator()
2023-02-21 21:33:57.911744 2023-02-21 21:33:57.908 26 ERROR keystone.server.flask.application   File "/var/lib/kolla/venv/lib/python3.9/site-packages/dogpile/cache/region.py", line 995, in gen_value
2023-02-21 21:33:57.911754 2023-02-21 21:33:57.908 26 ERROR keystone.server.flask.application     created_value = creator(
2023-02-21 21:33:57.911775 2023-02-21 21:33:57.908 26 ERROR keystone.server.flask.application   File "/var/lib/kolla/venv/lib/python3.9/site-packages/keystone/identity/core.py", line 1011, in get_user
2023-02-21 21:33:57.911787 2023-02-21 21:33:57.908 26 ERROR keystone.server.flask.application     ref = driver.get_user(entity_id)
2023-02-21 21:33:57.911796 2023-02-21 21:33:57.908 26 ERROR keystone.server.flask.application   File "/var/lib/kolla/venv/lib/python3.9/site-packages/keystone/identity/backends/sql.py", line 200, in get_user
2023-02-21 21:33:57.911806 2023-02-21 21:33:57.908 26 ERROR keystone.server.flask.application     self._get_user(session, user_id).to_dict())
2023-02-21 21:33:57.911816 2023-02-21 21:33:57.908 26 ERROR keystone.server.flask.application   File "/var/lib/kolla/venv/lib/python3.9/site-packages/keystone/identity/backends/sql.py", line 194, in _get_user
2023-02-21 21:33:57.911826 2023-02-21 21:33:57.908 26 ERROR keystone.server.flask.application     raise exception.UserNotFound(user_id=user_id)
2023-02-21 21:33:57.911835 2023-02-21 21:33:57.908 26 ERROR keystone.server.flask.application keystone.exception.UserNotFound: Could not find user: neutron.
2023-02-21 21:33:57.911845 2023-02-21 21:33:57.908 26 ERROR keystone.server.flask.application \x1b[00m
2023-02-21 21:33:58.644729 2023-02-21 21:33:58.641 27 ERROR keystone.server.flask.application [None req-abb11088-209f-43ef-9472-20ef8aeca9cd d0baa17cc04d45d091397605ff97a2c4 - - all default -] Could not find project: service.: keystone.exception.ProjectNotFound: Could not find project: service.
2023-02-21 21:33:58.644770 2023-02-21 21:33:58.641 27 ERROR keystone.server.flask.application Traceback (most recent call last):
2023-02-21 21:33:58.644781 2023-02-21 21:33:58.641 27 ERROR keystone.server.flask.application   File "/var/lib/kolla/venv/lib/python3.9/site-packages/flask/app.py", line 1820, in full_dispatch_request
2023-02-21 21:33:58.644791 2023-02-21 21:33:58.641 27 ERROR keystone.server.flask.application     rv = self.dispatch_request()
2023-02-21 21:33:58.644800 2023-02-21 21:33:58.641 27 ERROR keystone.server.flask.application   File "/var/lib/kolla/venv/lib/python3.9/site-packages/flask/app.py", line 1796, in dispatch_request
2023-02-21 21:33:58.644810 2023-02-21 21:33:58.641 27 ERROR keystone.server.flask.application     return self.ensure_sync(self.view_functions[rule.endpoint])(**view_args)
2023-02-21 21:33:58.644819 2023-02-21 21:33:58.641 27 ERROR keystone.server.flask.application   File "/var/lib/kolla/venv/lib/python3.9/site-packages/flask_restful/__init__.py", line 467, in wrapper
2023-02-21 21:33:58.644828 2023-02-21 21:33:58.641 27 ERROR keystone.server.flask.application     resp = resource(*args, **kwargs)
2023-02-21 21:33:58.644838 2023-02-21 21:33:58.641 27 ERROR keystone.server.flask.application   File "/var/lib/kolla/venv/lib/python3.9/site-packages/flask/views.py", line 107, in view
2023-02-21 21:33:58.644847 2023-02-21 21:33:58.641 27 ERROR keystone.server.flask.application     return current_app.ensure_sync(self.dispatch_request)(**kwargs)
2023-02-21 21:33:58.644857 2023-02-21 21:33:58.641 27 ERROR keystone.server.flask.application   File "/var/lib/kolla/venv/lib/python3.9/site-packages/flask_restful/__init__.py", line 582, in dispatch_request
2023-02-21 21:33:58.644866 2023-02-21 21:33:58.641 27 ERROR keystone.server.flask.application     resp = meth(*args, **kwargs)
2023-02-21 21:33:58.644875 2023-02-21 21:33:58.641 27 ERROR keystone.server.flask.application   File "/var/lib/kolla/venv/lib/python3.9/site-packages/keystone/api/projects.py", line 151, in get
2023-02-21 21:33:58.644926 2023-02-21 21:33:58.641 27 ERROR keystone.server.flask.application     return self._get_project(project_id)
2023-02-21 21:33:58.644943 2023-02-21 21:33:58.641 27 ERROR keystone.server.flask.application   File "/var/lib/kolla/venv/lib/python3.9/site-packages/keystone/api/projects.py", line 107, in _get_project
2023-02-21 21:33:58.644953 2023-02-21 21:33:58.641 27 ERROR keystone.server.flask.application     project = PROVIDERS.resource_api.get_project(project_id)
2023-02-21 21:33:58.644979 2023-02-21 21:33:58.641 27 ERROR keystone.server.flask.application   File "/var/lib/kolla/venv/lib/python3.9/site-packages/keystone/common/manager.py", line 115, in wrapped
2023-02-21 21:33:58.644990 2023-02-21 21:33:58.641 27 ERROR keystone.server.flask.application     __ret_val = __f(*args, **kwargs)
2023-02-21 21:33:58.644999 2023-02-21 21:33:58.641 27 ERROR keystone.server.flask.application   File "/var/lib/kolla/venv/lib/python3.9/site-packages/decorator.py", line 232, in fun
2023-02-21 21:33:58.645009 2023-02-21 21:33:58.641 27 ERROR keystone.server.flask.application     return caller(func, *(extras + args), **kw)
2023-02-21 21:33:58.645019 2023-02-21 21:33:58.641 27 ERROR keystone.server.flask.application   File "/var/lib/kolla/venv/lib/python3.9/site-packages/dogpile/cache/region.py", line 1577, in get_or_create_for_user_func
2023-02-21 21:33:58.645029 2023-02-21 21:33:58.641 27 ERROR keystone.server.flask.application     return self.get_or_create(
2023-02-21 21:33:58.645038 2023-02-21 21:33:58.641 27 ERROR keystone.server.flask.application   File "/var/lib/kolla/venv/lib/python3.9/site-packages/dogpile/cache/region.py", line 1042, in get_or_create
2023-02-21 21:33:58.645048 2023-02-21 21:33:58.641 27 ERROR keystone.server.flask.application     with Lock(
2023-02-21 21:33:58.645057 2023-02-21 21:33:58.641 27 ERROR keystone.server.flask.application   File "/var/lib/kolla/venv/lib/python3.9/site-packages/dogpile/lock.py", line 185, in __enter__
2023-02-21 21:33:58.645067 2023-02-21 21:33:58.641 27 ERROR keystone.server.flask.application     return self._enter()
2023-02-21 21:33:58.645076 2023-02-21 21:33:58.641 27 ERROR keystone.server.flask.application   File "/var/lib/kolla/venv/lib/python3.9/site-packages/dogpile/lock.py", line 94, in _enter
2023-02-21 21:33:58.645086 2023-02-21 21:33:58.641 27 ERROR keystone.server.flask.application     generated = self._enter_create(value, createdtime)
2023-02-21 21:33:58.645095 2023-02-21 21:33:58.641 27 ERROR keystone.server.flask.application   File "/var/lib/kolla/venv/lib/python3.9/site-packages/dogpile/lock.py", line 178, in _enter_create
2023-02-21 21:33:58.645105 2023-02-21 21:33:58.641 27 ERROR keystone.server.flask.application     return self.creator()
2023-02-21 21:33:58.645114 2023-02-21 21:33:58.641 27 ERROR keystone.server.flask.application   File "/var/lib/kolla/venv/lib/python3.9/site-packages/dogpile/cache/region.py", line 995, in gen_value
2023-02-21 21:33:58.645124 2023-02-21 21:33:58.641 27 ERROR keystone.server.flask.application     created_value = creator(
2023-02-21 21:33:58.645133 2023-02-21 21:33:58.641 27 ERROR keystone.server.flask.application   File "/var/lib/kolla/venv/lib/python3.9/site-packages/keystone/resource/core.py", line 903, in get_project
2023-02-21 21:33:58.645143 2023-02-21 21:33:58.641 27 ERROR keystone.server.flask.application     return self.driver.get_project(project_id)
2023-02-21 21:33:58.645153 2023-02-21 21:33:58.641 27 ERROR keystone.server.flask.application   File "/var/lib/kolla/venv/lib/python3.9/site-packages/keystone/resource/backends/sql.py", line 49, in get_project
2023-02-21 21:33:58.645162 2023-02-21 21:33:58.641 27 ERROR keystone.server.flask.application     return self._get_project(session, project_id).to_dict()
2023-02-21 21:33:58.645172 2023-02-21 21:33:58.641 27 ERROR keystone.server.flask.application   File "/var/lib/kolla/venv/lib/python3.9/site-packages/keystone/resource/backends/sql.py", line 44, in _get_project
2023-02-21 21:33:58.645182 2023-02-21 21:33:58.641 27 ERROR keystone.server.flask.application     raise exception.ProjectNotFound(project_id=project_id)
2023-02-21 21:33:58.645191 2023-02-21 21:33:58.641 27 ERROR keystone.server.flask.application keystone.exception.ProjectNotFound: Could not find project: service.
2023-02-21 21:33:58.645201 2023-02-21 21:33:58.641 27 ERROR keystone.server.flask.application \x1b[00m
