2023-04-12 06:40:35.037 23 INFO alembic.runtime.migration [-] Context impl MySQLImpl.
2023-04-12 06:40:35.039 23 INFO alembic.runtime.migration [-] Will assume non-transactional DDL.
2023-04-12 06:40:35.088 23 INFO alembic.runtime.migration [-] Context impl MySQLImpl.
2023-04-12 06:40:35.089 23 INFO alembic.runtime.migration [-] Will assume non-transactional DDL.
2023-04-12 06:40:35.132 23 INFO alembic.runtime.migration [-] Running upgrade  -> 27e647c0fad4, Initial version.
2023-04-12 06:40:36.220 23 INFO alembic.runtime.migration [-] Running upgrade 27e647c0fad4 -> e25ffa003242, Initial no-op Yoga contract migration.
2023-04-12 06:40:36.235 23 INFO alembic.runtime.migration [-] Running upgrade 27e647c0fad4 -> 29e87d24a316, Initial no-op Yoga expand migration.
2023-04-12 06:40:44.708 7 INFO keystone.common.fernet_utils [-] Created a new temporary key: /etc/keystone/fernet-keys/0.tmp
2023-04-12 06:40:44.714 7 INFO keystone.common.fernet_utils [-] Become a valid new key: /etc/keystone/fernet-keys/0
2023-04-12 06:40:44.715 7 INFO keystone.common.fernet_utils [-] Starting key rotation with 1 key files: ['/etc/keystone/fernet-keys/0']
2023-04-12 06:40:44.716 7 INFO keystone.common.fernet_utils [-] Created a new temporary key: /etc/keystone/fernet-keys/0.tmp
2023-04-12 06:40:44.717 7 INFO keystone.common.fernet_utils [-] Current primary key is: 0
2023-04-12 06:40:44.717 7 INFO keystone.common.fernet_utils [-] Next primary key will be: 1
2023-04-12 06:40:44.718 7 INFO keystone.common.fernet_utils [-] Promoted key 0 to be the primary: 1
2023-04-12 06:40:44.719 7 INFO keystone.common.fernet_utils [-] Become a valid new key: /etc/keystone/fernet-keys/0
2023-04-12 06:41:03.846 33 INFO keystone.cmd.bootstrap [None req-2dd2fed2-7505-44ef-a227-dfacd40e063e - - - - - -] Created domain default
2023-04-12 06:41:03.912 33 INFO keystone.cmd.bootstrap [None req-2dd2fed2-7505-44ef-a227-dfacd40e063e - - - - - -] Created project admin
2023-04-12 06:41:04.582 33 INFO keystone.cmd.bootstrap [None req-2dd2fed2-7505-44ef-a227-dfacd40e063e - - - - - -] Created user admin
2023-04-12 06:41:04.603 33 INFO keystone.cmd.bootstrap [None req-2dd2fed2-7505-44ef-a227-dfacd40e063e - - - - - -] Created role reader
2023-04-12 06:41:04.626 33 INFO keystone.cmd.bootstrap [None req-2dd2fed2-7505-44ef-a227-dfacd40e063e - - - - - -] Created role member
2023-04-12 06:41:04.692 33 INFO keystone.cmd.bootstrap [None req-2dd2fed2-7505-44ef-a227-dfacd40e063e - - - - - -] Created implied role where acbd500615794e228e1f21f8b02ca9d1 implies b4b7cbbb17f2482baca9fc24242f3cd2
2023-04-12 06:41:04.708 33 INFO keystone.cmd.bootstrap [None req-2dd2fed2-7505-44ef-a227-dfacd40e063e - - - - - -] Created role admin
2023-04-12 06:41:04.738 33 INFO keystone.cmd.bootstrap [None req-2dd2fed2-7505-44ef-a227-dfacd40e063e - - - - - -] Created implied role where f80a7f7c82cc4d769a810a912bd97e11 implies acbd500615794e228e1f21f8b02ca9d1
2023-04-12 06:41:04.755 33 INFO keystone.cmd.bootstrap [None req-2dd2fed2-7505-44ef-a227-dfacd40e063e - - - - - -] Granted role admin on project admin to user admin.
2023-04-12 06:41:04.766 33 INFO keystone.cmd.bootstrap [None req-2dd2fed2-7505-44ef-a227-dfacd40e063e - - - - - -] Granted role admin on the system to user admin.
2023-04-12 06:41:04.790 33 WARNING py.warnings [None req-2dd2fed2-7505-44ef-a227-dfacd40e063e - - - - - -] /var/lib/kolla/venv/lib/python3.9/site-packages/pycadf/identifier.py:71: UserWarning: Invalid uuid: RegionOne. To ensure interoperability, identifiers should be a valid uuid.
  warnings.warn(('Invalid uuid: %s. To ensure interoperability, '

2023-04-12 06:41:04.797 33 INFO keystone.cmd.bootstrap [None req-2dd2fed2-7505-44ef-a227-dfacd40e063e - - - - - -] Created region RegionOne
2023-04-12 06:41:04.851 33 INFO keystone.cmd.bootstrap [None req-2dd2fed2-7505-44ef-a227-dfacd40e063e - - - - - -] Created public endpoint http://169.16.1.146:5000
2023-04-12 06:41:04.864 33 INFO keystone.cmd.bootstrap [None req-2dd2fed2-7505-44ef-a227-dfacd40e063e - - - - - -] Created internal endpoint http://169.16.1.146:5000
2023-04-12 06:41:29.421 40 WARNING keystone.common.rbac_enforcer.enforcer [None req-5ed1406d-8c02-47e8-92e5-5418fe57f615 939ca49fd86e457aa26c99f9e150ded1 - - all default -] Deprecated policy rules found. Use oslopolicy-policy-generator and oslopolicy-policy-upgrade to detect and resolve deprecated policies in your configuration.
2023-04-12 06:41:30.275 39 WARNING keystone.common.rbac_enforcer.enforcer [None req-9f7ad5b2-78da-4247-8f2e-d0e7a05c7980 939ca49fd86e457aa26c99f9e150ded1 - - all default -] Deprecated policy rules found. Use oslopolicy-policy-generator and oslopolicy-policy-upgrade to detect and resolve deprecated policies in your configuration.
2023-04-12 06:41:38.400 38 WARNING keystone.common.rbac_enforcer.enforcer [None req-75fb31fa-3a84-4d92-9e20-b954aec7e327 939ca49fd86e457aa26c99f9e150ded1 - - all default -] Deprecated policy rules found. Use oslopolicy-policy-generator and oslopolicy-policy-upgrade to detect and resolve deprecated policies in your configuration.
2023-04-12 06:42:57.312 40 ERROR keystone.server.flask.application [None req-5c3fcc7a-932f-418e-a469-8acbb102f78d 939ca49fd86e457aa26c99f9e150ded1 - - all default -] Could not find project: service.: keystone.exception.ProjectNotFound: Could not find project: service.
2023-04-12 06:42:57.312 40 ERROR keystone.server.flask.application Traceback (most recent call last):
2023-04-12 06:42:57.312 40 ERROR keystone.server.flask.application   File "/var/lib/kolla/venv/lib/python3.9/site-packages/flask/app.py", line 1820, in full_dispatch_request
2023-04-12 06:42:57.312 40 ERROR keystone.server.flask.application     rv = self.dispatch_request()
2023-04-12 06:42:57.312 40 ERROR keystone.server.flask.application   File "/var/lib/kolla/venv/lib/python3.9/site-packages/flask/app.py", line 1796, in dispatch_request
2023-04-12 06:42:57.312 40 ERROR keystone.server.flask.application     return self.ensure_sync(self.view_functions[rule.endpoint])(**view_args)
2023-04-12 06:42:57.312 40 ERROR keystone.server.flask.application   File "/var/lib/kolla/venv/lib/python3.9/site-packages/flask_restful/__init__.py", line 467, in wrapper
2023-04-12 06:42:57.312 40 ERROR keystone.server.flask.application     resp = resource(*args, **kwargs)
2023-04-12 06:42:57.312 40 ERROR keystone.server.flask.application   File "/var/lib/kolla/venv/lib/python3.9/site-packages/flask/views.py", line 107, in view
2023-04-12 06:42:57.312 40 ERROR keystone.server.flask.application     return current_app.ensure_sync(self.dispatch_request)(**kwargs)
2023-04-12 06:42:57.312 40 ERROR keystone.server.flask.application   File "/var/lib/kolla/venv/lib/python3.9/site-packages/flask_restful/__init__.py", line 582, in dispatch_request
2023-04-12 06:42:57.312 40 ERROR keystone.server.flask.application     resp = meth(*args, **kwargs)
2023-04-12 06:42:57.312 40 ERROR keystone.server.flask.application   File "/var/lib/kolla/venv/lib/python3.9/site-packages/keystone/api/projects.py", line 151, in get
2023-04-12 06:42:57.312 40 ERROR keystone.server.flask.application     return self._get_project(project_id)
2023-04-12 06:42:57.312 40 ERROR keystone.server.flask.application   File "/var/lib/kolla/venv/lib/python3.9/site-packages/keystone/api/projects.py", line 107, in _get_project
2023-04-12 06:42:57.312 40 ERROR keystone.server.flask.application     project = PROVIDERS.resource_api.get_project(project_id)
2023-04-12 06:42:57.312 40 ERROR keystone.server.flask.application   File "/var/lib/kolla/venv/lib/python3.9/site-packages/keystone/common/manager.py", line 115, in wrapped
2023-04-12 06:42:57.312 40 ERROR keystone.server.flask.application     __ret_val = __f(*args, **kwargs)
2023-04-12 06:42:57.312 40 ERROR keystone.server.flask.application   File "/var/lib/kolla/venv/lib/python3.9/site-packages/decorator.py", line 232, in fun
2023-04-12 06:42:57.312 40 ERROR keystone.server.flask.application     return caller(func, *(extras + args), **kw)
2023-04-12 06:42:57.312 40 ERROR keystone.server.flask.application   File "/var/lib/kolla/venv/lib/python3.9/site-packages/dogpile/cache/region.py", line 1577, in get_or_create_for_user_func
2023-04-12 06:42:57.312 40 ERROR keystone.server.flask.application     return self.get_or_create(
2023-04-12 06:42:57.312 40 ERROR keystone.server.flask.application   File "/var/lib/kolla/venv/lib/python3.9/site-packages/dogpile/cache/region.py", line 1042, in get_or_create
2023-04-12 06:42:57.312 40 ERROR keystone.server.flask.application     with Lock(
2023-04-12 06:42:57.312 40 ERROR keystone.server.flask.application   File "/var/lib/kolla/venv/lib/python3.9/site-packages/dogpile/lock.py", line 185, in __enter__
2023-04-12 06:42:57.312 40 ERROR keystone.server.flask.application     return self._enter()
2023-04-12 06:42:57.312 40 ERROR keystone.server.flask.application   File "/var/lib/kolla/venv/lib/python3.9/site-packages/dogpile/lock.py", line 94, in _enter
2023-04-12 06:42:57.312 40 ERROR keystone.server.flask.application     generated = self._enter_create(value, createdtime)
2023-04-12 06:42:57.312 40 ERROR keystone.server.flask.application   File "/var/lib/kolla/venv/lib/python3.9/site-packages/dogpile/lock.py", line 178, in _enter_create
2023-04-12 06:42:57.312 40 ERROR keystone.server.flask.application     return self.creator()
2023-04-12 06:42:57.312 40 ERROR keystone.server.flask.application   File "/var/lib/kolla/venv/lib/python3.9/site-packages/dogpile/cache/region.py", line 995, in gen_value
2023-04-12 06:42:57.312 40 ERROR keystone.server.flask.application     created_value = creator(
2023-04-12 06:42:57.312 40 ERROR keystone.server.flask.application   File "/var/lib/kolla/venv/lib/python3.9/site-packages/keystone/resource/core.py", line 903, in get_project
2023-04-12 06:42:57.312 40 ERROR keystone.server.flask.application     return self.driver.get_project(project_id)
2023-04-12 06:42:57.312 40 ERROR keystone.server.flask.application   File "/var/lib/kolla/venv/lib/python3.9/site-packages/keystone/resource/backends/sql.py", line 49, in get_project
2023-04-12 06:42:57.312 40 ERROR keystone.server.flask.application     return self._get_project(session, project_id).to_dict()
2023-04-12 06:42:57.312 40 ERROR keystone.server.flask.application   File "/var/lib/kolla/venv/lib/python3.9/site-packages/keystone/resource/backends/sql.py", line 44, in _get_project
2023-04-12 06:42:57.312 40 ERROR keystone.server.flask.application     raise exception.ProjectNotFound(project_id=project_id)
2023-04-12 06:42:57.312 40 ERROR keystone.server.flask.application keystone.exception.ProjectNotFound: Could not find project: service.
2023-04-12 06:42:57.312 40 ERROR keystone.server.flask.application 
2023-04-12 06:43:07.451 38 ERROR keystone.server.flask.application [None req-6b0bdb7a-584e-455d-b929-a8d775a959b9 939ca49fd86e457aa26c99f9e150ded1 - - all default -] Could not find project: service.: keystone.exception.ProjectNotFound: Could not find project: service.
2023-04-12 06:43:07.451 38 ERROR keystone.server.flask.application Traceback (most recent call last):
2023-04-12 06:43:07.451 38 ERROR keystone.server.flask.application   File "/var/lib/kolla/venv/lib/python3.9/site-packages/flask/app.py", line 1820, in full_dispatch_request
2023-04-12 06:43:07.451 38 ERROR keystone.server.flask.application     rv = self.dispatch_request()
2023-04-12 06:43:07.451 38 ERROR keystone.server.flask.application   File "/var/lib/kolla/venv/lib/python3.9/site-packages/flask/app.py", line 1796, in dispatch_request
2023-04-12 06:43:07.451 38 ERROR keystone.server.flask.application     return self.ensure_sync(self.view_functions[rule.endpoint])(**view_args)
2023-04-12 06:43:07.451 38 ERROR keystone.server.flask.application   File "/var/lib/kolla/venv/lib/python3.9/site-packages/flask_restful/__init__.py", line 467, in wrapper
2023-04-12 06:43:07.451 38 ERROR keystone.server.flask.application     resp = resource(*args, **kwargs)
2023-04-12 06:43:07.451 38 ERROR keystone.server.flask.application   File "/var/lib/kolla/venv/lib/python3.9/site-packages/flask/views.py", line 107, in view
2023-04-12 06:43:07.451 38 ERROR keystone.server.flask.application     return current_app.ensure_sync(self.dispatch_request)(**kwargs)
2023-04-12 06:43:07.451 38 ERROR keystone.server.flask.application   File "/var/lib/kolla/venv/lib/python3.9/site-packages/flask_restful/__init__.py", line 582, in dispatch_request
2023-04-12 06:43:07.451 38 ERROR keystone.server.flask.application     resp = meth(*args, **kwargs)
2023-04-12 06:43:07.451 38 ERROR keystone.server.flask.application   File "/var/lib/kolla/venv/lib/python3.9/site-packages/keystone/api/projects.py", line 151, in get
2023-04-12 06:43:07.451 38 ERROR keystone.server.flask.application     return self._get_project(project_id)
2023-04-12 06:43:07.451 38 ERROR keystone.server.flask.application   File "/var/lib/kolla/venv/lib/python3.9/site-packages/keystone/api/projects.py", line 107, in _get_project
2023-04-12 06:43:07.451 38 ERROR keystone.server.flask.application     project = PROVIDERS.resource_api.get_project(project_id)
2023-04-12 06:43:07.451 38 ERROR keystone.server.flask.application   File "/var/lib/kolla/venv/lib/python3.9/site-packages/keystone/common/manager.py", line 115, in wrapped
2023-04-12 06:43:07.451 38 ERROR keystone.server.flask.application     __ret_val = __f(*args, **kwargs)
2023-04-12 06:43:07.451 38 ERROR keystone.server.flask.application   File "/var/lib/kolla/venv/lib/python3.9/site-packages/decorator.py", line 232, in fun
2023-04-12 06:43:07.451 38 ERROR keystone.server.flask.application     return caller(func, *(extras + args), **kw)
2023-04-12 06:43:07.451 38 ERROR keystone.server.flask.application   File "/var/lib/kolla/venv/lib/python3.9/site-packages/dogpile/cache/region.py", line 1577, in get_or_create_for_user_func
2023-04-12 06:43:07.451 38 ERROR keystone.server.flask.application     return self.get_or_create(
2023-04-12 06:43:07.451 38 ERROR keystone.server.flask.application   File "/var/lib/kolla/venv/lib/python3.9/site-packages/dogpile/cache/region.py", line 1042, in get_or_create
2023-04-12 06:43:07.451 38 ERROR keystone.server.flask.application     with Lock(
2023-04-12 06:43:07.451 38 ERROR keystone.server.flask.application   File "/var/lib/kolla/venv/lib/python3.9/site-packages/dogpile/lock.py", line 185, in __enter__
2023-04-12 06:43:07.451 38 ERROR keystone.server.flask.application     return self._enter()
2023-04-12 06:43:07.451 38 ERROR keystone.server.flask.application   File "/var/lib/kolla/venv/lib/python3.9/site-packages/dogpile/lock.py", line 94, in _enter
2023-04-12 06:43:07.451 38 ERROR keystone.server.flask.application     generated = self._enter_create(value, createdtime)
2023-04-12 06:43:07.451 38 ERROR keystone.server.flask.application   File "/var/lib/kolla/venv/lib/python3.9/site-packages/dogpile/lock.py", line 178, in _enter_create
2023-04-12 06:43:07.451 38 ERROR keystone.server.flask.application     return self.creator()
2023-04-12 06:43:07.451 38 ERROR keystone.server.flask.application   File "/var/lib/kolla/venv/lib/python3.9/site-packages/dogpile/cache/region.py", line 995, in gen_value
2023-04-12 06:43:07.451 38 ERROR keystone.server.flask.application     created_value = creator(
2023-04-12 06:43:07.451 38 ERROR keystone.server.flask.application   File "/var/lib/kolla/venv/lib/python3.9/site-packages/keystone/resource/core.py", line 903, in get_project
2023-04-12 06:43:07.451 38 ERROR keystone.server.flask.application     return self.driver.get_project(project_id)
2023-04-12 06:43:07.451 38 ERROR keystone.server.flask.application   File "/var/lib/kolla/venv/lib/python3.9/site-packages/keystone/resource/backends/sql.py", line 49, in get_project
2023-04-12 06:43:07.451 38 ERROR keystone.server.flask.application     return self._get_project(session, project_id).to_dict()
2023-04-12 06:43:07.451 38 ERROR keystone.server.flask.application   File "/var/lib/kolla/venv/lib/python3.9/site-packages/keystone/resource/backends/sql.py", line 44, in _get_project
2023-04-12 06:43:07.451 38 ERROR keystone.server.flask.application     raise exception.ProjectNotFound(project_id=project_id)
2023-04-12 06:43:07.451 38 ERROR keystone.server.flask.application keystone.exception.ProjectNotFound: Could not find project: service.
2023-04-12 06:43:07.451 38 ERROR keystone.server.flask.application 
2023-04-12 06:43:22.655 38 ERROR keystone.server.flask.application [None req-fbde5925-1728-4943-9088-9f2813999f92 939ca49fd86e457aa26c99f9e150ded1 - - all default -] Could not find role: admin.: keystone.exception.RoleNotFound: Could not find role: admin.
2023-04-12 06:43:22.655 38 ERROR keystone.server.flask.application Traceback (most recent call last):
2023-04-12 06:43:22.655 38 ERROR keystone.server.flask.application   File "/var/lib/kolla/venv/lib/python3.9/site-packages/flask/app.py", line 1820, in full_dispatch_request
2023-04-12 06:43:22.655 38 ERROR keystone.server.flask.application     rv = self.dispatch_request()
2023-04-12 06:43:22.655 38 ERROR keystone.server.flask.application   File "/var/lib/kolla/venv/lib/python3.9/site-packages/flask/app.py", line 1796, in dispatch_request
2023-04-12 06:43:22.655 38 ERROR keystone.server.flask.application     return self.ensure_sync(self.view_functions[rule.endpoint])(**view_args)
2023-04-12 06:43:22.655 38 ERROR keystone.server.flask.application   File "/var/lib/kolla/venv/lib/python3.9/site-packages/flask_restful/__init__.py", line 467, in wrapper
2023-04-12 06:43:22.655 38 ERROR keystone.server.flask.application     resp = resource(*args, **kwargs)
2023-04-12 06:43:22.655 38 ERROR keystone.server.flask.application   File "/var/lib/kolla/venv/lib/python3.9/site-packages/flask/views.py", line 107, in view
2023-04-12 06:43:22.655 38 ERROR keystone.server.flask.application     return current_app.ensure_sync(self.dispatch_request)(**kwargs)
2023-04-12 06:43:22.655 38 ERROR keystone.server.flask.application   File "/var/lib/kolla/venv/lib/python3.9/site-packages/flask_restful/__init__.py", line 582, in dispatch_request
2023-04-12 06:43:22.655 38 ERROR keystone.server.flask.application     resp = meth(*args, **kwargs)
2023-04-12 06:43:22.655 38 ERROR keystone.server.flask.application   File "/var/lib/kolla/venv/lib/python3.9/site-packages/keystone/api/roles.py", line 50, in get
2023-04-12 06:43:22.655 38 ERROR keystone.server.flask.application     return self._get_role(role_id)
2023-04-12 06:43:22.655 38 ERROR keystone.server.flask.application   File "/var/lib/kolla/venv/lib/python3.9/site-packages/keystone/api/roles.py", line 70, in _get_role
2023-04-12 06:43:22.655 38 ERROR keystone.server.flask.application     ENFORCER.enforce_call(action='identity:get_role')
2023-04-12 06:43:22.655 38 ERROR keystone.server.flask.application   File "/var/lib/kolla/venv/lib/python3.9/site-packages/keystone/common/rbac_enforcer/enforcer.py", line 402, in enforce_call
2023-04-12 06:43:22.655 38 ERROR keystone.server.flask.application     policy_dict.update(cls._extract_member_target_data(
2023-04-12 06:43:22.655 38 ERROR keystone.server.flask.application   File "/var/lib/kolla/venv/lib/python3.9/site-packages/keystone/common/rbac_enforcer/enforcer.py", line 234, in _extract_member_target_data
2023-04-12 06:43:22.655 38 ERROR keystone.server.flask.application     member_name: func(flask.request.view_args[key])
2023-04-12 06:43:22.655 38 ERROR keystone.server.flask.application   File "/var/lib/kolla/venv/lib/python3.9/site-packages/keystone/common/manager.py", line 115, in wrapped
2023-04-12 06:43:22.655 38 ERROR keystone.server.flask.application     __ret_val = __f(*args, **kwargs)
2023-04-12 06:43:22.655 38 ERROR keystone.server.flask.application   File "/var/lib/kolla/venv/lib/python3.9/site-packages/decorator.py", line 232, in fun
2023-04-12 06:43:22.655 38 ERROR keystone.server.flask.application     return caller(func, *(extras + args), **kw)
2023-04-12 06:43:22.655 38 ERROR keystone.server.flask.application   File "/var/lib/kolla/venv/lib/python3.9/site-packages/dogpile/cache/region.py", line 1577, in get_or_create_for_user_func
2023-04-12 06:43:22.655 38 ERROR keystone.server.flask.application     return self.get_or_create(
2023-04-12 06:43:22.655 38 ERROR keystone.server.flask.application   File "/var/lib/kolla/venv/lib/python3.9/site-packages/dogpile/cache/region.py", line 1042, in get_or_create
2023-04-12 06:43:22.655 38 ERROR keystone.server.flask.application     with Lock(
2023-04-12 06:43:22.655 38 ERROR keystone.server.flask.application   File "/var/lib/kolla/venv/lib/python3.9/site-packages/dogpile/lock.py", line 185, in __enter__
2023-04-12 06:43:22.655 38 ERROR keystone.server.flask.application     return self._enter()
2023-04-12 06:43:22.655 38 ERROR keystone.server.flask.application   File "/var/lib/kolla/venv/lib/python3.9/site-packages/dogpile/lock.py", line 94, in _enter
2023-04-12 06:43:22.655 38 ERROR keystone.server.flask.application     generated = self._enter_create(value, createdtime)
2023-04-12 06:43:22.655 38 ERROR keystone.server.flask.application   File "/var/lib/kolla/venv/lib/python3.9/site-packages/dogpile/lock.py", line 178, in _enter_create
2023-04-12 06:43:22.655 38 ERROR keystone.server.flask.application     return self.creator()
2023-04-12 06:43:22.655 38 ERROR keystone.server.flask.application   File "/var/lib/kolla/venv/lib/python3.9/site-packages/dogpile/cache/region.py", line 995, in gen_value
2023-04-12 06:43:22.655 38 ERROR keystone.server.flask.application     created_value = creator(
2023-04-12 06:43:22.655 38 ERROR keystone.server.flask.application   File "/var/lib/kolla/venv/lib/python3.9/site-packages/keystone/assignment/core.py", line 1276, in get_role
2023-04-12 06:43:22.655 38 ERROR keystone.server.flask.application     return self.driver.get_role(role_id)
2023-04-12 06:43:22.655 38 ERROR keystone.server.flask.application   File "/var/lib/kolla/venv/lib/python3.9/site-packages/keystone/assignment/role_backends/sql.py", line 70, in get_role
2023-04-12 06:43:22.655 38 ERROR keystone.server.flask.application     return self._get_role(session, role_id).to_dict()
2023-04-12 06:43:22.655 38 ERROR keystone.server.flask.application   File "/var/lib/kolla/venv/lib/python3.9/site-packages/keystone/assignment/role_backends/sql.py", line 65, in _get_role
2023-04-12 06:43:22.655 38 ERROR keystone.server.flask.application     raise exception.RoleNotFound(role_id=role_id)
2023-04-12 06:43:22.655 38 ERROR keystone.server.flask.application keystone.exception.RoleNotFound: Could not find role: admin.
2023-04-12 06:43:22.655 38 ERROR keystone.server.flask.application 
2023-04-12 06:43:24.178 38 ERROR keystone.server.flask.application [None req-b0af165f-e1aa-4e0c-8f64-9a018af44bec 939ca49fd86e457aa26c99f9e150ded1 - - all default -] Could not find user: ironic.: keystone.exception.UserNotFound: Could not find user: ironic.
2023-04-12 06:43:24.178 38 ERROR keystone.server.flask.application Traceback (most recent call last):
2023-04-12 06:43:24.178 38 ERROR keystone.server.flask.application   File "/var/lib/kolla/venv/lib/python3.9/site-packages/flask/app.py", line 1820, in full_dispatch_request
2023-04-12 06:43:24.178 38 ERROR keystone.server.flask.application     rv = self.dispatch_request()
2023-04-12 06:43:24.178 38 ERROR keystone.server.flask.application   File "/var/lib/kolla/venv/lib/python3.9/site-packages/flask/app.py", line 1796, in dispatch_request
2023-04-12 06:43:24.178 38 ERROR keystone.server.flask.application     return self.ensure_sync(self.view_functions[rule.endpoint])(**view_args)
2023-04-12 06:43:24.178 38 ERROR keystone.server.flask.application   File "/var/lib/kolla/venv/lib/python3.9/site-packages/flask_restful/__init__.py", line 467, in wrapper
2023-04-12 06:43:24.178 38 ERROR keystone.server.flask.application     resp = resource(*args, **kwargs)
2023-04-12 06:43:24.178 38 ERROR keystone.server.flask.application   File "/var/lib/kolla/venv/lib/python3.9/site-packages/flask/views.py", line 107, in view
2023-04-12 06:43:24.178 38 ERROR keystone.server.flask.application     return current_app.ensure_sync(self.dispatch_request)(**kwargs)
2023-04-12 06:43:24.178 38 ERROR keystone.server.flask.application   File "/var/lib/kolla/venv/lib/python3.9/site-packages/flask_restful/__init__.py", line 582, in dispatch_request
2023-04-12 06:43:24.178 38 ERROR keystone.server.flask.application     resp = meth(*args, **kwargs)
2023-04-12 06:43:24.178 38 ERROR keystone.server.flask.application   File "/var/lib/kolla/venv/lib/python3.9/site-packages/keystone/api/users.py", line 182, in get
2023-04-12 06:43:24.178 38 ERROR keystone.server.flask.application     return self._get_user(user_id)
2023-04-12 06:43:24.178 38 ERROR keystone.server.flask.application   File "/var/lib/kolla/venv/lib/python3.9/site-packages/keystone/api/users.py", line 194, in _get_user
2023-04-12 06:43:24.178 38 ERROR keystone.server.flask.application     ref = PROVIDERS.identity_api.get_user(user_id)
2023-04-12 06:43:24.178 38 ERROR keystone.server.flask.application   File "/var/lib/kolla/venv/lib/python3.9/site-packages/keystone/common/manager.py", line 115, in wrapped
2023-04-12 06:43:24.178 38 ERROR keystone.server.flask.application     __ret_val = __f(*args, **kwargs)
2023-04-12 06:43:24.178 38 ERROR keystone.server.flask.application   File "/var/lib/kolla/venv/lib/python3.9/site-packages/keystone/identity/core.py", line 414, in wrapper
2023-04-12 06:43:24.178 38 ERROR keystone.server.flask.application     return f(self, *args, **kwargs)
2023-04-12 06:43:24.178 38 ERROR keystone.server.flask.application   File "/var/lib/kolla/venv/lib/python3.9/site-packages/keystone/identity/core.py", line 424, in wrapper
2023-04-12 06:43:24.178 38 ERROR keystone.server.flask.application     return f(self, *args, **kwargs)
2023-04-12 06:43:24.178 38 ERROR keystone.server.flask.application   File "/var/lib/kolla/venv/lib/python3.9/site-packages/decorator.py", line 232, in fun
2023-04-12 06:43:24.178 38 ERROR keystone.server.flask.application     return caller(func, *(extras + args), **kw)
2023-04-12 06:43:24.178 38 ERROR keystone.server.flask.application   File "/var/lib/kolla/venv/lib/python3.9/site-packages/dogpile/cache/region.py", line 1577, in get_or_create_for_user_func
2023-04-12 06:43:24.178 38 ERROR keystone.server.flask.application     return self.get_or_create(
2023-04-12 06:43:24.178 38 ERROR keystone.server.flask.application   File "/var/lib/kolla/venv/lib/python3.9/site-packages/dogpile/cache/region.py", line 1042, in get_or_create
2023-04-12 06:43:24.178 38 ERROR keystone.server.flask.application     with Lock(
2023-04-12 06:43:24.178 38 ERROR keystone.server.flask.application   File "/var/lib/kolla/venv/lib/python3.9/site-packages/dogpile/lock.py", line 185, in __enter__
2023-04-12 06:43:24.178 38 ERROR keystone.server.flask.application     return self._enter()
2023-04-12 06:43:24.178 38 ERROR keystone.server.flask.application   File "/var/lib/kolla/venv/lib/python3.9/site-packages/dogpile/lock.py", line 94, in _enter
2023-04-12 06:43:24.178 38 ERROR keystone.server.flask.application     generated = self._enter_create(value, createdtime)
2023-04-12 06:43:24.178 38 ERROR keystone.server.flask.application   File "/var/lib/kolla/venv/lib/python3.9/site-packages/dogpile/lock.py", line 178, in _enter_create
2023-04-12 06:43:24.178 38 ERROR keystone.server.flask.application     return self.creator()
2023-04-12 06:43:24.178 38 ERROR keystone.server.flask.application   File "/var/lib/kolla/venv/lib/python3.9/site-packages/dogpile/cache/region.py", line 995, in gen_value
2023-04-12 06:43:24.178 38 ERROR keystone.server.flask.application     created_value = creator(
2023-04-12 06:43:24.178 38 ERROR keystone.server.flask.application   File "/var/lib/kolla/venv/lib/python3.9/site-packages/keystone/identity/core.py", line 1011, in get_user
2023-04-12 06:43:24.178 38 ERROR keystone.server.flask.application     ref = driver.get_user(entity_id)
2023-04-12 06:43:24.178 38 ERROR keystone.server.flask.application   File "/var/lib/kolla/venv/lib/python3.9/site-packages/keystone/identity/backends/sql.py", line 200, in get_user
2023-04-12 06:43:24.178 38 ERROR keystone.server.flask.application     self._get_user(session, user_id).to_dict())
2023-04-12 06:43:24.178 38 ERROR keystone.server.flask.application   File "/var/lib/kolla/venv/lib/python3.9/site-packages/keystone/identity/backends/sql.py", line 194, in _get_user
2023-04-12 06:43:24.178 38 ERROR keystone.server.flask.application     raise exception.UserNotFound(user_id=user_id)
2023-04-12 06:43:24.178 38 ERROR keystone.server.flask.application keystone.exception.UserNotFound: Could not find user: ironic.
2023-04-12 06:43:24.178 38 ERROR keystone.server.flask.application 
2023-04-12 06:43:25.106 39 ERROR keystone.server.flask.application [None req-b78e5a2f-afcf-402e-8bd5-d3329462e05e 939ca49fd86e457aa26c99f9e150ded1 - - all default -] Could not find project: service.: keystone.exception.ProjectNotFound: Could not find project: service.
2023-04-12 06:43:25.106 39 ERROR keystone.server.flask.application Traceback (most recent call last):
2023-04-12 06:43:25.106 39 ERROR keystone.server.flask.application   File "/var/lib/kolla/venv/lib/python3.9/site-packages/flask/app.py", line 1820, in full_dispatch_request
2023-04-12 06:43:25.106 39 ERROR keystone.server.flask.application     rv = self.dispatch_request()
2023-04-12 06:43:25.106 39 ERROR keystone.server.flask.application   File "/var/lib/kolla/venv/lib/python3.9/site-packages/flask/app.py", line 1796, in dispatch_request
2023-04-12 06:43:25.106 39 ERROR keystone.server.flask.application     return self.ensure_sync(self.view_functions[rule.endpoint])(**view_args)
2023-04-12 06:43:25.106 39 ERROR keystone.server.flask.application   File "/var/lib/kolla/venv/lib/python3.9/site-packages/flask_restful/__init__.py", line 467, in wrapper
2023-04-12 06:43:25.106 39 ERROR keystone.server.flask.application     resp = resource(*args, **kwargs)
2023-04-12 06:43:25.106 39 ERROR keystone.server.flask.application   File "/var/lib/kolla/venv/lib/python3.9/site-packages/flask/views.py", line 107, in view
2023-04-12 06:43:25.106 39 ERROR keystone.server.flask.application     return current_app.ensure_sync(self.dispatch_request)(**kwargs)
2023-04-12 06:43:25.106 39 ERROR keystone.server.flask.application   File "/var/lib/kolla/venv/lib/python3.9/site-packages/flask_restful/__init__.py", line 582, in dispatch_request
2023-04-12 06:43:25.106 39 ERROR keystone.server.flask.application     resp = meth(*args, **kwargs)
2023-04-12 06:43:25.106 39 ERROR keystone.server.flask.application   File "/var/lib/kolla/venv/lib/python3.9/site-packages/keystone/api/projects.py", line 151, in get
2023-04-12 06:43:25.106 39 ERROR keystone.server.flask.application     return self._get_project(project_id)
2023-04-12 06:43:25.106 39 ERROR keystone.server.flask.application   File "/var/lib/kolla/venv/lib/python3.9/site-packages/keystone/api/projects.py", line 107, in _get_project
2023-04-12 06:43:25.106 39 ERROR keystone.server.flask.application     project = PROVIDERS.resource_api.get_project(project_id)
2023-04-12 06:43:25.106 39 ERROR keystone.server.flask.application   File "/var/lib/kolla/venv/lib/python3.9/site-packages/keystone/common/manager.py", line 115, in wrapped
2023-04-12 06:43:25.106 39 ERROR keystone.server.flask.application     __ret_val = __f(*args, **kwargs)
2023-04-12 06:43:25.106 39 ERROR keystone.server.flask.application   File "/var/lib/kolla/venv/lib/python3.9/site-packages/decorator.py", line 232, in fun
2023-04-12 06:43:25.106 39 ERROR keystone.server.flask.application     return caller(func, *(extras + args), **kw)
2023-04-12 06:43:25.106 39 ERROR keystone.server.flask.application   File "/var/lib/kolla/venv/lib/python3.9/site-packages/dogpile/cache/region.py", line 1577, in get_or_create_for_user_func
2023-04-12 06:43:25.106 39 ERROR keystone.server.flask.application     return self.get_or_create(
2023-04-12 06:43:25.106 39 ERROR keystone.server.flask.application   File "/var/lib/kolla/venv/lib/python3.9/site-packages/dogpile/cache/region.py", line 1042, in get_or_create
2023-04-12 06:43:25.106 39 ERROR keystone.server.flask.application     with Lock(
2023-04-12 06:43:25.106 39 ERROR keystone.server.flask.application   File "/var/lib/kolla/venv/lib/python3.9/site-packages/dogpile/lock.py", line 185, in __enter__
2023-04-12 06:43:25.106 39 ERROR keystone.server.flask.application     return self._enter()
2023-04-12 06:43:25.106 39 ERROR keystone.server.flask.application   File "/var/lib/kolla/venv/lib/python3.9/site-packages/dogpile/lock.py", line 94, in _enter
2023-04-12 06:43:25.106 39 ERROR keystone.server.flask.application     generated = self._enter_create(value, createdtime)
2023-04-12 06:43:25.106 39 ERROR keystone.server.flask.application   File "/var/lib/kolla/venv/lib/python3.9/site-packages/dogpile/lock.py", line 178, in _enter_create
2023-04-12 06:43:25.106 39 ERROR keystone.server.flask.application     return self.creator()
2023-04-12 06:43:25.106 39 ERROR keystone.server.flask.application   File "/var/lib/kolla/venv/lib/python3.9/site-packages/dogpile/cache/region.py", line 995, in gen_value
2023-04-12 06:43:25.106 39 ERROR keystone.server.flask.application     created_value = creator(
2023-04-12 06:43:25.106 39 ERROR keystone.server.flask.application   File "/var/lib/kolla/venv/lib/python3.9/site-packages/keystone/resource/core.py", line 903, in get_project
2023-04-12 06:43:25.106 39 ERROR keystone.server.flask.application     return self.driver.get_project(project_id)
2023-04-12 06:43:25.106 39 ERROR keystone.server.flask.application   File "/var/lib/kolla/venv/lib/python3.9/site-packages/keystone/resource/backends/sql.py", line 49, in get_project
2023-04-12 06:43:25.106 39 ERROR keystone.server.flask.application     return self._get_project(session, project_id).to_dict()
2023-04-12 06:43:25.106 39 ERROR keystone.server.flask.application   File "/var/lib/kolla/venv/lib/python3.9/site-packages/keystone/resource/backends/sql.py", line 44, in _get_project
2023-04-12 06:43:25.106 39 ERROR keystone.server.flask.application     raise exception.ProjectNotFound(project_id=project_id)
2023-04-12 06:43:25.106 39 ERROR keystone.server.flask.application keystone.exception.ProjectNotFound: Could not find project: service.
2023-04-12 06:43:25.106 39 ERROR keystone.server.flask.application 
2023-04-12 06:43:35.105 40 ERROR keystone.server.flask.application [None req-2ed96be8-55e8-443f-bb5d-1aea8354e615 939ca49fd86e457aa26c99f9e150ded1 - - all default -] Could not find role: admin.: keystone.exception.RoleNotFound: Could not find role: admin.
2023-04-12 06:43:35.105 40 ERROR keystone.server.flask.application Traceback (most recent call last):
2023-04-12 06:43:35.105 40 ERROR keystone.server.flask.application   File "/var/lib/kolla/venv/lib/python3.9/site-packages/flask/app.py", line 1820, in full_dispatch_request
2023-04-12 06:43:35.105 40 ERROR keystone.server.flask.application     rv = self.dispatch_request()
2023-04-12 06:43:35.105 40 ERROR keystone.server.flask.application   File "/var/lib/kolla/venv/lib/python3.9/site-packages/flask/app.py", line 1796, in dispatch_request
2023-04-12 06:43:35.105 40 ERROR keystone.server.flask.application     return self.ensure_sync(self.view_functions[rule.endpoint])(**view_args)
2023-04-12 06:43:35.105 40 ERROR keystone.server.flask.application   File "/var/lib/kolla/venv/lib/python3.9/site-packages/flask_restful/__init__.py", line 467, in wrapper
2023-04-12 06:43:35.105 40 ERROR keystone.server.flask.application     resp = resource(*args, **kwargs)
2023-04-12 06:43:35.105 40 ERROR keystone.server.flask.application   File "/var/lib/kolla/venv/lib/python3.9/site-packages/flask/views.py", line 107, in view
2023-04-12 06:43:35.105 40 ERROR keystone.server.flask.application     return current_app.ensure_sync(self.dispatch_request)(**kwargs)
2023-04-12 06:43:35.105 40 ERROR keystone.server.flask.application   File "/var/lib/kolla/venv/lib/python3.9/site-packages/flask_restful/__init__.py", line 582, in dispatch_request
2023-04-12 06:43:35.105 40 ERROR keystone.server.flask.application     resp = meth(*args, **kwargs)
2023-04-12 06:43:35.105 40 ERROR keystone.server.flask.application   File "/var/lib/kolla/venv/lib/python3.9/site-packages/keystone/api/roles.py", line 50, in get
2023-04-12 06:43:35.105 40 ERROR keystone.server.flask.application     return self._get_role(role_id)
2023-04-12 06:43:35.105 40 ERROR keystone.server.flask.application   File "/var/lib/kolla/venv/lib/python3.9/site-packages/keystone/api/roles.py", line 70, in _get_role
2023-04-12 06:43:35.105 40 ERROR keystone.server.flask.application     ENFORCER.enforce_call(action='identity:get_role')
2023-04-12 06:43:35.105 40 ERROR keystone.server.flask.application   File "/var/lib/kolla/venv/lib/python3.9/site-packages/keystone/common/rbac_enforcer/enforcer.py", line 402, in enforce_call
2023-04-12 06:43:35.105 40 ERROR keystone.server.flask.application     policy_dict.update(cls._extract_member_target_data(
2023-04-12 06:43:35.105 40 ERROR keystone.server.flask.application   File "/var/lib/kolla/venv/lib/python3.9/site-packages/keystone/common/rbac_enforcer/enforcer.py", line 234, in _extract_member_target_data
2023-04-12 06:43:35.105 40 ERROR keystone.server.flask.application     member_name: func(flask.request.view_args[key])
2023-04-12 06:43:35.105 40 ERROR keystone.server.flask.application   File "/var/lib/kolla/venv/lib/python3.9/site-packages/keystone/common/manager.py", line 115, in wrapped
2023-04-12 06:43:35.105 40 ERROR keystone.server.flask.application     __ret_val = __f(*args, **kwargs)
2023-04-12 06:43:35.105 40 ERROR keystone.server.flask.application   File "/var/lib/kolla/venv/lib/python3.9/site-packages/decorator.py", line 232, in fun
2023-04-12 06:43:35.105 40 ERROR keystone.server.flask.application     return caller(func, *(extras + args), **kw)
2023-04-12 06:43:35.105 40 ERROR keystone.server.flask.application   File "/var/lib/kolla/venv/lib/python3.9/site-packages/dogpile/cache/region.py", line 1577, in get_or_create_for_user_func
2023-04-12 06:43:35.105 40 ERROR keystone.server.flask.application     return self.get_or_create(
2023-04-12 06:43:35.105 40 ERROR keystone.server.flask.application   File "/var/lib/kolla/venv/lib/python3.9/site-packages/dogpile/cache/region.py", line 1042, in get_or_create
2023-04-12 06:43:35.105 40 ERROR keystone.server.flask.application     with Lock(
2023-04-12 06:43:35.105 40 ERROR keystone.server.flask.application   File "/var/lib/kolla/venv/lib/python3.9/site-packages/dogpile/lock.py", line 185, in __enter__
2023-04-12 06:43:35.105 40 ERROR keystone.server.flask.application     return self._enter()
2023-04-12 06:43:35.105 40 ERROR keystone.server.flask.application   File "/var/lib/kolla/venv/lib/python3.9/site-packages/dogpile/lock.py", line 94, in _enter
2023-04-12 06:43:35.105 40 ERROR keystone.server.flask.application     generated = self._enter_create(value, createdtime)
2023-04-12 06:43:35.105 40 ERROR keystone.server.flask.application   File "/var/lib/kolla/venv/lib/python3.9/site-packages/dogpile/lock.py", line 178, in _enter_create
2023-04-12 06:43:35.105 40 ERROR keystone.server.flask.application     return self.creator()
2023-04-12 06:43:35.105 40 ERROR keystone.server.flask.application   File "/var/lib/kolla/venv/lib/python3.9/site-packages/dogpile/cache/region.py", line 995, in gen_value
2023-04-12 06:43:35.105 40 ERROR keystone.server.flask.application     created_value = creator(
2023-04-12 06:43:35.105 40 ERROR keystone.server.flask.application   File "/var/lib/kolla/venv/lib/python3.9/site-packages/keystone/assignment/core.py", line 1276, in get_role
2023-04-12 06:43:35.105 40 ERROR keystone.server.flask.application     return self.driver.get_role(role_id)
2023-04-12 06:43:35.105 40 ERROR keystone.server.flask.application   File "/var/lib/kolla/venv/lib/python3.9/site-packages/keystone/assignment/role_backends/sql.py", line 70, in get_role
2023-04-12 06:43:35.105 40 ERROR keystone.server.flask.application     return self._get_role(session, role_id).to_dict()
2023-04-12 06:43:35.105 40 ERROR keystone.server.flask.application   File "/var/lib/kolla/venv/lib/python3.9/site-packages/keystone/assignment/role_backends/sql.py", line 65, in _get_role
2023-04-12 06:43:35.105 40 ERROR keystone.server.flask.application     raise exception.RoleNotFound(role_id=role_id)
2023-04-12 06:43:35.105 40 ERROR keystone.server.flask.application keystone.exception.RoleNotFound: Could not find role: admin.
2023-04-12 06:43:35.105 40 ERROR keystone.server.flask.application 
2023-04-12 06:43:36.331 40 ERROR keystone.server.flask.application [None req-69e4ceeb-2110-4590-b433-e4cf1bb15dca 939ca49fd86e457aa26c99f9e150ded1 - - all default -] Could not find user: ironic-inspector.: keystone.exception.UserNotFound: Could not find user: ironic-inspector.
2023-04-12 06:43:36.331 40 ERROR keystone.server.flask.application Traceback (most recent call last):
2023-04-12 06:43:36.331 40 ERROR keystone.server.flask.application   File "/var/lib/kolla/venv/lib/python3.9/site-packages/flask/app.py", line 1820, in full_dispatch_request
2023-04-12 06:43:36.331 40 ERROR keystone.server.flask.application     rv = self.dispatch_request()
2023-04-12 06:43:36.331 40 ERROR keystone.server.flask.application   File "/var/lib/kolla/venv/lib/python3.9/site-packages/flask/app.py", line 1796, in dispatch_request
2023-04-12 06:43:36.331 40 ERROR keystone.server.flask.application     return self.ensure_sync(self.view_functions[rule.endpoint])(**view_args)
2023-04-12 06:43:36.331 40 ERROR keystone.server.flask.application   File "/var/lib/kolla/venv/lib/python3.9/site-packages/flask_restful/__init__.py", line 467, in wrapper
2023-04-12 06:43:36.331 40 ERROR keystone.server.flask.application     resp = resource(*args, **kwargs)
2023-04-12 06:43:36.331 40 ERROR keystone.server.flask.application   File "/var/lib/kolla/venv/lib/python3.9/site-packages/flask/views.py", line 107, in view
2023-04-12 06:43:36.331 40 ERROR keystone.server.flask.application     return current_app.ensure_sync(self.dispatch_request)(**kwargs)
2023-04-12 06:43:36.331 40 ERROR keystone.server.flask.application   File "/var/lib/kolla/venv/lib/python3.9/site-packages/flask_restful/__init__.py", line 582, in dispatch_request
2023-04-12 06:43:36.331 40 ERROR keystone.server.flask.application     resp = meth(*args, **kwargs)
2023-04-12 06:43:36.331 40 ERROR keystone.server.flask.application   File "/var/lib/kolla/venv/lib/python3.9/site-packages/keystone/api/users.py", line 182, in get
2023-04-12 06:43:36.331 40 ERROR keystone.server.flask.application     return self._get_user(user_id)
2023-04-12 06:43:36.331 40 ERROR keystone.server.flask.application   File "/var/lib/kolla/venv/lib/python3.9/site-packages/keystone/api/users.py", line 194, in _get_user
2023-04-12 06:43:36.331 40 ERROR keystone.server.flask.application     ref = PROVIDERS.identity_api.get_user(user_id)
2023-04-12 06:43:36.331 40 ERROR keystone.server.flask.application   File "/var/lib/kolla/venv/lib/python3.9/site-packages/keystone/common/manager.py", line 115, in wrapped
2023-04-12 06:43:36.331 40 ERROR keystone.server.flask.application     __ret_val = __f(*args, **kwargs)
2023-04-12 06:43:36.331 40 ERROR keystone.server.flask.application   File "/var/lib/kolla/venv/lib/python3.9/site-packages/keystone/identity/core.py", line 414, in wrapper
2023-04-12 06:43:36.331 40 ERROR keystone.server.flask.application     return f(self, *args, **kwargs)
2023-04-12 06:43:36.331 40 ERROR keystone.server.flask.application   File "/var/lib/kolla/venv/lib/python3.9/site-packages/keystone/identity/core.py", line 424, in wrapper
2023-04-12 06:43:36.331 40 ERROR keystone.server.flask.application     return f(self, *args, **kwargs)
2023-04-12 06:43:36.331 40 ERROR keystone.server.flask.application   File "/var/lib/kolla/venv/lib/python3.9/site-packages/decorator.py", line 232, in fun
2023-04-12 06:43:36.331 40 ERROR keystone.server.flask.application     return caller(func, *(extras + args), **kw)
2023-04-12 06:43:36.331 40 ERROR keystone.server.flask.application   File "/var/lib/kolla/venv/lib/python3.9/site-packages/dogpile/cache/region.py", line 1577, in get_or_create_for_user_func
2023-04-12 06:43:36.331 40 ERROR keystone.server.flask.application     return self.get_or_create(
2023-04-12 06:43:36.331 40 ERROR keystone.server.flask.application   File "/var/lib/kolla/venv/lib/python3.9/site-packages/dogpile/cache/region.py", line 1042, in get_or_create
2023-04-12 06:43:36.331 40 ERROR keystone.server.flask.application     with Lock(
2023-04-12 06:43:36.331 40 ERROR keystone.server.flask.application   File "/var/lib/kolla/venv/lib/python3.9/site-packages/dogpile/lock.py", line 185, in __enter__
2023-04-12 06:43:36.331 40 ERROR keystone.server.flask.application     return self._enter()
2023-04-12 06:43:36.331 40 ERROR keystone.server.flask.application   File "/var/lib/kolla/venv/lib/python3.9/site-packages/dogpile/lock.py", line 94, in _enter
2023-04-12 06:43:36.331 40 ERROR keystone.server.flask.application     generated = self._enter_create(value, createdtime)
2023-04-12 06:43:36.331 40 ERROR keystone.server.flask.application   File "/var/lib/kolla/venv/lib/python3.9/site-packages/dogpile/lock.py", line 178, in _enter_create
2023-04-12 06:43:36.331 40 ERROR keystone.server.flask.application     return self.creator()
2023-04-12 06:43:36.331 40 ERROR keystone.server.flask.application   File "/var/lib/kolla/venv/lib/python3.9/site-packages/dogpile/cache/region.py", line 995, in gen_value
2023-04-12 06:43:36.331 40 ERROR keystone.server.flask.application     created_value = creator(
2023-04-12 06:43:36.331 40 ERROR keystone.server.flask.application   File "/var/lib/kolla/venv/lib/python3.9/site-packages/keystone/identity/core.py", line 1011, in get_user
2023-04-12 06:43:36.331 40 ERROR keystone.server.flask.application     ref = driver.get_user(entity_id)
2023-04-12 06:43:36.331 40 ERROR keystone.server.flask.application   File "/var/lib/kolla/venv/lib/python3.9/site-packages/keystone/identity/backends/sql.py", line 200, in get_user
2023-04-12 06:43:36.331 40 ERROR keystone.server.flask.application     self._get_user(session, user_id).to_dict())
2023-04-12 06:43:36.331 40 ERROR keystone.server.flask.application   File "/var/lib/kolla/venv/lib/python3.9/site-packages/keystone/identity/backends/sql.py", line 194, in _get_user
2023-04-12 06:43:36.331 40 ERROR keystone.server.flask.application     raise exception.UserNotFound(user_id=user_id)
2023-04-12 06:43:36.331 40 ERROR keystone.server.flask.application keystone.exception.UserNotFound: Could not find user: ironic-inspector.
2023-04-12 06:43:36.331 40 ERROR keystone.server.flask.application 
2023-04-12 06:43:37.278 38 ERROR keystone.server.flask.application [None req-19c1f871-04e0-409e-a519-4f9bf5a926cd 939ca49fd86e457aa26c99f9e150ded1 - - all default -] Could not find project: service.: keystone.exception.ProjectNotFound: Could not find project: service.
2023-04-12 06:43:37.278 38 ERROR keystone.server.flask.application Traceback (most recent call last):
2023-04-12 06:43:37.278 38 ERROR keystone.server.flask.application   File "/var/lib/kolla/venv/lib/python3.9/site-packages/flask/app.py", line 1820, in full_dispatch_request
2023-04-12 06:43:37.278 38 ERROR keystone.server.flask.application     rv = self.dispatch_request()
2023-04-12 06:43:37.278 38 ERROR keystone.server.flask.application   File "/var/lib/kolla/venv/lib/python3.9/site-packages/flask/app.py", line 1796, in dispatch_request
2023-04-12 06:43:37.278 38 ERROR keystone.server.flask.application     return self.ensure_sync(self.view_functions[rule.endpoint])(**view_args)
2023-04-12 06:43:37.278 38 ERROR keystone.server.flask.application   File "/var/lib/kolla/venv/lib/python3.9/site-packages/flask_restful/__init__.py", line 467, in wrapper
2023-04-12 06:43:37.278 38 ERROR keystone.server.flask.application     resp = resource(*args, **kwargs)
2023-04-12 06:43:37.278 38 ERROR keystone.server.flask.application   File "/var/lib/kolla/venv/lib/python3.9/site-packages/flask/views.py", line 107, in view
2023-04-12 06:43:37.278 38 ERROR keystone.server.flask.application     return current_app.ensure_sync(self.dispatch_request)(**kwargs)
2023-04-12 06:43:37.278 38 ERROR keystone.server.flask.application   File "/var/lib/kolla/venv/lib/python3.9/site-packages/flask_restful/__init__.py", line 582, in dispatch_request
2023-04-12 06:43:37.278 38 ERROR keystone.server.flask.application     resp = meth(*args, **kwargs)
2023-04-12 06:43:37.278 38 ERROR keystone.server.flask.application   File "/var/lib/kolla/venv/lib/python3.9/site-packages/keystone/api/projects.py", line 151, in get
2023-04-12 06:43:37.278 38 ERROR keystone.server.flask.application     return self._get_project(project_id)
2023-04-12 06:43:37.278 38 ERROR keystone.server.flask.application   File "/var/lib/kolla/venv/lib/python3.9/site-packages/keystone/api/projects.py", line 107, in _get_project
2023-04-12 06:43:37.278 38 ERROR keystone.server.flask.application     project = PROVIDERS.resource_api.get_project(project_id)
2023-04-12 06:43:37.278 38 ERROR keystone.server.flask.application   File "/var/lib/kolla/venv/lib/python3.9/site-packages/keystone/common/manager.py", line 115, in wrapped
2023-04-12 06:43:37.278 38 ERROR keystone.server.flask.application     __ret_val = __f(*args, **kwargs)
2023-04-12 06:43:37.278 38 ERROR keystone.server.flask.application   File "/var/lib/kolla/venv/lib/python3.9/site-packages/decorator.py", line 232, in fun
2023-04-12 06:43:37.278 38 ERROR keystone.server.flask.application     return caller(func, *(extras + args), **kw)
2023-04-12 06:43:37.278 38 ERROR keystone.server.flask.application   File "/var/lib/kolla/venv/lib/python3.9/site-packages/dogpile/cache/region.py", line 1577, in get_or_create_for_user_func
2023-04-12 06:43:37.278 38 ERROR keystone.server.flask.application     return self.get_or_create(
2023-04-12 06:43:37.278 38 ERROR keystone.server.flask.application   File "/var/lib/kolla/venv/lib/python3.9/site-packages/dogpile/cache/region.py", line 1042, in get_or_create
2023-04-12 06:43:37.278 38 ERROR keystone.server.flask.application     with Lock(
2023-04-12 06:43:37.278 38 ERROR keystone.server.flask.application   File "/var/lib/kolla/venv/lib/python3.9/site-packages/dogpile/lock.py", line 185, in __enter__
2023-04-12 06:43:37.278 38 ERROR keystone.server.flask.application     return self._enter()
2023-04-12 06:43:37.278 38 ERROR keystone.server.flask.application   File "/var/lib/kolla/venv/lib/python3.9/site-packages/dogpile/lock.py", line 94, in _enter
2023-04-12 06:43:37.278 38 ERROR keystone.server.flask.application     generated = self._enter_create(value, createdtime)
2023-04-12 06:43:37.278 38 ERROR keystone.server.flask.application   File "/var/lib/kolla/venv/lib/python3.9/site-packages/dogpile/lock.py", line 178, in _enter_create
2023-04-12 06:43:37.278 38 ERROR keystone.server.flask.application     return self.creator()
2023-04-12 06:43:37.278 38 ERROR keystone.server.flask.application   File "/var/lib/kolla/venv/lib/python3.9/site-packages/dogpile/cache/region.py", line 995, in gen_value
2023-04-12 06:43:37.278 38 ERROR keystone.server.flask.application     created_value = creator(
2023-04-12 06:43:37.278 38 ERROR keystone.server.flask.application   File "/var/lib/kolla/venv/lib/python3.9/site-packages/keystone/resource/core.py", line 903, in get_project
2023-04-12 06:43:37.278 38 ERROR keystone.server.flask.application     return self.driver.get_project(project_id)
2023-04-12 06:43:37.278 38 ERROR keystone.server.flask.application   File "/var/lib/kolla/venv/lib/python3.9/site-packages/keystone/resource/backends/sql.py", line 49, in get_project
2023-04-12 06:43:37.278 38 ERROR keystone.server.flask.application     return self._get_project(session, project_id).to_dict()
2023-04-12 06:43:37.278 38 ERROR keystone.server.flask.application   File "/var/lib/kolla/venv/lib/python3.9/site-packages/keystone/resource/backends/sql.py", line 44, in _get_project
2023-04-12 06:43:37.278 38 ERROR keystone.server.flask.application     raise exception.ProjectNotFound(project_id=project_id)
2023-04-12 06:43:37.278 38 ERROR keystone.server.flask.application keystone.exception.ProjectNotFound: Could not find project: service.
2023-04-12 06:43:37.278 38 ERROR keystone.server.flask.application 
2023-04-12 06:46:28.493 38 ERROR keystone.server.flask.application [None req-734544ff-7edb-447c-bad9-30f8591edf63 939ca49fd86e457aa26c99f9e150ded1 - - all default -] Could not find project: service.: keystone.exception.ProjectNotFound: Could not find project: service.
2023-04-12 06:46:28.493 38 ERROR keystone.server.flask.application Traceback (most recent call last):
2023-04-12 06:46:28.493 38 ERROR keystone.server.flask.application   File "/var/lib/kolla/venv/lib/python3.9/site-packages/flask/app.py", line 1820, in full_dispatch_request
2023-04-12 06:46:28.493 38 ERROR keystone.server.flask.application     rv = self.dispatch_request()
2023-04-12 06:46:28.493 38 ERROR keystone.server.flask.application   File "/var/lib/kolla/venv/lib/python3.9/site-packages/flask/app.py", line 1796, in dispatch_request
2023-04-12 06:46:28.493 38 ERROR keystone.server.flask.application     return self.ensure_sync(self.view_functions[rule.endpoint])(**view_args)
2023-04-12 06:46:28.493 38 ERROR keystone.server.flask.application   File "/var/lib/kolla/venv/lib/python3.9/site-packages/flask_restful/__init__.py", line 467, in wrapper
2023-04-12 06:46:28.493 38 ERROR keystone.server.flask.application     resp = resource(*args, **kwargs)
2023-04-12 06:46:28.493 38 ERROR keystone.server.flask.application   File "/var/lib/kolla/venv/lib/python3.9/site-packages/flask/views.py", line 107, in view
2023-04-12 06:46:28.493 38 ERROR keystone.server.flask.application     return current_app.ensure_sync(self.dispatch_request)(**kwargs)
2023-04-12 06:46:28.493 38 ERROR keystone.server.flask.application   File "/var/lib/kolla/venv/lib/python3.9/site-packages/flask_restful/__init__.py", line 582, in dispatch_request
2023-04-12 06:46:28.493 38 ERROR keystone.server.flask.application     resp = meth(*args, **kwargs)
2023-04-12 06:46:28.493 38 ERROR keystone.server.flask.application   File "/var/lib/kolla/venv/lib/python3.9/site-packages/keystone/api/projects.py", line 151, in get
2023-04-12 06:46:28.493 38 ERROR keystone.server.flask.application     return self._get_project(project_id)
2023-04-12 06:46:28.493 38 ERROR keystone.server.flask.application   File "/var/lib/kolla/venv/lib/python3.9/site-packages/keystone/api/projects.py", line 107, in _get_project
2023-04-12 06:46:28.493 38 ERROR keystone.server.flask.application     project = PROVIDERS.resource_api.get_project(project_id)
2023-04-12 06:46:28.493 38 ERROR keystone.server.flask.application   File "/var/lib/kolla/venv/lib/python3.9/site-packages/keystone/common/manager.py", line 115, in wrapped
2023-04-12 06:46:28.493 38 ERROR keystone.server.flask.application     __ret_val = __f(*args, **kwargs)
2023-04-12 06:46:28.493 38 ERROR keystone.server.flask.application   File "/var/lib/kolla/venv/lib/python3.9/site-packages/decorator.py", line 232, in fun
2023-04-12 06:46:28.493 38 ERROR keystone.server.flask.application     return caller(func, *(extras + args), **kw)
2023-04-12 06:46:28.493 38 ERROR keystone.server.flask.application   File "/var/lib/kolla/venv/lib/python3.9/site-packages/dogpile/cache/region.py", line 1577, in get_or_create_for_user_func
2023-04-12 06:46:28.493 38 ERROR keystone.server.flask.application     return self.get_or_create(
2023-04-12 06:46:28.493 38 ERROR keystone.server.flask.application   File "/var/lib/kolla/venv/lib/python3.9/site-packages/dogpile/cache/region.py", line 1042, in get_or_create
2023-04-12 06:46:28.493 38 ERROR keystone.server.flask.application     with Lock(
2023-04-12 06:46:28.493 38 ERROR keystone.server.flask.application   File "/var/lib/kolla/venv/lib/python3.9/site-packages/dogpile/lock.py", line 185, in __enter__
2023-04-12 06:46:28.493 38 ERROR keystone.server.flask.application     return self._enter()
2023-04-12 06:46:28.493 38 ERROR keystone.server.flask.application   File "/var/lib/kolla/venv/lib/python3.9/site-packages/dogpile/lock.py", line 94, in _enter
2023-04-12 06:46:28.493 38 ERROR keystone.server.flask.application     generated = self._enter_create(value, createdtime)
2023-04-12 06:46:28.493 38 ERROR keystone.server.flask.application   File "/var/lib/kolla/venv/lib/python3.9/site-packages/dogpile/lock.py", line 178, in _enter_create
2023-04-12 06:46:28.493 38 ERROR keystone.server.flask.application     return self.creator()
2023-04-12 06:46:28.493 38 ERROR keystone.server.flask.application   File "/var/lib/kolla/venv/lib/python3.9/site-packages/dogpile/cache/region.py", line 995, in gen_value
2023-04-12 06:46:28.493 38 ERROR keystone.server.flask.application     created_value = creator(
2023-04-12 06:46:28.493 38 ERROR keystone.server.flask.application   File "/var/lib/kolla/venv/lib/python3.9/site-packages/keystone/resource/core.py", line 903, in get_project
2023-04-12 06:46:28.493 38 ERROR keystone.server.flask.application     return self.driver.get_project(project_id)
2023-04-12 06:46:28.493 38 ERROR keystone.server.flask.application   File "/var/lib/kolla/venv/lib/python3.9/site-packages/keystone/resource/backends/sql.py", line 49, in get_project
2023-04-12 06:46:28.493 38 ERROR keystone.server.flask.application     return self._get_project(session, project_id).to_dict()
2023-04-12 06:46:28.493 38 ERROR keystone.server.flask.application   File "/var/lib/kolla/venv/lib/python3.9/site-packages/keystone/resource/backends/sql.py", line 44, in _get_project
2023-04-12 06:46:28.493 38 ERROR keystone.server.flask.application     raise exception.ProjectNotFound(project_id=project_id)
2023-04-12 06:46:28.493 38 ERROR keystone.server.flask.application keystone.exception.ProjectNotFound: Could not find project: service.
2023-04-12 06:46:28.493 38 ERROR keystone.server.flask.application 
2023-04-12 06:46:43.209 40 ERROR keystone.server.flask.application [None req-911bfa9b-aeb8-44b8-9eec-d15d31a64bb8 939ca49fd86e457aa26c99f9e150ded1 - - all default -] Could not find role: admin.: keystone.exception.RoleNotFound: Could not find role: admin.
2023-04-12 06:46:43.209 40 ERROR keystone.server.flask.application Traceback (most recent call last):
2023-04-12 06:46:43.209 40 ERROR keystone.server.flask.application   File "/var/lib/kolla/venv/lib/python3.9/site-packages/flask/app.py", line 1820, in full_dispatch_request
2023-04-12 06:46:43.209 40 ERROR keystone.server.flask.application     rv = self.dispatch_request()
2023-04-12 06:46:43.209 40 ERROR keystone.server.flask.application   File "/var/lib/kolla/venv/lib/python3.9/site-packages/flask/app.py", line 1796, in dispatch_request
2023-04-12 06:46:43.209 40 ERROR keystone.server.flask.application     return self.ensure_sync(self.view_functions[rule.endpoint])(**view_args)
2023-04-12 06:46:43.209 40 ERROR keystone.server.flask.application   File "/var/lib/kolla/venv/lib/python3.9/site-packages/flask_restful/__init__.py", line 467, in wrapper
2023-04-12 06:46:43.209 40 ERROR keystone.server.flask.application     resp = resource(*args, **kwargs)
2023-04-12 06:46:43.209 40 ERROR keystone.server.flask.application   File "/var/lib/kolla/venv/lib/python3.9/site-packages/flask/views.py", line 107, in view
2023-04-12 06:46:43.209 40 ERROR keystone.server.flask.application     return current_app.ensure_sync(self.dispatch_request)(**kwargs)
2023-04-12 06:46:43.209 40 ERROR keystone.server.flask.application   File "/var/lib/kolla/venv/lib/python3.9/site-packages/flask_restful/__init__.py", line 582, in dispatch_request
2023-04-12 06:46:43.209 40 ERROR keystone.server.flask.application     resp = meth(*args, **kwargs)
2023-04-12 06:46:43.209 40 ERROR keystone.server.flask.application   File "/var/lib/kolla/venv/lib/python3.9/site-packages/keystone/api/roles.py", line 50, in get
2023-04-12 06:46:43.209 40 ERROR keystone.server.flask.application     return self._get_role(role_id)
2023-04-12 06:46:43.209 40 ERROR keystone.server.flask.application   File "/var/lib/kolla/venv/lib/python3.9/site-packages/keystone/api/roles.py", line 70, in _get_role
2023-04-12 06:46:43.209 40 ERROR keystone.server.flask.application     ENFORCER.enforce_call(action='identity:get_role')
2023-04-12 06:46:43.209 40 ERROR keystone.server.flask.application   File "/var/lib/kolla/venv/lib/python3.9/site-packages/keystone/common/rbac_enforcer/enforcer.py", line 402, in enforce_call
2023-04-12 06:46:43.209 40 ERROR keystone.server.flask.application     policy_dict.update(cls._extract_member_target_data(
2023-04-12 06:46:43.209 40 ERROR keystone.server.flask.application   File "/var/lib/kolla/venv/lib/python3.9/site-packages/keystone/common/rbac_enforcer/enforcer.py", line 234, in _extract_member_target_data
2023-04-12 06:46:43.209 40 ERROR keystone.server.flask.application     member_name: func(flask.request.view_args[key])
2023-04-12 06:46:43.209 40 ERROR keystone.server.flask.application   File "/var/lib/kolla/venv/lib/python3.9/site-packages/keystone/common/manager.py", line 115, in wrapped
2023-04-12 06:46:43.209 40 ERROR keystone.server.flask.application     __ret_val = __f(*args, **kwargs)
2023-04-12 06:46:43.209 40 ERROR keystone.server.flask.application   File "/var/lib/kolla/venv/lib/python3.9/site-packages/decorator.py", line 232, in fun
2023-04-12 06:46:43.209 40 ERROR keystone.server.flask.application     return caller(func, *(extras + args), **kw)
2023-04-12 06:46:43.209 40 ERROR keystone.server.flask.application   File "/var/lib/kolla/venv/lib/python3.9/site-packages/dogpile/cache/region.py", line 1577, in get_or_create_for_user_func
2023-04-12 06:46:43.209 40 ERROR keystone.server.flask.application     return self.get_or_create(
2023-04-12 06:46:43.209 40 ERROR keystone.server.flask.application   File "/var/lib/kolla/venv/lib/python3.9/site-packages/dogpile/cache/region.py", line 1042, in get_or_create
2023-04-12 06:46:43.209 40 ERROR keystone.server.flask.application     with Lock(
2023-04-12 06:46:43.209 40 ERROR keystone.server.flask.application   File "/var/lib/kolla/venv/lib/python3.9/site-packages/dogpile/lock.py", line 185, in __enter__
2023-04-12 06:46:43.209 40 ERROR keystone.server.flask.application     return self._enter()
2023-04-12 06:46:43.209 40 ERROR keystone.server.flask.application   File "/var/lib/kolla/venv/lib/python3.9/site-packages/dogpile/lock.py", line 94, in _enter
2023-04-12 06:46:43.209 40 ERROR keystone.server.flask.application     generated = self._enter_create(value, createdtime)
2023-04-12 06:46:43.209 40 ERROR keystone.server.flask.application   File "/var/lib/kolla/venv/lib/python3.9/site-packages/dogpile/lock.py", line 178, in _enter_create
2023-04-12 06:46:43.209 40 ERROR keystone.server.flask.application     return self.creator()
2023-04-12 06:46:43.209 40 ERROR keystone.server.flask.application   File "/var/lib/kolla/venv/lib/python3.9/site-packages/dogpile/cache/region.py", line 995, in gen_value
2023-04-12 06:46:43.209 40 ERROR keystone.server.flask.application     created_value = creator(
2023-04-12 06:46:43.209 40 ERROR keystone.server.flask.application   File "/var/lib/kolla/venv/lib/python3.9/site-packages/keystone/assignment/core.py", line 1276, in get_role
2023-04-12 06:46:43.209 40 ERROR keystone.server.flask.application     return self.driver.get_role(role_id)
2023-04-12 06:46:43.209 40 ERROR keystone.server.flask.application   File "/var/lib/kolla/venv/lib/python3.9/site-packages/keystone/assignment/role_backends/sql.py", line 70, in get_role
2023-04-12 06:46:43.209 40 ERROR keystone.server.flask.application     return self._get_role(session, role_id).to_dict()
2023-04-12 06:46:43.209 40 ERROR keystone.server.flask.application   File "/var/lib/kolla/venv/lib/python3.9/site-packages/keystone/assignment/role_backends/sql.py", line 65, in _get_role
2023-04-12 06:46:43.209 40 ERROR keystone.server.flask.application     raise exception.RoleNotFound(role_id=role_id)
2023-04-12 06:46:43.209 40 ERROR keystone.server.flask.application keystone.exception.RoleNotFound: Could not find role: admin.
2023-04-12 06:46:43.209 40 ERROR keystone.server.flask.application 
2023-04-12 06:46:44.356 40 ERROR keystone.server.flask.application [None req-6594d9ed-04eb-4c0f-a8be-b809a7171db5 939ca49fd86e457aa26c99f9e150ded1 - - all default -] Could not find user: neutron.: keystone.exception.UserNotFound: Could not find user: neutron.
2023-04-12 06:46:44.356 40 ERROR keystone.server.flask.application Traceback (most recent call last):
2023-04-12 06:46:44.356 40 ERROR keystone.server.flask.application   File "/var/lib/kolla/venv/lib/python3.9/site-packages/flask/app.py", line 1820, in full_dispatch_request
2023-04-12 06:46:44.356 40 ERROR keystone.server.flask.application     rv = self.dispatch_request()
2023-04-12 06:46:44.356 40 ERROR keystone.server.flask.application   File "/var/lib/kolla/venv/lib/python3.9/site-packages/flask/app.py", line 1796, in dispatch_request
2023-04-12 06:46:44.356 40 ERROR keystone.server.flask.application     return self.ensure_sync(self.view_functions[rule.endpoint])(**view_args)
2023-04-12 06:46:44.356 40 ERROR keystone.server.flask.application   File "/var/lib/kolla/venv/lib/python3.9/site-packages/flask_restful/__init__.py", line 467, in wrapper
2023-04-12 06:46:44.356 40 ERROR keystone.server.flask.application     resp = resource(*args, **kwargs)
2023-04-12 06:46:44.356 40 ERROR keystone.server.flask.application   File "/var/lib/kolla/venv/lib/python3.9/site-packages/flask/views.py", line 107, in view
2023-04-12 06:46:44.356 40 ERROR keystone.server.flask.application     return current_app.ensure_sync(self.dispatch_request)(**kwargs)
2023-04-12 06:46:44.356 40 ERROR keystone.server.flask.application   File "/var/lib/kolla/venv/lib/python3.9/site-packages/flask_restful/__init__.py", line 582, in dispatch_request
2023-04-12 06:46:44.356 40 ERROR keystone.server.flask.application     resp = meth(*args, **kwargs)
2023-04-12 06:46:44.356 40 ERROR keystone.server.flask.application   File "/var/lib/kolla/venv/lib/python3.9/site-packages/keystone/api/users.py", line 182, in get
2023-04-12 06:46:44.356 40 ERROR keystone.server.flask.application     return self._get_user(user_id)
2023-04-12 06:46:44.356 40 ERROR keystone.server.flask.application   File "/var/lib/kolla/venv/lib/python3.9/site-packages/keystone/api/users.py", line 194, in _get_user
2023-04-12 06:46:44.356 40 ERROR keystone.server.flask.application     ref = PROVIDERS.identity_api.get_user(user_id)
2023-04-12 06:46:44.356 40 ERROR keystone.server.flask.application   File "/var/lib/kolla/venv/lib/python3.9/site-packages/keystone/common/manager.py", line 115, in wrapped
2023-04-12 06:46:44.356 40 ERROR keystone.server.flask.application     __ret_val = __f(*args, **kwargs)
2023-04-12 06:46:44.356 40 ERROR keystone.server.flask.application   File "/var/lib/kolla/venv/lib/python3.9/site-packages/keystone/identity/core.py", line 414, in wrapper
2023-04-12 06:46:44.356 40 ERROR keystone.server.flask.application     return f(self, *args, **kwargs)
2023-04-12 06:46:44.356 40 ERROR keystone.server.flask.application   File "/var/lib/kolla/venv/lib/python3.9/site-packages/keystone/identity/core.py", line 424, in wrapper
2023-04-12 06:46:44.356 40 ERROR keystone.server.flask.application     return f(self, *args, **kwargs)
2023-04-12 06:46:44.356 40 ERROR keystone.server.flask.application   File "/var/lib/kolla/venv/lib/python3.9/site-packages/decorator.py", line 232, in fun
2023-04-12 06:46:44.356 40 ERROR keystone.server.flask.application     return caller(func, *(extras + args), **kw)
2023-04-12 06:46:44.356 40 ERROR keystone.server.flask.application   File "/var/lib/kolla/venv/lib/python3.9/site-packages/dogpile/cache/region.py", line 1577, in get_or_create_for_user_func
2023-04-12 06:46:44.356 40 ERROR keystone.server.flask.application     return self.get_or_create(
2023-04-12 06:46:44.356 40 ERROR keystone.server.flask.application   File "/var/lib/kolla/venv/lib/python3.9/site-packages/dogpile/cache/region.py", line 1042, in get_or_create
2023-04-12 06:46:44.356 40 ERROR keystone.server.flask.application     with Lock(
2023-04-12 06:46:44.356 40 ERROR keystone.server.flask.application   File "/var/lib/kolla/venv/lib/python3.9/site-packages/dogpile/lock.py", line 185, in __enter__
2023-04-12 06:46:44.356 40 ERROR keystone.server.flask.application     return self._enter()
2023-04-12 06:46:44.356 40 ERROR keystone.server.flask.application   File "/var/lib/kolla/venv/lib/python3.9/site-packages/dogpile/lock.py", line 94, in _enter
2023-04-12 06:46:44.356 40 ERROR keystone.server.flask.application     generated = self._enter_create(value, createdtime)
2023-04-12 06:46:44.356 40 ERROR keystone.server.flask.application   File "/var/lib/kolla/venv/lib/python3.9/site-packages/dogpile/lock.py", line 178, in _enter_create
2023-04-12 06:46:44.356 40 ERROR keystone.server.flask.application     return self.creator()
2023-04-12 06:46:44.356 40 ERROR keystone.server.flask.application   File "/var/lib/kolla/venv/lib/python3.9/site-packages/dogpile/cache/region.py", line 995, in gen_value
2023-04-12 06:46:44.356 40 ERROR keystone.server.flask.application     created_value = creator(
2023-04-12 06:46:44.356 40 ERROR keystone.server.flask.application   File "/var/lib/kolla/venv/lib/python3.9/site-packages/keystone/identity/core.py", line 1011, in get_user
2023-04-12 06:46:44.356 40 ERROR keystone.server.flask.application     ref = driver.get_user(entity_id)
2023-04-12 06:46:44.356 40 ERROR keystone.server.flask.application   File "/var/lib/kolla/venv/lib/python3.9/site-packages/keystone/identity/backends/sql.py", line 200, in get_user
2023-04-12 06:46:44.356 40 ERROR keystone.server.flask.application     self._get_user(session, user_id).to_dict())
2023-04-12 06:46:44.356 40 ERROR keystone.server.flask.application   File "/var/lib/kolla/venv/lib/python3.9/site-packages/keystone/identity/backends/sql.py", line 194, in _get_user
2023-04-12 06:46:44.356 40 ERROR keystone.server.flask.application     raise exception.UserNotFound(user_id=user_id)
2023-04-12 06:46:44.356 40 ERROR keystone.server.flask.application keystone.exception.UserNotFound: Could not find user: neutron.
2023-04-12 06:46:44.356 40 ERROR keystone.server.flask.application 
2023-04-12 06:46:45.060 39 ERROR keystone.server.flask.application [None req-560964f9-7cfb-4013-a233-d7296b38b7c4 939ca49fd86e457aa26c99f9e150ded1 - - all default -] Could not find project: service.: keystone.exception.ProjectNotFound: Could not find project: service.
2023-04-12 06:46:45.060 39 ERROR keystone.server.flask.application Traceback (most recent call last):
2023-04-12 06:46:45.060 39 ERROR keystone.server.flask.application   File "/var/lib/kolla/venv/lib/python3.9/site-packages/flask/app.py", line 1820, in full_dispatch_request
2023-04-12 06:46:45.060 39 ERROR keystone.server.flask.application     rv = self.dispatch_request()
2023-04-12 06:46:45.060 39 ERROR keystone.server.flask.application   File "/var/lib/kolla/venv/lib/python3.9/site-packages/flask/app.py", line 1796, in dispatch_request
2023-04-12 06:46:45.060 39 ERROR keystone.server.flask.application     return self.ensure_sync(self.view_functions[rule.endpoint])(**view_args)
2023-04-12 06:46:45.060 39 ERROR keystone.server.flask.application   File "/var/lib/kolla/venv/lib/python3.9/site-packages/flask_restful/__init__.py", line 467, in wrapper
2023-04-12 06:46:45.060 39 ERROR keystone.server.flask.application     resp = resource(*args, **kwargs)
2023-04-12 06:46:45.060 39 ERROR keystone.server.flask.application   File "/var/lib/kolla/venv/lib/python3.9/site-packages/flask/views.py", line 107, in view
2023-04-12 06:46:45.060 39 ERROR keystone.server.flask.application     return current_app.ensure_sync(self.dispatch_request)(**kwargs)
2023-04-12 06:46:45.060 39 ERROR keystone.server.flask.application   File "/var/lib/kolla/venv/lib/python3.9/site-packages/flask_restful/__init__.py", line 582, in dispatch_request
2023-04-12 06:46:45.060 39 ERROR keystone.server.flask.application     resp = meth(*args, **kwargs)
2023-04-12 06:46:45.060 39 ERROR keystone.server.flask.application   File "/var/lib/kolla/venv/lib/python3.9/site-packages/keystone/api/projects.py", line 151, in get
2023-04-12 06:46:45.060 39 ERROR keystone.server.flask.application     return self._get_project(project_id)
2023-04-12 06:46:45.060 39 ERROR keystone.server.flask.application   File "/var/lib/kolla/venv/lib/python3.9/site-packages/keystone/api/projects.py", line 107, in _get_project
2023-04-12 06:46:45.060 39 ERROR keystone.server.flask.application     project = PROVIDERS.resource_api.get_project(project_id)
2023-04-12 06:46:45.060 39 ERROR keystone.server.flask.application   File "/var/lib/kolla/venv/lib/python3.9/site-packages/keystone/common/manager.py", line 115, in wrapped
2023-04-12 06:46:45.060 39 ERROR keystone.server.flask.application     __ret_val = __f(*args, **kwargs)
2023-04-12 06:46:45.060 39 ERROR keystone.server.flask.application   File "/var/lib/kolla/venv/lib/python3.9/site-packages/decorator.py", line 232, in fun
2023-04-12 06:46:45.060 39 ERROR keystone.server.flask.application     return caller(func, *(extras + args), **kw)
2023-04-12 06:46:45.060 39 ERROR keystone.server.flask.application   File "/var/lib/kolla/venv/lib/python3.9/site-packages/dogpile/cache/region.py", line 1577, in get_or_create_for_user_func
2023-04-12 06:46:45.060 39 ERROR keystone.server.flask.application     return self.get_or_create(
2023-04-12 06:46:45.060 39 ERROR keystone.server.flask.application   File "/var/lib/kolla/venv/lib/python3.9/site-packages/dogpile/cache/region.py", line 1042, in get_or_create
2023-04-12 06:46:45.060 39 ERROR keystone.server.flask.application     with Lock(
2023-04-12 06:46:45.060 39 ERROR keystone.server.flask.application   File "/var/lib/kolla/venv/lib/python3.9/site-packages/dogpile/lock.py", line 185, in __enter__
2023-04-12 06:46:45.060 39 ERROR keystone.server.flask.application     return self._enter()
2023-04-12 06:46:45.060 39 ERROR keystone.server.flask.application   File "/var/lib/kolla/venv/lib/python3.9/site-packages/dogpile/lock.py", line 94, in _enter
2023-04-12 06:46:45.060 39 ERROR keystone.server.flask.application     generated = self._enter_create(value, createdtime)
2023-04-12 06:46:45.060 39 ERROR keystone.server.flask.application   File "/var/lib/kolla/venv/lib/python3.9/site-packages/dogpile/lock.py", line 178, in _enter_create
2023-04-12 06:46:45.060 39 ERROR keystone.server.flask.application     return self.creator()
2023-04-12 06:46:45.060 39 ERROR keystone.server.flask.application   File "/var/lib/kolla/venv/lib/python3.9/site-packages/dogpile/cache/region.py", line 995, in gen_value
2023-04-12 06:46:45.060 39 ERROR keystone.server.flask.application     created_value = creator(
2023-04-12 06:46:45.060 39 ERROR keystone.server.flask.application   File "/var/lib/kolla/venv/lib/python3.9/site-packages/keystone/resource/core.py", line 903, in get_project
2023-04-12 06:46:45.060 39 ERROR keystone.server.flask.application     return self.driver.get_project(project_id)
2023-04-12 06:46:45.060 39 ERROR keystone.server.flask.application   File "/var/lib/kolla/venv/lib/python3.9/site-packages/keystone/resource/backends/sql.py", line 49, in get_project
2023-04-12 06:46:45.060 39 ERROR keystone.server.flask.application     return self._get_project(session, project_id).to_dict()
2023-04-12 06:46:45.060 39 ERROR keystone.server.flask.application   File "/var/lib/kolla/venv/lib/python3.9/site-packages/keystone/resource/backends/sql.py", line 44, in _get_project
2023-04-12 06:46:45.060 39 ERROR keystone.server.flask.application     raise exception.ProjectNotFound(project_id=project_id)
2023-04-12 06:46:45.060 39 ERROR keystone.server.flask.application keystone.exception.ProjectNotFound: Could not find project: service.
2023-04-12 06:46:45.060 39 ERROR keystone.server.flask.application 
