2023-04-12 20:42:50.299367 2023-04-12 20:42:50.297 40 WARNING keystone.common.rbac_enforcer.enforcer [None req-30ce293f-fd3d-4a6d-ae11-36e788a15a58 75f471bf30cc4a67bf613cb538872fe7 - - all default -] Deprecated policy rules found. Use oslopolicy-policy-generator and oslopolicy-policy-upgrade to detect and resolve deprecated policies in your configuration.\x1b[00m
2023-04-12 20:42:51.271154 2023-04-12 20:42:51.269 38 WARNING keystone.common.rbac_enforcer.enforcer [None req-d339af89-2e77-403e-b7fb-2896181712fc 75f471bf30cc4a67bf613cb538872fe7 - - all default -] Deprecated policy rules found. Use oslopolicy-policy-generator and oslopolicy-policy-upgrade to detect and resolve deprecated policies in your configuration.\x1b[00m
2023-04-12 20:42:58.880009 2023-04-12 20:42:58.878 39 WARNING keystone.common.rbac_enforcer.enforcer [None req-16f42e4a-6ebb-41ed-b35d-9fa5b1075f0e 75f471bf30cc4a67bf613cb538872fe7 - - all default -] Deprecated policy rules found. Use oslopolicy-policy-generator and oslopolicy-policy-upgrade to detect and resolve deprecated policies in your configuration.\x1b[00m
2023-04-12 20:44:19.901317 2023-04-12 20:44:19.888 40 ERROR keystone.server.flask.application [None req-24115769-583b-40c0-a0ec-62e15e67ab8d 75f471bf30cc4a67bf613cb538872fe7 - - all default -] Could not find project: service.: keystone.exception.ProjectNotFound: Could not find project: service.
2023-04-12 20:44:19.901425 2023-04-12 20:44:19.888 40 ERROR keystone.server.flask.application Traceback (most recent call last):
2023-04-12 20:44:19.901446 2023-04-12 20:44:19.888 40 ERROR keystone.server.flask.application   File "/var/lib/kolla/venv/lib/python3.9/site-packages/flask/app.py", line 1820, in full_dispatch_request
2023-04-12 20:44:19.901463 2023-04-12 20:44:19.888 40 ERROR keystone.server.flask.application     rv = self.dispatch_request()
2023-04-12 20:44:19.901499 2023-04-12 20:44:19.888 40 ERROR keystone.server.flask.application   File "/var/lib/kolla/venv/lib/python3.9/site-packages/flask/app.py", line 1796, in dispatch_request
2023-04-12 20:44:19.901519 2023-04-12 20:44:19.888 40 ERROR keystone.server.flask.application     return self.ensure_sync(self.view_functions[rule.endpoint])(**view_args)
2023-04-12 20:44:19.901535 2023-04-12 20:44:19.888 40 ERROR keystone.server.flask.application   File "/var/lib/kolla/venv/lib/python3.9/site-packages/flask_restful/__init__.py", line 467, in wrapper
2023-04-12 20:44:19.901551 2023-04-12 20:44:19.888 40 ERROR keystone.server.flask.application     resp = resource(*args, **kwargs)
2023-04-12 20:44:19.901566 2023-04-12 20:44:19.888 40 ERROR keystone.server.flask.application   File "/var/lib/kolla/venv/lib/python3.9/site-packages/flask/views.py", line 107, in view
2023-04-12 20:44:19.901584 2023-04-12 20:44:19.888 40 ERROR keystone.server.flask.application     return current_app.ensure_sync(self.dispatch_request)(**kwargs)
2023-04-12 20:44:19.901600 2023-04-12 20:44:19.888 40 ERROR keystone.server.flask.application   File "/var/lib/kolla/venv/lib/python3.9/site-packages/flask_restful/__init__.py", line 582, in dispatch_request
2023-04-12 20:44:19.901674 2023-04-12 20:44:19.888 40 ERROR keystone.server.flask.application     resp = meth(*args, **kwargs)
2023-04-12 20:44:19.901693 2023-04-12 20:44:19.888 40 ERROR keystone.server.flask.application   File "/var/lib/kolla/venv/lib/python3.9/site-packages/keystone/api/projects.py", line 151, in get
2023-04-12 20:44:19.901710 2023-04-12 20:44:19.888 40 ERROR keystone.server.flask.application     return self._get_project(project_id)
2023-04-12 20:44:19.901726 2023-04-12 20:44:19.888 40 ERROR keystone.server.flask.application   File "/var/lib/kolla/venv/lib/python3.9/site-packages/keystone/api/projects.py", line 107, in _get_project
2023-04-12 20:44:19.901743 2023-04-12 20:44:19.888 40 ERROR keystone.server.flask.application     project = PROVIDERS.resource_api.get_project(project_id)
2023-04-12 20:44:19.901760 2023-04-12 20:44:19.888 40 ERROR keystone.server.flask.application   File "/var/lib/kolla/venv/lib/python3.9/site-packages/keystone/common/manager.py", line 115, in wrapped
2023-04-12 20:44:19.901843 2023-04-12 20:44:19.888 40 ERROR keystone.server.flask.application     __ret_val = __f(*args, **kwargs)
2023-04-12 20:44:19.901874 2023-04-12 20:44:19.888 40 ERROR keystone.server.flask.application   File "/var/lib/kolla/venv/lib/python3.9/site-packages/decorator.py", line 232, in fun
2023-04-12 20:44:19.901948 2023-04-12 20:44:19.888 40 ERROR keystone.server.flask.application     return caller(func, *(extras + args), **kw)
2023-04-12 20:44:19.901966 2023-04-12 20:44:19.888 40 ERROR keystone.server.flask.application   File "/var/lib/kolla/venv/lib/python3.9/site-packages/dogpile/cache/region.py", line 1577, in get_or_create_for_user_func
2023-04-12 20:44:19.901982 2023-04-12 20:44:19.888 40 ERROR keystone.server.flask.application     return self.get_or_create(
2023-04-12 20:44:19.901996 2023-04-12 20:44:19.888 40 ERROR keystone.server.flask.application   File "/var/lib/kolla/venv/lib/python3.9/site-packages/dogpile/cache/region.py", line 1042, in get_or_create
2023-04-12 20:44:19.902012 2023-04-12 20:44:19.888 40 ERROR keystone.server.flask.application     with Lock(
2023-04-12 20:44:19.902026 2023-04-12 20:44:19.888 40 ERROR keystone.server.flask.application   File "/var/lib/kolla/venv/lib/python3.9/site-packages/dogpile/lock.py", line 185, in __enter__
2023-04-12 20:44:19.902073 2023-04-12 20:44:19.888 40 ERROR keystone.server.flask.application     return self._enter()
2023-04-12 20:44:19.902089 2023-04-12 20:44:19.888 40 ERROR keystone.server.flask.application   File "/var/lib/kolla/venv/lib/python3.9/site-packages/dogpile/lock.py", line 94, in _enter
2023-04-12 20:44:19.902105 2023-04-12 20:44:19.888 40 ERROR keystone.server.flask.application     generated = self._enter_create(value, createdtime)
2023-04-12 20:44:19.902121 2023-04-12 20:44:19.888 40 ERROR keystone.server.flask.application   File "/var/lib/kolla/venv/lib/python3.9/site-packages/dogpile/lock.py", line 178, in _enter_create
2023-04-12 20:44:19.902137 2023-04-12 20:44:19.888 40 ERROR keystone.server.flask.application     return self.creator()
2023-04-12 20:44:19.902153 2023-04-12 20:44:19.888 40 ERROR keystone.server.flask.application   File "/var/lib/kolla/venv/lib/python3.9/site-packages/dogpile/cache/region.py", line 995, in gen_value
2023-04-12 20:44:19.902190 2023-04-12 20:44:19.888 40 ERROR keystone.server.flask.application     created_value = creator(
2023-04-12 20:44:19.902205 2023-04-12 20:44:19.888 40 ERROR keystone.server.flask.application   File "/var/lib/kolla/venv/lib/python3.9/site-packages/keystone/resource/core.py", line 903, in get_project
2023-04-12 20:44:19.902221 2023-04-12 20:44:19.888 40 ERROR keystone.server.flask.application     return self.driver.get_project(project_id)
2023-04-12 20:44:19.902238 2023-04-12 20:44:19.888 40 ERROR keystone.server.flask.application   File "/var/lib/kolla/venv/lib/python3.9/site-packages/keystone/resource/backends/sql.py", line 49, in get_project
2023-04-12 20:44:19.902254 2023-04-12 20:44:19.888 40 ERROR keystone.server.flask.application     return self._get_project(session, project_id).to_dict()
2023-04-12 20:44:19.902271 2023-04-12 20:44:19.888 40 ERROR keystone.server.flask.application   File "/var/lib/kolla/venv/lib/python3.9/site-packages/keystone/resource/backends/sql.py", line 44, in _get_project
2023-04-12 20:44:19.902289 2023-04-12 20:44:19.888 40 ERROR keystone.server.flask.application     raise exception.ProjectNotFound(project_id=project_id)
2023-04-12 20:44:19.902305 2023-04-12 20:44:19.888 40 ERROR keystone.server.flask.application keystone.exception.ProjectNotFound: Could not find project: service.
2023-04-12 20:44:19.902321 2023-04-12 20:44:19.888 40 ERROR keystone.server.flask.application \x1b[00m
2023-04-12 20:44:29.610444 2023-04-12 20:44:29.597 39 ERROR keystone.server.flask.application [None req-25a52e16-e7dc-48fe-b64c-fc3ca983a208 75f471bf30cc4a67bf613cb538872fe7 - - all default -] Could not find project: service.: keystone.exception.ProjectNotFound: Could not find project: service.
2023-04-12 20:44:29.610496 2023-04-12 20:44:29.597 39 ERROR keystone.server.flask.application Traceback (most recent call last):
2023-04-12 20:44:29.610540 2023-04-12 20:44:29.597 39 ERROR keystone.server.flask.application   File "/var/lib/kolla/venv/lib/python3.9/site-packages/flask/app.py", line 1820, in full_dispatch_request
2023-04-12 20:44:29.610553 2023-04-12 20:44:29.597 39 ERROR keystone.server.flask.application     rv = self.dispatch_request()
2023-04-12 20:44:29.610563 2023-04-12 20:44:29.597 39 ERROR keystone.server.flask.application   File "/var/lib/kolla/venv/lib/python3.9/site-packages/flask/app.py", line 1796, in dispatch_request
2023-04-12 20:44:29.610574 2023-04-12 20:44:29.597 39 ERROR keystone.server.flask.application     return self.ensure_sync(self.view_functions[rule.endpoint])(**view_args)
2023-04-12 20:44:29.610583 2023-04-12 20:44:29.597 39 ERROR keystone.server.flask.application   File "/var/lib/kolla/venv/lib/python3.9/site-packages/flask_restful/__init__.py", line 467, in wrapper
2023-04-12 20:44:29.610593 2023-04-12 20:44:29.597 39 ERROR keystone.server.flask.application     resp = resource(*args, **kwargs)
2023-04-12 20:44:29.610603 2023-04-12 20:44:29.597 39 ERROR keystone.server.flask.application   File "/var/lib/kolla/venv/lib/python3.9/site-packages/flask/views.py", line 107, in view
2023-04-12 20:44:29.610658 2023-04-12 20:44:29.597 39 ERROR keystone.server.flask.application     return current_app.ensure_sync(self.dispatch_request)(**kwargs)
2023-04-12 20:44:29.610679 2023-04-12 20:44:29.597 39 ERROR keystone.server.flask.application   File "/var/lib/kolla/venv/lib/python3.9/site-packages/flask_restful/__init__.py", line 582, in dispatch_request
2023-04-12 20:44:29.610697 2023-04-12 20:44:29.597 39 ERROR keystone.server.flask.application     resp = meth(*args, **kwargs)
2023-04-12 20:44:29.610709 2023-04-12 20:44:29.597 39 ERROR keystone.server.flask.application   File "/var/lib/kolla/venv/lib/python3.9/site-packages/keystone/api/projects.py", line 151, in get
2023-04-12 20:44:29.610719 2023-04-12 20:44:29.597 39 ERROR keystone.server.flask.application     return self._get_project(project_id)
2023-04-12 20:44:29.610729 2023-04-12 20:44:29.597 39 ERROR keystone.server.flask.application   File "/var/lib/kolla/venv/lib/python3.9/site-packages/keystone/api/projects.py", line 107, in _get_project
2023-04-12 20:44:29.610739 2023-04-12 20:44:29.597 39 ERROR keystone.server.flask.application     project = PROVIDERS.resource_api.get_project(project_id)
2023-04-12 20:44:29.610748 2023-04-12 20:44:29.597 39 ERROR keystone.server.flask.application   File "/var/lib/kolla/venv/lib/python3.9/site-packages/keystone/common/manager.py", line 115, in wrapped
2023-04-12 20:44:29.610758 2023-04-12 20:44:29.597 39 ERROR keystone.server.flask.application     __ret_val = __f(*args, **kwargs)
2023-04-12 20:44:29.610767 2023-04-12 20:44:29.597 39 ERROR keystone.server.flask.application   File "/var/lib/kolla/venv/lib/python3.9/site-packages/decorator.py", line 232, in fun
2023-04-12 20:44:29.610777 2023-04-12 20:44:29.597 39 ERROR keystone.server.flask.application     return caller(func, *(extras + args), **kw)
2023-04-12 20:44:29.610787 2023-04-12 20:44:29.597 39 ERROR keystone.server.flask.application   File "/var/lib/kolla/venv/lib/python3.9/site-packages/dogpile/cache/region.py", line 1577, in get_or_create_for_user_func
2023-04-12 20:44:29.610797 2023-04-12 20:44:29.597 39 ERROR keystone.server.flask.application     return self.get_or_create(
2023-04-12 20:44:29.610806 2023-04-12 20:44:29.597 39 ERROR keystone.server.flask.application   File "/var/lib/kolla/venv/lib/python3.9/site-packages/dogpile/cache/region.py", line 1042, in get_or_create
2023-04-12 20:44:29.610816 2023-04-12 20:44:29.597 39 ERROR keystone.server.flask.application     with Lock(
2023-04-12 20:44:29.610826 2023-04-12 20:44:29.597 39 ERROR keystone.server.flask.application   File "/var/lib/kolla/venv/lib/python3.9/site-packages/dogpile/lock.py", line 185, in __enter__
2023-04-12 20:44:29.610836 2023-04-12 20:44:29.597 39 ERROR keystone.server.flask.application     return self._enter()
2023-04-12 20:44:29.610889 2023-04-12 20:44:29.597 39 ERROR keystone.server.flask.application   File "/var/lib/kolla/venv/lib/python3.9/site-packages/dogpile/lock.py", line 94, in _enter
2023-04-12 20:44:29.610902 2023-04-12 20:44:29.597 39 ERROR keystone.server.flask.application     generated = self._enter_create(value, createdtime)
2023-04-12 20:44:29.610912 2023-04-12 20:44:29.597 39 ERROR keystone.server.flask.application   File "/var/lib/kolla/venv/lib/python3.9/site-packages/dogpile/lock.py", line 178, in _enter_create
2023-04-12 20:44:29.610922 2023-04-12 20:44:29.597 39 ERROR keystone.server.flask.application     return self.creator()
2023-04-12 20:44:29.610931 2023-04-12 20:44:29.597 39 ERROR keystone.server.flask.application   File "/var/lib/kolla/venv/lib/python3.9/site-packages/dogpile/cache/region.py", line 995, in gen_value
2023-04-12 20:44:29.610941 2023-04-12 20:44:29.597 39 ERROR keystone.server.flask.application     created_value = creator(
2023-04-12 20:44:29.610950 2023-04-12 20:44:29.597 39 ERROR keystone.server.flask.application   File "/var/lib/kolla/venv/lib/python3.9/site-packages/keystone/resource/core.py", line 903, in get_project
2023-04-12 20:44:29.610960 2023-04-12 20:44:29.597 39 ERROR keystone.server.flask.application     return self.driver.get_project(project_id)
2023-04-12 20:44:29.610970 2023-04-12 20:44:29.597 39 ERROR keystone.server.flask.application   File "/var/lib/kolla/venv/lib/python3.9/site-packages/keystone/resource/backends/sql.py", line 49, in get_project
2023-04-12 20:44:29.610980 2023-04-12 20:44:29.597 39 ERROR keystone.server.flask.application     return self._get_project(session, project_id).to_dict()
2023-04-12 20:44:29.610989 2023-04-12 20:44:29.597 39 ERROR keystone.server.flask.application   File "/var/lib/kolla/venv/lib/python3.9/site-packages/keystone/resource/backends/sql.py", line 44, in _get_project
2023-04-12 20:44:29.610999 2023-04-12 20:44:29.597 39 ERROR keystone.server.flask.application     raise exception.ProjectNotFound(project_id=project_id)
2023-04-12 20:44:29.611009 2023-04-12 20:44:29.597 39 ERROR keystone.server.flask.application keystone.exception.ProjectNotFound: Could not find project: service.
2023-04-12 20:44:29.611018 2023-04-12 20:44:29.597 39 ERROR keystone.server.flask.application \x1b[00m
2023-04-12 20:44:46.000130 2023-04-12 20:44:45.993 39 ERROR keystone.server.flask.application [None req-5fc520c0-f2fb-4845-b762-e43cc4fa9280 75f471bf30cc4a67bf613cb538872fe7 - - all default -] Could not find role: admin.: keystone.exception.RoleNotFound: Could not find role: admin.
2023-04-12 20:44:46.000182 2023-04-12 20:44:45.993 39 ERROR keystone.server.flask.application Traceback (most recent call last):
2023-04-12 20:44:46.000195 2023-04-12 20:44:45.993 39 ERROR keystone.server.flask.application   File "/var/lib/kolla/venv/lib/python3.9/site-packages/flask/app.py", line 1820, in full_dispatch_request
2023-04-12 20:44:46.000206 2023-04-12 20:44:45.993 39 ERROR keystone.server.flask.application     rv = self.dispatch_request()
2023-04-12 20:44:46.000216 2023-04-12 20:44:45.993 39 ERROR keystone.server.flask.application   File "/var/lib/kolla/venv/lib/python3.9/site-packages/flask/app.py", line 1796, in dispatch_request
2023-04-12 20:44:46.000227 2023-04-12 20:44:45.993 39 ERROR keystone.server.flask.application     return self.ensure_sync(self.view_functions[rule.endpoint])(**view_args)
2023-04-12 20:44:46.000237 2023-04-12 20:44:45.993 39 ERROR keystone.server.flask.application   File "/var/lib/kolla/venv/lib/python3.9/site-packages/flask_restful/__init__.py", line 467, in wrapper
2023-04-12 20:44:46.000247 2023-04-12 20:44:45.993 39 ERROR keystone.server.flask.application     resp = resource(*args, **kwargs)
2023-04-12 20:44:46.000257 2023-04-12 20:44:45.993 39 ERROR keystone.server.flask.application   File "/var/lib/kolla/venv/lib/python3.9/site-packages/flask/views.py", line 107, in view
2023-04-12 20:44:46.000268 2023-04-12 20:44:45.993 39 ERROR keystone.server.flask.application     return current_app.ensure_sync(self.dispatch_request)(**kwargs)
2023-04-12 20:44:46.000278 2023-04-12 20:44:45.993 39 ERROR keystone.server.flask.application   File "/var/lib/kolla/venv/lib/python3.9/site-packages/flask_restful/__init__.py", line 582, in dispatch_request
2023-04-12 20:44:46.000313 2023-04-12 20:44:45.993 39 ERROR keystone.server.flask.application     resp = meth(*args, **kwargs)
2023-04-12 20:44:46.000325 2023-04-12 20:44:45.993 39 ERROR keystone.server.flask.application   File "/var/lib/kolla/venv/lib/python3.9/site-packages/keystone/api/roles.py", line 50, in get
2023-04-12 20:44:46.000368 2023-04-12 20:44:45.993 39 ERROR keystone.server.flask.application     return self._get_role(role_id)
2023-04-12 20:44:46.000379 2023-04-12 20:44:45.993 39 ERROR keystone.server.flask.application   File "/var/lib/kolla/venv/lib/python3.9/site-packages/keystone/api/roles.py", line 70, in _get_role
2023-04-12 20:44:46.000389 2023-04-12 20:44:45.993 39 ERROR keystone.server.flask.application     ENFORCER.enforce_call(action='identity:get_role')
2023-04-12 20:44:46.000400 2023-04-12 20:44:45.993 39 ERROR keystone.server.flask.application   File "/var/lib/kolla/venv/lib/python3.9/site-packages/keystone/common/rbac_enforcer/enforcer.py", line 402, in enforce_call
2023-04-12 20:44:46.000410 2023-04-12 20:44:45.993 39 ERROR keystone.server.flask.application     policy_dict.update(cls._extract_member_target_data(
2023-04-12 20:44:46.000421 2023-04-12 20:44:45.993 39 ERROR keystone.server.flask.application   File "/var/lib/kolla/venv/lib/python3.9/site-packages/keystone/common/rbac_enforcer/enforcer.py", line 234, in _extract_member_target_data
2023-04-12 20:44:46.000432 2023-04-12 20:44:45.993 39 ERROR keystone.server.flask.application     member_name: func(flask.request.view_args[key])
2023-04-12 20:44:46.000442 2023-04-12 20:44:45.993 39 ERROR keystone.server.flask.application   File "/var/lib/kolla/venv/lib/python3.9/site-packages/keystone/common/manager.py", line 115, in wrapped
2023-04-12 20:44:46.000452 2023-04-12 20:44:45.993 39 ERROR keystone.server.flask.application     __ret_val = __f(*args, **kwargs)
2023-04-12 20:44:46.000462 2023-04-12 20:44:45.993 39 ERROR keystone.server.flask.application   File "/var/lib/kolla/venv/lib/python3.9/site-packages/decorator.py", line 232, in fun
2023-04-12 20:44:46.000472 2023-04-12 20:44:45.993 39 ERROR keystone.server.flask.application     return caller(func, *(extras + args), **kw)
2023-04-12 20:44:46.000482 2023-04-12 20:44:45.993 39 ERROR keystone.server.flask.application   File "/var/lib/kolla/venv/lib/python3.9/site-packages/dogpile/cache/region.py", line 1577, in get_or_create_for_user_func
2023-04-12 20:44:46.000492 2023-04-12 20:44:45.993 39 ERROR keystone.server.flask.application     return self.get_or_create(
2023-04-12 20:44:46.000502 2023-04-12 20:44:45.993 39 ERROR keystone.server.flask.application   File "/var/lib/kolla/venv/lib/python3.9/site-packages/dogpile/cache/region.py", line 1042, in get_or_create
2023-04-12 20:44:46.000513 2023-04-12 20:44:45.993 39 ERROR keystone.server.flask.application     with Lock(
2023-04-12 20:44:46.000522 2023-04-12 20:44:45.993 39 ERROR keystone.server.flask.application   File "/var/lib/kolla/venv/lib/python3.9/site-packages/dogpile/lock.py", line 185, in __enter__
2023-04-12 20:44:46.000533 2023-04-12 20:44:45.993 39 ERROR keystone.server.flask.application     return self._enter()
2023-04-12 20:44:46.000542 2023-04-12 20:44:45.993 39 ERROR keystone.server.flask.application   File "/var/lib/kolla/venv/lib/python3.9/site-packages/dogpile/lock.py", line 94, in _enter
2023-04-12 20:44:46.000553 2023-04-12 20:44:45.993 39 ERROR keystone.server.flask.application     generated = self._enter_create(value, createdtime)
2023-04-12 20:44:46.000563 2023-04-12 20:44:45.993 39 ERROR keystone.server.flask.application   File "/var/lib/kolla/venv/lib/python3.9/site-packages/dogpile/lock.py", line 178, in _enter_create
2023-04-12 20:44:46.000573 2023-04-12 20:44:45.993 39 ERROR keystone.server.flask.application     return self.creator()
2023-04-12 20:44:46.000583 2023-04-12 20:44:45.993 39 ERROR keystone.server.flask.application   File "/var/lib/kolla/venv/lib/python3.9/site-packages/dogpile/cache/region.py", line 995, in gen_value
2023-04-12 20:44:46.000606 2023-04-12 20:44:45.993 39 ERROR keystone.server.flask.application     created_value = creator(
2023-04-12 20:44:46.000617 2023-04-12 20:44:45.993 39 ERROR keystone.server.flask.application   File "/var/lib/kolla/venv/lib/python3.9/site-packages/keystone/assignment/core.py", line 1276, in get_role
2023-04-12 20:44:46.000655 2023-04-12 20:44:45.993 39 ERROR keystone.server.flask.application     return self.driver.get_role(role_id)
2023-04-12 20:44:46.000665 2023-04-12 20:44:45.993 39 ERROR keystone.server.flask.application   File "/var/lib/kolla/venv/lib/python3.9/site-packages/keystone/assignment/role_backends/sql.py", line 70, in get_role
2023-04-12 20:44:46.000676 2023-04-12 20:44:45.993 39 ERROR keystone.server.flask.application     return self._get_role(session, role_id).to_dict()
2023-04-12 20:44:46.000686 2023-04-12 20:44:45.993 39 ERROR keystone.server.flask.application   File "/var/lib/kolla/venv/lib/python3.9/site-packages/keystone/assignment/role_backends/sql.py", line 65, in _get_role
2023-04-12 20:44:46.000696 2023-04-12 20:44:45.993 39 ERROR keystone.server.flask.application     raise exception.RoleNotFound(role_id=role_id)
2023-04-12 20:44:46.000706 2023-04-12 20:44:45.993 39 ERROR keystone.server.flask.application keystone.exception.RoleNotFound: Could not find role: admin.
2023-04-12 20:44:46.000715 2023-04-12 20:44:45.993 39 ERROR keystone.server.flask.application \x1b[00m
2023-04-12 20:44:47.449234 2023-04-12 20:44:47.434 39 ERROR keystone.server.flask.application [None req-8f3e5e85-c7ce-4fca-9241-8358dc6d01fd 75f471bf30cc4a67bf613cb538872fe7 - - all default -] Could not find user: ironic.: keystone.exception.UserNotFound: Could not find user: ironic.
2023-04-12 20:44:47.449322 2023-04-12 20:44:47.434 39 ERROR keystone.server.flask.application Traceback (most recent call last):
2023-04-12 20:44:47.449357 2023-04-12 20:44:47.434 39 ERROR keystone.server.flask.application   File "/var/lib/kolla/venv/lib/python3.9/site-packages/flask/app.py", line 1820, in full_dispatch_request
2023-04-12 20:44:47.449372 2023-04-12 20:44:47.434 39 ERROR keystone.server.flask.application     rv = self.dispatch_request()
2023-04-12 20:44:47.449382 2023-04-12 20:44:47.434 39 ERROR keystone.server.flask.application   File "/var/lib/kolla/venv/lib/python3.9/site-packages/flask/app.py", line 1796, in dispatch_request
2023-04-12 20:44:47.449393 2023-04-12 20:44:47.434 39 ERROR keystone.server.flask.application     return self.ensure_sync(self.view_functions[rule.endpoint])(**view_args)
2023-04-12 20:44:47.449415 2023-04-12 20:44:47.434 39 ERROR keystone.server.flask.application   File "/var/lib/kolla/venv/lib/python3.9/site-packages/flask_restful/__init__.py", line 467, in wrapper
2023-04-12 20:44:47.449425 2023-04-12 20:44:47.434 39 ERROR keystone.server.flask.application     resp = resource(*args, **kwargs)
2023-04-12 20:44:47.449435 2023-04-12 20:44:47.434 39 ERROR keystone.server.flask.application   File "/var/lib/kolla/venv/lib/python3.9/site-packages/flask/views.py", line 107, in view
2023-04-12 20:44:47.449446 2023-04-12 20:44:47.434 39 ERROR keystone.server.flask.application     return current_app.ensure_sync(self.dispatch_request)(**kwargs)
2023-04-12 20:44:47.449455 2023-04-12 20:44:47.434 39 ERROR keystone.server.flask.application   File "/var/lib/kolla/venv/lib/python3.9/site-packages/flask_restful/__init__.py", line 582, in dispatch_request
2023-04-12 20:44:47.449465 2023-04-12 20:44:47.434 39 ERROR keystone.server.flask.application     resp = meth(*args, **kwargs)
2023-04-12 20:44:47.449474 2023-04-12 20:44:47.434 39 ERROR keystone.server.flask.application   File "/var/lib/kolla/venv/lib/python3.9/site-packages/keystone/api/users.py", line 182, in get
2023-04-12 20:44:47.449484 2023-04-12 20:44:47.434 39 ERROR keystone.server.flask.application     return self._get_user(user_id)
2023-04-12 20:44:47.449493 2023-04-12 20:44:47.434 39 ERROR keystone.server.flask.application   File "/var/lib/kolla/venv/lib/python3.9/site-packages/keystone/api/users.py", line 194, in _get_user
2023-04-12 20:44:47.449522 2023-04-12 20:44:47.434 39 ERROR keystone.server.flask.application     ref = PROVIDERS.identity_api.get_user(user_id)
2023-04-12 20:44:47.449533 2023-04-12 20:44:47.434 39 ERROR keystone.server.flask.application   File "/var/lib/kolla/venv/lib/python3.9/site-packages/keystone/common/manager.py", line 115, in wrapped
2023-04-12 20:44:47.449542 2023-04-12 20:44:47.434 39 ERROR keystone.server.flask.application     __ret_val = __f(*args, **kwargs)
2023-04-12 20:44:47.449552 2023-04-12 20:44:47.434 39 ERROR keystone.server.flask.application   File "/var/lib/kolla/venv/lib/python3.9/site-packages/keystone/identity/core.py", line 414, in wrapper
2023-04-12 20:44:47.449562 2023-04-12 20:44:47.434 39 ERROR keystone.server.flask.application     return f(self, *args, **kwargs)
2023-04-12 20:44:47.449571 2023-04-12 20:44:47.434 39 ERROR keystone.server.flask.application   File "/var/lib/kolla/venv/lib/python3.9/site-packages/keystone/identity/core.py", line 424, in wrapper
2023-04-12 20:44:47.449581 2023-04-12 20:44:47.434 39 ERROR keystone.server.flask.application     return f(self, *args, **kwargs)
2023-04-12 20:44:47.449590 2023-04-12 20:44:47.434 39 ERROR keystone.server.flask.application   File "/var/lib/kolla/venv/lib/python3.9/site-packages/decorator.py", line 232, in fun
2023-04-12 20:44:47.449600 2023-04-12 20:44:47.434 39 ERROR keystone.server.flask.application     return caller(func, *(extras + args), **kw)
2023-04-12 20:44:47.449636 2023-04-12 20:44:47.434 39 ERROR keystone.server.flask.application   File "/var/lib/kolla/venv/lib/python3.9/site-packages/dogpile/cache/region.py", line 1577, in get_or_create_for_user_func
2023-04-12 20:44:47.449649 2023-04-12 20:44:47.434 39 ERROR keystone.server.flask.application     return self.get_or_create(
2023-04-12 20:44:47.449659 2023-04-12 20:44:47.434 39 ERROR keystone.server.flask.application   File "/var/lib/kolla/venv/lib/python3.9/site-packages/dogpile/cache/region.py", line 1042, in get_or_create
2023-04-12 20:44:47.449669 2023-04-12 20:44:47.434 39 ERROR keystone.server.flask.application     with Lock(
2023-04-12 20:44:47.449678 2023-04-12 20:44:47.434 39 ERROR keystone.server.flask.application   File "/var/lib/kolla/venv/lib/python3.9/site-packages/dogpile/lock.py", line 185, in __enter__
2023-04-12 20:44:47.449688 2023-04-12 20:44:47.434 39 ERROR keystone.server.flask.application     return self._enter()
2023-04-12 20:44:47.449697 2023-04-12 20:44:47.434 39 ERROR keystone.server.flask.application   File "/var/lib/kolla/venv/lib/python3.9/site-packages/dogpile/lock.py", line 94, in _enter
2023-04-12 20:44:47.449706 2023-04-12 20:44:47.434 39 ERROR keystone.server.flask.application     generated = self._enter_create(value, createdtime)
2023-04-12 20:44:47.449715 2023-04-12 20:44:47.434 39 ERROR keystone.server.flask.application   File "/var/lib/kolla/venv/lib/python3.9/site-packages/dogpile/lock.py", line 178, in _enter_create
2023-04-12 20:44:47.449725 2023-04-12 20:44:47.434 39 ERROR keystone.server.flask.application     return self.creator()
2023-04-12 20:44:47.449734 2023-04-12 20:44:47.434 39 ERROR keystone.server.flask.application   File "/var/lib/kolla/venv/lib/python3.9/site-packages/dogpile/cache/region.py", line 995, in gen_value
2023-04-12 20:44:47.449743 2023-04-12 20:44:47.434 39 ERROR keystone.server.flask.application     created_value = creator(
2023-04-12 20:44:47.449752 2023-04-12 20:44:47.434 39 ERROR keystone.server.flask.application   File "/var/lib/kolla/venv/lib/python3.9/site-packages/keystone/identity/core.py", line 1011, in get_user
2023-04-12 20:44:47.449762 2023-04-12 20:44:47.434 39 ERROR keystone.server.flask.application     ref = driver.get_user(entity_id)
2023-04-12 20:44:47.449771 2023-04-12 20:44:47.434 39 ERROR keystone.server.flask.application   File "/var/lib/kolla/venv/lib/python3.9/site-packages/keystone/identity/backends/sql.py", line 200, in get_user
2023-04-12 20:44:47.449780 2023-04-12 20:44:47.434 39 ERROR keystone.server.flask.application     self._get_user(session, user_id).to_dict())
2023-04-12 20:44:47.449813 2023-04-12 20:44:47.434 39 ERROR keystone.server.flask.application   File "/var/lib/kolla/venv/lib/python3.9/site-packages/keystone/identity/backends/sql.py", line 194, in _get_user
2023-04-12 20:44:47.449825 2023-04-12 20:44:47.434 39 ERROR keystone.server.flask.application     raise exception.UserNotFound(user_id=user_id)
2023-04-12 20:44:47.449834 2023-04-12 20:44:47.434 39 ERROR keystone.server.flask.application keystone.exception.UserNotFound: Could not find user: ironic.
2023-04-12 20:44:47.449844 2023-04-12 20:44:47.434 39 ERROR keystone.server.flask.application \x1b[00m
2023-04-12 20:44:48.648705 2023-04-12 20:44:48.632 38 ERROR keystone.server.flask.application [None req-3c498145-2466-4178-9635-92bd48774a17 75f471bf30cc4a67bf613cb538872fe7 - - all default -] Could not find project: service.: keystone.exception.ProjectNotFound: Could not find project: service.
2023-04-12 20:44:48.648753 2023-04-12 20:44:48.632 38 ERROR keystone.server.flask.application Traceback (most recent call last):
2023-04-12 20:44:48.648765 2023-04-12 20:44:48.632 38 ERROR keystone.server.flask.application   File "/var/lib/kolla/venv/lib/python3.9/site-packages/flask/app.py", line 1820, in full_dispatch_request
2023-04-12 20:44:48.648776 2023-04-12 20:44:48.632 38 ERROR keystone.server.flask.application     rv = self.dispatch_request()
2023-04-12 20:44:48.648785 2023-04-12 20:44:48.632 38 ERROR keystone.server.flask.application   File "/var/lib/kolla/venv/lib/python3.9/site-packages/flask/app.py", line 1796, in dispatch_request
2023-04-12 20:44:48.648796 2023-04-12 20:44:48.632 38 ERROR keystone.server.flask.application     return self.ensure_sync(self.view_functions[rule.endpoint])(**view_args)
2023-04-12 20:44:48.648805 2023-04-12 20:44:48.632 38 ERROR keystone.server.flask.application   File "/var/lib/kolla/venv/lib/python3.9/site-packages/flask_restful/__init__.py", line 467, in wrapper
2023-04-12 20:44:48.648815 2023-04-12 20:44:48.632 38 ERROR keystone.server.flask.application     resp = resource(*args, **kwargs)
2023-04-12 20:44:48.648825 2023-04-12 20:44:48.632 38 ERROR keystone.server.flask.application   File "/var/lib/kolla/venv/lib/python3.9/site-packages/flask/views.py", line 107, in view
2023-04-12 20:44:48.648835 2023-04-12 20:44:48.632 38 ERROR keystone.server.flask.application     return current_app.ensure_sync(self.dispatch_request)(**kwargs)
2023-04-12 20:44:48.648844 2023-04-12 20:44:48.632 38 ERROR keystone.server.flask.application   File "/var/lib/kolla/venv/lib/python3.9/site-packages/flask_restful/__init__.py", line 582, in dispatch_request
2023-04-12 20:44:48.648854 2023-04-12 20:44:48.632 38 ERROR keystone.server.flask.application     resp = meth(*args, **kwargs)
2023-04-12 20:44:48.648863 2023-04-12 20:44:48.632 38 ERROR keystone.server.flask.application   File "/var/lib/kolla/venv/lib/python3.9/site-packages/keystone/api/projects.py", line 151, in get
2023-04-12 20:44:48.648873 2023-04-12 20:44:48.632 38 ERROR keystone.server.flask.application     return self._get_project(project_id)
2023-04-12 20:44:48.648883 2023-04-12 20:44:48.632 38 ERROR keystone.server.flask.application   File "/var/lib/kolla/venv/lib/python3.9/site-packages/keystone/api/projects.py", line 107, in _get_project
2023-04-12 20:44:48.648892 2023-04-12 20:44:48.632 38 ERROR keystone.server.flask.application     project = PROVIDERS.resource_api.get_project(project_id)
2023-04-12 20:44:48.648902 2023-04-12 20:44:48.632 38 ERROR keystone.server.flask.application   File "/var/lib/kolla/venv/lib/python3.9/site-packages/keystone/common/manager.py", line 115, in wrapped
2023-04-12 20:44:48.648911 2023-04-12 20:44:48.632 38 ERROR keystone.server.flask.application     __ret_val = __f(*args, **kwargs)
2023-04-12 20:44:48.648921 2023-04-12 20:44:48.632 38 ERROR keystone.server.flask.application   File "/var/lib/kolla/venv/lib/python3.9/site-packages/decorator.py", line 232, in fun
2023-04-12 20:44:48.648930 2023-04-12 20:44:48.632 38 ERROR keystone.server.flask.application     return caller(func, *(extras + args), **kw)
2023-04-12 20:44:48.648960 2023-04-12 20:44:48.632 38 ERROR keystone.server.flask.application   File "/var/lib/kolla/venv/lib/python3.9/site-packages/dogpile/cache/region.py", line 1577, in get_or_create_for_user_func
2023-04-12 20:44:48.648972 2023-04-12 20:44:48.632 38 ERROR keystone.server.flask.application     return self.get_or_create(
2023-04-12 20:44:48.648982 2023-04-12 20:44:48.632 38 ERROR keystone.server.flask.application   File "/var/lib/kolla/venv/lib/python3.9/site-packages/dogpile/cache/region.py", line 1042, in get_or_create
2023-04-12 20:44:48.648993 2023-04-12 20:44:48.632 38 ERROR keystone.server.flask.application     with Lock(
2023-04-12 20:44:48.649002 2023-04-12 20:44:48.632 38 ERROR keystone.server.flask.application   File "/var/lib/kolla/venv/lib/python3.9/site-packages/dogpile/lock.py", line 185, in __enter__
2023-04-12 20:44:48.649012 2023-04-12 20:44:48.632 38 ERROR keystone.server.flask.application     return self._enter()
2023-04-12 20:44:48.649022 2023-04-12 20:44:48.632 38 ERROR keystone.server.flask.application   File "/var/lib/kolla/venv/lib/python3.9/site-packages/dogpile/lock.py", line 94, in _enter
2023-04-12 20:44:48.649032 2023-04-12 20:44:48.632 38 ERROR keystone.server.flask.application     generated = self._enter_create(value, createdtime)
2023-04-12 20:44:48.649041 2023-04-12 20:44:48.632 38 ERROR keystone.server.flask.application   File "/var/lib/kolla/venv/lib/python3.9/site-packages/dogpile/lock.py", line 178, in _enter_create
2023-04-12 20:44:48.649051 2023-04-12 20:44:48.632 38 ERROR keystone.server.flask.application     return self.creator()
2023-04-12 20:44:48.649061 2023-04-12 20:44:48.632 38 ERROR keystone.server.flask.application   File "/var/lib/kolla/venv/lib/python3.9/site-packages/dogpile/cache/region.py", line 995, in gen_value
2023-04-12 20:44:48.649071 2023-04-12 20:44:48.632 38 ERROR keystone.server.flask.application     created_value = creator(
2023-04-12 20:44:48.649080 2023-04-12 20:44:48.632 38 ERROR keystone.server.flask.application   File "/var/lib/kolla/venv/lib/python3.9/site-packages/keystone/resource/core.py", line 903, in get_project
2023-04-12 20:44:48.649090 2023-04-12 20:44:48.632 38 ERROR keystone.server.flask.application     return self.driver.get_project(project_id)
2023-04-12 20:44:48.649100 2023-04-12 20:44:48.632 38 ERROR keystone.server.flask.application   File "/var/lib/kolla/venv/lib/python3.9/site-packages/keystone/resource/backends/sql.py", line 49, in get_project
2023-04-12 20:44:48.649110 2023-04-12 20:44:48.632 38 ERROR keystone.server.flask.application     return self._get_project(session, project_id).to_dict()
2023-04-12 20:44:48.649119 2023-04-12 20:44:48.632 38 ERROR keystone.server.flask.application   File "/var/lib/kolla/venv/lib/python3.9/site-packages/keystone/resource/backends/sql.py", line 44, in _get_project
2023-04-12 20:44:48.649130 2023-04-12 20:44:48.632 38 ERROR keystone.server.flask.application     raise exception.ProjectNotFound(project_id=project_id)
2023-04-12 20:44:48.649139 2023-04-12 20:44:48.632 38 ERROR keystone.server.flask.application keystone.exception.ProjectNotFound: Could not find project: service.
2023-04-12 20:44:48.649149 2023-04-12 20:44:48.632 38 ERROR keystone.server.flask.application \x1b[00m
2023-04-12 20:44:59.657149 2023-04-12 20:44:59.650 40 ERROR keystone.server.flask.application [None req-f7bbf4b1-ad5f-4847-9518-9b63d5f8ba2b 75f471bf30cc4a67bf613cb538872fe7 - - all default -] Could not find role: admin.: keystone.exception.RoleNotFound: Could not find role: admin.
2023-04-12 20:44:59.657198 2023-04-12 20:44:59.650 40 ERROR keystone.server.flask.application Traceback (most recent call last):
2023-04-12 20:44:59.657211 2023-04-12 20:44:59.650 40 ERROR keystone.server.flask.application   File "/var/lib/kolla/venv/lib/python3.9/site-packages/flask/app.py", line 1820, in full_dispatch_request
2023-04-12 20:44:59.657221 2023-04-12 20:44:59.650 40 ERROR keystone.server.flask.application     rv = self.dispatch_request()
2023-04-12 20:44:59.657231 2023-04-12 20:44:59.650 40 ERROR keystone.server.flask.application   File "/var/lib/kolla/venv/lib/python3.9/site-packages/flask/app.py", line 1796, in dispatch_request
2023-04-12 20:44:59.657254 2023-04-12 20:44:59.650 40 ERROR keystone.server.flask.application     return self.ensure_sync(self.view_functions[rule.endpoint])(**view_args)
2023-04-12 20:44:59.657265 2023-04-12 20:44:59.650 40 ERROR keystone.server.flask.application   File "/var/lib/kolla/venv/lib/python3.9/site-packages/flask_restful/__init__.py", line 467, in wrapper
2023-04-12 20:44:59.657275 2023-04-12 20:44:59.650 40 ERROR keystone.server.flask.application     resp = resource(*args, **kwargs)
2023-04-12 20:44:59.657285 2023-04-12 20:44:59.650 40 ERROR keystone.server.flask.application   File "/var/lib/kolla/venv/lib/python3.9/site-packages/flask/views.py", line 107, in view
2023-04-12 20:44:59.657296 2023-04-12 20:44:59.650 40 ERROR keystone.server.flask.application     return current_app.ensure_sync(self.dispatch_request)(**kwargs)
2023-04-12 20:44:59.657305 2023-04-12 20:44:59.650 40 ERROR keystone.server.flask.application   File "/var/lib/kolla/venv/lib/python3.9/site-packages/flask_restful/__init__.py", line 582, in dispatch_request
2023-04-12 20:44:59.657315 2023-04-12 20:44:59.650 40 ERROR keystone.server.flask.application     resp = meth(*args, **kwargs)
2023-04-12 20:44:59.657324 2023-04-12 20:44:59.650 40 ERROR keystone.server.flask.application   File "/var/lib/kolla/venv/lib/python3.9/site-packages/keystone/api/roles.py", line 50, in get
2023-04-12 20:44:59.657373 2023-04-12 20:44:59.650 40 ERROR keystone.server.flask.application     return self._get_role(role_id)
2023-04-12 20:44:59.657391 2023-04-12 20:44:59.650 40 ERROR keystone.server.flask.application   File "/var/lib/kolla/venv/lib/python3.9/site-packages/keystone/api/roles.py", line 70, in _get_role
2023-04-12 20:44:59.657401 2023-04-12 20:44:59.650 40 ERROR keystone.server.flask.application     ENFORCER.enforce_call(action='identity:get_role')
2023-04-12 20:44:59.657411 2023-04-12 20:44:59.650 40 ERROR keystone.server.flask.application   File "/var/lib/kolla/venv/lib/python3.9/site-packages/keystone/common/rbac_enforcer/enforcer.py", line 402, in enforce_call
2023-04-12 20:44:59.657421 2023-04-12 20:44:59.650 40 ERROR keystone.server.flask.application     policy_dict.update(cls._extract_member_target_data(
2023-04-12 20:44:59.657431 2023-04-12 20:44:59.650 40 ERROR keystone.server.flask.application   File "/var/lib/kolla/venv/lib/python3.9/site-packages/keystone/common/rbac_enforcer/enforcer.py", line 234, in _extract_member_target_data
2023-04-12 20:44:59.657442 2023-04-12 20:44:59.650 40 ERROR keystone.server.flask.application     member_name: func(flask.request.view_args[key])
2023-04-12 20:44:59.657451 2023-04-12 20:44:59.650 40 ERROR keystone.server.flask.application   File "/var/lib/kolla/venv/lib/python3.9/site-packages/keystone/common/manager.py", line 115, in wrapped
2023-04-12 20:44:59.657461 2023-04-12 20:44:59.650 40 ERROR keystone.server.flask.application     __ret_val = __f(*args, **kwargs)
2023-04-12 20:44:59.657470 2023-04-12 20:44:59.650 40 ERROR keystone.server.flask.application   File "/var/lib/kolla/venv/lib/python3.9/site-packages/decorator.py", line 232, in fun
2023-04-12 20:44:59.657480 2023-04-12 20:44:59.650 40 ERROR keystone.server.flask.application     return caller(func, *(extras + args), **kw)
2023-04-12 20:44:59.657490 2023-04-12 20:44:59.650 40 ERROR keystone.server.flask.application   File "/var/lib/kolla/venv/lib/python3.9/site-packages/dogpile/cache/region.py", line 1577, in get_or_create_for_user_func
2023-04-12 20:44:59.657500 2023-04-12 20:44:59.650 40 ERROR keystone.server.flask.application     return self.get_or_create(
2023-04-12 20:44:59.657509 2023-04-12 20:44:59.650 40 ERROR keystone.server.flask.application   File "/var/lib/kolla/venv/lib/python3.9/site-packages/dogpile/cache/region.py", line 1042, in get_or_create
2023-04-12 20:44:59.657519 2023-04-12 20:44:59.650 40 ERROR keystone.server.flask.application     with Lock(
2023-04-12 20:44:59.657541 2023-04-12 20:44:59.650 40 ERROR keystone.server.flask.application   File "/var/lib/kolla/venv/lib/python3.9/site-packages/dogpile/lock.py", line 185, in __enter__
2023-04-12 20:44:59.657552 2023-04-12 20:44:59.650 40 ERROR keystone.server.flask.application     return self._enter()
2023-04-12 20:44:59.657562 2023-04-12 20:44:59.650 40 ERROR keystone.server.flask.application   File "/var/lib/kolla/venv/lib/python3.9/site-packages/dogpile/lock.py", line 94, in _enter
2023-04-12 20:44:59.657571 2023-04-12 20:44:59.650 40 ERROR keystone.server.flask.application     generated = self._enter_create(value, createdtime)
2023-04-12 20:44:59.657581 2023-04-12 20:44:59.650 40 ERROR keystone.server.flask.application   File "/var/lib/kolla/venv/lib/python3.9/site-packages/dogpile/lock.py", line 178, in _enter_create
2023-04-12 20:44:59.657591 2023-04-12 20:44:59.650 40 ERROR keystone.server.flask.application     return self.creator()
2023-04-12 20:44:59.657600 2023-04-12 20:44:59.650 40 ERROR keystone.server.flask.application   File "/var/lib/kolla/venv/lib/python3.9/site-packages/dogpile/cache/region.py", line 995, in gen_value
2023-04-12 20:44:59.657610 2023-04-12 20:44:59.650 40 ERROR keystone.server.flask.application     created_value = creator(
2023-04-12 20:44:59.657633 2023-04-12 20:44:59.650 40 ERROR keystone.server.flask.application   File "/var/lib/kolla/venv/lib/python3.9/site-packages/keystone/assignment/core.py", line 1276, in get_role
2023-04-12 20:44:59.657664 2023-04-12 20:44:59.650 40 ERROR keystone.server.flask.application     return self.driver.get_role(role_id)
2023-04-12 20:44:59.657673 2023-04-12 20:44:59.650 40 ERROR keystone.server.flask.application   File "/var/lib/kolla/venv/lib/python3.9/site-packages/keystone/assignment/role_backends/sql.py", line 70, in get_role
2023-04-12 20:44:59.657683 2023-04-12 20:44:59.650 40 ERROR keystone.server.flask.application     return self._get_role(session, role_id).to_dict()
2023-04-12 20:44:59.657692 2023-04-12 20:44:59.650 40 ERROR keystone.server.flask.application   File "/var/lib/kolla/venv/lib/python3.9/site-packages/keystone/assignment/role_backends/sql.py", line 65, in _get_role
2023-04-12 20:44:59.657702 2023-04-12 20:44:59.650 40 ERROR keystone.server.flask.application     raise exception.RoleNotFound(role_id=role_id)
2023-04-12 20:44:59.657711 2023-04-12 20:44:59.650 40 ERROR keystone.server.flask.application keystone.exception.RoleNotFound: Could not find role: admin.
2023-04-12 20:44:59.657720 2023-04-12 20:44:59.650 40 ERROR keystone.server.flask.application \x1b[00m
2023-04-12 20:45:01.183110 2023-04-12 20:45:01.176 40 ERROR keystone.server.flask.application [None req-88b27970-ac05-4e9b-8df5-cbb3c65e4afc 75f471bf30cc4a67bf613cb538872fe7 - - all default -] Could not find user: ironic-inspector.: keystone.exception.UserNotFound: Could not find user: ironic-inspector.
2023-04-12 20:45:01.183152 2023-04-12 20:45:01.176 40 ERROR keystone.server.flask.application Traceback (most recent call last):
2023-04-12 20:45:01.183164 2023-04-12 20:45:01.176 40 ERROR keystone.server.flask.application   File "/var/lib/kolla/venv/lib/python3.9/site-packages/flask/app.py", line 1820, in full_dispatch_request
2023-04-12 20:45:01.183178 2023-04-12 20:45:01.176 40 ERROR keystone.server.flask.application     rv = self.dispatch_request()
2023-04-12 20:45:01.183193 2023-04-12 20:45:01.176 40 ERROR keystone.server.flask.application   File "/var/lib/kolla/venv/lib/python3.9/site-packages/flask/app.py", line 1796, in dispatch_request
2023-04-12 20:45:01.183204 2023-04-12 20:45:01.176 40 ERROR keystone.server.flask.application     return self.ensure_sync(self.view_functions[rule.endpoint])(**view_args)
2023-04-12 20:45:01.183213 2023-04-12 20:45:01.176 40 ERROR keystone.server.flask.application   File "/var/lib/kolla/venv/lib/python3.9/site-packages/flask_restful/__init__.py", line 467, in wrapper
2023-04-12 20:45:01.183223 2023-04-12 20:45:01.176 40 ERROR keystone.server.flask.application     resp = resource(*args, **kwargs)
2023-04-12 20:45:01.183239 2023-04-12 20:45:01.176 40 ERROR keystone.server.flask.application   File "/var/lib/kolla/venv/lib/python3.9/site-packages/flask/views.py", line 107, in view
2023-04-12 20:45:01.183291 2023-04-12 20:45:01.176 40 ERROR keystone.server.flask.application     return current_app.ensure_sync(self.dispatch_request)(**kwargs)
2023-04-12 20:45:01.183304 2023-04-12 20:45:01.176 40 ERROR keystone.server.flask.application   File "/var/lib/kolla/venv/lib/python3.9/site-packages/flask_restful/__init__.py", line 582, in dispatch_request
2023-04-12 20:45:01.183314 2023-04-12 20:45:01.176 40 ERROR keystone.server.flask.application     resp = meth(*args, **kwargs)
2023-04-12 20:45:01.183324 2023-04-12 20:45:01.176 40 ERROR keystone.server.flask.application   File "/var/lib/kolla/venv/lib/python3.9/site-packages/keystone/api/users.py", line 182, in get
2023-04-12 20:45:01.183334 2023-04-12 20:45:01.176 40 ERROR keystone.server.flask.application     return self._get_user(user_id)
2023-04-12 20:45:01.183378 2023-04-12 20:45:01.176 40 ERROR keystone.server.flask.application   File "/var/lib/kolla/venv/lib/python3.9/site-packages/keystone/api/users.py", line 194, in _get_user
2023-04-12 20:45:01.183389 2023-04-12 20:45:01.176 40 ERROR keystone.server.flask.application     ref = PROVIDERS.identity_api.get_user(user_id)
2023-04-12 20:45:01.183399 2023-04-12 20:45:01.176 40 ERROR keystone.server.flask.application   File "/var/lib/kolla/venv/lib/python3.9/site-packages/keystone/common/manager.py", line 115, in wrapped
2023-04-12 20:45:01.183408 2023-04-12 20:45:01.176 40 ERROR keystone.server.flask.application     __ret_val = __f(*args, **kwargs)
2023-04-12 20:45:01.183418 2023-04-12 20:45:01.176 40 ERROR keystone.server.flask.application   File "/var/lib/kolla/venv/lib/python3.9/site-packages/keystone/identity/core.py", line 414, in wrapper
2023-04-12 20:45:01.183428 2023-04-12 20:45:01.176 40 ERROR keystone.server.flask.application     return f(self, *args, **kwargs)
2023-04-12 20:45:01.183437 2023-04-12 20:45:01.176 40 ERROR keystone.server.flask.application   File "/var/lib/kolla/venv/lib/python3.9/site-packages/keystone/identity/core.py", line 424, in wrapper
2023-04-12 20:45:01.183447 2023-04-12 20:45:01.176 40 ERROR keystone.server.flask.application     return f(self, *args, **kwargs)
2023-04-12 20:45:01.183456 2023-04-12 20:45:01.176 40 ERROR keystone.server.flask.application   File "/var/lib/kolla/venv/lib/python3.9/site-packages/decorator.py", line 232, in fun
2023-04-12 20:45:01.183466 2023-04-12 20:45:01.176 40 ERROR keystone.server.flask.application     return caller(func, *(extras + args), **kw)
2023-04-12 20:45:01.183475 2023-04-12 20:45:01.176 40 ERROR keystone.server.flask.application   File "/var/lib/kolla/venv/lib/python3.9/site-packages/dogpile/cache/region.py", line 1577, in get_or_create_for_user_func
2023-04-12 20:45:01.183485 2023-04-12 20:45:01.176 40 ERROR keystone.server.flask.application     return self.get_or_create(
2023-04-12 20:45:01.183495 2023-04-12 20:45:01.176 40 ERROR keystone.server.flask.application   File "/var/lib/kolla/venv/lib/python3.9/site-packages/dogpile/cache/region.py", line 1042, in get_or_create
2023-04-12 20:45:01.183505 2023-04-12 20:45:01.176 40 ERROR keystone.server.flask.application     with Lock(
2023-04-12 20:45:01.183514 2023-04-12 20:45:01.176 40 ERROR keystone.server.flask.application   File "/var/lib/kolla/venv/lib/python3.9/site-packages/dogpile/lock.py", line 185, in __enter__
2023-04-12 20:45:01.183524 2023-04-12 20:45:01.176 40 ERROR keystone.server.flask.application     return self._enter()
2023-04-12 20:45:01.183533 2023-04-12 20:45:01.176 40 ERROR keystone.server.flask.application   File "/var/lib/kolla/venv/lib/python3.9/site-packages/dogpile/lock.py", line 94, in _enter
2023-04-12 20:45:01.183543 2023-04-12 20:45:01.176 40 ERROR keystone.server.flask.application     generated = self._enter_create(value, createdtime)
2023-04-12 20:45:01.183552 2023-04-12 20:45:01.176 40 ERROR keystone.server.flask.application   File "/var/lib/kolla/venv/lib/python3.9/site-packages/dogpile/lock.py", line 178, in _enter_create
2023-04-12 20:45:01.183575 2023-04-12 20:45:01.176 40 ERROR keystone.server.flask.application     return self.creator()
2023-04-12 20:45:01.183586 2023-04-12 20:45:01.176 40 ERROR keystone.server.flask.application   File "/var/lib/kolla/venv/lib/python3.9/site-packages/dogpile/cache/region.py", line 995, in gen_value
2023-04-12 20:45:01.183596 2023-04-12 20:45:01.176 40 ERROR keystone.server.flask.application     created_value = creator(
2023-04-12 20:45:01.183606 2023-04-12 20:45:01.176 40 ERROR keystone.server.flask.application   File "/var/lib/kolla/venv/lib/python3.9/site-packages/keystone/identity/core.py", line 1011, in get_user
2023-04-12 20:45:01.183616 2023-04-12 20:45:01.176 40 ERROR keystone.server.flask.application     ref = driver.get_user(entity_id)
2023-04-12 20:45:01.183650 2023-04-12 20:45:01.176 40 ERROR keystone.server.flask.application   File "/var/lib/kolla/venv/lib/python3.9/site-packages/keystone/identity/backends/sql.py", line 200, in get_user
2023-04-12 20:45:01.183660 2023-04-12 20:45:01.176 40 ERROR keystone.server.flask.application     self._get_user(session, user_id).to_dict())
2023-04-12 20:45:01.183670 2023-04-12 20:45:01.176 40 ERROR keystone.server.flask.application   File "/var/lib/kolla/venv/lib/python3.9/site-packages/keystone/identity/backends/sql.py", line 194, in _get_user
2023-04-12 20:45:01.183679 2023-04-12 20:45:01.176 40 ERROR keystone.server.flask.application     raise exception.UserNotFound(user_id=user_id)
2023-04-12 20:45:01.183689 2023-04-12 20:45:01.176 40 ERROR keystone.server.flask.application keystone.exception.UserNotFound: Could not find user: ironic-inspector.
2023-04-12 20:45:01.183698 2023-04-12 20:45:01.176 40 ERROR keystone.server.flask.application \x1b[00m
2023-04-12 20:45:02.147051 2023-04-12 20:45:02.143 39 ERROR keystone.server.flask.application [None req-34864951-891c-4da8-a1f7-63e74cb66d0c 75f471bf30cc4a67bf613cb538872fe7 - - all default -] Could not find project: service.: keystone.exception.ProjectNotFound: Could not find project: service.
2023-04-12 20:45:02.147093 2023-04-12 20:45:02.143 39 ERROR keystone.server.flask.application Traceback (most recent call last):
2023-04-12 20:45:02.147104 2023-04-12 20:45:02.143 39 ERROR keystone.server.flask.application   File "/var/lib/kolla/venv/lib/python3.9/site-packages/flask/app.py", line 1820, in full_dispatch_request
2023-04-12 20:45:02.147115 2023-04-12 20:45:02.143 39 ERROR keystone.server.flask.application     rv = self.dispatch_request()
2023-04-12 20:45:02.147125 2023-04-12 20:45:02.143 39 ERROR keystone.server.flask.application   File "/var/lib/kolla/venv/lib/python3.9/site-packages/flask/app.py", line 1796, in dispatch_request
2023-04-12 20:45:02.147135 2023-04-12 20:45:02.143 39 ERROR keystone.server.flask.application     return self.ensure_sync(self.view_functions[rule.endpoint])(**view_args)
2023-04-12 20:45:02.147144 2023-04-12 20:45:02.143 39 ERROR keystone.server.flask.application   File "/var/lib/kolla/venv/lib/python3.9/site-packages/flask_restful/__init__.py", line 467, in wrapper
2023-04-12 20:45:02.147154 2023-04-12 20:45:02.143 39 ERROR keystone.server.flask.application     resp = resource(*args, **kwargs)
2023-04-12 20:45:02.147164 2023-04-12 20:45:02.143 39 ERROR keystone.server.flask.application   File "/var/lib/kolla/venv/lib/python3.9/site-packages/flask/views.py", line 107, in view
2023-04-12 20:45:02.147181 2023-04-12 20:45:02.143 39 ERROR keystone.server.flask.application     return current_app.ensure_sync(self.dispatch_request)(**kwargs)
2023-04-12 20:45:02.147193 2023-04-12 20:45:02.143 39 ERROR keystone.server.flask.application   File "/var/lib/kolla/venv/lib/python3.9/site-packages/flask_restful/__init__.py", line 582, in dispatch_request
2023-04-12 20:45:02.147203 2023-04-12 20:45:02.143 39 ERROR keystone.server.flask.application     resp = meth(*args, **kwargs)
2023-04-12 20:45:02.147213 2023-04-12 20:45:02.143 39 ERROR keystone.server.flask.application   File "/var/lib/kolla/venv/lib/python3.9/site-packages/keystone/api/projects.py", line 151, in get
2023-04-12 20:45:02.147260 2023-04-12 20:45:02.143 39 ERROR keystone.server.flask.application     return self._get_project(project_id)
2023-04-12 20:45:02.147271 2023-04-12 20:45:02.143 39 ERROR keystone.server.flask.application   File "/var/lib/kolla/venv/lib/python3.9/site-packages/keystone/api/projects.py", line 107, in _get_project
2023-04-12 20:45:02.147281 2023-04-12 20:45:02.143 39 ERROR keystone.server.flask.application     project = PROVIDERS.resource_api.get_project(project_id)
2023-04-12 20:45:02.147291 2023-04-12 20:45:02.143 39 ERROR keystone.server.flask.application   File "/var/lib/kolla/venv/lib/python3.9/site-packages/keystone/common/manager.py", line 115, in wrapped
2023-04-12 20:45:02.147301 2023-04-12 20:45:02.143 39 ERROR keystone.server.flask.application     __ret_val = __f(*args, **kwargs)
2023-04-12 20:45:02.147310 2023-04-12 20:45:02.143 39 ERROR keystone.server.flask.application   File "/var/lib/kolla/venv/lib/python3.9/site-packages/decorator.py", line 232, in fun
2023-04-12 20:45:02.147320 2023-04-12 20:45:02.143 39 ERROR keystone.server.flask.application     return caller(func, *(extras + args), **kw)
2023-04-12 20:45:02.147371 2023-04-12 20:45:02.143 39 ERROR keystone.server.flask.application   File "/var/lib/kolla/venv/lib/python3.9/site-packages/dogpile/cache/region.py", line 1577, in get_or_create_for_user_func
2023-04-12 20:45:02.147388 2023-04-12 20:45:02.143 39 ERROR keystone.server.flask.application     return self.get_or_create(
2023-04-12 20:45:02.147398 2023-04-12 20:45:02.143 39 ERROR keystone.server.flask.application   File "/var/lib/kolla/venv/lib/python3.9/site-packages/dogpile/cache/region.py", line 1042, in get_or_create
2023-04-12 20:45:02.147408 2023-04-12 20:45:02.143 39 ERROR keystone.server.flask.application     with Lock(
2023-04-12 20:45:02.147418 2023-04-12 20:45:02.143 39 ERROR keystone.server.flask.application   File "/var/lib/kolla/venv/lib/python3.9/site-packages/dogpile/lock.py", line 185, in __enter__
2023-04-12 20:45:02.147428 2023-04-12 20:45:02.143 39 ERROR keystone.server.flask.application     return self._enter()
2023-04-12 20:45:02.147437 2023-04-12 20:45:02.143 39 ERROR keystone.server.flask.application   File "/var/lib/kolla/venv/lib/python3.9/site-packages/dogpile/lock.py", line 94, in _enter
2023-04-12 20:45:02.147447 2023-04-12 20:45:02.143 39 ERROR keystone.server.flask.application     generated = self._enter_create(value, createdtime)
2023-04-12 20:45:02.147457 2023-04-12 20:45:02.143 39 ERROR keystone.server.flask.application   File "/var/lib/kolla/venv/lib/python3.9/site-packages/dogpile/lock.py", line 178, in _enter_create
2023-04-12 20:45:02.147466 2023-04-12 20:45:02.143 39 ERROR keystone.server.flask.application     return self.creator()
2023-04-12 20:45:02.147476 2023-04-12 20:45:02.143 39 ERROR keystone.server.flask.application   File "/var/lib/kolla/venv/lib/python3.9/site-packages/dogpile/cache/region.py", line 995, in gen_value
2023-04-12 20:45:02.147486 2023-04-12 20:45:02.143 39 ERROR keystone.server.flask.application     created_value = creator(
2023-04-12 20:45:02.147495 2023-04-12 20:45:02.143 39 ERROR keystone.server.flask.application   File "/var/lib/kolla/venv/lib/python3.9/site-packages/keystone/resource/core.py", line 903, in get_project
2023-04-12 20:45:02.147505 2023-04-12 20:45:02.143 39 ERROR keystone.server.flask.application     return self.driver.get_project(project_id)
2023-04-12 20:45:02.147514 2023-04-12 20:45:02.143 39 ERROR keystone.server.flask.application   File "/var/lib/kolla/venv/lib/python3.9/site-packages/keystone/resource/backends/sql.py", line 49, in get_project
2023-04-12 20:45:02.147524 2023-04-12 20:45:02.143 39 ERROR keystone.server.flask.application     return self._get_project(session, project_id).to_dict()
2023-04-12 20:45:02.147534 2023-04-12 20:45:02.143 39 ERROR keystone.server.flask.application   File "/var/lib/kolla/venv/lib/python3.9/site-packages/keystone/resource/backends/sql.py", line 44, in _get_project
2023-04-12 20:45:02.147544 2023-04-12 20:45:02.143 39 ERROR keystone.server.flask.application     raise exception.ProjectNotFound(project_id=project_id)
2023-04-12 20:45:02.147566 2023-04-12 20:45:02.143 39 ERROR keystone.server.flask.application keystone.exception.ProjectNotFound: Could not find project: service.
2023-04-12 20:45:02.147577 2023-04-12 20:45:02.143 39 ERROR keystone.server.flask.application \x1b[00m
2023-04-12 20:47:58.619074 2023-04-12 20:47:58.615 38 ERROR keystone.server.flask.application [None req-605f7a75-d3af-41af-9e65-650e7069fba6 75f471bf30cc4a67bf613cb538872fe7 - - all default -] Could not find project: service.: keystone.exception.ProjectNotFound: Could not find project: service.
2023-04-12 20:47:58.619148 2023-04-12 20:47:58.615 38 ERROR keystone.server.flask.application Traceback (most recent call last):
2023-04-12 20:47:58.619185 2023-04-12 20:47:58.615 38 ERROR keystone.server.flask.application   File "/var/lib/kolla/venv/lib/python3.9/site-packages/flask/app.py", line 1820, in full_dispatch_request
2023-04-12 20:47:58.619214 2023-04-12 20:47:58.615 38 ERROR keystone.server.flask.application     rv = self.dispatch_request()
2023-04-12 20:47:58.619228 2023-04-12 20:47:58.615 38 ERROR keystone.server.flask.application   File "/var/lib/kolla/venv/lib/python3.9/site-packages/flask/app.py", line 1796, in dispatch_request
2023-04-12 20:47:58.619238 2023-04-12 20:47:58.615 38 ERROR keystone.server.flask.application     return self.ensure_sync(self.view_functions[rule.endpoint])(**view_args)
2023-04-12 20:47:58.619248 2023-04-12 20:47:58.615 38 ERROR keystone.server.flask.application   File "/var/lib/kolla/venv/lib/python3.9/site-packages/flask_restful/__init__.py", line 467, in wrapper
2023-04-12 20:47:58.619258 2023-04-12 20:47:58.615 38 ERROR keystone.server.flask.application     resp = resource(*args, **kwargs)
2023-04-12 20:47:58.619268 2023-04-12 20:47:58.615 38 ERROR keystone.server.flask.application   File "/var/lib/kolla/venv/lib/python3.9/site-packages/flask/views.py", line 107, in view
2023-04-12 20:47:58.619278 2023-04-12 20:47:58.615 38 ERROR keystone.server.flask.application     return current_app.ensure_sync(self.dispatch_request)(**kwargs)
2023-04-12 20:47:58.619288 2023-04-12 20:47:58.615 38 ERROR keystone.server.flask.application   File "/var/lib/kolla/venv/lib/python3.9/site-packages/flask_restful/__init__.py", line 582, in dispatch_request
2023-04-12 20:47:58.619297 2023-04-12 20:47:58.615 38 ERROR keystone.server.flask.application     resp = meth(*args, **kwargs)
2023-04-12 20:47:58.619307 2023-04-12 20:47:58.615 38 ERROR keystone.server.flask.application   File "/var/lib/kolla/venv/lib/python3.9/site-packages/keystone/api/projects.py", line 151, in get
2023-04-12 20:47:58.619317 2023-04-12 20:47:58.615 38 ERROR keystone.server.flask.application     return self._get_project(project_id)
2023-04-12 20:47:58.619326 2023-04-12 20:47:58.615 38 ERROR keystone.server.flask.application   File "/var/lib/kolla/venv/lib/python3.9/site-packages/keystone/api/projects.py", line 107, in _get_project
2023-04-12 20:47:58.619377 2023-04-12 20:47:58.615 38 ERROR keystone.server.flask.application     project = PROVIDERS.resource_api.get_project(project_id)
2023-04-12 20:47:58.619393 2023-04-12 20:47:58.615 38 ERROR keystone.server.flask.application   File "/var/lib/kolla/venv/lib/python3.9/site-packages/keystone/common/manager.py", line 115, in wrapped
2023-04-12 20:47:58.619403 2023-04-12 20:47:58.615 38 ERROR keystone.server.flask.application     __ret_val = __f(*args, **kwargs)
2023-04-12 20:47:58.619412 2023-04-12 20:47:58.615 38 ERROR keystone.server.flask.application   File "/var/lib/kolla/venv/lib/python3.9/site-packages/decorator.py", line 232, in fun
2023-04-12 20:47:58.619422 2023-04-12 20:47:58.615 38 ERROR keystone.server.flask.application     return caller(func, *(extras + args), **kw)
2023-04-12 20:47:58.619432 2023-04-12 20:47:58.615 38 ERROR keystone.server.flask.application   File "/var/lib/kolla/venv/lib/python3.9/site-packages/dogpile/cache/region.py", line 1577, in get_or_create_for_user_func
2023-04-12 20:47:58.619442 2023-04-12 20:47:58.615 38 ERROR keystone.server.flask.application     return self.get_or_create(
2023-04-12 20:47:58.619500 2023-04-12 20:47:58.615 38 ERROR keystone.server.flask.application   File "/var/lib/kolla/venv/lib/python3.9/site-packages/dogpile/cache/region.py", line 1042, in get_or_create
2023-04-12 20:47:58.619512 2023-04-12 20:47:58.615 38 ERROR keystone.server.flask.application     with Lock(
2023-04-12 20:47:58.619521 2023-04-12 20:47:58.615 38 ERROR keystone.server.flask.application   File "/var/lib/kolla/venv/lib/python3.9/site-packages/dogpile/lock.py", line 185, in __enter__
2023-04-12 20:47:58.619531 2023-04-12 20:47:58.615 38 ERROR keystone.server.flask.application     return self._enter()
2023-04-12 20:47:58.619540 2023-04-12 20:47:58.615 38 ERROR keystone.server.flask.application   File "/var/lib/kolla/venv/lib/python3.9/site-packages/dogpile/lock.py", line 94, in _enter
2023-04-12 20:47:58.619550 2023-04-12 20:47:58.615 38 ERROR keystone.server.flask.application     generated = self._enter_create(value, createdtime)
2023-04-12 20:47:58.619560 2023-04-12 20:47:58.615 38 ERROR keystone.server.flask.application   File "/var/lib/kolla/venv/lib/python3.9/site-packages/dogpile/lock.py", line 178, in _enter_create
2023-04-12 20:47:58.619569 2023-04-12 20:47:58.615 38 ERROR keystone.server.flask.application     return self.creator()
2023-04-12 20:47:58.619578 2023-04-12 20:47:58.615 38 ERROR keystone.server.flask.application   File "/var/lib/kolla/venv/lib/python3.9/site-packages/dogpile/cache/region.py", line 995, in gen_value
2023-04-12 20:47:58.619588 2023-04-12 20:47:58.615 38 ERROR keystone.server.flask.application     created_value = creator(
2023-04-12 20:47:58.619613 2023-04-12 20:47:58.615 38 ERROR keystone.server.flask.application   File "/var/lib/kolla/venv/lib/python3.9/site-packages/keystone/resource/core.py", line 903, in get_project
2023-04-12 20:47:58.619629 2023-04-12 20:47:58.615 38 ERROR keystone.server.flask.application     return self.driver.get_project(project_id)
2023-04-12 20:47:58.619639 2023-04-12 20:47:58.615 38 ERROR keystone.server.flask.application   File "/var/lib/kolla/venv/lib/python3.9/site-packages/keystone/resource/backends/sql.py", line 49, in get_project
2023-04-12 20:47:58.619649 2023-04-12 20:47:58.615 38 ERROR keystone.server.flask.application     return self._get_project(session, project_id).to_dict()
2023-04-12 20:47:58.619658 2023-04-12 20:47:58.615 38 ERROR keystone.server.flask.application   File "/var/lib/kolla/venv/lib/python3.9/site-packages/keystone/resource/backends/sql.py", line 44, in _get_project
2023-04-12 20:47:58.619667 2023-04-12 20:47:58.615 38 ERROR keystone.server.flask.application     raise exception.ProjectNotFound(project_id=project_id)
2023-04-12 20:47:58.619677 2023-04-12 20:47:58.615 38 ERROR keystone.server.flask.application keystone.exception.ProjectNotFound: Could not find project: service.
2023-04-12 20:47:58.619686 2023-04-12 20:47:58.615 38 ERROR keystone.server.flask.application \x1b[00m
2023-04-12 20:48:13.239719 2023-04-12 20:48:13.235 40 ERROR keystone.server.flask.application [None req-04f84155-a863-4a40-a432-d15a1a2de378 75f471bf30cc4a67bf613cb538872fe7 - - all default -] Could not find role: admin.: keystone.exception.RoleNotFound: Could not find role: admin.
2023-04-12 20:48:13.239765 2023-04-12 20:48:13.235 40 ERROR keystone.server.flask.application Traceback (most recent call last):
2023-04-12 20:48:13.239779 2023-04-12 20:48:13.235 40 ERROR keystone.server.flask.application   File "/var/lib/kolla/venv/lib/python3.9/site-packages/flask/app.py", line 1820, in full_dispatch_request
2023-04-12 20:48:13.239800 2023-04-12 20:48:13.235 40 ERROR keystone.server.flask.application     rv = self.dispatch_request()
2023-04-12 20:48:13.239817 2023-04-12 20:48:13.235 40 ERROR keystone.server.flask.application   File "/var/lib/kolla/venv/lib/python3.9/site-packages/flask/app.py", line 1796, in dispatch_request
2023-04-12 20:48:13.239836 2023-04-12 20:48:13.235 40 ERROR keystone.server.flask.application     return self.ensure_sync(self.view_functions[rule.endpoint])(**view_args)
2023-04-12 20:48:13.239853 2023-04-12 20:48:13.235 40 ERROR keystone.server.flask.application   File "/var/lib/kolla/venv/lib/python3.9/site-packages/flask_restful/__init__.py", line 467, in wrapper
2023-04-12 20:48:13.239883 2023-04-12 20:48:13.235 40 ERROR keystone.server.flask.application     resp = resource(*args, **kwargs)
2023-04-12 20:48:13.239895 2023-04-12 20:48:13.235 40 ERROR keystone.server.flask.application   File "/var/lib/kolla/venv/lib/python3.9/site-packages/flask/views.py", line 107, in view
2023-04-12 20:48:13.239905 2023-04-12 20:48:13.235 40 ERROR keystone.server.flask.application     return current_app.ensure_sync(self.dispatch_request)(**kwargs)
2023-04-12 20:48:13.239915 2023-04-12 20:48:13.235 40 ERROR keystone.server.flask.application   File "/var/lib/kolla/venv/lib/python3.9/site-packages/flask_restful/__init__.py", line 582, in dispatch_request
2023-04-12 20:48:13.239924 2023-04-12 20:48:13.235 40 ERROR keystone.server.flask.application     resp = meth(*args, **kwargs)
2023-04-12 20:48:13.239934 2023-04-12 20:48:13.235 40 ERROR keystone.server.flask.application   File "/var/lib/kolla/venv/lib/python3.9/site-packages/keystone/api/roles.py", line 50, in get
2023-04-12 20:48:13.239944 2023-04-12 20:48:13.235 40 ERROR keystone.server.flask.application     return self._get_role(role_id)
2023-04-12 20:48:13.239954 2023-04-12 20:48:13.235 40 ERROR keystone.server.flask.application   File "/var/lib/kolla/venv/lib/python3.9/site-packages/keystone/api/roles.py", line 70, in _get_role
2023-04-12 20:48:13.239972 2023-04-12 20:48:13.235 40 ERROR keystone.server.flask.application     ENFORCER.enforce_call(action='identity:get_role')
2023-04-12 20:48:13.240002 2023-04-12 20:48:13.235 40 ERROR keystone.server.flask.application   File "/var/lib/kolla/venv/lib/python3.9/site-packages/keystone/common/rbac_enforcer/enforcer.py", line 402, in enforce_call
2023-04-12 20:48:13.240013 2023-04-12 20:48:13.235 40 ERROR keystone.server.flask.application     policy_dict.update(cls._extract_member_target_data(
2023-04-12 20:48:13.240023 2023-04-12 20:48:13.235 40 ERROR keystone.server.flask.application   File "/var/lib/kolla/venv/lib/python3.9/site-packages/keystone/common/rbac_enforcer/enforcer.py", line 234, in _extract_member_target_data
2023-04-12 20:48:13.240033 2023-04-12 20:48:13.235 40 ERROR keystone.server.flask.application     member_name: func(flask.request.view_args[key])
2023-04-12 20:48:13.240042 2023-04-12 20:48:13.235 40 ERROR keystone.server.flask.application   File "/var/lib/kolla/venv/lib/python3.9/site-packages/keystone/common/manager.py", line 115, in wrapped
2023-04-12 20:48:13.240051 2023-04-12 20:48:13.235 40 ERROR keystone.server.flask.application     __ret_val = __f(*args, **kwargs)
2023-04-12 20:48:13.240061 2023-04-12 20:48:13.235 40 ERROR keystone.server.flask.application   File "/var/lib/kolla/venv/lib/python3.9/site-packages/decorator.py", line 232, in fun
2023-04-12 20:48:13.240070 2023-04-12 20:48:13.235 40 ERROR keystone.server.flask.application     return caller(func, *(extras + args), **kw)
2023-04-12 20:48:13.240079 2023-04-12 20:48:13.235 40 ERROR keystone.server.flask.application   File "/var/lib/kolla/venv/lib/python3.9/site-packages/dogpile/cache/region.py", line 1577, in get_or_create_for_user_func
2023-04-12 20:48:13.240089 2023-04-12 20:48:13.235 40 ERROR keystone.server.flask.application     return self.get_or_create(
2023-04-12 20:48:13.240098 2023-04-12 20:48:13.235 40 ERROR keystone.server.flask.application   File "/var/lib/kolla/venv/lib/python3.9/site-packages/dogpile/cache/region.py", line 1042, in get_or_create
2023-04-12 20:48:13.240107 2023-04-12 20:48:13.235 40 ERROR keystone.server.flask.application     with Lock(
2023-04-12 20:48:13.240116 2023-04-12 20:48:13.235 40 ERROR keystone.server.flask.application   File "/var/lib/kolla/venv/lib/python3.9/site-packages/dogpile/lock.py", line 185, in __enter__
2023-04-12 20:48:13.240126 2023-04-12 20:48:13.235 40 ERROR keystone.server.flask.application     return self._enter()
2023-04-12 20:48:13.240135 2023-04-12 20:48:13.235 40 ERROR keystone.server.flask.application   File "/var/lib/kolla/venv/lib/python3.9/site-packages/dogpile/lock.py", line 94, in _enter
2023-04-12 20:48:13.240156 2023-04-12 20:48:13.235 40 ERROR keystone.server.flask.application     generated = self._enter_create(value, createdtime)
2023-04-12 20:48:13.240167 2023-04-12 20:48:13.235 40 ERROR keystone.server.flask.application   File "/var/lib/kolla/venv/lib/python3.9/site-packages/dogpile/lock.py", line 178, in _enter_create
2023-04-12 20:48:13.240177 2023-04-12 20:48:13.235 40 ERROR keystone.server.flask.application     return self.creator()
2023-04-12 20:48:13.240186 2023-04-12 20:48:13.235 40 ERROR keystone.server.flask.application   File "/var/lib/kolla/venv/lib/python3.9/site-packages/dogpile/cache/region.py", line 995, in gen_value
2023-04-12 20:48:13.240196 2023-04-12 20:48:13.235 40 ERROR keystone.server.flask.application     created_value = creator(
2023-04-12 20:48:13.240206 2023-04-12 20:48:13.235 40 ERROR keystone.server.flask.application   File "/var/lib/kolla/venv/lib/python3.9/site-packages/keystone/assignment/core.py", line 1276, in get_role
2023-04-12 20:48:13.240216 2023-04-12 20:48:13.235 40 ERROR keystone.server.flask.application     return self.driver.get_role(role_id)
2023-04-12 20:48:13.240225 2023-04-12 20:48:13.235 40 ERROR keystone.server.flask.application   File "/var/lib/kolla/venv/lib/python3.9/site-packages/keystone/assignment/role_backends/sql.py", line 70, in get_role
2023-04-12 20:48:13.240235 2023-04-12 20:48:13.235 40 ERROR keystone.server.flask.application     return self._get_role(session, role_id).to_dict()
2023-04-12 20:48:13.240244 2023-04-12 20:48:13.235 40 ERROR keystone.server.flask.application   File "/var/lib/kolla/venv/lib/python3.9/site-packages/keystone/assignment/role_backends/sql.py", line 65, in _get_role
2023-04-12 20:48:13.240258 2023-04-12 20:48:13.235 40 ERROR keystone.server.flask.application     raise exception.RoleNotFound(role_id=role_id)
2023-04-12 20:48:13.240267 2023-04-12 20:48:13.235 40 ERROR keystone.server.flask.application keystone.exception.RoleNotFound: Could not find role: admin.
2023-04-12 20:48:13.240276 2023-04-12 20:48:13.235 40 ERROR keystone.server.flask.application \x1b[00m
2023-04-12 20:48:14.682616 2023-04-12 20:48:14.679 40 ERROR keystone.server.flask.application [None req-33e74ff7-d9a9-4acd-a32b-1c555d72183d 75f471bf30cc4a67bf613cb538872fe7 - - all default -] Could not find user: neutron.: keystone.exception.UserNotFound: Could not find user: neutron.
2023-04-12 20:48:14.682678 2023-04-12 20:48:14.679 40 ERROR keystone.server.flask.application Traceback (most recent call last):
2023-04-12 20:48:14.682699 2023-04-12 20:48:14.679 40 ERROR keystone.server.flask.application   File "/var/lib/kolla/venv/lib/python3.9/site-packages/flask/app.py", line 1820, in full_dispatch_request
2023-04-12 20:48:14.682715 2023-04-12 20:48:14.679 40 ERROR keystone.server.flask.application     rv = self.dispatch_request()
2023-04-12 20:48:14.682726 2023-04-12 20:48:14.679 40 ERROR keystone.server.flask.application   File "/var/lib/kolla/venv/lib/python3.9/site-packages/flask/app.py", line 1796, in dispatch_request
2023-04-12 20:48:14.682736 2023-04-12 20:48:14.679 40 ERROR keystone.server.flask.application     return self.ensure_sync(self.view_functions[rule.endpoint])(**view_args)
2023-04-12 20:48:14.682747 2023-04-12 20:48:14.679 40 ERROR keystone.server.flask.application   File "/var/lib/kolla/venv/lib/python3.9/site-packages/flask_restful/__init__.py", line 467, in wrapper
2023-04-12 20:48:14.682767 2023-04-12 20:48:14.679 40 ERROR keystone.server.flask.application     resp = resource(*args, **kwargs)
2023-04-12 20:48:14.682788 2023-04-12 20:48:14.679 40 ERROR keystone.server.flask.application   File "/var/lib/kolla/venv/lib/python3.9/site-packages/flask/views.py", line 107, in view
2023-04-12 20:48:14.682807 2023-04-12 20:48:14.679 40 ERROR keystone.server.flask.application     return current_app.ensure_sync(self.dispatch_request)(**kwargs)
2023-04-12 20:48:14.682824 2023-04-12 20:48:14.679 40 ERROR keystone.server.flask.application   File "/var/lib/kolla/venv/lib/python3.9/site-packages/flask_restful/__init__.py", line 582, in dispatch_request
2023-04-12 20:48:14.682894 2023-04-12 20:48:14.679 40 ERROR keystone.server.flask.application     resp = meth(*args, **kwargs)
2023-04-12 20:48:14.682915 2023-04-12 20:48:14.679 40 ERROR keystone.server.flask.application   File "/var/lib/kolla/venv/lib/python3.9/site-packages/keystone/api/users.py", line 182, in get
2023-04-12 20:48:14.682931 2023-04-12 20:48:14.679 40 ERROR keystone.server.flask.application     return self._get_user(user_id)
2023-04-12 20:48:14.682959 2023-04-12 20:48:14.679 40 ERROR keystone.server.flask.application   File "/var/lib/kolla/venv/lib/python3.9/site-packages/keystone/api/users.py", line 194, in _get_user
2023-04-12 20:48:14.682976 2023-04-12 20:48:14.679 40 ERROR keystone.server.flask.application     ref = PROVIDERS.identity_api.get_user(user_id)
2023-04-12 20:48:14.682993 2023-04-12 20:48:14.679 40 ERROR keystone.server.flask.application   File "/var/lib/kolla/venv/lib/python3.9/site-packages/keystone/common/manager.py", line 115, in wrapped
2023-04-12 20:48:14.683011 2023-04-12 20:48:14.679 40 ERROR keystone.server.flask.application     __ret_val = __f(*args, **kwargs)
2023-04-12 20:48:14.683025 2023-04-12 20:48:14.679 40 ERROR keystone.server.flask.application   File "/var/lib/kolla/venv/lib/python3.9/site-packages/keystone/identity/core.py", line 414, in wrapper
2023-04-12 20:48:14.683046 2023-04-12 20:48:14.679 40 ERROR keystone.server.flask.application     return f(self, *args, **kwargs)
2023-04-12 20:48:14.683059 2023-04-12 20:48:14.679 40 ERROR keystone.server.flask.application   File "/var/lib/kolla/venv/lib/python3.9/site-packages/keystone/identity/core.py", line 424, in wrapper
2023-04-12 20:48:14.683073 2023-04-12 20:48:14.679 40 ERROR keystone.server.flask.application     return f(self, *args, **kwargs)
2023-04-12 20:48:14.683082 2023-04-12 20:48:14.679 40 ERROR keystone.server.flask.application   File "/var/lib/kolla/venv/lib/python3.9/site-packages/decorator.py", line 232, in fun
2023-04-12 20:48:14.683092 2023-04-12 20:48:14.679 40 ERROR keystone.server.flask.application     return caller(func, *(extras + args), **kw)
2023-04-12 20:48:14.683102 2023-04-12 20:48:14.679 40 ERROR keystone.server.flask.application   File "/var/lib/kolla/venv/lib/python3.9/site-packages/dogpile/cache/region.py", line 1577, in get_or_create_for_user_func
2023-04-12 20:48:14.683112 2023-04-12 20:48:14.679 40 ERROR keystone.server.flask.application     return self.get_or_create(
2023-04-12 20:48:14.683121 2023-04-12 20:48:14.679 40 ERROR keystone.server.flask.application   File "/var/lib/kolla/venv/lib/python3.9/site-packages/dogpile/cache/region.py", line 1042, in get_or_create
2023-04-12 20:48:14.683131 2023-04-12 20:48:14.679 40 ERROR keystone.server.flask.application     with Lock(
2023-04-12 20:48:14.683140 2023-04-12 20:48:14.679 40 ERROR keystone.server.flask.application   File "/var/lib/kolla/venv/lib/python3.9/site-packages/dogpile/lock.py", line 185, in __enter__
2023-04-12 20:48:14.683150 2023-04-12 20:48:14.679 40 ERROR keystone.server.flask.application     return self._enter()
2023-04-12 20:48:14.683159 2023-04-12 20:48:14.679 40 ERROR keystone.server.flask.application   File "/var/lib/kolla/venv/lib/python3.9/site-packages/dogpile/lock.py", line 94, in _enter
2023-04-12 20:48:14.683169 2023-04-12 20:48:14.679 40 ERROR keystone.server.flask.application     generated = self._enter_create(value, createdtime)
2023-04-12 20:48:14.683178 2023-04-12 20:48:14.679 40 ERROR keystone.server.flask.application   File "/var/lib/kolla/venv/lib/python3.9/site-packages/dogpile/lock.py", line 178, in _enter_create
2023-04-12 20:48:14.683188 2023-04-12 20:48:14.679 40 ERROR keystone.server.flask.application     return self.creator()
2023-04-12 20:48:14.683197 2023-04-12 20:48:14.679 40 ERROR keystone.server.flask.application   File "/var/lib/kolla/venv/lib/python3.9/site-packages/dogpile/cache/region.py", line 995, in gen_value
2023-04-12 20:48:14.683207 2023-04-12 20:48:14.679 40 ERROR keystone.server.flask.application     created_value = creator(
2023-04-12 20:48:14.683231 2023-04-12 20:48:14.679 40 ERROR keystone.server.flask.application   File "/var/lib/kolla/venv/lib/python3.9/site-packages/keystone/identity/core.py", line 1011, in get_user
2023-04-12 20:48:14.683242 2023-04-12 20:48:14.679 40 ERROR keystone.server.flask.application     ref = driver.get_user(entity_id)
2023-04-12 20:48:14.683252 2023-04-12 20:48:14.679 40 ERROR keystone.server.flask.application   File "/var/lib/kolla/venv/lib/python3.9/site-packages/keystone/identity/backends/sql.py", line 200, in get_user
2023-04-12 20:48:14.683261 2023-04-12 20:48:14.679 40 ERROR keystone.server.flask.application     self._get_user(session, user_id).to_dict())
2023-04-12 20:48:14.683271 2023-04-12 20:48:14.679 40 ERROR keystone.server.flask.application   File "/var/lib/kolla/venv/lib/python3.9/site-packages/keystone/identity/backends/sql.py", line 194, in _get_user
2023-04-12 20:48:14.683281 2023-04-12 20:48:14.679 40 ERROR keystone.server.flask.application     raise exception.UserNotFound(user_id=user_id)
2023-04-12 20:48:14.683291 2023-04-12 20:48:14.679 40 ERROR keystone.server.flask.application keystone.exception.UserNotFound: Could not find user: neutron.
2023-04-12 20:48:14.683300 2023-04-12 20:48:14.679 40 ERROR keystone.server.flask.application \x1b[00m
2023-04-12 20:48:15.745747 2023-04-12 20:48:15.739 39 ERROR keystone.server.flask.application [None req-d60817cf-f978-4b3f-9b98-335b957a538b 75f471bf30cc4a67bf613cb538872fe7 - - all default -] Could not find project: service.: keystone.exception.ProjectNotFound: Could not find project: service.
2023-04-12 20:48:15.745844 2023-04-12 20:48:15.739 39 ERROR keystone.server.flask.application Traceback (most recent call last):
2023-04-12 20:48:15.745872 2023-04-12 20:48:15.739 39 ERROR keystone.server.flask.application   File "/var/lib/kolla/venv/lib/python3.9/site-packages/flask/app.py", line 1820, in full_dispatch_request
2023-04-12 20:48:15.745892 2023-04-12 20:48:15.739 39 ERROR keystone.server.flask.application     rv = self.dispatch_request()
2023-04-12 20:48:15.745908 2023-04-12 20:48:15.739 39 ERROR keystone.server.flask.application   File "/var/lib/kolla/venv/lib/python3.9/site-packages/flask/app.py", line 1796, in dispatch_request
2023-04-12 20:48:15.745942 2023-04-12 20:48:15.739 39 ERROR keystone.server.flask.application     return self.ensure_sync(self.view_functions[rule.endpoint])(**view_args)
2023-04-12 20:48:15.745958 2023-04-12 20:48:15.739 39 ERROR keystone.server.flask.application   File "/var/lib/kolla/venv/lib/python3.9/site-packages/flask_restful/__init__.py", line 467, in wrapper
2023-04-12 20:48:15.745974 2023-04-12 20:48:15.739 39 ERROR keystone.server.flask.application     resp = resource(*args, **kwargs)
2023-04-12 20:48:15.745995 2023-04-12 20:48:15.739 39 ERROR keystone.server.flask.application   File "/var/lib/kolla/venv/lib/python3.9/site-packages/flask/views.py", line 107, in view
2023-04-12 20:48:15.746035 2023-04-12 20:48:15.739 39 ERROR keystone.server.flask.application     return current_app.ensure_sync(self.dispatch_request)(**kwargs)
2023-04-12 20:48:15.746054 2023-04-12 20:48:15.739 39 ERROR keystone.server.flask.application   File "/var/lib/kolla/venv/lib/python3.9/site-packages/flask_restful/__init__.py", line 582, in dispatch_request
2023-04-12 20:48:15.746071 2023-04-12 20:48:15.739 39 ERROR keystone.server.flask.application     resp = meth(*args, **kwargs)
2023-04-12 20:48:15.746087 2023-04-12 20:48:15.739 39 ERROR keystone.server.flask.application   File "/var/lib/kolla/venv/lib/python3.9/site-packages/keystone/api/projects.py", line 151, in get
2023-04-12 20:48:15.746111 2023-04-12 20:48:15.739 39 ERROR keystone.server.flask.application     return self._get_project(project_id)
2023-04-12 20:48:15.746135 2023-04-12 20:48:15.739 39 ERROR keystone.server.flask.application   File "/var/lib/kolla/venv/lib/python3.9/site-packages/keystone/api/projects.py", line 107, in _get_project
2023-04-12 20:48:15.746153 2023-04-12 20:48:15.739 39 ERROR keystone.server.flask.application     project = PROVIDERS.resource_api.get_project(project_id)
2023-04-12 20:48:15.746198 2023-04-12 20:48:15.739 39 ERROR keystone.server.flask.application   File "/var/lib/kolla/venv/lib/python3.9/site-packages/keystone/common/manager.py", line 115, in wrapped
2023-04-12 20:48:15.746217 2023-04-12 20:48:15.739 39 ERROR keystone.server.flask.application     __ret_val = __f(*args, **kwargs)
2023-04-12 20:48:15.746233 2023-04-12 20:48:15.739 39 ERROR keystone.server.flask.application   File "/var/lib/kolla/venv/lib/python3.9/site-packages/decorator.py", line 232, in fun
2023-04-12 20:48:15.746249 2023-04-12 20:48:15.739 39 ERROR keystone.server.flask.application     return caller(func, *(extras + args), **kw)
2023-04-12 20:48:15.746265 2023-04-12 20:48:15.739 39 ERROR keystone.server.flask.application   File "/var/lib/kolla/venv/lib/python3.9/site-packages/dogpile/cache/region.py", line 1577, in get_or_create_for_user_func
2023-04-12 20:48:15.746282 2023-04-12 20:48:15.739 39 ERROR keystone.server.flask.application     return self.get_or_create(
2023-04-12 20:48:15.746306 2023-04-12 20:48:15.739 39 ERROR keystone.server.flask.application   File "/var/lib/kolla/venv/lib/python3.9/site-packages/dogpile/cache/region.py", line 1042, in get_or_create
2023-04-12 20:48:15.746325 2023-04-12 20:48:15.739 39 ERROR keystone.server.flask.application     with Lock(
2023-04-12 20:48:15.746422 2023-04-12 20:48:15.739 39 ERROR keystone.server.flask.application   File "/var/lib/kolla/venv/lib/python3.9/site-packages/dogpile/lock.py", line 185, in __enter__
2023-04-12 20:48:15.746454 2023-04-12 20:48:15.739 39 ERROR keystone.server.flask.application     return self._enter()
2023-04-12 20:48:15.746471 2023-04-12 20:48:15.739 39 ERROR keystone.server.flask.application   File "/var/lib/kolla/venv/lib/python3.9/site-packages/dogpile/lock.py", line 94, in _enter
2023-04-12 20:48:15.746487 2023-04-12 20:48:15.739 39 ERROR keystone.server.flask.application     generated = self._enter_create(value, createdtime)
2023-04-12 20:48:15.746503 2023-04-12 20:48:15.739 39 ERROR keystone.server.flask.application   File "/var/lib/kolla/venv/lib/python3.9/site-packages/dogpile/lock.py", line 178, in _enter_create
2023-04-12 20:48:15.746519 2023-04-12 20:48:15.739 39 ERROR keystone.server.flask.application     return self.creator()
2023-04-12 20:48:15.746539 2023-04-12 20:48:15.739 39 ERROR keystone.server.flask.application   File "/var/lib/kolla/venv/lib/python3.9/site-packages/dogpile/cache/region.py", line 995, in gen_value
2023-04-12 20:48:15.746561 2023-04-12 20:48:15.739 39 ERROR keystone.server.flask.application     created_value = creator(
2023-04-12 20:48:15.746577 2023-04-12 20:48:15.739 39 ERROR keystone.server.flask.application   File "/var/lib/kolla/venv/lib/python3.9/site-packages/keystone/resource/core.py", line 903, in get_project
2023-04-12 20:48:15.746593 2023-04-12 20:48:15.739 39 ERROR keystone.server.flask.application     return self.driver.get_project(project_id)
2023-04-12 20:48:15.746650 2023-04-12 20:48:15.739 39 ERROR keystone.server.flask.application   File "/var/lib/kolla/venv/lib/python3.9/site-packages/keystone/resource/backends/sql.py", line 49, in get_project
2023-04-12 20:48:15.746681 2023-04-12 20:48:15.739 39 ERROR keystone.server.flask.application     return self._get_project(session, project_id).to_dict()
2023-04-12 20:48:15.746711 2023-04-12 20:48:15.739 39 ERROR keystone.server.flask.application   File "/var/lib/kolla/venv/lib/python3.9/site-packages/keystone/resource/backends/sql.py", line 44, in _get_project
2023-04-12 20:48:15.746745 2023-04-12 20:48:15.739 39 ERROR keystone.server.flask.application     raise exception.ProjectNotFound(project_id=project_id)
2023-04-12 20:48:15.746772 2023-04-12 20:48:15.739 39 ERROR keystone.server.flask.application keystone.exception.ProjectNotFound: Could not find project: service.
2023-04-12 20:48:15.746801 2023-04-12 20:48:15.739 39 ERROR keystone.server.flask.application \x1b[00m
