2023-02-28 22:10:17.612868 2023-02-28 22:10:17.611 39 WARNING keystone.common.rbac_enforcer.enforcer [None req-810e21a9-25c2-4757-a6e8-efd47d71f7da afab145532ce44e89a27128ecf3b716c - - all default -] Deprecated policy rules found. Use oslopolicy-policy-generator and oslopolicy-policy-upgrade to detect and resolve deprecated policies in your configuration.\x1b[00m
2023-02-28 22:10:18.427132 2023-02-28 22:10:18.425 37 WARNING keystone.common.rbac_enforcer.enforcer [None req-c7215690-a274-45d4-98bd-4f91f49db738 afab145532ce44e89a27128ecf3b716c - - all default -] Deprecated policy rules found. Use oslopolicy-policy-generator and oslopolicy-policy-upgrade to detect and resolve deprecated policies in your configuration.\x1b[00m
2023-02-28 22:10:26.137920 2023-02-28 22:10:26.135 38 WARNING keystone.common.rbac_enforcer.enforcer [None req-ec864d99-6de6-4d9e-bd2b-54cd386fe4b7 afab145532ce44e89a27128ecf3b716c - - all default -] Deprecated policy rules found. Use oslopolicy-policy-generator and oslopolicy-policy-upgrade to detect and resolve deprecated policies in your configuration.\x1b[00m
2023-02-28 22:11:41.907506 2023-02-28 22:11:41.887 39 ERROR keystone.server.flask.application [None req-f0c6b49f-6f67-45a3-89a9-8589f204cdd8 afab145532ce44e89a27128ecf3b716c - - all default -] Could not find project: service.: keystone.exception.ProjectNotFound: Could not find project: service.
2023-02-28 22:11:41.907572 2023-02-28 22:11:41.887 39 ERROR keystone.server.flask.application Traceback (most recent call last):
2023-02-28 22:11:41.907586 2023-02-28 22:11:41.887 39 ERROR keystone.server.flask.application   File "/var/lib/kolla/venv/lib/python3.9/site-packages/flask/app.py", line 1820, in full_dispatch_request
2023-02-28 22:11:41.907597 2023-02-28 22:11:41.887 39 ERROR keystone.server.flask.application     rv = self.dispatch_request()
2023-02-28 22:11:41.907607 2023-02-28 22:11:41.887 39 ERROR keystone.server.flask.application   File "/var/lib/kolla/venv/lib/python3.9/site-packages/flask/app.py", line 1796, in dispatch_request
2023-02-28 22:11:41.907618 2023-02-28 22:11:41.887 39 ERROR keystone.server.flask.application     return self.ensure_sync(self.view_functions[rule.endpoint])(**view_args)
2023-02-28 22:11:41.907628 2023-02-28 22:11:41.887 39 ERROR keystone.server.flask.application   File "/var/lib/kolla/venv/lib/python3.9/site-packages/flask_restful/__init__.py", line 467, in wrapper
2023-02-28 22:11:41.907638 2023-02-28 22:11:41.887 39 ERROR keystone.server.flask.application     resp = resource(*args, **kwargs)
2023-02-28 22:11:41.907654 2023-02-28 22:11:41.887 39 ERROR keystone.server.flask.application   File "/var/lib/kolla/venv/lib/python3.9/site-packages/flask/views.py", line 107, in view
2023-02-28 22:11:41.907667 2023-02-28 22:11:41.887 39 ERROR keystone.server.flask.application     return current_app.ensure_sync(self.dispatch_request)(**kwargs)
2023-02-28 22:11:41.907677 2023-02-28 22:11:41.887 39 ERROR keystone.server.flask.application   File "/var/lib/kolla/venv/lib/python3.9/site-packages/flask_restful/__init__.py", line 582, in dispatch_request
2023-02-28 22:11:41.907687 2023-02-28 22:11:41.887 39 ERROR keystone.server.flask.application     resp = meth(*args, **kwargs)
2023-02-28 22:11:41.907697 2023-02-28 22:11:41.887 39 ERROR keystone.server.flask.application   File "/var/lib/kolla/venv/lib/python3.9/site-packages/keystone/api/projects.py", line 151, in get
2023-02-28 22:11:41.907708 2023-02-28 22:11:41.887 39 ERROR keystone.server.flask.application     return self._get_project(project_id)
2023-02-28 22:11:41.907718 2023-02-28 22:11:41.887 39 ERROR keystone.server.flask.application   File "/var/lib/kolla/venv/lib/python3.9/site-packages/keystone/api/projects.py", line 107, in _get_project
2023-02-28 22:11:41.907728 2023-02-28 22:11:41.887 39 ERROR keystone.server.flask.application     project = PROVIDERS.resource_api.get_project(project_id)
2023-02-28 22:11:41.907738 2023-02-28 22:11:41.887 39 ERROR keystone.server.flask.application   File "/var/lib/kolla/venv/lib/python3.9/site-packages/keystone/common/manager.py", line 115, in wrapped
2023-02-28 22:11:41.907768 2023-02-28 22:11:41.887 39 ERROR keystone.server.flask.application     __ret_val = __f(*args, **kwargs)
2023-02-28 22:11:41.907780 2023-02-28 22:11:41.887 39 ERROR keystone.server.flask.application   File "/var/lib/kolla/venv/lib/python3.9/site-packages/decorator.py", line 232, in fun
2023-02-28 22:11:41.907790 2023-02-28 22:11:41.887 39 ERROR keystone.server.flask.application     return caller(func, *(extras + args), **kw)
2023-02-28 22:11:41.907817 2023-02-28 22:11:41.887 39 ERROR keystone.server.flask.application   File "/var/lib/kolla/venv/lib/python3.9/site-packages/dogpile/cache/region.py", line 1577, in get_or_create_for_user_func
2023-02-28 22:11:41.907845 2023-02-28 22:11:41.887 39 ERROR keystone.server.flask.application     return self.get_or_create(
2023-02-28 22:11:41.907856 2023-02-28 22:11:41.887 39 ERROR keystone.server.flask.application   File "/var/lib/kolla/venv/lib/python3.9/site-packages/dogpile/cache/region.py", line 1042, in get_or_create
2023-02-28 22:11:41.907867 2023-02-28 22:11:41.887 39 ERROR keystone.server.flask.application     with Lock(
2023-02-28 22:11:41.907877 2023-02-28 22:11:41.887 39 ERROR keystone.server.flask.application   File "/var/lib/kolla/venv/lib/python3.9/site-packages/dogpile/lock.py", line 185, in __enter__
2023-02-28 22:11:41.907887 2023-02-28 22:11:41.887 39 ERROR keystone.server.flask.application     return self._enter()
2023-02-28 22:11:41.907896 2023-02-28 22:11:41.887 39 ERROR keystone.server.flask.application   File "/var/lib/kolla/venv/lib/python3.9/site-packages/dogpile/lock.py", line 94, in _enter
2023-02-28 22:11:41.907906 2023-02-28 22:11:41.887 39 ERROR keystone.server.flask.application     generated = self._enter_create(value, createdtime)
2023-02-28 22:11:41.907916 2023-02-28 22:11:41.887 39 ERROR keystone.server.flask.application   File "/var/lib/kolla/venv/lib/python3.9/site-packages/dogpile/lock.py", line 178, in _enter_create
2023-02-28 22:11:41.907926 2023-02-28 22:11:41.887 39 ERROR keystone.server.flask.application     return self.creator()
2023-02-28 22:11:41.907936 2023-02-28 22:11:41.887 39 ERROR keystone.server.flask.application   File "/var/lib/kolla/venv/lib/python3.9/site-packages/dogpile/cache/region.py", line 995, in gen_value
2023-02-28 22:11:41.907946 2023-02-28 22:11:41.887 39 ERROR keystone.server.flask.application     created_value = creator(
2023-02-28 22:11:41.907955 2023-02-28 22:11:41.887 39 ERROR keystone.server.flask.application   File "/var/lib/kolla/venv/lib/python3.9/site-packages/keystone/resource/core.py", line 903, in get_project
2023-02-28 22:11:41.907965 2023-02-28 22:11:41.887 39 ERROR keystone.server.flask.application     return self.driver.get_project(project_id)
2023-02-28 22:11:41.907975 2023-02-28 22:11:41.887 39 ERROR keystone.server.flask.application   File "/var/lib/kolla/venv/lib/python3.9/site-packages/keystone/resource/backends/sql.py", line 49, in get_project
2023-02-28 22:11:41.907985 2023-02-28 22:11:41.887 39 ERROR keystone.server.flask.application     return self._get_project(session, project_id).to_dict()
2023-02-28 22:11:41.907995 2023-02-28 22:11:41.887 39 ERROR keystone.server.flask.application   File "/var/lib/kolla/venv/lib/python3.9/site-packages/keystone/resource/backends/sql.py", line 44, in _get_project
2023-02-28 22:11:41.908005 2023-02-28 22:11:41.887 39 ERROR keystone.server.flask.application     raise exception.ProjectNotFound(project_id=project_id)
2023-02-28 22:11:41.908015 2023-02-28 22:11:41.887 39 ERROR keystone.server.flask.application keystone.exception.ProjectNotFound: Could not find project: service.
2023-02-28 22:11:41.908024 2023-02-28 22:11:41.887 39 ERROR keystone.server.flask.application \x1b[00m
2023-02-28 22:11:50.400761 2023-02-28 22:11:50.391 38 ERROR keystone.server.flask.application [None req-3d31a759-26a2-401a-92df-2a4fddbd91e0 afab145532ce44e89a27128ecf3b716c - - all default -] Could not find project: service.: keystone.exception.ProjectNotFound: Could not find project: service.
2023-02-28 22:11:50.400854 2023-02-28 22:11:50.391 38 ERROR keystone.server.flask.application Traceback (most recent call last):
2023-02-28 22:11:50.400924 2023-02-28 22:11:50.391 38 ERROR keystone.server.flask.application   File "/var/lib/kolla/venv/lib/python3.9/site-packages/flask/app.py", line 1820, in full_dispatch_request
2023-02-28 22:11:50.400948 2023-02-28 22:11:50.391 38 ERROR keystone.server.flask.application     rv = self.dispatch_request()
2023-02-28 22:11:50.400973 2023-02-28 22:11:50.391 38 ERROR keystone.server.flask.application   File "/var/lib/kolla/venv/lib/python3.9/site-packages/flask/app.py", line 1796, in dispatch_request
2023-02-28 22:11:50.400995 2023-02-28 22:11:50.391 38 ERROR keystone.server.flask.application     return self.ensure_sync(self.view_functions[rule.endpoint])(**view_args)
2023-02-28 22:11:50.401013 2023-02-28 22:11:50.391 38 ERROR keystone.server.flask.application   File "/var/lib/kolla/venv/lib/python3.9/site-packages/flask_restful/__init__.py", line 467, in wrapper
2023-02-28 22:11:50.401032 2023-02-28 22:11:50.391 38 ERROR keystone.server.flask.application     resp = resource(*args, **kwargs)
2023-02-28 22:11:50.401061 2023-02-28 22:11:50.391 38 ERROR keystone.server.flask.application   File "/var/lib/kolla/venv/lib/python3.9/site-packages/flask/views.py", line 107, in view
2023-02-28 22:11:50.401076 2023-02-28 22:11:50.391 38 ERROR keystone.server.flask.application     return current_app.ensure_sync(self.dispatch_request)(**kwargs)
2023-02-28 22:11:50.401086 2023-02-28 22:11:50.391 38 ERROR keystone.server.flask.application   File "/var/lib/kolla/venv/lib/python3.9/site-packages/flask_restful/__init__.py", line 582, in dispatch_request
2023-02-28 22:11:50.401097 2023-02-28 22:11:50.391 38 ERROR keystone.server.flask.application     resp = meth(*args, **kwargs)
2023-02-28 22:11:50.401106 2023-02-28 22:11:50.391 38 ERROR keystone.server.flask.application   File "/var/lib/kolla/venv/lib/python3.9/site-packages/keystone/api/projects.py", line 151, in get
2023-02-28 22:11:50.401117 2023-02-28 22:11:50.391 38 ERROR keystone.server.flask.application     return self._get_project(project_id)
2023-02-28 22:11:50.401133 2023-02-28 22:11:50.391 38 ERROR keystone.server.flask.application   File "/var/lib/kolla/venv/lib/python3.9/site-packages/keystone/api/projects.py", line 107, in _get_project
2023-02-28 22:11:50.401143 2023-02-28 22:11:50.391 38 ERROR keystone.server.flask.application     project = PROVIDERS.resource_api.get_project(project_id)
2023-02-28 22:11:50.401154 2023-02-28 22:11:50.391 38 ERROR keystone.server.flask.application   File "/var/lib/kolla/venv/lib/python3.9/site-packages/keystone/common/manager.py", line 115, in wrapped
2023-02-28 22:11:50.401164 2023-02-28 22:11:50.391 38 ERROR keystone.server.flask.application     __ret_val = __f(*args, **kwargs)
2023-02-28 22:11:50.401174 2023-02-28 22:11:50.391 38 ERROR keystone.server.flask.application   File "/var/lib/kolla/venv/lib/python3.9/site-packages/decorator.py", line 232, in fun
2023-02-28 22:11:50.401184 2023-02-28 22:11:50.391 38 ERROR keystone.server.flask.application     return caller(func, *(extras + args), **kw)
2023-02-28 22:11:50.401194 2023-02-28 22:11:50.391 38 ERROR keystone.server.flask.application   File "/var/lib/kolla/venv/lib/python3.9/site-packages/dogpile/cache/region.py", line 1577, in get_or_create_for_user_func
2023-02-28 22:11:50.401204 2023-02-28 22:11:50.391 38 ERROR keystone.server.flask.application     return self.get_or_create(
2023-02-28 22:11:50.401214 2023-02-28 22:11:50.391 38 ERROR keystone.server.flask.application   File "/var/lib/kolla/venv/lib/python3.9/site-packages/dogpile/cache/region.py", line 1042, in get_or_create
2023-02-28 22:11:50.401225 2023-02-28 22:11:50.391 38 ERROR keystone.server.flask.application     with Lock(
2023-02-28 22:11:50.401234 2023-02-28 22:11:50.391 38 ERROR keystone.server.flask.application   File "/var/lib/kolla/venv/lib/python3.9/site-packages/dogpile/lock.py", line 185, in __enter__
2023-02-28 22:11:50.401245 2023-02-28 22:11:50.391 38 ERROR keystone.server.flask.application     return self._enter()
2023-02-28 22:11:50.401276 2023-02-28 22:11:50.391 38 ERROR keystone.server.flask.application   File "/var/lib/kolla/venv/lib/python3.9/site-packages/dogpile/lock.py", line 94, in _enter
2023-02-28 22:11:50.401289 2023-02-28 22:11:50.391 38 ERROR keystone.server.flask.application     generated = self._enter_create(value, createdtime)
2023-02-28 22:11:50.401299 2023-02-28 22:11:50.391 38 ERROR keystone.server.flask.application   File "/var/lib/kolla/venv/lib/python3.9/site-packages/dogpile/lock.py", line 178, in _enter_create
2023-02-28 22:11:50.401310 2023-02-28 22:11:50.391 38 ERROR keystone.server.flask.application     return self.creator()
2023-02-28 22:11:50.401320 2023-02-28 22:11:50.391 38 ERROR keystone.server.flask.application   File "/var/lib/kolla/venv/lib/python3.9/site-packages/dogpile/cache/region.py", line 995, in gen_value
2023-02-28 22:11:50.401330 2023-02-28 22:11:50.391 38 ERROR keystone.server.flask.application     created_value = creator(
2023-02-28 22:11:50.401340 2023-02-28 22:11:50.391 38 ERROR keystone.server.flask.application   File "/var/lib/kolla/venv/lib/python3.9/site-packages/keystone/resource/core.py", line 903, in get_project
2023-02-28 22:11:50.401350 2023-02-28 22:11:50.391 38 ERROR keystone.server.flask.application     return self.driver.get_project(project_id)
2023-02-28 22:11:50.401360 2023-02-28 22:11:50.391 38 ERROR keystone.server.flask.application   File "/var/lib/kolla/venv/lib/python3.9/site-packages/keystone/resource/backends/sql.py", line 49, in get_project
2023-02-28 22:11:50.401370 2023-02-28 22:11:50.391 38 ERROR keystone.server.flask.application     return self._get_project(session, project_id).to_dict()
2023-02-28 22:11:50.401380 2023-02-28 22:11:50.391 38 ERROR keystone.server.flask.application   File "/var/lib/kolla/venv/lib/python3.9/site-packages/keystone/resource/backends/sql.py", line 44, in _get_project
2023-02-28 22:11:50.401390 2023-02-28 22:11:50.391 38 ERROR keystone.server.flask.application     raise exception.ProjectNotFound(project_id=project_id)
2023-02-28 22:11:50.401400 2023-02-28 22:11:50.391 38 ERROR keystone.server.flask.application keystone.exception.ProjectNotFound: Could not find project: service.
2023-02-28 22:11:50.401410 2023-02-28 22:11:50.391 38 ERROR keystone.server.flask.application \x1b[00m
2023-02-28 22:12:04.828738 2023-02-28 22:12:04.812 38 ERROR keystone.server.flask.application [None req-bb2cf22b-4f0c-4121-917a-5787ed214e77 afab145532ce44e89a27128ecf3b716c - - all default -] Could not find role: admin.: keystone.exception.RoleNotFound: Could not find role: admin.
2023-02-28 22:12:04.828843 2023-02-28 22:12:04.812 38 ERROR keystone.server.flask.application Traceback (most recent call last):
2023-02-28 22:12:04.828860 2023-02-28 22:12:04.812 38 ERROR keystone.server.flask.application   File "/var/lib/kolla/venv/lib/python3.9/site-packages/flask/app.py", line 1820, in full_dispatch_request
2023-02-28 22:12:04.828871 2023-02-28 22:12:04.812 38 ERROR keystone.server.flask.application     rv = self.dispatch_request()
2023-02-28 22:12:04.828881 2023-02-28 22:12:04.812 38 ERROR keystone.server.flask.application   File "/var/lib/kolla/venv/lib/python3.9/site-packages/flask/app.py", line 1796, in dispatch_request
2023-02-28 22:12:04.828892 2023-02-28 22:12:04.812 38 ERROR keystone.server.flask.application     return self.ensure_sync(self.view_functions[rule.endpoint])(**view_args)
2023-02-28 22:12:04.828902 2023-02-28 22:12:04.812 38 ERROR keystone.server.flask.application   File "/var/lib/kolla/venv/lib/python3.9/site-packages/flask_restful/__init__.py", line 467, in wrapper
2023-02-28 22:12:04.828912 2023-02-28 22:12:04.812 38 ERROR keystone.server.flask.application     resp = resource(*args, **kwargs)
2023-02-28 22:12:04.828930 2023-02-28 22:12:04.812 38 ERROR keystone.server.flask.application   File "/var/lib/kolla/venv/lib/python3.9/site-packages/flask/views.py", line 107, in view
2023-02-28 22:12:04.828943 2023-02-28 22:12:04.812 38 ERROR keystone.server.flask.application     return current_app.ensure_sync(self.dispatch_request)(**kwargs)
2023-02-28 22:12:04.828953 2023-02-28 22:12:04.812 38 ERROR keystone.server.flask.application   File "/var/lib/kolla/venv/lib/python3.9/site-packages/flask_restful/__init__.py", line 582, in dispatch_request
2023-02-28 22:12:04.828981 2023-02-28 22:12:04.812 38 ERROR keystone.server.flask.application     resp = meth(*args, **kwargs)
2023-02-28 22:12:04.828992 2023-02-28 22:12:04.812 38 ERROR keystone.server.flask.application   File "/var/lib/kolla/venv/lib/python3.9/site-packages/keystone/api/roles.py", line 50, in get
2023-02-28 22:12:04.829002 2023-02-28 22:12:04.812 38 ERROR keystone.server.flask.application     return self._get_role(role_id)
2023-02-28 22:12:04.829012 2023-02-28 22:12:04.812 38 ERROR keystone.server.flask.application   File "/var/lib/kolla/venv/lib/python3.9/site-packages/keystone/api/roles.py", line 70, in _get_role
2023-02-28 22:12:04.829023 2023-02-28 22:12:04.812 38 ERROR keystone.server.flask.application     ENFORCER.enforce_call(action='identity:get_role')
2023-02-28 22:12:04.829034 2023-02-28 22:12:04.812 38 ERROR keystone.server.flask.application   File "/var/lib/kolla/venv/lib/python3.9/site-packages/keystone/common/rbac_enforcer/enforcer.py", line 402, in enforce_call
2023-02-28 22:12:04.829044 2023-02-28 22:12:04.812 38 ERROR keystone.server.flask.application     policy_dict.update(cls._extract_member_target_data(
2023-02-28 22:12:04.829062 2023-02-28 22:12:04.812 38 ERROR keystone.server.flask.application   File "/var/lib/kolla/venv/lib/python3.9/site-packages/keystone/common/rbac_enforcer/enforcer.py", line 234, in _extract_member_target_data
2023-02-28 22:12:04.829076 2023-02-28 22:12:04.812 38 ERROR keystone.server.flask.application     member_name: func(flask.request.view_args[key])
2023-02-28 22:12:04.829086 2023-02-28 22:12:04.812 38 ERROR keystone.server.flask.application   File "/var/lib/kolla/venv/lib/python3.9/site-packages/keystone/common/manager.py", line 115, in wrapped
2023-02-28 22:12:04.829096 2023-02-28 22:12:04.812 38 ERROR keystone.server.flask.application     __ret_val = __f(*args, **kwargs)
2023-02-28 22:12:04.829106 2023-02-28 22:12:04.812 38 ERROR keystone.server.flask.application   File "/var/lib/kolla/venv/lib/python3.9/site-packages/decorator.py", line 232, in fun
2023-02-28 22:12:04.829117 2023-02-28 22:12:04.812 38 ERROR keystone.server.flask.application     return caller(func, *(extras + args), **kw)
2023-02-28 22:12:04.829127 2023-02-28 22:12:04.812 38 ERROR keystone.server.flask.application   File "/var/lib/kolla/venv/lib/python3.9/site-packages/dogpile/cache/region.py", line 1577, in get_or_create_for_user_func
2023-02-28 22:12:04.829138 2023-02-28 22:12:04.812 38 ERROR keystone.server.flask.application     return self.get_or_create(
2023-02-28 22:12:04.829148 2023-02-28 22:12:04.812 38 ERROR keystone.server.flask.application   File "/var/lib/kolla/venv/lib/python3.9/site-packages/dogpile/cache/region.py", line 1042, in get_or_create
2023-02-28 22:12:04.829159 2023-02-28 22:12:04.812 38 ERROR keystone.server.flask.application     with Lock(
2023-02-28 22:12:04.829169 2023-02-28 22:12:04.812 38 ERROR keystone.server.flask.application   File "/var/lib/kolla/venv/lib/python3.9/site-packages/dogpile/lock.py", line 185, in __enter__
2023-02-28 22:12:04.829179 2023-02-28 22:12:04.812 38 ERROR keystone.server.flask.application     return self._enter()
2023-02-28 22:12:04.829189 2023-02-28 22:12:04.812 38 ERROR keystone.server.flask.application   File "/var/lib/kolla/venv/lib/python3.9/site-packages/dogpile/lock.py", line 94, in _enter
2023-02-28 22:12:04.829199 2023-02-28 22:12:04.812 38 ERROR keystone.server.flask.application     generated = self._enter_create(value, createdtime)
2023-02-28 22:12:04.829209 2023-02-28 22:12:04.812 38 ERROR keystone.server.flask.application   File "/var/lib/kolla/venv/lib/python3.9/site-packages/dogpile/lock.py", line 178, in _enter_create
2023-02-28 22:12:04.829220 2023-02-28 22:12:04.812 38 ERROR keystone.server.flask.application     return self.creator()
2023-02-28 22:12:04.829230 2023-02-28 22:12:04.812 38 ERROR keystone.server.flask.application   File "/var/lib/kolla/venv/lib/python3.9/site-packages/dogpile/cache/region.py", line 995, in gen_value
2023-02-28 22:12:04.829253 2023-02-28 22:12:04.812 38 ERROR keystone.server.flask.application     created_value = creator(
2023-02-28 22:12:04.829264 2023-02-28 22:12:04.812 38 ERROR keystone.server.flask.application   File "/var/lib/kolla/venv/lib/python3.9/site-packages/keystone/assignment/core.py", line 1276, in get_role
2023-02-28 22:12:04.829275 2023-02-28 22:12:04.812 38 ERROR keystone.server.flask.application     return self.driver.get_role(role_id)
2023-02-28 22:12:04.829285 2023-02-28 22:12:04.812 38 ERROR keystone.server.flask.application   File "/var/lib/kolla/venv/lib/python3.9/site-packages/keystone/assignment/role_backends/sql.py", line 70, in get_role
2023-02-28 22:12:04.829295 2023-02-28 22:12:04.812 38 ERROR keystone.server.flask.application     return self._get_role(session, role_id).to_dict()
2023-02-28 22:12:04.829306 2023-02-28 22:12:04.812 38 ERROR keystone.server.flask.application   File "/var/lib/kolla/venv/lib/python3.9/site-packages/keystone/assignment/role_backends/sql.py", line 65, in _get_role
2023-02-28 22:12:04.829316 2023-02-28 22:12:04.812 38 ERROR keystone.server.flask.application     raise exception.RoleNotFound(role_id=role_id)
2023-02-28 22:12:04.829326 2023-02-28 22:12:04.812 38 ERROR keystone.server.flask.application keystone.exception.RoleNotFound: Could not find role: admin.
2023-02-28 22:12:04.829337 2023-02-28 22:12:04.812 38 ERROR keystone.server.flask.application \x1b[00m
2023-02-28 22:12:05.964410 2023-02-28 22:12:05.959 38 ERROR keystone.server.flask.application [None req-8eaa7105-2905-4d5c-a08b-2e13fc871c39 afab145532ce44e89a27128ecf3b716c - - all default -] Could not find user: ironic.: keystone.exception.UserNotFound: Could not find user: ironic.
2023-02-28 22:12:05.964455 2023-02-28 22:12:05.959 38 ERROR keystone.server.flask.application Traceback (most recent call last):
2023-02-28 22:12:05.964471 2023-02-28 22:12:05.959 38 ERROR keystone.server.flask.application   File "/var/lib/kolla/venv/lib/python3.9/site-packages/flask/app.py", line 1820, in full_dispatch_request
2023-02-28 22:12:05.964515 2023-02-28 22:12:05.959 38 ERROR keystone.server.flask.application     rv = self.dispatch_request()
2023-02-28 22:12:05.964525 2023-02-28 22:12:05.959 38 ERROR keystone.server.flask.application   File "/var/lib/kolla/venv/lib/python3.9/site-packages/flask/app.py", line 1796, in dispatch_request
2023-02-28 22:12:05.964536 2023-02-28 22:12:05.959 38 ERROR keystone.server.flask.application     return self.ensure_sync(self.view_functions[rule.endpoint])(**view_args)
2023-02-28 22:12:05.964547 2023-02-28 22:12:05.959 38 ERROR keystone.server.flask.application   File "/var/lib/kolla/venv/lib/python3.9/site-packages/flask_restful/__init__.py", line 467, in wrapper
2023-02-28 22:12:05.964557 2023-02-28 22:12:05.959 38 ERROR keystone.server.flask.application     resp = resource(*args, **kwargs)
2023-02-28 22:12:05.964567 2023-02-28 22:12:05.959 38 ERROR keystone.server.flask.application   File "/var/lib/kolla/venv/lib/python3.9/site-packages/flask/views.py", line 107, in view
2023-02-28 22:12:05.964578 2023-02-28 22:12:05.959 38 ERROR keystone.server.flask.application     return current_app.ensure_sync(self.dispatch_request)(**kwargs)
2023-02-28 22:12:05.964588 2023-02-28 22:12:05.959 38 ERROR keystone.server.flask.application   File "/var/lib/kolla/venv/lib/python3.9/site-packages/flask_restful/__init__.py", line 582, in dispatch_request
2023-02-28 22:12:05.964598 2023-02-28 22:12:05.959 38 ERROR keystone.server.flask.application     resp = meth(*args, **kwargs)
2023-02-28 22:12:05.964608 2023-02-28 22:12:05.959 38 ERROR keystone.server.flask.application   File "/var/lib/kolla/venv/lib/python3.9/site-packages/keystone/api/users.py", line 182, in get
2023-02-28 22:12:05.964619 2023-02-28 22:12:05.959 38 ERROR keystone.server.flask.application     return self._get_user(user_id)
2023-02-28 22:12:05.964628 2023-02-28 22:12:05.959 38 ERROR keystone.server.flask.application   File "/var/lib/kolla/venv/lib/python3.9/site-packages/keystone/api/users.py", line 194, in _get_user
2023-02-28 22:12:05.964655 2023-02-28 22:12:05.959 38 ERROR keystone.server.flask.application     ref = PROVIDERS.identity_api.get_user(user_id)
2023-02-28 22:12:05.964667 2023-02-28 22:12:05.959 38 ERROR keystone.server.flask.application   File "/var/lib/kolla/venv/lib/python3.9/site-packages/keystone/common/manager.py", line 115, in wrapped
2023-02-28 22:12:05.964677 2023-02-28 22:12:05.959 38 ERROR keystone.server.flask.application     __ret_val = __f(*args, **kwargs)
2023-02-28 22:12:05.964688 2023-02-28 22:12:05.959 38 ERROR keystone.server.flask.application   File "/var/lib/kolla/venv/lib/python3.9/site-packages/keystone/identity/core.py", line 414, in wrapper
2023-02-28 22:12:05.964698 2023-02-28 22:12:05.959 38 ERROR keystone.server.flask.application     return f(self, *args, **kwargs)
2023-02-28 22:12:05.964708 2023-02-28 22:12:05.959 38 ERROR keystone.server.flask.application   File "/var/lib/kolla/venv/lib/python3.9/site-packages/keystone/identity/core.py", line 424, in wrapper
2023-02-28 22:12:05.964718 2023-02-28 22:12:05.959 38 ERROR keystone.server.flask.application     return f(self, *args, **kwargs)
2023-02-28 22:12:05.964728 2023-02-28 22:12:05.959 38 ERROR keystone.server.flask.application   File "/var/lib/kolla/venv/lib/python3.9/site-packages/decorator.py", line 232, in fun
2023-02-28 22:12:05.964739 2023-02-28 22:12:05.959 38 ERROR keystone.server.flask.application     return caller(func, *(extras + args), **kw)
2023-02-28 22:12:05.964749 2023-02-28 22:12:05.959 38 ERROR keystone.server.flask.application   File "/var/lib/kolla/venv/lib/python3.9/site-packages/dogpile/cache/region.py", line 1577, in get_or_create_for_user_func
2023-02-28 22:12:05.964760 2023-02-28 22:12:05.959 38 ERROR keystone.server.flask.application     return self.get_or_create(
2023-02-28 22:12:05.964770 2023-02-28 22:12:05.959 38 ERROR keystone.server.flask.application   File "/var/lib/kolla/venv/lib/python3.9/site-packages/dogpile/cache/region.py", line 1042, in get_or_create
2023-02-28 22:12:05.964780 2023-02-28 22:12:05.959 38 ERROR keystone.server.flask.application     with Lock(
2023-02-28 22:12:05.964791 2023-02-28 22:12:05.959 38 ERROR keystone.server.flask.application   File "/var/lib/kolla/venv/lib/python3.9/site-packages/dogpile/lock.py", line 185, in __enter__
2023-02-28 22:12:05.964801 2023-02-28 22:12:05.959 38 ERROR keystone.server.flask.application     return self._enter()
2023-02-28 22:12:05.964813 2023-02-28 22:12:05.959 38 ERROR keystone.server.flask.application   File "/var/lib/kolla/venv/lib/python3.9/site-packages/dogpile/lock.py", line 94, in _enter
2023-02-28 22:12:05.964847 2023-02-28 22:12:05.959 38 ERROR keystone.server.flask.application     generated = self._enter_create(value, createdtime)
2023-02-28 22:12:05.964860 2023-02-28 22:12:05.959 38 ERROR keystone.server.flask.application   File "/var/lib/kolla/venv/lib/python3.9/site-packages/dogpile/lock.py", line 178, in _enter_create
2023-02-28 22:12:05.964870 2023-02-28 22:12:05.959 38 ERROR keystone.server.flask.application     return self.creator()
2023-02-28 22:12:05.964880 2023-02-28 22:12:05.959 38 ERROR keystone.server.flask.application   File "/var/lib/kolla/venv/lib/python3.9/site-packages/dogpile/cache/region.py", line 995, in gen_value
2023-02-28 22:12:05.964890 2023-02-28 22:12:05.959 38 ERROR keystone.server.flask.application     created_value = creator(
2023-02-28 22:12:05.964900 2023-02-28 22:12:05.959 38 ERROR keystone.server.flask.application   File "/var/lib/kolla/venv/lib/python3.9/site-packages/keystone/identity/core.py", line 1011, in get_user
2023-02-28 22:12:05.964910 2023-02-28 22:12:05.959 38 ERROR keystone.server.flask.application     ref = driver.get_user(entity_id)
2023-02-28 22:12:05.964920 2023-02-28 22:12:05.959 38 ERROR keystone.server.flask.application   File "/var/lib/kolla/venv/lib/python3.9/site-packages/keystone/identity/backends/sql.py", line 200, in get_user
2023-02-28 22:12:05.964930 2023-02-28 22:12:05.959 38 ERROR keystone.server.flask.application     self._get_user(session, user_id).to_dict())
2023-02-28 22:12:05.964951 2023-02-28 22:12:05.959 38 ERROR keystone.server.flask.application   File "/var/lib/kolla/venv/lib/python3.9/site-packages/keystone/identity/backends/sql.py", line 194, in _get_user
2023-02-28 22:12:05.964963 2023-02-28 22:12:05.959 38 ERROR keystone.server.flask.application     raise exception.UserNotFound(user_id=user_id)
2023-02-28 22:12:05.964973 2023-02-28 22:12:05.959 38 ERROR keystone.server.flask.application keystone.exception.UserNotFound: Could not find user: ironic.
2023-02-28 22:12:05.964983 2023-02-28 22:12:05.959 38 ERROR keystone.server.flask.application \x1b[00m
2023-02-28 22:12:06.753978 2023-02-28 22:12:06.742 37 ERROR keystone.server.flask.application [None req-196ed7eb-cc5e-4708-afc2-25e1f34240e2 afab145532ce44e89a27128ecf3b716c - - all default -] Could not find project: service.: keystone.exception.ProjectNotFound: Could not find project: service.
2023-02-28 22:12:06.754022 2023-02-28 22:12:06.742 37 ERROR keystone.server.flask.application Traceback (most recent call last):
2023-02-28 22:12:06.754033 2023-02-28 22:12:06.742 37 ERROR keystone.server.flask.application   File "/var/lib/kolla/venv/lib/python3.9/site-packages/flask/app.py", line 1820, in full_dispatch_request
2023-02-28 22:12:06.754044 2023-02-28 22:12:06.742 37 ERROR keystone.server.flask.application     rv = self.dispatch_request()
2023-02-28 22:12:06.754054 2023-02-28 22:12:06.742 37 ERROR keystone.server.flask.application   File "/var/lib/kolla/venv/lib/python3.9/site-packages/flask/app.py", line 1796, in dispatch_request
2023-02-28 22:12:06.754068 2023-02-28 22:12:06.742 37 ERROR keystone.server.flask.application     return self.ensure_sync(self.view_functions[rule.endpoint])(**view_args)
2023-02-28 22:12:06.754079 2023-02-28 22:12:06.742 37 ERROR keystone.server.flask.application   File "/var/lib/kolla/venv/lib/python3.9/site-packages/flask_restful/__init__.py", line 467, in wrapper
2023-02-28 22:12:06.754089 2023-02-28 22:12:06.742 37 ERROR keystone.server.flask.application     resp = resource(*args, **kwargs)
2023-02-28 22:12:06.754099 2023-02-28 22:12:06.742 37 ERROR keystone.server.flask.application   File "/var/lib/kolla/venv/lib/python3.9/site-packages/flask/views.py", line 107, in view
2023-02-28 22:12:06.754109 2023-02-28 22:12:06.742 37 ERROR keystone.server.flask.application     return current_app.ensure_sync(self.dispatch_request)(**kwargs)
2023-02-28 22:12:06.754125 2023-02-28 22:12:06.742 37 ERROR keystone.server.flask.application   File "/var/lib/kolla/venv/lib/python3.9/site-packages/flask_restful/__init__.py", line 582, in dispatch_request
2023-02-28 22:12:06.754146 2023-02-28 22:12:06.742 37 ERROR keystone.server.flask.application     resp = meth(*args, **kwargs)
2023-02-28 22:12:06.754167 2023-02-28 22:12:06.742 37 ERROR keystone.server.flask.application   File "/var/lib/kolla/venv/lib/python3.9/site-packages/keystone/api/projects.py", line 151, in get
2023-02-28 22:12:06.754190 2023-02-28 22:12:06.742 37 ERROR keystone.server.flask.application     return self._get_project(project_id)
2023-02-28 22:12:06.754210 2023-02-28 22:12:06.742 37 ERROR keystone.server.flask.application   File "/var/lib/kolla/venv/lib/python3.9/site-packages/keystone/api/projects.py", line 107, in _get_project
2023-02-28 22:12:06.754231 2023-02-28 22:12:06.742 37 ERROR keystone.server.flask.application     project = PROVIDERS.resource_api.get_project(project_id)
2023-02-28 22:12:06.754250 2023-02-28 22:12:06.742 37 ERROR keystone.server.flask.application   File "/var/lib/kolla/venv/lib/python3.9/site-packages/keystone/common/manager.py", line 115, in wrapped
2023-02-28 22:12:06.754270 2023-02-28 22:12:06.742 37 ERROR keystone.server.flask.application     __ret_val = __f(*args, **kwargs)
2023-02-28 22:12:06.754291 2023-02-28 22:12:06.742 37 ERROR keystone.server.flask.application   File "/var/lib/kolla/venv/lib/python3.9/site-packages/decorator.py", line 232, in fun
2023-02-28 22:12:06.754313 2023-02-28 22:12:06.742 37 ERROR keystone.server.flask.application     return caller(func, *(extras + args), **kw)
2023-02-28 22:12:06.754359 2023-02-28 22:12:06.742 37 ERROR keystone.server.flask.application   File "/var/lib/kolla/venv/lib/python3.9/site-packages/dogpile/cache/region.py", line 1577, in get_or_create_for_user_func
2023-02-28 22:12:06.754385 2023-02-28 22:12:06.742 37 ERROR keystone.server.flask.application     return self.get_or_create(
2023-02-28 22:12:06.754407 2023-02-28 22:12:06.742 37 ERROR keystone.server.flask.application   File "/var/lib/kolla/venv/lib/python3.9/site-packages/dogpile/cache/region.py", line 1042, in get_or_create
2023-02-28 22:12:06.754427 2023-02-28 22:12:06.742 37 ERROR keystone.server.flask.application     with Lock(
2023-02-28 22:12:06.754446 2023-02-28 22:12:06.742 37 ERROR keystone.server.flask.application   File "/var/lib/kolla/venv/lib/python3.9/site-packages/dogpile/lock.py", line 185, in __enter__
2023-02-28 22:12:06.754459 2023-02-28 22:12:06.742 37 ERROR keystone.server.flask.application     return self._enter()
2023-02-28 22:12:06.754470 2023-02-28 22:12:06.742 37 ERROR keystone.server.flask.application   File "/var/lib/kolla/venv/lib/python3.9/site-packages/dogpile/lock.py", line 94, in _enter
2023-02-28 22:12:06.754527 2023-02-28 22:12:06.742 37 ERROR keystone.server.flask.application     generated = self._enter_create(value, createdtime)
2023-02-28 22:12:06.754546 2023-02-28 22:12:06.742 37 ERROR keystone.server.flask.application   File "/var/lib/kolla/venv/lib/python3.9/site-packages/dogpile/lock.py", line 178, in _enter_create
2023-02-28 22:12:06.754564 2023-02-28 22:12:06.742 37 ERROR keystone.server.flask.application     return self.creator()
2023-02-28 22:12:06.754579 2023-02-28 22:12:06.742 37 ERROR keystone.server.flask.application   File "/var/lib/kolla/venv/lib/python3.9/site-packages/dogpile/cache/region.py", line 995, in gen_value
2023-02-28 22:12:06.754590 2023-02-28 22:12:06.742 37 ERROR keystone.server.flask.application     created_value = creator(
2023-02-28 22:12:06.754599 2023-02-28 22:12:06.742 37 ERROR keystone.server.flask.application   File "/var/lib/kolla/venv/lib/python3.9/site-packages/keystone/resource/core.py", line 903, in get_project
2023-02-28 22:12:06.754610 2023-02-28 22:12:06.742 37 ERROR keystone.server.flask.application     return self.driver.get_project(project_id)
2023-02-28 22:12:06.754619 2023-02-28 22:12:06.742 37 ERROR keystone.server.flask.application   File "/var/lib/kolla/venv/lib/python3.9/site-packages/keystone/resource/backends/sql.py", line 49, in get_project
2023-02-28 22:12:06.754630 2023-02-28 22:12:06.742 37 ERROR keystone.server.flask.application     return self._get_project(session, project_id).to_dict()
2023-02-28 22:12:06.754639 2023-02-28 22:12:06.742 37 ERROR keystone.server.flask.application   File "/var/lib/kolla/venv/lib/python3.9/site-packages/keystone/resource/backends/sql.py", line 44, in _get_project
2023-02-28 22:12:06.754649 2023-02-28 22:12:06.742 37 ERROR keystone.server.flask.application     raise exception.ProjectNotFound(project_id=project_id)
2023-02-28 22:12:06.754659 2023-02-28 22:12:06.742 37 ERROR keystone.server.flask.application keystone.exception.ProjectNotFound: Could not find project: service.
2023-02-28 22:12:06.754669 2023-02-28 22:12:06.742 37 ERROR keystone.server.flask.application \x1b[00m
2023-02-28 22:12:16.196792 2023-02-28 22:12:16.190 39 ERROR keystone.server.flask.application [None req-1fe2e835-535a-4cf7-9e7f-cabe5dc44afa afab145532ce44e89a27128ecf3b716c - - all default -] Could not find role: admin.: keystone.exception.RoleNotFound: Could not find role: admin.
2023-02-28 22:12:16.196882 2023-02-28 22:12:16.190 39 ERROR keystone.server.flask.application Traceback (most recent call last):
2023-02-28 22:12:16.196903 2023-02-28 22:12:16.190 39 ERROR keystone.server.flask.application   File "/var/lib/kolla/venv/lib/python3.9/site-packages/flask/app.py", line 1820, in full_dispatch_request
2023-02-28 22:12:16.196915 2023-02-28 22:12:16.190 39 ERROR keystone.server.flask.application     rv = self.dispatch_request()
2023-02-28 22:12:16.196925 2023-02-28 22:12:16.190 39 ERROR keystone.server.flask.application   File "/var/lib/kolla/venv/lib/python3.9/site-packages/flask/app.py", line 1796, in dispatch_request
2023-02-28 22:12:16.196962 2023-02-28 22:12:16.190 39 ERROR keystone.server.flask.application     return self.ensure_sync(self.view_functions[rule.endpoint])(**view_args)
2023-02-28 22:12:16.196975 2023-02-28 22:12:16.190 39 ERROR keystone.server.flask.application   File "/var/lib/kolla/venv/lib/python3.9/site-packages/flask_restful/__init__.py", line 467, in wrapper
2023-02-28 22:12:16.196985 2023-02-28 22:12:16.190 39 ERROR keystone.server.flask.application     resp = resource(*args, **kwargs)
2023-02-28 22:12:16.197001 2023-02-28 22:12:16.190 39 ERROR keystone.server.flask.application   File "/var/lib/kolla/venv/lib/python3.9/site-packages/flask/views.py", line 107, in view
2023-02-28 22:12:16.197014 2023-02-28 22:12:16.190 39 ERROR keystone.server.flask.application     return current_app.ensure_sync(self.dispatch_request)(**kwargs)
2023-02-28 22:12:16.197024 2023-02-28 22:12:16.190 39 ERROR keystone.server.flask.application   File "/var/lib/kolla/venv/lib/python3.9/site-packages/flask_restful/__init__.py", line 582, in dispatch_request
2023-02-28 22:12:16.197034 2023-02-28 22:12:16.190 39 ERROR keystone.server.flask.application     resp = meth(*args, **kwargs)
2023-02-28 22:12:16.197044 2023-02-28 22:12:16.190 39 ERROR keystone.server.flask.application   File "/var/lib/kolla/venv/lib/python3.9/site-packages/keystone/api/roles.py", line 50, in get
2023-02-28 22:12:16.197054 2023-02-28 22:12:16.190 39 ERROR keystone.server.flask.application     return self._get_role(role_id)
2023-02-28 22:12:16.197064 2023-02-28 22:12:16.190 39 ERROR keystone.server.flask.application   File "/var/lib/kolla/venv/lib/python3.9/site-packages/keystone/api/roles.py", line 70, in _get_role
2023-02-28 22:12:16.197074 2023-02-28 22:12:16.190 39 ERROR keystone.server.flask.application     ENFORCER.enforce_call(action='identity:get_role')
2023-02-28 22:12:16.197098 2023-02-28 22:12:16.190 39 ERROR keystone.server.flask.application   File "/var/lib/kolla/venv/lib/python3.9/site-packages/keystone/common/rbac_enforcer/enforcer.py", line 402, in enforce_call
2023-02-28 22:12:16.197108 2023-02-28 22:12:16.190 39 ERROR keystone.server.flask.application     policy_dict.update(cls._extract_member_target_data(
2023-02-28 22:12:16.197127 2023-02-28 22:12:16.190 39 ERROR keystone.server.flask.application   File "/var/lib/kolla/venv/lib/python3.9/site-packages/keystone/common/rbac_enforcer/enforcer.py", line 234, in _extract_member_target_data
2023-02-28 22:12:16.197139 2023-02-28 22:12:16.190 39 ERROR keystone.server.flask.application     member_name: func(flask.request.view_args[key])
2023-02-28 22:12:16.197150 2023-02-28 22:12:16.190 39 ERROR keystone.server.flask.application   File "/var/lib/kolla/venv/lib/python3.9/site-packages/keystone/common/manager.py", line 115, in wrapped
2023-02-28 22:12:16.197160 2023-02-28 22:12:16.190 39 ERROR keystone.server.flask.application     __ret_val = __f(*args, **kwargs)
2023-02-28 22:12:16.197170 2023-02-28 22:12:16.190 39 ERROR keystone.server.flask.application   File "/var/lib/kolla/venv/lib/python3.9/site-packages/decorator.py", line 232, in fun
2023-02-28 22:12:16.197180 2023-02-28 22:12:16.190 39 ERROR keystone.server.flask.application     return caller(func, *(extras + args), **kw)
2023-02-28 22:12:16.197190 2023-02-28 22:12:16.190 39 ERROR keystone.server.flask.application   File "/var/lib/kolla/venv/lib/python3.9/site-packages/dogpile/cache/region.py", line 1577, in get_or_create_for_user_func
2023-02-28 22:12:16.197200 2023-02-28 22:12:16.190 39 ERROR keystone.server.flask.application     return self.get_or_create(
2023-02-28 22:12:16.197210 2023-02-28 22:12:16.190 39 ERROR keystone.server.flask.application   File "/var/lib/kolla/venv/lib/python3.9/site-packages/dogpile/cache/region.py", line 1042, in get_or_create
2023-02-28 22:12:16.197221 2023-02-28 22:12:16.190 39 ERROR keystone.server.flask.application     with Lock(
2023-02-28 22:12:16.197250 2023-02-28 22:12:16.190 39 ERROR keystone.server.flask.application   File "/var/lib/kolla/venv/lib/python3.9/site-packages/dogpile/lock.py", line 185, in __enter__
2023-02-28 22:12:16.197263 2023-02-28 22:12:16.190 39 ERROR keystone.server.flask.application     return self._enter()
2023-02-28 22:12:16.197273 2023-02-28 22:12:16.190 39 ERROR keystone.server.flask.application   File "/var/lib/kolla/venv/lib/python3.9/site-packages/dogpile/lock.py", line 94, in _enter
2023-02-28 22:12:16.197284 2023-02-28 22:12:16.190 39 ERROR keystone.server.flask.application     generated = self._enter_create(value, createdtime)
2023-02-28 22:12:16.197294 2023-02-28 22:12:16.190 39 ERROR keystone.server.flask.application   File "/var/lib/kolla/venv/lib/python3.9/site-packages/dogpile/lock.py", line 178, in _enter_create
2023-02-28 22:12:16.197307 2023-02-28 22:12:16.190 39 ERROR keystone.server.flask.application     return self.creator()
2023-02-28 22:12:16.197322 2023-02-28 22:12:16.190 39 ERROR keystone.server.flask.application   File "/var/lib/kolla/venv/lib/python3.9/site-packages/dogpile/cache/region.py", line 995, in gen_value
2023-02-28 22:12:16.197333 2023-02-28 22:12:16.190 39 ERROR keystone.server.flask.application     created_value = creator(
2023-02-28 22:12:16.197343 2023-02-28 22:12:16.190 39 ERROR keystone.server.flask.application   File "/var/lib/kolla/venv/lib/python3.9/site-packages/keystone/assignment/core.py", line 1276, in get_role
2023-02-28 22:12:16.197353 2023-02-28 22:12:16.190 39 ERROR keystone.server.flask.application     return self.driver.get_role(role_id)
2023-02-28 22:12:16.197363 2023-02-28 22:12:16.190 39 ERROR keystone.server.flask.application   File "/var/lib/kolla/venv/lib/python3.9/site-packages/keystone/assignment/role_backends/sql.py", line 70, in get_role
2023-02-28 22:12:16.197374 2023-02-28 22:12:16.190 39 ERROR keystone.server.flask.application     return self._get_role(session, role_id).to_dict()
2023-02-28 22:12:16.197384 2023-02-28 22:12:16.190 39 ERROR keystone.server.flask.application   File "/var/lib/kolla/venv/lib/python3.9/site-packages/keystone/assignment/role_backends/sql.py", line 65, in _get_role
2023-02-28 22:12:16.197394 2023-02-28 22:12:16.190 39 ERROR keystone.server.flask.application     raise exception.RoleNotFound(role_id=role_id)
2023-02-28 22:12:16.197404 2023-02-28 22:12:16.190 39 ERROR keystone.server.flask.application keystone.exception.RoleNotFound: Could not find role: admin.
2023-02-28 22:12:16.197414 2023-02-28 22:12:16.190 39 ERROR keystone.server.flask.application \x1b[00m
2023-02-28 22:12:17.324673 2023-02-28 22:12:17.319 39 ERROR keystone.server.flask.application [None req-816fdcf6-2828-4656-9266-9dbaad4d591f afab145532ce44e89a27128ecf3b716c - - all default -] Could not find user: ironic-inspector.: keystone.exception.UserNotFound: Could not find user: ironic-inspector.
2023-02-28 22:12:17.324715 2023-02-28 22:12:17.319 39 ERROR keystone.server.flask.application Traceback (most recent call last):
2023-02-28 22:12:17.324727 2023-02-28 22:12:17.319 39 ERROR keystone.server.flask.application   File "/var/lib/kolla/venv/lib/python3.9/site-packages/flask/app.py", line 1820, in full_dispatch_request
2023-02-28 22:12:17.324738 2023-02-28 22:12:17.319 39 ERROR keystone.server.flask.application     rv = self.dispatch_request()
2023-02-28 22:12:17.324748 2023-02-28 22:12:17.319 39 ERROR keystone.server.flask.application   File "/var/lib/kolla/venv/lib/python3.9/site-packages/flask/app.py", line 1796, in dispatch_request
2023-02-28 22:12:17.324759 2023-02-28 22:12:17.319 39 ERROR keystone.server.flask.application     return self.ensure_sync(self.view_functions[rule.endpoint])(**view_args)
2023-02-28 22:12:17.324769 2023-02-28 22:12:17.319 39 ERROR keystone.server.flask.application   File "/var/lib/kolla/venv/lib/python3.9/site-packages/flask_restful/__init__.py", line 467, in wrapper
2023-02-28 22:12:17.324779 2023-02-28 22:12:17.319 39 ERROR keystone.server.flask.application     resp = resource(*args, **kwargs)
2023-02-28 22:12:17.324790 2023-02-28 22:12:17.319 39 ERROR keystone.server.flask.application   File "/var/lib/kolla/venv/lib/python3.9/site-packages/flask/views.py", line 107, in view
2023-02-28 22:12:17.324852 2023-02-28 22:12:17.319 39 ERROR keystone.server.flask.application     return current_app.ensure_sync(self.dispatch_request)(**kwargs)
2023-02-28 22:12:17.324867 2023-02-28 22:12:17.319 39 ERROR keystone.server.flask.application   File "/var/lib/kolla/venv/lib/python3.9/site-packages/flask_restful/__init__.py", line 582, in dispatch_request
2023-02-28 22:12:17.324878 2023-02-28 22:12:17.319 39 ERROR keystone.server.flask.application     resp = meth(*args, **kwargs)
2023-02-28 22:12:17.324887 2023-02-28 22:12:17.319 39 ERROR keystone.server.flask.application   File "/var/lib/kolla/venv/lib/python3.9/site-packages/keystone/api/users.py", line 182, in get
2023-02-28 22:12:17.324898 2023-02-28 22:12:17.319 39 ERROR keystone.server.flask.application     return self._get_user(user_id)
2023-02-28 22:12:17.324907 2023-02-28 22:12:17.319 39 ERROR keystone.server.flask.application   File "/var/lib/kolla/venv/lib/python3.9/site-packages/keystone/api/users.py", line 194, in _get_user
2023-02-28 22:12:17.324920 2023-02-28 22:12:17.319 39 ERROR keystone.server.flask.application     ref = PROVIDERS.identity_api.get_user(user_id)
2023-02-28 22:12:17.324930 2023-02-28 22:12:17.319 39 ERROR keystone.server.flask.application   File "/var/lib/kolla/venv/lib/python3.9/site-packages/keystone/common/manager.py", line 115, in wrapped
2023-02-28 22:12:17.324940 2023-02-28 22:12:17.319 39 ERROR keystone.server.flask.application     __ret_val = __f(*args, **kwargs)
2023-02-28 22:12:17.324949 2023-02-28 22:12:17.319 39 ERROR keystone.server.flask.application   File "/var/lib/kolla/venv/lib/python3.9/site-packages/keystone/identity/core.py", line 414, in wrapper
2023-02-28 22:12:17.324959 2023-02-28 22:12:17.319 39 ERROR keystone.server.flask.application     return f(self, *args, **kwargs)
2023-02-28 22:12:17.324969 2023-02-28 22:12:17.319 39 ERROR keystone.server.flask.application   File "/var/lib/kolla/venv/lib/python3.9/site-packages/keystone/identity/core.py", line 424, in wrapper
2023-02-28 22:12:17.324979 2023-02-28 22:12:17.319 39 ERROR keystone.server.flask.application     return f(self, *args, **kwargs)
2023-02-28 22:12:17.324989 2023-02-28 22:12:17.319 39 ERROR keystone.server.flask.application   File "/var/lib/kolla/venv/lib/python3.9/site-packages/decorator.py", line 232, in fun
2023-02-28 22:12:17.324999 2023-02-28 22:12:17.319 39 ERROR keystone.server.flask.application     return caller(func, *(extras + args), **kw)
2023-02-28 22:12:17.325009 2023-02-28 22:12:17.319 39 ERROR keystone.server.flask.application   File "/var/lib/kolla/venv/lib/python3.9/site-packages/dogpile/cache/region.py", line 1577, in get_or_create_for_user_func
2023-02-28 22:12:17.325019 2023-02-28 22:12:17.319 39 ERROR keystone.server.flask.application     return self.get_or_create(
2023-02-28 22:12:17.325029 2023-02-28 22:12:17.319 39 ERROR keystone.server.flask.application   File "/var/lib/kolla/venv/lib/python3.9/site-packages/dogpile/cache/region.py", line 1042, in get_or_create
2023-02-28 22:12:17.325039 2023-02-28 22:12:17.319 39 ERROR keystone.server.flask.application     with Lock(
2023-02-28 22:12:17.325049 2023-02-28 22:12:17.319 39 ERROR keystone.server.flask.application   File "/var/lib/kolla/venv/lib/python3.9/site-packages/dogpile/lock.py", line 185, in __enter__
2023-02-28 22:12:17.325059 2023-02-28 22:12:17.319 39 ERROR keystone.server.flask.application     return self._enter()
2023-02-28 22:12:17.325069 2023-02-28 22:12:17.319 39 ERROR keystone.server.flask.application   File "/var/lib/kolla/venv/lib/python3.9/site-packages/dogpile/lock.py", line 94, in _enter
2023-02-28 22:12:17.325079 2023-02-28 22:12:17.319 39 ERROR keystone.server.flask.application     generated = self._enter_create(value, createdtime)
2023-02-28 22:12:17.325089 2023-02-28 22:12:17.319 39 ERROR keystone.server.flask.application   File "/var/lib/kolla/venv/lib/python3.9/site-packages/dogpile/lock.py", line 178, in _enter_create
2023-02-28 22:12:17.325113 2023-02-28 22:12:17.319 39 ERROR keystone.server.flask.application     return self.creator()
2023-02-28 22:12:17.325125 2023-02-28 22:12:17.319 39 ERROR keystone.server.flask.application   File "/var/lib/kolla/venv/lib/python3.9/site-packages/dogpile/cache/region.py", line 995, in gen_value
2023-02-28 22:12:17.325135 2023-02-28 22:12:17.319 39 ERROR keystone.server.flask.application     created_value = creator(
2023-02-28 22:12:17.325145 2023-02-28 22:12:17.319 39 ERROR keystone.server.flask.application   File "/var/lib/kolla/venv/lib/python3.9/site-packages/keystone/identity/core.py", line 1011, in get_user
2023-02-28 22:12:17.325163 2023-02-28 22:12:17.319 39 ERROR keystone.server.flask.application     ref = driver.get_user(entity_id)
2023-02-28 22:12:17.325173 2023-02-28 22:12:17.319 39 ERROR keystone.server.flask.application   File "/var/lib/kolla/venv/lib/python3.9/site-packages/keystone/identity/backends/sql.py", line 200, in get_user
2023-02-28 22:12:17.325183 2023-02-28 22:12:17.319 39 ERROR keystone.server.flask.application     self._get_user(session, user_id).to_dict())
2023-02-28 22:12:17.325193 2023-02-28 22:12:17.319 39 ERROR keystone.server.flask.application   File "/var/lib/kolla/venv/lib/python3.9/site-packages/keystone/identity/backends/sql.py", line 194, in _get_user
2023-02-28 22:12:17.325204 2023-02-28 22:12:17.319 39 ERROR keystone.server.flask.application     raise exception.UserNotFound(user_id=user_id)
2023-02-28 22:12:17.325214 2023-02-28 22:12:17.319 39 ERROR keystone.server.flask.application keystone.exception.UserNotFound: Could not find user: ironic-inspector.
2023-02-28 22:12:17.325224 2023-02-28 22:12:17.319 39 ERROR keystone.server.flask.application \x1b[00m
2023-02-28 22:12:18.142971 2023-02-28 22:12:18.139 38 ERROR keystone.server.flask.application [None req-97c8fbd5-182b-4212-b360-94915c23a764 afab145532ce44e89a27128ecf3b716c - - all default -] Could not find project: service.: keystone.exception.ProjectNotFound: Could not find project: service.
2023-02-28 22:12:18.143013 2023-02-28 22:12:18.139 38 ERROR keystone.server.flask.application Traceback (most recent call last):
2023-02-28 22:12:18.143025 2023-02-28 22:12:18.139 38 ERROR keystone.server.flask.application   File "/var/lib/kolla/venv/lib/python3.9/site-packages/flask/app.py", line 1820, in full_dispatch_request
2023-02-28 22:12:18.143036 2023-02-28 22:12:18.139 38 ERROR keystone.server.flask.application     rv = self.dispatch_request()
2023-02-28 22:12:18.143046 2023-02-28 22:12:18.139 38 ERROR keystone.server.flask.application   File "/var/lib/kolla/venv/lib/python3.9/site-packages/flask/app.py", line 1796, in dispatch_request
2023-02-28 22:12:18.143056 2023-02-28 22:12:18.139 38 ERROR keystone.server.flask.application     return self.ensure_sync(self.view_functions[rule.endpoint])(**view_args)
2023-02-28 22:12:18.143066 2023-02-28 22:12:18.139 38 ERROR keystone.server.flask.application   File "/var/lib/kolla/venv/lib/python3.9/site-packages/flask_restful/__init__.py", line 467, in wrapper
2023-02-28 22:12:18.143079 2023-02-28 22:12:18.139 38 ERROR keystone.server.flask.application     resp = resource(*args, **kwargs)
2023-02-28 22:12:18.143098 2023-02-28 22:12:18.139 38 ERROR keystone.server.flask.application   File "/var/lib/kolla/venv/lib/python3.9/site-packages/flask/views.py", line 107, in view
2023-02-28 22:12:18.143111 2023-02-28 22:12:18.139 38 ERROR keystone.server.flask.application     return current_app.ensure_sync(self.dispatch_request)(**kwargs)
2023-02-28 22:12:18.143121 2023-02-28 22:12:18.139 38 ERROR keystone.server.flask.application   File "/var/lib/kolla/venv/lib/python3.9/site-packages/flask_restful/__init__.py", line 582, in dispatch_request
2023-02-28 22:12:18.143131 2023-02-28 22:12:18.139 38 ERROR keystone.server.flask.application     resp = meth(*args, **kwargs)
2023-02-28 22:12:18.143141 2023-02-28 22:12:18.139 38 ERROR keystone.server.flask.application   File "/var/lib/kolla/venv/lib/python3.9/site-packages/keystone/api/projects.py", line 151, in get
2023-02-28 22:12:18.143177 2023-02-28 22:12:18.139 38 ERROR keystone.server.flask.application     return self._get_project(project_id)
2023-02-28 22:12:18.143190 2023-02-28 22:12:18.139 38 ERROR keystone.server.flask.application   File "/var/lib/kolla/venv/lib/python3.9/site-packages/keystone/api/projects.py", line 107, in _get_project
2023-02-28 22:12:18.143200 2023-02-28 22:12:18.139 38 ERROR keystone.server.flask.application     project = PROVIDERS.resource_api.get_project(project_id)
2023-02-28 22:12:18.143210 2023-02-28 22:12:18.139 38 ERROR keystone.server.flask.application   File "/var/lib/kolla/venv/lib/python3.9/site-packages/keystone/common/manager.py", line 115, in wrapped
2023-02-28 22:12:18.143220 2023-02-28 22:12:18.139 38 ERROR keystone.server.flask.application     __ret_val = __f(*args, **kwargs)
2023-02-28 22:12:18.143230 2023-02-28 22:12:18.139 38 ERROR keystone.server.flask.application   File "/var/lib/kolla/venv/lib/python3.9/site-packages/decorator.py", line 232, in fun
2023-02-28 22:12:18.143241 2023-02-28 22:12:18.139 38 ERROR keystone.server.flask.application     return caller(func, *(extras + args), **kw)
2023-02-28 22:12:18.143251 2023-02-28 22:12:18.139 38 ERROR keystone.server.flask.application   File "/var/lib/kolla/venv/lib/python3.9/site-packages/dogpile/cache/region.py", line 1577, in get_or_create_for_user_func
2023-02-28 22:12:18.143262 2023-02-28 22:12:18.139 38 ERROR keystone.server.flask.application     return self.get_or_create(
2023-02-28 22:12:18.143272 2023-02-28 22:12:18.139 38 ERROR keystone.server.flask.application   File "/var/lib/kolla/venv/lib/python3.9/site-packages/dogpile/cache/region.py", line 1042, in get_or_create
2023-02-28 22:12:18.143283 2023-02-28 22:12:18.139 38 ERROR keystone.server.flask.application     with Lock(
2023-02-28 22:12:18.143293 2023-02-28 22:12:18.139 38 ERROR keystone.server.flask.application   File "/var/lib/kolla/venv/lib/python3.9/site-packages/dogpile/lock.py", line 185, in __enter__
2023-02-28 22:12:18.143303 2023-02-28 22:12:18.139 38 ERROR keystone.server.flask.application     return self._enter()
2023-02-28 22:12:18.143313 2023-02-28 22:12:18.139 38 ERROR keystone.server.flask.application   File "/var/lib/kolla/venv/lib/python3.9/site-packages/dogpile/lock.py", line 94, in _enter
2023-02-28 22:12:18.143323 2023-02-28 22:12:18.139 38 ERROR keystone.server.flask.application     generated = self._enter_create(value, createdtime)
2023-02-28 22:12:18.143333 2023-02-28 22:12:18.139 38 ERROR keystone.server.flask.application   File "/var/lib/kolla/venv/lib/python3.9/site-packages/dogpile/lock.py", line 178, in _enter_create
2023-02-28 22:12:18.143343 2023-02-28 22:12:18.139 38 ERROR keystone.server.flask.application     return self.creator()
2023-02-28 22:12:18.143353 2023-02-28 22:12:18.139 38 ERROR keystone.server.flask.application   File "/var/lib/kolla/venv/lib/python3.9/site-packages/dogpile/cache/region.py", line 995, in gen_value
2023-02-28 22:12:18.143364 2023-02-28 22:12:18.139 38 ERROR keystone.server.flask.application     created_value = creator(
2023-02-28 22:12:18.143374 2023-02-28 22:12:18.139 38 ERROR keystone.server.flask.application   File "/var/lib/kolla/venv/lib/python3.9/site-packages/keystone/resource/core.py", line 903, in get_project
2023-02-28 22:12:18.143384 2023-02-28 22:12:18.139 38 ERROR keystone.server.flask.application     return self.driver.get_project(project_id)
2023-02-28 22:12:18.143394 2023-02-28 22:12:18.139 38 ERROR keystone.server.flask.application   File "/var/lib/kolla/venv/lib/python3.9/site-packages/keystone/resource/backends/sql.py", line 49, in get_project
2023-02-28 22:12:18.143404 2023-02-28 22:12:18.139 38 ERROR keystone.server.flask.application     return self._get_project(session, project_id).to_dict()
2023-02-28 22:12:18.143414 2023-02-28 22:12:18.139 38 ERROR keystone.server.flask.application   File "/var/lib/kolla/venv/lib/python3.9/site-packages/keystone/resource/backends/sql.py", line 44, in _get_project
2023-02-28 22:12:18.143425 2023-02-28 22:12:18.139 38 ERROR keystone.server.flask.application     raise exception.ProjectNotFound(project_id=project_id)
2023-02-28 22:12:18.143453 2023-02-28 22:12:18.139 38 ERROR keystone.server.flask.application keystone.exception.ProjectNotFound: Could not find project: service.
2023-02-28 22:12:18.143465 2023-02-28 22:12:18.139 38 ERROR keystone.server.flask.application \x1b[00m
2023-02-28 22:15:08.175038 2023-02-28 22:15:08.171 39 ERROR keystone.server.flask.application [None req-b663be05-06ad-4621-9a0c-22c956ac05df afab145532ce44e89a27128ecf3b716c - - all default -] Could not find project: service.: keystone.exception.ProjectNotFound: Could not find project: service.
2023-02-28 22:15:08.175127 2023-02-28 22:15:08.171 39 ERROR keystone.server.flask.application Traceback (most recent call last):
2023-02-28 22:15:08.175140 2023-02-28 22:15:08.171 39 ERROR keystone.server.flask.application   File "/var/lib/kolla/venv/lib/python3.9/site-packages/flask/app.py", line 1820, in full_dispatch_request
2023-02-28 22:15:08.175152 2023-02-28 22:15:08.171 39 ERROR keystone.server.flask.application     rv = self.dispatch_request()
2023-02-28 22:15:08.175162 2023-02-28 22:15:08.171 39 ERROR keystone.server.flask.application   File "/var/lib/kolla/venv/lib/python3.9/site-packages/flask/app.py", line 1796, in dispatch_request
2023-02-28 22:15:08.175172 2023-02-28 22:15:08.171 39 ERROR keystone.server.flask.application     return self.ensure_sync(self.view_functions[rule.endpoint])(**view_args)
2023-02-28 22:15:08.175183 2023-02-28 22:15:08.171 39 ERROR keystone.server.flask.application   File "/var/lib/kolla/venv/lib/python3.9/site-packages/flask_restful/__init__.py", line 467, in wrapper
2023-02-28 22:15:08.175193 2023-02-28 22:15:08.171 39 ERROR keystone.server.flask.application     resp = resource(*args, **kwargs)
2023-02-28 22:15:08.175209 2023-02-28 22:15:08.171 39 ERROR keystone.server.flask.application   File "/var/lib/kolla/venv/lib/python3.9/site-packages/flask/views.py", line 107, in view
2023-02-28 22:15:08.175221 2023-02-28 22:15:08.171 39 ERROR keystone.server.flask.application     return current_app.ensure_sync(self.dispatch_request)(**kwargs)
2023-02-28 22:15:08.175232 2023-02-28 22:15:08.171 39 ERROR keystone.server.flask.application   File "/var/lib/kolla/venv/lib/python3.9/site-packages/flask_restful/__init__.py", line 582, in dispatch_request
2023-02-28 22:15:08.175242 2023-02-28 22:15:08.171 39 ERROR keystone.server.flask.application     resp = meth(*args, **kwargs)
2023-02-28 22:15:08.175252 2023-02-28 22:15:08.171 39 ERROR keystone.server.flask.application   File "/var/lib/kolla/venv/lib/python3.9/site-packages/keystone/api/projects.py", line 151, in get
2023-02-28 22:15:08.175263 2023-02-28 22:15:08.171 39 ERROR keystone.server.flask.application     return self._get_project(project_id)
2023-02-28 22:15:08.175273 2023-02-28 22:15:08.171 39 ERROR keystone.server.flask.application   File "/var/lib/kolla/venv/lib/python3.9/site-packages/keystone/api/projects.py", line 107, in _get_project
2023-02-28 22:15:08.175283 2023-02-28 22:15:08.171 39 ERROR keystone.server.flask.application     project = PROVIDERS.resource_api.get_project(project_id)
2023-02-28 22:15:08.175293 2023-02-28 22:15:08.171 39 ERROR keystone.server.flask.application   File "/var/lib/kolla/venv/lib/python3.9/site-packages/keystone/common/manager.py", line 115, in wrapped
2023-02-28 22:15:08.175303 2023-02-28 22:15:08.171 39 ERROR keystone.server.flask.application     __ret_val = __f(*args, **kwargs)
2023-02-28 22:15:08.175313 2023-02-28 22:15:08.171 39 ERROR keystone.server.flask.application   File "/var/lib/kolla/venv/lib/python3.9/site-packages/decorator.py", line 232, in fun
2023-02-28 22:15:08.175323 2023-02-28 22:15:08.171 39 ERROR keystone.server.flask.application     return caller(func, *(extras + args), **kw)
2023-02-28 22:15:08.175338 2023-02-28 22:15:08.171 39 ERROR keystone.server.flask.application   File "/var/lib/kolla/venv/lib/python3.9/site-packages/dogpile/cache/region.py", line 1577, in get_or_create_for_user_func
2023-02-28 22:15:08.175351 2023-02-28 22:15:08.171 39 ERROR keystone.server.flask.application     return self.get_or_create(
2023-02-28 22:15:08.175377 2023-02-28 22:15:08.171 39 ERROR keystone.server.flask.application   File "/var/lib/kolla/venv/lib/python3.9/site-packages/dogpile/cache/region.py", line 1042, in get_or_create
2023-02-28 22:15:08.175389 2023-02-28 22:15:08.171 39 ERROR keystone.server.flask.application     with Lock(
2023-02-28 22:15:08.175399 2023-02-28 22:15:08.171 39 ERROR keystone.server.flask.application   File "/var/lib/kolla/venv/lib/python3.9/site-packages/dogpile/lock.py", line 185, in __enter__
2023-02-28 22:15:08.175410 2023-02-28 22:15:08.171 39 ERROR keystone.server.flask.application     return self._enter()
2023-02-28 22:15:08.175420 2023-02-28 22:15:08.171 39 ERROR keystone.server.flask.application   File "/var/lib/kolla/venv/lib/python3.9/site-packages/dogpile/lock.py", line 94, in _enter
2023-02-28 22:15:08.175430 2023-02-28 22:15:08.171 39 ERROR keystone.server.flask.application     generated = self._enter_create(value, createdtime)
2023-02-28 22:15:08.175440 2023-02-28 22:15:08.171 39 ERROR keystone.server.flask.application   File "/var/lib/kolla/venv/lib/python3.9/site-packages/dogpile/lock.py", line 178, in _enter_create
2023-02-28 22:15:08.175450 2023-02-28 22:15:08.171 39 ERROR keystone.server.flask.application     return self.creator()
2023-02-28 22:15:08.175460 2023-02-28 22:15:08.171 39 ERROR keystone.server.flask.application   File "/var/lib/kolla/venv/lib/python3.9/site-packages/dogpile/cache/region.py", line 995, in gen_value
2023-02-28 22:15:08.175493 2023-02-28 22:15:08.171 39 ERROR keystone.server.flask.application     created_value = creator(
2023-02-28 22:15:08.175514 2023-02-28 22:15:08.171 39 ERROR keystone.server.flask.application   File "/var/lib/kolla/venv/lib/python3.9/site-packages/keystone/resource/core.py", line 903, in get_project
2023-02-28 22:15:08.175525 2023-02-28 22:15:08.171 39 ERROR keystone.server.flask.application     return self.driver.get_project(project_id)
2023-02-28 22:15:08.175535 2023-02-28 22:15:08.171 39 ERROR keystone.server.flask.application   File "/var/lib/kolla/venv/lib/python3.9/site-packages/keystone/resource/backends/sql.py", line 49, in get_project
2023-02-28 22:15:08.175545 2023-02-28 22:15:08.171 39 ERROR keystone.server.flask.application     return self._get_project(session, project_id).to_dict()
2023-02-28 22:15:08.175555 2023-02-28 22:15:08.171 39 ERROR keystone.server.flask.application   File "/var/lib/kolla/venv/lib/python3.9/site-packages/keystone/resource/backends/sql.py", line 44, in _get_project
2023-02-28 22:15:08.175566 2023-02-28 22:15:08.171 39 ERROR keystone.server.flask.application     raise exception.ProjectNotFound(project_id=project_id)
2023-02-28 22:15:08.175576 2023-02-28 22:15:08.171 39 ERROR keystone.server.flask.application keystone.exception.ProjectNotFound: Could not find project: service.
2023-02-28 22:15:08.175586 2023-02-28 22:15:08.171 39 ERROR keystone.server.flask.application \x1b[00m
2023-02-28 22:15:22.110301 2023-02-28 22:15:22.106 38 ERROR keystone.server.flask.application [None req-f8a8758d-f075-42a9-a175-dffc34d2c5d0 afab145532ce44e89a27128ecf3b716c - - all default -] Could not find role: admin.: keystone.exception.RoleNotFound: Could not find role: admin.
2023-02-28 22:15:22.110359 2023-02-28 22:15:22.106 38 ERROR keystone.server.flask.application Traceback (most recent call last):
2023-02-28 22:15:22.110372 2023-02-28 22:15:22.106 38 ERROR keystone.server.flask.application   File "/var/lib/kolla/venv/lib/python3.9/site-packages/flask/app.py", line 1820, in full_dispatch_request
2023-02-28 22:15:22.110383 2023-02-28 22:15:22.106 38 ERROR keystone.server.flask.application     rv = self.dispatch_request()
2023-02-28 22:15:22.110393 2023-02-28 22:15:22.106 38 ERROR keystone.server.flask.application   File "/var/lib/kolla/venv/lib/python3.9/site-packages/flask/app.py", line 1796, in dispatch_request
2023-02-28 22:15:22.110404 2023-02-28 22:15:22.106 38 ERROR keystone.server.flask.application     return self.ensure_sync(self.view_functions[rule.endpoint])(**view_args)
2023-02-28 22:15:22.110414 2023-02-28 22:15:22.106 38 ERROR keystone.server.flask.application   File "/var/lib/kolla/venv/lib/python3.9/site-packages/flask_restful/__init__.py", line 467, in wrapper
2023-02-28 22:15:22.110439 2023-02-28 22:15:22.106 38 ERROR keystone.server.flask.application     resp = resource(*args, **kwargs)
2023-02-28 22:15:22.110457 2023-02-28 22:15:22.106 38 ERROR keystone.server.flask.application   File "/var/lib/kolla/venv/lib/python3.9/site-packages/flask/views.py", line 107, in view
2023-02-28 22:15:22.110469 2023-02-28 22:15:22.106 38 ERROR keystone.server.flask.application     return current_app.ensure_sync(self.dispatch_request)(**kwargs)
2023-02-28 22:15:22.110509 2023-02-28 22:15:22.106 38 ERROR keystone.server.flask.application   File "/var/lib/kolla/venv/lib/python3.9/site-packages/flask_restful/__init__.py", line 582, in dispatch_request
2023-02-28 22:15:22.110521 2023-02-28 22:15:22.106 38 ERROR keystone.server.flask.application     resp = meth(*args, **kwargs)
2023-02-28 22:15:22.110531 2023-02-28 22:15:22.106 38 ERROR keystone.server.flask.application   File "/var/lib/kolla/venv/lib/python3.9/site-packages/keystone/api/roles.py", line 50, in get
2023-02-28 22:15:22.110549 2023-02-28 22:15:22.106 38 ERROR keystone.server.flask.application     return self._get_role(role_id)
2023-02-28 22:15:22.110559 2023-02-28 22:15:22.106 38 ERROR keystone.server.flask.application   File "/var/lib/kolla/venv/lib/python3.9/site-packages/keystone/api/roles.py", line 70, in _get_role
2023-02-28 22:15:22.110570 2023-02-28 22:15:22.106 38 ERROR keystone.server.flask.application     ENFORCER.enforce_call(action='identity:get_role')
2023-02-28 22:15:22.110580 2023-02-28 22:15:22.106 38 ERROR keystone.server.flask.application   File "/var/lib/kolla/venv/lib/python3.9/site-packages/keystone/common/rbac_enforcer/enforcer.py", line 402, in enforce_call
2023-02-28 22:15:22.110590 2023-02-28 22:15:22.106 38 ERROR keystone.server.flask.application     policy_dict.update(cls._extract_member_target_data(
2023-02-28 22:15:22.110607 2023-02-28 22:15:22.106 38 ERROR keystone.server.flask.application   File "/var/lib/kolla/venv/lib/python3.9/site-packages/keystone/common/rbac_enforcer/enforcer.py", line 234, in _extract_member_target_data
2023-02-28 22:15:22.110621 2023-02-28 22:15:22.106 38 ERROR keystone.server.flask.application     member_name: func(flask.request.view_args[key])
2023-02-28 22:15:22.110631 2023-02-28 22:15:22.106 38 ERROR keystone.server.flask.application   File "/var/lib/kolla/venv/lib/python3.9/site-packages/keystone/common/manager.py", line 115, in wrapped
2023-02-28 22:15:22.110641 2023-02-28 22:15:22.106 38 ERROR keystone.server.flask.application     __ret_val = __f(*args, **kwargs)
2023-02-28 22:15:22.110651 2023-02-28 22:15:22.106 38 ERROR keystone.server.flask.application   File "/var/lib/kolla/venv/lib/python3.9/site-packages/decorator.py", line 232, in fun
2023-02-28 22:15:22.110662 2023-02-28 22:15:22.106 38 ERROR keystone.server.flask.application     return caller(func, *(extras + args), **kw)
2023-02-28 22:15:22.110672 2023-02-28 22:15:22.106 38 ERROR keystone.server.flask.application   File "/var/lib/kolla/venv/lib/python3.9/site-packages/dogpile/cache/region.py", line 1577, in get_or_create_for_user_func
2023-02-28 22:15:22.110682 2023-02-28 22:15:22.106 38 ERROR keystone.server.flask.application     return self.get_or_create(
2023-02-28 22:15:22.110692 2023-02-28 22:15:22.106 38 ERROR keystone.server.flask.application   File "/var/lib/kolla/venv/lib/python3.9/site-packages/dogpile/cache/region.py", line 1042, in get_or_create
2023-02-28 22:15:22.110703 2023-02-28 22:15:22.106 38 ERROR keystone.server.flask.application     with Lock(
2023-02-28 22:15:22.110724 2023-02-28 22:15:22.106 38 ERROR keystone.server.flask.application   File "/var/lib/kolla/venv/lib/python3.9/site-packages/dogpile/lock.py", line 185, in __enter__
2023-02-28 22:15:22.110734 2023-02-28 22:15:22.106 38 ERROR keystone.server.flask.application     return self._enter()
2023-02-28 22:15:22.110744 2023-02-28 22:15:22.106 38 ERROR keystone.server.flask.application   File "/var/lib/kolla/venv/lib/python3.9/site-packages/dogpile/lock.py", line 94, in _enter
2023-02-28 22:15:22.110775 2023-02-28 22:15:22.106 38 ERROR keystone.server.flask.application     generated = self._enter_create(value, createdtime)
2023-02-28 22:15:22.110787 2023-02-28 22:15:22.106 38 ERROR keystone.server.flask.application   File "/var/lib/kolla/venv/lib/python3.9/site-packages/dogpile/lock.py", line 178, in _enter_create
2023-02-28 22:15:22.110814 2023-02-28 22:15:22.106 38 ERROR keystone.server.flask.application     return self.creator()
2023-02-28 22:15:22.110827 2023-02-28 22:15:22.106 38 ERROR keystone.server.flask.application   File "/var/lib/kolla/venv/lib/python3.9/site-packages/dogpile/cache/region.py", line 995, in gen_value
2023-02-28 22:15:22.110837 2023-02-28 22:15:22.106 38 ERROR keystone.server.flask.application     created_value = creator(
2023-02-28 22:15:22.110847 2023-02-28 22:15:22.106 38 ERROR keystone.server.flask.application   File "/var/lib/kolla/venv/lib/python3.9/site-packages/keystone/assignment/core.py", line 1276, in get_role
2023-02-28 22:15:22.110857 2023-02-28 22:15:22.106 38 ERROR keystone.server.flask.application     return self.driver.get_role(role_id)
2023-02-28 22:15:22.110867 2023-02-28 22:15:22.106 38 ERROR keystone.server.flask.application   File "/var/lib/kolla/venv/lib/python3.9/site-packages/keystone/assignment/role_backends/sql.py", line 70, in get_role
2023-02-28 22:15:22.110877 2023-02-28 22:15:22.106 38 ERROR keystone.server.flask.application     return self._get_role(session, role_id).to_dict()
2023-02-28 22:15:22.110887 2023-02-28 22:15:22.106 38 ERROR keystone.server.flask.application   File "/var/lib/kolla/venv/lib/python3.9/site-packages/keystone/assignment/role_backends/sql.py", line 65, in _get_role
2023-02-28 22:15:22.110898 2023-02-28 22:15:22.106 38 ERROR keystone.server.flask.application     raise exception.RoleNotFound(role_id=role_id)
2023-02-28 22:15:22.110908 2023-02-28 22:15:22.106 38 ERROR keystone.server.flask.application keystone.exception.RoleNotFound: Could not find role: admin.
2023-02-28 22:15:22.110917 2023-02-28 22:15:22.106 38 ERROR keystone.server.flask.application \x1b[00m
2023-02-28 22:15:23.212951 2023-02-28 22:15:23.209 38 ERROR keystone.server.flask.application [None req-a1296ccf-0446-4ffe-90bd-b76841987a8d afab145532ce44e89a27128ecf3b716c - - all default -] Could not find user: neutron.: keystone.exception.UserNotFound: Could not find user: neutron.
2023-02-28 22:15:23.213032 2023-02-28 22:15:23.209 38 ERROR keystone.server.flask.application Traceback (most recent call last):
2023-02-28 22:15:23.213066 2023-02-28 22:15:23.209 38 ERROR keystone.server.flask.application   File "/var/lib/kolla/venv/lib/python3.9/site-packages/flask/app.py", line 1820, in full_dispatch_request
2023-02-28 22:15:23.213077 2023-02-28 22:15:23.209 38 ERROR keystone.server.flask.application     rv = self.dispatch_request()
2023-02-28 22:15:23.213087 2023-02-28 22:15:23.209 38 ERROR keystone.server.flask.application   File "/var/lib/kolla/venv/lib/python3.9/site-packages/flask/app.py", line 1796, in dispatch_request
2023-02-28 22:15:23.213098 2023-02-28 22:15:23.209 38 ERROR keystone.server.flask.application     return self.ensure_sync(self.view_functions[rule.endpoint])(**view_args)
2023-02-28 22:15:23.213108 2023-02-28 22:15:23.209 38 ERROR keystone.server.flask.application   File "/var/lib/kolla/venv/lib/python3.9/site-packages/flask_restful/__init__.py", line 467, in wrapper
2023-02-28 22:15:23.213118 2023-02-28 22:15:23.209 38 ERROR keystone.server.flask.application     resp = resource(*args, **kwargs)
2023-02-28 22:15:23.213129 2023-02-28 22:15:23.209 38 ERROR keystone.server.flask.application   File "/var/lib/kolla/venv/lib/python3.9/site-packages/flask/views.py", line 107, in view
2023-02-28 22:15:23.213139 2023-02-28 22:15:23.209 38 ERROR keystone.server.flask.application     return current_app.ensure_sync(self.dispatch_request)(**kwargs)
2023-02-28 22:15:23.213149 2023-02-28 22:15:23.209 38 ERROR keystone.server.flask.application   File "/var/lib/kolla/venv/lib/python3.9/site-packages/flask_restful/__init__.py", line 582, in dispatch_request
2023-02-28 22:15:23.213176 2023-02-28 22:15:23.209 38 ERROR keystone.server.flask.application     resp = meth(*args, **kwargs)
2023-02-28 22:15:23.213188 2023-02-28 22:15:23.209 38 ERROR keystone.server.flask.application   File "/var/lib/kolla/venv/lib/python3.9/site-packages/keystone/api/users.py", line 182, in get
2023-02-28 22:15:23.213198 2023-02-28 22:15:23.209 38 ERROR keystone.server.flask.application     return self._get_user(user_id)
2023-02-28 22:15:23.213208 2023-02-28 22:15:23.209 38 ERROR keystone.server.flask.application   File "/var/lib/kolla/venv/lib/python3.9/site-packages/keystone/api/users.py", line 194, in _get_user
2023-02-28 22:15:23.213219 2023-02-28 22:15:23.209 38 ERROR keystone.server.flask.application     ref = PROVIDERS.identity_api.get_user(user_id)
2023-02-28 22:15:23.213229 2023-02-28 22:15:23.209 38 ERROR keystone.server.flask.application   File "/var/lib/kolla/venv/lib/python3.9/site-packages/keystone/common/manager.py", line 115, in wrapped
2023-02-28 22:15:23.213240 2023-02-28 22:15:23.209 38 ERROR keystone.server.flask.application     __ret_val = __f(*args, **kwargs)
2023-02-28 22:15:23.213249 2023-02-28 22:15:23.209 38 ERROR keystone.server.flask.application   File "/var/lib/kolla/venv/lib/python3.9/site-packages/keystone/identity/core.py", line 414, in wrapper
2023-02-28 22:15:23.213260 2023-02-28 22:15:23.209 38 ERROR keystone.server.flask.application     return f(self, *args, **kwargs)
2023-02-28 22:15:23.213269 2023-02-28 22:15:23.209 38 ERROR keystone.server.flask.application   File "/var/lib/kolla/venv/lib/python3.9/site-packages/keystone/identity/core.py", line 424, in wrapper
2023-02-28 22:15:23.213280 2023-02-28 22:15:23.209 38 ERROR keystone.server.flask.application     return f(self, *args, **kwargs)
2023-02-28 22:15:23.213289 2023-02-28 22:15:23.209 38 ERROR keystone.server.flask.application   File "/var/lib/kolla/venv/lib/python3.9/site-packages/decorator.py", line 232, in fun
2023-02-28 22:15:23.213299 2023-02-28 22:15:23.209 38 ERROR keystone.server.flask.application     return caller(func, *(extras + args), **kw)
2023-02-28 22:15:23.213326 2023-02-28 22:15:23.209 38 ERROR keystone.server.flask.application   File "/var/lib/kolla/venv/lib/python3.9/site-packages/dogpile/cache/region.py", line 1577, in get_or_create_for_user_func
2023-02-28 22:15:23.213336 2023-02-28 22:15:23.209 38 ERROR keystone.server.flask.application     return self.get_or_create(
2023-02-28 22:15:23.213346 2023-02-28 22:15:23.209 38 ERROR keystone.server.flask.application   File "/var/lib/kolla/venv/lib/python3.9/site-packages/dogpile/cache/region.py", line 1042, in get_or_create
2023-02-28 22:15:23.213357 2023-02-28 22:15:23.209 38 ERROR keystone.server.flask.application     with Lock(
2023-02-28 22:15:23.213367 2023-02-28 22:15:23.209 38 ERROR keystone.server.flask.application   File "/var/lib/kolla/venv/lib/python3.9/site-packages/dogpile/lock.py", line 185, in __enter__
2023-02-28 22:15:23.213377 2023-02-28 22:15:23.209 38 ERROR keystone.server.flask.application     return self._enter()
2023-02-28 22:15:23.213387 2023-02-28 22:15:23.209 38 ERROR keystone.server.flask.application   File "/var/lib/kolla/venv/lib/python3.9/site-packages/dogpile/lock.py", line 94, in _enter
2023-02-28 22:15:23.213397 2023-02-28 22:15:23.209 38 ERROR keystone.server.flask.application     generated = self._enter_create(value, createdtime)
2023-02-28 22:15:23.213407 2023-02-28 22:15:23.209 38 ERROR keystone.server.flask.application   File "/var/lib/kolla/venv/lib/python3.9/site-packages/dogpile/lock.py", line 178, in _enter_create
2023-02-28 22:15:23.213417 2023-02-28 22:15:23.209 38 ERROR keystone.server.flask.application     return self.creator()
2023-02-28 22:15:23.213427 2023-02-28 22:15:23.209 38 ERROR keystone.server.flask.application   File "/var/lib/kolla/venv/lib/python3.9/site-packages/dogpile/cache/region.py", line 995, in gen_value
2023-02-28 22:15:23.213437 2023-02-28 22:15:23.209 38 ERROR keystone.server.flask.application     created_value = creator(
2023-02-28 22:15:23.213457 2023-02-28 22:15:23.209 38 ERROR keystone.server.flask.application   File "/var/lib/kolla/venv/lib/python3.9/site-packages/keystone/identity/core.py", line 1011, in get_user
2023-02-28 22:15:23.213469 2023-02-28 22:15:23.209 38 ERROR keystone.server.flask.application     ref = driver.get_user(entity_id)
2023-02-28 22:15:23.213509 2023-02-28 22:15:23.209 38 ERROR keystone.server.flask.application   File "/var/lib/kolla/venv/lib/python3.9/site-packages/keystone/identity/backends/sql.py", line 200, in get_user
2023-02-28 22:15:23.213521 2023-02-28 22:15:23.209 38 ERROR keystone.server.flask.application     self._get_user(session, user_id).to_dict())
2023-02-28 22:15:23.213533 2023-02-28 22:15:23.209 38 ERROR keystone.server.flask.application   File "/var/lib/kolla/venv/lib/python3.9/site-packages/keystone/identity/backends/sql.py", line 194, in _get_user
2023-02-28 22:15:23.213545 2023-02-28 22:15:23.209 38 ERROR keystone.server.flask.application     raise exception.UserNotFound(user_id=user_id)
2023-02-28 22:15:23.213555 2023-02-28 22:15:23.209 38 ERROR keystone.server.flask.application keystone.exception.UserNotFound: Could not find user: neutron.
2023-02-28 22:15:23.213565 2023-02-28 22:15:23.209 38 ERROR keystone.server.flask.application \x1b[00m
2023-02-28 22:15:23.920441 2023-02-28 22:15:23.917 37 ERROR keystone.server.flask.application [None req-6950ce14-b1e4-4494-adbd-4f7080363864 afab145532ce44e89a27128ecf3b716c - - all default -] Could not find project: service.: keystone.exception.ProjectNotFound: Could not find project: service.
2023-02-28 22:15:23.920533 2023-02-28 22:15:23.917 37 ERROR keystone.server.flask.application Traceback (most recent call last):
2023-02-28 22:15:23.920545 2023-02-28 22:15:23.917 37 ERROR keystone.server.flask.application   File "/var/lib/kolla/venv/lib/python3.9/site-packages/flask/app.py", line 1820, in full_dispatch_request
2023-02-28 22:15:23.920556 2023-02-28 22:15:23.917 37 ERROR keystone.server.flask.application     rv = self.dispatch_request()
2023-02-28 22:15:23.920566 2023-02-28 22:15:23.917 37 ERROR keystone.server.flask.application   File "/var/lib/kolla/venv/lib/python3.9/site-packages/flask/app.py", line 1796, in dispatch_request
2023-02-28 22:15:23.920576 2023-02-28 22:15:23.917 37 ERROR keystone.server.flask.application     return self.ensure_sync(self.view_functions[rule.endpoint])(**view_args)
2023-02-28 22:15:23.920586 2023-02-28 22:15:23.917 37 ERROR keystone.server.flask.application   File "/var/lib/kolla/venv/lib/python3.9/site-packages/flask_restful/__init__.py", line 467, in wrapper
2023-02-28 22:15:23.920596 2023-02-28 22:15:23.917 37 ERROR keystone.server.flask.application     resp = resource(*args, **kwargs)
2023-02-28 22:15:23.920607 2023-02-28 22:15:23.917 37 ERROR keystone.server.flask.application   File "/var/lib/kolla/venv/lib/python3.9/site-packages/flask/views.py", line 107, in view
2023-02-28 22:15:23.920617 2023-02-28 22:15:23.917 37 ERROR keystone.server.flask.application     return current_app.ensure_sync(self.dispatch_request)(**kwargs)
2023-02-28 22:15:23.920627 2023-02-28 22:15:23.917 37 ERROR keystone.server.flask.application   File "/var/lib/kolla/venv/lib/python3.9/site-packages/flask_restful/__init__.py", line 582, in dispatch_request
2023-02-28 22:15:23.920637 2023-02-28 22:15:23.917 37 ERROR keystone.server.flask.application     resp = meth(*args, **kwargs)
2023-02-28 22:15:23.920647 2023-02-28 22:15:23.917 37 ERROR keystone.server.flask.application   File "/var/lib/kolla/venv/lib/python3.9/site-packages/keystone/api/projects.py", line 151, in get
2023-02-28 22:15:23.920657 2023-02-28 22:15:23.917 37 ERROR keystone.server.flask.application     return self._get_project(project_id)
2023-02-28 22:15:23.920667 2023-02-28 22:15:23.917 37 ERROR keystone.server.flask.application   File "/var/lib/kolla/venv/lib/python3.9/site-packages/keystone/api/projects.py", line 107, in _get_project
2023-02-28 22:15:23.920677 2023-02-28 22:15:23.917 37 ERROR keystone.server.flask.application     project = PROVIDERS.resource_api.get_project(project_id)
2023-02-28 22:15:23.920704 2023-02-28 22:15:23.917 37 ERROR keystone.server.flask.application   File "/var/lib/kolla/venv/lib/python3.9/site-packages/keystone/common/manager.py", line 115, in wrapped
2023-02-28 22:15:23.920716 2023-02-28 22:15:23.917 37 ERROR keystone.server.flask.application     __ret_val = __f(*args, **kwargs)
2023-02-28 22:15:23.920726 2023-02-28 22:15:23.917 37 ERROR keystone.server.flask.application   File "/var/lib/kolla/venv/lib/python3.9/site-packages/decorator.py", line 232, in fun
2023-02-28 22:15:23.920736 2023-02-28 22:15:23.917 37 ERROR keystone.server.flask.application     return caller(func, *(extras + args), **kw)
2023-02-28 22:15:23.920746 2023-02-28 22:15:23.917 37 ERROR keystone.server.flask.application   File "/var/lib/kolla/venv/lib/python3.9/site-packages/dogpile/cache/region.py", line 1577, in get_or_create_for_user_func
2023-02-28 22:15:23.920756 2023-02-28 22:15:23.917 37 ERROR keystone.server.flask.application     return self.get_or_create(
2023-02-28 22:15:23.920766 2023-02-28 22:15:23.917 37 ERROR keystone.server.flask.application   File "/var/lib/kolla/venv/lib/python3.9/site-packages/dogpile/cache/region.py", line 1042, in get_or_create
2023-02-28 22:15:23.920777 2023-02-28 22:15:23.917 37 ERROR keystone.server.flask.application     with Lock(
2023-02-28 22:15:23.920786 2023-02-28 22:15:23.917 37 ERROR keystone.server.flask.application   File "/var/lib/kolla/venv/lib/python3.9/site-packages/dogpile/lock.py", line 185, in __enter__
2023-02-28 22:15:23.920822 2023-02-28 22:15:23.917 37 ERROR keystone.server.flask.application     return self._enter()
2023-02-28 22:15:23.920836 2023-02-28 22:15:23.917 37 ERROR keystone.server.flask.application   File "/var/lib/kolla/venv/lib/python3.9/site-packages/dogpile/lock.py", line 94, in _enter
2023-02-28 22:15:23.921241 2023-02-28 22:15:23.917 37 ERROR keystone.server.flask.application     generated = self._enter_create(value, createdtime)
2023-02-28 22:15:23.921255 2023-02-28 22:15:23.917 37 ERROR keystone.server.flask.application   File "/var/lib/kolla/venv/lib/python3.9/site-packages/dogpile/lock.py", line 178, in _enter_create
2023-02-28 22:15:23.921265 2023-02-28 22:15:23.917 37 ERROR keystone.server.flask.application     return self.creator()
2023-02-28 22:15:23.921275 2023-02-28 22:15:23.917 37 ERROR keystone.server.flask.application   File "/var/lib/kolla/venv/lib/python3.9/site-packages/dogpile/cache/region.py", line 995, in gen_value
2023-02-28 22:15:23.921285 2023-02-28 22:15:23.917 37 ERROR keystone.server.flask.application     created_value = creator(
2023-02-28 22:15:23.921295 2023-02-28 22:15:23.917 37 ERROR keystone.server.flask.application   File "/var/lib/kolla/venv/lib/python3.9/site-packages/keystone/resource/core.py", line 903, in get_project
2023-02-28 22:15:23.921305 2023-02-28 22:15:23.917 37 ERROR keystone.server.flask.application     return self.driver.get_project(project_id)
2023-02-28 22:15:23.921314 2023-02-28 22:15:23.917 37 ERROR keystone.server.flask.application   File "/var/lib/kolla/venv/lib/python3.9/site-packages/keystone/resource/backends/sql.py", line 49, in get_project
2023-02-28 22:15:23.921324 2023-02-28 22:15:23.917 37 ERROR keystone.server.flask.application     return self._get_project(session, project_id).to_dict()
2023-02-28 22:15:23.921334 2023-02-28 22:15:23.917 37 ERROR keystone.server.flask.application   File "/var/lib/kolla/venv/lib/python3.9/site-packages/keystone/resource/backends/sql.py", line 44, in _get_project
2023-02-28 22:15:23.921344 2023-02-28 22:15:23.917 37 ERROR keystone.server.flask.application     raise exception.ProjectNotFound(project_id=project_id)
2023-02-28 22:15:23.921353 2023-02-28 22:15:23.917 37 ERROR keystone.server.flask.application keystone.exception.ProjectNotFound: Could not find project: service.
2023-02-28 22:15:23.921363 2023-02-28 22:15:23.917 37 ERROR keystone.server.flask.application \x1b[00m
