2023-02-20 20:27:04.822874 2023-02-20 20:27:04.821 39 WARNING keystone.common.rbac_enforcer.enforcer [None req-5fb5af13-c5e5-4dd9-8576-28bde416147f 7766320271d74dec9e294f2934f5a06f - - all default -] Deprecated policy rules found. Use oslopolicy-policy-generator and oslopolicy-policy-upgrade to detect and resolve deprecated policies in your configuration.\x1b[00m
2023-02-20 20:27:06.022485 2023-02-20 20:27:06.020 37 WARNING keystone.common.rbac_enforcer.enforcer [None req-867e40d2-7aca-494d-aba4-042f367b1887 7766320271d74dec9e294f2934f5a06f - - all default -] Deprecated policy rules found. Use oslopolicy-policy-generator and oslopolicy-policy-upgrade to detect and resolve deprecated policies in your configuration.\x1b[00m
2023-02-20 20:27:13.560575 2023-02-20 20:27:13.558 38 WARNING keystone.common.rbac_enforcer.enforcer [None req-77decdce-acf8-461c-b1eb-2ee290c737c7 7766320271d74dec9e294f2934f5a06f - - all default -] Deprecated policy rules found. Use oslopolicy-policy-generator and oslopolicy-policy-upgrade to detect and resolve deprecated policies in your configuration.\x1b[00m
2023-02-20 20:28:33.316883 2023-02-20 20:28:33.240 39 ERROR keystone.server.flask.application [None req-8dd929ab-a3b2-4978-b7c3-c0711180d7e0 7766320271d74dec9e294f2934f5a06f - - all default -] Could not find project: service.: keystone.exception.ProjectNotFound: Could not find project: service.
2023-02-20 20:28:33.316975 2023-02-20 20:28:33.240 39 ERROR keystone.server.flask.application Traceback (most recent call last):
2023-02-20 20:28:33.317010 2023-02-20 20:28:33.240 39 ERROR keystone.server.flask.application   File "/var/lib/kolla/venv/lib/python3.9/site-packages/flask/app.py", line 1820, in full_dispatch_request
2023-02-20 20:28:33.317033 2023-02-20 20:28:33.240 39 ERROR keystone.server.flask.application     rv = self.dispatch_request()
2023-02-20 20:28:33.317058 2023-02-20 20:28:33.240 39 ERROR keystone.server.flask.application   File "/var/lib/kolla/venv/lib/python3.9/site-packages/flask/app.py", line 1796, in dispatch_request
2023-02-20 20:28:33.317127 2023-02-20 20:28:33.240 39 ERROR keystone.server.flask.application     return self.ensure_sync(self.view_functions[rule.endpoint])(**view_args)
2023-02-20 20:28:33.317156 2023-02-20 20:28:33.240 39 ERROR keystone.server.flask.application   File "/var/lib/kolla/venv/lib/python3.9/site-packages/flask_restful/__init__.py", line 467, in wrapper
2023-02-20 20:28:33.317181 2023-02-20 20:28:33.240 39 ERROR keystone.server.flask.application     resp = resource(*args, **kwargs)
2023-02-20 20:28:33.317217 2023-02-20 20:28:33.240 39 ERROR keystone.server.flask.application   File "/var/lib/kolla/venv/lib/python3.9/site-packages/flask/views.py", line 107, in view
2023-02-20 20:28:33.317250 2023-02-20 20:28:33.240 39 ERROR keystone.server.flask.application     return current_app.ensure_sync(self.dispatch_request)(**kwargs)
2023-02-20 20:28:33.317275 2023-02-20 20:28:33.240 39 ERROR keystone.server.flask.application   File "/var/lib/kolla/venv/lib/python3.9/site-packages/flask_restful/__init__.py", line 582, in dispatch_request
2023-02-20 20:28:33.317298 2023-02-20 20:28:33.240 39 ERROR keystone.server.flask.application     resp = meth(*args, **kwargs)
2023-02-20 20:28:33.317321 2023-02-20 20:28:33.240 39 ERROR keystone.server.flask.application   File "/var/lib/kolla/venv/lib/python3.9/site-packages/keystone/api/projects.py", line 151, in get
2023-02-20 20:28:33.317337 2023-02-20 20:28:33.240 39 ERROR keystone.server.flask.application     return self._get_project(project_id)
2023-02-20 20:28:33.317359 2023-02-20 20:28:33.240 39 ERROR keystone.server.flask.application   File "/var/lib/kolla/venv/lib/python3.9/site-packages/keystone/api/projects.py", line 107, in _get_project
2023-02-20 20:28:33.317388 2023-02-20 20:28:33.240 39 ERROR keystone.server.flask.application     project = PROVIDERS.resource_api.get_project(project_id)
2023-02-20 20:28:33.317432 2023-02-20 20:28:33.240 39 ERROR keystone.server.flask.application   File "/var/lib/kolla/venv/lib/python3.9/site-packages/keystone/common/manager.py", line 115, in wrapped
2023-02-20 20:28:33.317573 2023-02-20 20:28:33.240 39 ERROR keystone.server.flask.application     __ret_val = __f(*args, **kwargs)
2023-02-20 20:28:33.317606 2023-02-20 20:28:33.240 39 ERROR keystone.server.flask.application   File "/var/lib/kolla/venv/lib/python3.9/site-packages/decorator.py", line 232, in fun
2023-02-20 20:28:33.317632 2023-02-20 20:28:33.240 39 ERROR keystone.server.flask.application     return caller(func, *(extras + args), **kw)
2023-02-20 20:28:33.317650 2023-02-20 20:28:33.240 39 ERROR keystone.server.flask.application   File "/var/lib/kolla/venv/lib/python3.9/site-packages/dogpile/cache/region.py", line 1577, in get_or_create_for_user_func
2023-02-20 20:28:33.317675 2023-02-20 20:28:33.240 39 ERROR keystone.server.flask.application     return self.get_or_create(
2023-02-20 20:28:33.317698 2023-02-20 20:28:33.240 39 ERROR keystone.server.flask.application   File "/var/lib/kolla/venv/lib/python3.9/site-packages/dogpile/cache/region.py", line 1042, in get_or_create
2023-02-20 20:28:33.317715 2023-02-20 20:28:33.240 39 ERROR keystone.server.flask.application     with Lock(
2023-02-20 20:28:33.317738 2023-02-20 20:28:33.240 39 ERROR keystone.server.flask.application   File "/var/lib/kolla/venv/lib/python3.9/site-packages/dogpile/lock.py", line 185, in __enter__
2023-02-20 20:28:33.317761 2023-02-20 20:28:33.240 39 ERROR keystone.server.flask.application     return self._enter()
2023-02-20 20:28:33.317778 2023-02-20 20:28:33.240 39 ERROR keystone.server.flask.application   File "/var/lib/kolla/venv/lib/python3.9/site-packages/dogpile/lock.py", line 94, in _enter
2023-02-20 20:28:33.317803 2023-02-20 20:28:33.240 39 ERROR keystone.server.flask.application     generated = self._enter_create(value, createdtime)
2023-02-20 20:28:33.317822 2023-02-20 20:28:33.240 39 ERROR keystone.server.flask.application   File "/var/lib/kolla/venv/lib/python3.9/site-packages/dogpile/lock.py", line 178, in _enter_create
2023-02-20 20:28:33.317844 2023-02-20 20:28:33.240 39 ERROR keystone.server.flask.application     return self.creator()
2023-02-20 20:28:33.317868 2023-02-20 20:28:33.240 39 ERROR keystone.server.flask.application   File "/var/lib/kolla/venv/lib/python3.9/site-packages/dogpile/cache/region.py", line 995, in gen_value
2023-02-20 20:28:33.317885 2023-02-20 20:28:33.240 39 ERROR keystone.server.flask.application     created_value = creator(
2023-02-20 20:28:33.317902 2023-02-20 20:28:33.240 39 ERROR keystone.server.flask.application   File "/var/lib/kolla/venv/lib/python3.9/site-packages/keystone/resource/core.py", line 903, in get_project
2023-02-20 20:28:33.317928 2023-02-20 20:28:33.240 39 ERROR keystone.server.flask.application     return self.driver.get_project(project_id)
2023-02-20 20:28:33.317949 2023-02-20 20:28:33.240 39 ERROR keystone.server.flask.application   File "/var/lib/kolla/venv/lib/python3.9/site-packages/keystone/resource/backends/sql.py", line 49, in get_project
2023-02-20 20:28:33.317968 2023-02-20 20:28:33.240 39 ERROR keystone.server.flask.application     return self._get_project(session, project_id).to_dict()
2023-02-20 20:28:33.317993 2023-02-20 20:28:33.240 39 ERROR keystone.server.flask.application   File "/var/lib/kolla/venv/lib/python3.9/site-packages/keystone/resource/backends/sql.py", line 44, in _get_project
2023-02-20 20:28:33.318010 2023-02-20 20:28:33.240 39 ERROR keystone.server.flask.application     raise exception.ProjectNotFound(project_id=project_id)
2023-02-20 20:28:33.318030 2023-02-20 20:28:33.240 39 ERROR keystone.server.flask.application keystone.exception.ProjectNotFound: Could not find project: service.
2023-02-20 20:28:33.318055 2023-02-20 20:28:33.240 39 ERROR keystone.server.flask.application \x1b[00m
2023-02-20 20:28:42.396129 2023-02-20 20:28:42.385 38 ERROR keystone.server.flask.application [None req-c5d4a51f-c531-4418-af6c-4922d01c11aa 7766320271d74dec9e294f2934f5a06f - - all default -] Could not find project: service.: keystone.exception.ProjectNotFound: Could not find project: service.
2023-02-20 20:28:42.396187 2023-02-20 20:28:42.385 38 ERROR keystone.server.flask.application Traceback (most recent call last):
2023-02-20 20:28:42.396220 2023-02-20 20:28:42.385 38 ERROR keystone.server.flask.application   File "/var/lib/kolla/venv/lib/python3.9/site-packages/flask/app.py", line 1820, in full_dispatch_request
2023-02-20 20:28:42.396233 2023-02-20 20:28:42.385 38 ERROR keystone.server.flask.application     rv = self.dispatch_request()
2023-02-20 20:28:42.396244 2023-02-20 20:28:42.385 38 ERROR keystone.server.flask.application   File "/var/lib/kolla/venv/lib/python3.9/site-packages/flask/app.py", line 1796, in dispatch_request
2023-02-20 20:28:42.396255 2023-02-20 20:28:42.385 38 ERROR keystone.server.flask.application     return self.ensure_sync(self.view_functions[rule.endpoint])(**view_args)
2023-02-20 20:28:42.396266 2023-02-20 20:28:42.385 38 ERROR keystone.server.flask.application   File "/var/lib/kolla/venv/lib/python3.9/site-packages/flask_restful/__init__.py", line 467, in wrapper
2023-02-20 20:28:42.396277 2023-02-20 20:28:42.385 38 ERROR keystone.server.flask.application     resp = resource(*args, **kwargs)
2023-02-20 20:28:42.396288 2023-02-20 20:28:42.385 38 ERROR keystone.server.flask.application   File "/var/lib/kolla/venv/lib/python3.9/site-packages/flask/views.py", line 107, in view
2023-02-20 20:28:42.396299 2023-02-20 20:28:42.385 38 ERROR keystone.server.flask.application     return current_app.ensure_sync(self.dispatch_request)(**kwargs)
2023-02-20 20:28:42.396310 2023-02-20 20:28:42.385 38 ERROR keystone.server.flask.application   File "/var/lib/kolla/venv/lib/python3.9/site-packages/flask_restful/__init__.py", line 582, in dispatch_request
2023-02-20 20:28:42.396321 2023-02-20 20:28:42.385 38 ERROR keystone.server.flask.application     resp = meth(*args, **kwargs)
2023-02-20 20:28:42.396331 2023-02-20 20:28:42.385 38 ERROR keystone.server.flask.application   File "/var/lib/kolla/venv/lib/python3.9/site-packages/keystone/api/projects.py", line 151, in get
2023-02-20 20:28:42.396342 2023-02-20 20:28:42.385 38 ERROR keystone.server.flask.application     return self._get_project(project_id)
2023-02-20 20:28:42.396353 2023-02-20 20:28:42.385 38 ERROR keystone.server.flask.application   File "/var/lib/kolla/venv/lib/python3.9/site-packages/keystone/api/projects.py", line 107, in _get_project
2023-02-20 20:28:42.396364 2023-02-20 20:28:42.385 38 ERROR keystone.server.flask.application     project = PROVIDERS.resource_api.get_project(project_id)
2023-02-20 20:28:42.396374 2023-02-20 20:28:42.385 38 ERROR keystone.server.flask.application   File "/var/lib/kolla/venv/lib/python3.9/site-packages/keystone/common/manager.py", line 115, in wrapped
2023-02-20 20:28:42.396385 2023-02-20 20:28:42.385 38 ERROR keystone.server.flask.application     __ret_val = __f(*args, **kwargs)
2023-02-20 20:28:42.396395 2023-02-20 20:28:42.385 38 ERROR keystone.server.flask.application   File "/var/lib/kolla/venv/lib/python3.9/site-packages/decorator.py", line 232, in fun
2023-02-20 20:28:42.396406 2023-02-20 20:28:42.385 38 ERROR keystone.server.flask.application     return caller(func, *(extras + args), **kw)
2023-02-20 20:28:42.396417 2023-02-20 20:28:42.385 38 ERROR keystone.server.flask.application   File "/var/lib/kolla/venv/lib/python3.9/site-packages/dogpile/cache/region.py", line 1577, in get_or_create_for_user_func
2023-02-20 20:28:42.396428 2023-02-20 20:28:42.385 38 ERROR keystone.server.flask.application     return self.get_or_create(
2023-02-20 20:28:42.396438 2023-02-20 20:28:42.385 38 ERROR keystone.server.flask.application   File "/var/lib/kolla/venv/lib/python3.9/site-packages/dogpile/cache/region.py", line 1042, in get_or_create
2023-02-20 20:28:42.396450 2023-02-20 20:28:42.385 38 ERROR keystone.server.flask.application     with Lock(
2023-02-20 20:28:42.396460 2023-02-20 20:28:42.385 38 ERROR keystone.server.flask.application   File "/var/lib/kolla/venv/lib/python3.9/site-packages/dogpile/lock.py", line 185, in __enter__
2023-02-20 20:28:42.396471 2023-02-20 20:28:42.385 38 ERROR keystone.server.flask.application     return self._enter()
2023-02-20 20:28:42.396551 2023-02-20 20:28:42.385 38 ERROR keystone.server.flask.application   File "/var/lib/kolla/venv/lib/python3.9/site-packages/dogpile/lock.py", line 94, in _enter
2023-02-20 20:28:42.396567 2023-02-20 20:28:42.385 38 ERROR keystone.server.flask.application     generated = self._enter_create(value, createdtime)
2023-02-20 20:28:42.396578 2023-02-20 20:28:42.385 38 ERROR keystone.server.flask.application   File "/var/lib/kolla/venv/lib/python3.9/site-packages/dogpile/lock.py", line 178, in _enter_create
2023-02-20 20:28:42.396589 2023-02-20 20:28:42.385 38 ERROR keystone.server.flask.application     return self.creator()
2023-02-20 20:28:42.396599 2023-02-20 20:28:42.385 38 ERROR keystone.server.flask.application   File "/var/lib/kolla/venv/lib/python3.9/site-packages/dogpile/cache/region.py", line 995, in gen_value
2023-02-20 20:28:42.396610 2023-02-20 20:28:42.385 38 ERROR keystone.server.flask.application     created_value = creator(
2023-02-20 20:28:42.396621 2023-02-20 20:28:42.385 38 ERROR keystone.server.flask.application   File "/var/lib/kolla/venv/lib/python3.9/site-packages/keystone/resource/core.py", line 903, in get_project
2023-02-20 20:28:42.396632 2023-02-20 20:28:42.385 38 ERROR keystone.server.flask.application     return self.driver.get_project(project_id)
2023-02-20 20:28:42.396642 2023-02-20 20:28:42.385 38 ERROR keystone.server.flask.application   File "/var/lib/kolla/venv/lib/python3.9/site-packages/keystone/resource/backends/sql.py", line 49, in get_project
2023-02-20 20:28:42.396653 2023-02-20 20:28:42.385 38 ERROR keystone.server.flask.application     return self._get_project(session, project_id).to_dict()
2023-02-20 20:28:42.396664 2023-02-20 20:28:42.385 38 ERROR keystone.server.flask.application   File "/var/lib/kolla/venv/lib/python3.9/site-packages/keystone/resource/backends/sql.py", line 44, in _get_project
2023-02-20 20:28:42.396675 2023-02-20 20:28:42.385 38 ERROR keystone.server.flask.application     raise exception.ProjectNotFound(project_id=project_id)
2023-02-20 20:28:42.396686 2023-02-20 20:28:42.385 38 ERROR keystone.server.flask.application keystone.exception.ProjectNotFound: Could not find project: service.
2023-02-20 20:28:42.396696 2023-02-20 20:28:42.385 38 ERROR keystone.server.flask.application \x1b[00m
2023-02-20 20:28:58.375878 2023-02-20 20:28:58.354 38 ERROR keystone.server.flask.application [None req-086ad88f-79dd-4381-95f3-f679cbfb2f42 7766320271d74dec9e294f2934f5a06f - - all default -] Could not find role: admin.: keystone.exception.RoleNotFound: Could not find role: admin.
2023-02-20 20:28:58.375944 2023-02-20 20:28:58.354 38 ERROR keystone.server.flask.application Traceback (most recent call last):
2023-02-20 20:28:58.375957 2023-02-20 20:28:58.354 38 ERROR keystone.server.flask.application   File "/var/lib/kolla/venv/lib/python3.9/site-packages/flask/app.py", line 1820, in full_dispatch_request
2023-02-20 20:28:58.375967 2023-02-20 20:28:58.354 38 ERROR keystone.server.flask.application     rv = self.dispatch_request()
2023-02-20 20:28:58.375977 2023-02-20 20:28:58.354 38 ERROR keystone.server.flask.application   File "/var/lib/kolla/venv/lib/python3.9/site-packages/flask/app.py", line 1796, in dispatch_request
2023-02-20 20:28:58.375988 2023-02-20 20:28:58.354 38 ERROR keystone.server.flask.application     return self.ensure_sync(self.view_functions[rule.endpoint])(**view_args)
2023-02-20 20:28:58.375997 2023-02-20 20:28:58.354 38 ERROR keystone.server.flask.application   File "/var/lib/kolla/venv/lib/python3.9/site-packages/flask_restful/__init__.py", line 467, in wrapper
2023-02-20 20:28:58.376007 2023-02-20 20:28:58.354 38 ERROR keystone.server.flask.application     resp = resource(*args, **kwargs)
2023-02-20 20:28:58.376017 2023-02-20 20:28:58.354 38 ERROR keystone.server.flask.application   File "/var/lib/kolla/venv/lib/python3.9/site-packages/flask/views.py", line 107, in view
2023-02-20 20:28:58.376027 2023-02-20 20:28:58.354 38 ERROR keystone.server.flask.application     return current_app.ensure_sync(self.dispatch_request)(**kwargs)
2023-02-20 20:28:58.376037 2023-02-20 20:28:58.354 38 ERROR keystone.server.flask.application   File "/var/lib/kolla/venv/lib/python3.9/site-packages/flask_restful/__init__.py", line 582, in dispatch_request
2023-02-20 20:28:58.376100 2023-02-20 20:28:58.354 38 ERROR keystone.server.flask.application     resp = meth(*args, **kwargs)
2023-02-20 20:28:58.376117 2023-02-20 20:28:58.354 38 ERROR keystone.server.flask.application   File "/var/lib/kolla/venv/lib/python3.9/site-packages/keystone/api/roles.py", line 50, in get
2023-02-20 20:28:58.376128 2023-02-20 20:28:58.354 38 ERROR keystone.server.flask.application     return self._get_role(role_id)
2023-02-20 20:28:58.376137 2023-02-20 20:28:58.354 38 ERROR keystone.server.flask.application   File "/var/lib/kolla/venv/lib/python3.9/site-packages/keystone/api/roles.py", line 70, in _get_role
2023-02-20 20:28:58.376147 2023-02-20 20:28:58.354 38 ERROR keystone.server.flask.application     ENFORCER.enforce_call(action='identity:get_role')
2023-02-20 20:28:58.376166 2023-02-20 20:28:58.354 38 ERROR keystone.server.flask.application   File "/var/lib/kolla/venv/lib/python3.9/site-packages/keystone/common/rbac_enforcer/enforcer.py", line 402, in enforce_call
2023-02-20 20:28:58.376178 2023-02-20 20:28:58.354 38 ERROR keystone.server.flask.application     policy_dict.update(cls._extract_member_target_data(
2023-02-20 20:28:58.376191 2023-02-20 20:28:58.354 38 ERROR keystone.server.flask.application   File "/var/lib/kolla/venv/lib/python3.9/site-packages/keystone/common/rbac_enforcer/enforcer.py", line 234, in _extract_member_target_data
2023-02-20 20:28:58.376203 2023-02-20 20:28:58.354 38 ERROR keystone.server.flask.application     member_name: func(flask.request.view_args[key])
2023-02-20 20:28:58.376218 2023-02-20 20:28:58.354 38 ERROR keystone.server.flask.application   File "/var/lib/kolla/venv/lib/python3.9/site-packages/keystone/common/manager.py", line 115, in wrapped
2023-02-20 20:28:58.376228 2023-02-20 20:28:58.354 38 ERROR keystone.server.flask.application     __ret_val = __f(*args, **kwargs)
2023-02-20 20:28:58.376237 2023-02-20 20:28:58.354 38 ERROR keystone.server.flask.application   File "/var/lib/kolla/venv/lib/python3.9/site-packages/decorator.py", line 232, in fun
2023-02-20 20:28:58.376247 2023-02-20 20:28:58.354 38 ERROR keystone.server.flask.application     return caller(func, *(extras + args), **kw)
2023-02-20 20:28:58.376258 2023-02-20 20:28:58.354 38 ERROR keystone.server.flask.application   File "/var/lib/kolla/venv/lib/python3.9/site-packages/dogpile/cache/region.py", line 1577, in get_or_create_for_user_func
2023-02-20 20:28:58.376268 2023-02-20 20:28:58.354 38 ERROR keystone.server.flask.application     return self.get_or_create(
2023-02-20 20:28:58.376277 2023-02-20 20:28:58.354 38 ERROR keystone.server.flask.application   File "/var/lib/kolla/venv/lib/python3.9/site-packages/dogpile/cache/region.py", line 1042, in get_or_create
2023-02-20 20:28:58.376296 2023-02-20 20:28:58.354 38 ERROR keystone.server.flask.application     with Lock(
2023-02-20 20:28:58.376320 2023-02-20 20:28:58.354 38 ERROR keystone.server.flask.application   File "/var/lib/kolla/venv/lib/python3.9/site-packages/dogpile/lock.py", line 185, in __enter__
2023-02-20 20:28:58.376330 2023-02-20 20:28:58.354 38 ERROR keystone.server.flask.application     return self._enter()
2023-02-20 20:28:58.376339 2023-02-20 20:28:58.354 38 ERROR keystone.server.flask.application   File "/var/lib/kolla/venv/lib/python3.9/site-packages/dogpile/lock.py", line 94, in _enter
2023-02-20 20:28:58.376349 2023-02-20 20:28:58.354 38 ERROR keystone.server.flask.application     generated = self._enter_create(value, createdtime)
2023-02-20 20:28:58.376358 2023-02-20 20:28:58.354 38 ERROR keystone.server.flask.application   File "/var/lib/kolla/venv/lib/python3.9/site-packages/dogpile/lock.py", line 178, in _enter_create
2023-02-20 20:28:58.376368 2023-02-20 20:28:58.354 38 ERROR keystone.server.flask.application     return self.creator()
2023-02-20 20:28:58.376377 2023-02-20 20:28:58.354 38 ERROR keystone.server.flask.application   File "/var/lib/kolla/venv/lib/python3.9/site-packages/dogpile/cache/region.py", line 995, in gen_value
2023-02-20 20:28:58.376410 2023-02-20 20:28:58.354 38 ERROR keystone.server.flask.application     created_value = creator(
2023-02-20 20:28:58.376422 2023-02-20 20:28:58.354 38 ERROR keystone.server.flask.application   File "/var/lib/kolla/venv/lib/python3.9/site-packages/keystone/assignment/core.py", line 1276, in get_role
2023-02-20 20:28:58.376432 2023-02-20 20:28:58.354 38 ERROR keystone.server.flask.application     return self.driver.get_role(role_id)
2023-02-20 20:28:58.376441 2023-02-20 20:28:58.354 38 ERROR keystone.server.flask.application   File "/var/lib/kolla/venv/lib/python3.9/site-packages/keystone/assignment/role_backends/sql.py", line 70, in get_role
2023-02-20 20:28:58.376451 2023-02-20 20:28:58.354 38 ERROR keystone.server.flask.application     return self._get_role(session, role_id).to_dict()
2023-02-20 20:28:58.376461 2023-02-20 20:28:58.354 38 ERROR keystone.server.flask.application   File "/var/lib/kolla/venv/lib/python3.9/site-packages/keystone/assignment/role_backends/sql.py", line 65, in _get_role
2023-02-20 20:28:58.376470 2023-02-20 20:28:58.354 38 ERROR keystone.server.flask.application     raise exception.RoleNotFound(role_id=role_id)
2023-02-20 20:28:58.376480 2023-02-20 20:28:58.354 38 ERROR keystone.server.flask.application keystone.exception.RoleNotFound: Could not find role: admin.
2023-02-20 20:28:58.376490 2023-02-20 20:28:58.354 38 ERROR keystone.server.flask.application \x1b[00m
2023-02-20 20:28:59.948372 2023-02-20 20:28:59.941 38 ERROR keystone.server.flask.application [None req-1df93e3b-81d3-41a2-bc09-836aaa54a0b7 7766320271d74dec9e294f2934f5a06f - - all default -] Could not find user: ironic.: keystone.exception.UserNotFound: Could not find user: ironic.
2023-02-20 20:28:59.948420 2023-02-20 20:28:59.941 38 ERROR keystone.server.flask.application Traceback (most recent call last):
2023-02-20 20:28:59.948431 2023-02-20 20:28:59.941 38 ERROR keystone.server.flask.application   File "/var/lib/kolla/venv/lib/python3.9/site-packages/flask/app.py", line 1820, in full_dispatch_request
2023-02-20 20:28:59.948441 2023-02-20 20:28:59.941 38 ERROR keystone.server.flask.application     rv = self.dispatch_request()
2023-02-20 20:28:59.948450 2023-02-20 20:28:59.941 38 ERROR keystone.server.flask.application   File "/var/lib/kolla/venv/lib/python3.9/site-packages/flask/app.py", line 1796, in dispatch_request
2023-02-20 20:28:59.948472 2023-02-20 20:28:59.941 38 ERROR keystone.server.flask.application     return self.ensure_sync(self.view_functions[rule.endpoint])(**view_args)
2023-02-20 20:28:59.948481 2023-02-20 20:28:59.941 38 ERROR keystone.server.flask.application   File "/var/lib/kolla/venv/lib/python3.9/site-packages/flask_restful/__init__.py", line 467, in wrapper
2023-02-20 20:28:59.948491 2023-02-20 20:28:59.941 38 ERROR keystone.server.flask.application     resp = resource(*args, **kwargs)
2023-02-20 20:28:59.948532 2023-02-20 20:28:59.941 38 ERROR keystone.server.flask.application   File "/var/lib/kolla/venv/lib/python3.9/site-packages/flask/views.py", line 107, in view
2023-02-20 20:28:59.948557 2023-02-20 20:28:59.941 38 ERROR keystone.server.flask.application     return current_app.ensure_sync(self.dispatch_request)(**kwargs)
2023-02-20 20:28:59.948567 2023-02-20 20:28:59.941 38 ERROR keystone.server.flask.application   File "/var/lib/kolla/venv/lib/python3.9/site-packages/flask_restful/__init__.py", line 582, in dispatch_request
2023-02-20 20:28:59.948576 2023-02-20 20:28:59.941 38 ERROR keystone.server.flask.application     resp = meth(*args, **kwargs)
2023-02-20 20:28:59.948585 2023-02-20 20:28:59.941 38 ERROR keystone.server.flask.application   File "/var/lib/kolla/venv/lib/python3.9/site-packages/keystone/api/users.py", line 182, in get
2023-02-20 20:28:59.948595 2023-02-20 20:28:59.941 38 ERROR keystone.server.flask.application     return self._get_user(user_id)
2023-02-20 20:28:59.948604 2023-02-20 20:28:59.941 38 ERROR keystone.server.flask.application   File "/var/lib/kolla/venv/lib/python3.9/site-packages/keystone/api/users.py", line 194, in _get_user
2023-02-20 20:28:59.948630 2023-02-20 20:28:59.941 38 ERROR keystone.server.flask.application     ref = PROVIDERS.identity_api.get_user(user_id)
2023-02-20 20:28:59.948641 2023-02-20 20:28:59.941 38 ERROR keystone.server.flask.application   File "/var/lib/kolla/venv/lib/python3.9/site-packages/keystone/common/manager.py", line 115, in wrapped
2023-02-20 20:28:59.948651 2023-02-20 20:28:59.941 38 ERROR keystone.server.flask.application     __ret_val = __f(*args, **kwargs)
2023-02-20 20:28:59.948660 2023-02-20 20:28:59.941 38 ERROR keystone.server.flask.application   File "/var/lib/kolla/venv/lib/python3.9/site-packages/keystone/identity/core.py", line 414, in wrapper
2023-02-20 20:28:59.948670 2023-02-20 20:28:59.941 38 ERROR keystone.server.flask.application     return f(self, *args, **kwargs)
2023-02-20 20:28:59.948679 2023-02-20 20:28:59.941 38 ERROR keystone.server.flask.application   File "/var/lib/kolla/venv/lib/python3.9/site-packages/keystone/identity/core.py", line 424, in wrapper
2023-02-20 20:28:59.948689 2023-02-20 20:28:59.941 38 ERROR keystone.server.flask.application     return f(self, *args, **kwargs)
2023-02-20 20:28:59.948698 2023-02-20 20:28:59.941 38 ERROR keystone.server.flask.application   File "/var/lib/kolla/venv/lib/python3.9/site-packages/decorator.py", line 232, in fun
2023-02-20 20:28:59.948708 2023-02-20 20:28:59.941 38 ERROR keystone.server.flask.application     return caller(func, *(extras + args), **kw)
2023-02-20 20:28:59.948718 2023-02-20 20:28:59.941 38 ERROR keystone.server.flask.application   File "/var/lib/kolla/venv/lib/python3.9/site-packages/dogpile/cache/region.py", line 1577, in get_or_create_for_user_func
2023-02-20 20:28:59.948728 2023-02-20 20:28:59.941 38 ERROR keystone.server.flask.application     return self.get_or_create(
2023-02-20 20:28:59.948737 2023-02-20 20:28:59.941 38 ERROR keystone.server.flask.application   File "/var/lib/kolla/venv/lib/python3.9/site-packages/dogpile/cache/region.py", line 1042, in get_or_create
2023-02-20 20:28:59.948749 2023-02-20 20:28:59.941 38 ERROR keystone.server.flask.application     with Lock(
2023-02-20 20:28:59.948759 2023-02-20 20:28:59.941 38 ERROR keystone.server.flask.application   File "/var/lib/kolla/venv/lib/python3.9/site-packages/dogpile/lock.py", line 185, in __enter__
2023-02-20 20:28:59.948768 2023-02-20 20:28:59.941 38 ERROR keystone.server.flask.application     return self._enter()
2023-02-20 20:28:59.948778 2023-02-20 20:28:59.941 38 ERROR keystone.server.flask.application   File "/var/lib/kolla/venv/lib/python3.9/site-packages/dogpile/lock.py", line 94, in _enter
2023-02-20 20:28:59.948788 2023-02-20 20:28:59.941 38 ERROR keystone.server.flask.application     generated = self._enter_create(value, createdtime)
2023-02-20 20:28:59.948811 2023-02-20 20:28:59.941 38 ERROR keystone.server.flask.application   File "/var/lib/kolla/venv/lib/python3.9/site-packages/dogpile/lock.py", line 178, in _enter_create
2023-02-20 20:28:59.948821 2023-02-20 20:28:59.941 38 ERROR keystone.server.flask.application     return self.creator()
2023-02-20 20:28:59.948830 2023-02-20 20:28:59.941 38 ERROR keystone.server.flask.application   File "/var/lib/kolla/venv/lib/python3.9/site-packages/dogpile/cache/region.py", line 995, in gen_value
2023-02-20 20:28:59.948840 2023-02-20 20:28:59.941 38 ERROR keystone.server.flask.application     created_value = creator(
2023-02-20 20:28:59.948863 2023-02-20 20:28:59.941 38 ERROR keystone.server.flask.application   File "/var/lib/kolla/venv/lib/python3.9/site-packages/keystone/identity/core.py", line 1011, in get_user
2023-02-20 20:28:59.948873 2023-02-20 20:28:59.941 38 ERROR keystone.server.flask.application     ref = driver.get_user(entity_id)
2023-02-20 20:28:59.948882 2023-02-20 20:28:59.941 38 ERROR keystone.server.flask.application   File "/var/lib/kolla/venv/lib/python3.9/site-packages/keystone/identity/backends/sql.py", line 200, in get_user
2023-02-20 20:28:59.948891 2023-02-20 20:28:59.941 38 ERROR keystone.server.flask.application     self._get_user(session, user_id).to_dict())
2023-02-20 20:28:59.948912 2023-02-20 20:28:59.941 38 ERROR keystone.server.flask.application   File "/var/lib/kolla/venv/lib/python3.9/site-packages/keystone/identity/backends/sql.py", line 194, in _get_user
2023-02-20 20:28:59.948923 2023-02-20 20:28:59.941 38 ERROR keystone.server.flask.application     raise exception.UserNotFound(user_id=user_id)
2023-02-20 20:28:59.948932 2023-02-20 20:28:59.941 38 ERROR keystone.server.flask.application keystone.exception.UserNotFound: Could not find user: ironic.
2023-02-20 20:28:59.948942 2023-02-20 20:28:59.941 38 ERROR keystone.server.flask.application \x1b[00m
2023-02-20 20:29:00.802574 2023-02-20 20:29:00.792 37 ERROR keystone.server.flask.application [None req-1a0ba176-d308-41cc-968f-462e83e8e798 7766320271d74dec9e294f2934f5a06f - - all default -] Could not find project: service.: keystone.exception.ProjectNotFound: Could not find project: service.
2023-02-20 20:29:00.802615 2023-02-20 20:29:00.792 37 ERROR keystone.server.flask.application Traceback (most recent call last):
2023-02-20 20:29:00.802626 2023-02-20 20:29:00.792 37 ERROR keystone.server.flask.application   File "/var/lib/kolla/venv/lib/python3.9/site-packages/flask/app.py", line 1820, in full_dispatch_request
2023-02-20 20:29:00.802636 2023-02-20 20:29:00.792 37 ERROR keystone.server.flask.application     rv = self.dispatch_request()
2023-02-20 20:29:00.802646 2023-02-20 20:29:00.792 37 ERROR keystone.server.flask.application   File "/var/lib/kolla/venv/lib/python3.9/site-packages/flask/app.py", line 1796, in dispatch_request
2023-02-20 20:29:00.802656 2023-02-20 20:29:00.792 37 ERROR keystone.server.flask.application     return self.ensure_sync(self.view_functions[rule.endpoint])(**view_args)
2023-02-20 20:29:00.802666 2023-02-20 20:29:00.792 37 ERROR keystone.server.flask.application   File "/var/lib/kolla/venv/lib/python3.9/site-packages/flask_restful/__init__.py", line 467, in wrapper
2023-02-20 20:29:00.802676 2023-02-20 20:29:00.792 37 ERROR keystone.server.flask.application     resp = resource(*args, **kwargs)
2023-02-20 20:29:00.802693 2023-02-20 20:29:00.792 37 ERROR keystone.server.flask.application   File "/var/lib/kolla/venv/lib/python3.9/site-packages/flask/views.py", line 107, in view
2023-02-20 20:29:00.802707 2023-02-20 20:29:00.792 37 ERROR keystone.server.flask.application     return current_app.ensure_sync(self.dispatch_request)(**kwargs)
2023-02-20 20:29:00.802716 2023-02-20 20:29:00.792 37 ERROR keystone.server.flask.application   File "/var/lib/kolla/venv/lib/python3.9/site-packages/flask_restful/__init__.py", line 582, in dispatch_request
2023-02-20 20:29:00.802726 2023-02-20 20:29:00.792 37 ERROR keystone.server.flask.application     resp = meth(*args, **kwargs)
2023-02-20 20:29:00.802735 2023-02-20 20:29:00.792 37 ERROR keystone.server.flask.application   File "/var/lib/kolla/venv/lib/python3.9/site-packages/keystone/api/projects.py", line 151, in get
2023-02-20 20:29:00.802766 2023-02-20 20:29:00.792 37 ERROR keystone.server.flask.application     return self._get_project(project_id)
2023-02-20 20:29:00.802776 2023-02-20 20:29:00.792 37 ERROR keystone.server.flask.application   File "/var/lib/kolla/venv/lib/python3.9/site-packages/keystone/api/projects.py", line 107, in _get_project
2023-02-20 20:29:00.802785 2023-02-20 20:29:00.792 37 ERROR keystone.server.flask.application     project = PROVIDERS.resource_api.get_project(project_id)
2023-02-20 20:29:00.802795 2023-02-20 20:29:00.792 37 ERROR keystone.server.flask.application   File "/var/lib/kolla/venv/lib/python3.9/site-packages/keystone/common/manager.py", line 115, in wrapped
2023-02-20 20:29:00.802804 2023-02-20 20:29:00.792 37 ERROR keystone.server.flask.application     __ret_val = __f(*args, **kwargs)
2023-02-20 20:29:00.802813 2023-02-20 20:29:00.792 37 ERROR keystone.server.flask.application   File "/var/lib/kolla/venv/lib/python3.9/site-packages/decorator.py", line 232, in fun
2023-02-20 20:29:00.802823 2023-02-20 20:29:00.792 37 ERROR keystone.server.flask.application     return caller(func, *(extras + args), **kw)
2023-02-20 20:29:00.802860 2023-02-20 20:29:00.792 37 ERROR keystone.server.flask.application   File "/var/lib/kolla/venv/lib/python3.9/site-packages/dogpile/cache/region.py", line 1577, in get_or_create_for_user_func
2023-02-20 20:29:00.802872 2023-02-20 20:29:00.792 37 ERROR keystone.server.flask.application     return self.get_or_create(
2023-02-20 20:29:00.802882 2023-02-20 20:29:00.792 37 ERROR keystone.server.flask.application   File "/var/lib/kolla/venv/lib/python3.9/site-packages/dogpile/cache/region.py", line 1042, in get_or_create
2023-02-20 20:29:00.802892 2023-02-20 20:29:00.792 37 ERROR keystone.server.flask.application     with Lock(
2023-02-20 20:29:00.802901 2023-02-20 20:29:00.792 37 ERROR keystone.server.flask.application   File "/var/lib/kolla/venv/lib/python3.9/site-packages/dogpile/lock.py", line 185, in __enter__
2023-02-20 20:29:00.802911 2023-02-20 20:29:00.792 37 ERROR keystone.server.flask.application     return self._enter()
2023-02-20 20:29:00.802920 2023-02-20 20:29:00.792 37 ERROR keystone.server.flask.application   File "/var/lib/kolla/venv/lib/python3.9/site-packages/dogpile/lock.py", line 94, in _enter
2023-02-20 20:29:00.802930 2023-02-20 20:29:00.792 37 ERROR keystone.server.flask.application     generated = self._enter_create(value, createdtime)
2023-02-20 20:29:00.802944 2023-02-20 20:29:00.792 37 ERROR keystone.server.flask.application   File "/var/lib/kolla/venv/lib/python3.9/site-packages/dogpile/lock.py", line 178, in _enter_create
2023-02-20 20:29:00.802962 2023-02-20 20:29:00.792 37 ERROR keystone.server.flask.application     return self.creator()
2023-02-20 20:29:00.802975 2023-02-20 20:29:00.792 37 ERROR keystone.server.flask.application   File "/var/lib/kolla/venv/lib/python3.9/site-packages/dogpile/cache/region.py", line 995, in gen_value
2023-02-20 20:29:00.802985 2023-02-20 20:29:00.792 37 ERROR keystone.server.flask.application     created_value = creator(
2023-02-20 20:29:00.802994 2023-02-20 20:29:00.792 37 ERROR keystone.server.flask.application   File "/var/lib/kolla/venv/lib/python3.9/site-packages/keystone/resource/core.py", line 903, in get_project
2023-02-20 20:29:00.803004 2023-02-20 20:29:00.792 37 ERROR keystone.server.flask.application     return self.driver.get_project(project_id)
2023-02-20 20:29:00.803014 2023-02-20 20:29:00.792 37 ERROR keystone.server.flask.application   File "/var/lib/kolla/venv/lib/python3.9/site-packages/keystone/resource/backends/sql.py", line 49, in get_project
2023-02-20 20:29:00.803024 2023-02-20 20:29:00.792 37 ERROR keystone.server.flask.application     return self._get_project(session, project_id).to_dict()
2023-02-20 20:29:00.803034 2023-02-20 20:29:00.792 37 ERROR keystone.server.flask.application   File "/var/lib/kolla/venv/lib/python3.9/site-packages/keystone/resource/backends/sql.py", line 44, in _get_project
2023-02-20 20:29:00.803043 2023-02-20 20:29:00.792 37 ERROR keystone.server.flask.application     raise exception.ProjectNotFound(project_id=project_id)
2023-02-20 20:29:00.803053 2023-02-20 20:29:00.792 37 ERROR keystone.server.flask.application keystone.exception.ProjectNotFound: Could not find project: service.
2023-02-20 20:29:00.803062 2023-02-20 20:29:00.792 37 ERROR keystone.server.flask.application \x1b[00m
2023-02-20 20:29:10.707056 2023-02-20 20:29:10.699 39 ERROR keystone.server.flask.application [None req-12a9fce5-ff6f-42eb-9028-fe596a58bbf6 7766320271d74dec9e294f2934f5a06f - - all default -] Could not find role: admin.: keystone.exception.RoleNotFound: Could not find role: admin.
2023-02-20 20:29:10.707146 2023-02-20 20:29:10.699 39 ERROR keystone.server.flask.application Traceback (most recent call last):
2023-02-20 20:29:10.707162 2023-02-20 20:29:10.699 39 ERROR keystone.server.flask.application   File "/var/lib/kolla/venv/lib/python3.9/site-packages/flask/app.py", line 1820, in full_dispatch_request
2023-02-20 20:29:10.707174 2023-02-20 20:29:10.699 39 ERROR keystone.server.flask.application     rv = self.dispatch_request()
2023-02-20 20:29:10.707185 2023-02-20 20:29:10.699 39 ERROR keystone.server.flask.application   File "/var/lib/kolla/venv/lib/python3.9/site-packages/flask/app.py", line 1796, in dispatch_request
2023-02-20 20:29:10.707214 2023-02-20 20:29:10.699 39 ERROR keystone.server.flask.application     return self.ensure_sync(self.view_functions[rule.endpoint])(**view_args)
2023-02-20 20:29:10.707226 2023-02-20 20:29:10.699 39 ERROR keystone.server.flask.application   File "/var/lib/kolla/venv/lib/python3.9/site-packages/flask_restful/__init__.py", line 467, in wrapper
2023-02-20 20:29:10.707238 2023-02-20 20:29:10.699 39 ERROR keystone.server.flask.application     resp = resource(*args, **kwargs)
2023-02-20 20:29:10.707258 2023-02-20 20:29:10.699 39 ERROR keystone.server.flask.application   File "/var/lib/kolla/venv/lib/python3.9/site-packages/flask/views.py", line 107, in view
2023-02-20 20:29:10.707273 2023-02-20 20:29:10.699 39 ERROR keystone.server.flask.application     return current_app.ensure_sync(self.dispatch_request)(**kwargs)
2023-02-20 20:29:10.707284 2023-02-20 20:29:10.699 39 ERROR keystone.server.flask.application   File "/var/lib/kolla/venv/lib/python3.9/site-packages/flask_restful/__init__.py", line 582, in dispatch_request
2023-02-20 20:29:10.707296 2023-02-20 20:29:10.699 39 ERROR keystone.server.flask.application     resp = meth(*args, **kwargs)
2023-02-20 20:29:10.707307 2023-02-20 20:29:10.699 39 ERROR keystone.server.flask.application   File "/var/lib/kolla/venv/lib/python3.9/site-packages/keystone/api/roles.py", line 50, in get
2023-02-20 20:29:10.707318 2023-02-20 20:29:10.699 39 ERROR keystone.server.flask.application     return self._get_role(role_id)
2023-02-20 20:29:10.707337 2023-02-20 20:29:10.699 39 ERROR keystone.server.flask.application   File "/var/lib/kolla/venv/lib/python3.9/site-packages/keystone/api/roles.py", line 70, in _get_role
2023-02-20 20:29:10.707359 2023-02-20 20:29:10.699 39 ERROR keystone.server.flask.application     ENFORCER.enforce_call(action='identity:get_role')
2023-02-20 20:29:10.707380 2023-02-20 20:29:10.699 39 ERROR keystone.server.flask.application   File "/var/lib/kolla/venv/lib/python3.9/site-packages/keystone/common/rbac_enforcer/enforcer.py", line 402, in enforce_call
2023-02-20 20:29:10.707392 2023-02-20 20:29:10.699 39 ERROR keystone.server.flask.application     policy_dict.update(cls._extract_member_target_data(
2023-02-20 20:29:10.707415 2023-02-20 20:29:10.699 39 ERROR keystone.server.flask.application   File "/var/lib/kolla/venv/lib/python3.9/site-packages/keystone/common/rbac_enforcer/enforcer.py", line 234, in _extract_member_target_data
2023-02-20 20:29:10.707430 2023-02-20 20:29:10.699 39 ERROR keystone.server.flask.application     member_name: func(flask.request.view_args[key])
2023-02-20 20:29:10.707441 2023-02-20 20:29:10.699 39 ERROR keystone.server.flask.application   File "/var/lib/kolla/venv/lib/python3.9/site-packages/keystone/common/manager.py", line 115, in wrapped
2023-02-20 20:29:10.707452 2023-02-20 20:29:10.699 39 ERROR keystone.server.flask.application     __ret_val = __f(*args, **kwargs)
2023-02-20 20:29:10.707463 2023-02-20 20:29:10.699 39 ERROR keystone.server.flask.application   File "/var/lib/kolla/venv/lib/python3.9/site-packages/decorator.py", line 232, in fun
2023-02-20 20:29:10.707474 2023-02-20 20:29:10.699 39 ERROR keystone.server.flask.application     return caller(func, *(extras + args), **kw)
2023-02-20 20:29:10.707490 2023-02-20 20:29:10.699 39 ERROR keystone.server.flask.application   File "/var/lib/kolla/venv/lib/python3.9/site-packages/dogpile/cache/region.py", line 1577, in get_or_create_for_user_func
2023-02-20 20:29:10.707533 2023-02-20 20:29:10.699 39 ERROR keystone.server.flask.application     return self.get_or_create(
2023-02-20 20:29:10.707544 2023-02-20 20:29:10.699 39 ERROR keystone.server.flask.application   File "/var/lib/kolla/venv/lib/python3.9/site-packages/dogpile/cache/region.py", line 1042, in get_or_create
2023-02-20 20:29:10.707556 2023-02-20 20:29:10.699 39 ERROR keystone.server.flask.application     with Lock(
2023-02-20 20:29:10.707583 2023-02-20 20:29:10.699 39 ERROR keystone.server.flask.application   File "/var/lib/kolla/venv/lib/python3.9/site-packages/dogpile/lock.py", line 185, in __enter__
2023-02-20 20:29:10.707596 2023-02-20 20:29:10.699 39 ERROR keystone.server.flask.application     return self._enter()
2023-02-20 20:29:10.707607 2023-02-20 20:29:10.699 39 ERROR keystone.server.flask.application   File "/var/lib/kolla/venv/lib/python3.9/site-packages/dogpile/lock.py", line 94, in _enter
2023-02-20 20:29:10.707618 2023-02-20 20:29:10.699 39 ERROR keystone.server.flask.application     generated = self._enter_create(value, createdtime)
2023-02-20 20:29:10.707629 2023-02-20 20:29:10.699 39 ERROR keystone.server.flask.application   File "/var/lib/kolla/venv/lib/python3.9/site-packages/dogpile/lock.py", line 178, in _enter_create
2023-02-20 20:29:10.707640 2023-02-20 20:29:10.699 39 ERROR keystone.server.flask.application     return self.creator()
2023-02-20 20:29:10.707651 2023-02-20 20:29:10.699 39 ERROR keystone.server.flask.application   File "/var/lib/kolla/venv/lib/python3.9/site-packages/dogpile/cache/region.py", line 995, in gen_value
2023-02-20 20:29:10.707663 2023-02-20 20:29:10.699 39 ERROR keystone.server.flask.application     created_value = creator(
2023-02-20 20:29:10.707674 2023-02-20 20:29:10.699 39 ERROR keystone.server.flask.application   File "/var/lib/kolla/venv/lib/python3.9/site-packages/keystone/assignment/core.py", line 1276, in get_role
2023-02-20 20:29:10.707685 2023-02-20 20:29:10.699 39 ERROR keystone.server.flask.application     return self.driver.get_role(role_id)
2023-02-20 20:29:10.707696 2023-02-20 20:29:10.699 39 ERROR keystone.server.flask.application   File "/var/lib/kolla/venv/lib/python3.9/site-packages/keystone/assignment/role_backends/sql.py", line 70, in get_role
2023-02-20 20:29:10.707708 2023-02-20 20:29:10.699 39 ERROR keystone.server.flask.application     return self._get_role(session, role_id).to_dict()
2023-02-20 20:29:10.707719 2023-02-20 20:29:10.699 39 ERROR keystone.server.flask.application   File "/var/lib/kolla/venv/lib/python3.9/site-packages/keystone/assignment/role_backends/sql.py", line 65, in _get_role
2023-02-20 20:29:10.707730 2023-02-20 20:29:10.699 39 ERROR keystone.server.flask.application     raise exception.RoleNotFound(role_id=role_id)
2023-02-20 20:29:10.707741 2023-02-20 20:29:10.699 39 ERROR keystone.server.flask.application keystone.exception.RoleNotFound: Could not find role: admin.
2023-02-20 20:29:10.707753 2023-02-20 20:29:10.699 39 ERROR keystone.server.flask.application \x1b[00m
2023-02-20 20:29:11.831926 2023-02-20 20:29:11.823 39 ERROR keystone.server.flask.application [None req-beef63c4-c2db-468c-aee0-b27ea32c6cd1 7766320271d74dec9e294f2934f5a06f - - all default -] Could not find user: ironic-inspector.: keystone.exception.UserNotFound: Could not find user: ironic-inspector.
2023-02-20 20:29:11.831978 2023-02-20 20:29:11.823 39 ERROR keystone.server.flask.application Traceback (most recent call last):
2023-02-20 20:29:11.832000 2023-02-20 20:29:11.823 39 ERROR keystone.server.flask.application   File "/var/lib/kolla/venv/lib/python3.9/site-packages/flask/app.py", line 1820, in full_dispatch_request
2023-02-20 20:29:11.832020 2023-02-20 20:29:11.823 39 ERROR keystone.server.flask.application     rv = self.dispatch_request()
2023-02-20 20:29:11.832032 2023-02-20 20:29:11.823 39 ERROR keystone.server.flask.application   File "/var/lib/kolla/venv/lib/python3.9/site-packages/flask/app.py", line 1796, in dispatch_request
2023-02-20 20:29:11.832048 2023-02-20 20:29:11.823 39 ERROR keystone.server.flask.application     return self.ensure_sync(self.view_functions[rule.endpoint])(**view_args)
2023-02-20 20:29:11.832061 2023-02-20 20:29:11.823 39 ERROR keystone.server.flask.application   File "/var/lib/kolla/venv/lib/python3.9/site-packages/flask_restful/__init__.py", line 467, in wrapper
2023-02-20 20:29:11.832103 2023-02-20 20:29:11.823 39 ERROR keystone.server.flask.application     resp = resource(*args, **kwargs)
2023-02-20 20:29:11.832119 2023-02-20 20:29:11.823 39 ERROR keystone.server.flask.application   File "/var/lib/kolla/venv/lib/python3.9/site-packages/flask/views.py", line 107, in view
2023-02-20 20:29:11.832146 2023-02-20 20:29:11.823 39 ERROR keystone.server.flask.application     return current_app.ensure_sync(self.dispatch_request)(**kwargs)
2023-02-20 20:29:11.832158 2023-02-20 20:29:11.823 39 ERROR keystone.server.flask.application   File "/var/lib/kolla/venv/lib/python3.9/site-packages/flask_restful/__init__.py", line 582, in dispatch_request
2023-02-20 20:29:11.832168 2023-02-20 20:29:11.823 39 ERROR keystone.server.flask.application     resp = meth(*args, **kwargs)
2023-02-20 20:29:11.832177 2023-02-20 20:29:11.823 39 ERROR keystone.server.flask.application   File "/var/lib/kolla/venv/lib/python3.9/site-packages/keystone/api/users.py", line 182, in get
2023-02-20 20:29:11.832193 2023-02-20 20:29:11.823 39 ERROR keystone.server.flask.application     return self._get_user(user_id)
2023-02-20 20:29:11.832203 2023-02-20 20:29:11.823 39 ERROR keystone.server.flask.application   File "/var/lib/kolla/venv/lib/python3.9/site-packages/keystone/api/users.py", line 194, in _get_user
2023-02-20 20:29:11.832222 2023-02-20 20:29:11.823 39 ERROR keystone.server.flask.application     ref = PROVIDERS.identity_api.get_user(user_id)
2023-02-20 20:29:11.832236 2023-02-20 20:29:11.823 39 ERROR keystone.server.flask.application   File "/var/lib/kolla/venv/lib/python3.9/site-packages/keystone/common/manager.py", line 115, in wrapped
2023-02-20 20:29:11.832246 2023-02-20 20:29:11.823 39 ERROR keystone.server.flask.application     __ret_val = __f(*args, **kwargs)
2023-02-20 20:29:11.832256 2023-02-20 20:29:11.823 39 ERROR keystone.server.flask.application   File "/var/lib/kolla/venv/lib/python3.9/site-packages/keystone/identity/core.py", line 414, in wrapper
2023-02-20 20:29:11.832265 2023-02-20 20:29:11.823 39 ERROR keystone.server.flask.application     return f(self, *args, **kwargs)
2023-02-20 20:29:11.832275 2023-02-20 20:29:11.823 39 ERROR keystone.server.flask.application   File "/var/lib/kolla/venv/lib/python3.9/site-packages/keystone/identity/core.py", line 424, in wrapper
2023-02-20 20:29:11.832284 2023-02-20 20:29:11.823 39 ERROR keystone.server.flask.application     return f(self, *args, **kwargs)
2023-02-20 20:29:11.832293 2023-02-20 20:29:11.823 39 ERROR keystone.server.flask.application   File "/var/lib/kolla/venv/lib/python3.9/site-packages/decorator.py", line 232, in fun
2023-02-20 20:29:11.832303 2023-02-20 20:29:11.823 39 ERROR keystone.server.flask.application     return caller(func, *(extras + args), **kw)
2023-02-20 20:29:11.832313 2023-02-20 20:29:11.823 39 ERROR keystone.server.flask.application   File "/var/lib/kolla/venv/lib/python3.9/site-packages/dogpile/cache/region.py", line 1577, in get_or_create_for_user_func
2023-02-20 20:29:11.832323 2023-02-20 20:29:11.823 39 ERROR keystone.server.flask.application     return self.get_or_create(
2023-02-20 20:29:11.832332 2023-02-20 20:29:11.823 39 ERROR keystone.server.flask.application   File "/var/lib/kolla/venv/lib/python3.9/site-packages/dogpile/cache/region.py", line 1042, in get_or_create
2023-02-20 20:29:11.832342 2023-02-20 20:29:11.823 39 ERROR keystone.server.flask.application     with Lock(
2023-02-20 20:29:11.832351 2023-02-20 20:29:11.823 39 ERROR keystone.server.flask.application   File "/var/lib/kolla/venv/lib/python3.9/site-packages/dogpile/lock.py", line 185, in __enter__
2023-02-20 20:29:11.832361 2023-02-20 20:29:11.823 39 ERROR keystone.server.flask.application     return self._enter()
2023-02-20 20:29:11.832370 2023-02-20 20:29:11.823 39 ERROR keystone.server.flask.application   File "/var/lib/kolla/venv/lib/python3.9/site-packages/dogpile/lock.py", line 94, in _enter
2023-02-20 20:29:11.832379 2023-02-20 20:29:11.823 39 ERROR keystone.server.flask.application     generated = self._enter_create(value, createdtime)
2023-02-20 20:29:11.832389 2023-02-20 20:29:11.823 39 ERROR keystone.server.flask.application   File "/var/lib/kolla/venv/lib/python3.9/site-packages/dogpile/lock.py", line 178, in _enter_create
2023-02-20 20:29:11.832410 2023-02-20 20:29:11.823 39 ERROR keystone.server.flask.application     return self.creator()
2023-02-20 20:29:11.832421 2023-02-20 20:29:11.823 39 ERROR keystone.server.flask.application   File "/var/lib/kolla/venv/lib/python3.9/site-packages/dogpile/cache/region.py", line 995, in gen_value
2023-02-20 20:29:11.832431 2023-02-20 20:29:11.823 39 ERROR keystone.server.flask.application     created_value = creator(
2023-02-20 20:29:11.832440 2023-02-20 20:29:11.823 39 ERROR keystone.server.flask.application   File "/var/lib/kolla/venv/lib/python3.9/site-packages/keystone/identity/core.py", line 1011, in get_user
2023-02-20 20:29:11.832450 2023-02-20 20:29:11.823 39 ERROR keystone.server.flask.application     ref = driver.get_user(entity_id)
2023-02-20 20:29:11.832460 2023-02-20 20:29:11.823 39 ERROR keystone.server.flask.application   File "/var/lib/kolla/venv/lib/python3.9/site-packages/keystone/identity/backends/sql.py", line 200, in get_user
2023-02-20 20:29:11.832470 2023-02-20 20:29:11.823 39 ERROR keystone.server.flask.application     self._get_user(session, user_id).to_dict())
2023-02-20 20:29:11.832479 2023-02-20 20:29:11.823 39 ERROR keystone.server.flask.application   File "/var/lib/kolla/venv/lib/python3.9/site-packages/keystone/identity/backends/sql.py", line 194, in _get_user
2023-02-20 20:29:11.832514 2023-02-20 20:29:11.823 39 ERROR keystone.server.flask.application     raise exception.UserNotFound(user_id=user_id)
2023-02-20 20:29:11.832531 2023-02-20 20:29:11.823 39 ERROR keystone.server.flask.application keystone.exception.UserNotFound: Could not find user: ironic-inspector.
2023-02-20 20:29:11.832540 2023-02-20 20:29:11.823 39 ERROR keystone.server.flask.application \x1b[00m
2023-02-20 20:29:12.670127 2023-02-20 20:29:12.665 38 ERROR keystone.server.flask.application [None req-59731495-b8b7-40ce-a9b4-d0e2cce0df83 7766320271d74dec9e294f2934f5a06f - - all default -] Could not find project: service.: keystone.exception.ProjectNotFound: Could not find project: service.
2023-02-20 20:29:12.670170 2023-02-20 20:29:12.665 38 ERROR keystone.server.flask.application Traceback (most recent call last):
2023-02-20 20:29:12.670182 2023-02-20 20:29:12.665 38 ERROR keystone.server.flask.application   File "/var/lib/kolla/venv/lib/python3.9/site-packages/flask/app.py", line 1820, in full_dispatch_request
2023-02-20 20:29:12.670193 2023-02-20 20:29:12.665 38 ERROR keystone.server.flask.application     rv = self.dispatch_request()
2023-02-20 20:29:12.670203 2023-02-20 20:29:12.665 38 ERROR keystone.server.flask.application   File "/var/lib/kolla/venv/lib/python3.9/site-packages/flask/app.py", line 1796, in dispatch_request
2023-02-20 20:29:12.670214 2023-02-20 20:29:12.665 38 ERROR keystone.server.flask.application     return self.ensure_sync(self.view_functions[rule.endpoint])(**view_args)
2023-02-20 20:29:12.670225 2023-02-20 20:29:12.665 38 ERROR keystone.server.flask.application   File "/var/lib/kolla/venv/lib/python3.9/site-packages/flask_restful/__init__.py", line 467, in wrapper
2023-02-20 20:29:12.670235 2023-02-20 20:29:12.665 38 ERROR keystone.server.flask.application     resp = resource(*args, **kwargs)
2023-02-20 20:29:12.670246 2023-02-20 20:29:12.665 38 ERROR keystone.server.flask.application   File "/var/lib/kolla/venv/lib/python3.9/site-packages/flask/views.py", line 107, in view
2023-02-20 20:29:12.670257 2023-02-20 20:29:12.665 38 ERROR keystone.server.flask.application     return current_app.ensure_sync(self.dispatch_request)(**kwargs)
2023-02-20 20:29:12.670267 2023-02-20 20:29:12.665 38 ERROR keystone.server.flask.application   File "/var/lib/kolla/venv/lib/python3.9/site-packages/flask_restful/__init__.py", line 582, in dispatch_request
2023-02-20 20:29:12.670278 2023-02-20 20:29:12.665 38 ERROR keystone.server.flask.application     resp = meth(*args, **kwargs)
2023-02-20 20:29:12.670288 2023-02-20 20:29:12.665 38 ERROR keystone.server.flask.application   File "/var/lib/kolla/venv/lib/python3.9/site-packages/keystone/api/projects.py", line 151, in get
2023-02-20 20:29:12.670317 2023-02-20 20:29:12.665 38 ERROR keystone.server.flask.application     return self._get_project(project_id)
2023-02-20 20:29:12.670329 2023-02-20 20:29:12.665 38 ERROR keystone.server.flask.application   File "/var/lib/kolla/venv/lib/python3.9/site-packages/keystone/api/projects.py", line 107, in _get_project
2023-02-20 20:29:12.670339 2023-02-20 20:29:12.665 38 ERROR keystone.server.flask.application     project = PROVIDERS.resource_api.get_project(project_id)
2023-02-20 20:29:12.670349 2023-02-20 20:29:12.665 38 ERROR keystone.server.flask.application   File "/var/lib/kolla/venv/lib/python3.9/site-packages/keystone/common/manager.py", line 115, in wrapped
2023-02-20 20:29:12.670360 2023-02-20 20:29:12.665 38 ERROR keystone.server.flask.application     __ret_val = __f(*args, **kwargs)
2023-02-20 20:29:12.670370 2023-02-20 20:29:12.665 38 ERROR keystone.server.flask.application   File "/var/lib/kolla/venv/lib/python3.9/site-packages/decorator.py", line 232, in fun
2023-02-20 20:29:12.670380 2023-02-20 20:29:12.665 38 ERROR keystone.server.flask.application     return caller(func, *(extras + args), **kw)
2023-02-20 20:29:12.670391 2023-02-20 20:29:12.665 38 ERROR keystone.server.flask.application   File "/var/lib/kolla/venv/lib/python3.9/site-packages/dogpile/cache/region.py", line 1577, in get_or_create_for_user_func
2023-02-20 20:29:12.670401 2023-02-20 20:29:12.665 38 ERROR keystone.server.flask.application     return self.get_or_create(
2023-02-20 20:29:12.670411 2023-02-20 20:29:12.665 38 ERROR keystone.server.flask.application   File "/var/lib/kolla/venv/lib/python3.9/site-packages/dogpile/cache/region.py", line 1042, in get_or_create
2023-02-20 20:29:12.670422 2023-02-20 20:29:12.665 38 ERROR keystone.server.flask.application     with Lock(
2023-02-20 20:29:12.670432 2023-02-20 20:29:12.665 38 ERROR keystone.server.flask.application   File "/var/lib/kolla/venv/lib/python3.9/site-packages/dogpile/lock.py", line 185, in __enter__
2023-02-20 20:29:12.670442 2023-02-20 20:29:12.665 38 ERROR keystone.server.flask.application     return self._enter()
2023-02-20 20:29:12.670452 2023-02-20 20:29:12.665 38 ERROR keystone.server.flask.application   File "/var/lib/kolla/venv/lib/python3.9/site-packages/dogpile/lock.py", line 94, in _enter
2023-02-20 20:29:12.670463 2023-02-20 20:29:12.665 38 ERROR keystone.server.flask.application     generated = self._enter_create(value, createdtime)
2023-02-20 20:29:12.670473 2023-02-20 20:29:12.665 38 ERROR keystone.server.flask.application   File "/var/lib/kolla/venv/lib/python3.9/site-packages/dogpile/lock.py", line 178, in _enter_create
2023-02-20 20:29:12.670483 2023-02-20 20:29:12.665 38 ERROR keystone.server.flask.application     return self.creator()
2023-02-20 20:29:12.670513 2023-02-20 20:29:12.665 38 ERROR keystone.server.flask.application   File "/var/lib/kolla/venv/lib/python3.9/site-packages/dogpile/cache/region.py", line 995, in gen_value
2023-02-20 20:29:12.670529 2023-02-20 20:29:12.665 38 ERROR keystone.server.flask.application     created_value = creator(
2023-02-20 20:29:12.670539 2023-02-20 20:29:12.665 38 ERROR keystone.server.flask.application   File "/var/lib/kolla/venv/lib/python3.9/site-packages/keystone/resource/core.py", line 903, in get_project
2023-02-20 20:29:12.670550 2023-02-20 20:29:12.665 38 ERROR keystone.server.flask.application     return self.driver.get_project(project_id)
2023-02-20 20:29:12.670559 2023-02-20 20:29:12.665 38 ERROR keystone.server.flask.application   File "/var/lib/kolla/venv/lib/python3.9/site-packages/keystone/resource/backends/sql.py", line 49, in get_project
2023-02-20 20:29:12.670570 2023-02-20 20:29:12.665 38 ERROR keystone.server.flask.application     return self._get_project(session, project_id).to_dict()
2023-02-20 20:29:12.670579 2023-02-20 20:29:12.665 38 ERROR keystone.server.flask.application   File "/var/lib/kolla/venv/lib/python3.9/site-packages/keystone/resource/backends/sql.py", line 44, in _get_project
2023-02-20 20:29:12.670590 2023-02-20 20:29:12.665 38 ERROR keystone.server.flask.application     raise exception.ProjectNotFound(project_id=project_id)
2023-02-20 20:29:12.670611 2023-02-20 20:29:12.665 38 ERROR keystone.server.flask.application keystone.exception.ProjectNotFound: Could not find project: service.
2023-02-20 20:29:12.670623 2023-02-20 20:29:12.665 38 ERROR keystone.server.flask.application \x1b[00m
2023-02-20 20:32:03.251259 2023-02-20 20:32:03.246 39 ERROR keystone.server.flask.application [None req-80b42d8d-25bf-4a2e-8141-a53f898c6d6b 7766320271d74dec9e294f2934f5a06f - - all default -] Could not find project: service.: keystone.exception.ProjectNotFound: Could not find project: service.
2023-02-20 20:32:03.251306 2023-02-20 20:32:03.246 39 ERROR keystone.server.flask.application Traceback (most recent call last):
2023-02-20 20:32:03.251317 2023-02-20 20:32:03.246 39 ERROR keystone.server.flask.application   File "/var/lib/kolla/venv/lib/python3.9/site-packages/flask/app.py", line 1820, in full_dispatch_request
2023-02-20 20:32:03.251328 2023-02-20 20:32:03.246 39 ERROR keystone.server.flask.application     rv = self.dispatch_request()
2023-02-20 20:32:03.251337 2023-02-20 20:32:03.246 39 ERROR keystone.server.flask.application   File "/var/lib/kolla/venv/lib/python3.9/site-packages/flask/app.py", line 1796, in dispatch_request
2023-02-20 20:32:03.251347 2023-02-20 20:32:03.246 39 ERROR keystone.server.flask.application     return self.ensure_sync(self.view_functions[rule.endpoint])(**view_args)
2023-02-20 20:32:03.251363 2023-02-20 20:32:03.246 39 ERROR keystone.server.flask.application   File "/var/lib/kolla/venv/lib/python3.9/site-packages/flask_restful/__init__.py", line 467, in wrapper
2023-02-20 20:32:03.251375 2023-02-20 20:32:03.246 39 ERROR keystone.server.flask.application     resp = resource(*args, **kwargs)
2023-02-20 20:32:03.251385 2023-02-20 20:32:03.246 39 ERROR keystone.server.flask.application   File "/var/lib/kolla/venv/lib/python3.9/site-packages/flask/views.py", line 107, in view
2023-02-20 20:32:03.251398 2023-02-20 20:32:03.246 39 ERROR keystone.server.flask.application     return current_app.ensure_sync(self.dispatch_request)(**kwargs)
2023-02-20 20:32:03.251408 2023-02-20 20:32:03.246 39 ERROR keystone.server.flask.application   File "/var/lib/kolla/venv/lib/python3.9/site-packages/flask_restful/__init__.py", line 582, in dispatch_request
2023-02-20 20:32:03.251417 2023-02-20 20:32:03.246 39 ERROR keystone.server.flask.application     resp = meth(*args, **kwargs)
2023-02-20 20:32:03.251427 2023-02-20 20:32:03.246 39 ERROR keystone.server.flask.application   File "/var/lib/kolla/venv/lib/python3.9/site-packages/keystone/api/projects.py", line 151, in get
2023-02-20 20:32:03.251437 2023-02-20 20:32:03.246 39 ERROR keystone.server.flask.application     return self._get_project(project_id)
2023-02-20 20:32:03.251446 2023-02-20 20:32:03.246 39 ERROR keystone.server.flask.application   File "/var/lib/kolla/venv/lib/python3.9/site-packages/keystone/api/projects.py", line 107, in _get_project
2023-02-20 20:32:03.251456 2023-02-20 20:32:03.246 39 ERROR keystone.server.flask.application     project = PROVIDERS.resource_api.get_project(project_id)
2023-02-20 20:32:03.251645 2023-02-20 20:32:03.246 39 ERROR keystone.server.flask.application   File "/var/lib/kolla/venv/lib/python3.9/site-packages/keystone/common/manager.py", line 115, in wrapped
2023-02-20 20:32:03.251663 2023-02-20 20:32:03.246 39 ERROR keystone.server.flask.application     __ret_val = __f(*args, **kwargs)
2023-02-20 20:32:03.251673 2023-02-20 20:32:03.246 39 ERROR keystone.server.flask.application   File "/var/lib/kolla/venv/lib/python3.9/site-packages/decorator.py", line 232, in fun
2023-02-20 20:32:03.251683 2023-02-20 20:32:03.246 39 ERROR keystone.server.flask.application     return caller(func, *(extras + args), **kw)
2023-02-20 20:32:03.251693 2023-02-20 20:32:03.246 39 ERROR keystone.server.flask.application   File "/var/lib/kolla/venv/lib/python3.9/site-packages/dogpile/cache/region.py", line 1577, in get_or_create_for_user_func
2023-02-20 20:32:03.251703 2023-02-20 20:32:03.246 39 ERROR keystone.server.flask.application     return self.get_or_create(
2023-02-20 20:32:03.251730 2023-02-20 20:32:03.246 39 ERROR keystone.server.flask.application   File "/var/lib/kolla/venv/lib/python3.9/site-packages/dogpile/cache/region.py", line 1042, in get_or_create
2023-02-20 20:32:03.251742 2023-02-20 20:32:03.246 39 ERROR keystone.server.flask.application     with Lock(
2023-02-20 20:32:03.251928 2023-02-20 20:32:03.246 39 ERROR keystone.server.flask.application   File "/var/lib/kolla/venv/lib/python3.9/site-packages/dogpile/lock.py", line 185, in __enter__
2023-02-20 20:32:03.251940 2023-02-20 20:32:03.246 39 ERROR keystone.server.flask.application     return self._enter()
2023-02-20 20:32:03.251950 2023-02-20 20:32:03.246 39 ERROR keystone.server.flask.application   File "/var/lib/kolla/venv/lib/python3.9/site-packages/dogpile/lock.py", line 94, in _enter
2023-02-20 20:32:03.251960 2023-02-20 20:32:03.246 39 ERROR keystone.server.flask.application     generated = self._enter_create(value, createdtime)
2023-02-20 20:32:03.251969 2023-02-20 20:32:03.246 39 ERROR keystone.server.flask.application   File "/var/lib/kolla/venv/lib/python3.9/site-packages/dogpile/lock.py", line 178, in _enter_create
2023-02-20 20:32:03.251979 2023-02-20 20:32:03.246 39 ERROR keystone.server.flask.application     return self.creator()
2023-02-20 20:32:03.251989 2023-02-20 20:32:03.246 39 ERROR keystone.server.flask.application   File "/var/lib/kolla/venv/lib/python3.9/site-packages/dogpile/cache/region.py", line 995, in gen_value
2023-02-20 20:32:03.251999 2023-02-20 20:32:03.246 39 ERROR keystone.server.flask.application     created_value = creator(
2023-02-20 20:32:03.252008 2023-02-20 20:32:03.246 39 ERROR keystone.server.flask.application   File "/var/lib/kolla/venv/lib/python3.9/site-packages/keystone/resource/core.py", line 903, in get_project
2023-02-20 20:32:03.252018 2023-02-20 20:32:03.246 39 ERROR keystone.server.flask.application     return self.driver.get_project(project_id)
2023-02-20 20:32:03.252028 2023-02-20 20:32:03.246 39 ERROR keystone.server.flask.application   File "/var/lib/kolla/venv/lib/python3.9/site-packages/keystone/resource/backends/sql.py", line 49, in get_project
2023-02-20 20:32:03.252038 2023-02-20 20:32:03.246 39 ERROR keystone.server.flask.application     return self._get_project(session, project_id).to_dict()
2023-02-20 20:32:03.252048 2023-02-20 20:32:03.246 39 ERROR keystone.server.flask.application   File "/var/lib/kolla/venv/lib/python3.9/site-packages/keystone/resource/backends/sql.py", line 44, in _get_project
2023-02-20 20:32:03.252058 2023-02-20 20:32:03.246 39 ERROR keystone.server.flask.application     raise exception.ProjectNotFound(project_id=project_id)
2023-02-20 20:32:03.252067 2023-02-20 20:32:03.246 39 ERROR keystone.server.flask.application keystone.exception.ProjectNotFound: Could not find project: service.
2023-02-20 20:32:03.252126 2023-02-20 20:32:03.246 39 ERROR keystone.server.flask.application \x1b[00m
2023-02-20 20:32:18.129585 2023-02-20 20:32:18.125 38 ERROR keystone.server.flask.application [None req-21bc31de-68c7-4e62-8f67-4fb85b045f9c 7766320271d74dec9e294f2934f5a06f - - all default -] Could not find role: admin.: keystone.exception.RoleNotFound: Could not find role: admin.
2023-02-20 20:32:18.129827 2023-02-20 20:32:18.125 38 ERROR keystone.server.flask.application Traceback (most recent call last):
2023-02-20 20:32:18.129844 2023-02-20 20:32:18.125 38 ERROR keystone.server.flask.application   File "/var/lib/kolla/venv/lib/python3.9/site-packages/flask/app.py", line 1820, in full_dispatch_request
2023-02-20 20:32:18.129855 2023-02-20 20:32:18.125 38 ERROR keystone.server.flask.application     rv = self.dispatch_request()
2023-02-20 20:32:18.129864 2023-02-20 20:32:18.125 38 ERROR keystone.server.flask.application   File "/var/lib/kolla/venv/lib/python3.9/site-packages/flask/app.py", line 1796, in dispatch_request
2023-02-20 20:32:18.129875 2023-02-20 20:32:18.125 38 ERROR keystone.server.flask.application     return self.ensure_sync(self.view_functions[rule.endpoint])(**view_args)
2023-02-20 20:32:18.129885 2023-02-20 20:32:18.125 38 ERROR keystone.server.flask.application   File "/var/lib/kolla/venv/lib/python3.9/site-packages/flask_restful/__init__.py", line 467, in wrapper
2023-02-20 20:32:18.129925 2023-02-20 20:32:18.125 38 ERROR keystone.server.flask.application     resp = resource(*args, **kwargs)
2023-02-20 20:32:18.129937 2023-02-20 20:32:18.125 38 ERROR keystone.server.flask.application   File "/var/lib/kolla/venv/lib/python3.9/site-packages/flask/views.py", line 107, in view
2023-02-20 20:32:18.129947 2023-02-20 20:32:18.125 38 ERROR keystone.server.flask.application     return current_app.ensure_sync(self.dispatch_request)(**kwargs)
2023-02-20 20:32:18.129957 2023-02-20 20:32:18.125 38 ERROR keystone.server.flask.application   File "/var/lib/kolla/venv/lib/python3.9/site-packages/flask_restful/__init__.py", line 582, in dispatch_request
2023-02-20 20:32:18.129967 2023-02-20 20:32:18.125 38 ERROR keystone.server.flask.application     resp = meth(*args, **kwargs)
2023-02-20 20:32:18.129977 2023-02-20 20:32:18.125 38 ERROR keystone.server.flask.application   File "/var/lib/kolla/venv/lib/python3.9/site-packages/keystone/api/roles.py", line 50, in get
2023-02-20 20:32:18.129987 2023-02-20 20:32:18.125 38 ERROR keystone.server.flask.application     return self._get_role(role_id)
2023-02-20 20:32:18.129996 2023-02-20 20:32:18.125 38 ERROR keystone.server.flask.application   File "/var/lib/kolla/venv/lib/python3.9/site-packages/keystone/api/roles.py", line 70, in _get_role
2023-02-20 20:32:18.130006 2023-02-20 20:32:18.125 38 ERROR keystone.server.flask.application     ENFORCER.enforce_call(action='identity:get_role')
2023-02-20 20:32:18.130017 2023-02-20 20:32:18.125 38 ERROR keystone.server.flask.application   File "/var/lib/kolla/venv/lib/python3.9/site-packages/keystone/common/rbac_enforcer/enforcer.py", line 402, in enforce_call
2023-02-20 20:32:18.130027 2023-02-20 20:32:18.125 38 ERROR keystone.server.flask.application     policy_dict.update(cls._extract_member_target_data(
2023-02-20 20:32:18.130037 2023-02-20 20:32:18.125 38 ERROR keystone.server.flask.application   File "/var/lib/kolla/venv/lib/python3.9/site-packages/keystone/common/rbac_enforcer/enforcer.py", line 234, in _extract_member_target_data
2023-02-20 20:32:18.130048 2023-02-20 20:32:18.125 38 ERROR keystone.server.flask.application     member_name: func(flask.request.view_args[key])
2023-02-20 20:32:18.130057 2023-02-20 20:32:18.125 38 ERROR keystone.server.flask.application   File "/var/lib/kolla/venv/lib/python3.9/site-packages/keystone/common/manager.py", line 115, in wrapped
2023-02-20 20:32:18.130067 2023-02-20 20:32:18.125 38 ERROR keystone.server.flask.application     __ret_val = __f(*args, **kwargs)
2023-02-20 20:32:18.130181 2023-02-20 20:32:18.125 38 ERROR keystone.server.flask.application   File "/var/lib/kolla/venv/lib/python3.9/site-packages/decorator.py", line 232, in fun
2023-02-20 20:32:18.130194 2023-02-20 20:32:18.125 38 ERROR keystone.server.flask.application     return caller(func, *(extras + args), **kw)
2023-02-20 20:32:18.130204 2023-02-20 20:32:18.125 38 ERROR keystone.server.flask.application   File "/var/lib/kolla/venv/lib/python3.9/site-packages/dogpile/cache/region.py", line 1577, in get_or_create_for_user_func
2023-02-20 20:32:18.130214 2023-02-20 20:32:18.125 38 ERROR keystone.server.flask.application     return self.get_or_create(
2023-02-20 20:32:18.130223 2023-02-20 20:32:18.125 38 ERROR keystone.server.flask.application   File "/var/lib/kolla/venv/lib/python3.9/site-packages/dogpile/cache/region.py", line 1042, in get_or_create
2023-02-20 20:32:18.130233 2023-02-20 20:32:18.125 38 ERROR keystone.server.flask.application     with Lock(
2023-02-20 20:32:18.130242 2023-02-20 20:32:18.125 38 ERROR keystone.server.flask.application   File "/var/lib/kolla/venv/lib/python3.9/site-packages/dogpile/lock.py", line 185, in __enter__
2023-02-20 20:32:18.130252 2023-02-20 20:32:18.125 38 ERROR keystone.server.flask.application     return self._enter()
2023-02-20 20:32:18.130261 2023-02-20 20:32:18.125 38 ERROR keystone.server.flask.application   File "/var/lib/kolla/venv/lib/python3.9/site-packages/dogpile/lock.py", line 94, in _enter
2023-02-20 20:32:18.130285 2023-02-20 20:32:18.125 38 ERROR keystone.server.flask.application     generated = self._enter_create(value, createdtime)
2023-02-20 20:32:18.130296 2023-02-20 20:32:18.125 38 ERROR keystone.server.flask.application   File "/var/lib/kolla/venv/lib/python3.9/site-packages/dogpile/lock.py", line 178, in _enter_create
2023-02-20 20:32:18.130306 2023-02-20 20:32:18.125 38 ERROR keystone.server.flask.application     return self.creator()
2023-02-20 20:32:18.130315 2023-02-20 20:32:18.125 38 ERROR keystone.server.flask.application   File "/var/lib/kolla/venv/lib/python3.9/site-packages/dogpile/cache/region.py", line 995, in gen_value
2023-02-20 20:32:18.130325 2023-02-20 20:32:18.125 38 ERROR keystone.server.flask.application     created_value = creator(
2023-02-20 20:32:18.130334 2023-02-20 20:32:18.125 38 ERROR keystone.server.flask.application   File "/var/lib/kolla/venv/lib/python3.9/site-packages/keystone/assignment/core.py", line 1276, in get_role
2023-02-20 20:32:18.130344 2023-02-20 20:32:18.125 38 ERROR keystone.server.flask.application     return self.driver.get_role(role_id)
2023-02-20 20:32:18.130353 2023-02-20 20:32:18.125 38 ERROR keystone.server.flask.application   File "/var/lib/kolla/venv/lib/python3.9/site-packages/keystone/assignment/role_backends/sql.py", line 70, in get_role
2023-02-20 20:32:18.130363 2023-02-20 20:32:18.125 38 ERROR keystone.server.flask.application     return self._get_role(session, role_id).to_dict()
2023-02-20 20:32:18.130372 2023-02-20 20:32:18.125 38 ERROR keystone.server.flask.application   File "/var/lib/kolla/venv/lib/python3.9/site-packages/keystone/assignment/role_backends/sql.py", line 65, in _get_role
2023-02-20 20:32:18.130382 2023-02-20 20:32:18.125 38 ERROR keystone.server.flask.application     raise exception.RoleNotFound(role_id=role_id)
2023-02-20 20:32:18.130391 2023-02-20 20:32:18.125 38 ERROR keystone.server.flask.application keystone.exception.RoleNotFound: Could not find role: admin.
2023-02-20 20:32:18.130401 2023-02-20 20:32:18.125 38 ERROR keystone.server.flask.application \x1b[00m
2023-02-20 20:32:19.217623 2023-02-20 20:32:19.214 38 ERROR keystone.server.flask.application [None req-c17cb301-6445-4d05-95b5-c2b9744ae18b 7766320271d74dec9e294f2934f5a06f - - all default -] Could not find user: neutron.: keystone.exception.UserNotFound: Could not find user: neutron.
2023-02-20 20:32:19.217665 2023-02-20 20:32:19.214 38 ERROR keystone.server.flask.application Traceback (most recent call last):
2023-02-20 20:32:19.217676 2023-02-20 20:32:19.214 38 ERROR keystone.server.flask.application   File "/var/lib/kolla/venv/lib/python3.9/site-packages/flask/app.py", line 1820, in full_dispatch_request
2023-02-20 20:32:19.217687 2023-02-20 20:32:19.214 38 ERROR keystone.server.flask.application     rv = self.dispatch_request()
2023-02-20 20:32:19.217696 2023-02-20 20:32:19.214 38 ERROR keystone.server.flask.application   File "/var/lib/kolla/venv/lib/python3.9/site-packages/flask/app.py", line 1796, in dispatch_request
2023-02-20 20:32:19.217708 2023-02-20 20:32:19.214 38 ERROR keystone.server.flask.application     return self.ensure_sync(self.view_functions[rule.endpoint])(**view_args)
2023-02-20 20:32:19.217726 2023-02-20 20:32:19.214 38 ERROR keystone.server.flask.application   File "/var/lib/kolla/venv/lib/python3.9/site-packages/flask_restful/__init__.py", line 467, in wrapper
2023-02-20 20:32:19.217736 2023-02-20 20:32:19.214 38 ERROR keystone.server.flask.application     resp = resource(*args, **kwargs)
2023-02-20 20:32:19.217746 2023-02-20 20:32:19.214 38 ERROR keystone.server.flask.application   File "/var/lib/kolla/venv/lib/python3.9/site-packages/flask/views.py", line 107, in view
2023-02-20 20:32:19.217756 2023-02-20 20:32:19.214 38 ERROR keystone.server.flask.application     return current_app.ensure_sync(self.dispatch_request)(**kwargs)
2023-02-20 20:32:19.217766 2023-02-20 20:32:19.214 38 ERROR keystone.server.flask.application   File "/var/lib/kolla/venv/lib/python3.9/site-packages/flask_restful/__init__.py", line 582, in dispatch_request
2023-02-20 20:32:19.217808 2023-02-20 20:32:19.214 38 ERROR keystone.server.flask.application     resp = meth(*args, **kwargs)
2023-02-20 20:32:19.217821 2023-02-20 20:32:19.214 38 ERROR keystone.server.flask.application   File "/var/lib/kolla/venv/lib/python3.9/site-packages/keystone/api/users.py", line 182, in get
2023-02-20 20:32:19.217831 2023-02-20 20:32:19.214 38 ERROR keystone.server.flask.application     return self._get_user(user_id)
2023-02-20 20:32:19.217854 2023-02-20 20:32:19.214 38 ERROR keystone.server.flask.application   File "/var/lib/kolla/venv/lib/python3.9/site-packages/keystone/api/users.py", line 194, in _get_user
2023-02-20 20:32:19.217863 2023-02-20 20:32:19.214 38 ERROR keystone.server.flask.application     ref = PROVIDERS.identity_api.get_user(user_id)
2023-02-20 20:32:19.217873 2023-02-20 20:32:19.214 38 ERROR keystone.server.flask.application   File "/var/lib/kolla/venv/lib/python3.9/site-packages/keystone/common/manager.py", line 115, in wrapped
2023-02-20 20:32:19.217882 2023-02-20 20:32:19.214 38 ERROR keystone.server.flask.application     __ret_val = __f(*args, **kwargs)
2023-02-20 20:32:19.217891 2023-02-20 20:32:19.214 38 ERROR keystone.server.flask.application   File "/var/lib/kolla/venv/lib/python3.9/site-packages/keystone/identity/core.py", line 414, in wrapper
2023-02-20 20:32:19.217901 2023-02-20 20:32:19.214 38 ERROR keystone.server.flask.application     return f(self, *args, **kwargs)
2023-02-20 20:32:19.217910 2023-02-20 20:32:19.214 38 ERROR keystone.server.flask.application   File "/var/lib/kolla/venv/lib/python3.9/site-packages/keystone/identity/core.py", line 424, in wrapper
2023-02-20 20:32:19.217920 2023-02-20 20:32:19.214 38 ERROR keystone.server.flask.application     return f(self, *args, **kwargs)
2023-02-20 20:32:19.217929 2023-02-20 20:32:19.214 38 ERROR keystone.server.flask.application   File "/var/lib/kolla/venv/lib/python3.9/site-packages/decorator.py", line 232, in fun
2023-02-20 20:32:19.217939 2023-02-20 20:32:19.214 38 ERROR keystone.server.flask.application     return caller(func, *(extras + args), **kw)
2023-02-20 20:32:19.217948 2023-02-20 20:32:19.214 38 ERROR keystone.server.flask.application   File "/var/lib/kolla/venv/lib/python3.9/site-packages/dogpile/cache/region.py", line 1577, in get_or_create_for_user_func
2023-02-20 20:32:19.217958 2023-02-20 20:32:19.214 38 ERROR keystone.server.flask.application     return self.get_or_create(
2023-02-20 20:32:19.217967 2023-02-20 20:32:19.214 38 ERROR keystone.server.flask.application   File "/var/lib/kolla/venv/lib/python3.9/site-packages/dogpile/cache/region.py", line 1042, in get_or_create
2023-02-20 20:32:19.217977 2023-02-20 20:32:19.214 38 ERROR keystone.server.flask.application     with Lock(
2023-02-20 20:32:19.217986 2023-02-20 20:32:19.214 38 ERROR keystone.server.flask.application   File "/var/lib/kolla/venv/lib/python3.9/site-packages/dogpile/lock.py", line 185, in __enter__
2023-02-20 20:32:19.217996 2023-02-20 20:32:19.214 38 ERROR keystone.server.flask.application     return self._enter()
2023-02-20 20:32:19.218005 2023-02-20 20:32:19.214 38 ERROR keystone.server.flask.application   File "/var/lib/kolla/venv/lib/python3.9/site-packages/dogpile/lock.py", line 94, in _enter
2023-02-20 20:32:19.218015 2023-02-20 20:32:19.214 38 ERROR keystone.server.flask.application     generated = self._enter_create(value, createdtime)
2023-02-20 20:32:19.218024 2023-02-20 20:32:19.214 38 ERROR keystone.server.flask.application   File "/var/lib/kolla/venv/lib/python3.9/site-packages/dogpile/lock.py", line 178, in _enter_create
2023-02-20 20:32:19.218034 2023-02-20 20:32:19.214 38 ERROR keystone.server.flask.application     return self.creator()
2023-02-20 20:32:19.218043 2023-02-20 20:32:19.214 38 ERROR keystone.server.flask.application   File "/var/lib/kolla/venv/lib/python3.9/site-packages/dogpile/cache/region.py", line 995, in gen_value
2023-02-20 20:32:19.218053 2023-02-20 20:32:19.214 38 ERROR keystone.server.flask.application     created_value = creator(
2023-02-20 20:32:19.218112 2023-02-20 20:32:19.214 38 ERROR keystone.server.flask.application   File "/var/lib/kolla/venv/lib/python3.9/site-packages/keystone/identity/core.py", line 1011, in get_user
2023-02-20 20:32:19.218128 2023-02-20 20:32:19.214 38 ERROR keystone.server.flask.application     ref = driver.get_user(entity_id)
2023-02-20 20:32:19.218137 2023-02-20 20:32:19.214 38 ERROR keystone.server.flask.application   File "/var/lib/kolla/venv/lib/python3.9/site-packages/keystone/identity/backends/sql.py", line 200, in get_user
2023-02-20 20:32:19.218147 2023-02-20 20:32:19.214 38 ERROR keystone.server.flask.application     self._get_user(session, user_id).to_dict())
2023-02-20 20:32:19.218163 2023-02-20 20:32:19.214 38 ERROR keystone.server.flask.application   File "/var/lib/kolla/venv/lib/python3.9/site-packages/keystone/identity/backends/sql.py", line 194, in _get_user
2023-02-20 20:32:19.218172 2023-02-20 20:32:19.214 38 ERROR keystone.server.flask.application     raise exception.UserNotFound(user_id=user_id)
2023-02-20 20:32:19.218182 2023-02-20 20:32:19.214 38 ERROR keystone.server.flask.application keystone.exception.UserNotFound: Could not find user: neutron.
2023-02-20 20:32:19.218191 2023-02-20 20:32:19.214 38 ERROR keystone.server.flask.application \x1b[00m
2023-02-20 20:32:20.144146 2023-02-20 20:32:20.139 37 ERROR keystone.server.flask.application [None req-67e09e1d-7ccd-4919-b785-f1629dc01ef5 7766320271d74dec9e294f2934f5a06f - - all default -] Could not find project: service.: keystone.exception.ProjectNotFound: Could not find project: service.
2023-02-20 20:32:20.144203 2023-02-20 20:32:20.139 37 ERROR keystone.server.flask.application Traceback (most recent call last):
2023-02-20 20:32:20.144222 2023-02-20 20:32:20.139 37 ERROR keystone.server.flask.application   File "/var/lib/kolla/venv/lib/python3.9/site-packages/flask/app.py", line 1820, in full_dispatch_request
2023-02-20 20:32:20.144240 2023-02-20 20:32:20.139 37 ERROR keystone.server.flask.application     rv = self.dispatch_request()
2023-02-20 20:32:20.144262 2023-02-20 20:32:20.139 37 ERROR keystone.server.flask.application   File "/var/lib/kolla/venv/lib/python3.9/site-packages/flask/app.py", line 1796, in dispatch_request
2023-02-20 20:32:20.144279 2023-02-20 20:32:20.139 37 ERROR keystone.server.flask.application     return self.ensure_sync(self.view_functions[rule.endpoint])(**view_args)
2023-02-20 20:32:20.144294 2023-02-20 20:32:20.139 37 ERROR keystone.server.flask.application   File "/var/lib/kolla/venv/lib/python3.9/site-packages/flask_restful/__init__.py", line 467, in wrapper
2023-02-20 20:32:20.144315 2023-02-20 20:32:20.139 37 ERROR keystone.server.flask.application     resp = resource(*args, **kwargs)
2023-02-20 20:32:20.144335 2023-02-20 20:32:20.139 37 ERROR keystone.server.flask.application   File "/var/lib/kolla/venv/lib/python3.9/site-packages/flask/views.py", line 107, in view
2023-02-20 20:32:20.144347 2023-02-20 20:32:20.139 37 ERROR keystone.server.flask.application     return current_app.ensure_sync(self.dispatch_request)(**kwargs)
2023-02-20 20:32:20.144363 2023-02-20 20:32:20.139 37 ERROR keystone.server.flask.application   File "/var/lib/kolla/venv/lib/python3.9/site-packages/flask_restful/__init__.py", line 582, in dispatch_request
2023-02-20 20:32:20.144404 2023-02-20 20:32:20.139 37 ERROR keystone.server.flask.application     resp = meth(*args, **kwargs)
2023-02-20 20:32:20.144421 2023-02-20 20:32:20.139 37 ERROR keystone.server.flask.application   File "/var/lib/kolla/venv/lib/python3.9/site-packages/keystone/api/projects.py", line 151, in get
2023-02-20 20:32:20.144436 2023-02-20 20:32:20.139 37 ERROR keystone.server.flask.application     return self._get_project(project_id)
2023-02-20 20:32:20.144469 2023-02-20 20:32:20.139 37 ERROR keystone.server.flask.application   File "/var/lib/kolla/venv/lib/python3.9/site-packages/keystone/api/projects.py", line 107, in _get_project
2023-02-20 20:32:20.144512 2023-02-20 20:32:20.139 37 ERROR keystone.server.flask.application     project = PROVIDERS.resource_api.get_project(project_id)
2023-02-20 20:32:20.144562 2023-02-20 20:32:20.139 37 ERROR keystone.server.flask.application   File "/var/lib/kolla/venv/lib/python3.9/site-packages/keystone/common/manager.py", line 115, in wrapped
2023-02-20 20:32:20.144587 2023-02-20 20:32:20.139 37 ERROR keystone.server.flask.application     __ret_val = __f(*args, **kwargs)
2023-02-20 20:32:20.144604 2023-02-20 20:32:20.139 37 ERROR keystone.server.flask.application   File "/var/lib/kolla/venv/lib/python3.9/site-packages/decorator.py", line 232, in fun
2023-02-20 20:32:20.144620 2023-02-20 20:32:20.139 37 ERROR keystone.server.flask.application     return caller(func, *(extras + args), **kw)
2023-02-20 20:32:20.144641 2023-02-20 20:32:20.139 37 ERROR keystone.server.flask.application   File "/var/lib/kolla/venv/lib/python3.9/site-packages/dogpile/cache/region.py", line 1577, in get_or_create_for_user_func
2023-02-20 20:32:20.144660 2023-02-20 20:32:20.139 37 ERROR keystone.server.flask.application     return self.get_or_create(
2023-02-20 20:32:20.144678 2023-02-20 20:32:20.139 37 ERROR keystone.server.flask.application   File "/var/lib/kolla/venv/lib/python3.9/site-packages/dogpile/cache/region.py", line 1042, in get_or_create
2023-02-20 20:32:20.144700 2023-02-20 20:32:20.139 37 ERROR keystone.server.flask.application     with Lock(
2023-02-20 20:32:20.144722 2023-02-20 20:32:20.139 37 ERROR keystone.server.flask.application   File "/var/lib/kolla/venv/lib/python3.9/site-packages/dogpile/lock.py", line 185, in __enter__
2023-02-20 20:32:20.144746 2023-02-20 20:32:20.139 37 ERROR keystone.server.flask.application     return self._enter()
2023-02-20 20:32:20.144766 2023-02-20 20:32:20.139 37 ERROR keystone.server.flask.application   File "/var/lib/kolla/venv/lib/python3.9/site-packages/dogpile/lock.py", line 94, in _enter
2023-02-20 20:32:20.144782 2023-02-20 20:32:20.139 37 ERROR keystone.server.flask.application     generated = self._enter_create(value, createdtime)
2023-02-20 20:32:20.144802 2023-02-20 20:32:20.139 37 ERROR keystone.server.flask.application   File "/var/lib/kolla/venv/lib/python3.9/site-packages/dogpile/lock.py", line 178, in _enter_create
2023-02-20 20:32:20.144823 2023-02-20 20:32:20.139 37 ERROR keystone.server.flask.application     return self.creator()
2023-02-20 20:32:20.144836 2023-02-20 20:32:20.139 37 ERROR keystone.server.flask.application   File "/var/lib/kolla/venv/lib/python3.9/site-packages/dogpile/cache/region.py", line 995, in gen_value
2023-02-20 20:32:20.144851 2023-02-20 20:32:20.139 37 ERROR keystone.server.flask.application     created_value = creator(
2023-02-20 20:32:20.144872 2023-02-20 20:32:20.139 37 ERROR keystone.server.flask.application   File "/var/lib/kolla/venv/lib/python3.9/site-packages/keystone/resource/core.py", line 903, in get_project
2023-02-20 20:32:20.144891 2023-02-20 20:32:20.139 37 ERROR keystone.server.flask.application     return self.driver.get_project(project_id)
2023-02-20 20:32:20.144903 2023-02-20 20:32:20.139 37 ERROR keystone.server.flask.application   File "/var/lib/kolla/venv/lib/python3.9/site-packages/keystone/resource/backends/sql.py", line 49, in get_project
2023-02-20 20:32:20.144922 2023-02-20 20:32:20.139 37 ERROR keystone.server.flask.application     return self._get_project(session, project_id).to_dict()
2023-02-20 20:32:20.144943 2023-02-20 20:32:20.139 37 ERROR keystone.server.flask.application   File "/var/lib/kolla/venv/lib/python3.9/site-packages/keystone/resource/backends/sql.py", line 44, in _get_project
2023-02-20 20:32:20.144958 2023-02-20 20:32:20.139 37 ERROR keystone.server.flask.application     raise exception.ProjectNotFound(project_id=project_id)
2023-02-20 20:32:20.144973 2023-02-20 20:32:20.139 37 ERROR keystone.server.flask.application keystone.exception.ProjectNotFound: Could not find project: service.
2023-02-20 20:32:20.144994 2023-02-20 20:32:20.139 37 ERROR keystone.server.flask.application \x1b[00m
2023-02-20 21:09:21.780418 2023-02-20 21:09:21.779 39 WARNING py.warnings [None req-93505b8b-cada-40fa-ba01-d6b67f5b0900 7766320271d74dec9e294f2934f5a06f f48eaa2e75294c9f9060fcf62682d673 - - default default] /var/lib/kolla/venv/lib/python3.9/site-packages/oslo_policy/policy.py:1129: UserWarning: Policy "identity:list_domains": "role:reader and system_scope:all" failed scope check. The token used to make the request was project scoped but the policy requires ['system'] scope. This behavior may change in the future where using the intended scope is required
2023-02-20 21:09:21.780522   warnings.warn(msg)
2023-02-20 21:09:21.780535 \x1b[00m
2023-02-20 21:09:22.010826 2023-02-20 21:09:22.009 37 WARNING py.warnings [None req-0dc76459-b068-4db6-b8bc-49c2e06d3057 7766320271d74dec9e294f2934f5a06f f48eaa2e75294c9f9060fcf62682d673 - - default default] /var/lib/kolla/venv/lib/python3.9/site-packages/oslo_policy/policy.py:1129: UserWarning: Policy "identity:create_project": "(role:admin and system_scope:all) or (role:admin and domain_id:%(target.project.domain_id)s)" failed scope check. The token used to make the request was project scoped but the policy requires ['system', 'domain'] scope. This behavior may change in the future where using the intended scope is required
2023-02-20 21:09:22.010868   warnings.warn(msg)
2023-02-20 21:09:22.010879 \x1b[00m
2023-02-20 21:09:22.448535 2023-02-20 21:09:22.447 38 WARNING py.warnings [None req-b727fe9a-fc3e-4385-8749-7bcb6fd6c595 7766320271d74dec9e294f2934f5a06f f48eaa2e75294c9f9060fcf62682d673 - - default default] /var/lib/kolla/venv/lib/python3.9/site-packages/oslo_policy/policy.py:1129: UserWarning: Policy "identity:create_user": "(role:admin and system_scope:all) or (role:admin and token.domain.id:%(target.user.domain_id)s)" failed scope check. The token used to make the request was project scoped but the policy requires ['system', 'domain'] scope. This behavior may change in the future where using the intended scope is required
2023-02-20 21:09:22.448576   warnings.warn(msg)
2023-02-20 21:09:22.448586 \x1b[00m
2023-02-20 21:09:23.354302 2023-02-20 21:09:23.353 37 WARNING py.warnings [None req-2ff8ed02-d315-40e8-9504-215072ae6bb3 7766320271d74dec9e294f2934f5a06f f48eaa2e75294c9f9060fcf62682d673 - - default default] /var/lib/kolla/venv/lib/python3.9/site-packages/oslo_policy/policy.py:1129: UserWarning: Policy "identity:list_roles": "role:reader and system_scope:all" failed scope check. The token used to make the request was project scoped but the policy requires ['system'] scope. This behavior may change in the future where using the intended scope is required
2023-02-20 21:09:23.354342   warnings.warn(msg)
2023-02-20 21:09:23.354352 \x1b[00m
2023-02-20 21:09:23.722803 2023-02-20 21:09:23.721 39 WARNING py.warnings [None req-9e1ac841-4e9c-4bca-ae2d-a25b2c287fbf 7766320271d74dec9e294f2934f5a06f f48eaa2e75294c9f9060fcf62682d673 - - default default] /var/lib/kolla/venv/lib/python3.9/site-packages/oslo_policy/policy.py:1129: UserWarning: Policy "identity:list_roles": "role:reader and system_scope:all" failed scope check. The token used to make the request was project scoped but the policy requires ['system'] scope. This behavior may change in the future where using the intended scope is required
2023-02-20 21:09:23.722846   warnings.warn(msg)
2023-02-20 21:09:23.722856 \x1b[00m
2023-02-20 21:09:24.079583 2023-02-20 21:09:24.078 38 WARNING py.warnings [None req-42ec5178-aa3f-4682-a41b-608c7e1fbf5a 7766320271d74dec9e294f2934f5a06f f48eaa2e75294c9f9060fcf62682d673 - - default default] /var/lib/kolla/venv/lib/python3.9/site-packages/oslo_policy/policy.py:1129: UserWarning: Policy "identity:create_grant": "(role:admin and system_scope:all) or ((role:admin and domain_id:%(target.user.domain_id)s and domain_id:%(target.project.domain_id)s) or (role:admin and domain_id:%(target.user.domain_id)s and domain_id:%(target.domain.id)s) or (role:admin and domain_id:%(target.group.domain_id)s and domain_id:%(target.project.domain_id)s) or (role:admin and domain_id:%(target.group.domain_id)s and domain_id:%(target.domain.id)s)) and (domain_id:%(target.role.domain_id)s or None:%(target.role.domain_id)s)" failed scope check. The token used to make the request was project scoped but the policy requires ['system', 'domain'] scope. This behavior may change in the future where using the intended scope is required
2023-02-20 21:09:24.079699   warnings.warn(msg)
2023-02-20 21:09:24.079721 \x1b[00m
2023-02-20 21:09:25.243146 2023-02-20 21:09:25.239 39 WARNING py.warnings [None req-e2e1eb02-bb71-4ff3-9bcd-8fa95ae7df93 7766320271d74dec9e294f2934f5a06f f48eaa2e75294c9f9060fcf62682d673 - - default default] /var/lib/kolla/venv/lib/python3.9/site-packages/oslo_policy/policy.py:1129: UserWarning: Policy "identity:create_project": "(role:admin and system_scope:all) or (role:admin and domain_id:%(target.project.domain_id)s)" failed scope check. The token used to make the request was project scoped but the policy requires ['system', 'domain'] scope. This behavior may change in the future where using the intended scope is required
2023-02-20 21:09:25.243257   warnings.warn(msg)
2023-02-20 21:09:25.243282 \x1b[00m
2023-02-20 21:09:26.927966 2023-02-20 21:09:26.927 39 WARNING py.warnings [None req-8172d149-2d81-428d-87f2-bb9401a2eb9a 7766320271d74dec9e294f2934f5a06f f48eaa2e75294c9f9060fcf62682d673 - - default default] /var/lib/kolla/venv/lib/python3.9/site-packages/oslo_policy/policy.py:1129: UserWarning: Policy "identity:create_grant": "(role:admin and system_scope:all) or ((role:admin and domain_id:%(target.user.domain_id)s and domain_id:%(target.project.domain_id)s) or (role:admin and domain_id:%(target.user.domain_id)s and domain_id:%(target.domain.id)s) or (role:admin and domain_id:%(target.group.domain_id)s and domain_id:%(target.project.domain_id)s) or (role:admin and domain_id:%(target.group.domain_id)s and domain_id:%(target.domain.id)s)) and (domain_id:%(target.role.domain_id)s or None:%(target.role.domain_id)s)" failed scope check. The token used to make the request was project scoped but the policy requires ['system', 'domain'] scope. This behavior may change in the future where using the intended scope is required
2023-02-20 21:09:26.928045   warnings.warn(msg)
2023-02-20 21:09:26.928056 \x1b[00m
2023-02-20 21:09:27.234046 2023-02-20 21:09:27.232 38 WARNING py.warnings [None req-b88f59f9-6d13-4170-95d8-30648ed3977d 7766320271d74dec9e294f2934f5a06f f48eaa2e75294c9f9060fcf62682d673 - - default default] /var/lib/kolla/venv/lib/python3.9/site-packages/oslo_policy/policy.py:1129: UserWarning: Policy "identity:list_roles": "role:reader and system_scope:all" failed scope check. The token used to make the request was project scoped but the policy requires ['system'] scope. This behavior may change in the future where using the intended scope is required
2023-02-20 21:09:27.234138   warnings.warn(msg)
2023-02-20 21:09:27.234150 \x1b[00m
2023-02-20 21:09:27.573410 2023-02-20 21:09:27.572 37 WARNING py.warnings [None req-5daf2e8d-b1e7-4ba6-b511-c2c4150a9265 7766320271d74dec9e294f2934f5a06f f48eaa2e75294c9f9060fcf62682d673 - - default default] /var/lib/kolla/venv/lib/python3.9/site-packages/oslo_policy/policy.py:1129: UserWarning: Policy "identity:create_grant": "(role:admin and system_scope:all) or ((role:admin and domain_id:%(target.user.domain_id)s and domain_id:%(target.project.domain_id)s) or (role:admin and domain_id:%(target.user.domain_id)s and domain_id:%(target.domain.id)s) or (role:admin and domain_id:%(target.group.domain_id)s and domain_id:%(target.project.domain_id)s) or (role:admin and domain_id:%(target.group.domain_id)s and domain_id:%(target.domain.id)s)) and (domain_id:%(target.role.domain_id)s or None:%(target.role.domain_id)s)" failed scope check. The token used to make the request was project scoped but the policy requires ['system', 'domain'] scope. This behavior may change in the future where using the intended scope is required
2023-02-20 21:09:27.573457   warnings.warn(msg)
2023-02-20 21:09:27.573466 \x1b[00m
2023-02-20 21:09:29.791398 2023-02-20 21:09:29.790 39 WARNING py.warnings [None req-e347b328-5906-4ca5-b9b8-6b81aefa6211 7766320271d74dec9e294f2934f5a06f f48eaa2e75294c9f9060fcf62682d673 - - default default] /var/lib/kolla/venv/lib/python3.9/site-packages/oslo_policy/policy.py:1129: UserWarning: Policy "identity:create_system_grant_for_user": "role:admin and system_scope:all" failed scope check. The token used to make the request was project scoped but the policy requires ['system'] scope. This behavior may change in the future where using the intended scope is required
2023-02-20 21:09:29.791500   warnings.warn(msg)
2023-02-20 21:09:29.791513 \x1b[00m
