2023-02-16 10:44:46.552 23 INFO alembic.runtime.migration [-] Context impl MySQLImpl.
2023-02-16 10:44:46.554 23 INFO alembic.runtime.migration [-] Will assume non-transactional DDL.
2023-02-16 10:44:46.593 23 INFO alembic.runtime.migration [-] Context impl MySQLImpl.
2023-02-16 10:44:46.594 23 INFO alembic.runtime.migration [-] Will assume non-transactional DDL.
2023-02-16 10:44:46.642 23 INFO alembic.runtime.migration [-] Running upgrade  -> 27e647c0fad4, Initial version.
2023-02-16 10:44:47.847 23 INFO alembic.runtime.migration [-] Running upgrade 27e647c0fad4 -> e25ffa003242, Initial no-op Yoga contract migration.
2023-02-16 10:44:47.853 23 INFO alembic.runtime.migration [-] Running upgrade 27e647c0fad4 -> 29e87d24a316, Initial no-op Yoga expand migration.
2023-02-16 10:44:56.706 8 INFO keystone.common.fernet_utils [-] Created a new temporary key: /etc/keystone/fernet-keys/0.tmp
2023-02-16 10:44:56.710 8 INFO keystone.common.fernet_utils [-] Become a valid new key: /etc/keystone/fernet-keys/0
2023-02-16 10:44:56.711 8 INFO keystone.common.fernet_utils [-] Starting key rotation with 1 key files: ['/etc/keystone/fernet-keys/0']
2023-02-16 10:44:56.712 8 INFO keystone.common.fernet_utils [-] Created a new temporary key: /etc/keystone/fernet-keys/0.tmp
2023-02-16 10:44:56.712 8 INFO keystone.common.fernet_utils [-] Current primary key is: 0
2023-02-16 10:44:56.714 8 INFO keystone.common.fernet_utils [-] Next primary key will be: 1
2023-02-16 10:44:56.714 8 INFO keystone.common.fernet_utils [-] Promoted key 0 to be the primary: 1
2023-02-16 10:44:56.715 8 INFO keystone.common.fernet_utils [-] Become a valid new key: /etc/keystone/fernet-keys/0
2023-02-16 10:45:14.882 32 INFO keystone.cmd.bootstrap [None req-834edf74-6c16-45e8-98d7-5cda9a7e8fee - - - - - -] Created domain default
2023-02-16 10:45:14.953 32 INFO keystone.cmd.bootstrap [None req-834edf74-6c16-45e8-98d7-5cda9a7e8fee - - - - - -] Created project admin
2023-02-16 10:45:15.564 32 INFO keystone.cmd.bootstrap [None req-834edf74-6c16-45e8-98d7-5cda9a7e8fee - - - - - -] Created user admin
2023-02-16 10:45:15.586 32 INFO keystone.cmd.bootstrap [None req-834edf74-6c16-45e8-98d7-5cda9a7e8fee - - - - - -] Created role reader
2023-02-16 10:45:15.602 32 INFO keystone.cmd.bootstrap [None req-834edf74-6c16-45e8-98d7-5cda9a7e8fee - - - - - -] Created role member
2023-02-16 10:45:15.635 32 INFO keystone.cmd.bootstrap [None req-834edf74-6c16-45e8-98d7-5cda9a7e8fee - - - - - -] Created implied role where ea370ecddecc45ce8d8f034c9fc85aef implies 4a81df6907024aabb4f73f2077414587
2023-02-16 10:45:15.650 32 INFO keystone.cmd.bootstrap [None req-834edf74-6c16-45e8-98d7-5cda9a7e8fee - - - - - -] Created role admin
2023-02-16 10:45:15.675 32 INFO keystone.cmd.bootstrap [None req-834edf74-6c16-45e8-98d7-5cda9a7e8fee - - - - - -] Created implied role where 9f7bb1c4a16d443e874d6d8d5f50f0bd implies ea370ecddecc45ce8d8f034c9fc85aef
2023-02-16 10:45:15.693 32 INFO keystone.cmd.bootstrap [None req-834edf74-6c16-45e8-98d7-5cda9a7e8fee - - - - - -] Granted role admin on project admin to user admin.
2023-02-16 10:45:15.705 32 INFO keystone.cmd.bootstrap [None req-834edf74-6c16-45e8-98d7-5cda9a7e8fee - - - - - -] Granted role admin on the system to user admin.
2023-02-16 10:45:15.725 32 WARNING py.warnings [None req-834edf74-6c16-45e8-98d7-5cda9a7e8fee - - - - - -] /var/lib/kolla/venv/lib/python3.9/site-packages/pycadf/identifier.py:71: UserWarning: Invalid uuid: RegionOne. To ensure interoperability, identifiers should be a valid uuid.
  warnings.warn(('Invalid uuid: %s. To ensure interoperability, '

2023-02-16 10:45:15.732 32 INFO keystone.cmd.bootstrap [None req-834edf74-6c16-45e8-98d7-5cda9a7e8fee - - - - - -] Created region RegionOne
2023-02-16 10:45:15.785 32 INFO keystone.cmd.bootstrap [None req-834edf74-6c16-45e8-98d7-5cda9a7e8fee - - - - - -] Created public endpoint http://169.16.1.151:5000
2023-02-16 10:45:15.799 32 INFO keystone.cmd.bootstrap [None req-834edf74-6c16-45e8-98d7-5cda9a7e8fee - - - - - -] Created internal endpoint http://169.16.1.151:5000
2023-02-16 10:45:40.839 39 WARNING keystone.common.rbac_enforcer.enforcer [None req-f247cb11-0b0f-4e06-8c44-33118b09ceda fb315d92609f4472883a5f0de5502027 - - all default -] Deprecated policy rules found. Use oslopolicy-policy-generator and oslopolicy-policy-upgrade to detect and resolve deprecated policies in your configuration.
2023-02-16 10:45:41.575 38 WARNING keystone.common.rbac_enforcer.enforcer [None req-e581f6df-f1f8-4e5f-9575-b9e1b9991105 fb315d92609f4472883a5f0de5502027 - - all default -] Deprecated policy rules found. Use oslopolicy-policy-generator and oslopolicy-policy-upgrade to detect and resolve deprecated policies in your configuration.
2023-02-16 10:45:48.924 37 WARNING keystone.common.rbac_enforcer.enforcer [None req-1bb69f93-8755-4c34-a184-800ce61c346f fb315d92609f4472883a5f0de5502027 - - all default -] Deprecated policy rules found. Use oslopolicy-policy-generator and oslopolicy-policy-upgrade to detect and resolve deprecated policies in your configuration.
2023-02-16 10:47:07.992 39 ERROR keystone.server.flask.application [None req-450a5705-6b60-4866-ad2b-cd52bd0a706c fb315d92609f4472883a5f0de5502027 - - all default -] Could not find project: service.: keystone.exception.ProjectNotFound: Could not find project: service.
2023-02-16 10:47:07.992 39 ERROR keystone.server.flask.application Traceback (most recent call last):
2023-02-16 10:47:07.992 39 ERROR keystone.server.flask.application   File "/var/lib/kolla/venv/lib/python3.9/site-packages/flask/app.py", line 1820, in full_dispatch_request
2023-02-16 10:47:07.992 39 ERROR keystone.server.flask.application     rv = self.dispatch_request()
2023-02-16 10:47:07.992 39 ERROR keystone.server.flask.application   File "/var/lib/kolla/venv/lib/python3.9/site-packages/flask/app.py", line 1796, in dispatch_request
2023-02-16 10:47:07.992 39 ERROR keystone.server.flask.application     return self.ensure_sync(self.view_functions[rule.endpoint])(**view_args)
2023-02-16 10:47:07.992 39 ERROR keystone.server.flask.application   File "/var/lib/kolla/venv/lib/python3.9/site-packages/flask_restful/__init__.py", line 467, in wrapper
2023-02-16 10:47:07.992 39 ERROR keystone.server.flask.application     resp = resource(*args, **kwargs)
2023-02-16 10:47:07.992 39 ERROR keystone.server.flask.application   File "/var/lib/kolla/venv/lib/python3.9/site-packages/flask/views.py", line 107, in view
2023-02-16 10:47:07.992 39 ERROR keystone.server.flask.application     return current_app.ensure_sync(self.dispatch_request)(**kwargs)
2023-02-16 10:47:07.992 39 ERROR keystone.server.flask.application   File "/var/lib/kolla/venv/lib/python3.9/site-packages/flask_restful/__init__.py", line 582, in dispatch_request
2023-02-16 10:47:07.992 39 ERROR keystone.server.flask.application     resp = meth(*args, **kwargs)
2023-02-16 10:47:07.992 39 ERROR keystone.server.flask.application   File "/var/lib/kolla/venv/lib/python3.9/site-packages/keystone/api/projects.py", line 151, in get
2023-02-16 10:47:07.992 39 ERROR keystone.server.flask.application     return self._get_project(project_id)
2023-02-16 10:47:07.992 39 ERROR keystone.server.flask.application   File "/var/lib/kolla/venv/lib/python3.9/site-packages/keystone/api/projects.py", line 107, in _get_project
2023-02-16 10:47:07.992 39 ERROR keystone.server.flask.application     project = PROVIDERS.resource_api.get_project(project_id)
2023-02-16 10:47:07.992 39 ERROR keystone.server.flask.application   File "/var/lib/kolla/venv/lib/python3.9/site-packages/keystone/common/manager.py", line 115, in wrapped
2023-02-16 10:47:07.992 39 ERROR keystone.server.flask.application     __ret_val = __f(*args, **kwargs)
2023-02-16 10:47:07.992 39 ERROR keystone.server.flask.application   File "/var/lib/kolla/venv/lib/python3.9/site-packages/decorator.py", line 232, in fun
2023-02-16 10:47:07.992 39 ERROR keystone.server.flask.application     return caller(func, *(extras + args), **kw)
2023-02-16 10:47:07.992 39 ERROR keystone.server.flask.application   File "/var/lib/kolla/venv/lib/python3.9/site-packages/dogpile/cache/region.py", line 1577, in get_or_create_for_user_func
2023-02-16 10:47:07.992 39 ERROR keystone.server.flask.application     return self.get_or_create(
2023-02-16 10:47:07.992 39 ERROR keystone.server.flask.application   File "/var/lib/kolla/venv/lib/python3.9/site-packages/dogpile/cache/region.py", line 1042, in get_or_create
2023-02-16 10:47:07.992 39 ERROR keystone.server.flask.application     with Lock(
2023-02-16 10:47:07.992 39 ERROR keystone.server.flask.application   File "/var/lib/kolla/venv/lib/python3.9/site-packages/dogpile/lock.py", line 185, in __enter__
2023-02-16 10:47:07.992 39 ERROR keystone.server.flask.application     return self._enter()
2023-02-16 10:47:07.992 39 ERROR keystone.server.flask.application   File "/var/lib/kolla/venv/lib/python3.9/site-packages/dogpile/lock.py", line 94, in _enter
2023-02-16 10:47:07.992 39 ERROR keystone.server.flask.application     generated = self._enter_create(value, createdtime)
2023-02-16 10:47:07.992 39 ERROR keystone.server.flask.application   File "/var/lib/kolla/venv/lib/python3.9/site-packages/dogpile/lock.py", line 178, in _enter_create
2023-02-16 10:47:07.992 39 ERROR keystone.server.flask.application     return self.creator()
2023-02-16 10:47:07.992 39 ERROR keystone.server.flask.application   File "/var/lib/kolla/venv/lib/python3.9/site-packages/dogpile/cache/region.py", line 995, in gen_value
2023-02-16 10:47:07.992 39 ERROR keystone.server.flask.application     created_value = creator(
2023-02-16 10:47:07.992 39 ERROR keystone.server.flask.application   File "/var/lib/kolla/venv/lib/python3.9/site-packages/keystone/resource/core.py", line 903, in get_project
2023-02-16 10:47:07.992 39 ERROR keystone.server.flask.application     return self.driver.get_project(project_id)
2023-02-16 10:47:07.992 39 ERROR keystone.server.flask.application   File "/var/lib/kolla/venv/lib/python3.9/site-packages/keystone/resource/backends/sql.py", line 49, in get_project
2023-02-16 10:47:07.992 39 ERROR keystone.server.flask.application     return self._get_project(session, project_id).to_dict()
2023-02-16 10:47:07.992 39 ERROR keystone.server.flask.application   File "/var/lib/kolla/venv/lib/python3.9/site-packages/keystone/resource/backends/sql.py", line 44, in _get_project
2023-02-16 10:47:07.992 39 ERROR keystone.server.flask.application     raise exception.ProjectNotFound(project_id=project_id)
2023-02-16 10:47:07.992 39 ERROR keystone.server.flask.application keystone.exception.ProjectNotFound: Could not find project: service.
2023-02-16 10:47:07.992 39 ERROR keystone.server.flask.application 
2023-02-16 10:47:17.230 37 ERROR keystone.server.flask.application [None req-6720fde6-9bf3-4158-8af7-3219f18c6ec3 fb315d92609f4472883a5f0de5502027 - - all default -] Could not find project: service.: keystone.exception.ProjectNotFound: Could not find project: service.
2023-02-16 10:47:17.230 37 ERROR keystone.server.flask.application Traceback (most recent call last):
2023-02-16 10:47:17.230 37 ERROR keystone.server.flask.application   File "/var/lib/kolla/venv/lib/python3.9/site-packages/flask/app.py", line 1820, in full_dispatch_request
2023-02-16 10:47:17.230 37 ERROR keystone.server.flask.application     rv = self.dispatch_request()
2023-02-16 10:47:17.230 37 ERROR keystone.server.flask.application   File "/var/lib/kolla/venv/lib/python3.9/site-packages/flask/app.py", line 1796, in dispatch_request
2023-02-16 10:47:17.230 37 ERROR keystone.server.flask.application     return self.ensure_sync(self.view_functions[rule.endpoint])(**view_args)
2023-02-16 10:47:17.230 37 ERROR keystone.server.flask.application   File "/var/lib/kolla/venv/lib/python3.9/site-packages/flask_restful/__init__.py", line 467, in wrapper
2023-02-16 10:47:17.230 37 ERROR keystone.server.flask.application     resp = resource(*args, **kwargs)
2023-02-16 10:47:17.230 37 ERROR keystone.server.flask.application   File "/var/lib/kolla/venv/lib/python3.9/site-packages/flask/views.py", line 107, in view
2023-02-16 10:47:17.230 37 ERROR keystone.server.flask.application     return current_app.ensure_sync(self.dispatch_request)(**kwargs)
2023-02-16 10:47:17.230 37 ERROR keystone.server.flask.application   File "/var/lib/kolla/venv/lib/python3.9/site-packages/flask_restful/__init__.py", line 582, in dispatch_request
2023-02-16 10:47:17.230 37 ERROR keystone.server.flask.application     resp = meth(*args, **kwargs)
2023-02-16 10:47:17.230 37 ERROR keystone.server.flask.application   File "/var/lib/kolla/venv/lib/python3.9/site-packages/keystone/api/projects.py", line 151, in get
2023-02-16 10:47:17.230 37 ERROR keystone.server.flask.application     return self._get_project(project_id)
2023-02-16 10:47:17.230 37 ERROR keystone.server.flask.application   File "/var/lib/kolla/venv/lib/python3.9/site-packages/keystone/api/projects.py", line 107, in _get_project
2023-02-16 10:47:17.230 37 ERROR keystone.server.flask.application     project = PROVIDERS.resource_api.get_project(project_id)
2023-02-16 10:47:17.230 37 ERROR keystone.server.flask.application   File "/var/lib/kolla/venv/lib/python3.9/site-packages/keystone/common/manager.py", line 115, in wrapped
2023-02-16 10:47:17.230 37 ERROR keystone.server.flask.application     __ret_val = __f(*args, **kwargs)
2023-02-16 10:47:17.230 37 ERROR keystone.server.flask.application   File "/var/lib/kolla/venv/lib/python3.9/site-packages/decorator.py", line 232, in fun
2023-02-16 10:47:17.230 37 ERROR keystone.server.flask.application     return caller(func, *(extras + args), **kw)
2023-02-16 10:47:17.230 37 ERROR keystone.server.flask.application   File "/var/lib/kolla/venv/lib/python3.9/site-packages/dogpile/cache/region.py", line 1577, in get_or_create_for_user_func
2023-02-16 10:47:17.230 37 ERROR keystone.server.flask.application     return self.get_or_create(
2023-02-16 10:47:17.230 37 ERROR keystone.server.flask.application   File "/var/lib/kolla/venv/lib/python3.9/site-packages/dogpile/cache/region.py", line 1042, in get_or_create
2023-02-16 10:47:17.230 37 ERROR keystone.server.flask.application     with Lock(
2023-02-16 10:47:17.230 37 ERROR keystone.server.flask.application   File "/var/lib/kolla/venv/lib/python3.9/site-packages/dogpile/lock.py", line 185, in __enter__
2023-02-16 10:47:17.230 37 ERROR keystone.server.flask.application     return self._enter()
2023-02-16 10:47:17.230 37 ERROR keystone.server.flask.application   File "/var/lib/kolla/venv/lib/python3.9/site-packages/dogpile/lock.py", line 94, in _enter
2023-02-16 10:47:17.230 37 ERROR keystone.server.flask.application     generated = self._enter_create(value, createdtime)
2023-02-16 10:47:17.230 37 ERROR keystone.server.flask.application   File "/var/lib/kolla/venv/lib/python3.9/site-packages/dogpile/lock.py", line 178, in _enter_create
2023-02-16 10:47:17.230 37 ERROR keystone.server.flask.application     return self.creator()
2023-02-16 10:47:17.230 37 ERROR keystone.server.flask.application   File "/var/lib/kolla/venv/lib/python3.9/site-packages/dogpile/cache/region.py", line 995, in gen_value
2023-02-16 10:47:17.230 37 ERROR keystone.server.flask.application     created_value = creator(
2023-02-16 10:47:17.230 37 ERROR keystone.server.flask.application   File "/var/lib/kolla/venv/lib/python3.9/site-packages/keystone/resource/core.py", line 903, in get_project
2023-02-16 10:47:17.230 37 ERROR keystone.server.flask.application     return self.driver.get_project(project_id)
2023-02-16 10:47:17.230 37 ERROR keystone.server.flask.application   File "/var/lib/kolla/venv/lib/python3.9/site-packages/keystone/resource/backends/sql.py", line 49, in get_project
2023-02-16 10:47:17.230 37 ERROR keystone.server.flask.application     return self._get_project(session, project_id).to_dict()
2023-02-16 10:47:17.230 37 ERROR keystone.server.flask.application   File "/var/lib/kolla/venv/lib/python3.9/site-packages/keystone/resource/backends/sql.py", line 44, in _get_project
2023-02-16 10:47:17.230 37 ERROR keystone.server.flask.application     raise exception.ProjectNotFound(project_id=project_id)
2023-02-16 10:47:17.230 37 ERROR keystone.server.flask.application keystone.exception.ProjectNotFound: Could not find project: service.
2023-02-16 10:47:17.230 37 ERROR keystone.server.flask.application 
2023-02-16 10:47:32.610 37 ERROR keystone.server.flask.application [None req-720a073d-4508-40e5-a09c-07d9e29c5494 fb315d92609f4472883a5f0de5502027 - - all default -] Could not find role: admin.: keystone.exception.RoleNotFound: Could not find role: admin.
2023-02-16 10:47:32.610 37 ERROR keystone.server.flask.application Traceback (most recent call last):
2023-02-16 10:47:32.610 37 ERROR keystone.server.flask.application   File "/var/lib/kolla/venv/lib/python3.9/site-packages/flask/app.py", line 1820, in full_dispatch_request
2023-02-16 10:47:32.610 37 ERROR keystone.server.flask.application     rv = self.dispatch_request()
2023-02-16 10:47:32.610 37 ERROR keystone.server.flask.application   File "/var/lib/kolla/venv/lib/python3.9/site-packages/flask/app.py", line 1796, in dispatch_request
2023-02-16 10:47:32.610 37 ERROR keystone.server.flask.application     return self.ensure_sync(self.view_functions[rule.endpoint])(**view_args)
2023-02-16 10:47:32.610 37 ERROR keystone.server.flask.application   File "/var/lib/kolla/venv/lib/python3.9/site-packages/flask_restful/__init__.py", line 467, in wrapper
2023-02-16 10:47:32.610 37 ERROR keystone.server.flask.application     resp = resource(*args, **kwargs)
2023-02-16 10:47:32.610 37 ERROR keystone.server.flask.application   File "/var/lib/kolla/venv/lib/python3.9/site-packages/flask/views.py", line 107, in view
2023-02-16 10:47:32.610 37 ERROR keystone.server.flask.application     return current_app.ensure_sync(self.dispatch_request)(**kwargs)
2023-02-16 10:47:32.610 37 ERROR keystone.server.flask.application   File "/var/lib/kolla/venv/lib/python3.9/site-packages/flask_restful/__init__.py", line 582, in dispatch_request
2023-02-16 10:47:32.610 37 ERROR keystone.server.flask.application     resp = meth(*args, **kwargs)
2023-02-16 10:47:32.610 37 ERROR keystone.server.flask.application   File "/var/lib/kolla/venv/lib/python3.9/site-packages/keystone/api/roles.py", line 50, in get
2023-02-16 10:47:32.610 37 ERROR keystone.server.flask.application     return self._get_role(role_id)
2023-02-16 10:47:32.610 37 ERROR keystone.server.flask.application   File "/var/lib/kolla/venv/lib/python3.9/site-packages/keystone/api/roles.py", line 70, in _get_role
2023-02-16 10:47:32.610 37 ERROR keystone.server.flask.application     ENFORCER.enforce_call(action='identity:get_role')
2023-02-16 10:47:32.610 37 ERROR keystone.server.flask.application   File "/var/lib/kolla/venv/lib/python3.9/site-packages/keystone/common/rbac_enforcer/enforcer.py", line 402, in enforce_call
2023-02-16 10:47:32.610 37 ERROR keystone.server.flask.application     policy_dict.update(cls._extract_member_target_data(
2023-02-16 10:47:32.610 37 ERROR keystone.server.flask.application   File "/var/lib/kolla/venv/lib/python3.9/site-packages/keystone/common/rbac_enforcer/enforcer.py", line 234, in _extract_member_target_data
2023-02-16 10:47:32.610 37 ERROR keystone.server.flask.application     member_name: func(flask.request.view_args[key])
2023-02-16 10:47:32.610 37 ERROR keystone.server.flask.application   File "/var/lib/kolla/venv/lib/python3.9/site-packages/keystone/common/manager.py", line 115, in wrapped
2023-02-16 10:47:32.610 37 ERROR keystone.server.flask.application     __ret_val = __f(*args, **kwargs)
2023-02-16 10:47:32.610 37 ERROR keystone.server.flask.application   File "/var/lib/kolla/venv/lib/python3.9/site-packages/decorator.py", line 232, in fun
2023-02-16 10:47:32.610 37 ERROR keystone.server.flask.application     return caller(func, *(extras + args), **kw)
2023-02-16 10:47:32.610 37 ERROR keystone.server.flask.application   File "/var/lib/kolla/venv/lib/python3.9/site-packages/dogpile/cache/region.py", line 1577, in get_or_create_for_user_func
2023-02-16 10:47:32.610 37 ERROR keystone.server.flask.application     return self.get_or_create(
2023-02-16 10:47:32.610 37 ERROR keystone.server.flask.application   File "/var/lib/kolla/venv/lib/python3.9/site-packages/dogpile/cache/region.py", line 1042, in get_or_create
2023-02-16 10:47:32.610 37 ERROR keystone.server.flask.application     with Lock(
2023-02-16 10:47:32.610 37 ERROR keystone.server.flask.application   File "/var/lib/kolla/venv/lib/python3.9/site-packages/dogpile/lock.py", line 185, in __enter__
2023-02-16 10:47:32.610 37 ERROR keystone.server.flask.application     return self._enter()
2023-02-16 10:47:32.610 37 ERROR keystone.server.flask.application   File "/var/lib/kolla/venv/lib/python3.9/site-packages/dogpile/lock.py", line 94, in _enter
2023-02-16 10:47:32.610 37 ERROR keystone.server.flask.application     generated = self._enter_create(value, createdtime)
2023-02-16 10:47:32.610 37 ERROR keystone.server.flask.application   File "/var/lib/kolla/venv/lib/python3.9/site-packages/dogpile/lock.py", line 178, in _enter_create
2023-02-16 10:47:32.610 37 ERROR keystone.server.flask.application     return self.creator()
2023-02-16 10:47:32.610 37 ERROR keystone.server.flask.application   File "/var/lib/kolla/venv/lib/python3.9/site-packages/dogpile/cache/region.py", line 995, in gen_value
2023-02-16 10:47:32.610 37 ERROR keystone.server.flask.application     created_value = creator(
2023-02-16 10:47:32.610 37 ERROR keystone.server.flask.application   File "/var/lib/kolla/venv/lib/python3.9/site-packages/keystone/assignment/core.py", line 1276, in get_role
2023-02-16 10:47:32.610 37 ERROR keystone.server.flask.application     return self.driver.get_role(role_id)
2023-02-16 10:47:32.610 37 ERROR keystone.server.flask.application   File "/var/lib/kolla/venv/lib/python3.9/site-packages/keystone/assignment/role_backends/sql.py", line 70, in get_role
2023-02-16 10:47:32.610 37 ERROR keystone.server.flask.application     return self._get_role(session, role_id).to_dict()
2023-02-16 10:47:32.610 37 ERROR keystone.server.flask.application   File "/var/lib/kolla/venv/lib/python3.9/site-packages/keystone/assignment/role_backends/sql.py", line 65, in _get_role
2023-02-16 10:47:32.610 37 ERROR keystone.server.flask.application     raise exception.RoleNotFound(role_id=role_id)
2023-02-16 10:47:32.610 37 ERROR keystone.server.flask.application keystone.exception.RoleNotFound: Could not find role: admin.
2023-02-16 10:47:32.610 37 ERROR keystone.server.flask.application 
2023-02-16 10:47:33.802 37 ERROR keystone.server.flask.application [None req-f9957655-d38e-497b-93a4-dd03ba6caee9 fb315d92609f4472883a5f0de5502027 - - all default -] Could not find user: ironic.: keystone.exception.UserNotFound: Could not find user: ironic.
2023-02-16 10:47:33.802 37 ERROR keystone.server.flask.application Traceback (most recent call last):
2023-02-16 10:47:33.802 37 ERROR keystone.server.flask.application   File "/var/lib/kolla/venv/lib/python3.9/site-packages/flask/app.py", line 1820, in full_dispatch_request
2023-02-16 10:47:33.802 37 ERROR keystone.server.flask.application     rv = self.dispatch_request()
2023-02-16 10:47:33.802 37 ERROR keystone.server.flask.application   File "/var/lib/kolla/venv/lib/python3.9/site-packages/flask/app.py", line 1796, in dispatch_request
2023-02-16 10:47:33.802 37 ERROR keystone.server.flask.application     return self.ensure_sync(self.view_functions[rule.endpoint])(**view_args)
2023-02-16 10:47:33.802 37 ERROR keystone.server.flask.application   File "/var/lib/kolla/venv/lib/python3.9/site-packages/flask_restful/__init__.py", line 467, in wrapper
2023-02-16 10:47:33.802 37 ERROR keystone.server.flask.application     resp = resource(*args, **kwargs)
2023-02-16 10:47:33.802 37 ERROR keystone.server.flask.application   File "/var/lib/kolla/venv/lib/python3.9/site-packages/flask/views.py", line 107, in view
2023-02-16 10:47:33.802 37 ERROR keystone.server.flask.application     return current_app.ensure_sync(self.dispatch_request)(**kwargs)
2023-02-16 10:47:33.802 37 ERROR keystone.server.flask.application   File "/var/lib/kolla/venv/lib/python3.9/site-packages/flask_restful/__init__.py", line 582, in dispatch_request
2023-02-16 10:47:33.802 37 ERROR keystone.server.flask.application     resp = meth(*args, **kwargs)
2023-02-16 10:47:33.802 37 ERROR keystone.server.flask.application   File "/var/lib/kolla/venv/lib/python3.9/site-packages/keystone/api/users.py", line 182, in get
2023-02-16 10:47:33.802 37 ERROR keystone.server.flask.application     return self._get_user(user_id)
2023-02-16 10:47:33.802 37 ERROR keystone.server.flask.application   File "/var/lib/kolla/venv/lib/python3.9/site-packages/keystone/api/users.py", line 194, in _get_user
2023-02-16 10:47:33.802 37 ERROR keystone.server.flask.application     ref = PROVIDERS.identity_api.get_user(user_id)
2023-02-16 10:47:33.802 37 ERROR keystone.server.flask.application   File "/var/lib/kolla/venv/lib/python3.9/site-packages/keystone/common/manager.py", line 115, in wrapped
2023-02-16 10:47:33.802 37 ERROR keystone.server.flask.application     __ret_val = __f(*args, **kwargs)
2023-02-16 10:47:33.802 37 ERROR keystone.server.flask.application   File "/var/lib/kolla/venv/lib/python3.9/site-packages/keystone/identity/core.py", line 414, in wrapper
2023-02-16 10:47:33.802 37 ERROR keystone.server.flask.application     return f(self, *args, **kwargs)
2023-02-16 10:47:33.802 37 ERROR keystone.server.flask.application   File "/var/lib/kolla/venv/lib/python3.9/site-packages/keystone/identity/core.py", line 424, in wrapper
2023-02-16 10:47:33.802 37 ERROR keystone.server.flask.application     return f(self, *args, **kwargs)
2023-02-16 10:47:33.802 37 ERROR keystone.server.flask.application   File "/var/lib/kolla/venv/lib/python3.9/site-packages/decorator.py", line 232, in fun
2023-02-16 10:47:33.802 37 ERROR keystone.server.flask.application     return caller(func, *(extras + args), **kw)
2023-02-16 10:47:33.802 37 ERROR keystone.server.flask.application   File "/var/lib/kolla/venv/lib/python3.9/site-packages/dogpile/cache/region.py", line 1577, in get_or_create_for_user_func
2023-02-16 10:47:33.802 37 ERROR keystone.server.flask.application     return self.get_or_create(
2023-02-16 10:47:33.802 37 ERROR keystone.server.flask.application   File "/var/lib/kolla/venv/lib/python3.9/site-packages/dogpile/cache/region.py", line 1042, in get_or_create
2023-02-16 10:47:33.802 37 ERROR keystone.server.flask.application     with Lock(
2023-02-16 10:47:33.802 37 ERROR keystone.server.flask.application   File "/var/lib/kolla/venv/lib/python3.9/site-packages/dogpile/lock.py", line 185, in __enter__
2023-02-16 10:47:33.802 37 ERROR keystone.server.flask.application     return self._enter()
2023-02-16 10:47:33.802 37 ERROR keystone.server.flask.application   File "/var/lib/kolla/venv/lib/python3.9/site-packages/dogpile/lock.py", line 94, in _enter
2023-02-16 10:47:33.802 37 ERROR keystone.server.flask.application     generated = self._enter_create(value, createdtime)
2023-02-16 10:47:33.802 37 ERROR keystone.server.flask.application   File "/var/lib/kolla/venv/lib/python3.9/site-packages/dogpile/lock.py", line 178, in _enter_create
2023-02-16 10:47:33.802 37 ERROR keystone.server.flask.application     return self.creator()
2023-02-16 10:47:33.802 37 ERROR keystone.server.flask.application   File "/var/lib/kolla/venv/lib/python3.9/site-packages/dogpile/cache/region.py", line 995, in gen_value
2023-02-16 10:47:33.802 37 ERROR keystone.server.flask.application     created_value = creator(
2023-02-16 10:47:33.802 37 ERROR keystone.server.flask.application   File "/var/lib/kolla/venv/lib/python3.9/site-packages/keystone/identity/core.py", line 1011, in get_user
2023-02-16 10:47:33.802 37 ERROR keystone.server.flask.application     ref = driver.get_user(entity_id)
2023-02-16 10:47:33.802 37 ERROR keystone.server.flask.application   File "/var/lib/kolla/venv/lib/python3.9/site-packages/keystone/identity/backends/sql.py", line 200, in get_user
2023-02-16 10:47:33.802 37 ERROR keystone.server.flask.application     self._get_user(session, user_id).to_dict())
2023-02-16 10:47:33.802 37 ERROR keystone.server.flask.application   File "/var/lib/kolla/venv/lib/python3.9/site-packages/keystone/identity/backends/sql.py", line 194, in _get_user
2023-02-16 10:47:33.802 37 ERROR keystone.server.flask.application     raise exception.UserNotFound(user_id=user_id)
2023-02-16 10:47:33.802 37 ERROR keystone.server.flask.application keystone.exception.UserNotFound: Could not find user: ironic.
2023-02-16 10:47:33.802 37 ERROR keystone.server.flask.application 
2023-02-16 10:47:34.844 38 ERROR keystone.server.flask.application [None req-f32adddc-1a00-4534-911a-91a69876436f fb315d92609f4472883a5f0de5502027 - - all default -] Could not find project: service.: keystone.exception.ProjectNotFound: Could not find project: service.
2023-02-16 10:47:34.844 38 ERROR keystone.server.flask.application Traceback (most recent call last):
2023-02-16 10:47:34.844 38 ERROR keystone.server.flask.application   File "/var/lib/kolla/venv/lib/python3.9/site-packages/flask/app.py", line 1820, in full_dispatch_request
2023-02-16 10:47:34.844 38 ERROR keystone.server.flask.application     rv = self.dispatch_request()
2023-02-16 10:47:34.844 38 ERROR keystone.server.flask.application   File "/var/lib/kolla/venv/lib/python3.9/site-packages/flask/app.py", line 1796, in dispatch_request
2023-02-16 10:47:34.844 38 ERROR keystone.server.flask.application     return self.ensure_sync(self.view_functions[rule.endpoint])(**view_args)
2023-02-16 10:47:34.844 38 ERROR keystone.server.flask.application   File "/var/lib/kolla/venv/lib/python3.9/site-packages/flask_restful/__init__.py", line 467, in wrapper
2023-02-16 10:47:34.844 38 ERROR keystone.server.flask.application     resp = resource(*args, **kwargs)
2023-02-16 10:47:34.844 38 ERROR keystone.server.flask.application   File "/var/lib/kolla/venv/lib/python3.9/site-packages/flask/views.py", line 107, in view
2023-02-16 10:47:34.844 38 ERROR keystone.server.flask.application     return current_app.ensure_sync(self.dispatch_request)(**kwargs)
2023-02-16 10:47:34.844 38 ERROR keystone.server.flask.application   File "/var/lib/kolla/venv/lib/python3.9/site-packages/flask_restful/__init__.py", line 582, in dispatch_request
2023-02-16 10:47:34.844 38 ERROR keystone.server.flask.application     resp = meth(*args, **kwargs)
2023-02-16 10:47:34.844 38 ERROR keystone.server.flask.application   File "/var/lib/kolla/venv/lib/python3.9/site-packages/keystone/api/projects.py", line 151, in get
2023-02-16 10:47:34.844 38 ERROR keystone.server.flask.application     return self._get_project(project_id)
2023-02-16 10:47:34.844 38 ERROR keystone.server.flask.application   File "/var/lib/kolla/venv/lib/python3.9/site-packages/keystone/api/projects.py", line 107, in _get_project
2023-02-16 10:47:34.844 38 ERROR keystone.server.flask.application     project = PROVIDERS.resource_api.get_project(project_id)
2023-02-16 10:47:34.844 38 ERROR keystone.server.flask.application   File "/var/lib/kolla/venv/lib/python3.9/site-packages/keystone/common/manager.py", line 115, in wrapped
2023-02-16 10:47:34.844 38 ERROR keystone.server.flask.application     __ret_val = __f(*args, **kwargs)
2023-02-16 10:47:34.844 38 ERROR keystone.server.flask.application   File "/var/lib/kolla/venv/lib/python3.9/site-packages/decorator.py", line 232, in fun
2023-02-16 10:47:34.844 38 ERROR keystone.server.flask.application     return caller(func, *(extras + args), **kw)
2023-02-16 10:47:34.844 38 ERROR keystone.server.flask.application   File "/var/lib/kolla/venv/lib/python3.9/site-packages/dogpile/cache/region.py", line 1577, in get_or_create_for_user_func
2023-02-16 10:47:34.844 38 ERROR keystone.server.flask.application     return self.get_or_create(
2023-02-16 10:47:34.844 38 ERROR keystone.server.flask.application   File "/var/lib/kolla/venv/lib/python3.9/site-packages/dogpile/cache/region.py", line 1042, in get_or_create
2023-02-16 10:47:34.844 38 ERROR keystone.server.flask.application     with Lock(
2023-02-16 10:47:34.844 38 ERROR keystone.server.flask.application   File "/var/lib/kolla/venv/lib/python3.9/site-packages/dogpile/lock.py", line 185, in __enter__
2023-02-16 10:47:34.844 38 ERROR keystone.server.flask.application     return self._enter()
2023-02-16 10:47:34.844 38 ERROR keystone.server.flask.application   File "/var/lib/kolla/venv/lib/python3.9/site-packages/dogpile/lock.py", line 94, in _enter
2023-02-16 10:47:34.844 38 ERROR keystone.server.flask.application     generated = self._enter_create(value, createdtime)
2023-02-16 10:47:34.844 38 ERROR keystone.server.flask.application   File "/var/lib/kolla/venv/lib/python3.9/site-packages/dogpile/lock.py", line 178, in _enter_create
2023-02-16 10:47:34.844 38 ERROR keystone.server.flask.application     return self.creator()
2023-02-16 10:47:34.844 38 ERROR keystone.server.flask.application   File "/var/lib/kolla/venv/lib/python3.9/site-packages/dogpile/cache/region.py", line 995, in gen_value
2023-02-16 10:47:34.844 38 ERROR keystone.server.flask.application     created_value = creator(
2023-02-16 10:47:34.844 38 ERROR keystone.server.flask.application   File "/var/lib/kolla/venv/lib/python3.9/site-packages/keystone/resource/core.py", line 903, in get_project
2023-02-16 10:47:34.844 38 ERROR keystone.server.flask.application     return self.driver.get_project(project_id)
2023-02-16 10:47:34.844 38 ERROR keystone.server.flask.application   File "/var/lib/kolla/venv/lib/python3.9/site-packages/keystone/resource/backends/sql.py", line 49, in get_project
2023-02-16 10:47:34.844 38 ERROR keystone.server.flask.application     return self._get_project(session, project_id).to_dict()
2023-02-16 10:47:34.844 38 ERROR keystone.server.flask.application   File "/var/lib/kolla/venv/lib/python3.9/site-packages/keystone/resource/backends/sql.py", line 44, in _get_project
2023-02-16 10:47:34.844 38 ERROR keystone.server.flask.application     raise exception.ProjectNotFound(project_id=project_id)
2023-02-16 10:47:34.844 38 ERROR keystone.server.flask.application keystone.exception.ProjectNotFound: Could not find project: service.
2023-02-16 10:47:34.844 38 ERROR keystone.server.flask.application 
2023-02-16 10:47:45.323 39 ERROR keystone.server.flask.application [None req-2ee84b3c-6313-4d41-97b8-9fec6aa8f06e fb315d92609f4472883a5f0de5502027 - - all default -] Could not find role: admin.: keystone.exception.RoleNotFound: Could not find role: admin.
2023-02-16 10:47:45.323 39 ERROR keystone.server.flask.application Traceback (most recent call last):
2023-02-16 10:47:45.323 39 ERROR keystone.server.flask.application   File "/var/lib/kolla/venv/lib/python3.9/site-packages/flask/app.py", line 1820, in full_dispatch_request
2023-02-16 10:47:45.323 39 ERROR keystone.server.flask.application     rv = self.dispatch_request()
2023-02-16 10:47:45.323 39 ERROR keystone.server.flask.application   File "/var/lib/kolla/venv/lib/python3.9/site-packages/flask/app.py", line 1796, in dispatch_request
2023-02-16 10:47:45.323 39 ERROR keystone.server.flask.application     return self.ensure_sync(self.view_functions[rule.endpoint])(**view_args)
2023-02-16 10:47:45.323 39 ERROR keystone.server.flask.application   File "/var/lib/kolla/venv/lib/python3.9/site-packages/flask_restful/__init__.py", line 467, in wrapper
2023-02-16 10:47:45.323 39 ERROR keystone.server.flask.application     resp = resource(*args, **kwargs)
2023-02-16 10:47:45.323 39 ERROR keystone.server.flask.application   File "/var/lib/kolla/venv/lib/python3.9/site-packages/flask/views.py", line 107, in view
2023-02-16 10:47:45.323 39 ERROR keystone.server.flask.application     return current_app.ensure_sync(self.dispatch_request)(**kwargs)
2023-02-16 10:47:45.323 39 ERROR keystone.server.flask.application   File "/var/lib/kolla/venv/lib/python3.9/site-packages/flask_restful/__init__.py", line 582, in dispatch_request
2023-02-16 10:47:45.323 39 ERROR keystone.server.flask.application     resp = meth(*args, **kwargs)
2023-02-16 10:47:45.323 39 ERROR keystone.server.flask.application   File "/var/lib/kolla/venv/lib/python3.9/site-packages/keystone/api/roles.py", line 50, in get
2023-02-16 10:47:45.323 39 ERROR keystone.server.flask.application     return self._get_role(role_id)
2023-02-16 10:47:45.323 39 ERROR keystone.server.flask.application   File "/var/lib/kolla/venv/lib/python3.9/site-packages/keystone/api/roles.py", line 70, in _get_role
2023-02-16 10:47:45.323 39 ERROR keystone.server.flask.application     ENFORCER.enforce_call(action='identity:get_role')
2023-02-16 10:47:45.323 39 ERROR keystone.server.flask.application   File "/var/lib/kolla/venv/lib/python3.9/site-packages/keystone/common/rbac_enforcer/enforcer.py", line 402, in enforce_call
2023-02-16 10:47:45.323 39 ERROR keystone.server.flask.application     policy_dict.update(cls._extract_member_target_data(
2023-02-16 10:47:45.323 39 ERROR keystone.server.flask.application   File "/var/lib/kolla/venv/lib/python3.9/site-packages/keystone/common/rbac_enforcer/enforcer.py", line 234, in _extract_member_target_data
2023-02-16 10:47:45.323 39 ERROR keystone.server.flask.application     member_name: func(flask.request.view_args[key])
2023-02-16 10:47:45.323 39 ERROR keystone.server.flask.application   File "/var/lib/kolla/venv/lib/python3.9/site-packages/keystone/common/manager.py", line 115, in wrapped
2023-02-16 10:47:45.323 39 ERROR keystone.server.flask.application     __ret_val = __f(*args, **kwargs)
2023-02-16 10:47:45.323 39 ERROR keystone.server.flask.application   File "/var/lib/kolla/venv/lib/python3.9/site-packages/decorator.py", line 232, in fun
2023-02-16 10:47:45.323 39 ERROR keystone.server.flask.application     return caller(func, *(extras + args), **kw)
2023-02-16 10:47:45.323 39 ERROR keystone.server.flask.application   File "/var/lib/kolla/venv/lib/python3.9/site-packages/dogpile/cache/region.py", line 1577, in get_or_create_for_user_func
2023-02-16 10:47:45.323 39 ERROR keystone.server.flask.application     return self.get_or_create(
2023-02-16 10:47:45.323 39 ERROR keystone.server.flask.application   File "/var/lib/kolla/venv/lib/python3.9/site-packages/dogpile/cache/region.py", line 1042, in get_or_create
2023-02-16 10:47:45.323 39 ERROR keystone.server.flask.application     with Lock(
2023-02-16 10:47:45.323 39 ERROR keystone.server.flask.application   File "/var/lib/kolla/venv/lib/python3.9/site-packages/dogpile/lock.py", line 185, in __enter__
2023-02-16 10:47:45.323 39 ERROR keystone.server.flask.application     return self._enter()
2023-02-16 10:47:45.323 39 ERROR keystone.server.flask.application   File "/var/lib/kolla/venv/lib/python3.9/site-packages/dogpile/lock.py", line 94, in _enter
2023-02-16 10:47:45.323 39 ERROR keystone.server.flask.application     generated = self._enter_create(value, createdtime)
2023-02-16 10:47:45.323 39 ERROR keystone.server.flask.application   File "/var/lib/kolla/venv/lib/python3.9/site-packages/dogpile/lock.py", line 178, in _enter_create
2023-02-16 10:47:45.323 39 ERROR keystone.server.flask.application     return self.creator()
2023-02-16 10:47:45.323 39 ERROR keystone.server.flask.application   File "/var/lib/kolla/venv/lib/python3.9/site-packages/dogpile/cache/region.py", line 995, in gen_value
2023-02-16 10:47:45.323 39 ERROR keystone.server.flask.application     created_value = creator(
2023-02-16 10:47:45.323 39 ERROR keystone.server.flask.application   File "/var/lib/kolla/venv/lib/python3.9/site-packages/keystone/assignment/core.py", line 1276, in get_role
2023-02-16 10:47:45.323 39 ERROR keystone.server.flask.application     return self.driver.get_role(role_id)
2023-02-16 10:47:45.323 39 ERROR keystone.server.flask.application   File "/var/lib/kolla/venv/lib/python3.9/site-packages/keystone/assignment/role_backends/sql.py", line 70, in get_role
2023-02-16 10:47:45.323 39 ERROR keystone.server.flask.application     return self._get_role(session, role_id).to_dict()
2023-02-16 10:47:45.323 39 ERROR keystone.server.flask.application   File "/var/lib/kolla/venv/lib/python3.9/site-packages/keystone/assignment/role_backends/sql.py", line 65, in _get_role
2023-02-16 10:47:45.323 39 ERROR keystone.server.flask.application     raise exception.RoleNotFound(role_id=role_id)
2023-02-16 10:47:45.323 39 ERROR keystone.server.flask.application keystone.exception.RoleNotFound: Could not find role: admin.
2023-02-16 10:47:45.323 39 ERROR keystone.server.flask.application 
2023-02-16 10:47:46.688 39 ERROR keystone.server.flask.application [None req-83a8cd84-63d9-4566-be04-aa71f60e0d1e fb315d92609f4472883a5f0de5502027 - - all default -] Could not find user: ironic-inspector.: keystone.exception.UserNotFound: Could not find user: ironic-inspector.
2023-02-16 10:47:46.688 39 ERROR keystone.server.flask.application Traceback (most recent call last):
2023-02-16 10:47:46.688 39 ERROR keystone.server.flask.application   File "/var/lib/kolla/venv/lib/python3.9/site-packages/flask/app.py", line 1820, in full_dispatch_request
2023-02-16 10:47:46.688 39 ERROR keystone.server.flask.application     rv = self.dispatch_request()
2023-02-16 10:47:46.688 39 ERROR keystone.server.flask.application   File "/var/lib/kolla/venv/lib/python3.9/site-packages/flask/app.py", line 1796, in dispatch_request
2023-02-16 10:47:46.688 39 ERROR keystone.server.flask.application     return self.ensure_sync(self.view_functions[rule.endpoint])(**view_args)
2023-02-16 10:47:46.688 39 ERROR keystone.server.flask.application   File "/var/lib/kolla/venv/lib/python3.9/site-packages/flask_restful/__init__.py", line 467, in wrapper
2023-02-16 10:47:46.688 39 ERROR keystone.server.flask.application     resp = resource(*args, **kwargs)
2023-02-16 10:47:46.688 39 ERROR keystone.server.flask.application   File "/var/lib/kolla/venv/lib/python3.9/site-packages/flask/views.py", line 107, in view
2023-02-16 10:47:46.688 39 ERROR keystone.server.flask.application     return current_app.ensure_sync(self.dispatch_request)(**kwargs)
2023-02-16 10:47:46.688 39 ERROR keystone.server.flask.application   File "/var/lib/kolla/venv/lib/python3.9/site-packages/flask_restful/__init__.py", line 582, in dispatch_request
2023-02-16 10:47:46.688 39 ERROR keystone.server.flask.application     resp = meth(*args, **kwargs)
2023-02-16 10:47:46.688 39 ERROR keystone.server.flask.application   File "/var/lib/kolla/venv/lib/python3.9/site-packages/keystone/api/users.py", line 182, in get
2023-02-16 10:47:46.688 39 ERROR keystone.server.flask.application     return self._get_user(user_id)
2023-02-16 10:47:46.688 39 ERROR keystone.server.flask.application   File "/var/lib/kolla/venv/lib/python3.9/site-packages/keystone/api/users.py", line 194, in _get_user
2023-02-16 10:47:46.688 39 ERROR keystone.server.flask.application     ref = PROVIDERS.identity_api.get_user(user_id)
2023-02-16 10:47:46.688 39 ERROR keystone.server.flask.application   File "/var/lib/kolla/venv/lib/python3.9/site-packages/keystone/common/manager.py", line 115, in wrapped
2023-02-16 10:47:46.688 39 ERROR keystone.server.flask.application     __ret_val = __f(*args, **kwargs)
2023-02-16 10:47:46.688 39 ERROR keystone.server.flask.application   File "/var/lib/kolla/venv/lib/python3.9/site-packages/keystone/identity/core.py", line 414, in wrapper
2023-02-16 10:47:46.688 39 ERROR keystone.server.flask.application     return f(self, *args, **kwargs)
2023-02-16 10:47:46.688 39 ERROR keystone.server.flask.application   File "/var/lib/kolla/venv/lib/python3.9/site-packages/keystone/identity/core.py", line 424, in wrapper
2023-02-16 10:47:46.688 39 ERROR keystone.server.flask.application     return f(self, *args, **kwargs)
2023-02-16 10:47:46.688 39 ERROR keystone.server.flask.application   File "/var/lib/kolla/venv/lib/python3.9/site-packages/decorator.py", line 232, in fun
2023-02-16 10:47:46.688 39 ERROR keystone.server.flask.application     return caller(func, *(extras + args), **kw)
2023-02-16 10:47:46.688 39 ERROR keystone.server.flask.application   File "/var/lib/kolla/venv/lib/python3.9/site-packages/dogpile/cache/region.py", line 1577, in get_or_create_for_user_func
2023-02-16 10:47:46.688 39 ERROR keystone.server.flask.application     return self.get_or_create(
2023-02-16 10:47:46.688 39 ERROR keystone.server.flask.application   File "/var/lib/kolla/venv/lib/python3.9/site-packages/dogpile/cache/region.py", line 1042, in get_or_create
2023-02-16 10:47:46.688 39 ERROR keystone.server.flask.application     with Lock(
2023-02-16 10:47:46.688 39 ERROR keystone.server.flask.application   File "/var/lib/kolla/venv/lib/python3.9/site-packages/dogpile/lock.py", line 185, in __enter__
2023-02-16 10:47:46.688 39 ERROR keystone.server.flask.application     return self._enter()
2023-02-16 10:47:46.688 39 ERROR keystone.server.flask.application   File "/var/lib/kolla/venv/lib/python3.9/site-packages/dogpile/lock.py", line 94, in _enter
2023-02-16 10:47:46.688 39 ERROR keystone.server.flask.application     generated = self._enter_create(value, createdtime)
2023-02-16 10:47:46.688 39 ERROR keystone.server.flask.application   File "/var/lib/kolla/venv/lib/python3.9/site-packages/dogpile/lock.py", line 178, in _enter_create
2023-02-16 10:47:46.688 39 ERROR keystone.server.flask.application     return self.creator()
2023-02-16 10:47:46.688 39 ERROR keystone.server.flask.application   File "/var/lib/kolla/venv/lib/python3.9/site-packages/dogpile/cache/region.py", line 995, in gen_value
2023-02-16 10:47:46.688 39 ERROR keystone.server.flask.application     created_value = creator(
2023-02-16 10:47:46.688 39 ERROR keystone.server.flask.application   File "/var/lib/kolla/venv/lib/python3.9/site-packages/keystone/identity/core.py", line 1011, in get_user
2023-02-16 10:47:46.688 39 ERROR keystone.server.flask.application     ref = driver.get_user(entity_id)
2023-02-16 10:47:46.688 39 ERROR keystone.server.flask.application   File "/var/lib/kolla/venv/lib/python3.9/site-packages/keystone/identity/backends/sql.py", line 200, in get_user
2023-02-16 10:47:46.688 39 ERROR keystone.server.flask.application     self._get_user(session, user_id).to_dict())
2023-02-16 10:47:46.688 39 ERROR keystone.server.flask.application   File "/var/lib/kolla/venv/lib/python3.9/site-packages/keystone/identity/backends/sql.py", line 194, in _get_user
2023-02-16 10:47:46.688 39 ERROR keystone.server.flask.application     raise exception.UserNotFound(user_id=user_id)
2023-02-16 10:47:46.688 39 ERROR keystone.server.flask.application keystone.exception.UserNotFound: Could not find user: ironic-inspector.
2023-02-16 10:47:46.688 39 ERROR keystone.server.flask.application 
2023-02-16 10:47:47.446 37 ERROR keystone.server.flask.application [None req-0fb62bb4-dbd5-47e7-8540-ea5a17b29542 fb315d92609f4472883a5f0de5502027 - - all default -] Could not find project: service.: keystone.exception.ProjectNotFound: Could not find project: service.
2023-02-16 10:47:47.446 37 ERROR keystone.server.flask.application Traceback (most recent call last):
2023-02-16 10:47:47.446 37 ERROR keystone.server.flask.application   File "/var/lib/kolla/venv/lib/python3.9/site-packages/flask/app.py", line 1820, in full_dispatch_request
2023-02-16 10:47:47.446 37 ERROR keystone.server.flask.application     rv = self.dispatch_request()
2023-02-16 10:47:47.446 37 ERROR keystone.server.flask.application   File "/var/lib/kolla/venv/lib/python3.9/site-packages/flask/app.py", line 1796, in dispatch_request
2023-02-16 10:47:47.446 37 ERROR keystone.server.flask.application     return self.ensure_sync(self.view_functions[rule.endpoint])(**view_args)
2023-02-16 10:47:47.446 37 ERROR keystone.server.flask.application   File "/var/lib/kolla/venv/lib/python3.9/site-packages/flask_restful/__init__.py", line 467, in wrapper
2023-02-16 10:47:47.446 37 ERROR keystone.server.flask.application     resp = resource(*args, **kwargs)
2023-02-16 10:47:47.446 37 ERROR keystone.server.flask.application   File "/var/lib/kolla/venv/lib/python3.9/site-packages/flask/views.py", line 107, in view
2023-02-16 10:47:47.446 37 ERROR keystone.server.flask.application     return current_app.ensure_sync(self.dispatch_request)(**kwargs)
2023-02-16 10:47:47.446 37 ERROR keystone.server.flask.application   File "/var/lib/kolla/venv/lib/python3.9/site-packages/flask_restful/__init__.py", line 582, in dispatch_request
2023-02-16 10:47:47.446 37 ERROR keystone.server.flask.application     resp = meth(*args, **kwargs)
2023-02-16 10:47:47.446 37 ERROR keystone.server.flask.application   File "/var/lib/kolla/venv/lib/python3.9/site-packages/keystone/api/projects.py", line 151, in get
2023-02-16 10:47:47.446 37 ERROR keystone.server.flask.application     return self._get_project(project_id)
2023-02-16 10:47:47.446 37 ERROR keystone.server.flask.application   File "/var/lib/kolla/venv/lib/python3.9/site-packages/keystone/api/projects.py", line 107, in _get_project
2023-02-16 10:47:47.446 37 ERROR keystone.server.flask.application     project = PROVIDERS.resource_api.get_project(project_id)
2023-02-16 10:47:47.446 37 ERROR keystone.server.flask.application   File "/var/lib/kolla/venv/lib/python3.9/site-packages/keystone/common/manager.py", line 115, in wrapped
2023-02-16 10:47:47.446 37 ERROR keystone.server.flask.application     __ret_val = __f(*args, **kwargs)
2023-02-16 10:47:47.446 37 ERROR keystone.server.flask.application   File "/var/lib/kolla/venv/lib/python3.9/site-packages/decorator.py", line 232, in fun
2023-02-16 10:47:47.446 37 ERROR keystone.server.flask.application     return caller(func, *(extras + args), **kw)
2023-02-16 10:47:47.446 37 ERROR keystone.server.flask.application   File "/var/lib/kolla/venv/lib/python3.9/site-packages/dogpile/cache/region.py", line 1577, in get_or_create_for_user_func
2023-02-16 10:47:47.446 37 ERROR keystone.server.flask.application     return self.get_or_create(
2023-02-16 10:47:47.446 37 ERROR keystone.server.flask.application   File "/var/lib/kolla/venv/lib/python3.9/site-packages/dogpile/cache/region.py", line 1042, in get_or_create
2023-02-16 10:47:47.446 37 ERROR keystone.server.flask.application     with Lock(
2023-02-16 10:47:47.446 37 ERROR keystone.server.flask.application   File "/var/lib/kolla/venv/lib/python3.9/site-packages/dogpile/lock.py", line 185, in __enter__
2023-02-16 10:47:47.446 37 ERROR keystone.server.flask.application     return self._enter()
2023-02-16 10:47:47.446 37 ERROR keystone.server.flask.application   File "/var/lib/kolla/venv/lib/python3.9/site-packages/dogpile/lock.py", line 94, in _enter
2023-02-16 10:47:47.446 37 ERROR keystone.server.flask.application     generated = self._enter_create(value, createdtime)
2023-02-16 10:47:47.446 37 ERROR keystone.server.flask.application   File "/var/lib/kolla/venv/lib/python3.9/site-packages/dogpile/lock.py", line 178, in _enter_create
2023-02-16 10:47:47.446 37 ERROR keystone.server.flask.application     return self.creator()
2023-02-16 10:47:47.446 37 ERROR keystone.server.flask.application   File "/var/lib/kolla/venv/lib/python3.9/site-packages/dogpile/cache/region.py", line 995, in gen_value
2023-02-16 10:47:47.446 37 ERROR keystone.server.flask.application     created_value = creator(
2023-02-16 10:47:47.446 37 ERROR keystone.server.flask.application   File "/var/lib/kolla/venv/lib/python3.9/site-packages/keystone/resource/core.py", line 903, in get_project
2023-02-16 10:47:47.446 37 ERROR keystone.server.flask.application     return self.driver.get_project(project_id)
2023-02-16 10:47:47.446 37 ERROR keystone.server.flask.application   File "/var/lib/kolla/venv/lib/python3.9/site-packages/keystone/resource/backends/sql.py", line 49, in get_project
2023-02-16 10:47:47.446 37 ERROR keystone.server.flask.application     return self._get_project(session, project_id).to_dict()
2023-02-16 10:47:47.446 37 ERROR keystone.server.flask.application   File "/var/lib/kolla/venv/lib/python3.9/site-packages/keystone/resource/backends/sql.py", line 44, in _get_project
2023-02-16 10:47:47.446 37 ERROR keystone.server.flask.application     raise exception.ProjectNotFound(project_id=project_id)
2023-02-16 10:47:47.446 37 ERROR keystone.server.flask.application keystone.exception.ProjectNotFound: Could not find project: service.
2023-02-16 10:47:47.446 37 ERROR keystone.server.flask.application 
2023-02-16 10:50:57.964 37 ERROR keystone.server.flask.application [None req-0e5fd80e-5358-471c-b7db-0084fd45839f fb315d92609f4472883a5f0de5502027 - - all default -] Could not find project: service.: keystone.exception.ProjectNotFound: Could not find project: service.
2023-02-16 10:50:57.964 37 ERROR keystone.server.flask.application Traceback (most recent call last):
2023-02-16 10:50:57.964 37 ERROR keystone.server.flask.application   File "/var/lib/kolla/venv/lib/python3.9/site-packages/flask/app.py", line 1820, in full_dispatch_request
2023-02-16 10:50:57.964 37 ERROR keystone.server.flask.application     rv = self.dispatch_request()
2023-02-16 10:50:57.964 37 ERROR keystone.server.flask.application   File "/var/lib/kolla/venv/lib/python3.9/site-packages/flask/app.py", line 1796, in dispatch_request
2023-02-16 10:50:57.964 37 ERROR keystone.server.flask.application     return self.ensure_sync(self.view_functions[rule.endpoint])(**view_args)
2023-02-16 10:50:57.964 37 ERROR keystone.server.flask.application   File "/var/lib/kolla/venv/lib/python3.9/site-packages/flask_restful/__init__.py", line 467, in wrapper
2023-02-16 10:50:57.964 37 ERROR keystone.server.flask.application     resp = resource(*args, **kwargs)
2023-02-16 10:50:57.964 37 ERROR keystone.server.flask.application   File "/var/lib/kolla/venv/lib/python3.9/site-packages/flask/views.py", line 107, in view
2023-02-16 10:50:57.964 37 ERROR keystone.server.flask.application     return current_app.ensure_sync(self.dispatch_request)(**kwargs)
2023-02-16 10:50:57.964 37 ERROR keystone.server.flask.application   File "/var/lib/kolla/venv/lib/python3.9/site-packages/flask_restful/__init__.py", line 582, in dispatch_request
2023-02-16 10:50:57.964 37 ERROR keystone.server.flask.application     resp = meth(*args, **kwargs)
2023-02-16 10:50:57.964 37 ERROR keystone.server.flask.application   File "/var/lib/kolla/venv/lib/python3.9/site-packages/keystone/api/projects.py", line 151, in get
2023-02-16 10:50:57.964 37 ERROR keystone.server.flask.application     return self._get_project(project_id)
2023-02-16 10:50:57.964 37 ERROR keystone.server.flask.application   File "/var/lib/kolla/venv/lib/python3.9/site-packages/keystone/api/projects.py", line 107, in _get_project
2023-02-16 10:50:57.964 37 ERROR keystone.server.flask.application     project = PROVIDERS.resource_api.get_project(project_id)
2023-02-16 10:50:57.964 37 ERROR keystone.server.flask.application   File "/var/lib/kolla/venv/lib/python3.9/site-packages/keystone/common/manager.py", line 115, in wrapped
2023-02-16 10:50:57.964 37 ERROR keystone.server.flask.application     __ret_val = __f(*args, **kwargs)
2023-02-16 10:50:57.964 37 ERROR keystone.server.flask.application   File "/var/lib/kolla/venv/lib/python3.9/site-packages/decorator.py", line 232, in fun
2023-02-16 10:50:57.964 37 ERROR keystone.server.flask.application     return caller(func, *(extras + args), **kw)
2023-02-16 10:50:57.964 37 ERROR keystone.server.flask.application   File "/var/lib/kolla/venv/lib/python3.9/site-packages/dogpile/cache/region.py", line 1577, in get_or_create_for_user_func
2023-02-16 10:50:57.964 37 ERROR keystone.server.flask.application     return self.get_or_create(
2023-02-16 10:50:57.964 37 ERROR keystone.server.flask.application   File "/var/lib/kolla/venv/lib/python3.9/site-packages/dogpile/cache/region.py", line 1042, in get_or_create
2023-02-16 10:50:57.964 37 ERROR keystone.server.flask.application     with Lock(
2023-02-16 10:50:57.964 37 ERROR keystone.server.flask.application   File "/var/lib/kolla/venv/lib/python3.9/site-packages/dogpile/lock.py", line 185, in __enter__
2023-02-16 10:50:57.964 37 ERROR keystone.server.flask.application     return self._enter()
2023-02-16 10:50:57.964 37 ERROR keystone.server.flask.application   File "/var/lib/kolla/venv/lib/python3.9/site-packages/dogpile/lock.py", line 94, in _enter
2023-02-16 10:50:57.964 37 ERROR keystone.server.flask.application     generated = self._enter_create(value, createdtime)
2023-02-16 10:50:57.964 37 ERROR keystone.server.flask.application   File "/var/lib/kolla/venv/lib/python3.9/site-packages/dogpile/lock.py", line 178, in _enter_create
2023-02-16 10:50:57.964 37 ERROR keystone.server.flask.application     return self.creator()
2023-02-16 10:50:57.964 37 ERROR keystone.server.flask.application   File "/var/lib/kolla/venv/lib/python3.9/site-packages/dogpile/cache/region.py", line 995, in gen_value
2023-02-16 10:50:57.964 37 ERROR keystone.server.flask.application     created_value = creator(
2023-02-16 10:50:57.964 37 ERROR keystone.server.flask.application   File "/var/lib/kolla/venv/lib/python3.9/site-packages/keystone/resource/core.py", line 903, in get_project
2023-02-16 10:50:57.964 37 ERROR keystone.server.flask.application     return self.driver.get_project(project_id)
2023-02-16 10:50:57.964 37 ERROR keystone.server.flask.application   File "/var/lib/kolla/venv/lib/python3.9/site-packages/keystone/resource/backends/sql.py", line 49, in get_project
2023-02-16 10:50:57.964 37 ERROR keystone.server.flask.application     return self._get_project(session, project_id).to_dict()
2023-02-16 10:50:57.964 37 ERROR keystone.server.flask.application   File "/var/lib/kolla/venv/lib/python3.9/site-packages/keystone/resource/backends/sql.py", line 44, in _get_project
2023-02-16 10:50:57.964 37 ERROR keystone.server.flask.application     raise exception.ProjectNotFound(project_id=project_id)
2023-02-16 10:50:57.964 37 ERROR keystone.server.flask.application keystone.exception.ProjectNotFound: Could not find project: service.
2023-02-16 10:50:57.964 37 ERROR keystone.server.flask.application 
2023-02-16 10:51:13.606 38 ERROR keystone.server.flask.application [None req-a8de33df-b428-4190-a36c-55eac668bc6e fb315d92609f4472883a5f0de5502027 - - all default -] Could not find role: admin.: keystone.exception.RoleNotFound: Could not find role: admin.
2023-02-16 10:51:13.606 38 ERROR keystone.server.flask.application Traceback (most recent call last):
2023-02-16 10:51:13.606 38 ERROR keystone.server.flask.application   File "/var/lib/kolla/venv/lib/python3.9/site-packages/flask/app.py", line 1820, in full_dispatch_request
2023-02-16 10:51:13.606 38 ERROR keystone.server.flask.application     rv = self.dispatch_request()
2023-02-16 10:51:13.606 38 ERROR keystone.server.flask.application   File "/var/lib/kolla/venv/lib/python3.9/site-packages/flask/app.py", line 1796, in dispatch_request
2023-02-16 10:51:13.606 38 ERROR keystone.server.flask.application     return self.ensure_sync(self.view_functions[rule.endpoint])(**view_args)
2023-02-16 10:51:13.606 38 ERROR keystone.server.flask.application   File "/var/lib/kolla/venv/lib/python3.9/site-packages/flask_restful/__init__.py", line 467, in wrapper
2023-02-16 10:51:13.606 38 ERROR keystone.server.flask.application     resp = resource(*args, **kwargs)
2023-02-16 10:51:13.606 38 ERROR keystone.server.flask.application   File "/var/lib/kolla/venv/lib/python3.9/site-packages/flask/views.py", line 107, in view
2023-02-16 10:51:13.606 38 ERROR keystone.server.flask.application     return current_app.ensure_sync(self.dispatch_request)(**kwargs)
2023-02-16 10:51:13.606 38 ERROR keystone.server.flask.application   File "/var/lib/kolla/venv/lib/python3.9/site-packages/flask_restful/__init__.py", line 582, in dispatch_request
2023-02-16 10:51:13.606 38 ERROR keystone.server.flask.application     resp = meth(*args, **kwargs)
2023-02-16 10:51:13.606 38 ERROR keystone.server.flask.application   File "/var/lib/kolla/venv/lib/python3.9/site-packages/keystone/api/roles.py", line 50, in get
2023-02-16 10:51:13.606 38 ERROR keystone.server.flask.application     return self._get_role(role_id)
2023-02-16 10:51:13.606 38 ERROR keystone.server.flask.application   File "/var/lib/kolla/venv/lib/python3.9/site-packages/keystone/api/roles.py", line 70, in _get_role
2023-02-16 10:51:13.606 38 ERROR keystone.server.flask.application     ENFORCER.enforce_call(action='identity:get_role')
2023-02-16 10:51:13.606 38 ERROR keystone.server.flask.application   File "/var/lib/kolla/venv/lib/python3.9/site-packages/keystone/common/rbac_enforcer/enforcer.py", line 402, in enforce_call
2023-02-16 10:51:13.606 38 ERROR keystone.server.flask.application     policy_dict.update(cls._extract_member_target_data(
2023-02-16 10:51:13.606 38 ERROR keystone.server.flask.application   File "/var/lib/kolla/venv/lib/python3.9/site-packages/keystone/common/rbac_enforcer/enforcer.py", line 234, in _extract_member_target_data
2023-02-16 10:51:13.606 38 ERROR keystone.server.flask.application     member_name: func(flask.request.view_args[key])
2023-02-16 10:51:13.606 38 ERROR keystone.server.flask.application   File "/var/lib/kolla/venv/lib/python3.9/site-packages/keystone/common/manager.py", line 115, in wrapped
2023-02-16 10:51:13.606 38 ERROR keystone.server.flask.application     __ret_val = __f(*args, **kwargs)
2023-02-16 10:51:13.606 38 ERROR keystone.server.flask.application   File "/var/lib/kolla/venv/lib/python3.9/site-packages/decorator.py", line 232, in fun
2023-02-16 10:51:13.606 38 ERROR keystone.server.flask.application     return caller(func, *(extras + args), **kw)
2023-02-16 10:51:13.606 38 ERROR keystone.server.flask.application   File "/var/lib/kolla/venv/lib/python3.9/site-packages/dogpile/cache/region.py", line 1577, in get_or_create_for_user_func
2023-02-16 10:51:13.606 38 ERROR keystone.server.flask.application     return self.get_or_create(
2023-02-16 10:51:13.606 38 ERROR keystone.server.flask.application   File "/var/lib/kolla/venv/lib/python3.9/site-packages/dogpile/cache/region.py", line 1042, in get_or_create
2023-02-16 10:51:13.606 38 ERROR keystone.server.flask.application     with Lock(
2023-02-16 10:51:13.606 38 ERROR keystone.server.flask.application   File "/var/lib/kolla/venv/lib/python3.9/site-packages/dogpile/lock.py", line 185, in __enter__
2023-02-16 10:51:13.606 38 ERROR keystone.server.flask.application     return self._enter()
2023-02-16 10:51:13.606 38 ERROR keystone.server.flask.application   File "/var/lib/kolla/venv/lib/python3.9/site-packages/dogpile/lock.py", line 94, in _enter
2023-02-16 10:51:13.606 38 ERROR keystone.server.flask.application     generated = self._enter_create(value, createdtime)
2023-02-16 10:51:13.606 38 ERROR keystone.server.flask.application   File "/var/lib/kolla/venv/lib/python3.9/site-packages/dogpile/lock.py", line 178, in _enter_create
2023-02-16 10:51:13.606 38 ERROR keystone.server.flask.application     return self.creator()
2023-02-16 10:51:13.606 38 ERROR keystone.server.flask.application   File "/var/lib/kolla/venv/lib/python3.9/site-packages/dogpile/cache/region.py", line 995, in gen_value
2023-02-16 10:51:13.606 38 ERROR keystone.server.flask.application     created_value = creator(
2023-02-16 10:51:13.606 38 ERROR keystone.server.flask.application   File "/var/lib/kolla/venv/lib/python3.9/site-packages/keystone/assignment/core.py", line 1276, in get_role
2023-02-16 10:51:13.606 38 ERROR keystone.server.flask.application     return self.driver.get_role(role_id)
2023-02-16 10:51:13.606 38 ERROR keystone.server.flask.application   File "/var/lib/kolla/venv/lib/python3.9/site-packages/keystone/assignment/role_backends/sql.py", line 70, in get_role
2023-02-16 10:51:13.606 38 ERROR keystone.server.flask.application     return self._get_role(session, role_id).to_dict()
2023-02-16 10:51:13.606 38 ERROR keystone.server.flask.application   File "/var/lib/kolla/venv/lib/python3.9/site-packages/keystone/assignment/role_backends/sql.py", line 65, in _get_role
2023-02-16 10:51:13.606 38 ERROR keystone.server.flask.application     raise exception.RoleNotFound(role_id=role_id)
2023-02-16 10:51:13.606 38 ERROR keystone.server.flask.application keystone.exception.RoleNotFound: Could not find role: admin.
2023-02-16 10:51:13.606 38 ERROR keystone.server.flask.application 
2023-02-16 10:51:14.690 38 ERROR keystone.server.flask.application [None req-41d4fa4a-0235-46d8-822b-37ccedc9614b fb315d92609f4472883a5f0de5502027 - - all default -] Could not find user: neutron.: keystone.exception.UserNotFound: Could not find user: neutron.
2023-02-16 10:51:14.690 38 ERROR keystone.server.flask.application Traceback (most recent call last):
2023-02-16 10:51:14.690 38 ERROR keystone.server.flask.application   File "/var/lib/kolla/venv/lib/python3.9/site-packages/flask/app.py", line 1820, in full_dispatch_request
2023-02-16 10:51:14.690 38 ERROR keystone.server.flask.application     rv = self.dispatch_request()
2023-02-16 10:51:14.690 38 ERROR keystone.server.flask.application   File "/var/lib/kolla/venv/lib/python3.9/site-packages/flask/app.py", line 1796, in dispatch_request
2023-02-16 10:51:14.690 38 ERROR keystone.server.flask.application     return self.ensure_sync(self.view_functions[rule.endpoint])(**view_args)
2023-02-16 10:51:14.690 38 ERROR keystone.server.flask.application   File "/var/lib/kolla/venv/lib/python3.9/site-packages/flask_restful/__init__.py", line 467, in wrapper
2023-02-16 10:51:14.690 38 ERROR keystone.server.flask.application     resp = resource(*args, **kwargs)
2023-02-16 10:51:14.690 38 ERROR keystone.server.flask.application   File "/var/lib/kolla/venv/lib/python3.9/site-packages/flask/views.py", line 107, in view
2023-02-16 10:51:14.690 38 ERROR keystone.server.flask.application     return current_app.ensure_sync(self.dispatch_request)(**kwargs)
2023-02-16 10:51:14.690 38 ERROR keystone.server.flask.application   File "/var/lib/kolla/venv/lib/python3.9/site-packages/flask_restful/__init__.py", line 582, in dispatch_request
2023-02-16 10:51:14.690 38 ERROR keystone.server.flask.application     resp = meth(*args, **kwargs)
2023-02-16 10:51:14.690 38 ERROR keystone.server.flask.application   File "/var/lib/kolla/venv/lib/python3.9/site-packages/keystone/api/users.py", line 182, in get
2023-02-16 10:51:14.690 38 ERROR keystone.server.flask.application     return self._get_user(user_id)
2023-02-16 10:51:14.690 38 ERROR keystone.server.flask.application   File "/var/lib/kolla/venv/lib/python3.9/site-packages/keystone/api/users.py", line 194, in _get_user
2023-02-16 10:51:14.690 38 ERROR keystone.server.flask.application     ref = PROVIDERS.identity_api.get_user(user_id)
2023-02-16 10:51:14.690 38 ERROR keystone.server.flask.application   File "/var/lib/kolla/venv/lib/python3.9/site-packages/keystone/common/manager.py", line 115, in wrapped
2023-02-16 10:51:14.690 38 ERROR keystone.server.flask.application     __ret_val = __f(*args, **kwargs)
2023-02-16 10:51:14.690 38 ERROR keystone.server.flask.application   File "/var/lib/kolla/venv/lib/python3.9/site-packages/keystone/identity/core.py", line 414, in wrapper
2023-02-16 10:51:14.690 38 ERROR keystone.server.flask.application     return f(self, *args, **kwargs)
2023-02-16 10:51:14.690 38 ERROR keystone.server.flask.application   File "/var/lib/kolla/venv/lib/python3.9/site-packages/keystone/identity/core.py", line 424, in wrapper
2023-02-16 10:51:14.690 38 ERROR keystone.server.flask.application     return f(self, *args, **kwargs)
2023-02-16 10:51:14.690 38 ERROR keystone.server.flask.application   File "/var/lib/kolla/venv/lib/python3.9/site-packages/decorator.py", line 232, in fun
2023-02-16 10:51:14.690 38 ERROR keystone.server.flask.application     return caller(func, *(extras + args), **kw)
2023-02-16 10:51:14.690 38 ERROR keystone.server.flask.application   File "/var/lib/kolla/venv/lib/python3.9/site-packages/dogpile/cache/region.py", line 1577, in get_or_create_for_user_func
2023-02-16 10:51:14.690 38 ERROR keystone.server.flask.application     return self.get_or_create(
2023-02-16 10:51:14.690 38 ERROR keystone.server.flask.application   File "/var/lib/kolla/venv/lib/python3.9/site-packages/dogpile/cache/region.py", line 1042, in get_or_create
2023-02-16 10:51:14.690 38 ERROR keystone.server.flask.application     with Lock(
2023-02-16 10:51:14.690 38 ERROR keystone.server.flask.application   File "/var/lib/kolla/venv/lib/python3.9/site-packages/dogpile/lock.py", line 185, in __enter__
2023-02-16 10:51:14.690 38 ERROR keystone.server.flask.application     return self._enter()
2023-02-16 10:51:14.690 38 ERROR keystone.server.flask.application   File "/var/lib/kolla/venv/lib/python3.9/site-packages/dogpile/lock.py", line 94, in _enter
2023-02-16 10:51:14.690 38 ERROR keystone.server.flask.application     generated = self._enter_create(value, createdtime)
2023-02-16 10:51:14.690 38 ERROR keystone.server.flask.application   File "/var/lib/kolla/venv/lib/python3.9/site-packages/dogpile/lock.py", line 178, in _enter_create
2023-02-16 10:51:14.690 38 ERROR keystone.server.flask.application     return self.creator()
2023-02-16 10:51:14.690 38 ERROR keystone.server.flask.application   File "/var/lib/kolla/venv/lib/python3.9/site-packages/dogpile/cache/region.py", line 995, in gen_value
2023-02-16 10:51:14.690 38 ERROR keystone.server.flask.application     created_value = creator(
2023-02-16 10:51:14.690 38 ERROR keystone.server.flask.application   File "/var/lib/kolla/venv/lib/python3.9/site-packages/keystone/identity/core.py", line 1011, in get_user
2023-02-16 10:51:14.690 38 ERROR keystone.server.flask.application     ref = driver.get_user(entity_id)
2023-02-16 10:51:14.690 38 ERROR keystone.server.flask.application   File "/var/lib/kolla/venv/lib/python3.9/site-packages/keystone/identity/backends/sql.py", line 200, in get_user
2023-02-16 10:51:14.690 38 ERROR keystone.server.flask.application     self._get_user(session, user_id).to_dict())
2023-02-16 10:51:14.690 38 ERROR keystone.server.flask.application   File "/var/lib/kolla/venv/lib/python3.9/site-packages/keystone/identity/backends/sql.py", line 194, in _get_user
2023-02-16 10:51:14.690 38 ERROR keystone.server.flask.application     raise exception.UserNotFound(user_id=user_id)
2023-02-16 10:51:14.690 38 ERROR keystone.server.flask.application keystone.exception.UserNotFound: Could not find user: neutron.
2023-02-16 10:51:14.690 38 ERROR keystone.server.flask.application 
2023-02-16 10:51:15.602 39 ERROR keystone.server.flask.application [None req-ee646383-7c97-4be2-a65c-877963faab33 fb315d92609f4472883a5f0de5502027 - - all default -] Could not find project: service.: keystone.exception.ProjectNotFound: Could not find project: service.
2023-02-16 10:51:15.602 39 ERROR keystone.server.flask.application Traceback (most recent call last):
2023-02-16 10:51:15.602 39 ERROR keystone.server.flask.application   File "/var/lib/kolla/venv/lib/python3.9/site-packages/flask/app.py", line 1820, in full_dispatch_request
2023-02-16 10:51:15.602 39 ERROR keystone.server.flask.application     rv = self.dispatch_request()
2023-02-16 10:51:15.602 39 ERROR keystone.server.flask.application   File "/var/lib/kolla/venv/lib/python3.9/site-packages/flask/app.py", line 1796, in dispatch_request
2023-02-16 10:51:15.602 39 ERROR keystone.server.flask.application     return self.ensure_sync(self.view_functions[rule.endpoint])(**view_args)
2023-02-16 10:51:15.602 39 ERROR keystone.server.flask.application   File "/var/lib/kolla/venv/lib/python3.9/site-packages/flask_restful/__init__.py", line 467, in wrapper
2023-02-16 10:51:15.602 39 ERROR keystone.server.flask.application     resp = resource(*args, **kwargs)
2023-02-16 10:51:15.602 39 ERROR keystone.server.flask.application   File "/var/lib/kolla/venv/lib/python3.9/site-packages/flask/views.py", line 107, in view
2023-02-16 10:51:15.602 39 ERROR keystone.server.flask.application     return current_app.ensure_sync(self.dispatch_request)(**kwargs)
2023-02-16 10:51:15.602 39 ERROR keystone.server.flask.application   File "/var/lib/kolla/venv/lib/python3.9/site-packages/flask_restful/__init__.py", line 582, in dispatch_request
2023-02-16 10:51:15.602 39 ERROR keystone.server.flask.application     resp = meth(*args, **kwargs)
2023-02-16 10:51:15.602 39 ERROR keystone.server.flask.application   File "/var/lib/kolla/venv/lib/python3.9/site-packages/keystone/api/projects.py", line 151, in get
2023-02-16 10:51:15.602 39 ERROR keystone.server.flask.application     return self._get_project(project_id)
2023-02-16 10:51:15.602 39 ERROR keystone.server.flask.application   File "/var/lib/kolla/venv/lib/python3.9/site-packages/keystone/api/projects.py", line 107, in _get_project
2023-02-16 10:51:15.602 39 ERROR keystone.server.flask.application     project = PROVIDERS.resource_api.get_project(project_id)
2023-02-16 10:51:15.602 39 ERROR keystone.server.flask.application   File "/var/lib/kolla/venv/lib/python3.9/site-packages/keystone/common/manager.py", line 115, in wrapped
2023-02-16 10:51:15.602 39 ERROR keystone.server.flask.application     __ret_val = __f(*args, **kwargs)
2023-02-16 10:51:15.602 39 ERROR keystone.server.flask.application   File "/var/lib/kolla/venv/lib/python3.9/site-packages/decorator.py", line 232, in fun
2023-02-16 10:51:15.602 39 ERROR keystone.server.flask.application     return caller(func, *(extras + args), **kw)
2023-02-16 10:51:15.602 39 ERROR keystone.server.flask.application   File "/var/lib/kolla/venv/lib/python3.9/site-packages/dogpile/cache/region.py", line 1577, in get_or_create_for_user_func
2023-02-16 10:51:15.602 39 ERROR keystone.server.flask.application     return self.get_or_create(
2023-02-16 10:51:15.602 39 ERROR keystone.server.flask.application   File "/var/lib/kolla/venv/lib/python3.9/site-packages/dogpile/cache/region.py", line 1042, in get_or_create
2023-02-16 10:51:15.602 39 ERROR keystone.server.flask.application     with Lock(
2023-02-16 10:51:15.602 39 ERROR keystone.server.flask.application   File "/var/lib/kolla/venv/lib/python3.9/site-packages/dogpile/lock.py", line 185, in __enter__
2023-02-16 10:51:15.602 39 ERROR keystone.server.flask.application     return self._enter()
2023-02-16 10:51:15.602 39 ERROR keystone.server.flask.application   File "/var/lib/kolla/venv/lib/python3.9/site-packages/dogpile/lock.py", line 94, in _enter
2023-02-16 10:51:15.602 39 ERROR keystone.server.flask.application     generated = self._enter_create(value, createdtime)
2023-02-16 10:51:15.602 39 ERROR keystone.server.flask.application   File "/var/lib/kolla/venv/lib/python3.9/site-packages/dogpile/lock.py", line 178, in _enter_create
2023-02-16 10:51:15.602 39 ERROR keystone.server.flask.application     return self.creator()
2023-02-16 10:51:15.602 39 ERROR keystone.server.flask.application   File "/var/lib/kolla/venv/lib/python3.9/site-packages/dogpile/cache/region.py", line 995, in gen_value
2023-02-16 10:51:15.602 39 ERROR keystone.server.flask.application     created_value = creator(
2023-02-16 10:51:15.602 39 ERROR keystone.server.flask.application   File "/var/lib/kolla/venv/lib/python3.9/site-packages/keystone/resource/core.py", line 903, in get_project
2023-02-16 10:51:15.602 39 ERROR keystone.server.flask.application     return self.driver.get_project(project_id)
2023-02-16 10:51:15.602 39 ERROR keystone.server.flask.application   File "/var/lib/kolla/venv/lib/python3.9/site-packages/keystone/resource/backends/sql.py", line 49, in get_project
2023-02-16 10:51:15.602 39 ERROR keystone.server.flask.application     return self._get_project(session, project_id).to_dict()
2023-02-16 10:51:15.602 39 ERROR keystone.server.flask.application   File "/var/lib/kolla/venv/lib/python3.9/site-packages/keystone/resource/backends/sql.py", line 44, in _get_project
2023-02-16 10:51:15.602 39 ERROR keystone.server.flask.application     raise exception.ProjectNotFound(project_id=project_id)
2023-02-16 10:51:15.602 39 ERROR keystone.server.flask.application keystone.exception.ProjectNotFound: Could not find project: service.
2023-02-16 10:51:15.602 39 ERROR keystone.server.flask.application 
