2023-04-01 08:35:30.355 23 INFO alembic.runtime.migration [-] Context impl MySQLImpl.
2023-04-01 08:35:30.357 23 INFO alembic.runtime.migration [-] Will assume non-transactional DDL.
2023-04-01 08:35:30.396 23 INFO alembic.runtime.migration [-] Context impl MySQLImpl.
2023-04-01 08:35:30.397 23 INFO alembic.runtime.migration [-] Will assume non-transactional DDL.
2023-04-01 08:35:30.452 23 INFO alembic.runtime.migration [-] Running upgrade  -> 27e647c0fad4, Initial version.
2023-04-01 08:35:31.827 23 INFO alembic.runtime.migration [-] Running upgrade 27e647c0fad4 -> e25ffa003242, Initial no-op Yoga contract migration.
2023-04-01 08:35:31.832 23 INFO alembic.runtime.migration [-] Running upgrade 27e647c0fad4 -> 29e87d24a316, Initial no-op Yoga expand migration.
2023-04-01 08:35:40.094 7 INFO keystone.common.fernet_utils [-] Created a new temporary key: /etc/keystone/fernet-keys/0.tmp
2023-04-01 08:35:40.099 7 INFO keystone.common.fernet_utils [-] Become a valid new key: /etc/keystone/fernet-keys/0
2023-04-01 08:35:40.099 7 INFO keystone.common.fernet_utils [-] Starting key rotation with 1 key files: ['/etc/keystone/fernet-keys/0']
2023-04-01 08:35:40.100 7 INFO keystone.common.fernet_utils [-] Created a new temporary key: /etc/keystone/fernet-keys/0.tmp
2023-04-01 08:35:40.101 7 INFO keystone.common.fernet_utils [-] Current primary key is: 0
2023-04-01 08:35:40.102 7 INFO keystone.common.fernet_utils [-] Next primary key will be: 1
2023-04-01 08:35:40.102 7 INFO keystone.common.fernet_utils [-] Promoted key 0 to be the primary: 1
2023-04-01 08:35:40.103 7 INFO keystone.common.fernet_utils [-] Become a valid new key: /etc/keystone/fernet-keys/0
2023-04-01 08:35:57.642 32 INFO keystone.cmd.bootstrap [None req-9dc8a633-68b4-431d-9eec-8ff30988d253 - - - - - -] Created domain default
2023-04-01 08:35:57.708 32 INFO keystone.cmd.bootstrap [None req-9dc8a633-68b4-431d-9eec-8ff30988d253 - - - - - -] Created project admin
2023-04-01 08:35:58.314 32 INFO keystone.cmd.bootstrap [None req-9dc8a633-68b4-431d-9eec-8ff30988d253 - - - - - -] Created user admin
2023-04-01 08:35:58.335 32 INFO keystone.cmd.bootstrap [None req-9dc8a633-68b4-431d-9eec-8ff30988d253 - - - - - -] Created role reader
2023-04-01 08:35:58.351 32 INFO keystone.cmd.bootstrap [None req-9dc8a633-68b4-431d-9eec-8ff30988d253 - - - - - -] Created role member
2023-04-01 08:35:58.393 32 INFO keystone.cmd.bootstrap [None req-9dc8a633-68b4-431d-9eec-8ff30988d253 - - - - - -] Created implied role where efb999cfb3914903806d67eef26c00b4 implies a8c6fc64a2c7418587f6a85c5c318284
2023-04-01 08:35:58.405 32 INFO keystone.cmd.bootstrap [None req-9dc8a633-68b4-431d-9eec-8ff30988d253 - - - - - -] Created role admin
2023-04-01 08:35:58.427 32 INFO keystone.cmd.bootstrap [None req-9dc8a633-68b4-431d-9eec-8ff30988d253 - - - - - -] Created implied role where 24843e86ac3d49909dc32f6e58a90c46 implies efb999cfb3914903806d67eef26c00b4
2023-04-01 08:35:58.442 32 INFO keystone.cmd.bootstrap [None req-9dc8a633-68b4-431d-9eec-8ff30988d253 - - - - - -] Granted role admin on project admin to user admin.
2023-04-01 08:35:58.450 32 INFO keystone.cmd.bootstrap [None req-9dc8a633-68b4-431d-9eec-8ff30988d253 - - - - - -] Granted role admin on the system to user admin.
2023-04-01 08:35:58.470 32 WARNING py.warnings [None req-9dc8a633-68b4-431d-9eec-8ff30988d253 - - - - - -] /var/lib/kolla/venv/lib/python3.9/site-packages/pycadf/identifier.py:71: UserWarning: Invalid uuid: RegionOne. To ensure interoperability, identifiers should be a valid uuid.
  warnings.warn(('Invalid uuid: %s. To ensure interoperability, '

2023-04-01 08:35:58.477 32 INFO keystone.cmd.bootstrap [None req-9dc8a633-68b4-431d-9eec-8ff30988d253 - - - - - -] Created region RegionOne
2023-04-01 08:35:58.527 32 INFO keystone.cmd.bootstrap [None req-9dc8a633-68b4-431d-9eec-8ff30988d253 - - - - - -] Created public endpoint http://169.16.1.190:5000
2023-04-01 08:35:58.541 32 INFO keystone.cmd.bootstrap [None req-9dc8a633-68b4-431d-9eec-8ff30988d253 - - - - - -] Created internal endpoint http://169.16.1.190:5000
2023-04-01 08:36:22.618 39 WARNING keystone.common.rbac_enforcer.enforcer [None req-7d041bbd-79d1-4caa-af48-1d8593898f4e 0c5e28d4d90748729c288e875518cd25 - - all default -] Deprecated policy rules found. Use oslopolicy-policy-generator and oslopolicy-policy-upgrade to detect and resolve deprecated policies in your configuration.
2023-04-01 08:36:23.346 37 WARNING keystone.common.rbac_enforcer.enforcer [None req-1dffb189-d63b-43c2-b2ac-03e001ab3fa7 0c5e28d4d90748729c288e875518cd25 - - all default -] Deprecated policy rules found. Use oslopolicy-policy-generator and oslopolicy-policy-upgrade to detect and resolve deprecated policies in your configuration.
2023-04-01 08:36:30.859 38 WARNING keystone.common.rbac_enforcer.enforcer [None req-8ce55581-af0b-43a2-81af-9ce412a51ef1 0c5e28d4d90748729c288e875518cd25 - - all default -] Deprecated policy rules found. Use oslopolicy-policy-generator and oslopolicy-policy-upgrade to detect and resolve deprecated policies in your configuration.
2023-04-01 08:37:48.070 39 ERROR keystone.server.flask.application [None req-e2b4207a-9d68-4d5a-ab60-ad52465985e2 0c5e28d4d90748729c288e875518cd25 - - all default -] Could not find project: service.: keystone.exception.ProjectNotFound: Could not find project: service.
2023-04-01 08:37:48.070 39 ERROR keystone.server.flask.application Traceback (most recent call last):
2023-04-01 08:37:48.070 39 ERROR keystone.server.flask.application   File "/var/lib/kolla/venv/lib/python3.9/site-packages/flask/app.py", line 1820, in full_dispatch_request
2023-04-01 08:37:48.070 39 ERROR keystone.server.flask.application     rv = self.dispatch_request()
2023-04-01 08:37:48.070 39 ERROR keystone.server.flask.application   File "/var/lib/kolla/venv/lib/python3.9/site-packages/flask/app.py", line 1796, in dispatch_request
2023-04-01 08:37:48.070 39 ERROR keystone.server.flask.application     return self.ensure_sync(self.view_functions[rule.endpoint])(**view_args)
2023-04-01 08:37:48.070 39 ERROR keystone.server.flask.application   File "/var/lib/kolla/venv/lib/python3.9/site-packages/flask_restful/__init__.py", line 467, in wrapper
2023-04-01 08:37:48.070 39 ERROR keystone.server.flask.application     resp = resource(*args, **kwargs)
2023-04-01 08:37:48.070 39 ERROR keystone.server.flask.application   File "/var/lib/kolla/venv/lib/python3.9/site-packages/flask/views.py", line 107, in view
2023-04-01 08:37:48.070 39 ERROR keystone.server.flask.application     return current_app.ensure_sync(self.dispatch_request)(**kwargs)
2023-04-01 08:37:48.070 39 ERROR keystone.server.flask.application   File "/var/lib/kolla/venv/lib/python3.9/site-packages/flask_restful/__init__.py", line 582, in dispatch_request
2023-04-01 08:37:48.070 39 ERROR keystone.server.flask.application     resp = meth(*args, **kwargs)
2023-04-01 08:37:48.070 39 ERROR keystone.server.flask.application   File "/var/lib/kolla/venv/lib/python3.9/site-packages/keystone/api/projects.py", line 151, in get
2023-04-01 08:37:48.070 39 ERROR keystone.server.flask.application     return self._get_project(project_id)
2023-04-01 08:37:48.070 39 ERROR keystone.server.flask.application   File "/var/lib/kolla/venv/lib/python3.9/site-packages/keystone/api/projects.py", line 107, in _get_project
2023-04-01 08:37:48.070 39 ERROR keystone.server.flask.application     project = PROVIDERS.resource_api.get_project(project_id)
2023-04-01 08:37:48.070 39 ERROR keystone.server.flask.application   File "/var/lib/kolla/venv/lib/python3.9/site-packages/keystone/common/manager.py", line 115, in wrapped
2023-04-01 08:37:48.070 39 ERROR keystone.server.flask.application     __ret_val = __f(*args, **kwargs)
2023-04-01 08:37:48.070 39 ERROR keystone.server.flask.application   File "/var/lib/kolla/venv/lib/python3.9/site-packages/decorator.py", line 232, in fun
2023-04-01 08:37:48.070 39 ERROR keystone.server.flask.application     return caller(func, *(extras + args), **kw)
2023-04-01 08:37:48.070 39 ERROR keystone.server.flask.application   File "/var/lib/kolla/venv/lib/python3.9/site-packages/dogpile/cache/region.py", line 1577, in get_or_create_for_user_func
2023-04-01 08:37:48.070 39 ERROR keystone.server.flask.application     return self.get_or_create(
2023-04-01 08:37:48.070 39 ERROR keystone.server.flask.application   File "/var/lib/kolla/venv/lib/python3.9/site-packages/dogpile/cache/region.py", line 1042, in get_or_create
2023-04-01 08:37:48.070 39 ERROR keystone.server.flask.application     with Lock(
2023-04-01 08:37:48.070 39 ERROR keystone.server.flask.application   File "/var/lib/kolla/venv/lib/python3.9/site-packages/dogpile/lock.py", line 185, in __enter__
2023-04-01 08:37:48.070 39 ERROR keystone.server.flask.application     return self._enter()
2023-04-01 08:37:48.070 39 ERROR keystone.server.flask.application   File "/var/lib/kolla/venv/lib/python3.9/site-packages/dogpile/lock.py", line 94, in _enter
2023-04-01 08:37:48.070 39 ERROR keystone.server.flask.application     generated = self._enter_create(value, createdtime)
2023-04-01 08:37:48.070 39 ERROR keystone.server.flask.application   File "/var/lib/kolla/venv/lib/python3.9/site-packages/dogpile/lock.py", line 178, in _enter_create
2023-04-01 08:37:48.070 39 ERROR keystone.server.flask.application     return self.creator()
2023-04-01 08:37:48.070 39 ERROR keystone.server.flask.application   File "/var/lib/kolla/venv/lib/python3.9/site-packages/dogpile/cache/region.py", line 995, in gen_value
2023-04-01 08:37:48.070 39 ERROR keystone.server.flask.application     created_value = creator(
2023-04-01 08:37:48.070 39 ERROR keystone.server.flask.application   File "/var/lib/kolla/venv/lib/python3.9/site-packages/keystone/resource/core.py", line 903, in get_project
2023-04-01 08:37:48.070 39 ERROR keystone.server.flask.application     return self.driver.get_project(project_id)
2023-04-01 08:37:48.070 39 ERROR keystone.server.flask.application   File "/var/lib/kolla/venv/lib/python3.9/site-packages/keystone/resource/backends/sql.py", line 49, in get_project
2023-04-01 08:37:48.070 39 ERROR keystone.server.flask.application     return self._get_project(session, project_id).to_dict()
2023-04-01 08:37:48.070 39 ERROR keystone.server.flask.application   File "/var/lib/kolla/venv/lib/python3.9/site-packages/keystone/resource/backends/sql.py", line 44, in _get_project
2023-04-01 08:37:48.070 39 ERROR keystone.server.flask.application     raise exception.ProjectNotFound(project_id=project_id)
2023-04-01 08:37:48.070 39 ERROR keystone.server.flask.application keystone.exception.ProjectNotFound: Could not find project: service.
2023-04-01 08:37:48.070 39 ERROR keystone.server.flask.application 
2023-04-01 08:37:56.957 38 ERROR keystone.server.flask.application [None req-6cd7b66d-1e3e-41d2-851c-e503b2420ba2 0c5e28d4d90748729c288e875518cd25 - - all default -] Could not find project: service.: keystone.exception.ProjectNotFound: Could not find project: service.
2023-04-01 08:37:56.957 38 ERROR keystone.server.flask.application Traceback (most recent call last):
2023-04-01 08:37:56.957 38 ERROR keystone.server.flask.application   File "/var/lib/kolla/venv/lib/python3.9/site-packages/flask/app.py", line 1820, in full_dispatch_request
2023-04-01 08:37:56.957 38 ERROR keystone.server.flask.application     rv = self.dispatch_request()
2023-04-01 08:37:56.957 38 ERROR keystone.server.flask.application   File "/var/lib/kolla/venv/lib/python3.9/site-packages/flask/app.py", line 1796, in dispatch_request
2023-04-01 08:37:56.957 38 ERROR keystone.server.flask.application     return self.ensure_sync(self.view_functions[rule.endpoint])(**view_args)
2023-04-01 08:37:56.957 38 ERROR keystone.server.flask.application   File "/var/lib/kolla/venv/lib/python3.9/site-packages/flask_restful/__init__.py", line 467, in wrapper
2023-04-01 08:37:56.957 38 ERROR keystone.server.flask.application     resp = resource(*args, **kwargs)
2023-04-01 08:37:56.957 38 ERROR keystone.server.flask.application   File "/var/lib/kolla/venv/lib/python3.9/site-packages/flask/views.py", line 107, in view
2023-04-01 08:37:56.957 38 ERROR keystone.server.flask.application     return current_app.ensure_sync(self.dispatch_request)(**kwargs)
2023-04-01 08:37:56.957 38 ERROR keystone.server.flask.application   File "/var/lib/kolla/venv/lib/python3.9/site-packages/flask_restful/__init__.py", line 582, in dispatch_request
2023-04-01 08:37:56.957 38 ERROR keystone.server.flask.application     resp = meth(*args, **kwargs)
2023-04-01 08:37:56.957 38 ERROR keystone.server.flask.application   File "/var/lib/kolla/venv/lib/python3.9/site-packages/keystone/api/projects.py", line 151, in get
2023-04-01 08:37:56.957 38 ERROR keystone.server.flask.application     return self._get_project(project_id)
2023-04-01 08:37:56.957 38 ERROR keystone.server.flask.application   File "/var/lib/kolla/venv/lib/python3.9/site-packages/keystone/api/projects.py", line 107, in _get_project
2023-04-01 08:37:56.957 38 ERROR keystone.server.flask.application     project = PROVIDERS.resource_api.get_project(project_id)
2023-04-01 08:37:56.957 38 ERROR keystone.server.flask.application   File "/var/lib/kolla/venv/lib/python3.9/site-packages/keystone/common/manager.py", line 115, in wrapped
2023-04-01 08:37:56.957 38 ERROR keystone.server.flask.application     __ret_val = __f(*args, **kwargs)
2023-04-01 08:37:56.957 38 ERROR keystone.server.flask.application   File "/var/lib/kolla/venv/lib/python3.9/site-packages/decorator.py", line 232, in fun
2023-04-01 08:37:56.957 38 ERROR keystone.server.flask.application     return caller(func, *(extras + args), **kw)
2023-04-01 08:37:56.957 38 ERROR keystone.server.flask.application   File "/var/lib/kolla/venv/lib/python3.9/site-packages/dogpile/cache/region.py", line 1577, in get_or_create_for_user_func
2023-04-01 08:37:56.957 38 ERROR keystone.server.flask.application     return self.get_or_create(
2023-04-01 08:37:56.957 38 ERROR keystone.server.flask.application   File "/var/lib/kolla/venv/lib/python3.9/site-packages/dogpile/cache/region.py", line 1042, in get_or_create
2023-04-01 08:37:56.957 38 ERROR keystone.server.flask.application     with Lock(
2023-04-01 08:37:56.957 38 ERROR keystone.server.flask.application   File "/var/lib/kolla/venv/lib/python3.9/site-packages/dogpile/lock.py", line 185, in __enter__
2023-04-01 08:37:56.957 38 ERROR keystone.server.flask.application     return self._enter()
2023-04-01 08:37:56.957 38 ERROR keystone.server.flask.application   File "/var/lib/kolla/venv/lib/python3.9/site-packages/dogpile/lock.py", line 94, in _enter
2023-04-01 08:37:56.957 38 ERROR keystone.server.flask.application     generated = self._enter_create(value, createdtime)
2023-04-01 08:37:56.957 38 ERROR keystone.server.flask.application   File "/var/lib/kolla/venv/lib/python3.9/site-packages/dogpile/lock.py", line 178, in _enter_create
2023-04-01 08:37:56.957 38 ERROR keystone.server.flask.application     return self.creator()
2023-04-01 08:37:56.957 38 ERROR keystone.server.flask.application   File "/var/lib/kolla/venv/lib/python3.9/site-packages/dogpile/cache/region.py", line 995, in gen_value
2023-04-01 08:37:56.957 38 ERROR keystone.server.flask.application     created_value = creator(
2023-04-01 08:37:56.957 38 ERROR keystone.server.flask.application   File "/var/lib/kolla/venv/lib/python3.9/site-packages/keystone/resource/core.py", line 903, in get_project
2023-04-01 08:37:56.957 38 ERROR keystone.server.flask.application     return self.driver.get_project(project_id)
2023-04-01 08:37:56.957 38 ERROR keystone.server.flask.application   File "/var/lib/kolla/venv/lib/python3.9/site-packages/keystone/resource/backends/sql.py", line 49, in get_project
2023-04-01 08:37:56.957 38 ERROR keystone.server.flask.application     return self._get_project(session, project_id).to_dict()
2023-04-01 08:37:56.957 38 ERROR keystone.server.flask.application   File "/var/lib/kolla/venv/lib/python3.9/site-packages/keystone/resource/backends/sql.py", line 44, in _get_project
2023-04-01 08:37:56.957 38 ERROR keystone.server.flask.application     raise exception.ProjectNotFound(project_id=project_id)
2023-04-01 08:37:56.957 38 ERROR keystone.server.flask.application keystone.exception.ProjectNotFound: Could not find project: service.
2023-04-01 08:37:56.957 38 ERROR keystone.server.flask.application 
2023-04-01 08:38:11.314 38 ERROR keystone.server.flask.application [None req-8985e659-4c87-45ff-8b53-e1f8029d4fb6 0c5e28d4d90748729c288e875518cd25 - - all default -] Could not find role: admin.: keystone.exception.RoleNotFound: Could not find role: admin.
2023-04-01 08:38:11.314 38 ERROR keystone.server.flask.application Traceback (most recent call last):
2023-04-01 08:38:11.314 38 ERROR keystone.server.flask.application   File "/var/lib/kolla/venv/lib/python3.9/site-packages/flask/app.py", line 1820, in full_dispatch_request
2023-04-01 08:38:11.314 38 ERROR keystone.server.flask.application     rv = self.dispatch_request()
2023-04-01 08:38:11.314 38 ERROR keystone.server.flask.application   File "/var/lib/kolla/venv/lib/python3.9/site-packages/flask/app.py", line 1796, in dispatch_request
2023-04-01 08:38:11.314 38 ERROR keystone.server.flask.application     return self.ensure_sync(self.view_functions[rule.endpoint])(**view_args)
2023-04-01 08:38:11.314 38 ERROR keystone.server.flask.application   File "/var/lib/kolla/venv/lib/python3.9/site-packages/flask_restful/__init__.py", line 467, in wrapper
2023-04-01 08:38:11.314 38 ERROR keystone.server.flask.application     resp = resource(*args, **kwargs)
2023-04-01 08:38:11.314 38 ERROR keystone.server.flask.application   File "/var/lib/kolla/venv/lib/python3.9/site-packages/flask/views.py", line 107, in view
2023-04-01 08:38:11.314 38 ERROR keystone.server.flask.application     return current_app.ensure_sync(self.dispatch_request)(**kwargs)
2023-04-01 08:38:11.314 38 ERROR keystone.server.flask.application   File "/var/lib/kolla/venv/lib/python3.9/site-packages/flask_restful/__init__.py", line 582, in dispatch_request
2023-04-01 08:38:11.314 38 ERROR keystone.server.flask.application     resp = meth(*args, **kwargs)
2023-04-01 08:38:11.314 38 ERROR keystone.server.flask.application   File "/var/lib/kolla/venv/lib/python3.9/site-packages/keystone/api/roles.py", line 50, in get
2023-04-01 08:38:11.314 38 ERROR keystone.server.flask.application     return self._get_role(role_id)
2023-04-01 08:38:11.314 38 ERROR keystone.server.flask.application   File "/var/lib/kolla/venv/lib/python3.9/site-packages/keystone/api/roles.py", line 70, in _get_role
2023-04-01 08:38:11.314 38 ERROR keystone.server.flask.application     ENFORCER.enforce_call(action='identity:get_role')
2023-04-01 08:38:11.314 38 ERROR keystone.server.flask.application   File "/var/lib/kolla/venv/lib/python3.9/site-packages/keystone/common/rbac_enforcer/enforcer.py", line 402, in enforce_call
2023-04-01 08:38:11.314 38 ERROR keystone.server.flask.application     policy_dict.update(cls._extract_member_target_data(
2023-04-01 08:38:11.314 38 ERROR keystone.server.flask.application   File "/var/lib/kolla/venv/lib/python3.9/site-packages/keystone/common/rbac_enforcer/enforcer.py", line 234, in _extract_member_target_data
2023-04-01 08:38:11.314 38 ERROR keystone.server.flask.application     member_name: func(flask.request.view_args[key])
2023-04-01 08:38:11.314 38 ERROR keystone.server.flask.application   File "/var/lib/kolla/venv/lib/python3.9/site-packages/keystone/common/manager.py", line 115, in wrapped
2023-04-01 08:38:11.314 38 ERROR keystone.server.flask.application     __ret_val = __f(*args, **kwargs)
2023-04-01 08:38:11.314 38 ERROR keystone.server.flask.application   File "/var/lib/kolla/venv/lib/python3.9/site-packages/decorator.py", line 232, in fun
2023-04-01 08:38:11.314 38 ERROR keystone.server.flask.application     return caller(func, *(extras + args), **kw)
2023-04-01 08:38:11.314 38 ERROR keystone.server.flask.application   File "/var/lib/kolla/venv/lib/python3.9/site-packages/dogpile/cache/region.py", line 1577, in get_or_create_for_user_func
2023-04-01 08:38:11.314 38 ERROR keystone.server.flask.application     return self.get_or_create(
2023-04-01 08:38:11.314 38 ERROR keystone.server.flask.application   File "/var/lib/kolla/venv/lib/python3.9/site-packages/dogpile/cache/region.py", line 1042, in get_or_create
2023-04-01 08:38:11.314 38 ERROR keystone.server.flask.application     with Lock(
2023-04-01 08:38:11.314 38 ERROR keystone.server.flask.application   File "/var/lib/kolla/venv/lib/python3.9/site-packages/dogpile/lock.py", line 185, in __enter__
2023-04-01 08:38:11.314 38 ERROR keystone.server.flask.application     return self._enter()
2023-04-01 08:38:11.314 38 ERROR keystone.server.flask.application   File "/var/lib/kolla/venv/lib/python3.9/site-packages/dogpile/lock.py", line 94, in _enter
2023-04-01 08:38:11.314 38 ERROR keystone.server.flask.application     generated = self._enter_create(value, createdtime)
2023-04-01 08:38:11.314 38 ERROR keystone.server.flask.application   File "/var/lib/kolla/venv/lib/python3.9/site-packages/dogpile/lock.py", line 178, in _enter_create
2023-04-01 08:38:11.314 38 ERROR keystone.server.flask.application     return self.creator()
2023-04-01 08:38:11.314 38 ERROR keystone.server.flask.application   File "/var/lib/kolla/venv/lib/python3.9/site-packages/dogpile/cache/region.py", line 995, in gen_value
2023-04-01 08:38:11.314 38 ERROR keystone.server.flask.application     created_value = creator(
2023-04-01 08:38:11.314 38 ERROR keystone.server.flask.application   File "/var/lib/kolla/venv/lib/python3.9/site-packages/keystone/assignment/core.py", line 1276, in get_role
2023-04-01 08:38:11.314 38 ERROR keystone.server.flask.application     return self.driver.get_role(role_id)
2023-04-01 08:38:11.314 38 ERROR keystone.server.flask.application   File "/var/lib/kolla/venv/lib/python3.9/site-packages/keystone/assignment/role_backends/sql.py", line 70, in get_role
2023-04-01 08:38:11.314 38 ERROR keystone.server.flask.application     return self._get_role(session, role_id).to_dict()
2023-04-01 08:38:11.314 38 ERROR keystone.server.flask.application   File "/var/lib/kolla/venv/lib/python3.9/site-packages/keystone/assignment/role_backends/sql.py", line 65, in _get_role
2023-04-01 08:38:11.314 38 ERROR keystone.server.flask.application     raise exception.RoleNotFound(role_id=role_id)
2023-04-01 08:38:11.314 38 ERROR keystone.server.flask.application keystone.exception.RoleNotFound: Could not find role: admin.
2023-04-01 08:38:11.314 38 ERROR keystone.server.flask.application 
2023-04-01 08:38:12.739 38 ERROR keystone.server.flask.application [None req-807caa1f-eb16-4a1d-8867-f60efc8e5a8e 0c5e28d4d90748729c288e875518cd25 - - all default -] Could not find user: ironic.: keystone.exception.UserNotFound: Could not find user: ironic.
2023-04-01 08:38:12.739 38 ERROR keystone.server.flask.application Traceback (most recent call last):
2023-04-01 08:38:12.739 38 ERROR keystone.server.flask.application   File "/var/lib/kolla/venv/lib/python3.9/site-packages/flask/app.py", line 1820, in full_dispatch_request
2023-04-01 08:38:12.739 38 ERROR keystone.server.flask.application     rv = self.dispatch_request()
2023-04-01 08:38:12.739 38 ERROR keystone.server.flask.application   File "/var/lib/kolla/venv/lib/python3.9/site-packages/flask/app.py", line 1796, in dispatch_request
2023-04-01 08:38:12.739 38 ERROR keystone.server.flask.application     return self.ensure_sync(self.view_functions[rule.endpoint])(**view_args)
2023-04-01 08:38:12.739 38 ERROR keystone.server.flask.application   File "/var/lib/kolla/venv/lib/python3.9/site-packages/flask_restful/__init__.py", line 467, in wrapper
2023-04-01 08:38:12.739 38 ERROR keystone.server.flask.application     resp = resource(*args, **kwargs)
2023-04-01 08:38:12.739 38 ERROR keystone.server.flask.application   File "/var/lib/kolla/venv/lib/python3.9/site-packages/flask/views.py", line 107, in view
2023-04-01 08:38:12.739 38 ERROR keystone.server.flask.application     return current_app.ensure_sync(self.dispatch_request)(**kwargs)
2023-04-01 08:38:12.739 38 ERROR keystone.server.flask.application   File "/var/lib/kolla/venv/lib/python3.9/site-packages/flask_restful/__init__.py", line 582, in dispatch_request
2023-04-01 08:38:12.739 38 ERROR keystone.server.flask.application     resp = meth(*args, **kwargs)
2023-04-01 08:38:12.739 38 ERROR keystone.server.flask.application   File "/var/lib/kolla/venv/lib/python3.9/site-packages/keystone/api/users.py", line 182, in get
2023-04-01 08:38:12.739 38 ERROR keystone.server.flask.application     return self._get_user(user_id)
2023-04-01 08:38:12.739 38 ERROR keystone.server.flask.application   File "/var/lib/kolla/venv/lib/python3.9/site-packages/keystone/api/users.py", line 194, in _get_user
2023-04-01 08:38:12.739 38 ERROR keystone.server.flask.application     ref = PROVIDERS.identity_api.get_user(user_id)
2023-04-01 08:38:12.739 38 ERROR keystone.server.flask.application   File "/var/lib/kolla/venv/lib/python3.9/site-packages/keystone/common/manager.py", line 115, in wrapped
2023-04-01 08:38:12.739 38 ERROR keystone.server.flask.application     __ret_val = __f(*args, **kwargs)
2023-04-01 08:38:12.739 38 ERROR keystone.server.flask.application   File "/var/lib/kolla/venv/lib/python3.9/site-packages/keystone/identity/core.py", line 414, in wrapper
2023-04-01 08:38:12.739 38 ERROR keystone.server.flask.application     return f(self, *args, **kwargs)
2023-04-01 08:38:12.739 38 ERROR keystone.server.flask.application   File "/var/lib/kolla/venv/lib/python3.9/site-packages/keystone/identity/core.py", line 424, in wrapper
2023-04-01 08:38:12.739 38 ERROR keystone.server.flask.application     return f(self, *args, **kwargs)
2023-04-01 08:38:12.739 38 ERROR keystone.server.flask.application   File "/var/lib/kolla/venv/lib/python3.9/site-packages/decorator.py", line 232, in fun
2023-04-01 08:38:12.739 38 ERROR keystone.server.flask.application     return caller(func, *(extras + args), **kw)
2023-04-01 08:38:12.739 38 ERROR keystone.server.flask.application   File "/var/lib/kolla/venv/lib/python3.9/site-packages/dogpile/cache/region.py", line 1577, in get_or_create_for_user_func
2023-04-01 08:38:12.739 38 ERROR keystone.server.flask.application     return self.get_or_create(
2023-04-01 08:38:12.739 38 ERROR keystone.server.flask.application   File "/var/lib/kolla/venv/lib/python3.9/site-packages/dogpile/cache/region.py", line 1042, in get_or_create
2023-04-01 08:38:12.739 38 ERROR keystone.server.flask.application     with Lock(
2023-04-01 08:38:12.739 38 ERROR keystone.server.flask.application   File "/var/lib/kolla/venv/lib/python3.9/site-packages/dogpile/lock.py", line 185, in __enter__
2023-04-01 08:38:12.739 38 ERROR keystone.server.flask.application     return self._enter()
2023-04-01 08:38:12.739 38 ERROR keystone.server.flask.application   File "/var/lib/kolla/venv/lib/python3.9/site-packages/dogpile/lock.py", line 94, in _enter
2023-04-01 08:38:12.739 38 ERROR keystone.server.flask.application     generated = self._enter_create(value, createdtime)
2023-04-01 08:38:12.739 38 ERROR keystone.server.flask.application   File "/var/lib/kolla/venv/lib/python3.9/site-packages/dogpile/lock.py", line 178, in _enter_create
2023-04-01 08:38:12.739 38 ERROR keystone.server.flask.application     return self.creator()
2023-04-01 08:38:12.739 38 ERROR keystone.server.flask.application   File "/var/lib/kolla/venv/lib/python3.9/site-packages/dogpile/cache/region.py", line 995, in gen_value
2023-04-01 08:38:12.739 38 ERROR keystone.server.flask.application     created_value = creator(
2023-04-01 08:38:12.739 38 ERROR keystone.server.flask.application   File "/var/lib/kolla/venv/lib/python3.9/site-packages/keystone/identity/core.py", line 1011, in get_user
2023-04-01 08:38:12.739 38 ERROR keystone.server.flask.application     ref = driver.get_user(entity_id)
2023-04-01 08:38:12.739 38 ERROR keystone.server.flask.application   File "/var/lib/kolla/venv/lib/python3.9/site-packages/keystone/identity/backends/sql.py", line 200, in get_user
2023-04-01 08:38:12.739 38 ERROR keystone.server.flask.application     self._get_user(session, user_id).to_dict())
2023-04-01 08:38:12.739 38 ERROR keystone.server.flask.application   File "/var/lib/kolla/venv/lib/python3.9/site-packages/keystone/identity/backends/sql.py", line 194, in _get_user
2023-04-01 08:38:12.739 38 ERROR keystone.server.flask.application     raise exception.UserNotFound(user_id=user_id)
2023-04-01 08:38:12.739 38 ERROR keystone.server.flask.application keystone.exception.UserNotFound: Could not find user: ironic.
2023-04-01 08:38:12.739 38 ERROR keystone.server.flask.application 
2023-04-01 08:38:13.602 37 ERROR keystone.server.flask.application [None req-d473683c-0a06-49a8-b02e-1c804e714822 0c5e28d4d90748729c288e875518cd25 - - all default -] Could not find project: service.: keystone.exception.ProjectNotFound: Could not find project: service.
2023-04-01 08:38:13.602 37 ERROR keystone.server.flask.application Traceback (most recent call last):
2023-04-01 08:38:13.602 37 ERROR keystone.server.flask.application   File "/var/lib/kolla/venv/lib/python3.9/site-packages/flask/app.py", line 1820, in full_dispatch_request
2023-04-01 08:38:13.602 37 ERROR keystone.server.flask.application     rv = self.dispatch_request()
2023-04-01 08:38:13.602 37 ERROR keystone.server.flask.application   File "/var/lib/kolla/venv/lib/python3.9/site-packages/flask/app.py", line 1796, in dispatch_request
2023-04-01 08:38:13.602 37 ERROR keystone.server.flask.application     return self.ensure_sync(self.view_functions[rule.endpoint])(**view_args)
2023-04-01 08:38:13.602 37 ERROR keystone.server.flask.application   File "/var/lib/kolla/venv/lib/python3.9/site-packages/flask_restful/__init__.py", line 467, in wrapper
2023-04-01 08:38:13.602 37 ERROR keystone.server.flask.application     resp = resource(*args, **kwargs)
2023-04-01 08:38:13.602 37 ERROR keystone.server.flask.application   File "/var/lib/kolla/venv/lib/python3.9/site-packages/flask/views.py", line 107, in view
2023-04-01 08:38:13.602 37 ERROR keystone.server.flask.application     return current_app.ensure_sync(self.dispatch_request)(**kwargs)
2023-04-01 08:38:13.602 37 ERROR keystone.server.flask.application   File "/var/lib/kolla/venv/lib/python3.9/site-packages/flask_restful/__init__.py", line 582, in dispatch_request
2023-04-01 08:38:13.602 37 ERROR keystone.server.flask.application     resp = meth(*args, **kwargs)
2023-04-01 08:38:13.602 37 ERROR keystone.server.flask.application   File "/var/lib/kolla/venv/lib/python3.9/site-packages/keystone/api/projects.py", line 151, in get
2023-04-01 08:38:13.602 37 ERROR keystone.server.flask.application     return self._get_project(project_id)
2023-04-01 08:38:13.602 37 ERROR keystone.server.flask.application   File "/var/lib/kolla/venv/lib/python3.9/site-packages/keystone/api/projects.py", line 107, in _get_project
2023-04-01 08:38:13.602 37 ERROR keystone.server.flask.application     project = PROVIDERS.resource_api.get_project(project_id)
2023-04-01 08:38:13.602 37 ERROR keystone.server.flask.application   File "/var/lib/kolla/venv/lib/python3.9/site-packages/keystone/common/manager.py", line 115, in wrapped
2023-04-01 08:38:13.602 37 ERROR keystone.server.flask.application     __ret_val = __f(*args, **kwargs)
2023-04-01 08:38:13.602 37 ERROR keystone.server.flask.application   File "/var/lib/kolla/venv/lib/python3.9/site-packages/decorator.py", line 232, in fun
2023-04-01 08:38:13.602 37 ERROR keystone.server.flask.application     return caller(func, *(extras + args), **kw)
2023-04-01 08:38:13.602 37 ERROR keystone.server.flask.application   File "/var/lib/kolla/venv/lib/python3.9/site-packages/dogpile/cache/region.py", line 1577, in get_or_create_for_user_func
2023-04-01 08:38:13.602 37 ERROR keystone.server.flask.application     return self.get_or_create(
2023-04-01 08:38:13.602 37 ERROR keystone.server.flask.application   File "/var/lib/kolla/venv/lib/python3.9/site-packages/dogpile/cache/region.py", line 1042, in get_or_create
2023-04-01 08:38:13.602 37 ERROR keystone.server.flask.application     with Lock(
2023-04-01 08:38:13.602 37 ERROR keystone.server.flask.application   File "/var/lib/kolla/venv/lib/python3.9/site-packages/dogpile/lock.py", line 185, in __enter__
2023-04-01 08:38:13.602 37 ERROR keystone.server.flask.application     return self._enter()
2023-04-01 08:38:13.602 37 ERROR keystone.server.flask.application   File "/var/lib/kolla/venv/lib/python3.9/site-packages/dogpile/lock.py", line 94, in _enter
2023-04-01 08:38:13.602 37 ERROR keystone.server.flask.application     generated = self._enter_create(value, createdtime)
2023-04-01 08:38:13.602 37 ERROR keystone.server.flask.application   File "/var/lib/kolla/venv/lib/python3.9/site-packages/dogpile/lock.py", line 178, in _enter_create
2023-04-01 08:38:13.602 37 ERROR keystone.server.flask.application     return self.creator()
2023-04-01 08:38:13.602 37 ERROR keystone.server.flask.application   File "/var/lib/kolla/venv/lib/python3.9/site-packages/dogpile/cache/region.py", line 995, in gen_value
2023-04-01 08:38:13.602 37 ERROR keystone.server.flask.application     created_value = creator(
2023-04-01 08:38:13.602 37 ERROR keystone.server.flask.application   File "/var/lib/kolla/venv/lib/python3.9/site-packages/keystone/resource/core.py", line 903, in get_project
2023-04-01 08:38:13.602 37 ERROR keystone.server.flask.application     return self.driver.get_project(project_id)
2023-04-01 08:38:13.602 37 ERROR keystone.server.flask.application   File "/var/lib/kolla/venv/lib/python3.9/site-packages/keystone/resource/backends/sql.py", line 49, in get_project
2023-04-01 08:38:13.602 37 ERROR keystone.server.flask.application     return self._get_project(session, project_id).to_dict()
2023-04-01 08:38:13.602 37 ERROR keystone.server.flask.application   File "/var/lib/kolla/venv/lib/python3.9/site-packages/keystone/resource/backends/sql.py", line 44, in _get_project
2023-04-01 08:38:13.602 37 ERROR keystone.server.flask.application     raise exception.ProjectNotFound(project_id=project_id)
2023-04-01 08:38:13.602 37 ERROR keystone.server.flask.application keystone.exception.ProjectNotFound: Could not find project: service.
2023-04-01 08:38:13.602 37 ERROR keystone.server.flask.application 
2023-04-01 08:38:23.478 39 ERROR keystone.server.flask.application [None req-92ede152-50ec-41ea-bd1f-378bacefa4ee 0c5e28d4d90748729c288e875518cd25 - - all default -] Could not find role: admin.: keystone.exception.RoleNotFound: Could not find role: admin.
2023-04-01 08:38:23.478 39 ERROR keystone.server.flask.application Traceback (most recent call last):
2023-04-01 08:38:23.478 39 ERROR keystone.server.flask.application   File "/var/lib/kolla/venv/lib/python3.9/site-packages/flask/app.py", line 1820, in full_dispatch_request
2023-04-01 08:38:23.478 39 ERROR keystone.server.flask.application     rv = self.dispatch_request()
2023-04-01 08:38:23.478 39 ERROR keystone.server.flask.application   File "/var/lib/kolla/venv/lib/python3.9/site-packages/flask/app.py", line 1796, in dispatch_request
2023-04-01 08:38:23.478 39 ERROR keystone.server.flask.application     return self.ensure_sync(self.view_functions[rule.endpoint])(**view_args)
2023-04-01 08:38:23.478 39 ERROR keystone.server.flask.application   File "/var/lib/kolla/venv/lib/python3.9/site-packages/flask_restful/__init__.py", line 467, in wrapper
2023-04-01 08:38:23.478 39 ERROR keystone.server.flask.application     resp = resource(*args, **kwargs)
2023-04-01 08:38:23.478 39 ERROR keystone.server.flask.application   File "/var/lib/kolla/venv/lib/python3.9/site-packages/flask/views.py", line 107, in view
2023-04-01 08:38:23.478 39 ERROR keystone.server.flask.application     return current_app.ensure_sync(self.dispatch_request)(**kwargs)
2023-04-01 08:38:23.478 39 ERROR keystone.server.flask.application   File "/var/lib/kolla/venv/lib/python3.9/site-packages/flask_restful/__init__.py", line 582, in dispatch_request
2023-04-01 08:38:23.478 39 ERROR keystone.server.flask.application     resp = meth(*args, **kwargs)
2023-04-01 08:38:23.478 39 ERROR keystone.server.flask.application   File "/var/lib/kolla/venv/lib/python3.9/site-packages/keystone/api/roles.py", line 50, in get
2023-04-01 08:38:23.478 39 ERROR keystone.server.flask.application     return self._get_role(role_id)
2023-04-01 08:38:23.478 39 ERROR keystone.server.flask.application   File "/var/lib/kolla/venv/lib/python3.9/site-packages/keystone/api/roles.py", line 70, in _get_role
2023-04-01 08:38:23.478 39 ERROR keystone.server.flask.application     ENFORCER.enforce_call(action='identity:get_role')
2023-04-01 08:38:23.478 39 ERROR keystone.server.flask.application   File "/var/lib/kolla/venv/lib/python3.9/site-packages/keystone/common/rbac_enforcer/enforcer.py", line 402, in enforce_call
2023-04-01 08:38:23.478 39 ERROR keystone.server.flask.application     policy_dict.update(cls._extract_member_target_data(
2023-04-01 08:38:23.478 39 ERROR keystone.server.flask.application   File "/var/lib/kolla/venv/lib/python3.9/site-packages/keystone/common/rbac_enforcer/enforcer.py", line 234, in _extract_member_target_data
2023-04-01 08:38:23.478 39 ERROR keystone.server.flask.application     member_name: func(flask.request.view_args[key])
2023-04-01 08:38:23.478 39 ERROR keystone.server.flask.application   File "/var/lib/kolla/venv/lib/python3.9/site-packages/keystone/common/manager.py", line 115, in wrapped
2023-04-01 08:38:23.478 39 ERROR keystone.server.flask.application     __ret_val = __f(*args, **kwargs)
2023-04-01 08:38:23.478 39 ERROR keystone.server.flask.application   File "/var/lib/kolla/venv/lib/python3.9/site-packages/decorator.py", line 232, in fun
2023-04-01 08:38:23.478 39 ERROR keystone.server.flask.application     return caller(func, *(extras + args), **kw)
2023-04-01 08:38:23.478 39 ERROR keystone.server.flask.application   File "/var/lib/kolla/venv/lib/python3.9/site-packages/dogpile/cache/region.py", line 1577, in get_or_create_for_user_func
2023-04-01 08:38:23.478 39 ERROR keystone.server.flask.application     return self.get_or_create(
2023-04-01 08:38:23.478 39 ERROR keystone.server.flask.application   File "/var/lib/kolla/venv/lib/python3.9/site-packages/dogpile/cache/region.py", line 1042, in get_or_create
2023-04-01 08:38:23.478 39 ERROR keystone.server.flask.application     with Lock(
2023-04-01 08:38:23.478 39 ERROR keystone.server.flask.application   File "/var/lib/kolla/venv/lib/python3.9/site-packages/dogpile/lock.py", line 185, in __enter__
2023-04-01 08:38:23.478 39 ERROR keystone.server.flask.application     return self._enter()
2023-04-01 08:38:23.478 39 ERROR keystone.server.flask.application   File "/var/lib/kolla/venv/lib/python3.9/site-packages/dogpile/lock.py", line 94, in _enter
2023-04-01 08:38:23.478 39 ERROR keystone.server.flask.application     generated = self._enter_create(value, createdtime)
2023-04-01 08:38:23.478 39 ERROR keystone.server.flask.application   File "/var/lib/kolla/venv/lib/python3.9/site-packages/dogpile/lock.py", line 178, in _enter_create
2023-04-01 08:38:23.478 39 ERROR keystone.server.flask.application     return self.creator()
2023-04-01 08:38:23.478 39 ERROR keystone.server.flask.application   File "/var/lib/kolla/venv/lib/python3.9/site-packages/dogpile/cache/region.py", line 995, in gen_value
2023-04-01 08:38:23.478 39 ERROR keystone.server.flask.application     created_value = creator(
2023-04-01 08:38:23.478 39 ERROR keystone.server.flask.application   File "/var/lib/kolla/venv/lib/python3.9/site-packages/keystone/assignment/core.py", line 1276, in get_role
2023-04-01 08:38:23.478 39 ERROR keystone.server.flask.application     return self.driver.get_role(role_id)
2023-04-01 08:38:23.478 39 ERROR keystone.server.flask.application   File "/var/lib/kolla/venv/lib/python3.9/site-packages/keystone/assignment/role_backends/sql.py", line 70, in get_role
2023-04-01 08:38:23.478 39 ERROR keystone.server.flask.application     return self._get_role(session, role_id).to_dict()
2023-04-01 08:38:23.478 39 ERROR keystone.server.flask.application   File "/var/lib/kolla/venv/lib/python3.9/site-packages/keystone/assignment/role_backends/sql.py", line 65, in _get_role
2023-04-01 08:38:23.478 39 ERROR keystone.server.flask.application     raise exception.RoleNotFound(role_id=role_id)
2023-04-01 08:38:23.478 39 ERROR keystone.server.flask.application keystone.exception.RoleNotFound: Could not find role: admin.
2023-04-01 08:38:23.478 39 ERROR keystone.server.flask.application 
2023-04-01 08:38:24.625 39 ERROR keystone.server.flask.application [None req-cfd30f14-69e9-4afd-8864-fe6fdb0b76bf 0c5e28d4d90748729c288e875518cd25 - - all default -] Could not find user: ironic-inspector.: keystone.exception.UserNotFound: Could not find user: ironic-inspector.
2023-04-01 08:38:24.625 39 ERROR keystone.server.flask.application Traceback (most recent call last):
2023-04-01 08:38:24.625 39 ERROR keystone.server.flask.application   File "/var/lib/kolla/venv/lib/python3.9/site-packages/flask/app.py", line 1820, in full_dispatch_request
2023-04-01 08:38:24.625 39 ERROR keystone.server.flask.application     rv = self.dispatch_request()
2023-04-01 08:38:24.625 39 ERROR keystone.server.flask.application   File "/var/lib/kolla/venv/lib/python3.9/site-packages/flask/app.py", line 1796, in dispatch_request
2023-04-01 08:38:24.625 39 ERROR keystone.server.flask.application     return self.ensure_sync(self.view_functions[rule.endpoint])(**view_args)
2023-04-01 08:38:24.625 39 ERROR keystone.server.flask.application   File "/var/lib/kolla/venv/lib/python3.9/site-packages/flask_restful/__init__.py", line 467, in wrapper
2023-04-01 08:38:24.625 39 ERROR keystone.server.flask.application     resp = resource(*args, **kwargs)
2023-04-01 08:38:24.625 39 ERROR keystone.server.flask.application   File "/var/lib/kolla/venv/lib/python3.9/site-packages/flask/views.py", line 107, in view
2023-04-01 08:38:24.625 39 ERROR keystone.server.flask.application     return current_app.ensure_sync(self.dispatch_request)(**kwargs)
2023-04-01 08:38:24.625 39 ERROR keystone.server.flask.application   File "/var/lib/kolla/venv/lib/python3.9/site-packages/flask_restful/__init__.py", line 582, in dispatch_request
2023-04-01 08:38:24.625 39 ERROR keystone.server.flask.application     resp = meth(*args, **kwargs)
2023-04-01 08:38:24.625 39 ERROR keystone.server.flask.application   File "/var/lib/kolla/venv/lib/python3.9/site-packages/keystone/api/users.py", line 182, in get
2023-04-01 08:38:24.625 39 ERROR keystone.server.flask.application     return self._get_user(user_id)
2023-04-01 08:38:24.625 39 ERROR keystone.server.flask.application   File "/var/lib/kolla/venv/lib/python3.9/site-packages/keystone/api/users.py", line 194, in _get_user
2023-04-01 08:38:24.625 39 ERROR keystone.server.flask.application     ref = PROVIDERS.identity_api.get_user(user_id)
2023-04-01 08:38:24.625 39 ERROR keystone.server.flask.application   File "/var/lib/kolla/venv/lib/python3.9/site-packages/keystone/common/manager.py", line 115, in wrapped
2023-04-01 08:38:24.625 39 ERROR keystone.server.flask.application     __ret_val = __f(*args, **kwargs)
2023-04-01 08:38:24.625 39 ERROR keystone.server.flask.application   File "/var/lib/kolla/venv/lib/python3.9/site-packages/keystone/identity/core.py", line 414, in wrapper
2023-04-01 08:38:24.625 39 ERROR keystone.server.flask.application     return f(self, *args, **kwargs)
2023-04-01 08:38:24.625 39 ERROR keystone.server.flask.application   File "/var/lib/kolla/venv/lib/python3.9/site-packages/keystone/identity/core.py", line 424, in wrapper
2023-04-01 08:38:24.625 39 ERROR keystone.server.flask.application     return f(self, *args, **kwargs)
2023-04-01 08:38:24.625 39 ERROR keystone.server.flask.application   File "/var/lib/kolla/venv/lib/python3.9/site-packages/decorator.py", line 232, in fun
2023-04-01 08:38:24.625 39 ERROR keystone.server.flask.application     return caller(func, *(extras + args), **kw)
2023-04-01 08:38:24.625 39 ERROR keystone.server.flask.application   File "/var/lib/kolla/venv/lib/python3.9/site-packages/dogpile/cache/region.py", line 1577, in get_or_create_for_user_func
2023-04-01 08:38:24.625 39 ERROR keystone.server.flask.application     return self.get_or_create(
2023-04-01 08:38:24.625 39 ERROR keystone.server.flask.application   File "/var/lib/kolla/venv/lib/python3.9/site-packages/dogpile/cache/region.py", line 1042, in get_or_create
2023-04-01 08:38:24.625 39 ERROR keystone.server.flask.application     with Lock(
2023-04-01 08:38:24.625 39 ERROR keystone.server.flask.application   File "/var/lib/kolla/venv/lib/python3.9/site-packages/dogpile/lock.py", line 185, in __enter__
2023-04-01 08:38:24.625 39 ERROR keystone.server.flask.application     return self._enter()
2023-04-01 08:38:24.625 39 ERROR keystone.server.flask.application   File "/var/lib/kolla/venv/lib/python3.9/site-packages/dogpile/lock.py", line 94, in _enter
2023-04-01 08:38:24.625 39 ERROR keystone.server.flask.application     generated = self._enter_create(value, createdtime)
2023-04-01 08:38:24.625 39 ERROR keystone.server.flask.application   File "/var/lib/kolla/venv/lib/python3.9/site-packages/dogpile/lock.py", line 178, in _enter_create
2023-04-01 08:38:24.625 39 ERROR keystone.server.flask.application     return self.creator()
2023-04-01 08:38:24.625 39 ERROR keystone.server.flask.application   File "/var/lib/kolla/venv/lib/python3.9/site-packages/dogpile/cache/region.py", line 995, in gen_value
2023-04-01 08:38:24.625 39 ERROR keystone.server.flask.application     created_value = creator(
2023-04-01 08:38:24.625 39 ERROR keystone.server.flask.application   File "/var/lib/kolla/venv/lib/python3.9/site-packages/keystone/identity/core.py", line 1011, in get_user
2023-04-01 08:38:24.625 39 ERROR keystone.server.flask.application     ref = driver.get_user(entity_id)
2023-04-01 08:38:24.625 39 ERROR keystone.server.flask.application   File "/var/lib/kolla/venv/lib/python3.9/site-packages/keystone/identity/backends/sql.py", line 200, in get_user
2023-04-01 08:38:24.625 39 ERROR keystone.server.flask.application     self._get_user(session, user_id).to_dict())
2023-04-01 08:38:24.625 39 ERROR keystone.server.flask.application   File "/var/lib/kolla/venv/lib/python3.9/site-packages/keystone/identity/backends/sql.py", line 194, in _get_user
2023-04-01 08:38:24.625 39 ERROR keystone.server.flask.application     raise exception.UserNotFound(user_id=user_id)
2023-04-01 08:38:24.625 39 ERROR keystone.server.flask.application keystone.exception.UserNotFound: Could not find user: ironic-inspector.
2023-04-01 08:38:24.625 39 ERROR keystone.server.flask.application 
2023-04-01 08:38:25.499 38 ERROR keystone.server.flask.application [None req-2a0bc876-01a6-469c-a9e2-5c6c35054340 0c5e28d4d90748729c288e875518cd25 - - all default -] Could not find project: service.: keystone.exception.ProjectNotFound: Could not find project: service.
2023-04-01 08:38:25.499 38 ERROR keystone.server.flask.application Traceback (most recent call last):
2023-04-01 08:38:25.499 38 ERROR keystone.server.flask.application   File "/var/lib/kolla/venv/lib/python3.9/site-packages/flask/app.py", line 1820, in full_dispatch_request
2023-04-01 08:38:25.499 38 ERROR keystone.server.flask.application     rv = self.dispatch_request()
2023-04-01 08:38:25.499 38 ERROR keystone.server.flask.application   File "/var/lib/kolla/venv/lib/python3.9/site-packages/flask/app.py", line 1796, in dispatch_request
2023-04-01 08:38:25.499 38 ERROR keystone.server.flask.application     return self.ensure_sync(self.view_functions[rule.endpoint])(**view_args)
2023-04-01 08:38:25.499 38 ERROR keystone.server.flask.application   File "/var/lib/kolla/venv/lib/python3.9/site-packages/flask_restful/__init__.py", line 467, in wrapper
2023-04-01 08:38:25.499 38 ERROR keystone.server.flask.application     resp = resource(*args, **kwargs)
2023-04-01 08:38:25.499 38 ERROR keystone.server.flask.application   File "/var/lib/kolla/venv/lib/python3.9/site-packages/flask/views.py", line 107, in view
2023-04-01 08:38:25.499 38 ERROR keystone.server.flask.application     return current_app.ensure_sync(self.dispatch_request)(**kwargs)
2023-04-01 08:38:25.499 38 ERROR keystone.server.flask.application   File "/var/lib/kolla/venv/lib/python3.9/site-packages/flask_restful/__init__.py", line 582, in dispatch_request
2023-04-01 08:38:25.499 38 ERROR keystone.server.flask.application     resp = meth(*args, **kwargs)
2023-04-01 08:38:25.499 38 ERROR keystone.server.flask.application   File "/var/lib/kolla/venv/lib/python3.9/site-packages/keystone/api/projects.py", line 151, in get
2023-04-01 08:38:25.499 38 ERROR keystone.server.flask.application     return self._get_project(project_id)
2023-04-01 08:38:25.499 38 ERROR keystone.server.flask.application   File "/var/lib/kolla/venv/lib/python3.9/site-packages/keystone/api/projects.py", line 107, in _get_project
2023-04-01 08:38:25.499 38 ERROR keystone.server.flask.application     project = PROVIDERS.resource_api.get_project(project_id)
2023-04-01 08:38:25.499 38 ERROR keystone.server.flask.application   File "/var/lib/kolla/venv/lib/python3.9/site-packages/keystone/common/manager.py", line 115, in wrapped
2023-04-01 08:38:25.499 38 ERROR keystone.server.flask.application     __ret_val = __f(*args, **kwargs)
2023-04-01 08:38:25.499 38 ERROR keystone.server.flask.application   File "/var/lib/kolla/venv/lib/python3.9/site-packages/decorator.py", line 232, in fun
2023-04-01 08:38:25.499 38 ERROR keystone.server.flask.application     return caller(func, *(extras + args), **kw)
2023-04-01 08:38:25.499 38 ERROR keystone.server.flask.application   File "/var/lib/kolla/venv/lib/python3.9/site-packages/dogpile/cache/region.py", line 1577, in get_or_create_for_user_func
2023-04-01 08:38:25.499 38 ERROR keystone.server.flask.application     return self.get_or_create(
2023-04-01 08:38:25.499 38 ERROR keystone.server.flask.application   File "/var/lib/kolla/venv/lib/python3.9/site-packages/dogpile/cache/region.py", line 1042, in get_or_create
2023-04-01 08:38:25.499 38 ERROR keystone.server.flask.application     with Lock(
2023-04-01 08:38:25.499 38 ERROR keystone.server.flask.application   File "/var/lib/kolla/venv/lib/python3.9/site-packages/dogpile/lock.py", line 185, in __enter__
2023-04-01 08:38:25.499 38 ERROR keystone.server.flask.application     return self._enter()
2023-04-01 08:38:25.499 38 ERROR keystone.server.flask.application   File "/var/lib/kolla/venv/lib/python3.9/site-packages/dogpile/lock.py", line 94, in _enter
2023-04-01 08:38:25.499 38 ERROR keystone.server.flask.application     generated = self._enter_create(value, createdtime)
2023-04-01 08:38:25.499 38 ERROR keystone.server.flask.application   File "/var/lib/kolla/venv/lib/python3.9/site-packages/dogpile/lock.py", line 178, in _enter_create
2023-04-01 08:38:25.499 38 ERROR keystone.server.flask.application     return self.creator()
2023-04-01 08:38:25.499 38 ERROR keystone.server.flask.application   File "/var/lib/kolla/venv/lib/python3.9/site-packages/dogpile/cache/region.py", line 995, in gen_value
2023-04-01 08:38:25.499 38 ERROR keystone.server.flask.application     created_value = creator(
2023-04-01 08:38:25.499 38 ERROR keystone.server.flask.application   File "/var/lib/kolla/venv/lib/python3.9/site-packages/keystone/resource/core.py", line 903, in get_project
2023-04-01 08:38:25.499 38 ERROR keystone.server.flask.application     return self.driver.get_project(project_id)
2023-04-01 08:38:25.499 38 ERROR keystone.server.flask.application   File "/var/lib/kolla/venv/lib/python3.9/site-packages/keystone/resource/backends/sql.py", line 49, in get_project
2023-04-01 08:38:25.499 38 ERROR keystone.server.flask.application     return self._get_project(session, project_id).to_dict()
2023-04-01 08:38:25.499 38 ERROR keystone.server.flask.application   File "/var/lib/kolla/venv/lib/python3.9/site-packages/keystone/resource/backends/sql.py", line 44, in _get_project
2023-04-01 08:38:25.499 38 ERROR keystone.server.flask.application     raise exception.ProjectNotFound(project_id=project_id)
2023-04-01 08:38:25.499 38 ERROR keystone.server.flask.application keystone.exception.ProjectNotFound: Could not find project: service.
2023-04-01 08:38:25.499 38 ERROR keystone.server.flask.application 
2023-04-01 08:41:28.020 38 ERROR keystone.server.flask.application [None req-71a22dff-7d8b-4dbc-96f4-f08efd5b0f88 0c5e28d4d90748729c288e875518cd25 - - all default -] Could not find project: service.: keystone.exception.ProjectNotFound: Could not find project: service.
2023-04-01 08:41:28.020 38 ERROR keystone.server.flask.application Traceback (most recent call last):
2023-04-01 08:41:28.020 38 ERROR keystone.server.flask.application   File "/var/lib/kolla/venv/lib/python3.9/site-packages/flask/app.py", line 1820, in full_dispatch_request
2023-04-01 08:41:28.020 38 ERROR keystone.server.flask.application     rv = self.dispatch_request()
2023-04-01 08:41:28.020 38 ERROR keystone.server.flask.application   File "/var/lib/kolla/venv/lib/python3.9/site-packages/flask/app.py", line 1796, in dispatch_request
2023-04-01 08:41:28.020 38 ERROR keystone.server.flask.application     return self.ensure_sync(self.view_functions[rule.endpoint])(**view_args)
2023-04-01 08:41:28.020 38 ERROR keystone.server.flask.application   File "/var/lib/kolla/venv/lib/python3.9/site-packages/flask_restful/__init__.py", line 467, in wrapper
2023-04-01 08:41:28.020 38 ERROR keystone.server.flask.application     resp = resource(*args, **kwargs)
2023-04-01 08:41:28.020 38 ERROR keystone.server.flask.application   File "/var/lib/kolla/venv/lib/python3.9/site-packages/flask/views.py", line 107, in view
2023-04-01 08:41:28.020 38 ERROR keystone.server.flask.application     return current_app.ensure_sync(self.dispatch_request)(**kwargs)
2023-04-01 08:41:28.020 38 ERROR keystone.server.flask.application   File "/var/lib/kolla/venv/lib/python3.9/site-packages/flask_restful/__init__.py", line 582, in dispatch_request
2023-04-01 08:41:28.020 38 ERROR keystone.server.flask.application     resp = meth(*args, **kwargs)
2023-04-01 08:41:28.020 38 ERROR keystone.server.flask.application   File "/var/lib/kolla/venv/lib/python3.9/site-packages/keystone/api/projects.py", line 151, in get
2023-04-01 08:41:28.020 38 ERROR keystone.server.flask.application     return self._get_project(project_id)
2023-04-01 08:41:28.020 38 ERROR keystone.server.flask.application   File "/var/lib/kolla/venv/lib/python3.9/site-packages/keystone/api/projects.py", line 107, in _get_project
2023-04-01 08:41:28.020 38 ERROR keystone.server.flask.application     project = PROVIDERS.resource_api.get_project(project_id)
2023-04-01 08:41:28.020 38 ERROR keystone.server.flask.application   File "/var/lib/kolla/venv/lib/python3.9/site-packages/keystone/common/manager.py", line 115, in wrapped
2023-04-01 08:41:28.020 38 ERROR keystone.server.flask.application     __ret_val = __f(*args, **kwargs)
2023-04-01 08:41:28.020 38 ERROR keystone.server.flask.application   File "/var/lib/kolla/venv/lib/python3.9/site-packages/decorator.py", line 232, in fun
2023-04-01 08:41:28.020 38 ERROR keystone.server.flask.application     return caller(func, *(extras + args), **kw)
2023-04-01 08:41:28.020 38 ERROR keystone.server.flask.application   File "/var/lib/kolla/venv/lib/python3.9/site-packages/dogpile/cache/region.py", line 1577, in get_or_create_for_user_func
2023-04-01 08:41:28.020 38 ERROR keystone.server.flask.application     return self.get_or_create(
2023-04-01 08:41:28.020 38 ERROR keystone.server.flask.application   File "/var/lib/kolla/venv/lib/python3.9/site-packages/dogpile/cache/region.py", line 1042, in get_or_create
2023-04-01 08:41:28.020 38 ERROR keystone.server.flask.application     with Lock(
2023-04-01 08:41:28.020 38 ERROR keystone.server.flask.application   File "/var/lib/kolla/venv/lib/python3.9/site-packages/dogpile/lock.py", line 185, in __enter__
2023-04-01 08:41:28.020 38 ERROR keystone.server.flask.application     return self._enter()
2023-04-01 08:41:28.020 38 ERROR keystone.server.flask.application   File "/var/lib/kolla/venv/lib/python3.9/site-packages/dogpile/lock.py", line 94, in _enter
2023-04-01 08:41:28.020 38 ERROR keystone.server.flask.application     generated = self._enter_create(value, createdtime)
2023-04-01 08:41:28.020 38 ERROR keystone.server.flask.application   File "/var/lib/kolla/venv/lib/python3.9/site-packages/dogpile/lock.py", line 178, in _enter_create
2023-04-01 08:41:28.020 38 ERROR keystone.server.flask.application     return self.creator()
2023-04-01 08:41:28.020 38 ERROR keystone.server.flask.application   File "/var/lib/kolla/venv/lib/python3.9/site-packages/dogpile/cache/region.py", line 995, in gen_value
2023-04-01 08:41:28.020 38 ERROR keystone.server.flask.application     created_value = creator(
2023-04-01 08:41:28.020 38 ERROR keystone.server.flask.application   File "/var/lib/kolla/venv/lib/python3.9/site-packages/keystone/resource/core.py", line 903, in get_project
2023-04-01 08:41:28.020 38 ERROR keystone.server.flask.application     return self.driver.get_project(project_id)
2023-04-01 08:41:28.020 38 ERROR keystone.server.flask.application   File "/var/lib/kolla/venv/lib/python3.9/site-packages/keystone/resource/backends/sql.py", line 49, in get_project
2023-04-01 08:41:28.020 38 ERROR keystone.server.flask.application     return self._get_project(session, project_id).to_dict()
2023-04-01 08:41:28.020 38 ERROR keystone.server.flask.application   File "/var/lib/kolla/venv/lib/python3.9/site-packages/keystone/resource/backends/sql.py", line 44, in _get_project
2023-04-01 08:41:28.020 38 ERROR keystone.server.flask.application     raise exception.ProjectNotFound(project_id=project_id)
2023-04-01 08:41:28.020 38 ERROR keystone.server.flask.application keystone.exception.ProjectNotFound: Could not find project: service.
2023-04-01 08:41:28.020 38 ERROR keystone.server.flask.application 
2023-04-01 08:41:42.688 37 ERROR keystone.server.flask.application [None req-d037a308-8c67-4ddc-8489-4d2f23d3b88b 0c5e28d4d90748729c288e875518cd25 - - all default -] Could not find role: admin.: keystone.exception.RoleNotFound: Could not find role: admin.
2023-04-01 08:41:42.688 37 ERROR keystone.server.flask.application Traceback (most recent call last):
2023-04-01 08:41:42.688 37 ERROR keystone.server.flask.application   File "/var/lib/kolla/venv/lib/python3.9/site-packages/flask/app.py", line 1820, in full_dispatch_request
2023-04-01 08:41:42.688 37 ERROR keystone.server.flask.application     rv = self.dispatch_request()
2023-04-01 08:41:42.688 37 ERROR keystone.server.flask.application   File "/var/lib/kolla/venv/lib/python3.9/site-packages/flask/app.py", line 1796, in dispatch_request
2023-04-01 08:41:42.688 37 ERROR keystone.server.flask.application     return self.ensure_sync(self.view_functions[rule.endpoint])(**view_args)
2023-04-01 08:41:42.688 37 ERROR keystone.server.flask.application   File "/var/lib/kolla/venv/lib/python3.9/site-packages/flask_restful/__init__.py", line 467, in wrapper
2023-04-01 08:41:42.688 37 ERROR keystone.server.flask.application     resp = resource(*args, **kwargs)
2023-04-01 08:41:42.688 37 ERROR keystone.server.flask.application   File "/var/lib/kolla/venv/lib/python3.9/site-packages/flask/views.py", line 107, in view
2023-04-01 08:41:42.688 37 ERROR keystone.server.flask.application     return current_app.ensure_sync(self.dispatch_request)(**kwargs)
2023-04-01 08:41:42.688 37 ERROR keystone.server.flask.application   File "/var/lib/kolla/venv/lib/python3.9/site-packages/flask_restful/__init__.py", line 582, in dispatch_request
2023-04-01 08:41:42.688 37 ERROR keystone.server.flask.application     resp = meth(*args, **kwargs)
2023-04-01 08:41:42.688 37 ERROR keystone.server.flask.application   File "/var/lib/kolla/venv/lib/python3.9/site-packages/keystone/api/roles.py", line 50, in get
2023-04-01 08:41:42.688 37 ERROR keystone.server.flask.application     return self._get_role(role_id)
2023-04-01 08:41:42.688 37 ERROR keystone.server.flask.application   File "/var/lib/kolla/venv/lib/python3.9/site-packages/keystone/api/roles.py", line 70, in _get_role
2023-04-01 08:41:42.688 37 ERROR keystone.server.flask.application     ENFORCER.enforce_call(action='identity:get_role')
2023-04-01 08:41:42.688 37 ERROR keystone.server.flask.application   File "/var/lib/kolla/venv/lib/python3.9/site-packages/keystone/common/rbac_enforcer/enforcer.py", line 402, in enforce_call
2023-04-01 08:41:42.688 37 ERROR keystone.server.flask.application     policy_dict.update(cls._extract_member_target_data(
2023-04-01 08:41:42.688 37 ERROR keystone.server.flask.application   File "/var/lib/kolla/venv/lib/python3.9/site-packages/keystone/common/rbac_enforcer/enforcer.py", line 234, in _extract_member_target_data
2023-04-01 08:41:42.688 37 ERROR keystone.server.flask.application     member_name: func(flask.request.view_args[key])
2023-04-01 08:41:42.688 37 ERROR keystone.server.flask.application   File "/var/lib/kolla/venv/lib/python3.9/site-packages/keystone/common/manager.py", line 115, in wrapped
2023-04-01 08:41:42.688 37 ERROR keystone.server.flask.application     __ret_val = __f(*args, **kwargs)
2023-04-01 08:41:42.688 37 ERROR keystone.server.flask.application   File "/var/lib/kolla/venv/lib/python3.9/site-packages/decorator.py", line 232, in fun
2023-04-01 08:41:42.688 37 ERROR keystone.server.flask.application     return caller(func, *(extras + args), **kw)
2023-04-01 08:41:42.688 37 ERROR keystone.server.flask.application   File "/var/lib/kolla/venv/lib/python3.9/site-packages/dogpile/cache/region.py", line 1577, in get_or_create_for_user_func
2023-04-01 08:41:42.688 37 ERROR keystone.server.flask.application     return self.get_or_create(
2023-04-01 08:41:42.688 37 ERROR keystone.server.flask.application   File "/var/lib/kolla/venv/lib/python3.9/site-packages/dogpile/cache/region.py", line 1042, in get_or_create
2023-04-01 08:41:42.688 37 ERROR keystone.server.flask.application     with Lock(
2023-04-01 08:41:42.688 37 ERROR keystone.server.flask.application   File "/var/lib/kolla/venv/lib/python3.9/site-packages/dogpile/lock.py", line 185, in __enter__
2023-04-01 08:41:42.688 37 ERROR keystone.server.flask.application     return self._enter()
2023-04-01 08:41:42.688 37 ERROR keystone.server.flask.application   File "/var/lib/kolla/venv/lib/python3.9/site-packages/dogpile/lock.py", line 94, in _enter
2023-04-01 08:41:42.688 37 ERROR keystone.server.flask.application     generated = self._enter_create(value, createdtime)
2023-04-01 08:41:42.688 37 ERROR keystone.server.flask.application   File "/var/lib/kolla/venv/lib/python3.9/site-packages/dogpile/lock.py", line 178, in _enter_create
2023-04-01 08:41:42.688 37 ERROR keystone.server.flask.application     return self.creator()
2023-04-01 08:41:42.688 37 ERROR keystone.server.flask.application   File "/var/lib/kolla/venv/lib/python3.9/site-packages/dogpile/cache/region.py", line 995, in gen_value
2023-04-01 08:41:42.688 37 ERROR keystone.server.flask.application     created_value = creator(
2023-04-01 08:41:42.688 37 ERROR keystone.server.flask.application   File "/var/lib/kolla/venv/lib/python3.9/site-packages/keystone/assignment/core.py", line 1276, in get_role
2023-04-01 08:41:42.688 37 ERROR keystone.server.flask.application     return self.driver.get_role(role_id)
2023-04-01 08:41:42.688 37 ERROR keystone.server.flask.application   File "/var/lib/kolla/venv/lib/python3.9/site-packages/keystone/assignment/role_backends/sql.py", line 70, in get_role
2023-04-01 08:41:42.688 37 ERROR keystone.server.flask.application     return self._get_role(session, role_id).to_dict()
2023-04-01 08:41:42.688 37 ERROR keystone.server.flask.application   File "/var/lib/kolla/venv/lib/python3.9/site-packages/keystone/assignment/role_backends/sql.py", line 65, in _get_role
2023-04-01 08:41:42.688 37 ERROR keystone.server.flask.application     raise exception.RoleNotFound(role_id=role_id)
2023-04-01 08:41:42.688 37 ERROR keystone.server.flask.application keystone.exception.RoleNotFound: Could not find role: admin.
2023-04-01 08:41:42.688 37 ERROR keystone.server.flask.application 
2023-04-01 08:41:43.783 37 ERROR keystone.server.flask.application [None req-a5500a6e-00fc-4e87-876a-b36aa62f7ab5 0c5e28d4d90748729c288e875518cd25 - - all default -] Could not find user: neutron.: keystone.exception.UserNotFound: Could not find user: neutron.
2023-04-01 08:41:43.783 37 ERROR keystone.server.flask.application Traceback (most recent call last):
2023-04-01 08:41:43.783 37 ERROR keystone.server.flask.application   File "/var/lib/kolla/venv/lib/python3.9/site-packages/flask/app.py", line 1820, in full_dispatch_request
2023-04-01 08:41:43.783 37 ERROR keystone.server.flask.application     rv = self.dispatch_request()
2023-04-01 08:41:43.783 37 ERROR keystone.server.flask.application   File "/var/lib/kolla/venv/lib/python3.9/site-packages/flask/app.py", line 1796, in dispatch_request
2023-04-01 08:41:43.783 37 ERROR keystone.server.flask.application     return self.ensure_sync(self.view_functions[rule.endpoint])(**view_args)
2023-04-01 08:41:43.783 37 ERROR keystone.server.flask.application   File "/var/lib/kolla/venv/lib/python3.9/site-packages/flask_restful/__init__.py", line 467, in wrapper
2023-04-01 08:41:43.783 37 ERROR keystone.server.flask.application     resp = resource(*args, **kwargs)
2023-04-01 08:41:43.783 37 ERROR keystone.server.flask.application   File "/var/lib/kolla/venv/lib/python3.9/site-packages/flask/views.py", line 107, in view
2023-04-01 08:41:43.783 37 ERROR keystone.server.flask.application     return current_app.ensure_sync(self.dispatch_request)(**kwargs)
2023-04-01 08:41:43.783 37 ERROR keystone.server.flask.application   File "/var/lib/kolla/venv/lib/python3.9/site-packages/flask_restful/__init__.py", line 582, in dispatch_request
2023-04-01 08:41:43.783 37 ERROR keystone.server.flask.application     resp = meth(*args, **kwargs)
2023-04-01 08:41:43.783 37 ERROR keystone.server.flask.application   File "/var/lib/kolla/venv/lib/python3.9/site-packages/keystone/api/users.py", line 182, in get
2023-04-01 08:41:43.783 37 ERROR keystone.server.flask.application     return self._get_user(user_id)
2023-04-01 08:41:43.783 37 ERROR keystone.server.flask.application   File "/var/lib/kolla/venv/lib/python3.9/site-packages/keystone/api/users.py", line 194, in _get_user
2023-04-01 08:41:43.783 37 ERROR keystone.server.flask.application     ref = PROVIDERS.identity_api.get_user(user_id)
2023-04-01 08:41:43.783 37 ERROR keystone.server.flask.application   File "/var/lib/kolla/venv/lib/python3.9/site-packages/keystone/common/manager.py", line 115, in wrapped
2023-04-01 08:41:43.783 37 ERROR keystone.server.flask.application     __ret_val = __f(*args, **kwargs)
2023-04-01 08:41:43.783 37 ERROR keystone.server.flask.application   File "/var/lib/kolla/venv/lib/python3.9/site-packages/keystone/identity/core.py", line 414, in wrapper
2023-04-01 08:41:43.783 37 ERROR keystone.server.flask.application     return f(self, *args, **kwargs)
2023-04-01 08:41:43.783 37 ERROR keystone.server.flask.application   File "/var/lib/kolla/venv/lib/python3.9/site-packages/keystone/identity/core.py", line 424, in wrapper
2023-04-01 08:41:43.783 37 ERROR keystone.server.flask.application     return f(self, *args, **kwargs)
2023-04-01 08:41:43.783 37 ERROR keystone.server.flask.application   File "/var/lib/kolla/venv/lib/python3.9/site-packages/decorator.py", line 232, in fun
2023-04-01 08:41:43.783 37 ERROR keystone.server.flask.application     return caller(func, *(extras + args), **kw)
2023-04-01 08:41:43.783 37 ERROR keystone.server.flask.application   File "/var/lib/kolla/venv/lib/python3.9/site-packages/dogpile/cache/region.py", line 1577, in get_or_create_for_user_func
2023-04-01 08:41:43.783 37 ERROR keystone.server.flask.application     return self.get_or_create(
2023-04-01 08:41:43.783 37 ERROR keystone.server.flask.application   File "/var/lib/kolla/venv/lib/python3.9/site-packages/dogpile/cache/region.py", line 1042, in get_or_create
2023-04-01 08:41:43.783 37 ERROR keystone.server.flask.application     with Lock(
2023-04-01 08:41:43.783 37 ERROR keystone.server.flask.application   File "/var/lib/kolla/venv/lib/python3.9/site-packages/dogpile/lock.py", line 185, in __enter__
2023-04-01 08:41:43.783 37 ERROR keystone.server.flask.application     return self._enter()
2023-04-01 08:41:43.783 37 ERROR keystone.server.flask.application   File "/var/lib/kolla/venv/lib/python3.9/site-packages/dogpile/lock.py", line 94, in _enter
2023-04-01 08:41:43.783 37 ERROR keystone.server.flask.application     generated = self._enter_create(value, createdtime)
2023-04-01 08:41:43.783 37 ERROR keystone.server.flask.application   File "/var/lib/kolla/venv/lib/python3.9/site-packages/dogpile/lock.py", line 178, in _enter_create
2023-04-01 08:41:43.783 37 ERROR keystone.server.flask.application     return self.creator()
2023-04-01 08:41:43.783 37 ERROR keystone.server.flask.application   File "/var/lib/kolla/venv/lib/python3.9/site-packages/dogpile/cache/region.py", line 995, in gen_value
2023-04-01 08:41:43.783 37 ERROR keystone.server.flask.application     created_value = creator(
2023-04-01 08:41:43.783 37 ERROR keystone.server.flask.application   File "/var/lib/kolla/venv/lib/python3.9/site-packages/keystone/identity/core.py", line 1011, in get_user
2023-04-01 08:41:43.783 37 ERROR keystone.server.flask.application     ref = driver.get_user(entity_id)
2023-04-01 08:41:43.783 37 ERROR keystone.server.flask.application   File "/var/lib/kolla/venv/lib/python3.9/site-packages/keystone/identity/backends/sql.py", line 200, in get_user
2023-04-01 08:41:43.783 37 ERROR keystone.server.flask.application     self._get_user(session, user_id).to_dict())
2023-04-01 08:41:43.783 37 ERROR keystone.server.flask.application   File "/var/lib/kolla/venv/lib/python3.9/site-packages/keystone/identity/backends/sql.py", line 194, in _get_user
2023-04-01 08:41:43.783 37 ERROR keystone.server.flask.application     raise exception.UserNotFound(user_id=user_id)
2023-04-01 08:41:43.783 37 ERROR keystone.server.flask.application keystone.exception.UserNotFound: Could not find user: neutron.
2023-04-01 08:41:43.783 37 ERROR keystone.server.flask.application 
2023-04-01 08:41:44.610 39 ERROR keystone.server.flask.application [None req-077cb2dc-e53d-43eb-ac88-0f28652fc1dc 0c5e28d4d90748729c288e875518cd25 - - all default -] Could not find project: service.: keystone.exception.ProjectNotFound: Could not find project: service.
2023-04-01 08:41:44.610 39 ERROR keystone.server.flask.application Traceback (most recent call last):
2023-04-01 08:41:44.610 39 ERROR keystone.server.flask.application   File "/var/lib/kolla/venv/lib/python3.9/site-packages/flask/app.py", line 1820, in full_dispatch_request
2023-04-01 08:41:44.610 39 ERROR keystone.server.flask.application     rv = self.dispatch_request()
2023-04-01 08:41:44.610 39 ERROR keystone.server.flask.application   File "/var/lib/kolla/venv/lib/python3.9/site-packages/flask/app.py", line 1796, in dispatch_request
2023-04-01 08:41:44.610 39 ERROR keystone.server.flask.application     return self.ensure_sync(self.view_functions[rule.endpoint])(**view_args)
2023-04-01 08:41:44.610 39 ERROR keystone.server.flask.application   File "/var/lib/kolla/venv/lib/python3.9/site-packages/flask_restful/__init__.py", line 467, in wrapper
2023-04-01 08:41:44.610 39 ERROR keystone.server.flask.application     resp = resource(*args, **kwargs)
2023-04-01 08:41:44.610 39 ERROR keystone.server.flask.application   File "/var/lib/kolla/venv/lib/python3.9/site-packages/flask/views.py", line 107, in view
2023-04-01 08:41:44.610 39 ERROR keystone.server.flask.application     return current_app.ensure_sync(self.dispatch_request)(**kwargs)
2023-04-01 08:41:44.610 39 ERROR keystone.server.flask.application   File "/var/lib/kolla/venv/lib/python3.9/site-packages/flask_restful/__init__.py", line 582, in dispatch_request
2023-04-01 08:41:44.610 39 ERROR keystone.server.flask.application     resp = meth(*args, **kwargs)
2023-04-01 08:41:44.610 39 ERROR keystone.server.flask.application   File "/var/lib/kolla/venv/lib/python3.9/site-packages/keystone/api/projects.py", line 151, in get
2023-04-01 08:41:44.610 39 ERROR keystone.server.flask.application     return self._get_project(project_id)
2023-04-01 08:41:44.610 39 ERROR keystone.server.flask.application   File "/var/lib/kolla/venv/lib/python3.9/site-packages/keystone/api/projects.py", line 107, in _get_project
2023-04-01 08:41:44.610 39 ERROR keystone.server.flask.application     project = PROVIDERS.resource_api.get_project(project_id)
2023-04-01 08:41:44.610 39 ERROR keystone.server.flask.application   File "/var/lib/kolla/venv/lib/python3.9/site-packages/keystone/common/manager.py", line 115, in wrapped
2023-04-01 08:41:44.610 39 ERROR keystone.server.flask.application     __ret_val = __f(*args, **kwargs)
2023-04-01 08:41:44.610 39 ERROR keystone.server.flask.application   File "/var/lib/kolla/venv/lib/python3.9/site-packages/decorator.py", line 232, in fun
2023-04-01 08:41:44.610 39 ERROR keystone.server.flask.application     return caller(func, *(extras + args), **kw)
2023-04-01 08:41:44.610 39 ERROR keystone.server.flask.application   File "/var/lib/kolla/venv/lib/python3.9/site-packages/dogpile/cache/region.py", line 1577, in get_or_create_for_user_func
2023-04-01 08:41:44.610 39 ERROR keystone.server.flask.application     return self.get_or_create(
2023-04-01 08:41:44.610 39 ERROR keystone.server.flask.application   File "/var/lib/kolla/venv/lib/python3.9/site-packages/dogpile/cache/region.py", line 1042, in get_or_create
2023-04-01 08:41:44.610 39 ERROR keystone.server.flask.application     with Lock(
2023-04-01 08:41:44.610 39 ERROR keystone.server.flask.application   File "/var/lib/kolla/venv/lib/python3.9/site-packages/dogpile/lock.py", line 185, in __enter__
2023-04-01 08:41:44.610 39 ERROR keystone.server.flask.application     return self._enter()
2023-04-01 08:41:44.610 39 ERROR keystone.server.flask.application   File "/var/lib/kolla/venv/lib/python3.9/site-packages/dogpile/lock.py", line 94, in _enter
2023-04-01 08:41:44.610 39 ERROR keystone.server.flask.application     generated = self._enter_create(value, createdtime)
2023-04-01 08:41:44.610 39 ERROR keystone.server.flask.application   File "/var/lib/kolla/venv/lib/python3.9/site-packages/dogpile/lock.py", line 178, in _enter_create
2023-04-01 08:41:44.610 39 ERROR keystone.server.flask.application     return self.creator()
2023-04-01 08:41:44.610 39 ERROR keystone.server.flask.application   File "/var/lib/kolla/venv/lib/python3.9/site-packages/dogpile/cache/region.py", line 995, in gen_value
2023-04-01 08:41:44.610 39 ERROR keystone.server.flask.application     created_value = creator(
2023-04-01 08:41:44.610 39 ERROR keystone.server.flask.application   File "/var/lib/kolla/venv/lib/python3.9/site-packages/keystone/resource/core.py", line 903, in get_project
2023-04-01 08:41:44.610 39 ERROR keystone.server.flask.application     return self.driver.get_project(project_id)
2023-04-01 08:41:44.610 39 ERROR keystone.server.flask.application   File "/var/lib/kolla/venv/lib/python3.9/site-packages/keystone/resource/backends/sql.py", line 49, in get_project
2023-04-01 08:41:44.610 39 ERROR keystone.server.flask.application     return self._get_project(session, project_id).to_dict()
2023-04-01 08:41:44.610 39 ERROR keystone.server.flask.application   File "/var/lib/kolla/venv/lib/python3.9/site-packages/keystone/resource/backends/sql.py", line 44, in _get_project
2023-04-01 08:41:44.610 39 ERROR keystone.server.flask.application     raise exception.ProjectNotFound(project_id=project_id)
2023-04-01 08:41:44.610 39 ERROR keystone.server.flask.application keystone.exception.ProjectNotFound: Could not find project: service.
2023-04-01 08:41:44.610 39 ERROR keystone.server.flask.application 
