2023-02-17 07:06:11.845797 2023-02-17 07:06:11.842 39 WARNING keystone.common.rbac_enforcer.enforcer [None req-feeebb5f-9aff-454d-b081-ec7049d13fc5 6be3aded1b9c47bcbc94453e09ec12ff - - all default -] Deprecated policy rules found. Use oslopolicy-policy-generator and oslopolicy-policy-upgrade to detect and resolve deprecated policies in your configuration.\x1b[00m
2023-02-17 07:06:12.724817 2023-02-17 07:06:12.723 38 WARNING keystone.common.rbac_enforcer.enforcer [None req-7f7da039-58ef-4f83-9039-58bb68c90969 6be3aded1b9c47bcbc94453e09ec12ff - - all default -] Deprecated policy rules found. Use oslopolicy-policy-generator and oslopolicy-policy-upgrade to detect and resolve deprecated policies in your configuration.\x1b[00m
2023-02-17 07:06:19.839983 2023-02-17 07:06:19.837 37 WARNING keystone.common.rbac_enforcer.enforcer [None req-b5df6f27-5bf2-4884-89e8-0e59577c85ec 6be3aded1b9c47bcbc94453e09ec12ff - - all default -] Deprecated policy rules found. Use oslopolicy-policy-generator and oslopolicy-policy-upgrade to detect and resolve deprecated policies in your configuration.\x1b[00m
2023-02-17 07:07:32.047905 2023-02-17 07:07:32.017 39 ERROR keystone.server.flask.application [None req-a1da25a0-e565-406f-a222-60c7e6faf5c5 6be3aded1b9c47bcbc94453e09ec12ff - - all default -] Could not find project: service.: keystone.exception.ProjectNotFound: Could not find project: service.
2023-02-17 07:07:32.047976 2023-02-17 07:07:32.017 39 ERROR keystone.server.flask.application Traceback (most recent call last):
2023-02-17 07:07:32.048000 2023-02-17 07:07:32.017 39 ERROR keystone.server.flask.application   File "/var/lib/kolla/venv/lib/python3.9/site-packages/flask/app.py", line 1820, in full_dispatch_request
2023-02-17 07:07:32.048020 2023-02-17 07:07:32.017 39 ERROR keystone.server.flask.application     rv = self.dispatch_request()
2023-02-17 07:07:32.048114 2023-02-17 07:07:32.017 39 ERROR keystone.server.flask.application   File "/var/lib/kolla/venv/lib/python3.9/site-packages/flask/app.py", line 1796, in dispatch_request
2023-02-17 07:07:32.048137 2023-02-17 07:07:32.017 39 ERROR keystone.server.flask.application     return self.ensure_sync(self.view_functions[rule.endpoint])(**view_args)
2023-02-17 07:07:32.048156 2023-02-17 07:07:32.017 39 ERROR keystone.server.flask.application   File "/var/lib/kolla/venv/lib/python3.9/site-packages/flask_restful/__init__.py", line 467, in wrapper
2023-02-17 07:07:32.048175 2023-02-17 07:07:32.017 39 ERROR keystone.server.flask.application     resp = resource(*args, **kwargs)
2023-02-17 07:07:32.048204 2023-02-17 07:07:32.017 39 ERROR keystone.server.flask.application   File "/var/lib/kolla/venv/lib/python3.9/site-packages/flask/views.py", line 107, in view
2023-02-17 07:07:32.048228 2023-02-17 07:07:32.017 39 ERROR keystone.server.flask.application     return current_app.ensure_sync(self.dispatch_request)(**kwargs)
2023-02-17 07:07:32.048249 2023-02-17 07:07:32.017 39 ERROR keystone.server.flask.application   File "/var/lib/kolla/venv/lib/python3.9/site-packages/flask_restful/__init__.py", line 582, in dispatch_request
2023-02-17 07:07:32.048271 2023-02-17 07:07:32.017 39 ERROR keystone.server.flask.application     resp = meth(*args, **kwargs)
2023-02-17 07:07:32.048290 2023-02-17 07:07:32.017 39 ERROR keystone.server.flask.application   File "/var/lib/kolla/venv/lib/python3.9/site-packages/keystone/api/projects.py", line 151, in get
2023-02-17 07:07:32.048321 2023-02-17 07:07:32.017 39 ERROR keystone.server.flask.application     return self._get_project(project_id)
2023-02-17 07:07:32.048340 2023-02-17 07:07:32.017 39 ERROR keystone.server.flask.application   File "/var/lib/kolla/venv/lib/python3.9/site-packages/keystone/api/projects.py", line 107, in _get_project
2023-02-17 07:07:32.048357 2023-02-17 07:07:32.017 39 ERROR keystone.server.flask.application     project = PROVIDERS.resource_api.get_project(project_id)
2023-02-17 07:07:32.048374 2023-02-17 07:07:32.017 39 ERROR keystone.server.flask.application   File "/var/lib/kolla/venv/lib/python3.9/site-packages/keystone/common/manager.py", line 115, in wrapped
2023-02-17 07:07:32.048469 2023-02-17 07:07:32.017 39 ERROR keystone.server.flask.application     __ret_val = __f(*args, **kwargs)
2023-02-17 07:07:32.048489 2023-02-17 07:07:32.017 39 ERROR keystone.server.flask.application   File "/var/lib/kolla/venv/lib/python3.9/site-packages/decorator.py", line 232, in fun
2023-02-17 07:07:32.048507 2023-02-17 07:07:32.017 39 ERROR keystone.server.flask.application     return caller(func, *(extras + args), **kw)
2023-02-17 07:07:32.048524 2023-02-17 07:07:32.017 39 ERROR keystone.server.flask.application   File "/var/lib/kolla/venv/lib/python3.9/site-packages/dogpile/cache/region.py", line 1577, in get_or_create_for_user_func
2023-02-17 07:07:32.048541 2023-02-17 07:07:32.017 39 ERROR keystone.server.flask.application     return self.get_or_create(
2023-02-17 07:07:32.048560 2023-02-17 07:07:32.017 39 ERROR keystone.server.flask.application   File "/var/lib/kolla/venv/lib/python3.9/site-packages/dogpile/cache/region.py", line 1042, in get_or_create
2023-02-17 07:07:32.048580 2023-02-17 07:07:32.017 39 ERROR keystone.server.flask.application     with Lock(
2023-02-17 07:07:32.048598 2023-02-17 07:07:32.017 39 ERROR keystone.server.flask.application   File "/var/lib/kolla/venv/lib/python3.9/site-packages/dogpile/lock.py", line 185, in __enter__
2023-02-17 07:07:32.048617 2023-02-17 07:07:32.017 39 ERROR keystone.server.flask.application     return self._enter()
2023-02-17 07:07:32.048639 2023-02-17 07:07:32.017 39 ERROR keystone.server.flask.application   File "/var/lib/kolla/venv/lib/python3.9/site-packages/dogpile/lock.py", line 94, in _enter
2023-02-17 07:07:32.048658 2023-02-17 07:07:32.017 39 ERROR keystone.server.flask.application     generated = self._enter_create(value, createdtime)
2023-02-17 07:07:32.048676 2023-02-17 07:07:32.017 39 ERROR keystone.server.flask.application   File "/var/lib/kolla/venv/lib/python3.9/site-packages/dogpile/lock.py", line 178, in _enter_create
2023-02-17 07:07:32.048700 2023-02-17 07:07:32.017 39 ERROR keystone.server.flask.application     return self.creator()
2023-02-17 07:07:32.048717 2023-02-17 07:07:32.017 39 ERROR keystone.server.flask.application   File "/var/lib/kolla/venv/lib/python3.9/site-packages/dogpile/cache/region.py", line 995, in gen_value
2023-02-17 07:07:32.048735 2023-02-17 07:07:32.017 39 ERROR keystone.server.flask.application     created_value = creator(
2023-02-17 07:07:32.048754 2023-02-17 07:07:32.017 39 ERROR keystone.server.flask.application   File "/var/lib/kolla/venv/lib/python3.9/site-packages/keystone/resource/core.py", line 903, in get_project
2023-02-17 07:07:32.048775 2023-02-17 07:07:32.017 39 ERROR keystone.server.flask.application     return self.driver.get_project(project_id)
2023-02-17 07:07:32.048792 2023-02-17 07:07:32.017 39 ERROR keystone.server.flask.application   File "/var/lib/kolla/venv/lib/python3.9/site-packages/keystone/resource/backends/sql.py", line 49, in get_project
2023-02-17 07:07:32.048811 2023-02-17 07:07:32.017 39 ERROR keystone.server.flask.application     return self._get_project(session, project_id).to_dict()
2023-02-17 07:07:32.048829 2023-02-17 07:07:32.017 39 ERROR keystone.server.flask.application   File "/var/lib/kolla/venv/lib/python3.9/site-packages/keystone/resource/backends/sql.py", line 44, in _get_project
2023-02-17 07:07:32.048847 2023-02-17 07:07:32.017 39 ERROR keystone.server.flask.application     raise exception.ProjectNotFound(project_id=project_id)
2023-02-17 07:07:32.048865 2023-02-17 07:07:32.017 39 ERROR keystone.server.flask.application keystone.exception.ProjectNotFound: Could not find project: service.
2023-02-17 07:07:32.048883 2023-02-17 07:07:32.017 39 ERROR keystone.server.flask.application \x1b[00m
2023-02-17 07:07:40.878115 2023-02-17 07:07:40.868 37 ERROR keystone.server.flask.application [None req-a6af9c69-00f5-48c5-b03e-5593554c4423 6be3aded1b9c47bcbc94453e09ec12ff - - all default -] Could not find project: service.: keystone.exception.ProjectNotFound: Could not find project: service.
2023-02-17 07:07:40.878166 2023-02-17 07:07:40.868 37 ERROR keystone.server.flask.application Traceback (most recent call last):
2023-02-17 07:07:40.878195 2023-02-17 07:07:40.868 37 ERROR keystone.server.flask.application   File "/var/lib/kolla/venv/lib/python3.9/site-packages/flask/app.py", line 1820, in full_dispatch_request
2023-02-17 07:07:40.878207 2023-02-17 07:07:40.868 37 ERROR keystone.server.flask.application     rv = self.dispatch_request()
2023-02-17 07:07:40.878217 2023-02-17 07:07:40.868 37 ERROR keystone.server.flask.application   File "/var/lib/kolla/venv/lib/python3.9/site-packages/flask/app.py", line 1796, in dispatch_request
2023-02-17 07:07:40.878227 2023-02-17 07:07:40.868 37 ERROR keystone.server.flask.application     return self.ensure_sync(self.view_functions[rule.endpoint])(**view_args)
2023-02-17 07:07:40.878237 2023-02-17 07:07:40.868 37 ERROR keystone.server.flask.application   File "/var/lib/kolla/venv/lib/python3.9/site-packages/flask_restful/__init__.py", line 467, in wrapper
2023-02-17 07:07:40.878247 2023-02-17 07:07:40.868 37 ERROR keystone.server.flask.application     resp = resource(*args, **kwargs)
2023-02-17 07:07:40.878264 2023-02-17 07:07:40.868 37 ERROR keystone.server.flask.application   File "/var/lib/kolla/venv/lib/python3.9/site-packages/flask/views.py", line 107, in view
2023-02-17 07:07:40.878276 2023-02-17 07:07:40.868 37 ERROR keystone.server.flask.application     return current_app.ensure_sync(self.dispatch_request)(**kwargs)
2023-02-17 07:07:40.878287 2023-02-17 07:07:40.868 37 ERROR keystone.server.flask.application   File "/var/lib/kolla/venv/lib/python3.9/site-packages/flask_restful/__init__.py", line 582, in dispatch_request
2023-02-17 07:07:40.878297 2023-02-17 07:07:40.868 37 ERROR keystone.server.flask.application     resp = meth(*args, **kwargs)
2023-02-17 07:07:40.878306 2023-02-17 07:07:40.868 37 ERROR keystone.server.flask.application   File "/var/lib/kolla/venv/lib/python3.9/site-packages/keystone/api/projects.py", line 151, in get
2023-02-17 07:07:40.878317 2023-02-17 07:07:40.868 37 ERROR keystone.server.flask.application     return self._get_project(project_id)
2023-02-17 07:07:40.878326 2023-02-17 07:07:40.868 37 ERROR keystone.server.flask.application   File "/var/lib/kolla/venv/lib/python3.9/site-packages/keystone/api/projects.py", line 107, in _get_project
2023-02-17 07:07:40.878340 2023-02-17 07:07:40.868 37 ERROR keystone.server.flask.application     project = PROVIDERS.resource_api.get_project(project_id)
2023-02-17 07:07:40.878350 2023-02-17 07:07:40.868 37 ERROR keystone.server.flask.application   File "/var/lib/kolla/venv/lib/python3.9/site-packages/keystone/common/manager.py", line 115, in wrapped
2023-02-17 07:07:40.878363 2023-02-17 07:07:40.868 37 ERROR keystone.server.flask.application     __ret_val = __f(*args, **kwargs)
2023-02-17 07:07:40.878375 2023-02-17 07:07:40.868 37 ERROR keystone.server.flask.application   File "/var/lib/kolla/venv/lib/python3.9/site-packages/decorator.py", line 232, in fun
2023-02-17 07:07:40.878385 2023-02-17 07:07:40.868 37 ERROR keystone.server.flask.application     return caller(func, *(extras + args), **kw)
2023-02-17 07:07:40.878403 2023-02-17 07:07:40.868 37 ERROR keystone.server.flask.application   File "/var/lib/kolla/venv/lib/python3.9/site-packages/dogpile/cache/region.py", line 1577, in get_or_create_for_user_func
2023-02-17 07:07:40.878415 2023-02-17 07:07:40.868 37 ERROR keystone.server.flask.application     return self.get_or_create(
2023-02-17 07:07:40.878425 2023-02-17 07:07:40.868 37 ERROR keystone.server.flask.application   File "/var/lib/kolla/venv/lib/python3.9/site-packages/dogpile/cache/region.py", line 1042, in get_or_create
2023-02-17 07:07:40.878436 2023-02-17 07:07:40.868 37 ERROR keystone.server.flask.application     with Lock(
2023-02-17 07:07:40.878445 2023-02-17 07:07:40.868 37 ERROR keystone.server.flask.application   File "/var/lib/kolla/venv/lib/python3.9/site-packages/dogpile/lock.py", line 185, in __enter__
2023-02-17 07:07:40.878455 2023-02-17 07:07:40.868 37 ERROR keystone.server.flask.application     return self._enter()
2023-02-17 07:07:40.878476 2023-02-17 07:07:40.868 37 ERROR keystone.server.flask.application   File "/var/lib/kolla/venv/lib/python3.9/site-packages/dogpile/lock.py", line 94, in _enter
2023-02-17 07:07:40.878487 2023-02-17 07:07:40.868 37 ERROR keystone.server.flask.application     generated = self._enter_create(value, createdtime)
2023-02-17 07:07:40.878497 2023-02-17 07:07:40.868 37 ERROR keystone.server.flask.application   File "/var/lib/kolla/venv/lib/python3.9/site-packages/dogpile/lock.py", line 178, in _enter_create
2023-02-17 07:07:40.878507 2023-02-17 07:07:40.868 37 ERROR keystone.server.flask.application     return self.creator()
2023-02-17 07:07:40.878516 2023-02-17 07:07:40.868 37 ERROR keystone.server.flask.application   File "/var/lib/kolla/venv/lib/python3.9/site-packages/dogpile/cache/region.py", line 995, in gen_value
2023-02-17 07:07:40.878526 2023-02-17 07:07:40.868 37 ERROR keystone.server.flask.application     created_value = creator(
2023-02-17 07:07:40.878535 2023-02-17 07:07:40.868 37 ERROR keystone.server.flask.application   File "/var/lib/kolla/venv/lib/python3.9/site-packages/keystone/resource/core.py", line 903, in get_project
2023-02-17 07:07:40.878545 2023-02-17 07:07:40.868 37 ERROR keystone.server.flask.application     return self.driver.get_project(project_id)
2023-02-17 07:07:40.878555 2023-02-17 07:07:40.868 37 ERROR keystone.server.flask.application   File "/var/lib/kolla/venv/lib/python3.9/site-packages/keystone/resource/backends/sql.py", line 49, in get_project
2023-02-17 07:07:40.878565 2023-02-17 07:07:40.868 37 ERROR keystone.server.flask.application     return self._get_project(session, project_id).to_dict()
2023-02-17 07:07:40.878575 2023-02-17 07:07:40.868 37 ERROR keystone.server.flask.application   File "/var/lib/kolla/venv/lib/python3.9/site-packages/keystone/resource/backends/sql.py", line 44, in _get_project
2023-02-17 07:07:40.878585 2023-02-17 07:07:40.868 37 ERROR keystone.server.flask.application     raise exception.ProjectNotFound(project_id=project_id)
2023-02-17 07:07:40.878594 2023-02-17 07:07:40.868 37 ERROR keystone.server.flask.application keystone.exception.ProjectNotFound: Could not find project: service.
2023-02-17 07:07:40.878604 2023-02-17 07:07:40.868 37 ERROR keystone.server.flask.application \x1b[00m
2023-02-17 07:07:54.507258 2023-02-17 07:07:54.494 37 ERROR keystone.server.flask.application [None req-b395c030-d9c5-4722-88d1-2aebaf4e539e 6be3aded1b9c47bcbc94453e09ec12ff - - all default -] Could not find role: admin.: keystone.exception.RoleNotFound: Could not find role: admin.
2023-02-17 07:07:54.507422 2023-02-17 07:07:54.494 37 ERROR keystone.server.flask.application Traceback (most recent call last):
2023-02-17 07:07:54.507443 2023-02-17 07:07:54.494 37 ERROR keystone.server.flask.application   File "/var/lib/kolla/venv/lib/python3.9/site-packages/flask/app.py", line 1820, in full_dispatch_request
2023-02-17 07:07:54.507459 2023-02-17 07:07:54.494 37 ERROR keystone.server.flask.application     rv = self.dispatch_request()
2023-02-17 07:07:54.507474 2023-02-17 07:07:54.494 37 ERROR keystone.server.flask.application   File "/var/lib/kolla/venv/lib/python3.9/site-packages/flask/app.py", line 1796, in dispatch_request
2023-02-17 07:07:54.507490 2023-02-17 07:07:54.494 37 ERROR keystone.server.flask.application     return self.ensure_sync(self.view_functions[rule.endpoint])(**view_args)
2023-02-17 07:07:54.507505 2023-02-17 07:07:54.494 37 ERROR keystone.server.flask.application   File "/var/lib/kolla/venv/lib/python3.9/site-packages/flask_restful/__init__.py", line 467, in wrapper
2023-02-17 07:07:54.507521 2023-02-17 07:07:54.494 37 ERROR keystone.server.flask.application     resp = resource(*args, **kwargs)
2023-02-17 07:07:54.507545 2023-02-17 07:07:54.494 37 ERROR keystone.server.flask.application   File "/var/lib/kolla/venv/lib/python3.9/site-packages/flask/views.py", line 107, in view
2023-02-17 07:07:54.507564 2023-02-17 07:07:54.494 37 ERROR keystone.server.flask.application     return current_app.ensure_sync(self.dispatch_request)(**kwargs)
2023-02-17 07:07:54.507580 2023-02-17 07:07:54.494 37 ERROR keystone.server.flask.application   File "/var/lib/kolla/venv/lib/python3.9/site-packages/flask_restful/__init__.py", line 582, in dispatch_request
2023-02-17 07:07:54.507620 2023-02-17 07:07:54.494 37 ERROR keystone.server.flask.application     resp = meth(*args, **kwargs)
2023-02-17 07:07:54.507637 2023-02-17 07:07:54.494 37 ERROR keystone.server.flask.application   File "/var/lib/kolla/venv/lib/python3.9/site-packages/keystone/api/roles.py", line 50, in get
2023-02-17 07:07:54.507652 2023-02-17 07:07:54.494 37 ERROR keystone.server.flask.application     return self._get_role(role_id)
2023-02-17 07:07:54.507666 2023-02-17 07:07:54.494 37 ERROR keystone.server.flask.application   File "/var/lib/kolla/venv/lib/python3.9/site-packages/keystone/api/roles.py", line 70, in _get_role
2023-02-17 07:07:54.507682 2023-02-17 07:07:54.494 37 ERROR keystone.server.flask.application     ENFORCER.enforce_call(action='identity:get_role')
2023-02-17 07:07:54.507707 2023-02-17 07:07:54.494 37 ERROR keystone.server.flask.application   File "/var/lib/kolla/venv/lib/python3.9/site-packages/keystone/common/rbac_enforcer/enforcer.py", line 402, in enforce_call
2023-02-17 07:07:54.507727 2023-02-17 07:07:54.494 37 ERROR keystone.server.flask.application     policy_dict.update(cls._extract_member_target_data(
2023-02-17 07:07:54.507750 2023-02-17 07:07:54.494 37 ERROR keystone.server.flask.application   File "/var/lib/kolla/venv/lib/python3.9/site-packages/keystone/common/rbac_enforcer/enforcer.py", line 234, in _extract_member_target_data
2023-02-17 07:07:54.507769 2023-02-17 07:07:54.494 37 ERROR keystone.server.flask.application     member_name: func(flask.request.view_args[key])
2023-02-17 07:07:54.507784 2023-02-17 07:07:54.494 37 ERROR keystone.server.flask.application   File "/var/lib/kolla/venv/lib/python3.9/site-packages/keystone/common/manager.py", line 115, in wrapped
2023-02-17 07:07:54.507799 2023-02-17 07:07:54.494 37 ERROR keystone.server.flask.application     __ret_val = __f(*args, **kwargs)
2023-02-17 07:07:54.507814 2023-02-17 07:07:54.494 37 ERROR keystone.server.flask.application   File "/var/lib/kolla/venv/lib/python3.9/site-packages/decorator.py", line 232, in fun
2023-02-17 07:07:54.507828 2023-02-17 07:07:54.494 37 ERROR keystone.server.flask.application     return caller(func, *(extras + args), **kw)
2023-02-17 07:07:54.507843 2023-02-17 07:07:54.494 37 ERROR keystone.server.flask.application   File "/var/lib/kolla/venv/lib/python3.9/site-packages/dogpile/cache/region.py", line 1577, in get_or_create_for_user_func
2023-02-17 07:07:54.507858 2023-02-17 07:07:54.494 37 ERROR keystone.server.flask.application     return self.get_or_create(
2023-02-17 07:07:54.507872 2023-02-17 07:07:54.494 37 ERROR keystone.server.flask.application   File "/var/lib/kolla/venv/lib/python3.9/site-packages/dogpile/cache/region.py", line 1042, in get_or_create
2023-02-17 07:07:54.507888 2023-02-17 07:07:54.494 37 ERROR keystone.server.flask.application     with Lock(
2023-02-17 07:07:54.507902 2023-02-17 07:07:54.494 37 ERROR keystone.server.flask.application   File "/var/lib/kolla/venv/lib/python3.9/site-packages/dogpile/lock.py", line 185, in __enter__
2023-02-17 07:07:54.507917 2023-02-17 07:07:54.494 37 ERROR keystone.server.flask.application     return self._enter()
2023-02-17 07:07:54.507931 2023-02-17 07:07:54.494 37 ERROR keystone.server.flask.application   File "/var/lib/kolla/venv/lib/python3.9/site-packages/dogpile/lock.py", line 94, in _enter
2023-02-17 07:07:54.507947 2023-02-17 07:07:54.494 37 ERROR keystone.server.flask.application     generated = self._enter_create(value, createdtime)
2023-02-17 07:07:54.507961 2023-02-17 07:07:54.494 37 ERROR keystone.server.flask.application   File "/var/lib/kolla/venv/lib/python3.9/site-packages/dogpile/lock.py", line 178, in _enter_create
2023-02-17 07:07:54.507976 2023-02-17 07:07:54.494 37 ERROR keystone.server.flask.application     return self.creator()
2023-02-17 07:07:54.507999 2023-02-17 07:07:54.494 37 ERROR keystone.server.flask.application   File "/var/lib/kolla/venv/lib/python3.9/site-packages/dogpile/cache/region.py", line 995, in gen_value
2023-02-17 07:07:54.508136 2023-02-17 07:07:54.494 37 ERROR keystone.server.flask.application     created_value = creator(
2023-02-17 07:07:54.508166 2023-02-17 07:07:54.494 37 ERROR keystone.server.flask.application   File "/var/lib/kolla/venv/lib/python3.9/site-packages/keystone/assignment/core.py", line 1276, in get_role
2023-02-17 07:07:54.508182 2023-02-17 07:07:54.494 37 ERROR keystone.server.flask.application     return self.driver.get_role(role_id)
2023-02-17 07:07:54.508197 2023-02-17 07:07:54.494 37 ERROR keystone.server.flask.application   File "/var/lib/kolla/venv/lib/python3.9/site-packages/keystone/assignment/role_backends/sql.py", line 70, in get_role
2023-02-17 07:07:54.508212 2023-02-17 07:07:54.494 37 ERROR keystone.server.flask.application     return self._get_role(session, role_id).to_dict()
2023-02-17 07:07:54.508227 2023-02-17 07:07:54.494 37 ERROR keystone.server.flask.application   File "/var/lib/kolla/venv/lib/python3.9/site-packages/keystone/assignment/role_backends/sql.py", line 65, in _get_role
2023-02-17 07:07:54.508243 2023-02-17 07:07:54.494 37 ERROR keystone.server.flask.application     raise exception.RoleNotFound(role_id=role_id)
2023-02-17 07:07:54.508257 2023-02-17 07:07:54.494 37 ERROR keystone.server.flask.application keystone.exception.RoleNotFound: Could not find role: admin.
2023-02-17 07:07:54.508272 2023-02-17 07:07:54.494 37 ERROR keystone.server.flask.application \x1b[00m
2023-02-17 07:07:55.889231 2023-02-17 07:07:55.879 37 ERROR keystone.server.flask.application [None req-0210ae5f-fe93-4635-ab34-ee18e8ac00e1 6be3aded1b9c47bcbc94453e09ec12ff - - all default -] Could not find user: ironic.: keystone.exception.UserNotFound: Could not find user: ironic.
2023-02-17 07:07:55.889291 2023-02-17 07:07:55.879 37 ERROR keystone.server.flask.application Traceback (most recent call last):
2023-02-17 07:07:55.889335 2023-02-17 07:07:55.879 37 ERROR keystone.server.flask.application   File "/var/lib/kolla/venv/lib/python3.9/site-packages/flask/app.py", line 1820, in full_dispatch_request
2023-02-17 07:07:55.889352 2023-02-17 07:07:55.879 37 ERROR keystone.server.flask.application     rv = self.dispatch_request()
2023-02-17 07:07:55.889368 2023-02-17 07:07:55.879 37 ERROR keystone.server.flask.application   File "/var/lib/kolla/venv/lib/python3.9/site-packages/flask/app.py", line 1796, in dispatch_request
2023-02-17 07:07:55.889386 2023-02-17 07:07:55.879 37 ERROR keystone.server.flask.application     return self.ensure_sync(self.view_functions[rule.endpoint])(**view_args)
2023-02-17 07:07:55.889402 2023-02-17 07:07:55.879 37 ERROR keystone.server.flask.application   File "/var/lib/kolla/venv/lib/python3.9/site-packages/flask_restful/__init__.py", line 467, in wrapper
2023-02-17 07:07:55.889419 2023-02-17 07:07:55.879 37 ERROR keystone.server.flask.application     resp = resource(*args, **kwargs)
2023-02-17 07:07:55.889435 2023-02-17 07:07:55.879 37 ERROR keystone.server.flask.application   File "/var/lib/kolla/venv/lib/python3.9/site-packages/flask/views.py", line 107, in view
2023-02-17 07:07:55.889452 2023-02-17 07:07:55.879 37 ERROR keystone.server.flask.application     return current_app.ensure_sync(self.dispatch_request)(**kwargs)
2023-02-17 07:07:55.889469 2023-02-17 07:07:55.879 37 ERROR keystone.server.flask.application   File "/var/lib/kolla/venv/lib/python3.9/site-packages/flask_restful/__init__.py", line 582, in dispatch_request
2023-02-17 07:07:55.889486 2023-02-17 07:07:55.879 37 ERROR keystone.server.flask.application     resp = meth(*args, **kwargs)
2023-02-17 07:07:55.889502 2023-02-17 07:07:55.879 37 ERROR keystone.server.flask.application   File "/var/lib/kolla/venv/lib/python3.9/site-packages/keystone/api/users.py", line 182, in get
2023-02-17 07:07:55.889518 2023-02-17 07:07:55.879 37 ERROR keystone.server.flask.application     return self._get_user(user_id)
2023-02-17 07:07:55.889534 2023-02-17 07:07:55.879 37 ERROR keystone.server.flask.application   File "/var/lib/kolla/venv/lib/python3.9/site-packages/keystone/api/users.py", line 194, in _get_user
2023-02-17 07:07:55.889598 2023-02-17 07:07:55.879 37 ERROR keystone.server.flask.application     ref = PROVIDERS.identity_api.get_user(user_id)
2023-02-17 07:07:55.889620 2023-02-17 07:07:55.879 37 ERROR keystone.server.flask.application   File "/var/lib/kolla/venv/lib/python3.9/site-packages/keystone/common/manager.py", line 115, in wrapped
2023-02-17 07:07:55.889636 2023-02-17 07:07:55.879 37 ERROR keystone.server.flask.application     __ret_val = __f(*args, **kwargs)
2023-02-17 07:07:55.889652 2023-02-17 07:07:55.879 37 ERROR keystone.server.flask.application   File "/var/lib/kolla/venv/lib/python3.9/site-packages/keystone/identity/core.py", line 414, in wrapper
2023-02-17 07:07:55.889669 2023-02-17 07:07:55.879 37 ERROR keystone.server.flask.application     return f(self, *args, **kwargs)
2023-02-17 07:07:55.889685 2023-02-17 07:07:55.879 37 ERROR keystone.server.flask.application   File "/var/lib/kolla/venv/lib/python3.9/site-packages/keystone/identity/core.py", line 424, in wrapper
2023-02-17 07:07:55.889701 2023-02-17 07:07:55.879 37 ERROR keystone.server.flask.application     return f(self, *args, **kwargs)
2023-02-17 07:07:55.889717 2023-02-17 07:07:55.879 37 ERROR keystone.server.flask.application   File "/var/lib/kolla/venv/lib/python3.9/site-packages/decorator.py", line 232, in fun
2023-02-17 07:07:55.889734 2023-02-17 07:07:55.879 37 ERROR keystone.server.flask.application     return caller(func, *(extras + args), **kw)
2023-02-17 07:07:55.889750 2023-02-17 07:07:55.879 37 ERROR keystone.server.flask.application   File "/var/lib/kolla/venv/lib/python3.9/site-packages/dogpile/cache/region.py", line 1577, in get_or_create_for_user_func
2023-02-17 07:07:55.889767 2023-02-17 07:07:55.879 37 ERROR keystone.server.flask.application     return self.get_or_create(
2023-02-17 07:07:55.889785 2023-02-17 07:07:55.879 37 ERROR keystone.server.flask.application   File "/var/lib/kolla/venv/lib/python3.9/site-packages/dogpile/cache/region.py", line 1042, in get_or_create
2023-02-17 07:07:55.889834 2023-02-17 07:07:55.879 37 ERROR keystone.server.flask.application     with Lock(
2023-02-17 07:07:55.889851 2023-02-17 07:07:55.879 37 ERROR keystone.server.flask.application   File "/var/lib/kolla/venv/lib/python3.9/site-packages/dogpile/lock.py", line 185, in __enter__
2023-02-17 07:07:55.889869 2023-02-17 07:07:55.879 37 ERROR keystone.server.flask.application     return self._enter()
2023-02-17 07:07:55.889882 2023-02-17 07:07:55.879 37 ERROR keystone.server.flask.application   File "/var/lib/kolla/venv/lib/python3.9/site-packages/dogpile/lock.py", line 94, in _enter
2023-02-17 07:07:55.889896 2023-02-17 07:07:55.879 37 ERROR keystone.server.flask.application     generated = self._enter_create(value, createdtime)
2023-02-17 07:07:55.889910 2023-02-17 07:07:55.879 37 ERROR keystone.server.flask.application   File "/var/lib/kolla/venv/lib/python3.9/site-packages/dogpile/lock.py", line 178, in _enter_create
2023-02-17 07:07:55.889923 2023-02-17 07:07:55.879 37 ERROR keystone.server.flask.application     return self.creator()
2023-02-17 07:07:55.889937 2023-02-17 07:07:55.879 37 ERROR keystone.server.flask.application   File "/var/lib/kolla/venv/lib/python3.9/site-packages/dogpile/cache/region.py", line 995, in gen_value
2023-02-17 07:07:55.889950 2023-02-17 07:07:55.879 37 ERROR keystone.server.flask.application     created_value = creator(
2023-02-17 07:07:55.889964 2023-02-17 07:07:55.879 37 ERROR keystone.server.flask.application   File "/var/lib/kolla/venv/lib/python3.9/site-packages/keystone/identity/core.py", line 1011, in get_user
2023-02-17 07:07:55.889978 2023-02-17 07:07:55.879 37 ERROR keystone.server.flask.application     ref = driver.get_user(entity_id)
2023-02-17 07:07:55.889991 2023-02-17 07:07:55.879 37 ERROR keystone.server.flask.application   File "/var/lib/kolla/venv/lib/python3.9/site-packages/keystone/identity/backends/sql.py", line 200, in get_user
2023-02-17 07:07:55.890005 2023-02-17 07:07:55.879 37 ERROR keystone.server.flask.application     self._get_user(session, user_id).to_dict())
2023-02-17 07:07:55.890119 2023-02-17 07:07:55.879 37 ERROR keystone.server.flask.application   File "/var/lib/kolla/venv/lib/python3.9/site-packages/keystone/identity/backends/sql.py", line 194, in _get_user
2023-02-17 07:07:55.890143 2023-02-17 07:07:55.879 37 ERROR keystone.server.flask.application     raise exception.UserNotFound(user_id=user_id)
2023-02-17 07:07:55.890157 2023-02-17 07:07:55.879 37 ERROR keystone.server.flask.application keystone.exception.UserNotFound: Could not find user: ironic.
2023-02-17 07:07:55.890171 2023-02-17 07:07:55.879 37 ERROR keystone.server.flask.application \x1b[00m
2023-02-17 07:07:56.799504 2023-02-17 07:07:56.784 38 ERROR keystone.server.flask.application [None req-8ed236db-fb54-42bb-bdc9-151287e0401a 6be3aded1b9c47bcbc94453e09ec12ff - - all default -] Could not find project: service.: keystone.exception.ProjectNotFound: Could not find project: service.
2023-02-17 07:07:56.799553 2023-02-17 07:07:56.784 38 ERROR keystone.server.flask.application Traceback (most recent call last):
2023-02-17 07:07:56.799565 2023-02-17 07:07:56.784 38 ERROR keystone.server.flask.application   File "/var/lib/kolla/venv/lib/python3.9/site-packages/flask/app.py", line 1820, in full_dispatch_request
2023-02-17 07:07:56.799575 2023-02-17 07:07:56.784 38 ERROR keystone.server.flask.application     rv = self.dispatch_request()
2023-02-17 07:07:56.799584 2023-02-17 07:07:56.784 38 ERROR keystone.server.flask.application   File "/var/lib/kolla/venv/lib/python3.9/site-packages/flask/app.py", line 1796, in dispatch_request
2023-02-17 07:07:56.799594 2023-02-17 07:07:56.784 38 ERROR keystone.server.flask.application     return self.ensure_sync(self.view_functions[rule.endpoint])(**view_args)
2023-02-17 07:07:56.799604 2023-02-17 07:07:56.784 38 ERROR keystone.server.flask.application   File "/var/lib/kolla/venv/lib/python3.9/site-packages/flask_restful/__init__.py", line 467, in wrapper
2023-02-17 07:07:56.799614 2023-02-17 07:07:56.784 38 ERROR keystone.server.flask.application     resp = resource(*args, **kwargs)
2023-02-17 07:07:56.799631 2023-02-17 07:07:56.784 38 ERROR keystone.server.flask.application   File "/var/lib/kolla/venv/lib/python3.9/site-packages/flask/views.py", line 107, in view
2023-02-17 07:07:56.799644 2023-02-17 07:07:56.784 38 ERROR keystone.server.flask.application     return current_app.ensure_sync(self.dispatch_request)(**kwargs)
2023-02-17 07:07:56.799653 2023-02-17 07:07:56.784 38 ERROR keystone.server.flask.application   File "/var/lib/kolla/venv/lib/python3.9/site-packages/flask_restful/__init__.py", line 582, in dispatch_request
2023-02-17 07:07:56.799663 2023-02-17 07:07:56.784 38 ERROR keystone.server.flask.application     resp = meth(*args, **kwargs)
2023-02-17 07:07:56.799672 2023-02-17 07:07:56.784 38 ERROR keystone.server.flask.application   File "/var/lib/kolla/venv/lib/python3.9/site-packages/keystone/api/projects.py", line 151, in get
2023-02-17 07:07:56.799682 2023-02-17 07:07:56.784 38 ERROR keystone.server.flask.application     return self._get_project(project_id)
2023-02-17 07:07:56.799692 2023-02-17 07:07:56.784 38 ERROR keystone.server.flask.application   File "/var/lib/kolla/venv/lib/python3.9/site-packages/keystone/api/projects.py", line 107, in _get_project
2023-02-17 07:07:56.799701 2023-02-17 07:07:56.784 38 ERROR keystone.server.flask.application     project = PROVIDERS.resource_api.get_project(project_id)
2023-02-17 07:07:56.799711 2023-02-17 07:07:56.784 38 ERROR keystone.server.flask.application   File "/var/lib/kolla/venv/lib/python3.9/site-packages/keystone/common/manager.py", line 115, in wrapped
2023-02-17 07:07:56.799732 2023-02-17 07:07:56.784 38 ERROR keystone.server.flask.application     __ret_val = __f(*args, **kwargs)
2023-02-17 07:07:56.799741 2023-02-17 07:07:56.784 38 ERROR keystone.server.flask.application   File "/var/lib/kolla/venv/lib/python3.9/site-packages/decorator.py", line 232, in fun
2023-02-17 07:07:56.799751 2023-02-17 07:07:56.784 38 ERROR keystone.server.flask.application     return caller(func, *(extras + args), **kw)
2023-02-17 07:07:56.799798 2023-02-17 07:07:56.784 38 ERROR keystone.server.flask.application   File "/var/lib/kolla/venv/lib/python3.9/site-packages/dogpile/cache/region.py", line 1577, in get_or_create_for_user_func
2023-02-17 07:07:56.799812 2023-02-17 07:07:56.784 38 ERROR keystone.server.flask.application     return self.get_or_create(
2023-02-17 07:07:56.799822 2023-02-17 07:07:56.784 38 ERROR keystone.server.flask.application   File "/var/lib/kolla/venv/lib/python3.9/site-packages/dogpile/cache/region.py", line 1042, in get_or_create
2023-02-17 07:07:56.799833 2023-02-17 07:07:56.784 38 ERROR keystone.server.flask.application     with Lock(
2023-02-17 07:07:56.799842 2023-02-17 07:07:56.784 38 ERROR keystone.server.flask.application   File "/var/lib/kolla/venv/lib/python3.9/site-packages/dogpile/lock.py", line 185, in __enter__
2023-02-17 07:07:56.799852 2023-02-17 07:07:56.784 38 ERROR keystone.server.flask.application     return self._enter()
2023-02-17 07:07:56.799862 2023-02-17 07:07:56.784 38 ERROR keystone.server.flask.application   File "/var/lib/kolla/venv/lib/python3.9/site-packages/dogpile/lock.py", line 94, in _enter
2023-02-17 07:07:56.799872 2023-02-17 07:07:56.784 38 ERROR keystone.server.flask.application     generated = self._enter_create(value, createdtime)
2023-02-17 07:07:56.799882 2023-02-17 07:07:56.784 38 ERROR keystone.server.flask.application   File "/var/lib/kolla/venv/lib/python3.9/site-packages/dogpile/lock.py", line 178, in _enter_create
2023-02-17 07:07:56.799892 2023-02-17 07:07:56.784 38 ERROR keystone.server.flask.application     return self.creator()
2023-02-17 07:07:56.799901 2023-02-17 07:07:56.784 38 ERROR keystone.server.flask.application   File "/var/lib/kolla/venv/lib/python3.9/site-packages/dogpile/cache/region.py", line 995, in gen_value
2023-02-17 07:07:56.799911 2023-02-17 07:07:56.784 38 ERROR keystone.server.flask.application     created_value = creator(
2023-02-17 07:07:56.799921 2023-02-17 07:07:56.784 38 ERROR keystone.server.flask.application   File "/var/lib/kolla/venv/lib/python3.9/site-packages/keystone/resource/core.py", line 903, in get_project
2023-02-17 07:07:56.799931 2023-02-17 07:07:56.784 38 ERROR keystone.server.flask.application     return self.driver.get_project(project_id)
2023-02-17 07:07:56.799941 2023-02-17 07:07:56.784 38 ERROR keystone.server.flask.application   File "/var/lib/kolla/venv/lib/python3.9/site-packages/keystone/resource/backends/sql.py", line 49, in get_project
2023-02-17 07:07:56.799951 2023-02-17 07:07:56.784 38 ERROR keystone.server.flask.application     return self._get_project(session, project_id).to_dict()
2023-02-17 07:07:56.799961 2023-02-17 07:07:56.784 38 ERROR keystone.server.flask.application   File "/var/lib/kolla/venv/lib/python3.9/site-packages/keystone/resource/backends/sql.py", line 44, in _get_project
2023-02-17 07:07:56.799971 2023-02-17 07:07:56.784 38 ERROR keystone.server.flask.application     raise exception.ProjectNotFound(project_id=project_id)
2023-02-17 07:07:56.799981 2023-02-17 07:07:56.784 38 ERROR keystone.server.flask.application keystone.exception.ProjectNotFound: Could not find project: service.
2023-02-17 07:07:56.799990 2023-02-17 07:07:56.784 38 ERROR keystone.server.flask.application \x1b[00m
2023-02-17 07:08:05.634598 2023-02-17 07:08:05.628 39 ERROR keystone.server.flask.application [None req-661c570b-d1b5-495d-b32d-78353c812286 6be3aded1b9c47bcbc94453e09ec12ff - - all default -] Could not find role: admin.: keystone.exception.RoleNotFound: Could not find role: admin.
2023-02-17 07:08:05.634642 2023-02-17 07:08:05.628 39 ERROR keystone.server.flask.application Traceback (most recent call last):
2023-02-17 07:08:05.634655 2023-02-17 07:08:05.628 39 ERROR keystone.server.flask.application   File "/var/lib/kolla/venv/lib/python3.9/site-packages/flask/app.py", line 1820, in full_dispatch_request
2023-02-17 07:08:05.634666 2023-02-17 07:08:05.628 39 ERROR keystone.server.flask.application     rv = self.dispatch_request()
2023-02-17 07:08:05.634688 2023-02-17 07:08:05.628 39 ERROR keystone.server.flask.application   File "/var/lib/kolla/venv/lib/python3.9/site-packages/flask/app.py", line 1796, in dispatch_request
2023-02-17 07:08:05.634742 2023-02-17 07:08:05.628 39 ERROR keystone.server.flask.application     return self.ensure_sync(self.view_functions[rule.endpoint])(**view_args)
2023-02-17 07:08:05.634754 2023-02-17 07:08:05.628 39 ERROR keystone.server.flask.application   File "/var/lib/kolla/venv/lib/python3.9/site-packages/flask_restful/__init__.py", line 467, in wrapper
2023-02-17 07:08:05.634764 2023-02-17 07:08:05.628 39 ERROR keystone.server.flask.application     resp = resource(*args, **kwargs)
2023-02-17 07:08:05.634780 2023-02-17 07:08:05.628 39 ERROR keystone.server.flask.application   File "/var/lib/kolla/venv/lib/python3.9/site-packages/flask/views.py", line 107, in view
2023-02-17 07:08:05.634793 2023-02-17 07:08:05.628 39 ERROR keystone.server.flask.application     return current_app.ensure_sync(self.dispatch_request)(**kwargs)
2023-02-17 07:08:05.634803 2023-02-17 07:08:05.628 39 ERROR keystone.server.flask.application   File "/var/lib/kolla/venv/lib/python3.9/site-packages/flask_restful/__init__.py", line 582, in dispatch_request
2023-02-17 07:08:05.634813 2023-02-17 07:08:05.628 39 ERROR keystone.server.flask.application     resp = meth(*args, **kwargs)
2023-02-17 07:08:05.634822 2023-02-17 07:08:05.628 39 ERROR keystone.server.flask.application   File "/var/lib/kolla/venv/lib/python3.9/site-packages/keystone/api/roles.py", line 50, in get
2023-02-17 07:08:05.634832 2023-02-17 07:08:05.628 39 ERROR keystone.server.flask.application     return self._get_role(role_id)
2023-02-17 07:08:05.634842 2023-02-17 07:08:05.628 39 ERROR keystone.server.flask.application   File "/var/lib/kolla/venv/lib/python3.9/site-packages/keystone/api/roles.py", line 70, in _get_role
2023-02-17 07:08:05.634852 2023-02-17 07:08:05.628 39 ERROR keystone.server.flask.application     ENFORCER.enforce_call(action='identity:get_role')
2023-02-17 07:08:05.634872 2023-02-17 07:08:05.628 39 ERROR keystone.server.flask.application   File "/var/lib/kolla/venv/lib/python3.9/site-packages/keystone/common/rbac_enforcer/enforcer.py", line 402, in enforce_call
2023-02-17 07:08:05.634883 2023-02-17 07:08:05.628 39 ERROR keystone.server.flask.application     policy_dict.update(cls._extract_member_target_data(
2023-02-17 07:08:05.634893 2023-02-17 07:08:05.628 39 ERROR keystone.server.flask.application   File "/var/lib/kolla/venv/lib/python3.9/site-packages/keystone/common/rbac_enforcer/enforcer.py", line 234, in _extract_member_target_data
2023-02-17 07:08:05.634903 2023-02-17 07:08:05.628 39 ERROR keystone.server.flask.application     member_name: func(flask.request.view_args[key])
2023-02-17 07:08:05.634913 2023-02-17 07:08:05.628 39 ERROR keystone.server.flask.application   File "/var/lib/kolla/venv/lib/python3.9/site-packages/keystone/common/manager.py", line 115, in wrapped
2023-02-17 07:08:05.634923 2023-02-17 07:08:05.628 39 ERROR keystone.server.flask.application     __ret_val = __f(*args, **kwargs)
2023-02-17 07:08:05.634933 2023-02-17 07:08:05.628 39 ERROR keystone.server.flask.application   File "/var/lib/kolla/venv/lib/python3.9/site-packages/decorator.py", line 232, in fun
2023-02-17 07:08:05.634943 2023-02-17 07:08:05.628 39 ERROR keystone.server.flask.application     return caller(func, *(extras + args), **kw)
2023-02-17 07:08:05.634952 2023-02-17 07:08:05.628 39 ERROR keystone.server.flask.application   File "/var/lib/kolla/venv/lib/python3.9/site-packages/dogpile/cache/region.py", line 1577, in get_or_create_for_user_func
2023-02-17 07:08:05.634962 2023-02-17 07:08:05.628 39 ERROR keystone.server.flask.application     return self.get_or_create(
2023-02-17 07:08:05.634972 2023-02-17 07:08:05.628 39 ERROR keystone.server.flask.application   File "/var/lib/kolla/venv/lib/python3.9/site-packages/dogpile/cache/region.py", line 1042, in get_or_create
2023-02-17 07:08:05.634982 2023-02-17 07:08:05.628 39 ERROR keystone.server.flask.application     with Lock(
2023-02-17 07:08:05.635012 2023-02-17 07:08:05.628 39 ERROR keystone.server.flask.application   File "/var/lib/kolla/venv/lib/python3.9/site-packages/dogpile/lock.py", line 185, in __enter__
2023-02-17 07:08:05.635111 2023-02-17 07:08:05.628 39 ERROR keystone.server.flask.application     return self._enter()
2023-02-17 07:08:05.635131 2023-02-17 07:08:05.628 39 ERROR keystone.server.flask.application   File "/var/lib/kolla/venv/lib/python3.9/site-packages/dogpile/lock.py", line 94, in _enter
2023-02-17 07:08:05.635141 2023-02-17 07:08:05.628 39 ERROR keystone.server.flask.application     generated = self._enter_create(value, createdtime)
2023-02-17 07:08:05.635151 2023-02-17 07:08:05.628 39 ERROR keystone.server.flask.application   File "/var/lib/kolla/venv/lib/python3.9/site-packages/dogpile/lock.py", line 178, in _enter_create
2023-02-17 07:08:05.635161 2023-02-17 07:08:05.628 39 ERROR keystone.server.flask.application     return self.creator()
2023-02-17 07:08:05.635170 2023-02-17 07:08:05.628 39 ERROR keystone.server.flask.application   File "/var/lib/kolla/venv/lib/python3.9/site-packages/dogpile/cache/region.py", line 995, in gen_value
2023-02-17 07:08:05.635180 2023-02-17 07:08:05.628 39 ERROR keystone.server.flask.application     created_value = creator(
2023-02-17 07:08:05.635190 2023-02-17 07:08:05.628 39 ERROR keystone.server.flask.application   File "/var/lib/kolla/venv/lib/python3.9/site-packages/keystone/assignment/core.py", line 1276, in get_role
2023-02-17 07:08:05.635200 2023-02-17 07:08:05.628 39 ERROR keystone.server.flask.application     return self.driver.get_role(role_id)
2023-02-17 07:08:05.635209 2023-02-17 07:08:05.628 39 ERROR keystone.server.flask.application   File "/var/lib/kolla/venv/lib/python3.9/site-packages/keystone/assignment/role_backends/sql.py", line 70, in get_role
2023-02-17 07:08:05.635219 2023-02-17 07:08:05.628 39 ERROR keystone.server.flask.application     return self._get_role(session, role_id).to_dict()
2023-02-17 07:08:05.635229 2023-02-17 07:08:05.628 39 ERROR keystone.server.flask.application   File "/var/lib/kolla/venv/lib/python3.9/site-packages/keystone/assignment/role_backends/sql.py", line 65, in _get_role
2023-02-17 07:08:05.635239 2023-02-17 07:08:05.628 39 ERROR keystone.server.flask.application     raise exception.RoleNotFound(role_id=role_id)
2023-02-17 07:08:05.635249 2023-02-17 07:08:05.628 39 ERROR keystone.server.flask.application keystone.exception.RoleNotFound: Could not find role: admin.
2023-02-17 07:08:05.635259 2023-02-17 07:08:05.628 39 ERROR keystone.server.flask.application \x1b[00m
2023-02-17 07:08:06.720443 2023-02-17 07:08:06.713 39 ERROR keystone.server.flask.application [None req-8faf4397-c1cb-40d2-a220-6fb9e6a9e347 6be3aded1b9c47bcbc94453e09ec12ff - - all default -] Could not find user: ironic-inspector.: keystone.exception.UserNotFound: Could not find user: ironic-inspector.
2023-02-17 07:08:06.720484 2023-02-17 07:08:06.713 39 ERROR keystone.server.flask.application Traceback (most recent call last):
2023-02-17 07:08:06.720496 2023-02-17 07:08:06.713 39 ERROR keystone.server.flask.application   File "/var/lib/kolla/venv/lib/python3.9/site-packages/flask/app.py", line 1820, in full_dispatch_request
2023-02-17 07:08:06.720507 2023-02-17 07:08:06.713 39 ERROR keystone.server.flask.application     rv = self.dispatch_request()
2023-02-17 07:08:06.720517 2023-02-17 07:08:06.713 39 ERROR keystone.server.flask.application   File "/var/lib/kolla/venv/lib/python3.9/site-packages/flask/app.py", line 1796, in dispatch_request
2023-02-17 07:08:06.720527 2023-02-17 07:08:06.713 39 ERROR keystone.server.flask.application     return self.ensure_sync(self.view_functions[rule.endpoint])(**view_args)
2023-02-17 07:08:06.720537 2023-02-17 07:08:06.713 39 ERROR keystone.server.flask.application   File "/var/lib/kolla/venv/lib/python3.9/site-packages/flask_restful/__init__.py", line 467, in wrapper
2023-02-17 07:08:06.720547 2023-02-17 07:08:06.713 39 ERROR keystone.server.flask.application     resp = resource(*args, **kwargs)
2023-02-17 07:08:06.720557 2023-02-17 07:08:06.713 39 ERROR keystone.server.flask.application   File "/var/lib/kolla/venv/lib/python3.9/site-packages/flask/views.py", line 107, in view
2023-02-17 07:08:06.720596 2023-02-17 07:08:06.713 39 ERROR keystone.server.flask.application     return current_app.ensure_sync(self.dispatch_request)(**kwargs)
2023-02-17 07:08:06.720609 2023-02-17 07:08:06.713 39 ERROR keystone.server.flask.application   File "/var/lib/kolla/venv/lib/python3.9/site-packages/flask_restful/__init__.py", line 582, in dispatch_request
2023-02-17 07:08:06.720619 2023-02-17 07:08:06.713 39 ERROR keystone.server.flask.application     resp = meth(*args, **kwargs)
2023-02-17 07:08:06.720629 2023-02-17 07:08:06.713 39 ERROR keystone.server.flask.application   File "/var/lib/kolla/venv/lib/python3.9/site-packages/keystone/api/users.py", line 182, in get
2023-02-17 07:08:06.720639 2023-02-17 07:08:06.713 39 ERROR keystone.server.flask.application     return self._get_user(user_id)
2023-02-17 07:08:06.720648 2023-02-17 07:08:06.713 39 ERROR keystone.server.flask.application   File "/var/lib/kolla/venv/lib/python3.9/site-packages/keystone/api/users.py", line 194, in _get_user
2023-02-17 07:08:06.720659 2023-02-17 07:08:06.713 39 ERROR keystone.server.flask.application     ref = PROVIDERS.identity_api.get_user(user_id)
2023-02-17 07:08:06.720669 2023-02-17 07:08:06.713 39 ERROR keystone.server.flask.application   File "/var/lib/kolla/venv/lib/python3.9/site-packages/keystone/common/manager.py", line 115, in wrapped
2023-02-17 07:08:06.720678 2023-02-17 07:08:06.713 39 ERROR keystone.server.flask.application     __ret_val = __f(*args, **kwargs)
2023-02-17 07:08:06.720688 2023-02-17 07:08:06.713 39 ERROR keystone.server.flask.application   File "/var/lib/kolla/venv/lib/python3.9/site-packages/keystone/identity/core.py", line 414, in wrapper
2023-02-17 07:08:06.720698 2023-02-17 07:08:06.713 39 ERROR keystone.server.flask.application     return f(self, *args, **kwargs)
2023-02-17 07:08:06.720707 2023-02-17 07:08:06.713 39 ERROR keystone.server.flask.application   File "/var/lib/kolla/venv/lib/python3.9/site-packages/keystone/identity/core.py", line 424, in wrapper
2023-02-17 07:08:06.720717 2023-02-17 07:08:06.713 39 ERROR keystone.server.flask.application     return f(self, *args, **kwargs)
2023-02-17 07:08:06.720727 2023-02-17 07:08:06.713 39 ERROR keystone.server.flask.application   File "/var/lib/kolla/venv/lib/python3.9/site-packages/decorator.py", line 232, in fun
2023-02-17 07:08:06.720737 2023-02-17 07:08:06.713 39 ERROR keystone.server.flask.application     return caller(func, *(extras + args), **kw)
2023-02-17 07:08:06.720747 2023-02-17 07:08:06.713 39 ERROR keystone.server.flask.application   File "/var/lib/kolla/venv/lib/python3.9/site-packages/dogpile/cache/region.py", line 1577, in get_or_create_for_user_func
2023-02-17 07:08:06.720756 2023-02-17 07:08:06.713 39 ERROR keystone.server.flask.application     return self.get_or_create(
2023-02-17 07:08:06.720766 2023-02-17 07:08:06.713 39 ERROR keystone.server.flask.application   File "/var/lib/kolla/venv/lib/python3.9/site-packages/dogpile/cache/region.py", line 1042, in get_or_create
2023-02-17 07:08:06.720777 2023-02-17 07:08:06.713 39 ERROR keystone.server.flask.application     with Lock(
2023-02-17 07:08:06.720787 2023-02-17 07:08:06.713 39 ERROR keystone.server.flask.application   File "/var/lib/kolla/venv/lib/python3.9/site-packages/dogpile/lock.py", line 185, in __enter__
2023-02-17 07:08:06.720803 2023-02-17 07:08:06.713 39 ERROR keystone.server.flask.application     return self._enter()
2023-02-17 07:08:06.720812 2023-02-17 07:08:06.713 39 ERROR keystone.server.flask.application   File "/var/lib/kolla/venv/lib/python3.9/site-packages/dogpile/lock.py", line 94, in _enter
2023-02-17 07:08:06.720822 2023-02-17 07:08:06.713 39 ERROR keystone.server.flask.application     generated = self._enter_create(value, createdtime)
2023-02-17 07:08:06.720832 2023-02-17 07:08:06.713 39 ERROR keystone.server.flask.application   File "/var/lib/kolla/venv/lib/python3.9/site-packages/dogpile/lock.py", line 178, in _enter_create
2023-02-17 07:08:06.720865 2023-02-17 07:08:06.713 39 ERROR keystone.server.flask.application     return self.creator()
2023-02-17 07:08:06.720877 2023-02-17 07:08:06.713 39 ERROR keystone.server.flask.application   File "/var/lib/kolla/venv/lib/python3.9/site-packages/dogpile/cache/region.py", line 995, in gen_value
2023-02-17 07:08:06.720887 2023-02-17 07:08:06.713 39 ERROR keystone.server.flask.application     created_value = creator(
2023-02-17 07:08:06.720897 2023-02-17 07:08:06.713 39 ERROR keystone.server.flask.application   File "/var/lib/kolla/venv/lib/python3.9/site-packages/keystone/identity/core.py", line 1011, in get_user
2023-02-17 07:08:06.720906 2023-02-17 07:08:06.713 39 ERROR keystone.server.flask.application     ref = driver.get_user(entity_id)
2023-02-17 07:08:06.720916 2023-02-17 07:08:06.713 39 ERROR keystone.server.flask.application   File "/var/lib/kolla/venv/lib/python3.9/site-packages/keystone/identity/backends/sql.py", line 200, in get_user
2023-02-17 07:08:06.720926 2023-02-17 07:08:06.713 39 ERROR keystone.server.flask.application     self._get_user(session, user_id).to_dict())
2023-02-17 07:08:06.720935 2023-02-17 07:08:06.713 39 ERROR keystone.server.flask.application   File "/var/lib/kolla/venv/lib/python3.9/site-packages/keystone/identity/backends/sql.py", line 194, in _get_user
2023-02-17 07:08:06.720945 2023-02-17 07:08:06.713 39 ERROR keystone.server.flask.application     raise exception.UserNotFound(user_id=user_id)
2023-02-17 07:08:06.720955 2023-02-17 07:08:06.713 39 ERROR keystone.server.flask.application keystone.exception.UserNotFound: Could not find user: ironic-inspector.
2023-02-17 07:08:06.720965 2023-02-17 07:08:06.713 39 ERROR keystone.server.flask.application \x1b[00m
2023-02-17 07:08:07.496964 2023-02-17 07:08:07.493 37 ERROR keystone.server.flask.application [None req-29527560-894d-49e8-9713-b0f8e0b6e360 6be3aded1b9c47bcbc94453e09ec12ff - - all default -] Could not find project: service.: keystone.exception.ProjectNotFound: Could not find project: service.
2023-02-17 07:08:07.497006 2023-02-17 07:08:07.493 37 ERROR keystone.server.flask.application Traceback (most recent call last):
2023-02-17 07:08:07.497018 2023-02-17 07:08:07.493 37 ERROR keystone.server.flask.application   File "/var/lib/kolla/venv/lib/python3.9/site-packages/flask/app.py", line 1820, in full_dispatch_request
2023-02-17 07:08:07.497098 2023-02-17 07:08:07.493 37 ERROR keystone.server.flask.application     rv = self.dispatch_request()
2023-02-17 07:08:07.497116 2023-02-17 07:08:07.493 37 ERROR keystone.server.flask.application   File "/var/lib/kolla/venv/lib/python3.9/site-packages/flask/app.py", line 1796, in dispatch_request
2023-02-17 07:08:07.497126 2023-02-17 07:08:07.493 37 ERROR keystone.server.flask.application     return self.ensure_sync(self.view_functions[rule.endpoint])(**view_args)
2023-02-17 07:08:07.497136 2023-02-17 07:08:07.493 37 ERROR keystone.server.flask.application   File "/var/lib/kolla/venv/lib/python3.9/site-packages/flask_restful/__init__.py", line 467, in wrapper
2023-02-17 07:08:07.497145 2023-02-17 07:08:07.493 37 ERROR keystone.server.flask.application     resp = resource(*args, **kwargs)
2023-02-17 07:08:07.497155 2023-02-17 07:08:07.493 37 ERROR keystone.server.flask.application   File "/var/lib/kolla/venv/lib/python3.9/site-packages/flask/views.py", line 107, in view
2023-02-17 07:08:07.497174 2023-02-17 07:08:07.493 37 ERROR keystone.server.flask.application     return current_app.ensure_sync(self.dispatch_request)(**kwargs)
2023-02-17 07:08:07.497187 2023-02-17 07:08:07.493 37 ERROR keystone.server.flask.application   File "/var/lib/kolla/venv/lib/python3.9/site-packages/flask_restful/__init__.py", line 582, in dispatch_request
2023-02-17 07:08:07.497197 2023-02-17 07:08:07.493 37 ERROR keystone.server.flask.application     resp = meth(*args, **kwargs)
2023-02-17 07:08:07.497207 2023-02-17 07:08:07.493 37 ERROR keystone.server.flask.application   File "/var/lib/kolla/venv/lib/python3.9/site-packages/keystone/api/projects.py", line 151, in get
2023-02-17 07:08:07.497233 2023-02-17 07:08:07.493 37 ERROR keystone.server.flask.application     return self._get_project(project_id)
2023-02-17 07:08:07.497245 2023-02-17 07:08:07.493 37 ERROR keystone.server.flask.application   File "/var/lib/kolla/venv/lib/python3.9/site-packages/keystone/api/projects.py", line 107, in _get_project
2023-02-17 07:08:07.497254 2023-02-17 07:08:07.493 37 ERROR keystone.server.flask.application     project = PROVIDERS.resource_api.get_project(project_id)
2023-02-17 07:08:07.497264 2023-02-17 07:08:07.493 37 ERROR keystone.server.flask.application   File "/var/lib/kolla/venv/lib/python3.9/site-packages/keystone/common/manager.py", line 115, in wrapped
2023-02-17 07:08:07.497274 2023-02-17 07:08:07.493 37 ERROR keystone.server.flask.application     __ret_val = __f(*args, **kwargs)
2023-02-17 07:08:07.497284 2023-02-17 07:08:07.493 37 ERROR keystone.server.flask.application   File "/var/lib/kolla/venv/lib/python3.9/site-packages/decorator.py", line 232, in fun
2023-02-17 07:08:07.497293 2023-02-17 07:08:07.493 37 ERROR keystone.server.flask.application     return caller(func, *(extras + args), **kw)
2023-02-17 07:08:07.497304 2023-02-17 07:08:07.493 37 ERROR keystone.server.flask.application   File "/var/lib/kolla/venv/lib/python3.9/site-packages/dogpile/cache/region.py", line 1577, in get_or_create_for_user_func
2023-02-17 07:08:07.497314 2023-02-17 07:08:07.493 37 ERROR keystone.server.flask.application     return self.get_or_create(
2023-02-17 07:08:07.497323 2023-02-17 07:08:07.493 37 ERROR keystone.server.flask.application   File "/var/lib/kolla/venv/lib/python3.9/site-packages/dogpile/cache/region.py", line 1042, in get_or_create
2023-02-17 07:08:07.497333 2023-02-17 07:08:07.493 37 ERROR keystone.server.flask.application     with Lock(
2023-02-17 07:08:07.497343 2023-02-17 07:08:07.493 37 ERROR keystone.server.flask.application   File "/var/lib/kolla/venv/lib/python3.9/site-packages/dogpile/lock.py", line 185, in __enter__
2023-02-17 07:08:07.497353 2023-02-17 07:08:07.493 37 ERROR keystone.server.flask.application     return self._enter()
2023-02-17 07:08:07.497362 2023-02-17 07:08:07.493 37 ERROR keystone.server.flask.application   File "/var/lib/kolla/venv/lib/python3.9/site-packages/dogpile/lock.py", line 94, in _enter
2023-02-17 07:08:07.497372 2023-02-17 07:08:07.493 37 ERROR keystone.server.flask.application     generated = self._enter_create(value, createdtime)
2023-02-17 07:08:07.497382 2023-02-17 07:08:07.493 37 ERROR keystone.server.flask.application   File "/var/lib/kolla/venv/lib/python3.9/site-packages/dogpile/lock.py", line 178, in _enter_create
2023-02-17 07:08:07.497392 2023-02-17 07:08:07.493 37 ERROR keystone.server.flask.application     return self.creator()
2023-02-17 07:08:07.497402 2023-02-17 07:08:07.493 37 ERROR keystone.server.flask.application   File "/var/lib/kolla/venv/lib/python3.9/site-packages/dogpile/cache/region.py", line 995, in gen_value
2023-02-17 07:08:07.497412 2023-02-17 07:08:07.493 37 ERROR keystone.server.flask.application     created_value = creator(
2023-02-17 07:08:07.497421 2023-02-17 07:08:07.493 37 ERROR keystone.server.flask.application   File "/var/lib/kolla/venv/lib/python3.9/site-packages/keystone/resource/core.py", line 903, in get_project
2023-02-17 07:08:07.497431 2023-02-17 07:08:07.493 37 ERROR keystone.server.flask.application     return self.driver.get_project(project_id)
2023-02-17 07:08:07.497441 2023-02-17 07:08:07.493 37 ERROR keystone.server.flask.application   File "/var/lib/kolla/venv/lib/python3.9/site-packages/keystone/resource/backends/sql.py", line 49, in get_project
2023-02-17 07:08:07.497450 2023-02-17 07:08:07.493 37 ERROR keystone.server.flask.application     return self._get_project(session, project_id).to_dict()
2023-02-17 07:08:07.497460 2023-02-17 07:08:07.493 37 ERROR keystone.server.flask.application   File "/var/lib/kolla/venv/lib/python3.9/site-packages/keystone/resource/backends/sql.py", line 44, in _get_project
2023-02-17 07:08:07.497470 2023-02-17 07:08:07.493 37 ERROR keystone.server.flask.application     raise exception.ProjectNotFound(project_id=project_id)
2023-02-17 07:08:07.497489 2023-02-17 07:08:07.493 37 ERROR keystone.server.flask.application keystone.exception.ProjectNotFound: Could not find project: service.
2023-02-17 07:08:07.497500 2023-02-17 07:08:07.493 37 ERROR keystone.server.flask.application \x1b[00m
2023-02-17 07:10:50.242129 2023-02-17 07:10:50.238 39 ERROR keystone.server.flask.application [None req-b9bd03e2-06ef-42ef-b91f-d65c8e080bb9 6be3aded1b9c47bcbc94453e09ec12ff - - all default -] Could not find project: service.: keystone.exception.ProjectNotFound: Could not find project: service.
2023-02-17 07:10:50.242179 2023-02-17 07:10:50.238 39 ERROR keystone.server.flask.application Traceback (most recent call last):
2023-02-17 07:10:50.242191 2023-02-17 07:10:50.238 39 ERROR keystone.server.flask.application   File "/var/lib/kolla/venv/lib/python3.9/site-packages/flask/app.py", line 1820, in full_dispatch_request
2023-02-17 07:10:50.242202 2023-02-17 07:10:50.238 39 ERROR keystone.server.flask.application     rv = self.dispatch_request()
2023-02-17 07:10:50.242212 2023-02-17 07:10:50.238 39 ERROR keystone.server.flask.application   File "/var/lib/kolla/venv/lib/python3.9/site-packages/flask/app.py", line 1796, in dispatch_request
2023-02-17 07:10:50.242222 2023-02-17 07:10:50.238 39 ERROR keystone.server.flask.application     return self.ensure_sync(self.view_functions[rule.endpoint])(**view_args)
2023-02-17 07:10:50.242232 2023-02-17 07:10:50.238 39 ERROR keystone.server.flask.application   File "/var/lib/kolla/venv/lib/python3.9/site-packages/flask_restful/__init__.py", line 467, in wrapper
2023-02-17 07:10:50.242242 2023-02-17 07:10:50.238 39 ERROR keystone.server.flask.application     resp = resource(*args, **kwargs)
2023-02-17 07:10:50.242259 2023-02-17 07:10:50.238 39 ERROR keystone.server.flask.application   File "/var/lib/kolla/venv/lib/python3.9/site-packages/flask/views.py", line 107, in view
2023-02-17 07:10:50.242272 2023-02-17 07:10:50.238 39 ERROR keystone.server.flask.application     return current_app.ensure_sync(self.dispatch_request)(**kwargs)
2023-02-17 07:10:50.242282 2023-02-17 07:10:50.238 39 ERROR keystone.server.flask.application   File "/var/lib/kolla/venv/lib/python3.9/site-packages/flask_restful/__init__.py", line 582, in dispatch_request
2023-02-17 07:10:50.242293 2023-02-17 07:10:50.238 39 ERROR keystone.server.flask.application     resp = meth(*args, **kwargs)
2023-02-17 07:10:50.242302 2023-02-17 07:10:50.238 39 ERROR keystone.server.flask.application   File "/var/lib/kolla/venv/lib/python3.9/site-packages/keystone/api/projects.py", line 151, in get
2023-02-17 07:10:50.242313 2023-02-17 07:10:50.238 39 ERROR keystone.server.flask.application     return self._get_project(project_id)
2023-02-17 07:10:50.242323 2023-02-17 07:10:50.238 39 ERROR keystone.server.flask.application   File "/var/lib/kolla/venv/lib/python3.9/site-packages/keystone/api/projects.py", line 107, in _get_project
2023-02-17 07:10:50.242333 2023-02-17 07:10:50.238 39 ERROR keystone.server.flask.application     project = PROVIDERS.resource_api.get_project(project_id)
2023-02-17 07:10:50.242343 2023-02-17 07:10:50.238 39 ERROR keystone.server.flask.application   File "/var/lib/kolla/venv/lib/python3.9/site-packages/keystone/common/manager.py", line 115, in wrapped
2023-02-17 07:10:50.242353 2023-02-17 07:10:50.238 39 ERROR keystone.server.flask.application     __ret_val = __f(*args, **kwargs)
2023-02-17 07:10:50.242363 2023-02-17 07:10:50.238 39 ERROR keystone.server.flask.application   File "/var/lib/kolla/venv/lib/python3.9/site-packages/decorator.py", line 232, in fun
2023-02-17 07:10:50.242373 2023-02-17 07:10:50.238 39 ERROR keystone.server.flask.application     return caller(func, *(extras + args), **kw)
2023-02-17 07:10:50.242383 2023-02-17 07:10:50.238 39 ERROR keystone.server.flask.application   File "/var/lib/kolla/venv/lib/python3.9/site-packages/dogpile/cache/region.py", line 1577, in get_or_create_for_user_func
2023-02-17 07:10:50.242393 2023-02-17 07:10:50.238 39 ERROR keystone.server.flask.application     return self.get_or_create(
2023-02-17 07:10:50.242421 2023-02-17 07:10:50.238 39 ERROR keystone.server.flask.application   File "/var/lib/kolla/venv/lib/python3.9/site-packages/dogpile/cache/region.py", line 1042, in get_or_create
2023-02-17 07:10:50.242433 2023-02-17 07:10:50.238 39 ERROR keystone.server.flask.application     with Lock(
2023-02-17 07:10:50.242443 2023-02-17 07:10:50.238 39 ERROR keystone.server.flask.application   File "/var/lib/kolla/venv/lib/python3.9/site-packages/dogpile/lock.py", line 185, in __enter__
2023-02-17 07:10:50.242453 2023-02-17 07:10:50.238 39 ERROR keystone.server.flask.application     return self._enter()
2023-02-17 07:10:50.242463 2023-02-17 07:10:50.238 39 ERROR keystone.server.flask.application   File "/var/lib/kolla/venv/lib/python3.9/site-packages/dogpile/lock.py", line 94, in _enter
2023-02-17 07:10:50.242473 2023-02-17 07:10:50.238 39 ERROR keystone.server.flask.application     generated = self._enter_create(value, createdtime)
2023-02-17 07:10:50.242483 2023-02-17 07:10:50.238 39 ERROR keystone.server.flask.application   File "/var/lib/kolla/venv/lib/python3.9/site-packages/dogpile/lock.py", line 178, in _enter_create
2023-02-17 07:10:50.242493 2023-02-17 07:10:50.238 39 ERROR keystone.server.flask.application     return self.creator()
2023-02-17 07:10:50.242503 2023-02-17 07:10:50.238 39 ERROR keystone.server.flask.application   File "/var/lib/kolla/venv/lib/python3.9/site-packages/dogpile/cache/region.py", line 995, in gen_value
2023-02-17 07:10:50.242513 2023-02-17 07:10:50.238 39 ERROR keystone.server.flask.application     created_value = creator(
2023-02-17 07:10:50.242523 2023-02-17 07:10:50.238 39 ERROR keystone.server.flask.application   File "/var/lib/kolla/venv/lib/python3.9/site-packages/keystone/resource/core.py", line 903, in get_project
2023-02-17 07:10:50.242533 2023-02-17 07:10:50.238 39 ERROR keystone.server.flask.application     return self.driver.get_project(project_id)
2023-02-17 07:10:50.242543 2023-02-17 07:10:50.238 39 ERROR keystone.server.flask.application   File "/var/lib/kolla/venv/lib/python3.9/site-packages/keystone/resource/backends/sql.py", line 49, in get_project
2023-02-17 07:10:50.242553 2023-02-17 07:10:50.238 39 ERROR keystone.server.flask.application     return self._get_project(session, project_id).to_dict()
2023-02-17 07:10:50.242563 2023-02-17 07:10:50.238 39 ERROR keystone.server.flask.application   File "/var/lib/kolla/venv/lib/python3.9/site-packages/keystone/resource/backends/sql.py", line 44, in _get_project
2023-02-17 07:10:50.242573 2023-02-17 07:10:50.238 39 ERROR keystone.server.flask.application     raise exception.ProjectNotFound(project_id=project_id)
2023-02-17 07:10:50.242583 2023-02-17 07:10:50.238 39 ERROR keystone.server.flask.application keystone.exception.ProjectNotFound: Could not find project: service.
2023-02-17 07:10:50.242592 2023-02-17 07:10:50.238 39 ERROR keystone.server.flask.application \x1b[00m
2023-02-17 07:11:04.536113 2023-02-17 07:11:04.527 38 ERROR keystone.server.flask.application [None req-713e0f4c-af90-4169-a26b-1f51aca85154 6be3aded1b9c47bcbc94453e09ec12ff - - all default -] Could not find role: admin.: keystone.exception.RoleNotFound: Could not find role: admin.
2023-02-17 07:11:04.536171 2023-02-17 07:11:04.527 38 ERROR keystone.server.flask.application Traceback (most recent call last):
2023-02-17 07:11:04.536184 2023-02-17 07:11:04.527 38 ERROR keystone.server.flask.application   File "/var/lib/kolla/venv/lib/python3.9/site-packages/flask/app.py", line 1820, in full_dispatch_request
2023-02-17 07:11:04.536195 2023-02-17 07:11:04.527 38 ERROR keystone.server.flask.application     rv = self.dispatch_request()
2023-02-17 07:11:04.536205 2023-02-17 07:11:04.527 38 ERROR keystone.server.flask.application   File "/var/lib/kolla/venv/lib/python3.9/site-packages/flask/app.py", line 1796, in dispatch_request
2023-02-17 07:11:04.536216 2023-02-17 07:11:04.527 38 ERROR keystone.server.flask.application     return self.ensure_sync(self.view_functions[rule.endpoint])(**view_args)
2023-02-17 07:11:04.536226 2023-02-17 07:11:04.527 38 ERROR keystone.server.flask.application   File "/var/lib/kolla/venv/lib/python3.9/site-packages/flask_restful/__init__.py", line 467, in wrapper
2023-02-17 07:11:04.536259 2023-02-17 07:11:04.527 38 ERROR keystone.server.flask.application     resp = resource(*args, **kwargs)
2023-02-17 07:11:04.536304 2023-02-17 07:11:04.527 38 ERROR keystone.server.flask.application   File "/var/lib/kolla/venv/lib/python3.9/site-packages/flask/views.py", line 107, in view
2023-02-17 07:11:04.536335 2023-02-17 07:11:04.527 38 ERROR keystone.server.flask.application     return current_app.ensure_sync(self.dispatch_request)(**kwargs)
2023-02-17 07:11:04.536347 2023-02-17 07:11:04.527 38 ERROR keystone.server.flask.application   File "/var/lib/kolla/venv/lib/python3.9/site-packages/flask_restful/__init__.py", line 582, in dispatch_request
2023-02-17 07:11:04.536357 2023-02-17 07:11:04.527 38 ERROR keystone.server.flask.application     resp = meth(*args, **kwargs)
2023-02-17 07:11:04.536367 2023-02-17 07:11:04.527 38 ERROR keystone.server.flask.application   File "/var/lib/kolla/venv/lib/python3.9/site-packages/keystone/api/roles.py", line 50, in get
2023-02-17 07:11:04.536381 2023-02-17 07:11:04.527 38 ERROR keystone.server.flask.application     return self._get_role(role_id)
2023-02-17 07:11:04.536391 2023-02-17 07:11:04.527 38 ERROR keystone.server.flask.application   File "/var/lib/kolla/venv/lib/python3.9/site-packages/keystone/api/roles.py", line 70, in _get_role
2023-02-17 07:11:04.536401 2023-02-17 07:11:04.527 38 ERROR keystone.server.flask.application     ENFORCER.enforce_call(action='identity:get_role')
2023-02-17 07:11:04.536412 2023-02-17 07:11:04.527 38 ERROR keystone.server.flask.application   File "/var/lib/kolla/venv/lib/python3.9/site-packages/keystone/common/rbac_enforcer/enforcer.py", line 402, in enforce_call
2023-02-17 07:11:04.536422 2023-02-17 07:11:04.527 38 ERROR keystone.server.flask.application     policy_dict.update(cls._extract_member_target_data(
2023-02-17 07:11:04.536441 2023-02-17 07:11:04.527 38 ERROR keystone.server.flask.application   File "/var/lib/kolla/venv/lib/python3.9/site-packages/keystone/common/rbac_enforcer/enforcer.py", line 234, in _extract_member_target_data
2023-02-17 07:11:04.536454 2023-02-17 07:11:04.527 38 ERROR keystone.server.flask.application     member_name: func(flask.request.view_args[key])
2023-02-17 07:11:04.536464 2023-02-17 07:11:04.527 38 ERROR keystone.server.flask.application   File "/var/lib/kolla/venv/lib/python3.9/site-packages/keystone/common/manager.py", line 115, in wrapped
2023-02-17 07:11:04.536474 2023-02-17 07:11:04.527 38 ERROR keystone.server.flask.application     __ret_val = __f(*args, **kwargs)
2023-02-17 07:11:04.536484 2023-02-17 07:11:04.527 38 ERROR keystone.server.flask.application   File "/var/lib/kolla/venv/lib/python3.9/site-packages/decorator.py", line 232, in fun
2023-02-17 07:11:04.536494 2023-02-17 07:11:04.527 38 ERROR keystone.server.flask.application     return caller(func, *(extras + args), **kw)
2023-02-17 07:11:04.536504 2023-02-17 07:11:04.527 38 ERROR keystone.server.flask.application   File "/var/lib/kolla/venv/lib/python3.9/site-packages/dogpile/cache/region.py", line 1577, in get_or_create_for_user_func
2023-02-17 07:11:04.536514 2023-02-17 07:11:04.527 38 ERROR keystone.server.flask.application     return self.get_or_create(
2023-02-17 07:11:04.536524 2023-02-17 07:11:04.527 38 ERROR keystone.server.flask.application   File "/var/lib/kolla/venv/lib/python3.9/site-packages/dogpile/cache/region.py", line 1042, in get_or_create
2023-02-17 07:11:04.536534 2023-02-17 07:11:04.527 38 ERROR keystone.server.flask.application     with Lock(
2023-02-17 07:11:04.536544 2023-02-17 07:11:04.527 38 ERROR keystone.server.flask.application   File "/var/lib/kolla/venv/lib/python3.9/site-packages/dogpile/lock.py", line 185, in __enter__
2023-02-17 07:11:04.536554 2023-02-17 07:11:04.527 38 ERROR keystone.server.flask.application     return self._enter()
2023-02-17 07:11:04.536563 2023-02-17 07:11:04.527 38 ERROR keystone.server.flask.application   File "/var/lib/kolla/venv/lib/python3.9/site-packages/dogpile/lock.py", line 94, in _enter
2023-02-17 07:11:04.536586 2023-02-17 07:11:04.527 38 ERROR keystone.server.flask.application     generated = self._enter_create(value, createdtime)
2023-02-17 07:11:04.536597 2023-02-17 07:11:04.527 38 ERROR keystone.server.flask.application   File "/var/lib/kolla/venv/lib/python3.9/site-packages/dogpile/lock.py", line 178, in _enter_create
2023-02-17 07:11:04.536608 2023-02-17 07:11:04.527 38 ERROR keystone.server.flask.application     return self.creator()
2023-02-17 07:11:04.536617 2023-02-17 07:11:04.527 38 ERROR keystone.server.flask.application   File "/var/lib/kolla/venv/lib/python3.9/site-packages/dogpile/cache/region.py", line 995, in gen_value
2023-02-17 07:11:04.536628 2023-02-17 07:11:04.527 38 ERROR keystone.server.flask.application     created_value = creator(
2023-02-17 07:11:04.536637 2023-02-17 07:11:04.527 38 ERROR keystone.server.flask.application   File "/var/lib/kolla/venv/lib/python3.9/site-packages/keystone/assignment/core.py", line 1276, in get_role
2023-02-17 07:11:04.536647 2023-02-17 07:11:04.527 38 ERROR keystone.server.flask.application     return self.driver.get_role(role_id)
2023-02-17 07:11:04.536657 2023-02-17 07:11:04.527 38 ERROR keystone.server.flask.application   File "/var/lib/kolla/venv/lib/python3.9/site-packages/keystone/assignment/role_backends/sql.py", line 70, in get_role
2023-02-17 07:11:04.536668 2023-02-17 07:11:04.527 38 ERROR keystone.server.flask.application     return self._get_role(session, role_id).to_dict()
2023-02-17 07:11:04.536677 2023-02-17 07:11:04.527 38 ERROR keystone.server.flask.application   File "/var/lib/kolla/venv/lib/python3.9/site-packages/keystone/assignment/role_backends/sql.py", line 65, in _get_role
2023-02-17 07:11:04.536688 2023-02-17 07:11:04.527 38 ERROR keystone.server.flask.application     raise exception.RoleNotFound(role_id=role_id)
2023-02-17 07:11:04.536697 2023-02-17 07:11:04.527 38 ERROR keystone.server.flask.application keystone.exception.RoleNotFound: Could not find role: admin.
2023-02-17 07:11:04.536707 2023-02-17 07:11:04.527 38 ERROR keystone.server.flask.application \x1b[00m
2023-02-17 07:11:05.653011 2023-02-17 07:11:05.647 38 ERROR keystone.server.flask.application [None req-bac89709-e131-4dba-b52f-afa1b4fc6230 6be3aded1b9c47bcbc94453e09ec12ff - - all default -] Could not find user: neutron.: keystone.exception.UserNotFound: Could not find user: neutron.
2023-02-17 07:11:05.653110 2023-02-17 07:11:05.647 38 ERROR keystone.server.flask.application Traceback (most recent call last):
2023-02-17 07:11:05.653122 2023-02-17 07:11:05.647 38 ERROR keystone.server.flask.application   File "/var/lib/kolla/venv/lib/python3.9/site-packages/flask/app.py", line 1820, in full_dispatch_request
2023-02-17 07:11:05.653133 2023-02-17 07:11:05.647 38 ERROR keystone.server.flask.application     rv = self.dispatch_request()
2023-02-17 07:11:05.653142 2023-02-17 07:11:05.647 38 ERROR keystone.server.flask.application   File "/var/lib/kolla/venv/lib/python3.9/site-packages/flask/app.py", line 1796, in dispatch_request
2023-02-17 07:11:05.653153 2023-02-17 07:11:05.647 38 ERROR keystone.server.flask.application     return self.ensure_sync(self.view_functions[rule.endpoint])(**view_args)
2023-02-17 07:11:05.653163 2023-02-17 07:11:05.647 38 ERROR keystone.server.flask.application   File "/var/lib/kolla/venv/lib/python3.9/site-packages/flask_restful/__init__.py", line 467, in wrapper
2023-02-17 07:11:05.653173 2023-02-17 07:11:05.647 38 ERROR keystone.server.flask.application     resp = resource(*args, **kwargs)
2023-02-17 07:11:05.653183 2023-02-17 07:11:05.647 38 ERROR keystone.server.flask.application   File "/var/lib/kolla/venv/lib/python3.9/site-packages/flask/views.py", line 107, in view
2023-02-17 07:11:05.653193 2023-02-17 07:11:05.647 38 ERROR keystone.server.flask.application     return current_app.ensure_sync(self.dispatch_request)(**kwargs)
2023-02-17 07:11:05.653203 2023-02-17 07:11:05.647 38 ERROR keystone.server.flask.application   File "/var/lib/kolla/venv/lib/python3.9/site-packages/flask_restful/__init__.py", line 582, in dispatch_request
2023-02-17 07:11:05.653230 2023-02-17 07:11:05.647 38 ERROR keystone.server.flask.application     resp = meth(*args, **kwargs)
2023-02-17 07:11:05.653242 2023-02-17 07:11:05.647 38 ERROR keystone.server.flask.application   File "/var/lib/kolla/venv/lib/python3.9/site-packages/keystone/api/users.py", line 182, in get
2023-02-17 07:11:05.653252 2023-02-17 07:11:05.647 38 ERROR keystone.server.flask.application     return self._get_user(user_id)
2023-02-17 07:11:05.653262 2023-02-17 07:11:05.647 38 ERROR keystone.server.flask.application   File "/var/lib/kolla/venv/lib/python3.9/site-packages/keystone/api/users.py", line 194, in _get_user
2023-02-17 07:11:05.653287 2023-02-17 07:11:05.647 38 ERROR keystone.server.flask.application     ref = PROVIDERS.identity_api.get_user(user_id)
2023-02-17 07:11:05.653298 2023-02-17 07:11:05.647 38 ERROR keystone.server.flask.application   File "/var/lib/kolla/venv/lib/python3.9/site-packages/keystone/common/manager.py", line 115, in wrapped
2023-02-17 07:11:05.653308 2023-02-17 07:11:05.647 38 ERROR keystone.server.flask.application     __ret_val = __f(*args, **kwargs)
2023-02-17 07:11:05.653318 2023-02-17 07:11:05.647 38 ERROR keystone.server.flask.application   File "/var/lib/kolla/venv/lib/python3.9/site-packages/keystone/identity/core.py", line 414, in wrapper
2023-02-17 07:11:05.653328 2023-02-17 07:11:05.647 38 ERROR keystone.server.flask.application     return f(self, *args, **kwargs)
2023-02-17 07:11:05.653337 2023-02-17 07:11:05.647 38 ERROR keystone.server.flask.application   File "/var/lib/kolla/venv/lib/python3.9/site-packages/keystone/identity/core.py", line 424, in wrapper
2023-02-17 07:11:05.653347 2023-02-17 07:11:05.647 38 ERROR keystone.server.flask.application     return f(self, *args, **kwargs)
2023-02-17 07:11:05.653357 2023-02-17 07:11:05.647 38 ERROR keystone.server.flask.application   File "/var/lib/kolla/venv/lib/python3.9/site-packages/decorator.py", line 232, in fun
2023-02-17 07:11:05.653367 2023-02-17 07:11:05.647 38 ERROR keystone.server.flask.application     return caller(func, *(extras + args), **kw)
2023-02-17 07:11:05.653377 2023-02-17 07:11:05.647 38 ERROR keystone.server.flask.application   File "/var/lib/kolla/venv/lib/python3.9/site-packages/dogpile/cache/region.py", line 1577, in get_or_create_for_user_func
2023-02-17 07:11:05.653388 2023-02-17 07:11:05.647 38 ERROR keystone.server.flask.application     return self.get_or_create(
2023-02-17 07:11:05.653397 2023-02-17 07:11:05.647 38 ERROR keystone.server.flask.application   File "/var/lib/kolla/venv/lib/python3.9/site-packages/dogpile/cache/region.py", line 1042, in get_or_create
2023-02-17 07:11:05.653408 2023-02-17 07:11:05.647 38 ERROR keystone.server.flask.application     with Lock(
2023-02-17 07:11:05.653417 2023-02-17 07:11:05.647 38 ERROR keystone.server.flask.application   File "/var/lib/kolla/venv/lib/python3.9/site-packages/dogpile/lock.py", line 185, in __enter__
2023-02-17 07:11:05.653427 2023-02-17 07:11:05.647 38 ERROR keystone.server.flask.application     return self._enter()
2023-02-17 07:11:05.653437 2023-02-17 07:11:05.647 38 ERROR keystone.server.flask.application   File "/var/lib/kolla/venv/lib/python3.9/site-packages/dogpile/lock.py", line 94, in _enter
2023-02-17 07:11:05.653447 2023-02-17 07:11:05.647 38 ERROR keystone.server.flask.application     generated = self._enter_create(value, createdtime)
2023-02-17 07:11:05.653457 2023-02-17 07:11:05.647 38 ERROR keystone.server.flask.application   File "/var/lib/kolla/venv/lib/python3.9/site-packages/dogpile/lock.py", line 178, in _enter_create
2023-02-17 07:11:05.653467 2023-02-17 07:11:05.647 38 ERROR keystone.server.flask.application     return self.creator()
2023-02-17 07:11:05.653477 2023-02-17 07:11:05.647 38 ERROR keystone.server.flask.application   File "/var/lib/kolla/venv/lib/python3.9/site-packages/dogpile/cache/region.py", line 995, in gen_value
2023-02-17 07:11:05.653487 2023-02-17 07:11:05.647 38 ERROR keystone.server.flask.application     created_value = creator(
2023-02-17 07:11:05.653507 2023-02-17 07:11:05.647 38 ERROR keystone.server.flask.application   File "/var/lib/kolla/venv/lib/python3.9/site-packages/keystone/identity/core.py", line 1011, in get_user
2023-02-17 07:11:05.653518 2023-02-17 07:11:05.647 38 ERROR keystone.server.flask.application     ref = driver.get_user(entity_id)
2023-02-17 07:11:05.653528 2023-02-17 07:11:05.647 38 ERROR keystone.server.flask.application   File "/var/lib/kolla/venv/lib/python3.9/site-packages/keystone/identity/backends/sql.py", line 200, in get_user
2023-02-17 07:11:05.653538 2023-02-17 07:11:05.647 38 ERROR keystone.server.flask.application     self._get_user(session, user_id).to_dict())
2023-02-17 07:11:05.653548 2023-02-17 07:11:05.647 38 ERROR keystone.server.flask.application   File "/var/lib/kolla/venv/lib/python3.9/site-packages/keystone/identity/backends/sql.py", line 194, in _get_user
2023-02-17 07:11:05.653558 2023-02-17 07:11:05.647 38 ERROR keystone.server.flask.application     raise exception.UserNotFound(user_id=user_id)
2023-02-17 07:11:05.653571 2023-02-17 07:11:05.647 38 ERROR keystone.server.flask.application keystone.exception.UserNotFound: Could not find user: neutron.
2023-02-17 07:11:05.653581 2023-02-17 07:11:05.647 38 ERROR keystone.server.flask.application \x1b[00m
2023-02-17 07:11:06.456222 2023-02-17 07:11:06.453 39 ERROR keystone.server.flask.application [None req-e5e95a10-4417-4783-9c0d-5db8589b5915 6be3aded1b9c47bcbc94453e09ec12ff - - all default -] Could not find project: service.: keystone.exception.ProjectNotFound: Could not find project: service.
2023-02-17 07:11:06.456264 2023-02-17 07:11:06.453 39 ERROR keystone.server.flask.application Traceback (most recent call last):
2023-02-17 07:11:06.456288 2023-02-17 07:11:06.453 39 ERROR keystone.server.flask.application   File "/var/lib/kolla/venv/lib/python3.9/site-packages/flask/app.py", line 1820, in full_dispatch_request
2023-02-17 07:11:06.456298 2023-02-17 07:11:06.453 39 ERROR keystone.server.flask.application     rv = self.dispatch_request()
2023-02-17 07:11:06.456308 2023-02-17 07:11:06.453 39 ERROR keystone.server.flask.application   File "/var/lib/kolla/venv/lib/python3.9/site-packages/flask/app.py", line 1796, in dispatch_request
2023-02-17 07:11:06.456317 2023-02-17 07:11:06.453 39 ERROR keystone.server.flask.application     return self.ensure_sync(self.view_functions[rule.endpoint])(**view_args)
2023-02-17 07:11:06.456327 2023-02-17 07:11:06.453 39 ERROR keystone.server.flask.application   File "/var/lib/kolla/venv/lib/python3.9/site-packages/flask_restful/__init__.py", line 467, in wrapper
2023-02-17 07:11:06.456337 2023-02-17 07:11:06.453 39 ERROR keystone.server.flask.application     resp = resource(*args, **kwargs)
2023-02-17 07:11:06.456346 2023-02-17 07:11:06.453 39 ERROR keystone.server.flask.application   File "/var/lib/kolla/venv/lib/python3.9/site-packages/flask/views.py", line 107, in view
2023-02-17 07:11:06.456357 2023-02-17 07:11:06.453 39 ERROR keystone.server.flask.application     return current_app.ensure_sync(self.dispatch_request)(**kwargs)
2023-02-17 07:11:06.456366 2023-02-17 07:11:06.453 39 ERROR keystone.server.flask.application   File "/var/lib/kolla/venv/lib/python3.9/site-packages/flask_restful/__init__.py", line 582, in dispatch_request
2023-02-17 07:11:06.456376 2023-02-17 07:11:06.453 39 ERROR keystone.server.flask.application     resp = meth(*args, **kwargs)
2023-02-17 07:11:06.456385 2023-02-17 07:11:06.453 39 ERROR keystone.server.flask.application   File "/var/lib/kolla/venv/lib/python3.9/site-packages/keystone/api/projects.py", line 151, in get
2023-02-17 07:11:06.456395 2023-02-17 07:11:06.453 39 ERROR keystone.server.flask.application     return self._get_project(project_id)
2023-02-17 07:11:06.456404 2023-02-17 07:11:06.453 39 ERROR keystone.server.flask.application   File "/var/lib/kolla/venv/lib/python3.9/site-packages/keystone/api/projects.py", line 107, in _get_project
2023-02-17 07:11:06.456414 2023-02-17 07:11:06.453 39 ERROR keystone.server.flask.application     project = PROVIDERS.resource_api.get_project(project_id)
2023-02-17 07:11:06.456462 2023-02-17 07:11:06.453 39 ERROR keystone.server.flask.application   File "/var/lib/kolla/venv/lib/python3.9/site-packages/keystone/common/manager.py", line 115, in wrapped
2023-02-17 07:11:06.456474 2023-02-17 07:11:06.453 39 ERROR keystone.server.flask.application     __ret_val = __f(*args, **kwargs)
2023-02-17 07:11:06.456484 2023-02-17 07:11:06.453 39 ERROR keystone.server.flask.application   File "/var/lib/kolla/venv/lib/python3.9/site-packages/decorator.py", line 232, in fun
2023-02-17 07:11:06.456494 2023-02-17 07:11:06.453 39 ERROR keystone.server.flask.application     return caller(func, *(extras + args), **kw)
2023-02-17 07:11:06.456504 2023-02-17 07:11:06.453 39 ERROR keystone.server.flask.application   File "/var/lib/kolla/venv/lib/python3.9/site-packages/dogpile/cache/region.py", line 1577, in get_or_create_for_user_func
2023-02-17 07:11:06.456514 2023-02-17 07:11:06.453 39 ERROR keystone.server.flask.application     return self.get_or_create(
2023-02-17 07:11:06.456523 2023-02-17 07:11:06.453 39 ERROR keystone.server.flask.application   File "/var/lib/kolla/venv/lib/python3.9/site-packages/dogpile/cache/region.py", line 1042, in get_or_create
2023-02-17 07:11:06.456534 2023-02-17 07:11:06.453 39 ERROR keystone.server.flask.application     with Lock(
2023-02-17 07:11:06.456544 2023-02-17 07:11:06.453 39 ERROR keystone.server.flask.application   File "/var/lib/kolla/venv/lib/python3.9/site-packages/dogpile/lock.py", line 185, in __enter__
2023-02-17 07:11:06.456554 2023-02-17 07:11:06.453 39 ERROR keystone.server.flask.application     return self._enter()
2023-02-17 07:11:06.456563 2023-02-17 07:11:06.453 39 ERROR keystone.server.flask.application   File "/var/lib/kolla/venv/lib/python3.9/site-packages/dogpile/lock.py", line 94, in _enter
2023-02-17 07:11:06.456573 2023-02-17 07:11:06.453 39 ERROR keystone.server.flask.application     generated = self._enter_create(value, createdtime)
2023-02-17 07:11:06.456583 2023-02-17 07:11:06.453 39 ERROR keystone.server.flask.application   File "/var/lib/kolla/venv/lib/python3.9/site-packages/dogpile/lock.py", line 178, in _enter_create
2023-02-17 07:11:06.456593 2023-02-17 07:11:06.453 39 ERROR keystone.server.flask.application     return self.creator()
2023-02-17 07:11:06.456603 2023-02-17 07:11:06.453 39 ERROR keystone.server.flask.application   File "/var/lib/kolla/venv/lib/python3.9/site-packages/dogpile/cache/region.py", line 995, in gen_value
2023-02-17 07:11:06.456613 2023-02-17 07:11:06.453 39 ERROR keystone.server.flask.application     created_value = creator(
2023-02-17 07:11:06.456623 2023-02-17 07:11:06.453 39 ERROR keystone.server.flask.application   File "/var/lib/kolla/venv/lib/python3.9/site-packages/keystone/resource/core.py", line 903, in get_project
2023-02-17 07:11:06.456633 2023-02-17 07:11:06.453 39 ERROR keystone.server.flask.application     return self.driver.get_project(project_id)
2023-02-17 07:11:06.456642 2023-02-17 07:11:06.453 39 ERROR keystone.server.flask.application   File "/var/lib/kolla/venv/lib/python3.9/site-packages/keystone/resource/backends/sql.py", line 49, in get_project
2023-02-17 07:11:06.456652 2023-02-17 07:11:06.453 39 ERROR keystone.server.flask.application     return self._get_project(session, project_id).to_dict()
2023-02-17 07:11:06.456662 2023-02-17 07:11:06.453 39 ERROR keystone.server.flask.application   File "/var/lib/kolla/venv/lib/python3.9/site-packages/keystone/resource/backends/sql.py", line 44, in _get_project
2023-02-17 07:11:06.456672 2023-02-17 07:11:06.453 39 ERROR keystone.server.flask.application     raise exception.ProjectNotFound(project_id=project_id)
2023-02-17 07:11:06.456682 2023-02-17 07:11:06.453 39 ERROR keystone.server.flask.application keystone.exception.ProjectNotFound: Could not find project: service.
2023-02-17 07:11:06.456691 2023-02-17 07:11:06.453 39 ERROR keystone.server.flask.application \x1b[00m
2023-02-17 07:17:57.225052 2023-02-17 07:17:57.223 39 WARNING py.warnings [None req-0fdbb5d4-caf1-462a-be26-755c88b9f04c 6be3aded1b9c47bcbc94453e09ec12ff caf697e00cb04f798d0f55d38467c17b - - default default] /var/lib/kolla/venv/lib/python3.9/site-packages/oslo_policy/policy.py:1129: UserWarning: Policy "identity:list_domains": "role:reader and system_scope:all" failed scope check. The token used to make the request was project scoped but the policy requires ['system'] scope. This behavior may change in the future where using the intended scope is required
2023-02-17 07:17:57.225124   warnings.warn(msg)
2023-02-17 07:17:57.225137 \x1b[00m
2023-02-17 07:17:57.409756 2023-02-17 07:17:57.408 38 WARNING py.warnings [None req-bd6420eb-77c4-4847-957c-03e7973ac7ec 6be3aded1b9c47bcbc94453e09ec12ff caf697e00cb04f798d0f55d38467c17b - - default default] /var/lib/kolla/venv/lib/python3.9/site-packages/oslo_policy/policy.py:1129: UserWarning: Policy "identity:create_project": "(role:admin and system_scope:all) or (role:admin and domain_id:%(target.project.domain_id)s)" failed scope check. The token used to make the request was project scoped but the policy requires ['system', 'domain'] scope. This behavior may change in the future where using the intended scope is required
2023-02-17 07:17:57.409811   warnings.warn(msg)
2023-02-17 07:17:57.409822 \x1b[00m
2023-02-17 07:17:57.645219 2023-02-17 07:17:57.643 37 WARNING py.warnings [None req-ba38bba6-eaea-4936-8307-0f488769d3b5 6be3aded1b9c47bcbc94453e09ec12ff caf697e00cb04f798d0f55d38467c17b - - default default] /var/lib/kolla/venv/lib/python3.9/site-packages/oslo_policy/policy.py:1129: UserWarning: Policy "identity:create_user": "(role:admin and system_scope:all) or (role:admin and token.domain.id:%(target.user.domain_id)s)" failed scope check. The token used to make the request was project scoped but the policy requires ['system', 'domain'] scope. This behavior may change in the future where using the intended scope is required
2023-02-17 07:17:57.645269   warnings.warn(msg)
2023-02-17 07:17:57.645279 \x1b[00m
2023-02-17 07:17:58.439480 2023-02-17 07:17:58.438 39 WARNING py.warnings [None req-efa00f05-054a-4399-a647-dd4c05c4c9ee 6be3aded1b9c47bcbc94453e09ec12ff caf697e00cb04f798d0f55d38467c17b - - default default] /var/lib/kolla/venv/lib/python3.9/site-packages/oslo_policy/policy.py:1129: UserWarning: Policy "identity:list_roles": "role:reader and system_scope:all" failed scope check. The token used to make the request was project scoped but the policy requires ['system'] scope. This behavior may change in the future where using the intended scope is required
2023-02-17 07:17:58.439538   warnings.warn(msg)
2023-02-17 07:17:58.439548 \x1b[00m
2023-02-17 07:17:58.688364 2023-02-17 07:17:58.687 38 WARNING py.warnings [None req-44686298-3605-405c-9dd9-a726dfeac7aa 6be3aded1b9c47bcbc94453e09ec12ff caf697e00cb04f798d0f55d38467c17b - - default default] /var/lib/kolla/venv/lib/python3.9/site-packages/oslo_policy/policy.py:1129: UserWarning: Policy "identity:list_roles": "role:reader and system_scope:all" failed scope check. The token used to make the request was project scoped but the policy requires ['system'] scope. This behavior may change in the future where using the intended scope is required
2023-02-17 07:17:58.689941   warnings.warn(msg)
2023-02-17 07:17:58.689958 \x1b[00m
2023-02-17 07:17:58.932461 2023-02-17 07:17:58.931 37 WARNING py.warnings [None req-8a5096c0-ade3-42f2-86a5-86770a940b26 6be3aded1b9c47bcbc94453e09ec12ff caf697e00cb04f798d0f55d38467c17b - - default default] /var/lib/kolla/venv/lib/python3.9/site-packages/oslo_policy/policy.py:1129: UserWarning: Policy "identity:create_grant": "(role:admin and system_scope:all) or ((role:admin and domain_id:%(target.user.domain_id)s and domain_id:%(target.project.domain_id)s) or (role:admin and domain_id:%(target.user.domain_id)s and domain_id:%(target.domain.id)s) or (role:admin and domain_id:%(target.group.domain_id)s and domain_id:%(target.project.domain_id)s) or (role:admin and domain_id:%(target.group.domain_id)s and domain_id:%(target.domain.id)s)) and (domain_id:%(target.role.domain_id)s or None:%(target.role.domain_id)s)" failed scope check. The token used to make the request was project scoped but the policy requires ['system', 'domain'] scope. This behavior may change in the future where using the intended scope is required
2023-02-17 07:17:58.932532   warnings.warn(msg)
2023-02-17 07:17:58.932543 \x1b[00m
2023-02-17 07:18:01.506465 2023-02-17 07:18:01.505 38 WARNING py.warnings [None req-8f47d529-210d-4d2e-9523-8f5787b85d30 6be3aded1b9c47bcbc94453e09ec12ff caf697e00cb04f798d0f55d38467c17b - - default default] /var/lib/kolla/venv/lib/python3.9/site-packages/oslo_policy/policy.py:1129: UserWarning: Policy "identity:create_grant": "(role:admin and system_scope:all) or ((role:admin and domain_id:%(target.user.domain_id)s and domain_id:%(target.project.domain_id)s) or (role:admin and domain_id:%(target.user.domain_id)s and domain_id:%(target.domain.id)s) or (role:admin and domain_id:%(target.group.domain_id)s and domain_id:%(target.project.domain_id)s) or (role:admin and domain_id:%(target.group.domain_id)s and domain_id:%(target.domain.id)s)) and (domain_id:%(target.role.domain_id)s or None:%(target.role.domain_id)s)" failed scope check. The token used to make the request was project scoped but the policy requires ['system', 'domain'] scope. This behavior may change in the future where using the intended scope is required
2023-02-17 07:18:01.506514   warnings.warn(msg)
2023-02-17 07:18:01.506525 \x1b[00m
2023-02-17 07:18:01.714581 2023-02-17 07:18:01.712 37 WARNING py.warnings [None req-ea093210-529c-4686-97ed-62e7a94f2077 6be3aded1b9c47bcbc94453e09ec12ff caf697e00cb04f798d0f55d38467c17b - - default default] /var/lib/kolla/venv/lib/python3.9/site-packages/oslo_policy/policy.py:1129: UserWarning: Policy "identity:list_roles": "role:reader and system_scope:all" failed scope check. The token used to make the request was project scoped but the policy requires ['system'] scope. This behavior may change in the future where using the intended scope is required
2023-02-17 07:18:01.714633   warnings.warn(msg)
2023-02-17 07:18:01.714657 \x1b[00m
2023-02-17 07:18:01.988302 2023-02-17 07:18:01.987 39 WARNING py.warnings [None req-94db19b5-d418-4a78-8853-704e173fb523 6be3aded1b9c47bcbc94453e09ec12ff caf697e00cb04f798d0f55d38467c17b - - default default] /var/lib/kolla/venv/lib/python3.9/site-packages/oslo_policy/policy.py:1129: UserWarning: Policy "identity:create_grant": "(role:admin and system_scope:all) or ((role:admin and domain_id:%(target.user.domain_id)s and domain_id:%(target.project.domain_id)s) or (role:admin and domain_id:%(target.user.domain_id)s and domain_id:%(target.domain.id)s) or (role:admin and domain_id:%(target.group.domain_id)s and domain_id:%(target.project.domain_id)s) or (role:admin and domain_id:%(target.group.domain_id)s and domain_id:%(target.domain.id)s)) and (domain_id:%(target.role.domain_id)s or None:%(target.role.domain_id)s)" failed scope check. The token used to make the request was project scoped but the policy requires ['system', 'domain'] scope. This behavior may change in the future where using the intended scope is required
2023-02-17 07:18:01.988380   warnings.warn(msg)
2023-02-17 07:18:01.988391 \x1b[00m
2023-02-17 07:18:04.185258 2023-02-17 07:18:04.184 38 WARNING py.warnings [None req-8065b901-e3c1-4f6a-b6d3-4f5eebe5c601 6be3aded1b9c47bcbc94453e09ec12ff caf697e00cb04f798d0f55d38467c17b - - default default] /var/lib/kolla/venv/lib/python3.9/site-packages/oslo_policy/policy.py:1129: UserWarning: Policy "identity:create_system_grant_for_user": "role:admin and system_scope:all" failed scope check. The token used to make the request was project scoped but the policy requires ['system'] scope. This behavior may change in the future where using the intended scope is required
2023-02-17 07:18:04.185300   warnings.warn(msg)
2023-02-17 07:18:04.185311 \x1b[00m
