2023-02-23 17:16:12.573 24 INFO alembic.runtime.migration [-] Context impl MySQLImpl.
2023-02-23 17:16:12.576 24 INFO alembic.runtime.migration [-] Will assume non-transactional DDL.
2023-02-23 17:16:12.616 24 INFO alembic.runtime.migration [-] Context impl MySQLImpl.
2023-02-23 17:16:12.617 24 INFO alembic.runtime.migration [-] Will assume non-transactional DDL.
2023-02-23 17:16:12.666 24 INFO alembic.runtime.migration [-] Running upgrade  -> 27e647c0fad4, Initial version.
2023-02-23 17:16:14.107 24 INFO alembic.runtime.migration [-] Running upgrade 27e647c0fad4 -> e25ffa003242, Initial no-op Yoga contract migration.
2023-02-23 17:16:14.115 24 INFO alembic.runtime.migration [-] Running upgrade 27e647c0fad4 -> 29e87d24a316, Initial no-op Yoga expand migration.
2023-02-23 17:16:22.565 8 INFO keystone.common.fernet_utils [-] Created a new temporary key: /etc/keystone/fernet-keys/0.tmp
2023-02-23 17:16:22.570 8 INFO keystone.common.fernet_utils [-] Become a valid new key: /etc/keystone/fernet-keys/0
2023-02-23 17:16:22.571 8 INFO keystone.common.fernet_utils [-] Starting key rotation with 1 key files: ['/etc/keystone/fernet-keys/0']
2023-02-23 17:16:22.572 8 INFO keystone.common.fernet_utils [-] Created a new temporary key: /etc/keystone/fernet-keys/0.tmp
2023-02-23 17:16:22.573 8 INFO keystone.common.fernet_utils [-] Current primary key is: 0
2023-02-23 17:16:22.574 8 INFO keystone.common.fernet_utils [-] Next primary key will be: 1
2023-02-23 17:16:22.574 8 INFO keystone.common.fernet_utils [-] Promoted key 0 to be the primary: 1
2023-02-23 17:16:22.575 8 INFO keystone.common.fernet_utils [-] Become a valid new key: /etc/keystone/fernet-keys/0
2023-02-23 17:16:40.792 32 INFO keystone.cmd.bootstrap [None req-e150e620-3a25-4b8f-852f-69d5a87a45fd - - - - - -] Created domain default
2023-02-23 17:16:40.861 32 INFO keystone.cmd.bootstrap [None req-e150e620-3a25-4b8f-852f-69d5a87a45fd - - - - - -] Created project admin
2023-02-23 17:16:41.511 32 INFO keystone.cmd.bootstrap [None req-e150e620-3a25-4b8f-852f-69d5a87a45fd - - - - - -] Created user admin
2023-02-23 17:16:41.533 32 INFO keystone.cmd.bootstrap [None req-e150e620-3a25-4b8f-852f-69d5a87a45fd - - - - - -] Created role reader
2023-02-23 17:16:41.549 32 INFO keystone.cmd.bootstrap [None req-e150e620-3a25-4b8f-852f-69d5a87a45fd - - - - - -] Created role member
2023-02-23 17:16:41.584 32 INFO keystone.cmd.bootstrap [None req-e150e620-3a25-4b8f-852f-69d5a87a45fd - - - - - -] Created implied role where b55bd78f2c8f42f6b529f51604c65719 implies 55baee8babe1433683fdb7a46331d69d
2023-02-23 17:16:41.598 32 INFO keystone.cmd.bootstrap [None req-e150e620-3a25-4b8f-852f-69d5a87a45fd - - - - - -] Created role admin
2023-02-23 17:16:41.623 32 INFO keystone.cmd.bootstrap [None req-e150e620-3a25-4b8f-852f-69d5a87a45fd - - - - - -] Created implied role where 929522c27d034d1f94c19af961c3430b implies b55bd78f2c8f42f6b529f51604c65719
2023-02-23 17:16:41.641 32 INFO keystone.cmd.bootstrap [None req-e150e620-3a25-4b8f-852f-69d5a87a45fd - - - - - -] Granted role admin on project admin to user admin.
2023-02-23 17:16:41.650 32 INFO keystone.cmd.bootstrap [None req-e150e620-3a25-4b8f-852f-69d5a87a45fd - - - - - -] Granted role admin on the system to user admin.
2023-02-23 17:16:41.670 32 WARNING py.warnings [None req-e150e620-3a25-4b8f-852f-69d5a87a45fd - - - - - -] /var/lib/kolla/venv/lib/python3.9/site-packages/pycadf/identifier.py:71: UserWarning: Invalid uuid: RegionOne. To ensure interoperability, identifiers should be a valid uuid.
  warnings.warn(('Invalid uuid: %s. To ensure interoperability, '

2023-02-23 17:16:41.678 32 INFO keystone.cmd.bootstrap [None req-e150e620-3a25-4b8f-852f-69d5a87a45fd - - - - - -] Created region RegionOne
2023-02-23 17:16:41.733 32 INFO keystone.cmd.bootstrap [None req-e150e620-3a25-4b8f-852f-69d5a87a45fd - - - - - -] Created public endpoint http://169.16.1.175:5000
2023-02-23 17:16:41.746 32 INFO keystone.cmd.bootstrap [None req-e150e620-3a25-4b8f-852f-69d5a87a45fd - - - - - -] Created internal endpoint http://169.16.1.175:5000
2023-02-23 17:17:06.880 38 WARNING keystone.common.rbac_enforcer.enforcer [None req-74366871-3098-4962-9eaf-6d88f214bfe8 83eb42f521384d0a9ea56c6eabc41e20 - - all default -] Deprecated policy rules found. Use oslopolicy-policy-generator and oslopolicy-policy-upgrade to detect and resolve deprecated policies in your configuration.
2023-02-23 17:17:07.704 39 WARNING keystone.common.rbac_enforcer.enforcer [None req-e35f7069-c42d-45e6-b630-b101c222708a 83eb42f521384d0a9ea56c6eabc41e20 - - all default -] Deprecated policy rules found. Use oslopolicy-policy-generator and oslopolicy-policy-upgrade to detect and resolve deprecated policies in your configuration.
2023-02-23 17:17:15.052 37 WARNING keystone.common.rbac_enforcer.enforcer [None req-1f7f81ae-1cd9-4c4c-883f-f5df140aaa3d 83eb42f521384d0a9ea56c6eabc41e20 - - all default -] Deprecated policy rules found. Use oslopolicy-policy-generator and oslopolicy-policy-upgrade to detect and resolve deprecated policies in your configuration.
2023-02-23 17:18:38.300 38 ERROR keystone.server.flask.application [None req-35d51f6a-c799-450a-972f-73b98f119e31 83eb42f521384d0a9ea56c6eabc41e20 - - all default -] Could not find project: service.: keystone.exception.ProjectNotFound: Could not find project: service.
2023-02-23 17:18:38.300 38 ERROR keystone.server.flask.application Traceback (most recent call last):
2023-02-23 17:18:38.300 38 ERROR keystone.server.flask.application   File "/var/lib/kolla/venv/lib/python3.9/site-packages/flask/app.py", line 1820, in full_dispatch_request
2023-02-23 17:18:38.300 38 ERROR keystone.server.flask.application     rv = self.dispatch_request()
2023-02-23 17:18:38.300 38 ERROR keystone.server.flask.application   File "/var/lib/kolla/venv/lib/python3.9/site-packages/flask/app.py", line 1796, in dispatch_request
2023-02-23 17:18:38.300 38 ERROR keystone.server.flask.application     return self.ensure_sync(self.view_functions[rule.endpoint])(**view_args)
2023-02-23 17:18:38.300 38 ERROR keystone.server.flask.application   File "/var/lib/kolla/venv/lib/python3.9/site-packages/flask_restful/__init__.py", line 467, in wrapper
2023-02-23 17:18:38.300 38 ERROR keystone.server.flask.application     resp = resource(*args, **kwargs)
2023-02-23 17:18:38.300 38 ERROR keystone.server.flask.application   File "/var/lib/kolla/venv/lib/python3.9/site-packages/flask/views.py", line 107, in view
2023-02-23 17:18:38.300 38 ERROR keystone.server.flask.application     return current_app.ensure_sync(self.dispatch_request)(**kwargs)
2023-02-23 17:18:38.300 38 ERROR keystone.server.flask.application   File "/var/lib/kolla/venv/lib/python3.9/site-packages/flask_restful/__init__.py", line 582, in dispatch_request
2023-02-23 17:18:38.300 38 ERROR keystone.server.flask.application     resp = meth(*args, **kwargs)
2023-02-23 17:18:38.300 38 ERROR keystone.server.flask.application   File "/var/lib/kolla/venv/lib/python3.9/site-packages/keystone/api/projects.py", line 151, in get
2023-02-23 17:18:38.300 38 ERROR keystone.server.flask.application     return self._get_project(project_id)
2023-02-23 17:18:38.300 38 ERROR keystone.server.flask.application   File "/var/lib/kolla/venv/lib/python3.9/site-packages/keystone/api/projects.py", line 107, in _get_project
2023-02-23 17:18:38.300 38 ERROR keystone.server.flask.application     project = PROVIDERS.resource_api.get_project(project_id)
2023-02-23 17:18:38.300 38 ERROR keystone.server.flask.application   File "/var/lib/kolla/venv/lib/python3.9/site-packages/keystone/common/manager.py", line 115, in wrapped
2023-02-23 17:18:38.300 38 ERROR keystone.server.flask.application     __ret_val = __f(*args, **kwargs)
2023-02-23 17:18:38.300 38 ERROR keystone.server.flask.application   File "/var/lib/kolla/venv/lib/python3.9/site-packages/decorator.py", line 232, in fun
2023-02-23 17:18:38.300 38 ERROR keystone.server.flask.application     return caller(func, *(extras + args), **kw)
2023-02-23 17:18:38.300 38 ERROR keystone.server.flask.application   File "/var/lib/kolla/venv/lib/python3.9/site-packages/dogpile/cache/region.py", line 1577, in get_or_create_for_user_func
2023-02-23 17:18:38.300 38 ERROR keystone.server.flask.application     return self.get_or_create(
2023-02-23 17:18:38.300 38 ERROR keystone.server.flask.application   File "/var/lib/kolla/venv/lib/python3.9/site-packages/dogpile/cache/region.py", line 1042, in get_or_create
2023-02-23 17:18:38.300 38 ERROR keystone.server.flask.application     with Lock(
2023-02-23 17:18:38.300 38 ERROR keystone.server.flask.application   File "/var/lib/kolla/venv/lib/python3.9/site-packages/dogpile/lock.py", line 185, in __enter__
2023-02-23 17:18:38.300 38 ERROR keystone.server.flask.application     return self._enter()
2023-02-23 17:18:38.300 38 ERROR keystone.server.flask.application   File "/var/lib/kolla/venv/lib/python3.9/site-packages/dogpile/lock.py", line 94, in _enter
2023-02-23 17:18:38.300 38 ERROR keystone.server.flask.application     generated = self._enter_create(value, createdtime)
2023-02-23 17:18:38.300 38 ERROR keystone.server.flask.application   File "/var/lib/kolla/venv/lib/python3.9/site-packages/dogpile/lock.py", line 178, in _enter_create
2023-02-23 17:18:38.300 38 ERROR keystone.server.flask.application     return self.creator()
2023-02-23 17:18:38.300 38 ERROR keystone.server.flask.application   File "/var/lib/kolla/venv/lib/python3.9/site-packages/dogpile/cache/region.py", line 995, in gen_value
2023-02-23 17:18:38.300 38 ERROR keystone.server.flask.application     created_value = creator(
2023-02-23 17:18:38.300 38 ERROR keystone.server.flask.application   File "/var/lib/kolla/venv/lib/python3.9/site-packages/keystone/resource/core.py", line 903, in get_project
2023-02-23 17:18:38.300 38 ERROR keystone.server.flask.application     return self.driver.get_project(project_id)
2023-02-23 17:18:38.300 38 ERROR keystone.server.flask.application   File "/var/lib/kolla/venv/lib/python3.9/site-packages/keystone/resource/backends/sql.py", line 49, in get_project
2023-02-23 17:18:38.300 38 ERROR keystone.server.flask.application     return self._get_project(session, project_id).to_dict()
2023-02-23 17:18:38.300 38 ERROR keystone.server.flask.application   File "/var/lib/kolla/venv/lib/python3.9/site-packages/keystone/resource/backends/sql.py", line 44, in _get_project
2023-02-23 17:18:38.300 38 ERROR keystone.server.flask.application     raise exception.ProjectNotFound(project_id=project_id)
2023-02-23 17:18:38.300 38 ERROR keystone.server.flask.application keystone.exception.ProjectNotFound: Could not find project: service.
2023-02-23 17:18:38.300 38 ERROR keystone.server.flask.application 
2023-02-23 17:18:48.876 37 ERROR keystone.server.flask.application [None req-fe888898-baa2-48ec-bf30-bd0e06aab5ce 83eb42f521384d0a9ea56c6eabc41e20 - - all default -] Could not find project: service.: keystone.exception.ProjectNotFound: Could not find project: service.
2023-02-23 17:18:48.876 37 ERROR keystone.server.flask.application Traceback (most recent call last):
2023-02-23 17:18:48.876 37 ERROR keystone.server.flask.application   File "/var/lib/kolla/venv/lib/python3.9/site-packages/flask/app.py", line 1820, in full_dispatch_request
2023-02-23 17:18:48.876 37 ERROR keystone.server.flask.application     rv = self.dispatch_request()
2023-02-23 17:18:48.876 37 ERROR keystone.server.flask.application   File "/var/lib/kolla/venv/lib/python3.9/site-packages/flask/app.py", line 1796, in dispatch_request
2023-02-23 17:18:48.876 37 ERROR keystone.server.flask.application     return self.ensure_sync(self.view_functions[rule.endpoint])(**view_args)
2023-02-23 17:18:48.876 37 ERROR keystone.server.flask.application   File "/var/lib/kolla/venv/lib/python3.9/site-packages/flask_restful/__init__.py", line 467, in wrapper
2023-02-23 17:18:48.876 37 ERROR keystone.server.flask.application     resp = resource(*args, **kwargs)
2023-02-23 17:18:48.876 37 ERROR keystone.server.flask.application   File "/var/lib/kolla/venv/lib/python3.9/site-packages/flask/views.py", line 107, in view
2023-02-23 17:18:48.876 37 ERROR keystone.server.flask.application     return current_app.ensure_sync(self.dispatch_request)(**kwargs)
2023-02-23 17:18:48.876 37 ERROR keystone.server.flask.application   File "/var/lib/kolla/venv/lib/python3.9/site-packages/flask_restful/__init__.py", line 582, in dispatch_request
2023-02-23 17:18:48.876 37 ERROR keystone.server.flask.application     resp = meth(*args, **kwargs)
2023-02-23 17:18:48.876 37 ERROR keystone.server.flask.application   File "/var/lib/kolla/venv/lib/python3.9/site-packages/keystone/api/projects.py", line 151, in get
2023-02-23 17:18:48.876 37 ERROR keystone.server.flask.application     return self._get_project(project_id)
2023-02-23 17:18:48.876 37 ERROR keystone.server.flask.application   File "/var/lib/kolla/venv/lib/python3.9/site-packages/keystone/api/projects.py", line 107, in _get_project
2023-02-23 17:18:48.876 37 ERROR keystone.server.flask.application     project = PROVIDERS.resource_api.get_project(project_id)
2023-02-23 17:18:48.876 37 ERROR keystone.server.flask.application   File "/var/lib/kolla/venv/lib/python3.9/site-packages/keystone/common/manager.py", line 115, in wrapped
2023-02-23 17:18:48.876 37 ERROR keystone.server.flask.application     __ret_val = __f(*args, **kwargs)
2023-02-23 17:18:48.876 37 ERROR keystone.server.flask.application   File "/var/lib/kolla/venv/lib/python3.9/site-packages/decorator.py", line 232, in fun
2023-02-23 17:18:48.876 37 ERROR keystone.server.flask.application     return caller(func, *(extras + args), **kw)
2023-02-23 17:18:48.876 37 ERROR keystone.server.flask.application   File "/var/lib/kolla/venv/lib/python3.9/site-packages/dogpile/cache/region.py", line 1577, in get_or_create_for_user_func
2023-02-23 17:18:48.876 37 ERROR keystone.server.flask.application     return self.get_or_create(
2023-02-23 17:18:48.876 37 ERROR keystone.server.flask.application   File "/var/lib/kolla/venv/lib/python3.9/site-packages/dogpile/cache/region.py", line 1042, in get_or_create
2023-02-23 17:18:48.876 37 ERROR keystone.server.flask.application     with Lock(
2023-02-23 17:18:48.876 37 ERROR keystone.server.flask.application   File "/var/lib/kolla/venv/lib/python3.9/site-packages/dogpile/lock.py", line 185, in __enter__
2023-02-23 17:18:48.876 37 ERROR keystone.server.flask.application     return self._enter()
2023-02-23 17:18:48.876 37 ERROR keystone.server.flask.application   File "/var/lib/kolla/venv/lib/python3.9/site-packages/dogpile/lock.py", line 94, in _enter
2023-02-23 17:18:48.876 37 ERROR keystone.server.flask.application     generated = self._enter_create(value, createdtime)
2023-02-23 17:18:48.876 37 ERROR keystone.server.flask.application   File "/var/lib/kolla/venv/lib/python3.9/site-packages/dogpile/lock.py", line 178, in _enter_create
2023-02-23 17:18:48.876 37 ERROR keystone.server.flask.application     return self.creator()
2023-02-23 17:18:48.876 37 ERROR keystone.server.flask.application   File "/var/lib/kolla/venv/lib/python3.9/site-packages/dogpile/cache/region.py", line 995, in gen_value
2023-02-23 17:18:48.876 37 ERROR keystone.server.flask.application     created_value = creator(
2023-02-23 17:18:48.876 37 ERROR keystone.server.flask.application   File "/var/lib/kolla/venv/lib/python3.9/site-packages/keystone/resource/core.py", line 903, in get_project
2023-02-23 17:18:48.876 37 ERROR keystone.server.flask.application     return self.driver.get_project(project_id)
2023-02-23 17:18:48.876 37 ERROR keystone.server.flask.application   File "/var/lib/kolla/venv/lib/python3.9/site-packages/keystone/resource/backends/sql.py", line 49, in get_project
2023-02-23 17:18:48.876 37 ERROR keystone.server.flask.application     return self._get_project(session, project_id).to_dict()
2023-02-23 17:18:48.876 37 ERROR keystone.server.flask.application   File "/var/lib/kolla/venv/lib/python3.9/site-packages/keystone/resource/backends/sql.py", line 44, in _get_project
2023-02-23 17:18:48.876 37 ERROR keystone.server.flask.application     raise exception.ProjectNotFound(project_id=project_id)
2023-02-23 17:18:48.876 37 ERROR keystone.server.flask.application keystone.exception.ProjectNotFound: Could not find project: service.
2023-02-23 17:18:48.876 37 ERROR keystone.server.flask.application 
2023-02-23 17:19:06.849 37 ERROR keystone.server.flask.application [None req-5593a17d-794b-4f17-a23c-80a15f156931 83eb42f521384d0a9ea56c6eabc41e20 - - all default -] Could not find role: admin.: keystone.exception.RoleNotFound: Could not find role: admin.
2023-02-23 17:19:06.849 37 ERROR keystone.server.flask.application Traceback (most recent call last):
2023-02-23 17:19:06.849 37 ERROR keystone.server.flask.application   File "/var/lib/kolla/venv/lib/python3.9/site-packages/flask/app.py", line 1820, in full_dispatch_request
2023-02-23 17:19:06.849 37 ERROR keystone.server.flask.application     rv = self.dispatch_request()
2023-02-23 17:19:06.849 37 ERROR keystone.server.flask.application   File "/var/lib/kolla/venv/lib/python3.9/site-packages/flask/app.py", line 1796, in dispatch_request
2023-02-23 17:19:06.849 37 ERROR keystone.server.flask.application     return self.ensure_sync(self.view_functions[rule.endpoint])(**view_args)
2023-02-23 17:19:06.849 37 ERROR keystone.server.flask.application   File "/var/lib/kolla/venv/lib/python3.9/site-packages/flask_restful/__init__.py", line 467, in wrapper
2023-02-23 17:19:06.849 37 ERROR keystone.server.flask.application     resp = resource(*args, **kwargs)
2023-02-23 17:19:06.849 37 ERROR keystone.server.flask.application   File "/var/lib/kolla/venv/lib/python3.9/site-packages/flask/views.py", line 107, in view
2023-02-23 17:19:06.849 37 ERROR keystone.server.flask.application     return current_app.ensure_sync(self.dispatch_request)(**kwargs)
2023-02-23 17:19:06.849 37 ERROR keystone.server.flask.application   File "/var/lib/kolla/venv/lib/python3.9/site-packages/flask_restful/__init__.py", line 582, in dispatch_request
2023-02-23 17:19:06.849 37 ERROR keystone.server.flask.application     resp = meth(*args, **kwargs)
2023-02-23 17:19:06.849 37 ERROR keystone.server.flask.application   File "/var/lib/kolla/venv/lib/python3.9/site-packages/keystone/api/roles.py", line 50, in get
2023-02-23 17:19:06.849 37 ERROR keystone.server.flask.application     return self._get_role(role_id)
2023-02-23 17:19:06.849 37 ERROR keystone.server.flask.application   File "/var/lib/kolla/venv/lib/python3.9/site-packages/keystone/api/roles.py", line 70, in _get_role
2023-02-23 17:19:06.849 37 ERROR keystone.server.flask.application     ENFORCER.enforce_call(action='identity:get_role')
2023-02-23 17:19:06.849 37 ERROR keystone.server.flask.application   File "/var/lib/kolla/venv/lib/python3.9/site-packages/keystone/common/rbac_enforcer/enforcer.py", line 402, in enforce_call
2023-02-23 17:19:06.849 37 ERROR keystone.server.flask.application     policy_dict.update(cls._extract_member_target_data(
2023-02-23 17:19:06.849 37 ERROR keystone.server.flask.application   File "/var/lib/kolla/venv/lib/python3.9/site-packages/keystone/common/rbac_enforcer/enforcer.py", line 234, in _extract_member_target_data
2023-02-23 17:19:06.849 37 ERROR keystone.server.flask.application     member_name: func(flask.request.view_args[key])
2023-02-23 17:19:06.849 37 ERROR keystone.server.flask.application   File "/var/lib/kolla/venv/lib/python3.9/site-packages/keystone/common/manager.py", line 115, in wrapped
2023-02-23 17:19:06.849 37 ERROR keystone.server.flask.application     __ret_val = __f(*args, **kwargs)
2023-02-23 17:19:06.849 37 ERROR keystone.server.flask.application   File "/var/lib/kolla/venv/lib/python3.9/site-packages/decorator.py", line 232, in fun
2023-02-23 17:19:06.849 37 ERROR keystone.server.flask.application     return caller(func, *(extras + args), **kw)
2023-02-23 17:19:06.849 37 ERROR keystone.server.flask.application   File "/var/lib/kolla/venv/lib/python3.9/site-packages/dogpile/cache/region.py", line 1577, in get_or_create_for_user_func
2023-02-23 17:19:06.849 37 ERROR keystone.server.flask.application     return self.get_or_create(
2023-02-23 17:19:06.849 37 ERROR keystone.server.flask.application   File "/var/lib/kolla/venv/lib/python3.9/site-packages/dogpile/cache/region.py", line 1042, in get_or_create
2023-02-23 17:19:06.849 37 ERROR keystone.server.flask.application     with Lock(
2023-02-23 17:19:06.849 37 ERROR keystone.server.flask.application   File "/var/lib/kolla/venv/lib/python3.9/site-packages/dogpile/lock.py", line 185, in __enter__
2023-02-23 17:19:06.849 37 ERROR keystone.server.flask.application     return self._enter()
2023-02-23 17:19:06.849 37 ERROR keystone.server.flask.application   File "/var/lib/kolla/venv/lib/python3.9/site-packages/dogpile/lock.py", line 94, in _enter
2023-02-23 17:19:06.849 37 ERROR keystone.server.flask.application     generated = self._enter_create(value, createdtime)
2023-02-23 17:19:06.849 37 ERROR keystone.server.flask.application   File "/var/lib/kolla/venv/lib/python3.9/site-packages/dogpile/lock.py", line 178, in _enter_create
2023-02-23 17:19:06.849 37 ERROR keystone.server.flask.application     return self.creator()
2023-02-23 17:19:06.849 37 ERROR keystone.server.flask.application   File "/var/lib/kolla/venv/lib/python3.9/site-packages/dogpile/cache/region.py", line 995, in gen_value
2023-02-23 17:19:06.849 37 ERROR keystone.server.flask.application     created_value = creator(
2023-02-23 17:19:06.849 37 ERROR keystone.server.flask.application   File "/var/lib/kolla/venv/lib/python3.9/site-packages/keystone/assignment/core.py", line 1276, in get_role
2023-02-23 17:19:06.849 37 ERROR keystone.server.flask.application     return self.driver.get_role(role_id)
2023-02-23 17:19:06.849 37 ERROR keystone.server.flask.application   File "/var/lib/kolla/venv/lib/python3.9/site-packages/keystone/assignment/role_backends/sql.py", line 70, in get_role
2023-02-23 17:19:06.849 37 ERROR keystone.server.flask.application     return self._get_role(session, role_id).to_dict()
2023-02-23 17:19:06.849 37 ERROR keystone.server.flask.application   File "/var/lib/kolla/venv/lib/python3.9/site-packages/keystone/assignment/role_backends/sql.py", line 65, in _get_role
2023-02-23 17:19:06.849 37 ERROR keystone.server.flask.application     raise exception.RoleNotFound(role_id=role_id)
2023-02-23 17:19:06.849 37 ERROR keystone.server.flask.application keystone.exception.RoleNotFound: Could not find role: admin.
2023-02-23 17:19:06.849 37 ERROR keystone.server.flask.application 
2023-02-23 17:19:08.064 37 ERROR keystone.server.flask.application [None req-7f291044-1c1d-485b-8d31-68643f8df8bc 83eb42f521384d0a9ea56c6eabc41e20 - - all default -] Could not find user: ironic.: keystone.exception.UserNotFound: Could not find user: ironic.
2023-02-23 17:19:08.064 37 ERROR keystone.server.flask.application Traceback (most recent call last):
2023-02-23 17:19:08.064 37 ERROR keystone.server.flask.application   File "/var/lib/kolla/venv/lib/python3.9/site-packages/flask/app.py", line 1820, in full_dispatch_request
2023-02-23 17:19:08.064 37 ERROR keystone.server.flask.application     rv = self.dispatch_request()
2023-02-23 17:19:08.064 37 ERROR keystone.server.flask.application   File "/var/lib/kolla/venv/lib/python3.9/site-packages/flask/app.py", line 1796, in dispatch_request
2023-02-23 17:19:08.064 37 ERROR keystone.server.flask.application     return self.ensure_sync(self.view_functions[rule.endpoint])(**view_args)
2023-02-23 17:19:08.064 37 ERROR keystone.server.flask.application   File "/var/lib/kolla/venv/lib/python3.9/site-packages/flask_restful/__init__.py", line 467, in wrapper
2023-02-23 17:19:08.064 37 ERROR keystone.server.flask.application     resp = resource(*args, **kwargs)
2023-02-23 17:19:08.064 37 ERROR keystone.server.flask.application   File "/var/lib/kolla/venv/lib/python3.9/site-packages/flask/views.py", line 107, in view
2023-02-23 17:19:08.064 37 ERROR keystone.server.flask.application     return current_app.ensure_sync(self.dispatch_request)(**kwargs)
2023-02-23 17:19:08.064 37 ERROR keystone.server.flask.application   File "/var/lib/kolla/venv/lib/python3.9/site-packages/flask_restful/__init__.py", line 582, in dispatch_request
2023-02-23 17:19:08.064 37 ERROR keystone.server.flask.application     resp = meth(*args, **kwargs)
2023-02-23 17:19:08.064 37 ERROR keystone.server.flask.application   File "/var/lib/kolla/venv/lib/python3.9/site-packages/keystone/api/users.py", line 182, in get
2023-02-23 17:19:08.064 37 ERROR keystone.server.flask.application     return self._get_user(user_id)
2023-02-23 17:19:08.064 37 ERROR keystone.server.flask.application   File "/var/lib/kolla/venv/lib/python3.9/site-packages/keystone/api/users.py", line 194, in _get_user
2023-02-23 17:19:08.064 37 ERROR keystone.server.flask.application     ref = PROVIDERS.identity_api.get_user(user_id)
2023-02-23 17:19:08.064 37 ERROR keystone.server.flask.application   File "/var/lib/kolla/venv/lib/python3.9/site-packages/keystone/common/manager.py", line 115, in wrapped
2023-02-23 17:19:08.064 37 ERROR keystone.server.flask.application     __ret_val = __f(*args, **kwargs)
2023-02-23 17:19:08.064 37 ERROR keystone.server.flask.application   File "/var/lib/kolla/venv/lib/python3.9/site-packages/keystone/identity/core.py", line 414, in wrapper
2023-02-23 17:19:08.064 37 ERROR keystone.server.flask.application     return f(self, *args, **kwargs)
2023-02-23 17:19:08.064 37 ERROR keystone.server.flask.application   File "/var/lib/kolla/venv/lib/python3.9/site-packages/keystone/identity/core.py", line 424, in wrapper
2023-02-23 17:19:08.064 37 ERROR keystone.server.flask.application     return f(self, *args, **kwargs)
2023-02-23 17:19:08.064 37 ERROR keystone.server.flask.application   File "/var/lib/kolla/venv/lib/python3.9/site-packages/decorator.py", line 232, in fun
2023-02-23 17:19:08.064 37 ERROR keystone.server.flask.application     return caller(func, *(extras + args), **kw)
2023-02-23 17:19:08.064 37 ERROR keystone.server.flask.application   File "/var/lib/kolla/venv/lib/python3.9/site-packages/dogpile/cache/region.py", line 1577, in get_or_create_for_user_func
2023-02-23 17:19:08.064 37 ERROR keystone.server.flask.application     return self.get_or_create(
2023-02-23 17:19:08.064 37 ERROR keystone.server.flask.application   File "/var/lib/kolla/venv/lib/python3.9/site-packages/dogpile/cache/region.py", line 1042, in get_or_create
2023-02-23 17:19:08.064 37 ERROR keystone.server.flask.application     with Lock(
2023-02-23 17:19:08.064 37 ERROR keystone.server.flask.application   File "/var/lib/kolla/venv/lib/python3.9/site-packages/dogpile/lock.py", line 185, in __enter__
2023-02-23 17:19:08.064 37 ERROR keystone.server.flask.application     return self._enter()
2023-02-23 17:19:08.064 37 ERROR keystone.server.flask.application   File "/var/lib/kolla/venv/lib/python3.9/site-packages/dogpile/lock.py", line 94, in _enter
2023-02-23 17:19:08.064 37 ERROR keystone.server.flask.application     generated = self._enter_create(value, createdtime)
2023-02-23 17:19:08.064 37 ERROR keystone.server.flask.application   File "/var/lib/kolla/venv/lib/python3.9/site-packages/dogpile/lock.py", line 178, in _enter_create
2023-02-23 17:19:08.064 37 ERROR keystone.server.flask.application     return self.creator()
2023-02-23 17:19:08.064 37 ERROR keystone.server.flask.application   File "/var/lib/kolla/venv/lib/python3.9/site-packages/dogpile/cache/region.py", line 995, in gen_value
2023-02-23 17:19:08.064 37 ERROR keystone.server.flask.application     created_value = creator(
2023-02-23 17:19:08.064 37 ERROR keystone.server.flask.application   File "/var/lib/kolla/venv/lib/python3.9/site-packages/keystone/identity/core.py", line 1011, in get_user
2023-02-23 17:19:08.064 37 ERROR keystone.server.flask.application     ref = driver.get_user(entity_id)
2023-02-23 17:19:08.064 37 ERROR keystone.server.flask.application   File "/var/lib/kolla/venv/lib/python3.9/site-packages/keystone/identity/backends/sql.py", line 200, in get_user
2023-02-23 17:19:08.064 37 ERROR keystone.server.flask.application     self._get_user(session, user_id).to_dict())
2023-02-23 17:19:08.064 37 ERROR keystone.server.flask.application   File "/var/lib/kolla/venv/lib/python3.9/site-packages/keystone/identity/backends/sql.py", line 194, in _get_user
2023-02-23 17:19:08.064 37 ERROR keystone.server.flask.application     raise exception.UserNotFound(user_id=user_id)
2023-02-23 17:19:08.064 37 ERROR keystone.server.flask.application keystone.exception.UserNotFound: Could not find user: ironic.
2023-02-23 17:19:08.064 37 ERROR keystone.server.flask.application 
2023-02-23 17:19:09.388 39 ERROR keystone.server.flask.application [None req-cb64bfe3-5c83-423d-a4e3-97987faf42c7 83eb42f521384d0a9ea56c6eabc41e20 - - all default -] Could not find project: service.: keystone.exception.ProjectNotFound: Could not find project: service.
2023-02-23 17:19:09.388 39 ERROR keystone.server.flask.application Traceback (most recent call last):
2023-02-23 17:19:09.388 39 ERROR keystone.server.flask.application   File "/var/lib/kolla/venv/lib/python3.9/site-packages/flask/app.py", line 1820, in full_dispatch_request
2023-02-23 17:19:09.388 39 ERROR keystone.server.flask.application     rv = self.dispatch_request()
2023-02-23 17:19:09.388 39 ERROR keystone.server.flask.application   File "/var/lib/kolla/venv/lib/python3.9/site-packages/flask/app.py", line 1796, in dispatch_request
2023-02-23 17:19:09.388 39 ERROR keystone.server.flask.application     return self.ensure_sync(self.view_functions[rule.endpoint])(**view_args)
2023-02-23 17:19:09.388 39 ERROR keystone.server.flask.application   File "/var/lib/kolla/venv/lib/python3.9/site-packages/flask_restful/__init__.py", line 467, in wrapper
2023-02-23 17:19:09.388 39 ERROR keystone.server.flask.application     resp = resource(*args, **kwargs)
2023-02-23 17:19:09.388 39 ERROR keystone.server.flask.application   File "/var/lib/kolla/venv/lib/python3.9/site-packages/flask/views.py", line 107, in view
2023-02-23 17:19:09.388 39 ERROR keystone.server.flask.application     return current_app.ensure_sync(self.dispatch_request)(**kwargs)
2023-02-23 17:19:09.388 39 ERROR keystone.server.flask.application   File "/var/lib/kolla/venv/lib/python3.9/site-packages/flask_restful/__init__.py", line 582, in dispatch_request
2023-02-23 17:19:09.388 39 ERROR keystone.server.flask.application     resp = meth(*args, **kwargs)
2023-02-23 17:19:09.388 39 ERROR keystone.server.flask.application   File "/var/lib/kolla/venv/lib/python3.9/site-packages/keystone/api/projects.py", line 151, in get
2023-02-23 17:19:09.388 39 ERROR keystone.server.flask.application     return self._get_project(project_id)
2023-02-23 17:19:09.388 39 ERROR keystone.server.flask.application   File "/var/lib/kolla/venv/lib/python3.9/site-packages/keystone/api/projects.py", line 107, in _get_project
2023-02-23 17:19:09.388 39 ERROR keystone.server.flask.application     project = PROVIDERS.resource_api.get_project(project_id)
2023-02-23 17:19:09.388 39 ERROR keystone.server.flask.application   File "/var/lib/kolla/venv/lib/python3.9/site-packages/keystone/common/manager.py", line 115, in wrapped
2023-02-23 17:19:09.388 39 ERROR keystone.server.flask.application     __ret_val = __f(*args, **kwargs)
2023-02-23 17:19:09.388 39 ERROR keystone.server.flask.application   File "/var/lib/kolla/venv/lib/python3.9/site-packages/decorator.py", line 232, in fun
2023-02-23 17:19:09.388 39 ERROR keystone.server.flask.application     return caller(func, *(extras + args), **kw)
2023-02-23 17:19:09.388 39 ERROR keystone.server.flask.application   File "/var/lib/kolla/venv/lib/python3.9/site-packages/dogpile/cache/region.py", line 1577, in get_or_create_for_user_func
2023-02-23 17:19:09.388 39 ERROR keystone.server.flask.application     return self.get_or_create(
2023-02-23 17:19:09.388 39 ERROR keystone.server.flask.application   File "/var/lib/kolla/venv/lib/python3.9/site-packages/dogpile/cache/region.py", line 1042, in get_or_create
2023-02-23 17:19:09.388 39 ERROR keystone.server.flask.application     with Lock(
2023-02-23 17:19:09.388 39 ERROR keystone.server.flask.application   File "/var/lib/kolla/venv/lib/python3.9/site-packages/dogpile/lock.py", line 185, in __enter__
2023-02-23 17:19:09.388 39 ERROR keystone.server.flask.application     return self._enter()
2023-02-23 17:19:09.388 39 ERROR keystone.server.flask.application   File "/var/lib/kolla/venv/lib/python3.9/site-packages/dogpile/lock.py", line 94, in _enter
2023-02-23 17:19:09.388 39 ERROR keystone.server.flask.application     generated = self._enter_create(value, createdtime)
2023-02-23 17:19:09.388 39 ERROR keystone.server.flask.application   File "/var/lib/kolla/venv/lib/python3.9/site-packages/dogpile/lock.py", line 178, in _enter_create
2023-02-23 17:19:09.388 39 ERROR keystone.server.flask.application     return self.creator()
2023-02-23 17:19:09.388 39 ERROR keystone.server.flask.application   File "/var/lib/kolla/venv/lib/python3.9/site-packages/dogpile/cache/region.py", line 995, in gen_value
2023-02-23 17:19:09.388 39 ERROR keystone.server.flask.application     created_value = creator(
2023-02-23 17:19:09.388 39 ERROR keystone.server.flask.application   File "/var/lib/kolla/venv/lib/python3.9/site-packages/keystone/resource/core.py", line 903, in get_project
2023-02-23 17:19:09.388 39 ERROR keystone.server.flask.application     return self.driver.get_project(project_id)
2023-02-23 17:19:09.388 39 ERROR keystone.server.flask.application   File "/var/lib/kolla/venv/lib/python3.9/site-packages/keystone/resource/backends/sql.py", line 49, in get_project
2023-02-23 17:19:09.388 39 ERROR keystone.server.flask.application     return self._get_project(session, project_id).to_dict()
2023-02-23 17:19:09.388 39 ERROR keystone.server.flask.application   File "/var/lib/kolla/venv/lib/python3.9/site-packages/keystone/resource/backends/sql.py", line 44, in _get_project
2023-02-23 17:19:09.388 39 ERROR keystone.server.flask.application     raise exception.ProjectNotFound(project_id=project_id)
2023-02-23 17:19:09.388 39 ERROR keystone.server.flask.application keystone.exception.ProjectNotFound: Could not find project: service.
2023-02-23 17:19:09.388 39 ERROR keystone.server.flask.application 
2023-02-23 17:19:20.922 38 ERROR keystone.server.flask.application [None req-89a4e538-64cc-4f3d-ab11-76d21b0de1d4 83eb42f521384d0a9ea56c6eabc41e20 - - all default -] Could not find role: admin.: keystone.exception.RoleNotFound: Could not find role: admin.
2023-02-23 17:19:20.922 38 ERROR keystone.server.flask.application Traceback (most recent call last):
2023-02-23 17:19:20.922 38 ERROR keystone.server.flask.application   File "/var/lib/kolla/venv/lib/python3.9/site-packages/flask/app.py", line 1820, in full_dispatch_request
2023-02-23 17:19:20.922 38 ERROR keystone.server.flask.application     rv = self.dispatch_request()
2023-02-23 17:19:20.922 38 ERROR keystone.server.flask.application   File "/var/lib/kolla/venv/lib/python3.9/site-packages/flask/app.py", line 1796, in dispatch_request
2023-02-23 17:19:20.922 38 ERROR keystone.server.flask.application     return self.ensure_sync(self.view_functions[rule.endpoint])(**view_args)
2023-02-23 17:19:20.922 38 ERROR keystone.server.flask.application   File "/var/lib/kolla/venv/lib/python3.9/site-packages/flask_restful/__init__.py", line 467, in wrapper
2023-02-23 17:19:20.922 38 ERROR keystone.server.flask.application     resp = resource(*args, **kwargs)
2023-02-23 17:19:20.922 38 ERROR keystone.server.flask.application   File "/var/lib/kolla/venv/lib/python3.9/site-packages/flask/views.py", line 107, in view
2023-02-23 17:19:20.922 38 ERROR keystone.server.flask.application     return current_app.ensure_sync(self.dispatch_request)(**kwargs)
2023-02-23 17:19:20.922 38 ERROR keystone.server.flask.application   File "/var/lib/kolla/venv/lib/python3.9/site-packages/flask_restful/__init__.py", line 582, in dispatch_request
2023-02-23 17:19:20.922 38 ERROR keystone.server.flask.application     resp = meth(*args, **kwargs)
2023-02-23 17:19:20.922 38 ERROR keystone.server.flask.application   File "/var/lib/kolla/venv/lib/python3.9/site-packages/keystone/api/roles.py", line 50, in get
2023-02-23 17:19:20.922 38 ERROR keystone.server.flask.application     return self._get_role(role_id)
2023-02-23 17:19:20.922 38 ERROR keystone.server.flask.application   File "/var/lib/kolla/venv/lib/python3.9/site-packages/keystone/api/roles.py", line 70, in _get_role
2023-02-23 17:19:20.922 38 ERROR keystone.server.flask.application     ENFORCER.enforce_call(action='identity:get_role')
2023-02-23 17:19:20.922 38 ERROR keystone.server.flask.application   File "/var/lib/kolla/venv/lib/python3.9/site-packages/keystone/common/rbac_enforcer/enforcer.py", line 402, in enforce_call
2023-02-23 17:19:20.922 38 ERROR keystone.server.flask.application     policy_dict.update(cls._extract_member_target_data(
2023-02-23 17:19:20.922 38 ERROR keystone.server.flask.application   File "/var/lib/kolla/venv/lib/python3.9/site-packages/keystone/common/rbac_enforcer/enforcer.py", line 234, in _extract_member_target_data
2023-02-23 17:19:20.922 38 ERROR keystone.server.flask.application     member_name: func(flask.request.view_args[key])
2023-02-23 17:19:20.922 38 ERROR keystone.server.flask.application   File "/var/lib/kolla/venv/lib/python3.9/site-packages/keystone/common/manager.py", line 115, in wrapped
2023-02-23 17:19:20.922 38 ERROR keystone.server.flask.application     __ret_val = __f(*args, **kwargs)
2023-02-23 17:19:20.922 38 ERROR keystone.server.flask.application   File "/var/lib/kolla/venv/lib/python3.9/site-packages/decorator.py", line 232, in fun
2023-02-23 17:19:20.922 38 ERROR keystone.server.flask.application     return caller(func, *(extras + args), **kw)
2023-02-23 17:19:20.922 38 ERROR keystone.server.flask.application   File "/var/lib/kolla/venv/lib/python3.9/site-packages/dogpile/cache/region.py", line 1577, in get_or_create_for_user_func
2023-02-23 17:19:20.922 38 ERROR keystone.server.flask.application     return self.get_or_create(
2023-02-23 17:19:20.922 38 ERROR keystone.server.flask.application   File "/var/lib/kolla/venv/lib/python3.9/site-packages/dogpile/cache/region.py", line 1042, in get_or_create
2023-02-23 17:19:20.922 38 ERROR keystone.server.flask.application     with Lock(
2023-02-23 17:19:20.922 38 ERROR keystone.server.flask.application   File "/var/lib/kolla/venv/lib/python3.9/site-packages/dogpile/lock.py", line 185, in __enter__
2023-02-23 17:19:20.922 38 ERROR keystone.server.flask.application     return self._enter()
2023-02-23 17:19:20.922 38 ERROR keystone.server.flask.application   File "/var/lib/kolla/venv/lib/python3.9/site-packages/dogpile/lock.py", line 94, in _enter
2023-02-23 17:19:20.922 38 ERROR keystone.server.flask.application     generated = self._enter_create(value, createdtime)
2023-02-23 17:19:20.922 38 ERROR keystone.server.flask.application   File "/var/lib/kolla/venv/lib/python3.9/site-packages/dogpile/lock.py", line 178, in _enter_create
2023-02-23 17:19:20.922 38 ERROR keystone.server.flask.application     return self.creator()
2023-02-23 17:19:20.922 38 ERROR keystone.server.flask.application   File "/var/lib/kolla/venv/lib/python3.9/site-packages/dogpile/cache/region.py", line 995, in gen_value
2023-02-23 17:19:20.922 38 ERROR keystone.server.flask.application     created_value = creator(
2023-02-23 17:19:20.922 38 ERROR keystone.server.flask.application   File "/var/lib/kolla/venv/lib/python3.9/site-packages/keystone/assignment/core.py", line 1276, in get_role
2023-02-23 17:19:20.922 38 ERROR keystone.server.flask.application     return self.driver.get_role(role_id)
2023-02-23 17:19:20.922 38 ERROR keystone.server.flask.application   File "/var/lib/kolla/venv/lib/python3.9/site-packages/keystone/assignment/role_backends/sql.py", line 70, in get_role
2023-02-23 17:19:20.922 38 ERROR keystone.server.flask.application     return self._get_role(session, role_id).to_dict()
2023-02-23 17:19:20.922 38 ERROR keystone.server.flask.application   File "/var/lib/kolla/venv/lib/python3.9/site-packages/keystone/assignment/role_backends/sql.py", line 65, in _get_role
2023-02-23 17:19:20.922 38 ERROR keystone.server.flask.application     raise exception.RoleNotFound(role_id=role_id)
2023-02-23 17:19:20.922 38 ERROR keystone.server.flask.application keystone.exception.RoleNotFound: Could not find role: admin.
2023-02-23 17:19:20.922 38 ERROR keystone.server.flask.application 
2023-02-23 17:19:22.086 38 ERROR keystone.server.flask.application [None req-1653f878-94c5-47bf-80b7-6ba415139b5c 83eb42f521384d0a9ea56c6eabc41e20 - - all default -] Could not find user: ironic-inspector.: keystone.exception.UserNotFound: Could not find user: ironic-inspector.
2023-02-23 17:19:22.086 38 ERROR keystone.server.flask.application Traceback (most recent call last):
2023-02-23 17:19:22.086 38 ERROR keystone.server.flask.application   File "/var/lib/kolla/venv/lib/python3.9/site-packages/flask/app.py", line 1820, in full_dispatch_request
2023-02-23 17:19:22.086 38 ERROR keystone.server.flask.application     rv = self.dispatch_request()
2023-02-23 17:19:22.086 38 ERROR keystone.server.flask.application   File "/var/lib/kolla/venv/lib/python3.9/site-packages/flask/app.py", line 1796, in dispatch_request
2023-02-23 17:19:22.086 38 ERROR keystone.server.flask.application     return self.ensure_sync(self.view_functions[rule.endpoint])(**view_args)
2023-02-23 17:19:22.086 38 ERROR keystone.server.flask.application   File "/var/lib/kolla/venv/lib/python3.9/site-packages/flask_restful/__init__.py", line 467, in wrapper
2023-02-23 17:19:22.086 38 ERROR keystone.server.flask.application     resp = resource(*args, **kwargs)
2023-02-23 17:19:22.086 38 ERROR keystone.server.flask.application   File "/var/lib/kolla/venv/lib/python3.9/site-packages/flask/views.py", line 107, in view
2023-02-23 17:19:22.086 38 ERROR keystone.server.flask.application     return current_app.ensure_sync(self.dispatch_request)(**kwargs)
2023-02-23 17:19:22.086 38 ERROR keystone.server.flask.application   File "/var/lib/kolla/venv/lib/python3.9/site-packages/flask_restful/__init__.py", line 582, in dispatch_request
2023-02-23 17:19:22.086 38 ERROR keystone.server.flask.application     resp = meth(*args, **kwargs)
2023-02-23 17:19:22.086 38 ERROR keystone.server.flask.application   File "/var/lib/kolla/venv/lib/python3.9/site-packages/keystone/api/users.py", line 182, in get
2023-02-23 17:19:22.086 38 ERROR keystone.server.flask.application     return self._get_user(user_id)
2023-02-23 17:19:22.086 38 ERROR keystone.server.flask.application   File "/var/lib/kolla/venv/lib/python3.9/site-packages/keystone/api/users.py", line 194, in _get_user
2023-02-23 17:19:22.086 38 ERROR keystone.server.flask.application     ref = PROVIDERS.identity_api.get_user(user_id)
2023-02-23 17:19:22.086 38 ERROR keystone.server.flask.application   File "/var/lib/kolla/venv/lib/python3.9/site-packages/keystone/common/manager.py", line 115, in wrapped
2023-02-23 17:19:22.086 38 ERROR keystone.server.flask.application     __ret_val = __f(*args, **kwargs)
2023-02-23 17:19:22.086 38 ERROR keystone.server.flask.application   File "/var/lib/kolla/venv/lib/python3.9/site-packages/keystone/identity/core.py", line 414, in wrapper
2023-02-23 17:19:22.086 38 ERROR keystone.server.flask.application     return f(self, *args, **kwargs)
2023-02-23 17:19:22.086 38 ERROR keystone.server.flask.application   File "/var/lib/kolla/venv/lib/python3.9/site-packages/keystone/identity/core.py", line 424, in wrapper
2023-02-23 17:19:22.086 38 ERROR keystone.server.flask.application     return f(self, *args, **kwargs)
2023-02-23 17:19:22.086 38 ERROR keystone.server.flask.application   File "/var/lib/kolla/venv/lib/python3.9/site-packages/decorator.py", line 232, in fun
2023-02-23 17:19:22.086 38 ERROR keystone.server.flask.application     return caller(func, *(extras + args), **kw)
2023-02-23 17:19:22.086 38 ERROR keystone.server.flask.application   File "/var/lib/kolla/venv/lib/python3.9/site-packages/dogpile/cache/region.py", line 1577, in get_or_create_for_user_func
2023-02-23 17:19:22.086 38 ERROR keystone.server.flask.application     return self.get_or_create(
2023-02-23 17:19:22.086 38 ERROR keystone.server.flask.application   File "/var/lib/kolla/venv/lib/python3.9/site-packages/dogpile/cache/region.py", line 1042, in get_or_create
2023-02-23 17:19:22.086 38 ERROR keystone.server.flask.application     with Lock(
2023-02-23 17:19:22.086 38 ERROR keystone.server.flask.application   File "/var/lib/kolla/venv/lib/python3.9/site-packages/dogpile/lock.py", line 185, in __enter__
2023-02-23 17:19:22.086 38 ERROR keystone.server.flask.application     return self._enter()
2023-02-23 17:19:22.086 38 ERROR keystone.server.flask.application   File "/var/lib/kolla/venv/lib/python3.9/site-packages/dogpile/lock.py", line 94, in _enter
2023-02-23 17:19:22.086 38 ERROR keystone.server.flask.application     generated = self._enter_create(value, createdtime)
2023-02-23 17:19:22.086 38 ERROR keystone.server.flask.application   File "/var/lib/kolla/venv/lib/python3.9/site-packages/dogpile/lock.py", line 178, in _enter_create
2023-02-23 17:19:22.086 38 ERROR keystone.server.flask.application     return self.creator()
2023-02-23 17:19:22.086 38 ERROR keystone.server.flask.application   File "/var/lib/kolla/venv/lib/python3.9/site-packages/dogpile/cache/region.py", line 995, in gen_value
2023-02-23 17:19:22.086 38 ERROR keystone.server.flask.application     created_value = creator(
2023-02-23 17:19:22.086 38 ERROR keystone.server.flask.application   File "/var/lib/kolla/venv/lib/python3.9/site-packages/keystone/identity/core.py", line 1011, in get_user
2023-02-23 17:19:22.086 38 ERROR keystone.server.flask.application     ref = driver.get_user(entity_id)
2023-02-23 17:19:22.086 38 ERROR keystone.server.flask.application   File "/var/lib/kolla/venv/lib/python3.9/site-packages/keystone/identity/backends/sql.py", line 200, in get_user
2023-02-23 17:19:22.086 38 ERROR keystone.server.flask.application     self._get_user(session, user_id).to_dict())
2023-02-23 17:19:22.086 38 ERROR keystone.server.flask.application   File "/var/lib/kolla/venv/lib/python3.9/site-packages/keystone/identity/backends/sql.py", line 194, in _get_user
2023-02-23 17:19:22.086 38 ERROR keystone.server.flask.application     raise exception.UserNotFound(user_id=user_id)
2023-02-23 17:19:22.086 38 ERROR keystone.server.flask.application keystone.exception.UserNotFound: Could not find user: ironic-inspector.
2023-02-23 17:19:22.086 38 ERROR keystone.server.flask.application 
2023-02-23 17:19:23.052 37 ERROR keystone.server.flask.application [None req-895b871b-edb6-4bde-8b9d-705b1e6901c2 83eb42f521384d0a9ea56c6eabc41e20 - - all default -] Could not find project: service.: keystone.exception.ProjectNotFound: Could not find project: service.
2023-02-23 17:19:23.052 37 ERROR keystone.server.flask.application Traceback (most recent call last):
2023-02-23 17:19:23.052 37 ERROR keystone.server.flask.application   File "/var/lib/kolla/venv/lib/python3.9/site-packages/flask/app.py", line 1820, in full_dispatch_request
2023-02-23 17:19:23.052 37 ERROR keystone.server.flask.application     rv = self.dispatch_request()
2023-02-23 17:19:23.052 37 ERROR keystone.server.flask.application   File "/var/lib/kolla/venv/lib/python3.9/site-packages/flask/app.py", line 1796, in dispatch_request
2023-02-23 17:19:23.052 37 ERROR keystone.server.flask.application     return self.ensure_sync(self.view_functions[rule.endpoint])(**view_args)
2023-02-23 17:19:23.052 37 ERROR keystone.server.flask.application   File "/var/lib/kolla/venv/lib/python3.9/site-packages/flask_restful/__init__.py", line 467, in wrapper
2023-02-23 17:19:23.052 37 ERROR keystone.server.flask.application     resp = resource(*args, **kwargs)
2023-02-23 17:19:23.052 37 ERROR keystone.server.flask.application   File "/var/lib/kolla/venv/lib/python3.9/site-packages/flask/views.py", line 107, in view
2023-02-23 17:19:23.052 37 ERROR keystone.server.flask.application     return current_app.ensure_sync(self.dispatch_request)(**kwargs)
2023-02-23 17:19:23.052 37 ERROR keystone.server.flask.application   File "/var/lib/kolla/venv/lib/python3.9/site-packages/flask_restful/__init__.py", line 582, in dispatch_request
2023-02-23 17:19:23.052 37 ERROR keystone.server.flask.application     resp = meth(*args, **kwargs)
2023-02-23 17:19:23.052 37 ERROR keystone.server.flask.application   File "/var/lib/kolla/venv/lib/python3.9/site-packages/keystone/api/projects.py", line 151, in get
2023-02-23 17:19:23.052 37 ERROR keystone.server.flask.application     return self._get_project(project_id)
2023-02-23 17:19:23.052 37 ERROR keystone.server.flask.application   File "/var/lib/kolla/venv/lib/python3.9/site-packages/keystone/api/projects.py", line 107, in _get_project
2023-02-23 17:19:23.052 37 ERROR keystone.server.flask.application     project = PROVIDERS.resource_api.get_project(project_id)
2023-02-23 17:19:23.052 37 ERROR keystone.server.flask.application   File "/var/lib/kolla/venv/lib/python3.9/site-packages/keystone/common/manager.py", line 115, in wrapped
2023-02-23 17:19:23.052 37 ERROR keystone.server.flask.application     __ret_val = __f(*args, **kwargs)
2023-02-23 17:19:23.052 37 ERROR keystone.server.flask.application   File "/var/lib/kolla/venv/lib/python3.9/site-packages/decorator.py", line 232, in fun
2023-02-23 17:19:23.052 37 ERROR keystone.server.flask.application     return caller(func, *(extras + args), **kw)
2023-02-23 17:19:23.052 37 ERROR keystone.server.flask.application   File "/var/lib/kolla/venv/lib/python3.9/site-packages/dogpile/cache/region.py", line 1577, in get_or_create_for_user_func
2023-02-23 17:19:23.052 37 ERROR keystone.server.flask.application     return self.get_or_create(
2023-02-23 17:19:23.052 37 ERROR keystone.server.flask.application   File "/var/lib/kolla/venv/lib/python3.9/site-packages/dogpile/cache/region.py", line 1042, in get_or_create
2023-02-23 17:19:23.052 37 ERROR keystone.server.flask.application     with Lock(
2023-02-23 17:19:23.052 37 ERROR keystone.server.flask.application   File "/var/lib/kolla/venv/lib/python3.9/site-packages/dogpile/lock.py", line 185, in __enter__
2023-02-23 17:19:23.052 37 ERROR keystone.server.flask.application     return self._enter()
2023-02-23 17:19:23.052 37 ERROR keystone.server.flask.application   File "/var/lib/kolla/venv/lib/python3.9/site-packages/dogpile/lock.py", line 94, in _enter
2023-02-23 17:19:23.052 37 ERROR keystone.server.flask.application     generated = self._enter_create(value, createdtime)
2023-02-23 17:19:23.052 37 ERROR keystone.server.flask.application   File "/var/lib/kolla/venv/lib/python3.9/site-packages/dogpile/lock.py", line 178, in _enter_create
2023-02-23 17:19:23.052 37 ERROR keystone.server.flask.application     return self.creator()
2023-02-23 17:19:23.052 37 ERROR keystone.server.flask.application   File "/var/lib/kolla/venv/lib/python3.9/site-packages/dogpile/cache/region.py", line 995, in gen_value
2023-02-23 17:19:23.052 37 ERROR keystone.server.flask.application     created_value = creator(
2023-02-23 17:19:23.052 37 ERROR keystone.server.flask.application   File "/var/lib/kolla/venv/lib/python3.9/site-packages/keystone/resource/core.py", line 903, in get_project
2023-02-23 17:19:23.052 37 ERROR keystone.server.flask.application     return self.driver.get_project(project_id)
2023-02-23 17:19:23.052 37 ERROR keystone.server.flask.application   File "/var/lib/kolla/venv/lib/python3.9/site-packages/keystone/resource/backends/sql.py", line 49, in get_project
2023-02-23 17:19:23.052 37 ERROR keystone.server.flask.application     return self._get_project(session, project_id).to_dict()
2023-02-23 17:19:23.052 37 ERROR keystone.server.flask.application   File "/var/lib/kolla/venv/lib/python3.9/site-packages/keystone/resource/backends/sql.py", line 44, in _get_project
2023-02-23 17:19:23.052 37 ERROR keystone.server.flask.application     raise exception.ProjectNotFound(project_id=project_id)
2023-02-23 17:19:23.052 37 ERROR keystone.server.flask.application keystone.exception.ProjectNotFound: Could not find project: service.
2023-02-23 17:19:23.052 37 ERROR keystone.server.flask.application 
2023-02-23 17:22:16.934 37 ERROR keystone.server.flask.application [None req-ff3cb8e7-ce32-4538-aa03-5fab2808b3c6 83eb42f521384d0a9ea56c6eabc41e20 - - all default -] Could not find project: service.: keystone.exception.ProjectNotFound: Could not find project: service.
2023-02-23 17:22:16.934 37 ERROR keystone.server.flask.application Traceback (most recent call last):
2023-02-23 17:22:16.934 37 ERROR keystone.server.flask.application   File "/var/lib/kolla/venv/lib/python3.9/site-packages/flask/app.py", line 1820, in full_dispatch_request
2023-02-23 17:22:16.934 37 ERROR keystone.server.flask.application     rv = self.dispatch_request()
2023-02-23 17:22:16.934 37 ERROR keystone.server.flask.application   File "/var/lib/kolla/venv/lib/python3.9/site-packages/flask/app.py", line 1796, in dispatch_request
2023-02-23 17:22:16.934 37 ERROR keystone.server.flask.application     return self.ensure_sync(self.view_functions[rule.endpoint])(**view_args)
2023-02-23 17:22:16.934 37 ERROR keystone.server.flask.application   File "/var/lib/kolla/venv/lib/python3.9/site-packages/flask_restful/__init__.py", line 467, in wrapper
2023-02-23 17:22:16.934 37 ERROR keystone.server.flask.application     resp = resource(*args, **kwargs)
2023-02-23 17:22:16.934 37 ERROR keystone.server.flask.application   File "/var/lib/kolla/venv/lib/python3.9/site-packages/flask/views.py", line 107, in view
2023-02-23 17:22:16.934 37 ERROR keystone.server.flask.application     return current_app.ensure_sync(self.dispatch_request)(**kwargs)
2023-02-23 17:22:16.934 37 ERROR keystone.server.flask.application   File "/var/lib/kolla/venv/lib/python3.9/site-packages/flask_restful/__init__.py", line 582, in dispatch_request
2023-02-23 17:22:16.934 37 ERROR keystone.server.flask.application     resp = meth(*args, **kwargs)
2023-02-23 17:22:16.934 37 ERROR keystone.server.flask.application   File "/var/lib/kolla/venv/lib/python3.9/site-packages/keystone/api/projects.py", line 151, in get
2023-02-23 17:22:16.934 37 ERROR keystone.server.flask.application     return self._get_project(project_id)
2023-02-23 17:22:16.934 37 ERROR keystone.server.flask.application   File "/var/lib/kolla/venv/lib/python3.9/site-packages/keystone/api/projects.py", line 107, in _get_project
2023-02-23 17:22:16.934 37 ERROR keystone.server.flask.application     project = PROVIDERS.resource_api.get_project(project_id)
2023-02-23 17:22:16.934 37 ERROR keystone.server.flask.application   File "/var/lib/kolla/venv/lib/python3.9/site-packages/keystone/common/manager.py", line 115, in wrapped
2023-02-23 17:22:16.934 37 ERROR keystone.server.flask.application     __ret_val = __f(*args, **kwargs)
2023-02-23 17:22:16.934 37 ERROR keystone.server.flask.application   File "/var/lib/kolla/venv/lib/python3.9/site-packages/decorator.py", line 232, in fun
2023-02-23 17:22:16.934 37 ERROR keystone.server.flask.application     return caller(func, *(extras + args), **kw)
2023-02-23 17:22:16.934 37 ERROR keystone.server.flask.application   File "/var/lib/kolla/venv/lib/python3.9/site-packages/dogpile/cache/region.py", line 1577, in get_or_create_for_user_func
2023-02-23 17:22:16.934 37 ERROR keystone.server.flask.application     return self.get_or_create(
2023-02-23 17:22:16.934 37 ERROR keystone.server.flask.application   File "/var/lib/kolla/venv/lib/python3.9/site-packages/dogpile/cache/region.py", line 1042, in get_or_create
2023-02-23 17:22:16.934 37 ERROR keystone.server.flask.application     with Lock(
2023-02-23 17:22:16.934 37 ERROR keystone.server.flask.application   File "/var/lib/kolla/venv/lib/python3.9/site-packages/dogpile/lock.py", line 185, in __enter__
2023-02-23 17:22:16.934 37 ERROR keystone.server.flask.application     return self._enter()
2023-02-23 17:22:16.934 37 ERROR keystone.server.flask.application   File "/var/lib/kolla/venv/lib/python3.9/site-packages/dogpile/lock.py", line 94, in _enter
2023-02-23 17:22:16.934 37 ERROR keystone.server.flask.application     generated = self._enter_create(value, createdtime)
2023-02-23 17:22:16.934 37 ERROR keystone.server.flask.application   File "/var/lib/kolla/venv/lib/python3.9/site-packages/dogpile/lock.py", line 178, in _enter_create
2023-02-23 17:22:16.934 37 ERROR keystone.server.flask.application     return self.creator()
2023-02-23 17:22:16.934 37 ERROR keystone.server.flask.application   File "/var/lib/kolla/venv/lib/python3.9/site-packages/dogpile/cache/region.py", line 995, in gen_value
2023-02-23 17:22:16.934 37 ERROR keystone.server.flask.application     created_value = creator(
2023-02-23 17:22:16.934 37 ERROR keystone.server.flask.application   File "/var/lib/kolla/venv/lib/python3.9/site-packages/keystone/resource/core.py", line 903, in get_project
2023-02-23 17:22:16.934 37 ERROR keystone.server.flask.application     return self.driver.get_project(project_id)
2023-02-23 17:22:16.934 37 ERROR keystone.server.flask.application   File "/var/lib/kolla/venv/lib/python3.9/site-packages/keystone/resource/backends/sql.py", line 49, in get_project
2023-02-23 17:22:16.934 37 ERROR keystone.server.flask.application     return self._get_project(session, project_id).to_dict()
2023-02-23 17:22:16.934 37 ERROR keystone.server.flask.application   File "/var/lib/kolla/venv/lib/python3.9/site-packages/keystone/resource/backends/sql.py", line 44, in _get_project
2023-02-23 17:22:16.934 37 ERROR keystone.server.flask.application     raise exception.ProjectNotFound(project_id=project_id)
2023-02-23 17:22:16.934 37 ERROR keystone.server.flask.application keystone.exception.ProjectNotFound: Could not find project: service.
2023-02-23 17:22:16.934 37 ERROR keystone.server.flask.application 
2023-02-23 17:22:32.847 39 ERROR keystone.server.flask.application [None req-cd65b115-1836-428d-906c-341c9bac6beb 83eb42f521384d0a9ea56c6eabc41e20 - - all default -] Could not find role: admin.: keystone.exception.RoleNotFound: Could not find role: admin.
2023-02-23 17:22:32.847 39 ERROR keystone.server.flask.application Traceback (most recent call last):
2023-02-23 17:22:32.847 39 ERROR keystone.server.flask.application   File "/var/lib/kolla/venv/lib/python3.9/site-packages/flask/app.py", line 1820, in full_dispatch_request
2023-02-23 17:22:32.847 39 ERROR keystone.server.flask.application     rv = self.dispatch_request()
2023-02-23 17:22:32.847 39 ERROR keystone.server.flask.application   File "/var/lib/kolla/venv/lib/python3.9/site-packages/flask/app.py", line 1796, in dispatch_request
2023-02-23 17:22:32.847 39 ERROR keystone.server.flask.application     return self.ensure_sync(self.view_functions[rule.endpoint])(**view_args)
2023-02-23 17:22:32.847 39 ERROR keystone.server.flask.application   File "/var/lib/kolla/venv/lib/python3.9/site-packages/flask_restful/__init__.py", line 467, in wrapper
2023-02-23 17:22:32.847 39 ERROR keystone.server.flask.application     resp = resource(*args, **kwargs)
2023-02-23 17:22:32.847 39 ERROR keystone.server.flask.application   File "/var/lib/kolla/venv/lib/python3.9/site-packages/flask/views.py", line 107, in view
2023-02-23 17:22:32.847 39 ERROR keystone.server.flask.application     return current_app.ensure_sync(self.dispatch_request)(**kwargs)
2023-02-23 17:22:32.847 39 ERROR keystone.server.flask.application   File "/var/lib/kolla/venv/lib/python3.9/site-packages/flask_restful/__init__.py", line 582, in dispatch_request
2023-02-23 17:22:32.847 39 ERROR keystone.server.flask.application     resp = meth(*args, **kwargs)
2023-02-23 17:22:32.847 39 ERROR keystone.server.flask.application   File "/var/lib/kolla/venv/lib/python3.9/site-packages/keystone/api/roles.py", line 50, in get
2023-02-23 17:22:32.847 39 ERROR keystone.server.flask.application     return self._get_role(role_id)
2023-02-23 17:22:32.847 39 ERROR keystone.server.flask.application   File "/var/lib/kolla/venv/lib/python3.9/site-packages/keystone/api/roles.py", line 70, in _get_role
2023-02-23 17:22:32.847 39 ERROR keystone.server.flask.application     ENFORCER.enforce_call(action='identity:get_role')
2023-02-23 17:22:32.847 39 ERROR keystone.server.flask.application   File "/var/lib/kolla/venv/lib/python3.9/site-packages/keystone/common/rbac_enforcer/enforcer.py", line 402, in enforce_call
2023-02-23 17:22:32.847 39 ERROR keystone.server.flask.application     policy_dict.update(cls._extract_member_target_data(
2023-02-23 17:22:32.847 39 ERROR keystone.server.flask.application   File "/var/lib/kolla/venv/lib/python3.9/site-packages/keystone/common/rbac_enforcer/enforcer.py", line 234, in _extract_member_target_data
2023-02-23 17:22:32.847 39 ERROR keystone.server.flask.application     member_name: func(flask.request.view_args[key])
2023-02-23 17:22:32.847 39 ERROR keystone.server.flask.application   File "/var/lib/kolla/venv/lib/python3.9/site-packages/keystone/common/manager.py", line 115, in wrapped
2023-02-23 17:22:32.847 39 ERROR keystone.server.flask.application     __ret_val = __f(*args, **kwargs)
2023-02-23 17:22:32.847 39 ERROR keystone.server.flask.application   File "/var/lib/kolla/venv/lib/python3.9/site-packages/decorator.py", line 232, in fun
2023-02-23 17:22:32.847 39 ERROR keystone.server.flask.application     return caller(func, *(extras + args), **kw)
2023-02-23 17:22:32.847 39 ERROR keystone.server.flask.application   File "/var/lib/kolla/venv/lib/python3.9/site-packages/dogpile/cache/region.py", line 1577, in get_or_create_for_user_func
2023-02-23 17:22:32.847 39 ERROR keystone.server.flask.application     return self.get_or_create(
2023-02-23 17:22:32.847 39 ERROR keystone.server.flask.application   File "/var/lib/kolla/venv/lib/python3.9/site-packages/dogpile/cache/region.py", line 1042, in get_or_create
2023-02-23 17:22:32.847 39 ERROR keystone.server.flask.application     with Lock(
2023-02-23 17:22:32.847 39 ERROR keystone.server.flask.application   File "/var/lib/kolla/venv/lib/python3.9/site-packages/dogpile/lock.py", line 185, in __enter__
2023-02-23 17:22:32.847 39 ERROR keystone.server.flask.application     return self._enter()
2023-02-23 17:22:32.847 39 ERROR keystone.server.flask.application   File "/var/lib/kolla/venv/lib/python3.9/site-packages/dogpile/lock.py", line 94, in _enter
2023-02-23 17:22:32.847 39 ERROR keystone.server.flask.application     generated = self._enter_create(value, createdtime)
2023-02-23 17:22:32.847 39 ERROR keystone.server.flask.application   File "/var/lib/kolla/venv/lib/python3.9/site-packages/dogpile/lock.py", line 178, in _enter_create
2023-02-23 17:22:32.847 39 ERROR keystone.server.flask.application     return self.creator()
2023-02-23 17:22:32.847 39 ERROR keystone.server.flask.application   File "/var/lib/kolla/venv/lib/python3.9/site-packages/dogpile/cache/region.py", line 995, in gen_value
2023-02-23 17:22:32.847 39 ERROR keystone.server.flask.application     created_value = creator(
2023-02-23 17:22:32.847 39 ERROR keystone.server.flask.application   File "/var/lib/kolla/venv/lib/python3.9/site-packages/keystone/assignment/core.py", line 1276, in get_role
2023-02-23 17:22:32.847 39 ERROR keystone.server.flask.application     return self.driver.get_role(role_id)
2023-02-23 17:22:32.847 39 ERROR keystone.server.flask.application   File "/var/lib/kolla/venv/lib/python3.9/site-packages/keystone/assignment/role_backends/sql.py", line 70, in get_role
2023-02-23 17:22:32.847 39 ERROR keystone.server.flask.application     return self._get_role(session, role_id).to_dict()
2023-02-23 17:22:32.847 39 ERROR keystone.server.flask.application   File "/var/lib/kolla/venv/lib/python3.9/site-packages/keystone/assignment/role_backends/sql.py", line 65, in _get_role
2023-02-23 17:22:32.847 39 ERROR keystone.server.flask.application     raise exception.RoleNotFound(role_id=role_id)
2023-02-23 17:22:32.847 39 ERROR keystone.server.flask.application keystone.exception.RoleNotFound: Could not find role: admin.
2023-02-23 17:22:32.847 39 ERROR keystone.server.flask.application 
2023-02-23 17:22:34.060 39 ERROR keystone.server.flask.application [None req-30854ade-6adc-4917-8359-c131bb83f26f 83eb42f521384d0a9ea56c6eabc41e20 - - all default -] Could not find user: neutron.: keystone.exception.UserNotFound: Could not find user: neutron.
2023-02-23 17:22:34.060 39 ERROR keystone.server.flask.application Traceback (most recent call last):
2023-02-23 17:22:34.060 39 ERROR keystone.server.flask.application   File "/var/lib/kolla/venv/lib/python3.9/site-packages/flask/app.py", line 1820, in full_dispatch_request
2023-02-23 17:22:34.060 39 ERROR keystone.server.flask.application     rv = self.dispatch_request()
2023-02-23 17:22:34.060 39 ERROR keystone.server.flask.application   File "/var/lib/kolla/venv/lib/python3.9/site-packages/flask/app.py", line 1796, in dispatch_request
2023-02-23 17:22:34.060 39 ERROR keystone.server.flask.application     return self.ensure_sync(self.view_functions[rule.endpoint])(**view_args)
2023-02-23 17:22:34.060 39 ERROR keystone.server.flask.application   File "/var/lib/kolla/venv/lib/python3.9/site-packages/flask_restful/__init__.py", line 467, in wrapper
2023-02-23 17:22:34.060 39 ERROR keystone.server.flask.application     resp = resource(*args, **kwargs)
2023-02-23 17:22:34.060 39 ERROR keystone.server.flask.application   File "/var/lib/kolla/venv/lib/python3.9/site-packages/flask/views.py", line 107, in view
2023-02-23 17:22:34.060 39 ERROR keystone.server.flask.application     return current_app.ensure_sync(self.dispatch_request)(**kwargs)
2023-02-23 17:22:34.060 39 ERROR keystone.server.flask.application   File "/var/lib/kolla/venv/lib/python3.9/site-packages/flask_restful/__init__.py", line 582, in dispatch_request
2023-02-23 17:22:34.060 39 ERROR keystone.server.flask.application     resp = meth(*args, **kwargs)
2023-02-23 17:22:34.060 39 ERROR keystone.server.flask.application   File "/var/lib/kolla/venv/lib/python3.9/site-packages/keystone/api/users.py", line 182, in get
2023-02-23 17:22:34.060 39 ERROR keystone.server.flask.application     return self._get_user(user_id)
2023-02-23 17:22:34.060 39 ERROR keystone.server.flask.application   File "/var/lib/kolla/venv/lib/python3.9/site-packages/keystone/api/users.py", line 194, in _get_user
2023-02-23 17:22:34.060 39 ERROR keystone.server.flask.application     ref = PROVIDERS.identity_api.get_user(user_id)
2023-02-23 17:22:34.060 39 ERROR keystone.server.flask.application   File "/var/lib/kolla/venv/lib/python3.9/site-packages/keystone/common/manager.py", line 115, in wrapped
2023-02-23 17:22:34.060 39 ERROR keystone.server.flask.application     __ret_val = __f(*args, **kwargs)
2023-02-23 17:22:34.060 39 ERROR keystone.server.flask.application   File "/var/lib/kolla/venv/lib/python3.9/site-packages/keystone/identity/core.py", line 414, in wrapper
2023-02-23 17:22:34.060 39 ERROR keystone.server.flask.application     return f(self, *args, **kwargs)
2023-02-23 17:22:34.060 39 ERROR keystone.server.flask.application   File "/var/lib/kolla/venv/lib/python3.9/site-packages/keystone/identity/core.py", line 424, in wrapper
2023-02-23 17:22:34.060 39 ERROR keystone.server.flask.application     return f(self, *args, **kwargs)
2023-02-23 17:22:34.060 39 ERROR keystone.server.flask.application   File "/var/lib/kolla/venv/lib/python3.9/site-packages/decorator.py", line 232, in fun
2023-02-23 17:22:34.060 39 ERROR keystone.server.flask.application     return caller(func, *(extras + args), **kw)
2023-02-23 17:22:34.060 39 ERROR keystone.server.flask.application   File "/var/lib/kolla/venv/lib/python3.9/site-packages/dogpile/cache/region.py", line 1577, in get_or_create_for_user_func
2023-02-23 17:22:34.060 39 ERROR keystone.server.flask.application     return self.get_or_create(
2023-02-23 17:22:34.060 39 ERROR keystone.server.flask.application   File "/var/lib/kolla/venv/lib/python3.9/site-packages/dogpile/cache/region.py", line 1042, in get_or_create
2023-02-23 17:22:34.060 39 ERROR keystone.server.flask.application     with Lock(
2023-02-23 17:22:34.060 39 ERROR keystone.server.flask.application   File "/var/lib/kolla/venv/lib/python3.9/site-packages/dogpile/lock.py", line 185, in __enter__
2023-02-23 17:22:34.060 39 ERROR keystone.server.flask.application     return self._enter()
2023-02-23 17:22:34.060 39 ERROR keystone.server.flask.application   File "/var/lib/kolla/venv/lib/python3.9/site-packages/dogpile/lock.py", line 94, in _enter
2023-02-23 17:22:34.060 39 ERROR keystone.server.flask.application     generated = self._enter_create(value, createdtime)
2023-02-23 17:22:34.060 39 ERROR keystone.server.flask.application   File "/var/lib/kolla/venv/lib/python3.9/site-packages/dogpile/lock.py", line 178, in _enter_create
2023-02-23 17:22:34.060 39 ERROR keystone.server.flask.application     return self.creator()
2023-02-23 17:22:34.060 39 ERROR keystone.server.flask.application   File "/var/lib/kolla/venv/lib/python3.9/site-packages/dogpile/cache/region.py", line 995, in gen_value
2023-02-23 17:22:34.060 39 ERROR keystone.server.flask.application     created_value = creator(
2023-02-23 17:22:34.060 39 ERROR keystone.server.flask.application   File "/var/lib/kolla/venv/lib/python3.9/site-packages/keystone/identity/core.py", line 1011, in get_user
2023-02-23 17:22:34.060 39 ERROR keystone.server.flask.application     ref = driver.get_user(entity_id)
2023-02-23 17:22:34.060 39 ERROR keystone.server.flask.application   File "/var/lib/kolla/venv/lib/python3.9/site-packages/keystone/identity/backends/sql.py", line 200, in get_user
2023-02-23 17:22:34.060 39 ERROR keystone.server.flask.application     self._get_user(session, user_id).to_dict())
2023-02-23 17:22:34.060 39 ERROR keystone.server.flask.application   File "/var/lib/kolla/venv/lib/python3.9/site-packages/keystone/identity/backends/sql.py", line 194, in _get_user
2023-02-23 17:22:34.060 39 ERROR keystone.server.flask.application     raise exception.UserNotFound(user_id=user_id)
2023-02-23 17:22:34.060 39 ERROR keystone.server.flask.application keystone.exception.UserNotFound: Could not find user: neutron.
2023-02-23 17:22:34.060 39 ERROR keystone.server.flask.application 
2023-02-23 17:22:34.979 37 ERROR keystone.server.flask.application [None req-41ab88fd-7fbc-4d96-8358-a84c76a9b21e 83eb42f521384d0a9ea56c6eabc41e20 - - all default -] Could not find project: service.: keystone.exception.ProjectNotFound: Could not find project: service.
2023-02-23 17:22:34.979 37 ERROR keystone.server.flask.application Traceback (most recent call last):
2023-02-23 17:22:34.979 37 ERROR keystone.server.flask.application   File "/var/lib/kolla/venv/lib/python3.9/site-packages/flask/app.py", line 1820, in full_dispatch_request
2023-02-23 17:22:34.979 37 ERROR keystone.server.flask.application     rv = self.dispatch_request()
2023-02-23 17:22:34.979 37 ERROR keystone.server.flask.application   File "/var/lib/kolla/venv/lib/python3.9/site-packages/flask/app.py", line 1796, in dispatch_request
2023-02-23 17:22:34.979 37 ERROR keystone.server.flask.application     return self.ensure_sync(self.view_functions[rule.endpoint])(**view_args)
2023-02-23 17:22:34.979 37 ERROR keystone.server.flask.application   File "/var/lib/kolla/venv/lib/python3.9/site-packages/flask_restful/__init__.py", line 467, in wrapper
2023-02-23 17:22:34.979 37 ERROR keystone.server.flask.application     resp = resource(*args, **kwargs)
2023-02-23 17:22:34.979 37 ERROR keystone.server.flask.application   File "/var/lib/kolla/venv/lib/python3.9/site-packages/flask/views.py", line 107, in view
2023-02-23 17:22:34.979 37 ERROR keystone.server.flask.application     return current_app.ensure_sync(self.dispatch_request)(**kwargs)
2023-02-23 17:22:34.979 37 ERROR keystone.server.flask.application   File "/var/lib/kolla/venv/lib/python3.9/site-packages/flask_restful/__init__.py", line 582, in dispatch_request
2023-02-23 17:22:34.979 37 ERROR keystone.server.flask.application     resp = meth(*args, **kwargs)
2023-02-23 17:22:34.979 37 ERROR keystone.server.flask.application   File "/var/lib/kolla/venv/lib/python3.9/site-packages/keystone/api/projects.py", line 151, in get
2023-02-23 17:22:34.979 37 ERROR keystone.server.flask.application     return self._get_project(project_id)
2023-02-23 17:22:34.979 37 ERROR keystone.server.flask.application   File "/var/lib/kolla/venv/lib/python3.9/site-packages/keystone/api/projects.py", line 107, in _get_project
2023-02-23 17:22:34.979 37 ERROR keystone.server.flask.application     project = PROVIDERS.resource_api.get_project(project_id)
2023-02-23 17:22:34.979 37 ERROR keystone.server.flask.application   File "/var/lib/kolla/venv/lib/python3.9/site-packages/keystone/common/manager.py", line 115, in wrapped
2023-02-23 17:22:34.979 37 ERROR keystone.server.flask.application     __ret_val = __f(*args, **kwargs)
2023-02-23 17:22:34.979 37 ERROR keystone.server.flask.application   File "/var/lib/kolla/venv/lib/python3.9/site-packages/decorator.py", line 232, in fun
2023-02-23 17:22:34.979 37 ERROR keystone.server.flask.application     return caller(func, *(extras + args), **kw)
2023-02-23 17:22:34.979 37 ERROR keystone.server.flask.application   File "/var/lib/kolla/venv/lib/python3.9/site-packages/dogpile/cache/region.py", line 1577, in get_or_create_for_user_func
2023-02-23 17:22:34.979 37 ERROR keystone.server.flask.application     return self.get_or_create(
2023-02-23 17:22:34.979 37 ERROR keystone.server.flask.application   File "/var/lib/kolla/venv/lib/python3.9/site-packages/dogpile/cache/region.py", line 1042, in get_or_create
2023-02-23 17:22:34.979 37 ERROR keystone.server.flask.application     with Lock(
2023-02-23 17:22:34.979 37 ERROR keystone.server.flask.application   File "/var/lib/kolla/venv/lib/python3.9/site-packages/dogpile/lock.py", line 185, in __enter__
2023-02-23 17:22:34.979 37 ERROR keystone.server.flask.application     return self._enter()
2023-02-23 17:22:34.979 37 ERROR keystone.server.flask.application   File "/var/lib/kolla/venv/lib/python3.9/site-packages/dogpile/lock.py", line 94, in _enter
2023-02-23 17:22:34.979 37 ERROR keystone.server.flask.application     generated = self._enter_create(value, createdtime)
2023-02-23 17:22:34.979 37 ERROR keystone.server.flask.application   File "/var/lib/kolla/venv/lib/python3.9/site-packages/dogpile/lock.py", line 178, in _enter_create
2023-02-23 17:22:34.979 37 ERROR keystone.server.flask.application     return self.creator()
2023-02-23 17:22:34.979 37 ERROR keystone.server.flask.application   File "/var/lib/kolla/venv/lib/python3.9/site-packages/dogpile/cache/region.py", line 995, in gen_value
2023-02-23 17:22:34.979 37 ERROR keystone.server.flask.application     created_value = creator(
2023-02-23 17:22:34.979 37 ERROR keystone.server.flask.application   File "/var/lib/kolla/venv/lib/python3.9/site-packages/keystone/resource/core.py", line 903, in get_project
2023-02-23 17:22:34.979 37 ERROR keystone.server.flask.application     return self.driver.get_project(project_id)
2023-02-23 17:22:34.979 37 ERROR keystone.server.flask.application   File "/var/lib/kolla/venv/lib/python3.9/site-packages/keystone/resource/backends/sql.py", line 49, in get_project
2023-02-23 17:22:34.979 37 ERROR keystone.server.flask.application     return self._get_project(session, project_id).to_dict()
2023-02-23 17:22:34.979 37 ERROR keystone.server.flask.application   File "/var/lib/kolla/venv/lib/python3.9/site-packages/keystone/resource/backends/sql.py", line 44, in _get_project
2023-02-23 17:22:34.979 37 ERROR keystone.server.flask.application     raise exception.ProjectNotFound(project_id=project_id)
2023-02-23 17:22:34.979 37 ERROR keystone.server.flask.application keystone.exception.ProjectNotFound: Could not find project: service.
2023-02-23 17:22:34.979 37 ERROR keystone.server.flask.application 
2023-02-23 20:14:16.978 37 WARNING py.warnings [None req-c49250aa-affa-42d1-ba26-c20ac01d3161 83eb42f521384d0a9ea56c6eabc41e20 e4cd64e877bc420b831193ae8deb97a3 - - default default] /var/lib/kolla/venv/lib/python3.9/site-packages/oslo_policy/policy.py:1129: UserWarning: Policy "identity:list_domains": "role:reader and system_scope:all" failed scope check. The token used to make the request was project scoped but the policy requires ['system'] scope. This behavior may change in the future where using the intended scope is required
  warnings.warn(msg)

2023-02-23 20:14:17.309 38 WARNING py.warnings [None req-15aae8a8-d5f4-4904-a4d2-a653cb16a556 83eb42f521384d0a9ea56c6eabc41e20 e4cd64e877bc420b831193ae8deb97a3 - - default default] /var/lib/kolla/venv/lib/python3.9/site-packages/oslo_policy/policy.py:1129: UserWarning: Policy "identity:create_project": "(role:admin and system_scope:all) or (role:admin and domain_id:%(target.project.domain_id)s)" failed scope check. The token used to make the request was project scoped but the policy requires ['system', 'domain'] scope. This behavior may change in the future where using the intended scope is required
  warnings.warn(msg)

2023-02-23 20:14:17.651 39 WARNING py.warnings [None req-7c51ef21-f249-49c5-990d-0e00536f2708 83eb42f521384d0a9ea56c6eabc41e20 e4cd64e877bc420b831193ae8deb97a3 - - default default] /var/lib/kolla/venv/lib/python3.9/site-packages/oslo_policy/policy.py:1129: UserWarning: Policy "identity:create_user": "(role:admin and system_scope:all) or (role:admin and token.domain.id:%(target.user.domain_id)s)" failed scope check. The token used to make the request was project scoped but the policy requires ['system', 'domain'] scope. This behavior may change in the future where using the intended scope is required
  warnings.warn(msg)

2023-02-23 20:14:18.478 37 WARNING py.warnings [None req-de7b6beb-3d07-49bc-b15b-055fd0a9b1cb 83eb42f521384d0a9ea56c6eabc41e20 e4cd64e877bc420b831193ae8deb97a3 - - default default] /var/lib/kolla/venv/lib/python3.9/site-packages/oslo_policy/policy.py:1129: UserWarning: Policy "identity:list_roles": "role:reader and system_scope:all" failed scope check. The token used to make the request was project scoped but the policy requires ['system'] scope. This behavior may change in the future where using the intended scope is required
  warnings.warn(msg)

2023-02-23 20:14:18.888 38 WARNING py.warnings [None req-6c485b9c-6658-4bb1-845e-f5aab7e7fc7b 83eb42f521384d0a9ea56c6eabc41e20 e4cd64e877bc420b831193ae8deb97a3 - - default default] /var/lib/kolla/venv/lib/python3.9/site-packages/oslo_policy/policy.py:1129: UserWarning: Policy "identity:list_roles": "role:reader and system_scope:all" failed scope check. The token used to make the request was project scoped but the policy requires ['system'] scope. This behavior may change in the future where using the intended scope is required
  warnings.warn(msg)

2023-02-23 20:14:19.240 39 WARNING py.warnings [None req-47d08cbb-2472-4e4a-b2f0-94133953f58b 83eb42f521384d0a9ea56c6eabc41e20 e4cd64e877bc420b831193ae8deb97a3 - - default default] /var/lib/kolla/venv/lib/python3.9/site-packages/oslo_policy/policy.py:1129: UserWarning: Policy "identity:create_grant": "(role:admin and system_scope:all) or ((role:admin and domain_id:%(target.user.domain_id)s and domain_id:%(target.project.domain_id)s) or (role:admin and domain_id:%(target.user.domain_id)s and domain_id:%(target.domain.id)s) or (role:admin and domain_id:%(target.group.domain_id)s and domain_id:%(target.project.domain_id)s) or (role:admin and domain_id:%(target.group.domain_id)s and domain_id:%(target.domain.id)s)) and (domain_id:%(target.role.domain_id)s or None:%(target.role.domain_id)s)" failed scope check. The token used to make the request was project scoped but the policy requires ['system', 'domain'] scope. This behavior may change in the future where using the intended scope is required
  warnings.warn(msg)

2023-02-23 20:14:22.212 38 WARNING py.warnings [None req-8b28e55c-9037-4f40-9209-c9c06470f138 83eb42f521384d0a9ea56c6eabc41e20 e4cd64e877bc420b831193ae8deb97a3 - - default default] /var/lib/kolla/venv/lib/python3.9/site-packages/oslo_policy/policy.py:1129: UserWarning: Policy "identity:create_grant": "(role:admin and system_scope:all) or ((role:admin and domain_id:%(target.user.domain_id)s and domain_id:%(target.project.domain_id)s) or (role:admin and domain_id:%(target.user.domain_id)s and domain_id:%(target.domain.id)s) or (role:admin and domain_id:%(target.group.domain_id)s and domain_id:%(target.project.domain_id)s) or (role:admin and domain_id:%(target.group.domain_id)s and domain_id:%(target.domain.id)s)) and (domain_id:%(target.role.domain_id)s or None:%(target.role.domain_id)s)" failed scope check. The token used to make the request was project scoped but the policy requires ['system', 'domain'] scope. This behavior may change in the future where using the intended scope is required
  warnings.warn(msg)

2023-02-23 20:14:24.119 38 WARNING py.warnings [None req-0947e653-c799-4919-8cde-5dc8ea1edffc 83eb42f521384d0a9ea56c6eabc41e20 e4cd64e877bc420b831193ae8deb97a3 - - default default] /var/lib/kolla/venv/lib/python3.9/site-packages/oslo_policy/policy.py:1129: UserWarning: Policy "identity:create_user": "(role:admin and system_scope:all) or (role:admin and token.domain.id:%(target.user.domain_id)s)" failed scope check. The token used to make the request was project scoped but the policy requires ['system', 'domain'] scope. This behavior may change in the future where using the intended scope is required
  warnings.warn(msg)

2023-02-23 20:14:25.309 39 WARNING py.warnings [None req-24ae7505-312d-44a8-8452-9ea4a92cb22e 83eb42f521384d0a9ea56c6eabc41e20 e4cd64e877bc420b831193ae8deb97a3 - - default default] /var/lib/kolla/venv/lib/python3.9/site-packages/oslo_policy/policy.py:1129: UserWarning: Policy "identity:list_roles": "role:reader and system_scope:all" failed scope check. The token used to make the request was project scoped but the policy requires ['system'] scope. This behavior may change in the future where using the intended scope is required
  warnings.warn(msg)

2023-02-23 20:14:25.912 37 WARNING py.warnings [None req-960ca0d4-1475-4dae-b864-716c33df77a5 83eb42f521384d0a9ea56c6eabc41e20 e4cd64e877bc420b831193ae8deb97a3 - - default default] /var/lib/kolla/venv/lib/python3.9/site-packages/oslo_policy/policy.py:1129: UserWarning: Policy "identity:create_system_grant_for_user": "role:admin and system_scope:all" failed scope check. The token used to make the request was project scoped but the policy requires ['system'] scope. This behavior may change in the future where using the intended scope is required
  warnings.warn(msg)

