2023-03-07 22:18:57.529962 2023-03-07 22:18:57.526 34 WARNING keystone.common.rbac_enforcer.enforcer [None req-224d705a-0a07-43af-b86a-b0d1ec0ed1e7 557c326d318a409bbd94bffd97735c7e - - all default -] Deprecated policy rules found. Use oslopolicy-policy-generator and oslopolicy-policy-upgrade to detect and resolve deprecated policies in your configuration.\x1b[00m
2023-03-07 22:18:58.405183 2023-03-07 22:18:58.403 32 WARNING keystone.common.rbac_enforcer.enforcer [None req-a6ae7859-4973-48bf-a428-b6cdfc47aee4 557c326d318a409bbd94bffd97735c7e - - all default -] Deprecated policy rules found. Use oslopolicy-policy-generator and oslopolicy-policy-upgrade to detect and resolve deprecated policies in your configuration.\x1b[00m
2023-03-07 22:19:06.335516 2023-03-07 22:19:06.333 33 WARNING keystone.common.rbac_enforcer.enforcer [None req-e30bbd0a-0ea4-4978-94b2-9bdf2859154b 557c326d318a409bbd94bffd97735c7e - - all default -] Deprecated policy rules found. Use oslopolicy-policy-generator and oslopolicy-policy-upgrade to detect and resolve deprecated policies in your configuration.\x1b[00m
2023-03-07 22:20:28.403308 2023-03-07 22:20:28.387 34 ERROR keystone.server.flask.application [None req-7d0f415c-4c9c-4f3f-b088-5a08ba7f5d81 557c326d318a409bbd94bffd97735c7e - - all default -] Could not find project: service.: keystone.exception.ProjectNotFound: Could not find project: service.
2023-03-07 22:20:28.403406 2023-03-07 22:20:28.387 34 ERROR keystone.server.flask.application Traceback (most recent call last):
2023-03-07 22:20:28.403422 2023-03-07 22:20:28.387 34 ERROR keystone.server.flask.application   File "/var/lib/kolla/venv/lib/python3.9/site-packages/flask/app.py", line 1820, in full_dispatch_request
2023-03-07 22:20:28.403433 2023-03-07 22:20:28.387 34 ERROR keystone.server.flask.application     rv = self.dispatch_request()
2023-03-07 22:20:28.403443 2023-03-07 22:20:28.387 34 ERROR keystone.server.flask.application   File "/var/lib/kolla/venv/lib/python3.9/site-packages/flask/app.py", line 1796, in dispatch_request
2023-03-07 22:20:28.403454 2023-03-07 22:20:28.387 34 ERROR keystone.server.flask.application     return self.ensure_sync(self.view_functions[rule.endpoint])(**view_args)
2023-03-07 22:20:28.403464 2023-03-07 22:20:28.387 34 ERROR keystone.server.flask.application   File "/var/lib/kolla/venv/lib/python3.9/site-packages/flask_restful/__init__.py", line 467, in wrapper
2023-03-07 22:20:28.403473 2023-03-07 22:20:28.387 34 ERROR keystone.server.flask.application     resp = resource(*args, **kwargs)
2023-03-07 22:20:28.403484 2023-03-07 22:20:28.387 34 ERROR keystone.server.flask.application   File "/var/lib/kolla/venv/lib/python3.9/site-packages/flask/views.py", line 107, in view
2023-03-07 22:20:28.403495 2023-03-07 22:20:28.387 34 ERROR keystone.server.flask.application     return current_app.ensure_sync(self.dispatch_request)(**kwargs)
2023-03-07 22:20:28.403504 2023-03-07 22:20:28.387 34 ERROR keystone.server.flask.application   File "/var/lib/kolla/venv/lib/python3.9/site-packages/flask_restful/__init__.py", line 582, in dispatch_request
2023-03-07 22:20:28.403514 2023-03-07 22:20:28.387 34 ERROR keystone.server.flask.application     resp = meth(*args, **kwargs)
2023-03-07 22:20:28.403524 2023-03-07 22:20:28.387 34 ERROR keystone.server.flask.application   File "/var/lib/kolla/venv/lib/python3.9/site-packages/keystone/api/projects.py", line 151, in get
2023-03-07 22:20:28.403576 2023-03-07 22:20:28.387 34 ERROR keystone.server.flask.application     return self._get_project(project_id)
2023-03-07 22:20:28.403588 2023-03-07 22:20:28.387 34 ERROR keystone.server.flask.application   File "/var/lib/kolla/venv/lib/python3.9/site-packages/keystone/api/projects.py", line 107, in _get_project
2023-03-07 22:20:28.403598 2023-03-07 22:20:28.387 34 ERROR keystone.server.flask.application     project = PROVIDERS.resource_api.get_project(project_id)
2023-03-07 22:20:28.403608 2023-03-07 22:20:28.387 34 ERROR keystone.server.flask.application   File "/var/lib/kolla/venv/lib/python3.9/site-packages/keystone/common/manager.py", line 115, in wrapped
2023-03-07 22:20:28.403649 2023-03-07 22:20:28.387 34 ERROR keystone.server.flask.application     __ret_val = __f(*args, **kwargs)
2023-03-07 22:20:28.403662 2023-03-07 22:20:28.387 34 ERROR keystone.server.flask.application   File "/var/lib/kolla/venv/lib/python3.9/site-packages/decorator.py", line 232, in fun
2023-03-07 22:20:28.403672 2023-03-07 22:20:28.387 34 ERROR keystone.server.flask.application     return caller(func, *(extras + args), **kw)
2023-03-07 22:20:28.403682 2023-03-07 22:20:28.387 34 ERROR keystone.server.flask.application   File "/var/lib/kolla/venv/lib/python3.9/site-packages/dogpile/cache/region.py", line 1577, in get_or_create_for_user_func
2023-03-07 22:20:28.403692 2023-03-07 22:20:28.387 34 ERROR keystone.server.flask.application     return self.get_or_create(
2023-03-07 22:20:28.403702 2023-03-07 22:20:28.387 34 ERROR keystone.server.flask.application   File "/var/lib/kolla/venv/lib/python3.9/site-packages/dogpile/cache/region.py", line 1042, in get_or_create
2023-03-07 22:20:28.403713 2023-03-07 22:20:28.387 34 ERROR keystone.server.flask.application     with Lock(
2023-03-07 22:20:28.403722 2023-03-07 22:20:28.387 34 ERROR keystone.server.flask.application   File "/var/lib/kolla/venv/lib/python3.9/site-packages/dogpile/lock.py", line 185, in __enter__
2023-03-07 22:20:28.403732 2023-03-07 22:20:28.387 34 ERROR keystone.server.flask.application     return self._enter()
2023-03-07 22:20:28.403741 2023-03-07 22:20:28.387 34 ERROR keystone.server.flask.application   File "/var/lib/kolla/venv/lib/python3.9/site-packages/dogpile/lock.py", line 94, in _enter
2023-03-07 22:20:28.403751 2023-03-07 22:20:28.387 34 ERROR keystone.server.flask.application     generated = self._enter_create(value, createdtime)
2023-03-07 22:20:28.403761 2023-03-07 22:20:28.387 34 ERROR keystone.server.flask.application   File "/var/lib/kolla/venv/lib/python3.9/site-packages/dogpile/lock.py", line 178, in _enter_create
2023-03-07 22:20:28.403771 2023-03-07 22:20:28.387 34 ERROR keystone.server.flask.application     return self.creator()
2023-03-07 22:20:28.403781 2023-03-07 22:20:28.387 34 ERROR keystone.server.flask.application   File "/var/lib/kolla/venv/lib/python3.9/site-packages/dogpile/cache/region.py", line 995, in gen_value
2023-03-07 22:20:28.403791 2023-03-07 22:20:28.387 34 ERROR keystone.server.flask.application     created_value = creator(
2023-03-07 22:20:28.403804 2023-03-07 22:20:28.387 34 ERROR keystone.server.flask.application   File "/var/lib/kolla/venv/lib/python3.9/site-packages/keystone/resource/core.py", line 903, in get_project
2023-03-07 22:20:28.403840 2023-03-07 22:20:28.387 34 ERROR keystone.server.flask.application     return self.driver.get_project(project_id)
2023-03-07 22:20:28.403858 2023-03-07 22:20:28.387 34 ERROR keystone.server.flask.application   File "/var/lib/kolla/venv/lib/python3.9/site-packages/keystone/resource/backends/sql.py", line 49, in get_project
2023-03-07 22:20:28.403883 2023-03-07 22:20:28.387 34 ERROR keystone.server.flask.application     return self._get_project(session, project_id).to_dict()
2023-03-07 22:20:28.403920 2023-03-07 22:20:28.387 34 ERROR keystone.server.flask.application   File "/var/lib/kolla/venv/lib/python3.9/site-packages/keystone/resource/backends/sql.py", line 44, in _get_project
2023-03-07 22:20:28.403938 2023-03-07 22:20:28.387 34 ERROR keystone.server.flask.application     raise exception.ProjectNotFound(project_id=project_id)
2023-03-07 22:20:28.403958 2023-03-07 22:20:28.387 34 ERROR keystone.server.flask.application keystone.exception.ProjectNotFound: Could not find project: service.
2023-03-07 22:20:28.403985 2023-03-07 22:20:28.387 34 ERROR keystone.server.flask.application \x1b[00m
2023-03-07 22:20:37.429775 2023-03-07 22:20:37.419 33 ERROR keystone.server.flask.application [None req-dd010e8f-1dda-4e70-ac2d-4cc18625fcf2 557c326d318a409bbd94bffd97735c7e - - all default -] Could not find project: service.: keystone.exception.ProjectNotFound: Could not find project: service.
2023-03-07 22:20:37.429828 2023-03-07 22:20:37.419 33 ERROR keystone.server.flask.application Traceback (most recent call last):
2023-03-07 22:20:37.429856 2023-03-07 22:20:37.419 33 ERROR keystone.server.flask.application   File "/var/lib/kolla/venv/lib/python3.9/site-packages/flask/app.py", line 1820, in full_dispatch_request
2023-03-07 22:20:37.429871 2023-03-07 22:20:37.419 33 ERROR keystone.server.flask.application     rv = self.dispatch_request()
2023-03-07 22:20:37.429880 2023-03-07 22:20:37.419 33 ERROR keystone.server.flask.application   File "/var/lib/kolla/venv/lib/python3.9/site-packages/flask/app.py", line 1796, in dispatch_request
2023-03-07 22:20:37.429890 2023-03-07 22:20:37.419 33 ERROR keystone.server.flask.application     return self.ensure_sync(self.view_functions[rule.endpoint])(**view_args)
2023-03-07 22:20:37.429899 2023-03-07 22:20:37.419 33 ERROR keystone.server.flask.application   File "/var/lib/kolla/venv/lib/python3.9/site-packages/flask_restful/__init__.py", line 467, in wrapper
2023-03-07 22:20:37.429909 2023-03-07 22:20:37.419 33 ERROR keystone.server.flask.application     resp = resource(*args, **kwargs)
2023-03-07 22:20:37.429935 2023-03-07 22:20:37.419 33 ERROR keystone.server.flask.application   File "/var/lib/kolla/venv/lib/python3.9/site-packages/flask/views.py", line 107, in view
2023-03-07 22:20:37.429948 2023-03-07 22:20:37.419 33 ERROR keystone.server.flask.application     return current_app.ensure_sync(self.dispatch_request)(**kwargs)
2023-03-07 22:20:37.429958 2023-03-07 22:20:37.419 33 ERROR keystone.server.flask.application   File "/var/lib/kolla/venv/lib/python3.9/site-packages/flask_restful/__init__.py", line 582, in dispatch_request
2023-03-07 22:20:37.429967 2023-03-07 22:20:37.419 33 ERROR keystone.server.flask.application     resp = meth(*args, **kwargs)
2023-03-07 22:20:37.429977 2023-03-07 22:20:37.419 33 ERROR keystone.server.flask.application   File "/var/lib/kolla/venv/lib/python3.9/site-packages/keystone/api/projects.py", line 151, in get
2023-03-07 22:20:37.429987 2023-03-07 22:20:37.419 33 ERROR keystone.server.flask.application     return self._get_project(project_id)
2023-03-07 22:20:37.429996 2023-03-07 22:20:37.419 33 ERROR keystone.server.flask.application   File "/var/lib/kolla/venv/lib/python3.9/site-packages/keystone/api/projects.py", line 107, in _get_project
2023-03-07 22:20:37.430006 2023-03-07 22:20:37.419 33 ERROR keystone.server.flask.application     project = PROVIDERS.resource_api.get_project(project_id)
2023-03-07 22:20:37.430015 2023-03-07 22:20:37.419 33 ERROR keystone.server.flask.application   File "/var/lib/kolla/venv/lib/python3.9/site-packages/keystone/common/manager.py", line 115, in wrapped
2023-03-07 22:20:37.430024 2023-03-07 22:20:37.419 33 ERROR keystone.server.flask.application     __ret_val = __f(*args, **kwargs)
2023-03-07 22:20:37.430034 2023-03-07 22:20:37.419 33 ERROR keystone.server.flask.application   File "/var/lib/kolla/venv/lib/python3.9/site-packages/decorator.py", line 232, in fun
2023-03-07 22:20:37.430043 2023-03-07 22:20:37.419 33 ERROR keystone.server.flask.application     return caller(func, *(extras + args), **kw)
2023-03-07 22:20:37.430053 2023-03-07 22:20:37.419 33 ERROR keystone.server.flask.application   File "/var/lib/kolla/venv/lib/python3.9/site-packages/dogpile/cache/region.py", line 1577, in get_or_create_for_user_func
2023-03-07 22:20:37.430063 2023-03-07 22:20:37.419 33 ERROR keystone.server.flask.application     return self.get_or_create(
2023-03-07 22:20:37.430072 2023-03-07 22:20:37.419 33 ERROR keystone.server.flask.application   File "/var/lib/kolla/venv/lib/python3.9/site-packages/dogpile/cache/region.py", line 1042, in get_or_create
2023-03-07 22:20:37.430082 2023-03-07 22:20:37.419 33 ERROR keystone.server.flask.application     with Lock(
2023-03-07 22:20:37.430091 2023-03-07 22:20:37.419 33 ERROR keystone.server.flask.application   File "/var/lib/kolla/venv/lib/python3.9/site-packages/dogpile/lock.py", line 185, in __enter__
2023-03-07 22:20:37.430101 2023-03-07 22:20:37.419 33 ERROR keystone.server.flask.application     return self._enter()
2023-03-07 22:20:37.430121 2023-03-07 22:20:37.419 33 ERROR keystone.server.flask.application   File "/var/lib/kolla/venv/lib/python3.9/site-packages/dogpile/lock.py", line 94, in _enter
2023-03-07 22:20:37.430133 2023-03-07 22:20:37.419 33 ERROR keystone.server.flask.application     generated = self._enter_create(value, createdtime)
2023-03-07 22:20:37.430142 2023-03-07 22:20:37.419 33 ERROR keystone.server.flask.application   File "/var/lib/kolla/venv/lib/python3.9/site-packages/dogpile/lock.py", line 178, in _enter_create
2023-03-07 22:20:37.430152 2023-03-07 22:20:37.419 33 ERROR keystone.server.flask.application     return self.creator()
2023-03-07 22:20:37.430161 2023-03-07 22:20:37.419 33 ERROR keystone.server.flask.application   File "/var/lib/kolla/venv/lib/python3.9/site-packages/dogpile/cache/region.py", line 995, in gen_value
2023-03-07 22:20:37.430171 2023-03-07 22:20:37.419 33 ERROR keystone.server.flask.application     created_value = creator(
2023-03-07 22:20:37.430181 2023-03-07 22:20:37.419 33 ERROR keystone.server.flask.application   File "/var/lib/kolla/venv/lib/python3.9/site-packages/keystone/resource/core.py", line 903, in get_project
2023-03-07 22:20:37.430191 2023-03-07 22:20:37.419 33 ERROR keystone.server.flask.application     return self.driver.get_project(project_id)
2023-03-07 22:20:37.430200 2023-03-07 22:20:37.419 33 ERROR keystone.server.flask.application   File "/var/lib/kolla/venv/lib/python3.9/site-packages/keystone/resource/backends/sql.py", line 49, in get_project
2023-03-07 22:20:37.430210 2023-03-07 22:20:37.419 33 ERROR keystone.server.flask.application     return self._get_project(session, project_id).to_dict()
2023-03-07 22:20:37.430220 2023-03-07 22:20:37.419 33 ERROR keystone.server.flask.application   File "/var/lib/kolla/venv/lib/python3.9/site-packages/keystone/resource/backends/sql.py", line 44, in _get_project
2023-03-07 22:20:37.430229 2023-03-07 22:20:37.419 33 ERROR keystone.server.flask.application     raise exception.ProjectNotFound(project_id=project_id)
2023-03-07 22:20:37.430238 2023-03-07 22:20:37.419 33 ERROR keystone.server.flask.application keystone.exception.ProjectNotFound: Could not find project: service.
2023-03-07 22:20:37.430248 2023-03-07 22:20:37.419 33 ERROR keystone.server.flask.application \x1b[00m
2023-03-07 22:20:53.640016 2023-03-07 22:20:53.628 33 ERROR keystone.server.flask.application [None req-6eb07f50-d465-4076-bef8-43338d7a48f4 557c326d318a409bbd94bffd97735c7e - - all default -] Could not find role: admin.: keystone.exception.RoleNotFound: Could not find role: admin.
2023-03-07 22:20:53.640113 2023-03-07 22:20:53.628 33 ERROR keystone.server.flask.application Traceback (most recent call last):
2023-03-07 22:20:53.640138 2023-03-07 22:20:53.628 33 ERROR keystone.server.flask.application   File "/var/lib/kolla/venv/lib/python3.9/site-packages/flask/app.py", line 1820, in full_dispatch_request
2023-03-07 22:20:53.640160 2023-03-07 22:20:53.628 33 ERROR keystone.server.flask.application     rv = self.dispatch_request()
2023-03-07 22:20:53.640188 2023-03-07 22:20:53.628 33 ERROR keystone.server.flask.application   File "/var/lib/kolla/venv/lib/python3.9/site-packages/flask/app.py", line 1796, in dispatch_request
2023-03-07 22:20:53.640206 2023-03-07 22:20:53.628 33 ERROR keystone.server.flask.application     return self.ensure_sync(self.view_functions[rule.endpoint])(**view_args)
2023-03-07 22:20:53.640228 2023-03-07 22:20:53.628 33 ERROR keystone.server.flask.application   File "/var/lib/kolla/venv/lib/python3.9/site-packages/flask_restful/__init__.py", line 467, in wrapper
2023-03-07 22:20:53.640252 2023-03-07 22:20:53.628 33 ERROR keystone.server.flask.application     resp = resource(*args, **kwargs)
2023-03-07 22:20:53.640282 2023-03-07 22:20:53.628 33 ERROR keystone.server.flask.application   File "/var/lib/kolla/venv/lib/python3.9/site-packages/flask/views.py", line 107, in view
2023-03-07 22:20:53.640305 2023-03-07 22:20:53.628 33 ERROR keystone.server.flask.application     return current_app.ensure_sync(self.dispatch_request)(**kwargs)
2023-03-07 22:20:53.640323 2023-03-07 22:20:53.628 33 ERROR keystone.server.flask.application   File "/var/lib/kolla/venv/lib/python3.9/site-packages/flask_restful/__init__.py", line 582, in dispatch_request
2023-03-07 22:20:53.640624 2023-03-07 22:20:53.628 33 ERROR keystone.server.flask.application     resp = meth(*args, **kwargs)
2023-03-07 22:20:53.640651 2023-03-07 22:20:53.628 33 ERROR keystone.server.flask.application   File "/var/lib/kolla/venv/lib/python3.9/site-packages/keystone/api/roles.py", line 50, in get
2023-03-07 22:20:53.640694 2023-03-07 22:20:53.628 33 ERROR keystone.server.flask.application     return self._get_role(role_id)
2023-03-07 22:20:53.640711 2023-03-07 22:20:53.628 33 ERROR keystone.server.flask.application   File "/var/lib/kolla/venv/lib/python3.9/site-packages/keystone/api/roles.py", line 70, in _get_role
2023-03-07 22:20:53.640727 2023-03-07 22:20:53.628 33 ERROR keystone.server.flask.application     ENFORCER.enforce_call(action='identity:get_role')
2023-03-07 22:20:53.640754 2023-03-07 22:20:53.628 33 ERROR keystone.server.flask.application   File "/var/lib/kolla/venv/lib/python3.9/site-packages/keystone/common/rbac_enforcer/enforcer.py", line 402, in enforce_call
2023-03-07 22:20:53.640775 2023-03-07 22:20:53.628 33 ERROR keystone.server.flask.application     policy_dict.update(cls._extract_member_target_data(
2023-03-07 22:20:53.640807 2023-03-07 22:20:53.628 33 ERROR keystone.server.flask.application   File "/var/lib/kolla/venv/lib/python3.9/site-packages/keystone/common/rbac_enforcer/enforcer.py", line 234, in _extract_member_target_data
2023-03-07 22:20:53.640830 2023-03-07 22:20:53.628 33 ERROR keystone.server.flask.application     member_name: func(flask.request.view_args[key])
2023-03-07 22:20:53.640849 2023-03-07 22:20:53.628 33 ERROR keystone.server.flask.application   File "/var/lib/kolla/venv/lib/python3.9/site-packages/keystone/common/manager.py", line 115, in wrapped
2023-03-07 22:20:53.640867 2023-03-07 22:20:53.628 33 ERROR keystone.server.flask.application     __ret_val = __f(*args, **kwargs)
2023-03-07 22:20:53.640888 2023-03-07 22:20:53.628 33 ERROR keystone.server.flask.application   File "/var/lib/kolla/venv/lib/python3.9/site-packages/decorator.py", line 232, in fun
2023-03-07 22:20:53.640914 2023-03-07 22:20:53.628 33 ERROR keystone.server.flask.application     return caller(func, *(extras + args), **kw)
2023-03-07 22:20:53.640936 2023-03-07 22:20:53.628 33 ERROR keystone.server.flask.application   File "/var/lib/kolla/venv/lib/python3.9/site-packages/dogpile/cache/region.py", line 1577, in get_or_create_for_user_func
2023-03-07 22:20:53.640952 2023-03-07 22:20:53.628 33 ERROR keystone.server.flask.application     return self.get_or_create(
2023-03-07 22:20:53.640967 2023-03-07 22:20:53.628 33 ERROR keystone.server.flask.application   File "/var/lib/kolla/venv/lib/python3.9/site-packages/dogpile/cache/region.py", line 1042, in get_or_create
2023-03-07 22:20:53.640984 2023-03-07 22:20:53.628 33 ERROR keystone.server.flask.application     with Lock(
2023-03-07 22:20:53.640999 2023-03-07 22:20:53.628 33 ERROR keystone.server.flask.application   File "/var/lib/kolla/venv/lib/python3.9/site-packages/dogpile/lock.py", line 185, in __enter__
2023-03-07 22:20:53.641015 2023-03-07 22:20:53.628 33 ERROR keystone.server.flask.application     return self._enter()
2023-03-07 22:20:53.641031 2023-03-07 22:20:53.628 33 ERROR keystone.server.flask.application   File "/var/lib/kolla/venv/lib/python3.9/site-packages/dogpile/lock.py", line 94, in _enter
2023-03-07 22:20:53.641048 2023-03-07 22:20:53.628 33 ERROR keystone.server.flask.application     generated = self._enter_create(value, createdtime)
2023-03-07 22:20:53.641062 2023-03-07 22:20:53.628 33 ERROR keystone.server.flask.application   File "/var/lib/kolla/venv/lib/python3.9/site-packages/dogpile/lock.py", line 178, in _enter_create
2023-03-07 22:20:53.641078 2023-03-07 22:20:53.628 33 ERROR keystone.server.flask.application     return self.creator()
2023-03-07 22:20:53.641094 2023-03-07 22:20:53.628 33 ERROR keystone.server.flask.application   File "/var/lib/kolla/venv/lib/python3.9/site-packages/dogpile/cache/region.py", line 995, in gen_value
2023-03-07 22:20:53.641149 2023-03-07 22:20:53.628 33 ERROR keystone.server.flask.application     created_value = creator(
2023-03-07 22:20:53.641180 2023-03-07 22:20:53.628 33 ERROR keystone.server.flask.application   File "/var/lib/kolla/venv/lib/python3.9/site-packages/keystone/assignment/core.py", line 1276, in get_role
2023-03-07 22:20:53.641202 2023-03-07 22:20:53.628 33 ERROR keystone.server.flask.application     return self.driver.get_role(role_id)
2023-03-07 22:20:53.641224 2023-03-07 22:20:53.628 33 ERROR keystone.server.flask.application   File "/var/lib/kolla/venv/lib/python3.9/site-packages/keystone/assignment/role_backends/sql.py", line 70, in get_role
2023-03-07 22:20:53.641244 2023-03-07 22:20:53.628 33 ERROR keystone.server.flask.application     return self._get_role(session, role_id).to_dict()
2023-03-07 22:20:53.641264 2023-03-07 22:20:53.628 33 ERROR keystone.server.flask.application   File "/var/lib/kolla/venv/lib/python3.9/site-packages/keystone/assignment/role_backends/sql.py", line 65, in _get_role
2023-03-07 22:20:53.641285 2023-03-07 22:20:53.628 33 ERROR keystone.server.flask.application     raise exception.RoleNotFound(role_id=role_id)
2023-03-07 22:20:53.641308 2023-03-07 22:20:53.628 33 ERROR keystone.server.flask.application keystone.exception.RoleNotFound: Could not find role: admin.
2023-03-07 22:20:53.641330 2023-03-07 22:20:53.628 33 ERROR keystone.server.flask.application \x1b[00m
2023-03-07 22:20:54.886521 2023-03-07 22:20:54.879 33 ERROR keystone.server.flask.application [None req-41cbb6a6-3d07-4caf-993d-f6dc420f2262 557c326d318a409bbd94bffd97735c7e - - all default -] Could not find user: ironic.: keystone.exception.UserNotFound: Could not find user: ironic.
2023-03-07 22:20:54.886614 2023-03-07 22:20:54.879 33 ERROR keystone.server.flask.application Traceback (most recent call last):
2023-03-07 22:20:54.886626 2023-03-07 22:20:54.879 33 ERROR keystone.server.flask.application   File "/var/lib/kolla/venv/lib/python3.9/site-packages/flask/app.py", line 1820, in full_dispatch_request
2023-03-07 22:20:54.886637 2023-03-07 22:20:54.879 33 ERROR keystone.server.flask.application     rv = self.dispatch_request()
2023-03-07 22:20:54.886647 2023-03-07 22:20:54.879 33 ERROR keystone.server.flask.application   File "/var/lib/kolla/venv/lib/python3.9/site-packages/flask/app.py", line 1796, in dispatch_request
2023-03-07 22:20:54.886657 2023-03-07 22:20:54.879 33 ERROR keystone.server.flask.application     return self.ensure_sync(self.view_functions[rule.endpoint])(**view_args)
2023-03-07 22:20:54.886675 2023-03-07 22:20:54.879 33 ERROR keystone.server.flask.application   File "/var/lib/kolla/venv/lib/python3.9/site-packages/flask_restful/__init__.py", line 467, in wrapper
2023-03-07 22:20:54.886684 2023-03-07 22:20:54.879 33 ERROR keystone.server.flask.application     resp = resource(*args, **kwargs)
2023-03-07 22:20:54.886694 2023-03-07 22:20:54.879 33 ERROR keystone.server.flask.application   File "/var/lib/kolla/venv/lib/python3.9/site-packages/flask/views.py", line 107, in view
2023-03-07 22:20:54.886704 2023-03-07 22:20:54.879 33 ERROR keystone.server.flask.application     return current_app.ensure_sync(self.dispatch_request)(**kwargs)
2023-03-07 22:20:54.886714 2023-03-07 22:20:54.879 33 ERROR keystone.server.flask.application   File "/var/lib/kolla/venv/lib/python3.9/site-packages/flask_restful/__init__.py", line 582, in dispatch_request
2023-03-07 22:20:54.886723 2023-03-07 22:20:54.879 33 ERROR keystone.server.flask.application     resp = meth(*args, **kwargs)
2023-03-07 22:20:54.886732 2023-03-07 22:20:54.879 33 ERROR keystone.server.flask.application   File "/var/lib/kolla/venv/lib/python3.9/site-packages/keystone/api/users.py", line 182, in get
2023-03-07 22:20:54.886742 2023-03-07 22:20:54.879 33 ERROR keystone.server.flask.application     return self._get_user(user_id)
2023-03-07 22:20:54.886751 2023-03-07 22:20:54.879 33 ERROR keystone.server.flask.application   File "/var/lib/kolla/venv/lib/python3.9/site-packages/keystone/api/users.py", line 194, in _get_user
2023-03-07 22:20:54.886777 2023-03-07 22:20:54.879 33 ERROR keystone.server.flask.application     ref = PROVIDERS.identity_api.get_user(user_id)
2023-03-07 22:20:54.886788 2023-03-07 22:20:54.879 33 ERROR keystone.server.flask.application   File "/var/lib/kolla/venv/lib/python3.9/site-packages/keystone/common/manager.py", line 115, in wrapped
2023-03-07 22:20:54.886798 2023-03-07 22:20:54.879 33 ERROR keystone.server.flask.application     __ret_val = __f(*args, **kwargs)
2023-03-07 22:20:54.886808 2023-03-07 22:20:54.879 33 ERROR keystone.server.flask.application   File "/var/lib/kolla/venv/lib/python3.9/site-packages/keystone/identity/core.py", line 414, in wrapper
2023-03-07 22:20:54.886817 2023-03-07 22:20:54.879 33 ERROR keystone.server.flask.application     return f(self, *args, **kwargs)
2023-03-07 22:20:54.886827 2023-03-07 22:20:54.879 33 ERROR keystone.server.flask.application   File "/var/lib/kolla/venv/lib/python3.9/site-packages/keystone/identity/core.py", line 424, in wrapper
2023-03-07 22:20:54.886837 2023-03-07 22:20:54.879 33 ERROR keystone.server.flask.application     return f(self, *args, **kwargs)
2023-03-07 22:20:54.886846 2023-03-07 22:20:54.879 33 ERROR keystone.server.flask.application   File "/var/lib/kolla/venv/lib/python3.9/site-packages/decorator.py", line 232, in fun
2023-03-07 22:20:54.886856 2023-03-07 22:20:54.879 33 ERROR keystone.server.flask.application     return caller(func, *(extras + args), **kw)
2023-03-07 22:20:54.886866 2023-03-07 22:20:54.879 33 ERROR keystone.server.flask.application   File "/var/lib/kolla/venv/lib/python3.9/site-packages/dogpile/cache/region.py", line 1577, in get_or_create_for_user_func
2023-03-07 22:20:54.886876 2023-03-07 22:20:54.879 33 ERROR keystone.server.flask.application     return self.get_or_create(
2023-03-07 22:20:54.886885 2023-03-07 22:20:54.879 33 ERROR keystone.server.flask.application   File "/var/lib/kolla/venv/lib/python3.9/site-packages/dogpile/cache/region.py", line 1042, in get_or_create
2023-03-07 22:20:54.886896 2023-03-07 22:20:54.879 33 ERROR keystone.server.flask.application     with Lock(
2023-03-07 22:20:54.886906 2023-03-07 22:20:54.879 33 ERROR keystone.server.flask.application   File "/var/lib/kolla/venv/lib/python3.9/site-packages/dogpile/lock.py", line 185, in __enter__
2023-03-07 22:20:54.886916 2023-03-07 22:20:54.879 33 ERROR keystone.server.flask.application     return self._enter()
2023-03-07 22:20:54.886925 2023-03-07 22:20:54.879 33 ERROR keystone.server.flask.application   File "/var/lib/kolla/venv/lib/python3.9/site-packages/dogpile/lock.py", line 94, in _enter
2023-03-07 22:20:54.886935 2023-03-07 22:20:54.879 33 ERROR keystone.server.flask.application     generated = self._enter_create(value, createdtime)
2023-03-07 22:20:54.886945 2023-03-07 22:20:54.879 33 ERROR keystone.server.flask.application   File "/var/lib/kolla/venv/lib/python3.9/site-packages/dogpile/lock.py", line 178, in _enter_create
2023-03-07 22:20:54.886955 2023-03-07 22:20:54.879 33 ERROR keystone.server.flask.application     return self.creator()
2023-03-07 22:20:54.886964 2023-03-07 22:20:54.879 33 ERROR keystone.server.flask.application   File "/var/lib/kolla/venv/lib/python3.9/site-packages/dogpile/cache/region.py", line 995, in gen_value
2023-03-07 22:20:54.886974 2023-03-07 22:20:54.879 33 ERROR keystone.server.flask.application     created_value = creator(
2023-03-07 22:20:54.886984 2023-03-07 22:20:54.879 33 ERROR keystone.server.flask.application   File "/var/lib/kolla/venv/lib/python3.9/site-packages/keystone/identity/core.py", line 1011, in get_user
2023-03-07 22:20:54.886994 2023-03-07 22:20:54.879 33 ERROR keystone.server.flask.application     ref = driver.get_user(entity_id)
2023-03-07 22:20:54.887003 2023-03-07 22:20:54.879 33 ERROR keystone.server.flask.application   File "/var/lib/kolla/venv/lib/python3.9/site-packages/keystone/identity/backends/sql.py", line 200, in get_user
2023-03-07 22:20:54.887013 2023-03-07 22:20:54.879 33 ERROR keystone.server.flask.application     self._get_user(session, user_id).to_dict())
2023-03-07 22:20:54.887033 2023-03-07 22:20:54.879 33 ERROR keystone.server.flask.application   File "/var/lib/kolla/venv/lib/python3.9/site-packages/keystone/identity/backends/sql.py", line 194, in _get_user
2023-03-07 22:20:54.887044 2023-03-07 22:20:54.879 33 ERROR keystone.server.flask.application     raise exception.UserNotFound(user_id=user_id)
2023-03-07 22:20:54.887054 2023-03-07 22:20:54.879 33 ERROR keystone.server.flask.application keystone.exception.UserNotFound: Could not find user: ironic.
2023-03-07 22:20:54.887063 2023-03-07 22:20:54.879 33 ERROR keystone.server.flask.application \x1b[00m
2023-03-07 22:20:55.892405 2023-03-07 22:20:55.882 32 ERROR keystone.server.flask.application [None req-1da92032-268f-4fb4-81dd-3be8d15e2ae2 557c326d318a409bbd94bffd97735c7e - - all default -] Could not find project: service.: keystone.exception.ProjectNotFound: Could not find project: service.
2023-03-07 22:20:55.892466 2023-03-07 22:20:55.882 32 ERROR keystone.server.flask.application Traceback (most recent call last):
2023-03-07 22:20:55.892478 2023-03-07 22:20:55.882 32 ERROR keystone.server.flask.application   File "/var/lib/kolla/venv/lib/python3.9/site-packages/flask/app.py", line 1820, in full_dispatch_request
2023-03-07 22:20:55.892489 2023-03-07 22:20:55.882 32 ERROR keystone.server.flask.application     rv = self.dispatch_request()
2023-03-07 22:20:55.892498 2023-03-07 22:20:55.882 32 ERROR keystone.server.flask.application   File "/var/lib/kolla/venv/lib/python3.9/site-packages/flask/app.py", line 1796, in dispatch_request
2023-03-07 22:20:55.892508 2023-03-07 22:20:55.882 32 ERROR keystone.server.flask.application     return self.ensure_sync(self.view_functions[rule.endpoint])(**view_args)
2023-03-07 22:20:55.892518 2023-03-07 22:20:55.882 32 ERROR keystone.server.flask.application   File "/var/lib/kolla/venv/lib/python3.9/site-packages/flask_restful/__init__.py", line 467, in wrapper
2023-03-07 22:20:55.892528 2023-03-07 22:20:55.882 32 ERROR keystone.server.flask.application     resp = resource(*args, **kwargs)
2023-03-07 22:20:55.892568 2023-03-07 22:20:55.882 32 ERROR keystone.server.flask.application   File "/var/lib/kolla/venv/lib/python3.9/site-packages/flask/views.py", line 107, in view
2023-03-07 22:20:55.892594 2023-03-07 22:20:55.882 32 ERROR keystone.server.flask.application     return current_app.ensure_sync(self.dispatch_request)(**kwargs)
2023-03-07 22:20:55.892603 2023-03-07 22:20:55.882 32 ERROR keystone.server.flask.application   File "/var/lib/kolla/venv/lib/python3.9/site-packages/flask_restful/__init__.py", line 582, in dispatch_request
2023-03-07 22:20:55.892613 2023-03-07 22:20:55.882 32 ERROR keystone.server.flask.application     resp = meth(*args, **kwargs)
2023-03-07 22:20:55.892622 2023-03-07 22:20:55.882 32 ERROR keystone.server.flask.application   File "/var/lib/kolla/venv/lib/python3.9/site-packages/keystone/api/projects.py", line 151, in get
2023-03-07 22:20:55.892632 2023-03-07 22:20:55.882 32 ERROR keystone.server.flask.application     return self._get_project(project_id)
2023-03-07 22:20:55.892641 2023-03-07 22:20:55.882 32 ERROR keystone.server.flask.application   File "/var/lib/kolla/venv/lib/python3.9/site-packages/keystone/api/projects.py", line 107, in _get_project
2023-03-07 22:20:55.892651 2023-03-07 22:20:55.882 32 ERROR keystone.server.flask.application     project = PROVIDERS.resource_api.get_project(project_id)
2023-03-07 22:20:55.892660 2023-03-07 22:20:55.882 32 ERROR keystone.server.flask.application   File "/var/lib/kolla/venv/lib/python3.9/site-packages/keystone/common/manager.py", line 115, in wrapped
2023-03-07 22:20:55.892670 2023-03-07 22:20:55.882 32 ERROR keystone.server.flask.application     __ret_val = __f(*args, **kwargs)
2023-03-07 22:20:55.892679 2023-03-07 22:20:55.882 32 ERROR keystone.server.flask.application   File "/var/lib/kolla/venv/lib/python3.9/site-packages/decorator.py", line 232, in fun
2023-03-07 22:20:55.892689 2023-03-07 22:20:55.882 32 ERROR keystone.server.flask.application     return caller(func, *(extras + args), **kw)
2023-03-07 22:20:55.892723 2023-03-07 22:20:55.882 32 ERROR keystone.server.flask.application   File "/var/lib/kolla/venv/lib/python3.9/site-packages/dogpile/cache/region.py", line 1577, in get_or_create_for_user_func
2023-03-07 22:20:55.892738 2023-03-07 22:20:55.882 32 ERROR keystone.server.flask.application     return self.get_or_create(
2023-03-07 22:20:55.892747 2023-03-07 22:20:55.882 32 ERROR keystone.server.flask.application   File "/var/lib/kolla/venv/lib/python3.9/site-packages/dogpile/cache/region.py", line 1042, in get_or_create
2023-03-07 22:20:55.892757 2023-03-07 22:20:55.882 32 ERROR keystone.server.flask.application     with Lock(
2023-03-07 22:20:55.892767 2023-03-07 22:20:55.882 32 ERROR keystone.server.flask.application   File "/var/lib/kolla/venv/lib/python3.9/site-packages/dogpile/lock.py", line 185, in __enter__
2023-03-07 22:20:55.892777 2023-03-07 22:20:55.882 32 ERROR keystone.server.flask.application     return self._enter()
2023-03-07 22:20:55.892786 2023-03-07 22:20:55.882 32 ERROR keystone.server.flask.application   File "/var/lib/kolla/venv/lib/python3.9/site-packages/dogpile/lock.py", line 94, in _enter
2023-03-07 22:20:55.892796 2023-03-07 22:20:55.882 32 ERROR keystone.server.flask.application     generated = self._enter_create(value, createdtime)
2023-03-07 22:20:55.892805 2023-03-07 22:20:55.882 32 ERROR keystone.server.flask.application   File "/var/lib/kolla/venv/lib/python3.9/site-packages/dogpile/lock.py", line 178, in _enter_create
2023-03-07 22:20:55.892815 2023-03-07 22:20:55.882 32 ERROR keystone.server.flask.application     return self.creator()
2023-03-07 22:20:55.892824 2023-03-07 22:20:55.882 32 ERROR keystone.server.flask.application   File "/var/lib/kolla/venv/lib/python3.9/site-packages/dogpile/cache/region.py", line 995, in gen_value
2023-03-07 22:20:55.892834 2023-03-07 22:20:55.882 32 ERROR keystone.server.flask.application     created_value = creator(
2023-03-07 22:20:55.892844 2023-03-07 22:20:55.882 32 ERROR keystone.server.flask.application   File "/var/lib/kolla/venv/lib/python3.9/site-packages/keystone/resource/core.py", line 903, in get_project
2023-03-07 22:20:55.892854 2023-03-07 22:20:55.882 32 ERROR keystone.server.flask.application     return self.driver.get_project(project_id)
2023-03-07 22:20:55.892863 2023-03-07 22:20:55.882 32 ERROR keystone.server.flask.application   File "/var/lib/kolla/venv/lib/python3.9/site-packages/keystone/resource/backends/sql.py", line 49, in get_project
2023-03-07 22:20:55.892873 2023-03-07 22:20:55.882 32 ERROR keystone.server.flask.application     return self._get_project(session, project_id).to_dict()
2023-03-07 22:20:55.892883 2023-03-07 22:20:55.882 32 ERROR keystone.server.flask.application   File "/var/lib/kolla/venv/lib/python3.9/site-packages/keystone/resource/backends/sql.py", line 44, in _get_project
2023-03-07 22:20:55.892893 2023-03-07 22:20:55.882 32 ERROR keystone.server.flask.application     raise exception.ProjectNotFound(project_id=project_id)
2023-03-07 22:20:55.892902 2023-03-07 22:20:55.882 32 ERROR keystone.server.flask.application keystone.exception.ProjectNotFound: Could not find project: service.
2023-03-07 22:20:55.892912 2023-03-07 22:20:55.882 32 ERROR keystone.server.flask.application \x1b[00m
2023-03-07 22:21:06.234686 2023-03-07 22:21:06.228 34 ERROR keystone.server.flask.application [None req-1dc705fe-0633-48fa-917c-00d8592a4694 557c326d318a409bbd94bffd97735c7e - - all default -] Could not find role: admin.: keystone.exception.RoleNotFound: Could not find role: admin.
2023-03-07 22:21:06.234757 2023-03-07 22:21:06.228 34 ERROR keystone.server.flask.application Traceback (most recent call last):
2023-03-07 22:21:06.234770 2023-03-07 22:21:06.228 34 ERROR keystone.server.flask.application   File "/var/lib/kolla/venv/lib/python3.9/site-packages/flask/app.py", line 1820, in full_dispatch_request
2023-03-07 22:21:06.234780 2023-03-07 22:21:06.228 34 ERROR keystone.server.flask.application     rv = self.dispatch_request()
2023-03-07 22:21:06.234790 2023-03-07 22:21:06.228 34 ERROR keystone.server.flask.application   File "/var/lib/kolla/venv/lib/python3.9/site-packages/flask/app.py", line 1796, in dispatch_request
2023-03-07 22:21:06.234826 2023-03-07 22:21:06.228 34 ERROR keystone.server.flask.application     return self.ensure_sync(self.view_functions[rule.endpoint])(**view_args)
2023-03-07 22:21:06.234839 2023-03-07 22:21:06.228 34 ERROR keystone.server.flask.application   File "/var/lib/kolla/venv/lib/python3.9/site-packages/flask_restful/__init__.py", line 467, in wrapper
2023-03-07 22:21:06.234849 2023-03-07 22:21:06.228 34 ERROR keystone.server.flask.application     resp = resource(*args, **kwargs)
2023-03-07 22:21:06.234859 2023-03-07 22:21:06.228 34 ERROR keystone.server.flask.application   File "/var/lib/kolla/venv/lib/python3.9/site-packages/flask/views.py", line 107, in view
2023-03-07 22:21:06.234870 2023-03-07 22:21:06.228 34 ERROR keystone.server.flask.application     return current_app.ensure_sync(self.dispatch_request)(**kwargs)
2023-03-07 22:21:06.234880 2023-03-07 22:21:06.228 34 ERROR keystone.server.flask.application   File "/var/lib/kolla/venv/lib/python3.9/site-packages/flask_restful/__init__.py", line 582, in dispatch_request
2023-03-07 22:21:06.234890 2023-03-07 22:21:06.228 34 ERROR keystone.server.flask.application     resp = meth(*args, **kwargs)
2023-03-07 22:21:06.234899 2023-03-07 22:21:06.228 34 ERROR keystone.server.flask.application   File "/var/lib/kolla/venv/lib/python3.9/site-packages/keystone/api/roles.py", line 50, in get
2023-03-07 22:21:06.234909 2023-03-07 22:21:06.228 34 ERROR keystone.server.flask.application     return self._get_role(role_id)
2023-03-07 22:21:06.234919 2023-03-07 22:21:06.228 34 ERROR keystone.server.flask.application   File "/var/lib/kolla/venv/lib/python3.9/site-packages/keystone/api/roles.py", line 70, in _get_role
2023-03-07 22:21:06.234929 2023-03-07 22:21:06.228 34 ERROR keystone.server.flask.application     ENFORCER.enforce_call(action='identity:get_role')
2023-03-07 22:21:06.234939 2023-03-07 22:21:06.228 34 ERROR keystone.server.flask.application   File "/var/lib/kolla/venv/lib/python3.9/site-packages/keystone/common/rbac_enforcer/enforcer.py", line 402, in enforce_call
2023-03-07 22:21:06.234949 2023-03-07 22:21:06.228 34 ERROR keystone.server.flask.application     policy_dict.update(cls._extract_member_target_data(
2023-03-07 22:21:06.234965 2023-03-07 22:21:06.228 34 ERROR keystone.server.flask.application   File "/var/lib/kolla/venv/lib/python3.9/site-packages/keystone/common/rbac_enforcer/enforcer.py", line 234, in _extract_member_target_data
2023-03-07 22:21:06.234979 2023-03-07 22:21:06.228 34 ERROR keystone.server.flask.application     member_name: func(flask.request.view_args[key])
2023-03-07 22:21:06.234989 2023-03-07 22:21:06.228 34 ERROR keystone.server.flask.application   File "/var/lib/kolla/venv/lib/python3.9/site-packages/keystone/common/manager.py", line 115, in wrapped
2023-03-07 22:21:06.234999 2023-03-07 22:21:06.228 34 ERROR keystone.server.flask.application     __ret_val = __f(*args, **kwargs)
2023-03-07 22:21:06.235008 2023-03-07 22:21:06.228 34 ERROR keystone.server.flask.application   File "/var/lib/kolla/venv/lib/python3.9/site-packages/decorator.py", line 232, in fun
2023-03-07 22:21:06.235018 2023-03-07 22:21:06.228 34 ERROR keystone.server.flask.application     return caller(func, *(extras + args), **kw)
2023-03-07 22:21:06.235027 2023-03-07 22:21:06.228 34 ERROR keystone.server.flask.application   File "/var/lib/kolla/venv/lib/python3.9/site-packages/dogpile/cache/region.py", line 1577, in get_or_create_for_user_func
2023-03-07 22:21:06.235037 2023-03-07 22:21:06.228 34 ERROR keystone.server.flask.application     return self.get_or_create(
2023-03-07 22:21:06.235046 2023-03-07 22:21:06.228 34 ERROR keystone.server.flask.application   File "/var/lib/kolla/venv/lib/python3.9/site-packages/dogpile/cache/region.py", line 1042, in get_or_create
2023-03-07 22:21:06.235056 2023-03-07 22:21:06.228 34 ERROR keystone.server.flask.application     with Lock(
2023-03-07 22:21:06.235091 2023-03-07 22:21:06.228 34 ERROR keystone.server.flask.application   File "/var/lib/kolla/venv/lib/python3.9/site-packages/dogpile/lock.py", line 185, in __enter__
2023-03-07 22:21:06.235104 2023-03-07 22:21:06.228 34 ERROR keystone.server.flask.application     return self._enter()
2023-03-07 22:21:06.235113 2023-03-07 22:21:06.228 34 ERROR keystone.server.flask.application   File "/var/lib/kolla/venv/lib/python3.9/site-packages/dogpile/lock.py", line 94, in _enter
2023-03-07 22:21:06.235123 2023-03-07 22:21:06.228 34 ERROR keystone.server.flask.application     generated = self._enter_create(value, createdtime)
2023-03-07 22:21:06.235133 2023-03-07 22:21:06.228 34 ERROR keystone.server.flask.application   File "/var/lib/kolla/venv/lib/python3.9/site-packages/dogpile/lock.py", line 178, in _enter_create
2023-03-07 22:21:06.235142 2023-03-07 22:21:06.228 34 ERROR keystone.server.flask.application     return self.creator()
2023-03-07 22:21:06.235152 2023-03-07 22:21:06.228 34 ERROR keystone.server.flask.application   File "/var/lib/kolla/venv/lib/python3.9/site-packages/dogpile/cache/region.py", line 995, in gen_value
2023-03-07 22:21:06.235162 2023-03-07 22:21:06.228 34 ERROR keystone.server.flask.application     created_value = creator(
2023-03-07 22:21:06.235172 2023-03-07 22:21:06.228 34 ERROR keystone.server.flask.application   File "/var/lib/kolla/venv/lib/python3.9/site-packages/keystone/assignment/core.py", line 1276, in get_role
2023-03-07 22:21:06.235182 2023-03-07 22:21:06.228 34 ERROR keystone.server.flask.application     return self.driver.get_role(role_id)
2023-03-07 22:21:06.235191 2023-03-07 22:21:06.228 34 ERROR keystone.server.flask.application   File "/var/lib/kolla/venv/lib/python3.9/site-packages/keystone/assignment/role_backends/sql.py", line 70, in get_role
2023-03-07 22:21:06.235201 2023-03-07 22:21:06.228 34 ERROR keystone.server.flask.application     return self._get_role(session, role_id).to_dict()
2023-03-07 22:21:06.235211 2023-03-07 22:21:06.228 34 ERROR keystone.server.flask.application   File "/var/lib/kolla/venv/lib/python3.9/site-packages/keystone/assignment/role_backends/sql.py", line 65, in _get_role
2023-03-07 22:21:06.235221 2023-03-07 22:21:06.228 34 ERROR keystone.server.flask.application     raise exception.RoleNotFound(role_id=role_id)
2023-03-07 22:21:06.235230 2023-03-07 22:21:06.228 34 ERROR keystone.server.flask.application keystone.exception.RoleNotFound: Could not find role: admin.
2023-03-07 22:21:06.235240 2023-03-07 22:21:06.228 34 ERROR keystone.server.flask.application \x1b[00m
2023-03-07 22:21:07.525346 2023-03-07 22:21:07.518 34 ERROR keystone.server.flask.application [None req-5a83c00c-bcc8-4291-8f3d-885b12cd2f80 557c326d318a409bbd94bffd97735c7e - - all default -] Could not find user: ironic-inspector.: keystone.exception.UserNotFound: Could not find user: ironic-inspector.
2023-03-07 22:21:07.525465 2023-03-07 22:21:07.518 34 ERROR keystone.server.flask.application Traceback (most recent call last):
2023-03-07 22:21:07.525481 2023-03-07 22:21:07.518 34 ERROR keystone.server.flask.application   File "/var/lib/kolla/venv/lib/python3.9/site-packages/flask/app.py", line 1820, in full_dispatch_request
2023-03-07 22:21:07.525493 2023-03-07 22:21:07.518 34 ERROR keystone.server.flask.application     rv = self.dispatch_request()
2023-03-07 22:21:07.525505 2023-03-07 22:21:07.518 34 ERROR keystone.server.flask.application   File "/var/lib/kolla/venv/lib/python3.9/site-packages/flask/app.py", line 1796, in dispatch_request
2023-03-07 22:21:07.525518 2023-03-07 22:21:07.518 34 ERROR keystone.server.flask.application     return self.ensure_sync(self.view_functions[rule.endpoint])(**view_args)
2023-03-07 22:21:07.525534 2023-03-07 22:21:07.518 34 ERROR keystone.server.flask.application   File "/var/lib/kolla/venv/lib/python3.9/site-packages/flask_restful/__init__.py", line 467, in wrapper
2023-03-07 22:21:07.525568 2023-03-07 22:21:07.518 34 ERROR keystone.server.flask.application     resp = resource(*args, **kwargs)
2023-03-07 22:21:07.525584 2023-03-07 22:21:07.518 34 ERROR keystone.server.flask.application   File "/var/lib/kolla/venv/lib/python3.9/site-packages/flask/views.py", line 107, in view
2023-03-07 22:21:07.525616 2023-03-07 22:21:07.518 34 ERROR keystone.server.flask.application     return current_app.ensure_sync(self.dispatch_request)(**kwargs)
2023-03-07 22:21:07.525630 2023-03-07 22:21:07.518 34 ERROR keystone.server.flask.application   File "/var/lib/kolla/venv/lib/python3.9/site-packages/flask_restful/__init__.py", line 582, in dispatch_request
2023-03-07 22:21:07.525643 2023-03-07 22:21:07.518 34 ERROR keystone.server.flask.application     resp = meth(*args, **kwargs)
2023-03-07 22:21:07.525655 2023-03-07 22:21:07.518 34 ERROR keystone.server.flask.application   File "/var/lib/kolla/venv/lib/python3.9/site-packages/keystone/api/users.py", line 182, in get
2023-03-07 22:21:07.525667 2023-03-07 22:21:07.518 34 ERROR keystone.server.flask.application     return self._get_user(user_id)
2023-03-07 22:21:07.525679 2023-03-07 22:21:07.518 34 ERROR keystone.server.flask.application   File "/var/lib/kolla/venv/lib/python3.9/site-packages/keystone/api/users.py", line 194, in _get_user
2023-03-07 22:21:07.525691 2023-03-07 22:21:07.518 34 ERROR keystone.server.flask.application     ref = PROVIDERS.identity_api.get_user(user_id)
2023-03-07 22:21:07.525703 2023-03-07 22:21:07.518 34 ERROR keystone.server.flask.application   File "/var/lib/kolla/venv/lib/python3.9/site-packages/keystone/common/manager.py", line 115, in wrapped
2023-03-07 22:21:07.525716 2023-03-07 22:21:07.518 34 ERROR keystone.server.flask.application     __ret_val = __f(*args, **kwargs)
2023-03-07 22:21:07.525728 2023-03-07 22:21:07.518 34 ERROR keystone.server.flask.application   File "/var/lib/kolla/venv/lib/python3.9/site-packages/keystone/identity/core.py", line 414, in wrapper
2023-03-07 22:21:07.525740 2023-03-07 22:21:07.518 34 ERROR keystone.server.flask.application     return f(self, *args, **kwargs)
2023-03-07 22:21:07.525752 2023-03-07 22:21:07.518 34 ERROR keystone.server.flask.application   File "/var/lib/kolla/venv/lib/python3.9/site-packages/keystone/identity/core.py", line 424, in wrapper
2023-03-07 22:21:07.525765 2023-03-07 22:21:07.518 34 ERROR keystone.server.flask.application     return f(self, *args, **kwargs)
2023-03-07 22:21:07.525777 2023-03-07 22:21:07.518 34 ERROR keystone.server.flask.application   File "/var/lib/kolla/venv/lib/python3.9/site-packages/decorator.py", line 232, in fun
2023-03-07 22:21:07.525790 2023-03-07 22:21:07.518 34 ERROR keystone.server.flask.application     return caller(func, *(extras + args), **kw)
2023-03-07 22:21:07.525802 2023-03-07 22:21:07.518 34 ERROR keystone.server.flask.application   File "/var/lib/kolla/venv/lib/python3.9/site-packages/dogpile/cache/region.py", line 1577, in get_or_create_for_user_func
2023-03-07 22:21:07.525815 2023-03-07 22:21:07.518 34 ERROR keystone.server.flask.application     return self.get_or_create(
2023-03-07 22:21:07.525827 2023-03-07 22:21:07.518 34 ERROR keystone.server.flask.application   File "/var/lib/kolla/venv/lib/python3.9/site-packages/dogpile/cache/region.py", line 1042, in get_or_create
2023-03-07 22:21:07.525839 2023-03-07 22:21:07.518 34 ERROR keystone.server.flask.application     with Lock(
2023-03-07 22:21:07.525851 2023-03-07 22:21:07.518 34 ERROR keystone.server.flask.application   File "/var/lib/kolla/venv/lib/python3.9/site-packages/dogpile/lock.py", line 185, in __enter__
2023-03-07 22:21:07.525864 2023-03-07 22:21:07.518 34 ERROR keystone.server.flask.application     return self._enter()
2023-03-07 22:21:07.525875 2023-03-07 22:21:07.518 34 ERROR keystone.server.flask.application   File "/var/lib/kolla/venv/lib/python3.9/site-packages/dogpile/lock.py", line 94, in _enter
2023-03-07 22:21:07.525888 2023-03-07 22:21:07.518 34 ERROR keystone.server.flask.application     generated = self._enter_create(value, createdtime)
2023-03-07 22:21:07.525900 2023-03-07 22:21:07.518 34 ERROR keystone.server.flask.application   File "/var/lib/kolla/venv/lib/python3.9/site-packages/dogpile/lock.py", line 178, in _enter_create
2023-03-07 22:21:07.525925 2023-03-07 22:21:07.518 34 ERROR keystone.server.flask.application     return self.creator()
2023-03-07 22:21:07.525938 2023-03-07 22:21:07.518 34 ERROR keystone.server.flask.application   File "/var/lib/kolla/venv/lib/python3.9/site-packages/dogpile/cache/region.py", line 995, in gen_value
2023-03-07 22:21:07.525950 2023-03-07 22:21:07.518 34 ERROR keystone.server.flask.application     created_value = creator(
2023-03-07 22:21:07.525962 2023-03-07 22:21:07.518 34 ERROR keystone.server.flask.application   File "/var/lib/kolla/venv/lib/python3.9/site-packages/keystone/identity/core.py", line 1011, in get_user
2023-03-07 22:21:07.525975 2023-03-07 22:21:07.518 34 ERROR keystone.server.flask.application     ref = driver.get_user(entity_id)
2023-03-07 22:21:07.525987 2023-03-07 22:21:07.518 34 ERROR keystone.server.flask.application   File "/var/lib/kolla/venv/lib/python3.9/site-packages/keystone/identity/backends/sql.py", line 200, in get_user
2023-03-07 22:21:07.525999 2023-03-07 22:21:07.518 34 ERROR keystone.server.flask.application     self._get_user(session, user_id).to_dict())
2023-03-07 22:21:07.526011 2023-03-07 22:21:07.518 34 ERROR keystone.server.flask.application   File "/var/lib/kolla/venv/lib/python3.9/site-packages/keystone/identity/backends/sql.py", line 194, in _get_user
2023-03-07 22:21:07.526024 2023-03-07 22:21:07.518 34 ERROR keystone.server.flask.application     raise exception.UserNotFound(user_id=user_id)
2023-03-07 22:21:07.526036 2023-03-07 22:21:07.518 34 ERROR keystone.server.flask.application keystone.exception.UserNotFound: Could not find user: ironic-inspector.
2023-03-07 22:21:07.526048 2023-03-07 22:21:07.518 34 ERROR keystone.server.flask.application \x1b[00m
2023-03-07 22:21:08.442897 2023-03-07 22:21:08.439 33 ERROR keystone.server.flask.application [None req-914dcb28-480b-46b2-9210-a3b3b4da4fb8 557c326d318a409bbd94bffd97735c7e - - all default -] Could not find project: service.: keystone.exception.ProjectNotFound: Could not find project: service.
2023-03-07 22:21:08.442940 2023-03-07 22:21:08.439 33 ERROR keystone.server.flask.application Traceback (most recent call last):
2023-03-07 22:21:08.442952 2023-03-07 22:21:08.439 33 ERROR keystone.server.flask.application   File "/var/lib/kolla/venv/lib/python3.9/site-packages/flask/app.py", line 1820, in full_dispatch_request
2023-03-07 22:21:08.442962 2023-03-07 22:21:08.439 33 ERROR keystone.server.flask.application     rv = self.dispatch_request()
2023-03-07 22:21:08.442976 2023-03-07 22:21:08.439 33 ERROR keystone.server.flask.application   File "/var/lib/kolla/venv/lib/python3.9/site-packages/flask/app.py", line 1796, in dispatch_request
2023-03-07 22:21:08.442996 2023-03-07 22:21:08.439 33 ERROR keystone.server.flask.application     return self.ensure_sync(self.view_functions[rule.endpoint])(**view_args)
2023-03-07 22:21:08.443005 2023-03-07 22:21:08.439 33 ERROR keystone.server.flask.application   File "/var/lib/kolla/venv/lib/python3.9/site-packages/flask_restful/__init__.py", line 467, in wrapper
2023-03-07 22:21:08.443015 2023-03-07 22:21:08.439 33 ERROR keystone.server.flask.application     resp = resource(*args, **kwargs)
2023-03-07 22:21:08.443033 2023-03-07 22:21:08.439 33 ERROR keystone.server.flask.application   File "/var/lib/kolla/venv/lib/python3.9/site-packages/flask/views.py", line 107, in view
2023-03-07 22:21:08.443046 2023-03-07 22:21:08.439 33 ERROR keystone.server.flask.application     return current_app.ensure_sync(self.dispatch_request)(**kwargs)
2023-03-07 22:21:08.443055 2023-03-07 22:21:08.439 33 ERROR keystone.server.flask.application   File "/var/lib/kolla/venv/lib/python3.9/site-packages/flask_restful/__init__.py", line 582, in dispatch_request
2023-03-07 22:21:08.443065 2023-03-07 22:21:08.439 33 ERROR keystone.server.flask.application     resp = meth(*args, **kwargs)
2023-03-07 22:21:08.443074 2023-03-07 22:21:08.439 33 ERROR keystone.server.flask.application   File "/var/lib/kolla/venv/lib/python3.9/site-packages/keystone/api/projects.py", line 151, in get
2023-03-07 22:21:08.443108 2023-03-07 22:21:08.439 33 ERROR keystone.server.flask.application     return self._get_project(project_id)
2023-03-07 22:21:08.443120 2023-03-07 22:21:08.439 33 ERROR keystone.server.flask.application   File "/var/lib/kolla/venv/lib/python3.9/site-packages/keystone/api/projects.py", line 107, in _get_project
2023-03-07 22:21:08.443129 2023-03-07 22:21:08.439 33 ERROR keystone.server.flask.application     project = PROVIDERS.resource_api.get_project(project_id)
2023-03-07 22:21:08.443139 2023-03-07 22:21:08.439 33 ERROR keystone.server.flask.application   File "/var/lib/kolla/venv/lib/python3.9/site-packages/keystone/common/manager.py", line 115, in wrapped
2023-03-07 22:21:08.443148 2023-03-07 22:21:08.439 33 ERROR keystone.server.flask.application     __ret_val = __f(*args, **kwargs)
2023-03-07 22:21:08.443157 2023-03-07 22:21:08.439 33 ERROR keystone.server.flask.application   File "/var/lib/kolla/venv/lib/python3.9/site-packages/decorator.py", line 232, in fun
2023-03-07 22:21:08.443167 2023-03-07 22:21:08.439 33 ERROR keystone.server.flask.application     return caller(func, *(extras + args), **kw)
2023-03-07 22:21:08.443190 2023-03-07 22:21:08.439 33 ERROR keystone.server.flask.application   File "/var/lib/kolla/venv/lib/python3.9/site-packages/dogpile/cache/region.py", line 1577, in get_or_create_for_user_func
2023-03-07 22:21:08.443201 2023-03-07 22:21:08.439 33 ERROR keystone.server.flask.application     return self.get_or_create(
2023-03-07 22:21:08.443210 2023-03-07 22:21:08.439 33 ERROR keystone.server.flask.application   File "/var/lib/kolla/venv/lib/python3.9/site-packages/dogpile/cache/region.py", line 1042, in get_or_create
2023-03-07 22:21:08.443220 2023-03-07 22:21:08.439 33 ERROR keystone.server.flask.application     with Lock(
2023-03-07 22:21:08.443229 2023-03-07 22:21:08.439 33 ERROR keystone.server.flask.application   File "/var/lib/kolla/venv/lib/python3.9/site-packages/dogpile/lock.py", line 185, in __enter__
2023-03-07 22:21:08.443239 2023-03-07 22:21:08.439 33 ERROR keystone.server.flask.application     return self._enter()
2023-03-07 22:21:08.443248 2023-03-07 22:21:08.439 33 ERROR keystone.server.flask.application   File "/var/lib/kolla/venv/lib/python3.9/site-packages/dogpile/lock.py", line 94, in _enter
2023-03-07 22:21:08.443257 2023-03-07 22:21:08.439 33 ERROR keystone.server.flask.application     generated = self._enter_create(value, createdtime)
2023-03-07 22:21:08.443266 2023-03-07 22:21:08.439 33 ERROR keystone.server.flask.application   File "/var/lib/kolla/venv/lib/python3.9/site-packages/dogpile/lock.py", line 178, in _enter_create
2023-03-07 22:21:08.443276 2023-03-07 22:21:08.439 33 ERROR keystone.server.flask.application     return self.creator()
2023-03-07 22:21:08.443285 2023-03-07 22:21:08.439 33 ERROR keystone.server.flask.application   File "/var/lib/kolla/venv/lib/python3.9/site-packages/dogpile/cache/region.py", line 995, in gen_value
2023-03-07 22:21:08.443294 2023-03-07 22:21:08.439 33 ERROR keystone.server.flask.application     created_value = creator(
2023-03-07 22:21:08.443303 2023-03-07 22:21:08.439 33 ERROR keystone.server.flask.application   File "/var/lib/kolla/venv/lib/python3.9/site-packages/keystone/resource/core.py", line 903, in get_project
2023-03-07 22:21:08.443313 2023-03-07 22:21:08.439 33 ERROR keystone.server.flask.application     return self.driver.get_project(project_id)
2023-03-07 22:21:08.443322 2023-03-07 22:21:08.439 33 ERROR keystone.server.flask.application   File "/var/lib/kolla/venv/lib/python3.9/site-packages/keystone/resource/backends/sql.py", line 49, in get_project
2023-03-07 22:21:08.443332 2023-03-07 22:21:08.439 33 ERROR keystone.server.flask.application     return self._get_project(session, project_id).to_dict()
2023-03-07 22:21:08.443341 2023-03-07 22:21:08.439 33 ERROR keystone.server.flask.application   File "/var/lib/kolla/venv/lib/python3.9/site-packages/keystone/resource/backends/sql.py", line 44, in _get_project
2023-03-07 22:21:08.443383 2023-03-07 22:21:08.439 33 ERROR keystone.server.flask.application     raise exception.ProjectNotFound(project_id=project_id)
2023-03-07 22:21:08.443422 2023-03-07 22:21:08.439 33 ERROR keystone.server.flask.application keystone.exception.ProjectNotFound: Could not find project: service.
2023-03-07 22:21:08.443434 2023-03-07 22:21:08.439 33 ERROR keystone.server.flask.application \x1b[00m
2023-03-07 22:24:03.516628 2023-03-07 22:24:03.513 34 ERROR keystone.server.flask.application [None req-7ccd4de7-e6e8-46e9-ab50-20d67dc6dcba 557c326d318a409bbd94bffd97735c7e - - all default -] Could not find project: service.: keystone.exception.ProjectNotFound: Could not find project: service.
2023-03-07 22:24:03.516690 2023-03-07 22:24:03.513 34 ERROR keystone.server.flask.application Traceback (most recent call last):
2023-03-07 22:24:03.516704 2023-03-07 22:24:03.513 34 ERROR keystone.server.flask.application   File "/var/lib/kolla/venv/lib/python3.9/site-packages/flask/app.py", line 1820, in full_dispatch_request
2023-03-07 22:24:03.516715 2023-03-07 22:24:03.513 34 ERROR keystone.server.flask.application     rv = self.dispatch_request()
2023-03-07 22:24:03.516725 2023-03-07 22:24:03.513 34 ERROR keystone.server.flask.application   File "/var/lib/kolla/venv/lib/python3.9/site-packages/flask/app.py", line 1796, in dispatch_request
2023-03-07 22:24:03.516735 2023-03-07 22:24:03.513 34 ERROR keystone.server.flask.application     return self.ensure_sync(self.view_functions[rule.endpoint])(**view_args)
2023-03-07 22:24:03.516745 2023-03-07 22:24:03.513 34 ERROR keystone.server.flask.application   File "/var/lib/kolla/venv/lib/python3.9/site-packages/flask_restful/__init__.py", line 467, in wrapper
2023-03-07 22:24:03.516754 2023-03-07 22:24:03.513 34 ERROR keystone.server.flask.application     resp = resource(*args, **kwargs)
2023-03-07 22:24:03.516774 2023-03-07 22:24:03.513 34 ERROR keystone.server.flask.application   File "/var/lib/kolla/venv/lib/python3.9/site-packages/flask/views.py", line 107, in view
2023-03-07 22:24:03.516800 2023-03-07 22:24:03.513 34 ERROR keystone.server.flask.application     return current_app.ensure_sync(self.dispatch_request)(**kwargs)
2023-03-07 22:24:03.516815 2023-03-07 22:24:03.513 34 ERROR keystone.server.flask.application   File "/var/lib/kolla/venv/lib/python3.9/site-packages/flask_restful/__init__.py", line 582, in dispatch_request
2023-03-07 22:24:03.516825 2023-03-07 22:24:03.513 34 ERROR keystone.server.flask.application     resp = meth(*args, **kwargs)
2023-03-07 22:24:03.516835 2023-03-07 22:24:03.513 34 ERROR keystone.server.flask.application   File "/var/lib/kolla/venv/lib/python3.9/site-packages/keystone/api/projects.py", line 151, in get
2023-03-07 22:24:03.516846 2023-03-07 22:24:03.513 34 ERROR keystone.server.flask.application     return self._get_project(project_id)
2023-03-07 22:24:03.516856 2023-03-07 22:24:03.513 34 ERROR keystone.server.flask.application   File "/var/lib/kolla/venv/lib/python3.9/site-packages/keystone/api/projects.py", line 107, in _get_project
2023-03-07 22:24:03.516866 2023-03-07 22:24:03.513 34 ERROR keystone.server.flask.application     project = PROVIDERS.resource_api.get_project(project_id)
2023-03-07 22:24:03.516875 2023-03-07 22:24:03.513 34 ERROR keystone.server.flask.application   File "/var/lib/kolla/venv/lib/python3.9/site-packages/keystone/common/manager.py", line 115, in wrapped
2023-03-07 22:24:03.516885 2023-03-07 22:24:03.513 34 ERROR keystone.server.flask.application     __ret_val = __f(*args, **kwargs)
2023-03-07 22:24:03.516895 2023-03-07 22:24:03.513 34 ERROR keystone.server.flask.application   File "/var/lib/kolla/venv/lib/python3.9/site-packages/decorator.py", line 232, in fun
2023-03-07 22:24:03.516904 2023-03-07 22:24:03.513 34 ERROR keystone.server.flask.application     return caller(func, *(extras + args), **kw)
2023-03-07 22:24:03.516915 2023-03-07 22:24:03.513 34 ERROR keystone.server.flask.application   File "/var/lib/kolla/venv/lib/python3.9/site-packages/dogpile/cache/region.py", line 1577, in get_or_create_for_user_func
2023-03-07 22:24:03.516924 2023-03-07 22:24:03.513 34 ERROR keystone.server.flask.application     return self.get_or_create(
2023-03-07 22:24:03.516952 2023-03-07 22:24:03.513 34 ERROR keystone.server.flask.application   File "/var/lib/kolla/venv/lib/python3.9/site-packages/dogpile/cache/region.py", line 1042, in get_or_create
2023-03-07 22:24:03.516964 2023-03-07 22:24:03.513 34 ERROR keystone.server.flask.application     with Lock(
2023-03-07 22:24:03.516974 2023-03-07 22:24:03.513 34 ERROR keystone.server.flask.application   File "/var/lib/kolla/venv/lib/python3.9/site-packages/dogpile/lock.py", line 185, in __enter__
2023-03-07 22:24:03.516984 2023-03-07 22:24:03.513 34 ERROR keystone.server.flask.application     return self._enter()
2023-03-07 22:24:03.516993 2023-03-07 22:24:03.513 34 ERROR keystone.server.flask.application   File "/var/lib/kolla/venv/lib/python3.9/site-packages/dogpile/lock.py", line 94, in _enter
2023-03-07 22:24:03.517002 2023-03-07 22:24:03.513 34 ERROR keystone.server.flask.application     generated = self._enter_create(value, createdtime)
2023-03-07 22:24:03.517012 2023-03-07 22:24:03.513 34 ERROR keystone.server.flask.application   File "/var/lib/kolla/venv/lib/python3.9/site-packages/dogpile/lock.py", line 178, in _enter_create
2023-03-07 22:24:03.517021 2023-03-07 22:24:03.513 34 ERROR keystone.server.flask.application     return self.creator()
2023-03-07 22:24:03.517030 2023-03-07 22:24:03.513 34 ERROR keystone.server.flask.application   File "/var/lib/kolla/venv/lib/python3.9/site-packages/dogpile/cache/region.py", line 995, in gen_value
2023-03-07 22:24:03.517040 2023-03-07 22:24:03.513 34 ERROR keystone.server.flask.application     created_value = creator(
2023-03-07 22:24:03.517049 2023-03-07 22:24:03.513 34 ERROR keystone.server.flask.application   File "/var/lib/kolla/venv/lib/python3.9/site-packages/keystone/resource/core.py", line 903, in get_project
2023-03-07 22:24:03.517059 2023-03-07 22:24:03.513 34 ERROR keystone.server.flask.application     return self.driver.get_project(project_id)
2023-03-07 22:24:03.517068 2023-03-07 22:24:03.513 34 ERROR keystone.server.flask.application   File "/var/lib/kolla/venv/lib/python3.9/site-packages/keystone/resource/backends/sql.py", line 49, in get_project
2023-03-07 22:24:03.517078 2023-03-07 22:24:03.513 34 ERROR keystone.server.flask.application     return self._get_project(session, project_id).to_dict()
2023-03-07 22:24:03.517088 2023-03-07 22:24:03.513 34 ERROR keystone.server.flask.application   File "/var/lib/kolla/venv/lib/python3.9/site-packages/keystone/resource/backends/sql.py", line 44, in _get_project
2023-03-07 22:24:03.517098 2023-03-07 22:24:03.513 34 ERROR keystone.server.flask.application     raise exception.ProjectNotFound(project_id=project_id)
2023-03-07 22:24:03.517107 2023-03-07 22:24:03.513 34 ERROR keystone.server.flask.application keystone.exception.ProjectNotFound: Could not find project: service.
2023-03-07 22:24:03.517117 2023-03-07 22:24:03.513 34 ERROR keystone.server.flask.application \x1b[00m
2023-03-07 22:24:18.814429 2023-03-07 22:24:18.810 33 ERROR keystone.server.flask.application [None req-6349360a-25ce-4d06-81fa-2c4e25f2e044 557c326d318a409bbd94bffd97735c7e - - all default -] Could not find role: admin.: keystone.exception.RoleNotFound: Could not find role: admin.
2023-03-07 22:24:18.814481 2023-03-07 22:24:18.810 33 ERROR keystone.server.flask.application Traceback (most recent call last):
2023-03-07 22:24:18.814493 2023-03-07 22:24:18.810 33 ERROR keystone.server.flask.application   File "/var/lib/kolla/venv/lib/python3.9/site-packages/flask/app.py", line 1820, in full_dispatch_request
2023-03-07 22:24:18.814504 2023-03-07 22:24:18.810 33 ERROR keystone.server.flask.application     rv = self.dispatch_request()
2023-03-07 22:24:18.814514 2023-03-07 22:24:18.810 33 ERROR keystone.server.flask.application   File "/var/lib/kolla/venv/lib/python3.9/site-packages/flask/app.py", line 1796, in dispatch_request
2023-03-07 22:24:18.814545 2023-03-07 22:24:18.810 33 ERROR keystone.server.flask.application     return self.ensure_sync(self.view_functions[rule.endpoint])(**view_args)
2023-03-07 22:24:18.814559 2023-03-07 22:24:18.810 33 ERROR keystone.server.flask.application   File "/var/lib/kolla/venv/lib/python3.9/site-packages/flask_restful/__init__.py", line 467, in wrapper
2023-03-07 22:24:18.814601 2023-03-07 22:24:18.810 33 ERROR keystone.server.flask.application     resp = resource(*args, **kwargs)
2023-03-07 22:24:18.814612 2023-03-07 22:24:18.810 33 ERROR keystone.server.flask.application   File "/var/lib/kolla/venv/lib/python3.9/site-packages/flask/views.py", line 107, in view
2023-03-07 22:24:18.814622 2023-03-07 22:24:18.810 33 ERROR keystone.server.flask.application     return current_app.ensure_sync(self.dispatch_request)(**kwargs)
2023-03-07 22:24:18.814632 2023-03-07 22:24:18.810 33 ERROR keystone.server.flask.application   File "/var/lib/kolla/venv/lib/python3.9/site-packages/flask_restful/__init__.py", line 582, in dispatch_request
2023-03-07 22:24:18.814642 2023-03-07 22:24:18.810 33 ERROR keystone.server.flask.application     resp = meth(*args, **kwargs)
2023-03-07 22:24:18.814651 2023-03-07 22:24:18.810 33 ERROR keystone.server.flask.application   File "/var/lib/kolla/venv/lib/python3.9/site-packages/keystone/api/roles.py", line 50, in get
2023-03-07 22:24:18.814661 2023-03-07 22:24:18.810 33 ERROR keystone.server.flask.application     return self._get_role(role_id)
2023-03-07 22:24:18.814670 2023-03-07 22:24:18.810 33 ERROR keystone.server.flask.application   File "/var/lib/kolla/venv/lib/python3.9/site-packages/keystone/api/roles.py", line 70, in _get_role
2023-03-07 22:24:18.814680 2023-03-07 22:24:18.810 33 ERROR keystone.server.flask.application     ENFORCER.enforce_call(action='identity:get_role')
2023-03-07 22:24:18.814690 2023-03-07 22:24:18.810 33 ERROR keystone.server.flask.application   File "/var/lib/kolla/venv/lib/python3.9/site-packages/keystone/common/rbac_enforcer/enforcer.py", line 402, in enforce_call
2023-03-07 22:24:18.814699 2023-03-07 22:24:18.810 33 ERROR keystone.server.flask.application     policy_dict.update(cls._extract_member_target_data(
2023-03-07 22:24:18.814709 2023-03-07 22:24:18.810 33 ERROR keystone.server.flask.application   File "/var/lib/kolla/venv/lib/python3.9/site-packages/keystone/common/rbac_enforcer/enforcer.py", line 234, in _extract_member_target_data
2023-03-07 22:24:18.814727 2023-03-07 22:24:18.810 33 ERROR keystone.server.flask.application     member_name: func(flask.request.view_args[key])
2023-03-07 22:24:18.814736 2023-03-07 22:24:18.810 33 ERROR keystone.server.flask.application   File "/var/lib/kolla/venv/lib/python3.9/site-packages/keystone/common/manager.py", line 115, in wrapped
2023-03-07 22:24:18.814746 2023-03-07 22:24:18.810 33 ERROR keystone.server.flask.application     __ret_val = __f(*args, **kwargs)
2023-03-07 22:24:18.814756 2023-03-07 22:24:18.810 33 ERROR keystone.server.flask.application   File "/var/lib/kolla/venv/lib/python3.9/site-packages/decorator.py", line 232, in fun
2023-03-07 22:24:18.814766 2023-03-07 22:24:18.810 33 ERROR keystone.server.flask.application     return caller(func, *(extras + args), **kw)
2023-03-07 22:24:18.814776 2023-03-07 22:24:18.810 33 ERROR keystone.server.flask.application   File "/var/lib/kolla/venv/lib/python3.9/site-packages/dogpile/cache/region.py", line 1577, in get_or_create_for_user_func
2023-03-07 22:24:18.814786 2023-03-07 22:24:18.810 33 ERROR keystone.server.flask.application     return self.get_or_create(
2023-03-07 22:24:18.814796 2023-03-07 22:24:18.810 33 ERROR keystone.server.flask.application   File "/var/lib/kolla/venv/lib/python3.9/site-packages/dogpile/cache/region.py", line 1042, in get_or_create
2023-03-07 22:24:18.814806 2023-03-07 22:24:18.810 33 ERROR keystone.server.flask.application     with Lock(
2023-03-07 22:24:18.814815 2023-03-07 22:24:18.810 33 ERROR keystone.server.flask.application   File "/var/lib/kolla/venv/lib/python3.9/site-packages/dogpile/lock.py", line 185, in __enter__
2023-03-07 22:24:18.814825 2023-03-07 22:24:18.810 33 ERROR keystone.server.flask.application     return self._enter()
2023-03-07 22:24:18.814835 2023-03-07 22:24:18.810 33 ERROR keystone.server.flask.application   File "/var/lib/kolla/venv/lib/python3.9/site-packages/dogpile/lock.py", line 94, in _enter
2023-03-07 22:24:18.814858 2023-03-07 22:24:18.810 33 ERROR keystone.server.flask.application     generated = self._enter_create(value, createdtime)
2023-03-07 22:24:18.814869 2023-03-07 22:24:18.810 33 ERROR keystone.server.flask.application   File "/var/lib/kolla/venv/lib/python3.9/site-packages/dogpile/lock.py", line 178, in _enter_create
2023-03-07 22:24:18.814878 2023-03-07 22:24:18.810 33 ERROR keystone.server.flask.application     return self.creator()
2023-03-07 22:24:18.814888 2023-03-07 22:24:18.810 33 ERROR keystone.server.flask.application   File "/var/lib/kolla/venv/lib/python3.9/site-packages/dogpile/cache/region.py", line 995, in gen_value
2023-03-07 22:24:18.814897 2023-03-07 22:24:18.810 33 ERROR keystone.server.flask.application     created_value = creator(
2023-03-07 22:24:18.814907 2023-03-07 22:24:18.810 33 ERROR keystone.server.flask.application   File "/var/lib/kolla/venv/lib/python3.9/site-packages/keystone/assignment/core.py", line 1276, in get_role
2023-03-07 22:24:18.814916 2023-03-07 22:24:18.810 33 ERROR keystone.server.flask.application     return self.driver.get_role(role_id)
2023-03-07 22:24:18.814926 2023-03-07 22:24:18.810 33 ERROR keystone.server.flask.application   File "/var/lib/kolla/venv/lib/python3.9/site-packages/keystone/assignment/role_backends/sql.py", line 70, in get_role
2023-03-07 22:24:18.814936 2023-03-07 22:24:18.810 33 ERROR keystone.server.flask.application     return self._get_role(session, role_id).to_dict()
2023-03-07 22:24:18.814946 2023-03-07 22:24:18.810 33 ERROR keystone.server.flask.application   File "/var/lib/kolla/venv/lib/python3.9/site-packages/keystone/assignment/role_backends/sql.py", line 65, in _get_role
2023-03-07 22:24:18.814955 2023-03-07 22:24:18.810 33 ERROR keystone.server.flask.application     raise exception.RoleNotFound(role_id=role_id)
2023-03-07 22:24:18.814965 2023-03-07 22:24:18.810 33 ERROR keystone.server.flask.application keystone.exception.RoleNotFound: Could not find role: admin.
2023-03-07 22:24:18.814974 2023-03-07 22:24:18.810 33 ERROR keystone.server.flask.application \x1b[00m
2023-03-07 22:24:19.918603 2023-03-07 22:24:19.913 33 ERROR keystone.server.flask.application [None req-4d923132-a0a4-489f-8f2b-e623d33f35ec 557c326d318a409bbd94bffd97735c7e - - all default -] Could not find user: neutron.: keystone.exception.UserNotFound: Could not find user: neutron.
2023-03-07 22:24:19.918650 2023-03-07 22:24:19.913 33 ERROR keystone.server.flask.application Traceback (most recent call last):
2023-03-07 22:24:19.918661 2023-03-07 22:24:19.913 33 ERROR keystone.server.flask.application   File "/var/lib/kolla/venv/lib/python3.9/site-packages/flask/app.py", line 1820, in full_dispatch_request
2023-03-07 22:24:19.918672 2023-03-07 22:24:19.913 33 ERROR keystone.server.flask.application     rv = self.dispatch_request()
2023-03-07 22:24:19.918681 2023-03-07 22:24:19.913 33 ERROR keystone.server.flask.application   File "/var/lib/kolla/venv/lib/python3.9/site-packages/flask/app.py", line 1796, in dispatch_request
2023-03-07 22:24:19.918691 2023-03-07 22:24:19.913 33 ERROR keystone.server.flask.application     return self.ensure_sync(self.view_functions[rule.endpoint])(**view_args)
2023-03-07 22:24:19.918700 2023-03-07 22:24:19.913 33 ERROR keystone.server.flask.application   File "/var/lib/kolla/venv/lib/python3.9/site-packages/flask_restful/__init__.py", line 467, in wrapper
2023-03-07 22:24:19.918710 2023-03-07 22:24:19.913 33 ERROR keystone.server.flask.application     resp = resource(*args, **kwargs)
2023-03-07 22:24:19.918719 2023-03-07 22:24:19.913 33 ERROR keystone.server.flask.application   File "/var/lib/kolla/venv/lib/python3.9/site-packages/flask/views.py", line 107, in view
2023-03-07 22:24:19.918728 2023-03-07 22:24:19.913 33 ERROR keystone.server.flask.application     return current_app.ensure_sync(self.dispatch_request)(**kwargs)
2023-03-07 22:24:19.918738 2023-03-07 22:24:19.913 33 ERROR keystone.server.flask.application   File "/var/lib/kolla/venv/lib/python3.9/site-packages/flask_restful/__init__.py", line 582, in dispatch_request
2023-03-07 22:24:19.918785 2023-03-07 22:24:19.913 33 ERROR keystone.server.flask.application     resp = meth(*args, **kwargs)
2023-03-07 22:24:19.918796 2023-03-07 22:24:19.913 33 ERROR keystone.server.flask.application   File "/var/lib/kolla/venv/lib/python3.9/site-packages/keystone/api/users.py", line 182, in get
2023-03-07 22:24:19.918806 2023-03-07 22:24:19.913 33 ERROR keystone.server.flask.application     return self._get_user(user_id)
2023-03-07 22:24:19.918815 2023-03-07 22:24:19.913 33 ERROR keystone.server.flask.application   File "/var/lib/kolla/venv/lib/python3.9/site-packages/keystone/api/users.py", line 194, in _get_user
2023-03-07 22:24:19.918825 2023-03-07 22:24:19.913 33 ERROR keystone.server.flask.application     ref = PROVIDERS.identity_api.get_user(user_id)
2023-03-07 22:24:19.918845 2023-03-07 22:24:19.913 33 ERROR keystone.server.flask.application   File "/var/lib/kolla/venv/lib/python3.9/site-packages/keystone/common/manager.py", line 115, in wrapped
2023-03-07 22:24:19.918860 2023-03-07 22:24:19.913 33 ERROR keystone.server.flask.application     __ret_val = __f(*args, **kwargs)
2023-03-07 22:24:19.918869 2023-03-07 22:24:19.913 33 ERROR keystone.server.flask.application   File "/var/lib/kolla/venv/lib/python3.9/site-packages/keystone/identity/core.py", line 414, in wrapper
2023-03-07 22:24:19.918878 2023-03-07 22:24:19.913 33 ERROR keystone.server.flask.application     return f(self, *args, **kwargs)
2023-03-07 22:24:19.918887 2023-03-07 22:24:19.913 33 ERROR keystone.server.flask.application   File "/var/lib/kolla/venv/lib/python3.9/site-packages/keystone/identity/core.py", line 424, in wrapper
2023-03-07 22:24:19.918900 2023-03-07 22:24:19.913 33 ERROR keystone.server.flask.application     return f(self, *args, **kwargs)
2023-03-07 22:24:19.918909 2023-03-07 22:24:19.913 33 ERROR keystone.server.flask.application   File "/var/lib/kolla/venv/lib/python3.9/site-packages/decorator.py", line 232, in fun
2023-03-07 22:24:19.918918 2023-03-07 22:24:19.913 33 ERROR keystone.server.flask.application     return caller(func, *(extras + args), **kw)
2023-03-07 22:24:19.918928 2023-03-07 22:24:19.913 33 ERROR keystone.server.flask.application   File "/var/lib/kolla/venv/lib/python3.9/site-packages/dogpile/cache/region.py", line 1577, in get_or_create_for_user_func
2023-03-07 22:24:19.918939 2023-03-07 22:24:19.913 33 ERROR keystone.server.flask.application     return self.get_or_create(
2023-03-07 22:24:19.918959 2023-03-07 22:24:19.913 33 ERROR keystone.server.flask.application   File "/var/lib/kolla/venv/lib/python3.9/site-packages/dogpile/cache/region.py", line 1042, in get_or_create
2023-03-07 22:24:19.918968 2023-03-07 22:24:19.913 33 ERROR keystone.server.flask.application     with Lock(
2023-03-07 22:24:19.918978 2023-03-07 22:24:19.913 33 ERROR keystone.server.flask.application   File "/var/lib/kolla/venv/lib/python3.9/site-packages/dogpile/lock.py", line 185, in __enter__
2023-03-07 22:24:19.918987 2023-03-07 22:24:19.913 33 ERROR keystone.server.flask.application     return self._enter()
2023-03-07 22:24:19.918997 2023-03-07 22:24:19.913 33 ERROR keystone.server.flask.application   File "/var/lib/kolla/venv/lib/python3.9/site-packages/dogpile/lock.py", line 94, in _enter
2023-03-07 22:24:19.919007 2023-03-07 22:24:19.913 33 ERROR keystone.server.flask.application     generated = self._enter_create(value, createdtime)
2023-03-07 22:24:19.919016 2023-03-07 22:24:19.913 33 ERROR keystone.server.flask.application   File "/var/lib/kolla/venv/lib/python3.9/site-packages/dogpile/lock.py", line 178, in _enter_create
2023-03-07 22:24:19.919026 2023-03-07 22:24:19.913 33 ERROR keystone.server.flask.application     return self.creator()
2023-03-07 22:24:19.919035 2023-03-07 22:24:19.913 33 ERROR keystone.server.flask.application   File "/var/lib/kolla/venv/lib/python3.9/site-packages/dogpile/cache/region.py", line 995, in gen_value
2023-03-07 22:24:19.919045 2023-03-07 22:24:19.913 33 ERROR keystone.server.flask.application     created_value = creator(
2023-03-07 22:24:19.919065 2023-03-07 22:24:19.913 33 ERROR keystone.server.flask.application   File "/var/lib/kolla/venv/lib/python3.9/site-packages/keystone/identity/core.py", line 1011, in get_user
2023-03-07 22:24:19.919076 2023-03-07 22:24:19.913 33 ERROR keystone.server.flask.application     ref = driver.get_user(entity_id)
2023-03-07 22:24:19.919085 2023-03-07 22:24:19.913 33 ERROR keystone.server.flask.application   File "/var/lib/kolla/venv/lib/python3.9/site-packages/keystone/identity/backends/sql.py", line 200, in get_user
2023-03-07 22:24:19.919095 2023-03-07 22:24:19.913 33 ERROR keystone.server.flask.application     self._get_user(session, user_id).to_dict())
2023-03-07 22:24:19.919104 2023-03-07 22:24:19.913 33 ERROR keystone.server.flask.application   File "/var/lib/kolla/venv/lib/python3.9/site-packages/keystone/identity/backends/sql.py", line 194, in _get_user
2023-03-07 22:24:19.919114 2023-03-07 22:24:19.913 33 ERROR keystone.server.flask.application     raise exception.UserNotFound(user_id=user_id)
2023-03-07 22:24:19.919124 2023-03-07 22:24:19.913 33 ERROR keystone.server.flask.application keystone.exception.UserNotFound: Could not find user: neutron.
2023-03-07 22:24:19.919133 2023-03-07 22:24:19.913 33 ERROR keystone.server.flask.application \x1b[00m
2023-03-07 22:24:20.836577 2023-03-07 22:24:20.831 34 ERROR keystone.server.flask.application [None req-957b4737-50d7-4ab7-852f-9a6ff9a82f4c 557c326d318a409bbd94bffd97735c7e - - all default -] Could not find project: service.: keystone.exception.ProjectNotFound: Could not find project: service.
2023-03-07 22:24:20.836672 2023-03-07 22:24:20.831 34 ERROR keystone.server.flask.application Traceback (most recent call last):
2023-03-07 22:24:20.836684 2023-03-07 22:24:20.831 34 ERROR keystone.server.flask.application   File "/var/lib/kolla/venv/lib/python3.9/site-packages/flask/app.py", line 1820, in full_dispatch_request
2023-03-07 22:24:20.836694 2023-03-07 22:24:20.831 34 ERROR keystone.server.flask.application     rv = self.dispatch_request()
2023-03-07 22:24:20.836703 2023-03-07 22:24:20.831 34 ERROR keystone.server.flask.application   File "/var/lib/kolla/venv/lib/python3.9/site-packages/flask/app.py", line 1796, in dispatch_request
2023-03-07 22:24:20.836713 2023-03-07 22:24:20.831 34 ERROR keystone.server.flask.application     return self.ensure_sync(self.view_functions[rule.endpoint])(**view_args)
2023-03-07 22:24:20.836723 2023-03-07 22:24:20.831 34 ERROR keystone.server.flask.application   File "/var/lib/kolla/venv/lib/python3.9/site-packages/flask_restful/__init__.py", line 467, in wrapper
2023-03-07 22:24:20.836732 2023-03-07 22:24:20.831 34 ERROR keystone.server.flask.application     resp = resource(*args, **kwargs)
2023-03-07 22:24:20.836742 2023-03-07 22:24:20.831 34 ERROR keystone.server.flask.application   File "/var/lib/kolla/venv/lib/python3.9/site-packages/flask/views.py", line 107, in view
2023-03-07 22:24:20.836763 2023-03-07 22:24:20.831 34 ERROR keystone.server.flask.application     return current_app.ensure_sync(self.dispatch_request)(**kwargs)
2023-03-07 22:24:20.836776 2023-03-07 22:24:20.831 34 ERROR keystone.server.flask.application   File "/var/lib/kolla/venv/lib/python3.9/site-packages/flask_restful/__init__.py", line 582, in dispatch_request
2023-03-07 22:24:20.836786 2023-03-07 22:24:20.831 34 ERROR keystone.server.flask.application     resp = meth(*args, **kwargs)
2023-03-07 22:24:20.836795 2023-03-07 22:24:20.831 34 ERROR keystone.server.flask.application   File "/var/lib/kolla/venv/lib/python3.9/site-packages/keystone/api/projects.py", line 151, in get
2023-03-07 22:24:20.836805 2023-03-07 22:24:20.831 34 ERROR keystone.server.flask.application     return self._get_project(project_id)
2023-03-07 22:24:20.836815 2023-03-07 22:24:20.831 34 ERROR keystone.server.flask.application   File "/var/lib/kolla/venv/lib/python3.9/site-packages/keystone/api/projects.py", line 107, in _get_project
2023-03-07 22:24:20.836824 2023-03-07 22:24:20.831 34 ERROR keystone.server.flask.application     project = PROVIDERS.resource_api.get_project(project_id)
2023-03-07 22:24:20.836853 2023-03-07 22:24:20.831 34 ERROR keystone.server.flask.application   File "/var/lib/kolla/venv/lib/python3.9/site-packages/keystone/common/manager.py", line 115, in wrapped
2023-03-07 22:24:20.836865 2023-03-07 22:24:20.831 34 ERROR keystone.server.flask.application     __ret_val = __f(*args, **kwargs)
2023-03-07 22:24:20.836875 2023-03-07 22:24:20.831 34 ERROR keystone.server.flask.application   File "/var/lib/kolla/venv/lib/python3.9/site-packages/decorator.py", line 232, in fun
2023-03-07 22:24:20.836884 2023-03-07 22:24:20.831 34 ERROR keystone.server.flask.application     return caller(func, *(extras + args), **kw)
2023-03-07 22:24:20.836894 2023-03-07 22:24:20.831 34 ERROR keystone.server.flask.application   File "/var/lib/kolla/venv/lib/python3.9/site-packages/dogpile/cache/region.py", line 1577, in get_or_create_for_user_func
2023-03-07 22:24:20.836904 2023-03-07 22:24:20.831 34 ERROR keystone.server.flask.application     return self.get_or_create(
2023-03-07 22:24:20.836914 2023-03-07 22:24:20.831 34 ERROR keystone.server.flask.application   File "/var/lib/kolla/venv/lib/python3.9/site-packages/dogpile/cache/region.py", line 1042, in get_or_create
2023-03-07 22:24:20.836924 2023-03-07 22:24:20.831 34 ERROR keystone.server.flask.application     with Lock(
2023-03-07 22:24:20.836933 2023-03-07 22:24:20.831 34 ERROR keystone.server.flask.application   File "/var/lib/kolla/venv/lib/python3.9/site-packages/dogpile/lock.py", line 185, in __enter__
2023-03-07 22:24:20.836943 2023-03-07 22:24:20.831 34 ERROR keystone.server.flask.application     return self._enter()
2023-03-07 22:24:20.836958 2023-03-07 22:24:20.831 34 ERROR keystone.server.flask.application   File "/var/lib/kolla/venv/lib/python3.9/site-packages/dogpile/lock.py", line 94, in _enter
2023-03-07 22:24:20.836968 2023-03-07 22:24:20.831 34 ERROR keystone.server.flask.application     generated = self._enter_create(value, createdtime)
2023-03-07 22:24:20.836978 2023-03-07 22:24:20.831 34 ERROR keystone.server.flask.application   File "/var/lib/kolla/venv/lib/python3.9/site-packages/dogpile/lock.py", line 178, in _enter_create
2023-03-07 22:24:20.836987 2023-03-07 22:24:20.831 34 ERROR keystone.server.flask.application     return self.creator()
2023-03-07 22:24:20.836997 2023-03-07 22:24:20.831 34 ERROR keystone.server.flask.application   File "/var/lib/kolla/venv/lib/python3.9/site-packages/dogpile/cache/region.py", line 995, in gen_value
2023-03-07 22:24:20.837006 2023-03-07 22:24:20.831 34 ERROR keystone.server.flask.application     created_value = creator(
2023-03-07 22:24:20.837016 2023-03-07 22:24:20.831 34 ERROR keystone.server.flask.application   File "/var/lib/kolla/venv/lib/python3.9/site-packages/keystone/resource/core.py", line 903, in get_project
2023-03-07 22:24:20.837026 2023-03-07 22:24:20.831 34 ERROR keystone.server.flask.application     return self.driver.get_project(project_id)
2023-03-07 22:24:20.837035 2023-03-07 22:24:20.831 34 ERROR keystone.server.flask.application   File "/var/lib/kolla/venv/lib/python3.9/site-packages/keystone/resource/backends/sql.py", line 49, in get_project
2023-03-07 22:24:20.837045 2023-03-07 22:24:20.831 34 ERROR keystone.server.flask.application     return self._get_project(session, project_id).to_dict()
2023-03-07 22:24:20.837055 2023-03-07 22:24:20.831 34 ERROR keystone.server.flask.application   File "/var/lib/kolla/venv/lib/python3.9/site-packages/keystone/resource/backends/sql.py", line 44, in _get_project
2023-03-07 22:24:20.837065 2023-03-07 22:24:20.831 34 ERROR keystone.server.flask.application     raise exception.ProjectNotFound(project_id=project_id)
2023-03-07 22:24:20.837075 2023-03-07 22:24:20.831 34 ERROR keystone.server.flask.application keystone.exception.ProjectNotFound: Could not find project: service.
2023-03-07 22:24:20.837084 2023-03-07 22:24:20.831 34 ERROR keystone.server.flask.application \x1b[00m
2023-03-08 02:19:02.669228 2023-03-08 02:19:02.666 33 WARNING py.warnings [None req-f805e227-1482-41a7-95c4-f9fe93218c23 557c326d318a409bbd94bffd97735c7e 473a45be84e544139bf85d4e66c6b1be - - default default] /var/lib/kolla/venv/lib/python3.9/site-packages/oslo_policy/policy.py:1129: UserWarning: Policy "identity:list_domains": "role:reader and system_scope:all" failed scope check. The token used to make the request was project scoped but the policy requires ['system'] scope. This behavior may change in the future where using the intended scope is required
2023-03-08 02:19:02.669392   warnings.warn(msg)
2023-03-08 02:19:02.669410 \x1b[00m
2023-03-08 02:19:02.955565 2023-03-08 02:19:02.952 34 WARNING py.warnings [None req-e32d5945-d9cb-47c2-9f1e-a386c62b7655 557c326d318a409bbd94bffd97735c7e 473a45be84e544139bf85d4e66c6b1be - - default default] /var/lib/kolla/venv/lib/python3.9/site-packages/oslo_policy/policy.py:1129: UserWarning: Policy "identity:create_project": "(role:admin and system_scope:all) or (role:admin and domain_id:%(target.project.domain_id)s)" failed scope check. The token used to make the request was project scoped but the policy requires ['system', 'domain'] scope. This behavior may change in the future where using the intended scope is required
2023-03-08 02:19:02.955653   warnings.warn(msg)
2023-03-08 02:19:02.955675 \x1b[00m
2023-03-08 02:19:03.225308 2023-03-08 02:19:03.223 32 WARNING py.warnings [None req-4bd6a197-42df-40ac-bcb4-4cae7559c138 557c326d318a409bbd94bffd97735c7e 473a45be84e544139bf85d4e66c6b1be - - default default] /var/lib/kolla/venv/lib/python3.9/site-packages/oslo_policy/policy.py:1129: UserWarning: Policy "identity:create_user": "(role:admin and system_scope:all) or (role:admin and token.domain.id:%(target.user.domain_id)s)" failed scope check. The token used to make the request was project scoped but the policy requires ['system', 'domain'] scope. This behavior may change in the future where using the intended scope is required
2023-03-08 02:19:03.225415   warnings.warn(msg)
2023-03-08 02:19:03.225433 \x1b[00m
2023-03-08 02:19:04.023299 2023-03-08 02:19:04.022 33 WARNING py.warnings [None req-7892874d-f863-4cd8-ba52-7c6967f262da 557c326d318a409bbd94bffd97735c7e 473a45be84e544139bf85d4e66c6b1be - - default default] /var/lib/kolla/venv/lib/python3.9/site-packages/oslo_policy/policy.py:1129: UserWarning: Policy "identity:list_roles": "role:reader and system_scope:all" failed scope check. The token used to make the request was project scoped but the policy requires ['system'] scope. This behavior may change in the future where using the intended scope is required
2023-03-08 02:19:04.023347   warnings.warn(msg)
2023-03-08 02:19:04.023391 \x1b[00m
2023-03-08 02:19:04.358291 2023-03-08 02:19:04.357 34 WARNING py.warnings [None req-2e1053fe-6f0c-4b28-a9b9-353658e03f32 557c326d318a409bbd94bffd97735c7e 473a45be84e544139bf85d4e66c6b1be - - default default] /var/lib/kolla/venv/lib/python3.9/site-packages/oslo_policy/policy.py:1129: UserWarning: Policy "identity:create_grant": "(role:admin and system_scope:all) or ((role:admin and domain_id:%(target.user.domain_id)s and domain_id:%(target.project.domain_id)s) or (role:admin and domain_id:%(target.user.domain_id)s and domain_id:%(target.domain.id)s) or (role:admin and domain_id:%(target.group.domain_id)s and domain_id:%(target.project.domain_id)s) or (role:admin and domain_id:%(target.group.domain_id)s and domain_id:%(target.domain.id)s)) and (domain_id:%(target.role.domain_id)s or None:%(target.role.domain_id)s)" failed scope check. The token used to make the request was project scoped but the policy requires ['system', 'domain'] scope. This behavior may change in the future where using the intended scope is required
2023-03-08 02:19:04.358336   warnings.warn(msg)
2023-03-08 02:19:04.358347 \x1b[00m
2023-03-08 02:19:05.519647 2023-03-08 02:19:05.518 33 WARNING py.warnings [None req-90322359-3e0c-4f48-b263-a1813d4ba6c1 557c326d318a409bbd94bffd97735c7e 473a45be84e544139bf85d4e66c6b1be - - default default] /var/lib/kolla/venv/lib/python3.9/site-packages/oslo_policy/policy.py:1129: UserWarning: Policy "identity:create_project": "(role:admin and system_scope:all) or (role:admin and domain_id:%(target.project.domain_id)s)" failed scope check. The token used to make the request was project scoped but the policy requires ['system', 'domain'] scope. This behavior may change in the future where using the intended scope is required
2023-03-08 02:19:05.519726   warnings.warn(msg)
2023-03-08 02:19:05.519739 \x1b[00m
2023-03-08 02:19:05.942047 2023-03-08 02:19:05.941 34 WARNING py.warnings [None req-5d6681f8-3f82-4ce4-bb16-1c7cf978dd25 557c326d318a409bbd94bffd97735c7e 473a45be84e544139bf85d4e66c6b1be - - default default] /var/lib/kolla/venv/lib/python3.9/site-packages/oslo_policy/policy.py:1129: UserWarning: Policy "identity:create_user": "(role:admin and system_scope:all) or (role:admin and token.domain.id:%(target.user.domain_id)s)" failed scope check. The token used to make the request was project scoped but the policy requires ['system', 'domain'] scope. This behavior may change in the future where using the intended scope is required
2023-03-08 02:19:05.942098   warnings.warn(msg)
2023-03-08 02:19:05.942109 \x1b[00m
2023-03-08 02:19:06.855682 2023-03-08 02:19:06.854 32 WARNING py.warnings [None req-b506b574-f540-4344-8c11-0dd3424f9723 557c326d318a409bbd94bffd97735c7e 473a45be84e544139bf85d4e66c6b1be - - default default] /var/lib/kolla/venv/lib/python3.9/site-packages/oslo_policy/policy.py:1129: UserWarning: Policy "identity:list_roles": "role:reader and system_scope:all" failed scope check. The token used to make the request was project scoped but the policy requires ['system'] scope. This behavior may change in the future where using the intended scope is required
2023-03-08 02:19:06.855729   warnings.warn(msg)
2023-03-08 02:19:06.855741 \x1b[00m
2023-03-08 02:19:07.187650 2023-03-08 02:19:07.186 33 WARNING py.warnings [None req-93e06bf9-2396-43de-95e9-08a732471631 557c326d318a409bbd94bffd97735c7e 473a45be84e544139bf85d4e66c6b1be - - default default] /var/lib/kolla/venv/lib/python3.9/site-packages/oslo_policy/policy.py:1129: UserWarning: Policy "identity:create_grant": "(role:admin and system_scope:all) or ((role:admin and domain_id:%(target.user.domain_id)s and domain_id:%(target.project.domain_id)s) or (role:admin and domain_id:%(target.user.domain_id)s and domain_id:%(target.domain.id)s) or (role:admin and domain_id:%(target.group.domain_id)s and domain_id:%(target.project.domain_id)s) or (role:admin and domain_id:%(target.group.domain_id)s and domain_id:%(target.domain.id)s)) and (domain_id:%(target.role.domain_id)s or None:%(target.role.domain_id)s)" failed scope check. The token used to make the request was project scoped but the policy requires ['system', 'domain'] scope. This behavior may change in the future where using the intended scope is required
2023-03-08 02:19:07.187695   warnings.warn(msg)
2023-03-08 02:19:07.187706 \x1b[00m
2023-03-08 02:19:09.290787 2023-03-08 02:19:09.289 33 WARNING py.warnings [None req-fe9ee8be-c468-4246-a873-5fc2e7c60744 557c326d318a409bbd94bffd97735c7e 473a45be84e544139bf85d4e66c6b1be - - default default] /var/lib/kolla/venv/lib/python3.9/site-packages/oslo_policy/policy.py:1129: UserWarning: Policy "identity:create_user": "(role:admin and system_scope:all) or (role:admin and token.domain.id:%(target.user.domain_id)s)" failed scope check. The token used to make the request was project scoped but the policy requires ['system', 'domain'] scope. This behavior may change in the future where using the intended scope is required
2023-03-08 02:19:09.290838   warnings.warn(msg)
2023-03-08 02:19:09.290850 \x1b[00m
2023-03-08 02:19:10.671162 2023-03-08 02:19:10.669 34 WARNING py.warnings [None req-62d18f48-b289-4942-b4cd-b0878c603e3f 557c326d318a409bbd94bffd97735c7e 473a45be84e544139bf85d4e66c6b1be - - default default] /var/lib/kolla/venv/lib/python3.9/site-packages/oslo_policy/policy.py:1129: UserWarning: Policy "identity:create_system_grant_for_user": "role:admin and system_scope:all" failed scope check. The token used to make the request was project scoped but the policy requires ['system'] scope. This behavior may change in the future where using the intended scope is required
2023-03-08 02:19:10.671254   warnings.warn(msg)
2023-03-08 02:19:10.671267 \x1b[00m
