2023-03-06 21:03:19.822924 2023-03-06 21:03:19.819 40 WARNING keystone.common.rbac_enforcer.enforcer [None req-078a96ca-80a3-4346-9e39-7de4b0899aac 0ec98a772fae4111a46b99e8bc573150 - - all default -] Deprecated policy rules found. Use oslopolicy-policy-generator and oslopolicy-policy-upgrade to detect and resolve deprecated policies in your configuration.\x1b[00m
2023-03-06 21:03:20.782706 2023-03-06 21:03:20.780 39 WARNING keystone.common.rbac_enforcer.enforcer [None req-896ab2cb-6c2c-4a69-9790-04501a21d81d 0ec98a772fae4111a46b99e8bc573150 - - all default -] Deprecated policy rules found. Use oslopolicy-policy-generator and oslopolicy-policy-upgrade to detect and resolve deprecated policies in your configuration.\x1b[00m
2023-03-06 21:03:28.832532 2023-03-06 21:03:28.830 38 WARNING keystone.common.rbac_enforcer.enforcer [None req-35f84d8f-0e58-472f-a72d-d963dbb91d8c 0ec98a772fae4111a46b99e8bc573150 - - all default -] Deprecated policy rules found. Use oslopolicy-policy-generator and oslopolicy-policy-upgrade to detect and resolve deprecated policies in your configuration.\x1b[00m
2023-03-06 21:04:51.508057 2023-03-06 21:04:51.494 38 ERROR keystone.server.flask.application [None req-8dd97881-0e7a-4c5a-a338-8034085d38d7 0ec98a772fae4111a46b99e8bc573150 - - all default -] Could not find project: service.: keystone.exception.ProjectNotFound: Could not find project: service.
2023-03-06 21:04:51.508121 2023-03-06 21:04:51.494 38 ERROR keystone.server.flask.application Traceback (most recent call last):
2023-03-06 21:04:51.508134 2023-03-06 21:04:51.494 38 ERROR keystone.server.flask.application   File "/var/lib/kolla/venv/lib/python3.9/site-packages/flask/app.py", line 1820, in full_dispatch_request
2023-03-06 21:04:51.508145 2023-03-06 21:04:51.494 38 ERROR keystone.server.flask.application     rv = self.dispatch_request()
2023-03-06 21:04:51.508154 2023-03-06 21:04:51.494 38 ERROR keystone.server.flask.application   File "/var/lib/kolla/venv/lib/python3.9/site-packages/flask/app.py", line 1796, in dispatch_request
2023-03-06 21:04:51.508165 2023-03-06 21:04:51.494 38 ERROR keystone.server.flask.application     return self.ensure_sync(self.view_functions[rule.endpoint])(**view_args)
2023-03-06 21:04:51.508175 2023-03-06 21:04:51.494 38 ERROR keystone.server.flask.application   File "/var/lib/kolla/venv/lib/python3.9/site-packages/flask_restful/__init__.py", line 467, in wrapper
2023-03-06 21:04:51.508184 2023-03-06 21:04:51.494 38 ERROR keystone.server.flask.application     resp = resource(*args, **kwargs)
2023-03-06 21:04:51.508194 2023-03-06 21:04:51.494 38 ERROR keystone.server.flask.application   File "/var/lib/kolla/venv/lib/python3.9/site-packages/flask/views.py", line 107, in view
2023-03-06 21:04:51.508314 2023-03-06 21:04:51.494 38 ERROR keystone.server.flask.application     return current_app.ensure_sync(self.dispatch_request)(**kwargs)
2023-03-06 21:04:51.508325 2023-03-06 21:04:51.494 38 ERROR keystone.server.flask.application   File "/var/lib/kolla/venv/lib/python3.9/site-packages/flask_restful/__init__.py", line 582, in dispatch_request
2023-03-06 21:04:51.508335 2023-03-06 21:04:51.494 38 ERROR keystone.server.flask.application     resp = meth(*args, **kwargs)
2023-03-06 21:04:51.508344 2023-03-06 21:04:51.494 38 ERROR keystone.server.flask.application   File "/var/lib/kolla/venv/lib/python3.9/site-packages/keystone/api/projects.py", line 151, in get
2023-03-06 21:04:51.508355 2023-03-06 21:04:51.494 38 ERROR keystone.server.flask.application     return self._get_project(project_id)
2023-03-06 21:04:51.508364 2023-03-06 21:04:51.494 38 ERROR keystone.server.flask.application   File "/var/lib/kolla/venv/lib/python3.9/site-packages/keystone/api/projects.py", line 107, in _get_project
2023-03-06 21:04:51.508374 2023-03-06 21:04:51.494 38 ERROR keystone.server.flask.application     project = PROVIDERS.resource_api.get_project(project_id)
2023-03-06 21:04:51.508383 2023-03-06 21:04:51.494 38 ERROR keystone.server.flask.application   File "/var/lib/kolla/venv/lib/python3.9/site-packages/keystone/common/manager.py", line 115, in wrapped
2023-03-06 21:04:51.508421 2023-03-06 21:04:51.494 38 ERROR keystone.server.flask.application     __ret_val = __f(*args, **kwargs)
2023-03-06 21:04:51.508433 2023-03-06 21:04:51.494 38 ERROR keystone.server.flask.application   File "/var/lib/kolla/venv/lib/python3.9/site-packages/decorator.py", line 232, in fun
2023-03-06 21:04:51.508443 2023-03-06 21:04:51.494 38 ERROR keystone.server.flask.application     return caller(func, *(extras + args), **kw)
2023-03-06 21:04:51.508453 2023-03-06 21:04:51.494 38 ERROR keystone.server.flask.application   File "/var/lib/kolla/venv/lib/python3.9/site-packages/dogpile/cache/region.py", line 1577, in get_or_create_for_user_func
2023-03-06 21:04:51.508463 2023-03-06 21:04:51.494 38 ERROR keystone.server.flask.application     return self.get_or_create(
2023-03-06 21:04:51.508473 2023-03-06 21:04:51.494 38 ERROR keystone.server.flask.application   File "/var/lib/kolla/venv/lib/python3.9/site-packages/dogpile/cache/region.py", line 1042, in get_or_create
2023-03-06 21:04:51.508489 2023-03-06 21:04:51.494 38 ERROR keystone.server.flask.application     with Lock(
2023-03-06 21:04:51.508499 2023-03-06 21:04:51.494 38 ERROR keystone.server.flask.application   File "/var/lib/kolla/venv/lib/python3.9/site-packages/dogpile/lock.py", line 185, in __enter__
2023-03-06 21:04:51.508509 2023-03-06 21:04:51.494 38 ERROR keystone.server.flask.application     return self._enter()
2023-03-06 21:04:51.508518 2023-03-06 21:04:51.494 38 ERROR keystone.server.flask.application   File "/var/lib/kolla/venv/lib/python3.9/site-packages/dogpile/lock.py", line 94, in _enter
2023-03-06 21:04:51.508528 2023-03-06 21:04:51.494 38 ERROR keystone.server.flask.application     generated = self._enter_create(value, createdtime)
2023-03-06 21:04:51.508538 2023-03-06 21:04:51.494 38 ERROR keystone.server.flask.application   File "/var/lib/kolla/venv/lib/python3.9/site-packages/dogpile/lock.py", line 178, in _enter_create
2023-03-06 21:04:51.508548 2023-03-06 21:04:51.494 38 ERROR keystone.server.flask.application     return self.creator()
2023-03-06 21:04:51.508557 2023-03-06 21:04:51.494 38 ERROR keystone.server.flask.application   File "/var/lib/kolla/venv/lib/python3.9/site-packages/dogpile/cache/region.py", line 995, in gen_value
2023-03-06 21:04:51.508567 2023-03-06 21:04:51.494 38 ERROR keystone.server.flask.application     created_value = creator(
2023-03-06 21:04:51.508577 2023-03-06 21:04:51.494 38 ERROR keystone.server.flask.application   File "/var/lib/kolla/venv/lib/python3.9/site-packages/keystone/resource/core.py", line 903, in get_project
2023-03-06 21:04:51.508586 2023-03-06 21:04:51.494 38 ERROR keystone.server.flask.application     return self.driver.get_project(project_id)
2023-03-06 21:04:51.508596 2023-03-06 21:04:51.494 38 ERROR keystone.server.flask.application   File "/var/lib/kolla/venv/lib/python3.9/site-packages/keystone/resource/backends/sql.py", line 49, in get_project
2023-03-06 21:04:51.508606 2023-03-06 21:04:51.494 38 ERROR keystone.server.flask.application     return self._get_project(session, project_id).to_dict()
2023-03-06 21:04:51.508616 2023-03-06 21:04:51.494 38 ERROR keystone.server.flask.application   File "/var/lib/kolla/venv/lib/python3.9/site-packages/keystone/resource/backends/sql.py", line 44, in _get_project
2023-03-06 21:04:51.508629 2023-03-06 21:04:51.494 38 ERROR keystone.server.flask.application     raise exception.ProjectNotFound(project_id=project_id)
2023-03-06 21:04:51.508639 2023-03-06 21:04:51.494 38 ERROR keystone.server.flask.application keystone.exception.ProjectNotFound: Could not find project: service.
2023-03-06 21:04:51.508649 2023-03-06 21:04:51.494 38 ERROR keystone.server.flask.application \x1b[00m
2023-03-06 21:05:01.133307 2023-03-06 21:05:01.120 39 ERROR keystone.server.flask.application [None req-b886d46f-99c4-4658-ad87-3639088a78d0 0ec98a772fae4111a46b99e8bc573150 - - all default -] Could not find project: service.: keystone.exception.ProjectNotFound: Could not find project: service.
2023-03-06 21:05:01.133366 2023-03-06 21:05:01.120 39 ERROR keystone.server.flask.application Traceback (most recent call last):
2023-03-06 21:05:01.133394 2023-03-06 21:05:01.120 39 ERROR keystone.server.flask.application   File "/var/lib/kolla/venv/lib/python3.9/site-packages/flask/app.py", line 1820, in full_dispatch_request
2023-03-06 21:05:01.133408 2023-03-06 21:05:01.120 39 ERROR keystone.server.flask.application     rv = self.dispatch_request()
2023-03-06 21:05:01.133417 2023-03-06 21:05:01.120 39 ERROR keystone.server.flask.application   File "/var/lib/kolla/venv/lib/python3.9/site-packages/flask/app.py", line 1796, in dispatch_request
2023-03-06 21:05:01.133428 2023-03-06 21:05:01.120 39 ERROR keystone.server.flask.application     return self.ensure_sync(self.view_functions[rule.endpoint])(**view_args)
2023-03-06 21:05:01.133437 2023-03-06 21:05:01.120 39 ERROR keystone.server.flask.application   File "/var/lib/kolla/venv/lib/python3.9/site-packages/flask_restful/__init__.py", line 467, in wrapper
2023-03-06 21:05:01.133447 2023-03-06 21:05:01.120 39 ERROR keystone.server.flask.application     resp = resource(*args, **kwargs)
2023-03-06 21:05:01.133471 2023-03-06 21:05:01.120 39 ERROR keystone.server.flask.application   File "/var/lib/kolla/venv/lib/python3.9/site-packages/flask/views.py", line 107, in view
2023-03-06 21:05:01.133484 2023-03-06 21:05:01.120 39 ERROR keystone.server.flask.application     return current_app.ensure_sync(self.dispatch_request)(**kwargs)
2023-03-06 21:05:01.133493 2023-03-06 21:05:01.120 39 ERROR keystone.server.flask.application   File "/var/lib/kolla/venv/lib/python3.9/site-packages/flask_restful/__init__.py", line 582, in dispatch_request
2023-03-06 21:05:01.133503 2023-03-06 21:05:01.120 39 ERROR keystone.server.flask.application     resp = meth(*args, **kwargs)
2023-03-06 21:05:01.133512 2023-03-06 21:05:01.120 39 ERROR keystone.server.flask.application   File "/var/lib/kolla/venv/lib/python3.9/site-packages/keystone/api/projects.py", line 151, in get
2023-03-06 21:05:01.133522 2023-03-06 21:05:01.120 39 ERROR keystone.server.flask.application     return self._get_project(project_id)
2023-03-06 21:05:01.133532 2023-03-06 21:05:01.120 39 ERROR keystone.server.flask.application   File "/var/lib/kolla/venv/lib/python3.9/site-packages/keystone/api/projects.py", line 107, in _get_project
2023-03-06 21:05:01.133541 2023-03-06 21:05:01.120 39 ERROR keystone.server.flask.application     project = PROVIDERS.resource_api.get_project(project_id)
2023-03-06 21:05:01.133551 2023-03-06 21:05:01.120 39 ERROR keystone.server.flask.application   File "/var/lib/kolla/venv/lib/python3.9/site-packages/keystone/common/manager.py", line 115, in wrapped
2023-03-06 21:05:01.133560 2023-03-06 21:05:01.120 39 ERROR keystone.server.flask.application     __ret_val = __f(*args, **kwargs)
2023-03-06 21:05:01.133570 2023-03-06 21:05:01.120 39 ERROR keystone.server.flask.application   File "/var/lib/kolla/venv/lib/python3.9/site-packages/decorator.py", line 232, in fun
2023-03-06 21:05:01.133579 2023-03-06 21:05:01.120 39 ERROR keystone.server.flask.application     return caller(func, *(extras + args), **kw)
2023-03-06 21:05:01.133596 2023-03-06 21:05:01.120 39 ERROR keystone.server.flask.application   File "/var/lib/kolla/venv/lib/python3.9/site-packages/dogpile/cache/region.py", line 1577, in get_or_create_for_user_func
2023-03-06 21:05:01.133608 2023-03-06 21:05:01.120 39 ERROR keystone.server.flask.application     return self.get_or_create(
2023-03-06 21:05:01.133618 2023-03-06 21:05:01.120 39 ERROR keystone.server.flask.application   File "/var/lib/kolla/venv/lib/python3.9/site-packages/dogpile/cache/region.py", line 1042, in get_or_create
2023-03-06 21:05:01.133628 2023-03-06 21:05:01.120 39 ERROR keystone.server.flask.application     with Lock(
2023-03-06 21:05:01.133637 2023-03-06 21:05:01.120 39 ERROR keystone.server.flask.application   File "/var/lib/kolla/venv/lib/python3.9/site-packages/dogpile/lock.py", line 185, in __enter__
2023-03-06 21:05:01.133647 2023-03-06 21:05:01.120 39 ERROR keystone.server.flask.application     return self._enter()
2023-03-06 21:05:01.133668 2023-03-06 21:05:01.120 39 ERROR keystone.server.flask.application   File "/var/lib/kolla/venv/lib/python3.9/site-packages/dogpile/lock.py", line 94, in _enter
2023-03-06 21:05:01.133679 2023-03-06 21:05:01.120 39 ERROR keystone.server.flask.application     generated = self._enter_create(value, createdtime)
2023-03-06 21:05:01.133688 2023-03-06 21:05:01.120 39 ERROR keystone.server.flask.application   File "/var/lib/kolla/venv/lib/python3.9/site-packages/dogpile/lock.py", line 178, in _enter_create
2023-03-06 21:05:01.133879 2023-03-06 21:05:01.120 39 ERROR keystone.server.flask.application     return self.creator()
2023-03-06 21:05:01.133894 2023-03-06 21:05:01.120 39 ERROR keystone.server.flask.application   File "/var/lib/kolla/venv/lib/python3.9/site-packages/dogpile/cache/region.py", line 995, in gen_value
2023-03-06 21:05:01.133904 2023-03-06 21:05:01.120 39 ERROR keystone.server.flask.application     created_value = creator(
2023-03-06 21:05:01.133913 2023-03-06 21:05:01.120 39 ERROR keystone.server.flask.application   File "/var/lib/kolla/venv/lib/python3.9/site-packages/keystone/resource/core.py", line 903, in get_project
2023-03-06 21:05:01.133923 2023-03-06 21:05:01.120 39 ERROR keystone.server.flask.application     return self.driver.get_project(project_id)
2023-03-06 21:05:01.133933 2023-03-06 21:05:01.120 39 ERROR keystone.server.flask.application   File "/var/lib/kolla/venv/lib/python3.9/site-packages/keystone/resource/backends/sql.py", line 49, in get_project
2023-03-06 21:05:01.133942 2023-03-06 21:05:01.120 39 ERROR keystone.server.flask.application     return self._get_project(session, project_id).to_dict()
2023-03-06 21:05:01.133952 2023-03-06 21:05:01.120 39 ERROR keystone.server.flask.application   File "/var/lib/kolla/venv/lib/python3.9/site-packages/keystone/resource/backends/sql.py", line 44, in _get_project
2023-03-06 21:05:01.133962 2023-03-06 21:05:01.120 39 ERROR keystone.server.flask.application     raise exception.ProjectNotFound(project_id=project_id)
2023-03-06 21:05:01.133971 2023-03-06 21:05:01.120 39 ERROR keystone.server.flask.application keystone.exception.ProjectNotFound: Could not find project: service.
2023-03-06 21:05:01.133980 2023-03-06 21:05:01.120 39 ERROR keystone.server.flask.application \x1b[00m
2023-03-06 21:05:16.564760 2023-03-06 21:05:16.548 39 ERROR keystone.server.flask.application [None req-3143ed9b-ec7f-4321-857c-5be52136da63 0ec98a772fae4111a46b99e8bc573150 - - all default -] Could not find role: admin.: keystone.exception.RoleNotFound: Could not find role: admin.
2023-03-06 21:05:16.564840 2023-03-06 21:05:16.548 39 ERROR keystone.server.flask.application Traceback (most recent call last):
2023-03-06 21:05:16.564853 2023-03-06 21:05:16.548 39 ERROR keystone.server.flask.application   File "/var/lib/kolla/venv/lib/python3.9/site-packages/flask/app.py", line 1820, in full_dispatch_request
2023-03-06 21:05:16.564863 2023-03-06 21:05:16.548 39 ERROR keystone.server.flask.application     rv = self.dispatch_request()
2023-03-06 21:05:16.564872 2023-03-06 21:05:16.548 39 ERROR keystone.server.flask.application   File "/var/lib/kolla/venv/lib/python3.9/site-packages/flask/app.py", line 1796, in dispatch_request
2023-03-06 21:05:16.564882 2023-03-06 21:05:16.548 39 ERROR keystone.server.flask.application     return self.ensure_sync(self.view_functions[rule.endpoint])(**view_args)
2023-03-06 21:05:16.564892 2023-03-06 21:05:16.548 39 ERROR keystone.server.flask.application   File "/var/lib/kolla/venv/lib/python3.9/site-packages/flask_restful/__init__.py", line 467, in wrapper
2023-03-06 21:05:16.564902 2023-03-06 21:05:16.548 39 ERROR keystone.server.flask.application     resp = resource(*args, **kwargs)
2023-03-06 21:05:16.564918 2023-03-06 21:05:16.548 39 ERROR keystone.server.flask.application   File "/var/lib/kolla/venv/lib/python3.9/site-packages/flask/views.py", line 107, in view
2023-03-06 21:05:16.564931 2023-03-06 21:05:16.548 39 ERROR keystone.server.flask.application     return current_app.ensure_sync(self.dispatch_request)(**kwargs)
2023-03-06 21:05:16.564941 2023-03-06 21:05:16.548 39 ERROR keystone.server.flask.application   File "/var/lib/kolla/venv/lib/python3.9/site-packages/flask_restful/__init__.py", line 582, in dispatch_request
2023-03-06 21:05:16.564987 2023-03-06 21:05:16.548 39 ERROR keystone.server.flask.application     resp = meth(*args, **kwargs)
2023-03-06 21:05:16.564999 2023-03-06 21:05:16.548 39 ERROR keystone.server.flask.application   File "/var/lib/kolla/venv/lib/python3.9/site-packages/keystone/api/roles.py", line 50, in get
2023-03-06 21:05:16.565008 2023-03-06 21:05:16.548 39 ERROR keystone.server.flask.application     return self._get_role(role_id)
2023-03-06 21:05:16.565018 2023-03-06 21:05:16.548 39 ERROR keystone.server.flask.application   File "/var/lib/kolla/venv/lib/python3.9/site-packages/keystone/api/roles.py", line 70, in _get_role
2023-03-06 21:05:16.565031 2023-03-06 21:05:16.548 39 ERROR keystone.server.flask.application     ENFORCER.enforce_call(action='identity:get_role')
2023-03-06 21:05:16.565047 2023-03-06 21:05:16.548 39 ERROR keystone.server.flask.application   File "/var/lib/kolla/venv/lib/python3.9/site-packages/keystone/common/rbac_enforcer/enforcer.py", line 402, in enforce_call
2023-03-06 21:05:16.565059 2023-03-06 21:05:16.548 39 ERROR keystone.server.flask.application     policy_dict.update(cls._extract_member_target_data(
2023-03-06 21:05:16.565076 2023-03-06 21:05:16.548 39 ERROR keystone.server.flask.application   File "/var/lib/kolla/venv/lib/python3.9/site-packages/keystone/common/rbac_enforcer/enforcer.py", line 234, in _extract_member_target_data
2023-03-06 21:05:16.565088 2023-03-06 21:05:16.548 39 ERROR keystone.server.flask.application     member_name: func(flask.request.view_args[key])
2023-03-06 21:05:16.565098 2023-03-06 21:05:16.548 39 ERROR keystone.server.flask.application   File "/var/lib/kolla/venv/lib/python3.9/site-packages/keystone/common/manager.py", line 115, in wrapped
2023-03-06 21:05:16.565108 2023-03-06 21:05:16.548 39 ERROR keystone.server.flask.application     __ret_val = __f(*args, **kwargs)
2023-03-06 21:05:16.565117 2023-03-06 21:05:16.548 39 ERROR keystone.server.flask.application   File "/var/lib/kolla/venv/lib/python3.9/site-packages/decorator.py", line 232, in fun
2023-03-06 21:05:16.565127 2023-03-06 21:05:16.548 39 ERROR keystone.server.flask.application     return caller(func, *(extras + args), **kw)
2023-03-06 21:05:16.565136 2023-03-06 21:05:16.548 39 ERROR keystone.server.flask.application   File "/var/lib/kolla/venv/lib/python3.9/site-packages/dogpile/cache/region.py", line 1577, in get_or_create_for_user_func
2023-03-06 21:05:16.565146 2023-03-06 21:05:16.548 39 ERROR keystone.server.flask.application     return self.get_or_create(
2023-03-06 21:05:16.565155 2023-03-06 21:05:16.548 39 ERROR keystone.server.flask.application   File "/var/lib/kolla/venv/lib/python3.9/site-packages/dogpile/cache/region.py", line 1042, in get_or_create
2023-03-06 21:05:16.565166 2023-03-06 21:05:16.548 39 ERROR keystone.server.flask.application     with Lock(
2023-03-06 21:05:16.565175 2023-03-06 21:05:16.548 39 ERROR keystone.server.flask.application   File "/var/lib/kolla/venv/lib/python3.9/site-packages/dogpile/lock.py", line 185, in __enter__
2023-03-06 21:05:16.565185 2023-03-06 21:05:16.548 39 ERROR keystone.server.flask.application     return self._enter()
2023-03-06 21:05:16.565194 2023-03-06 21:05:16.548 39 ERROR keystone.server.flask.application   File "/var/lib/kolla/venv/lib/python3.9/site-packages/dogpile/lock.py", line 94, in _enter
2023-03-06 21:05:16.565268 2023-03-06 21:05:16.548 39 ERROR keystone.server.flask.application     generated = self._enter_create(value, createdtime)
2023-03-06 21:05:16.565279 2023-03-06 21:05:16.548 39 ERROR keystone.server.flask.application   File "/var/lib/kolla/venv/lib/python3.9/site-packages/dogpile/lock.py", line 178, in _enter_create
2023-03-06 21:05:16.565289 2023-03-06 21:05:16.548 39 ERROR keystone.server.flask.application     return self.creator()
2023-03-06 21:05:16.565298 2023-03-06 21:05:16.548 39 ERROR keystone.server.flask.application   File "/var/lib/kolla/venv/lib/python3.9/site-packages/dogpile/cache/region.py", line 995, in gen_value
2023-03-06 21:05:16.565332 2023-03-06 21:05:16.548 39 ERROR keystone.server.flask.application     created_value = creator(
2023-03-06 21:05:16.565344 2023-03-06 21:05:16.548 39 ERROR keystone.server.flask.application   File "/var/lib/kolla/venv/lib/python3.9/site-packages/keystone/assignment/core.py", line 1276, in get_role
2023-03-06 21:05:16.565354 2023-03-06 21:05:16.548 39 ERROR keystone.server.flask.application     return self.driver.get_role(role_id)
2023-03-06 21:05:16.565364 2023-03-06 21:05:16.548 39 ERROR keystone.server.flask.application   File "/var/lib/kolla/venv/lib/python3.9/site-packages/keystone/assignment/role_backends/sql.py", line 70, in get_role
2023-03-06 21:05:16.565381 2023-03-06 21:05:16.548 39 ERROR keystone.server.flask.application     return self._get_role(session, role_id).to_dict()
2023-03-06 21:05:16.565401 2023-03-06 21:05:16.548 39 ERROR keystone.server.flask.application   File "/var/lib/kolla/venv/lib/python3.9/site-packages/keystone/assignment/role_backends/sql.py", line 65, in _get_role
2023-03-06 21:05:16.565420 2023-03-06 21:05:16.548 39 ERROR keystone.server.flask.application     raise exception.RoleNotFound(role_id=role_id)
2023-03-06 21:05:16.565438 2023-03-06 21:05:16.548 39 ERROR keystone.server.flask.application keystone.exception.RoleNotFound: Could not find role: admin.
2023-03-06 21:05:16.565452 2023-03-06 21:05:16.548 39 ERROR keystone.server.flask.application \x1b[00m
2023-03-06 21:05:17.898063 2023-03-06 21:05:17.887 39 ERROR keystone.server.flask.application [None req-c84b66ee-0bdc-4855-bd08-0f2476468d0e 0ec98a772fae4111a46b99e8bc573150 - - all default -] Could not find user: ironic.: keystone.exception.UserNotFound: Could not find user: ironic.
2023-03-06 21:05:17.898123 2023-03-06 21:05:17.887 39 ERROR keystone.server.flask.application Traceback (most recent call last):
2023-03-06 21:05:17.898135 2023-03-06 21:05:17.887 39 ERROR keystone.server.flask.application   File "/var/lib/kolla/venv/lib/python3.9/site-packages/flask/app.py", line 1820, in full_dispatch_request
2023-03-06 21:05:17.898145 2023-03-06 21:05:17.887 39 ERROR keystone.server.flask.application     rv = self.dispatch_request()
2023-03-06 21:05:17.898155 2023-03-06 21:05:17.887 39 ERROR keystone.server.flask.application   File "/var/lib/kolla/venv/lib/python3.9/site-packages/flask/app.py", line 1796, in dispatch_request
2023-03-06 21:05:17.898166 2023-03-06 21:05:17.887 39 ERROR keystone.server.flask.application     return self.ensure_sync(self.view_functions[rule.endpoint])(**view_args)
2023-03-06 21:05:17.898175 2023-03-06 21:05:17.887 39 ERROR keystone.server.flask.application   File "/var/lib/kolla/venv/lib/python3.9/site-packages/flask_restful/__init__.py", line 467, in wrapper
2023-03-06 21:05:17.898185 2023-03-06 21:05:17.887 39 ERROR keystone.server.flask.application     resp = resource(*args, **kwargs)
2023-03-06 21:05:17.898270 2023-03-06 21:05:17.887 39 ERROR keystone.server.flask.application   File "/var/lib/kolla/venv/lib/python3.9/site-packages/flask/views.py", line 107, in view
2023-03-06 21:05:17.898291 2023-03-06 21:05:17.887 39 ERROR keystone.server.flask.application     return current_app.ensure_sync(self.dispatch_request)(**kwargs)
2023-03-06 21:05:17.898301 2023-03-06 21:05:17.887 39 ERROR keystone.server.flask.application   File "/var/lib/kolla/venv/lib/python3.9/site-packages/flask_restful/__init__.py", line 582, in dispatch_request
2023-03-06 21:05:17.898311 2023-03-06 21:05:17.887 39 ERROR keystone.server.flask.application     resp = meth(*args, **kwargs)
2023-03-06 21:05:17.898321 2023-03-06 21:05:17.887 39 ERROR keystone.server.flask.application   File "/var/lib/kolla/venv/lib/python3.9/site-packages/keystone/api/users.py", line 182, in get
2023-03-06 21:05:17.898330 2023-03-06 21:05:17.887 39 ERROR keystone.server.flask.application     return self._get_user(user_id)
2023-03-06 21:05:17.898340 2023-03-06 21:05:17.887 39 ERROR keystone.server.flask.application   File "/var/lib/kolla/venv/lib/python3.9/site-packages/keystone/api/users.py", line 194, in _get_user
2023-03-06 21:05:17.898378 2023-03-06 21:05:17.887 39 ERROR keystone.server.flask.application     ref = PROVIDERS.identity_api.get_user(user_id)
2023-03-06 21:05:17.898390 2023-03-06 21:05:17.887 39 ERROR keystone.server.flask.application   File "/var/lib/kolla/venv/lib/python3.9/site-packages/keystone/common/manager.py", line 115, in wrapped
2023-03-06 21:05:17.898400 2023-03-06 21:05:17.887 39 ERROR keystone.server.flask.application     __ret_val = __f(*args, **kwargs)
2023-03-06 21:05:17.898409 2023-03-06 21:05:17.887 39 ERROR keystone.server.flask.application   File "/var/lib/kolla/venv/lib/python3.9/site-packages/keystone/identity/core.py", line 414, in wrapper
2023-03-06 21:05:17.898419 2023-03-06 21:05:17.887 39 ERROR keystone.server.flask.application     return f(self, *args, **kwargs)
2023-03-06 21:05:17.898428 2023-03-06 21:05:17.887 39 ERROR keystone.server.flask.application   File "/var/lib/kolla/venv/lib/python3.9/site-packages/keystone/identity/core.py", line 424, in wrapper
2023-03-06 21:05:17.898438 2023-03-06 21:05:17.887 39 ERROR keystone.server.flask.application     return f(self, *args, **kwargs)
2023-03-06 21:05:17.898448 2023-03-06 21:05:17.887 39 ERROR keystone.server.flask.application   File "/var/lib/kolla/venv/lib/python3.9/site-packages/decorator.py", line 232, in fun
2023-03-06 21:05:17.898460 2023-03-06 21:05:17.887 39 ERROR keystone.server.flask.application     return caller(func, *(extras + args), **kw)
2023-03-06 21:05:17.898470 2023-03-06 21:05:17.887 39 ERROR keystone.server.flask.application   File "/var/lib/kolla/venv/lib/python3.9/site-packages/dogpile/cache/region.py", line 1577, in get_or_create_for_user_func
2023-03-06 21:05:17.898480 2023-03-06 21:05:17.887 39 ERROR keystone.server.flask.application     return self.get_or_create(
2023-03-06 21:05:17.898489 2023-03-06 21:05:17.887 39 ERROR keystone.server.flask.application   File "/var/lib/kolla/venv/lib/python3.9/site-packages/dogpile/cache/region.py", line 1042, in get_or_create
2023-03-06 21:05:17.898502 2023-03-06 21:05:17.887 39 ERROR keystone.server.flask.application     with Lock(
2023-03-06 21:05:17.898511 2023-03-06 21:05:17.887 39 ERROR keystone.server.flask.application   File "/var/lib/kolla/venv/lib/python3.9/site-packages/dogpile/lock.py", line 185, in __enter__
2023-03-06 21:05:17.898521 2023-03-06 21:05:17.887 39 ERROR keystone.server.flask.application     return self._enter()
2023-03-06 21:05:17.898530 2023-03-06 21:05:17.887 39 ERROR keystone.server.flask.application   File "/var/lib/kolla/venv/lib/python3.9/site-packages/dogpile/lock.py", line 94, in _enter
2023-03-06 21:05:17.898540 2023-03-06 21:05:17.887 39 ERROR keystone.server.flask.application     generated = self._enter_create(value, createdtime)
2023-03-06 21:05:17.898549 2023-03-06 21:05:17.887 39 ERROR keystone.server.flask.application   File "/var/lib/kolla/venv/lib/python3.9/site-packages/dogpile/lock.py", line 178, in _enter_create
2023-03-06 21:05:17.898559 2023-03-06 21:05:17.887 39 ERROR keystone.server.flask.application     return self.creator()
2023-03-06 21:05:17.898568 2023-03-06 21:05:17.887 39 ERROR keystone.server.flask.application   File "/var/lib/kolla/venv/lib/python3.9/site-packages/dogpile/cache/region.py", line 995, in gen_value
2023-03-06 21:05:17.898578 2023-03-06 21:05:17.887 39 ERROR keystone.server.flask.application     created_value = creator(
2023-03-06 21:05:17.898587 2023-03-06 21:05:17.887 39 ERROR keystone.server.flask.application   File "/var/lib/kolla/venv/lib/python3.9/site-packages/keystone/identity/core.py", line 1011, in get_user
2023-03-06 21:05:17.898597 2023-03-06 21:05:17.887 39 ERROR keystone.server.flask.application     ref = driver.get_user(entity_id)
2023-03-06 21:05:17.898607 2023-03-06 21:05:17.887 39 ERROR keystone.server.flask.application   File "/var/lib/kolla/venv/lib/python3.9/site-packages/keystone/identity/backends/sql.py", line 200, in get_user
2023-03-06 21:05:17.898616 2023-03-06 21:05:17.887 39 ERROR keystone.server.flask.application     self._get_user(session, user_id).to_dict())
2023-03-06 21:05:17.898646 2023-03-06 21:05:17.887 39 ERROR keystone.server.flask.application   File "/var/lib/kolla/venv/lib/python3.9/site-packages/keystone/identity/backends/sql.py", line 194, in _get_user
2023-03-06 21:05:17.898658 2023-03-06 21:05:17.887 39 ERROR keystone.server.flask.application     raise exception.UserNotFound(user_id=user_id)
2023-03-06 21:05:17.898668 2023-03-06 21:05:17.887 39 ERROR keystone.server.flask.application keystone.exception.UserNotFound: Could not find user: ironic.
2023-03-06 21:05:17.898677 2023-03-06 21:05:17.887 39 ERROR keystone.server.flask.application \x1b[00m
2023-03-06 21:05:18.746895 2023-03-06 21:05:18.731 40 ERROR keystone.server.flask.application [None req-b82cafa7-c85b-4557-a44d-e9874a0054fc 0ec98a772fae4111a46b99e8bc573150 - - all default -] Could not find project: service.: keystone.exception.ProjectNotFound: Could not find project: service.
2023-03-06 21:05:18.746940 2023-03-06 21:05:18.731 40 ERROR keystone.server.flask.application Traceback (most recent call last):
2023-03-06 21:05:18.746972 2023-03-06 21:05:18.731 40 ERROR keystone.server.flask.application   File "/var/lib/kolla/venv/lib/python3.9/site-packages/flask/app.py", line 1820, in full_dispatch_request
2023-03-06 21:05:18.746984 2023-03-06 21:05:18.731 40 ERROR keystone.server.flask.application     rv = self.dispatch_request()
2023-03-06 21:05:18.746994 2023-03-06 21:05:18.731 40 ERROR keystone.server.flask.application   File "/var/lib/kolla/venv/lib/python3.9/site-packages/flask/app.py", line 1796, in dispatch_request
2023-03-06 21:05:18.747004 2023-03-06 21:05:18.731 40 ERROR keystone.server.flask.application     return self.ensure_sync(self.view_functions[rule.endpoint])(**view_args)
2023-03-06 21:05:18.747014 2023-03-06 21:05:18.731 40 ERROR keystone.server.flask.application   File "/var/lib/kolla/venv/lib/python3.9/site-packages/flask_restful/__init__.py", line 467, in wrapper
2023-03-06 21:05:18.747024 2023-03-06 21:05:18.731 40 ERROR keystone.server.flask.application     resp = resource(*args, **kwargs)
2023-03-06 21:05:18.747034 2023-03-06 21:05:18.731 40 ERROR keystone.server.flask.application   File "/var/lib/kolla/venv/lib/python3.9/site-packages/flask/views.py", line 107, in view
2023-03-06 21:05:18.747045 2023-03-06 21:05:18.731 40 ERROR keystone.server.flask.application     return current_app.ensure_sync(self.dispatch_request)(**kwargs)
2023-03-06 21:05:18.747054 2023-03-06 21:05:18.731 40 ERROR keystone.server.flask.application   File "/var/lib/kolla/venv/lib/python3.9/site-packages/flask_restful/__init__.py", line 582, in dispatch_request
2023-03-06 21:05:18.747064 2023-03-06 21:05:18.731 40 ERROR keystone.server.flask.application     resp = meth(*args, **kwargs)
2023-03-06 21:05:18.747074 2023-03-06 21:05:18.731 40 ERROR keystone.server.flask.application   File "/var/lib/kolla/venv/lib/python3.9/site-packages/keystone/api/projects.py", line 151, in get
2023-03-06 21:05:18.747084 2023-03-06 21:05:18.731 40 ERROR keystone.server.flask.application     return self._get_project(project_id)
2023-03-06 21:05:18.747093 2023-03-06 21:05:18.731 40 ERROR keystone.server.flask.application   File "/var/lib/kolla/venv/lib/python3.9/site-packages/keystone/api/projects.py", line 107, in _get_project
2023-03-06 21:05:18.747103 2023-03-06 21:05:18.731 40 ERROR keystone.server.flask.application     project = PROVIDERS.resource_api.get_project(project_id)
2023-03-06 21:05:18.747113 2023-03-06 21:05:18.731 40 ERROR keystone.server.flask.application   File "/var/lib/kolla/venv/lib/python3.9/site-packages/keystone/common/manager.py", line 115, in wrapped
2023-03-06 21:05:18.747123 2023-03-06 21:05:18.731 40 ERROR keystone.server.flask.application     __ret_val = __f(*args, **kwargs)
2023-03-06 21:05:18.747132 2023-03-06 21:05:18.731 40 ERROR keystone.server.flask.application   File "/var/lib/kolla/venv/lib/python3.9/site-packages/decorator.py", line 232, in fun
2023-03-06 21:05:18.747142 2023-03-06 21:05:18.731 40 ERROR keystone.server.flask.application     return caller(func, *(extras + args), **kw)
2023-03-06 21:05:18.747250 2023-03-06 21:05:18.731 40 ERROR keystone.server.flask.application   File "/var/lib/kolla/venv/lib/python3.9/site-packages/dogpile/cache/region.py", line 1577, in get_or_create_for_user_func
2023-03-06 21:05:18.747270 2023-03-06 21:05:18.731 40 ERROR keystone.server.flask.application     return self.get_or_create(
2023-03-06 21:05:18.747280 2023-03-06 21:05:18.731 40 ERROR keystone.server.flask.application   File "/var/lib/kolla/venv/lib/python3.9/site-packages/dogpile/cache/region.py", line 1042, in get_or_create
2023-03-06 21:05:18.747292 2023-03-06 21:05:18.731 40 ERROR keystone.server.flask.application     with Lock(
2023-03-06 21:05:18.747301 2023-03-06 21:05:18.731 40 ERROR keystone.server.flask.application   File "/var/lib/kolla/venv/lib/python3.9/site-packages/dogpile/lock.py", line 185, in __enter__
2023-03-06 21:05:18.747311 2023-03-06 21:05:18.731 40 ERROR keystone.server.flask.application     return self._enter()
2023-03-06 21:05:18.747320 2023-03-06 21:05:18.731 40 ERROR keystone.server.flask.application   File "/var/lib/kolla/venv/lib/python3.9/site-packages/dogpile/lock.py", line 94, in _enter
2023-03-06 21:05:18.747330 2023-03-06 21:05:18.731 40 ERROR keystone.server.flask.application     generated = self._enter_create(value, createdtime)
2023-03-06 21:05:18.747340 2023-03-06 21:05:18.731 40 ERROR keystone.server.flask.application   File "/var/lib/kolla/venv/lib/python3.9/site-packages/dogpile/lock.py", line 178, in _enter_create
2023-03-06 21:05:18.747349 2023-03-06 21:05:18.731 40 ERROR keystone.server.flask.application     return self.creator()
2023-03-06 21:05:18.747359 2023-03-06 21:05:18.731 40 ERROR keystone.server.flask.application   File "/var/lib/kolla/venv/lib/python3.9/site-packages/dogpile/cache/region.py", line 995, in gen_value
2023-03-06 21:05:18.747369 2023-03-06 21:05:18.731 40 ERROR keystone.server.flask.application     created_value = creator(
2023-03-06 21:05:18.747378 2023-03-06 21:05:18.731 40 ERROR keystone.server.flask.application   File "/var/lib/kolla/venv/lib/python3.9/site-packages/keystone/resource/core.py", line 903, in get_project
2023-03-06 21:05:18.747388 2023-03-06 21:05:18.731 40 ERROR keystone.server.flask.application     return self.driver.get_project(project_id)
2023-03-06 21:05:18.747397 2023-03-06 21:05:18.731 40 ERROR keystone.server.flask.application   File "/var/lib/kolla/venv/lib/python3.9/site-packages/keystone/resource/backends/sql.py", line 49, in get_project
2023-03-06 21:05:18.747407 2023-03-06 21:05:18.731 40 ERROR keystone.server.flask.application     return self._get_project(session, project_id).to_dict()
2023-03-06 21:05:18.747416 2023-03-06 21:05:18.731 40 ERROR keystone.server.flask.application   File "/var/lib/kolla/venv/lib/python3.9/site-packages/keystone/resource/backends/sql.py", line 44, in _get_project
2023-03-06 21:05:18.747442 2023-03-06 21:05:18.731 40 ERROR keystone.server.flask.application     raise exception.ProjectNotFound(project_id=project_id)
2023-03-06 21:05:18.747452 2023-03-06 21:05:18.731 40 ERROR keystone.server.flask.application keystone.exception.ProjectNotFound: Could not find project: service.
2023-03-06 21:05:18.747462 2023-03-06 21:05:18.731 40 ERROR keystone.server.flask.application \x1b[00m
2023-03-06 21:05:30.218065 2023-03-06 21:05:30.210 38 ERROR keystone.server.flask.application [None req-734e2b17-2ed1-44f3-a000-83568278182d 0ec98a772fae4111a46b99e8bc573150 - - all default -] Could not find role: admin.: keystone.exception.RoleNotFound: Could not find role: admin.
2023-03-06 21:05:30.218122 2023-03-06 21:05:30.210 38 ERROR keystone.server.flask.application Traceback (most recent call last):
2023-03-06 21:05:30.218136 2023-03-06 21:05:30.210 38 ERROR keystone.server.flask.application   File "/var/lib/kolla/venv/lib/python3.9/site-packages/flask/app.py", line 1820, in full_dispatch_request
2023-03-06 21:05:30.218153 2023-03-06 21:05:30.210 38 ERROR keystone.server.flask.application     rv = self.dispatch_request()
2023-03-06 21:05:30.218164 2023-03-06 21:05:30.210 38 ERROR keystone.server.flask.application   File "/var/lib/kolla/venv/lib/python3.9/site-packages/flask/app.py", line 1796, in dispatch_request
2023-03-06 21:05:30.218259 2023-03-06 21:05:30.210 38 ERROR keystone.server.flask.application     return self.ensure_sync(self.view_functions[rule.endpoint])(**view_args)
2023-03-06 21:05:30.218277 2023-03-06 21:05:30.210 38 ERROR keystone.server.flask.application   File "/var/lib/kolla/venv/lib/python3.9/site-packages/flask_restful/__init__.py", line 467, in wrapper
2023-03-06 21:05:30.218286 2023-03-06 21:05:30.210 38 ERROR keystone.server.flask.application     resp = resource(*args, **kwargs)
2023-03-06 21:05:30.218296 2023-03-06 21:05:30.210 38 ERROR keystone.server.flask.application   File "/var/lib/kolla/venv/lib/python3.9/site-packages/flask/views.py", line 107, in view
2023-03-06 21:05:30.218307 2023-03-06 21:05:30.210 38 ERROR keystone.server.flask.application     return current_app.ensure_sync(self.dispatch_request)(**kwargs)
2023-03-06 21:05:30.218316 2023-03-06 21:05:30.210 38 ERROR keystone.server.flask.application   File "/var/lib/kolla/venv/lib/python3.9/site-packages/flask_restful/__init__.py", line 582, in dispatch_request
2023-03-06 21:05:30.218326 2023-03-06 21:05:30.210 38 ERROR keystone.server.flask.application     resp = meth(*args, **kwargs)
2023-03-06 21:05:30.218335 2023-03-06 21:05:30.210 38 ERROR keystone.server.flask.application   File "/var/lib/kolla/venv/lib/python3.9/site-packages/keystone/api/roles.py", line 50, in get
2023-03-06 21:05:30.218345 2023-03-06 21:05:30.210 38 ERROR keystone.server.flask.application     return self._get_role(role_id)
2023-03-06 21:05:30.218355 2023-03-06 21:05:30.210 38 ERROR keystone.server.flask.application   File "/var/lib/kolla/venv/lib/python3.9/site-packages/keystone/api/roles.py", line 70, in _get_role
2023-03-06 21:05:30.218364 2023-03-06 21:05:30.210 38 ERROR keystone.server.flask.application     ENFORCER.enforce_call(action='identity:get_role')
2023-03-06 21:05:30.218374 2023-03-06 21:05:30.210 38 ERROR keystone.server.flask.application   File "/var/lib/kolla/venv/lib/python3.9/site-packages/keystone/common/rbac_enforcer/enforcer.py", line 402, in enforce_call
2023-03-06 21:05:30.218384 2023-03-06 21:05:30.210 38 ERROR keystone.server.flask.application     policy_dict.update(cls._extract_member_target_data(
2023-03-06 21:05:30.218394 2023-03-06 21:05:30.210 38 ERROR keystone.server.flask.application   File "/var/lib/kolla/venv/lib/python3.9/site-packages/keystone/common/rbac_enforcer/enforcer.py", line 234, in _extract_member_target_data
2023-03-06 21:05:30.218404 2023-03-06 21:05:30.210 38 ERROR keystone.server.flask.application     member_name: func(flask.request.view_args[key])
2023-03-06 21:05:30.218413 2023-03-06 21:05:30.210 38 ERROR keystone.server.flask.application   File "/var/lib/kolla/venv/lib/python3.9/site-packages/keystone/common/manager.py", line 115, in wrapped
2023-03-06 21:05:30.218423 2023-03-06 21:05:30.210 38 ERROR keystone.server.flask.application     __ret_val = __f(*args, **kwargs)
2023-03-06 21:05:30.218432 2023-03-06 21:05:30.210 38 ERROR keystone.server.flask.application   File "/var/lib/kolla/venv/lib/python3.9/site-packages/decorator.py", line 232, in fun
2023-03-06 21:05:30.218442 2023-03-06 21:05:30.210 38 ERROR keystone.server.flask.application     return caller(func, *(extras + args), **kw)
2023-03-06 21:05:30.218451 2023-03-06 21:05:30.210 38 ERROR keystone.server.flask.application   File "/var/lib/kolla/venv/lib/python3.9/site-packages/dogpile/cache/region.py", line 1577, in get_or_create_for_user_func
2023-03-06 21:05:30.218461 2023-03-06 21:05:30.210 38 ERROR keystone.server.flask.application     return self.get_or_create(
2023-03-06 21:05:30.218470 2023-03-06 21:05:30.210 38 ERROR keystone.server.flask.application   File "/var/lib/kolla/venv/lib/python3.9/site-packages/dogpile/cache/region.py", line 1042, in get_or_create
2023-03-06 21:05:30.218481 2023-03-06 21:05:30.210 38 ERROR keystone.server.flask.application     with Lock(
2023-03-06 21:05:30.218503 2023-03-06 21:05:30.210 38 ERROR keystone.server.flask.application   File "/var/lib/kolla/venv/lib/python3.9/site-packages/dogpile/lock.py", line 185, in __enter__
2023-03-06 21:05:30.218515 2023-03-06 21:05:30.210 38 ERROR keystone.server.flask.application     return self._enter()
2023-03-06 21:05:30.218524 2023-03-06 21:05:30.210 38 ERROR keystone.server.flask.application   File "/var/lib/kolla/venv/lib/python3.9/site-packages/dogpile/lock.py", line 94, in _enter
2023-03-06 21:05:30.218534 2023-03-06 21:05:30.210 38 ERROR keystone.server.flask.application     generated = self._enter_create(value, createdtime)
2023-03-06 21:05:30.218544 2023-03-06 21:05:30.210 38 ERROR keystone.server.flask.application   File "/var/lib/kolla/venv/lib/python3.9/site-packages/dogpile/lock.py", line 178, in _enter_create
2023-03-06 21:05:30.218554 2023-03-06 21:05:30.210 38 ERROR keystone.server.flask.application     return self.creator()
2023-03-06 21:05:30.218563 2023-03-06 21:05:30.210 38 ERROR keystone.server.flask.application   File "/var/lib/kolla/venv/lib/python3.9/site-packages/dogpile/cache/region.py", line 995, in gen_value
2023-03-06 21:05:30.218573 2023-03-06 21:05:30.210 38 ERROR keystone.server.flask.application     created_value = creator(
2023-03-06 21:05:30.218583 2023-03-06 21:05:30.210 38 ERROR keystone.server.flask.application   File "/var/lib/kolla/venv/lib/python3.9/site-packages/keystone/assignment/core.py", line 1276, in get_role
2023-03-06 21:05:30.218593 2023-03-06 21:05:30.210 38 ERROR keystone.server.flask.application     return self.driver.get_role(role_id)
2023-03-06 21:05:30.218602 2023-03-06 21:05:30.210 38 ERROR keystone.server.flask.application   File "/var/lib/kolla/venv/lib/python3.9/site-packages/keystone/assignment/role_backends/sql.py", line 70, in get_role
2023-03-06 21:05:30.218612 2023-03-06 21:05:30.210 38 ERROR keystone.server.flask.application     return self._get_role(session, role_id).to_dict()
2023-03-06 21:05:30.218622 2023-03-06 21:05:30.210 38 ERROR keystone.server.flask.application   File "/var/lib/kolla/venv/lib/python3.9/site-packages/keystone/assignment/role_backends/sql.py", line 65, in _get_role
2023-03-06 21:05:30.218632 2023-03-06 21:05:30.210 38 ERROR keystone.server.flask.application     raise exception.RoleNotFound(role_id=role_id)
2023-03-06 21:05:30.218641 2023-03-06 21:05:30.210 38 ERROR keystone.server.flask.application keystone.exception.RoleNotFound: Could not find role: admin.
2023-03-06 21:05:30.218651 2023-03-06 21:05:30.210 38 ERROR keystone.server.flask.application \x1b[00m
2023-03-06 21:05:31.542111 2023-03-06 21:05:31.535 38 ERROR keystone.server.flask.application [None req-23566d39-b2b8-441e-b573-e08c8268cf0a 0ec98a772fae4111a46b99e8bc573150 - - all default -] Could not find user: ironic-inspector.: keystone.exception.UserNotFound: Could not find user: ironic-inspector.
2023-03-06 21:05:31.542157 2023-03-06 21:05:31.535 38 ERROR keystone.server.flask.application Traceback (most recent call last):
2023-03-06 21:05:31.542168 2023-03-06 21:05:31.535 38 ERROR keystone.server.flask.application   File "/var/lib/kolla/venv/lib/python3.9/site-packages/flask/app.py", line 1820, in full_dispatch_request
2023-03-06 21:05:31.542179 2023-03-06 21:05:31.535 38 ERROR keystone.server.flask.application     rv = self.dispatch_request()
2023-03-06 21:05:31.542189 2023-03-06 21:05:31.535 38 ERROR keystone.server.flask.application   File "/var/lib/kolla/venv/lib/python3.9/site-packages/flask/app.py", line 1796, in dispatch_request
2023-03-06 21:05:31.542275 2023-03-06 21:05:31.535 38 ERROR keystone.server.flask.application     return self.ensure_sync(self.view_functions[rule.endpoint])(**view_args)
2023-03-06 21:05:31.542291 2023-03-06 21:05:31.535 38 ERROR keystone.server.flask.application   File "/var/lib/kolla/venv/lib/python3.9/site-packages/flask_restful/__init__.py", line 467, in wrapper
2023-03-06 21:05:31.542301 2023-03-06 21:05:31.535 38 ERROR keystone.server.flask.application     resp = resource(*args, **kwargs)
2023-03-06 21:05:31.542311 2023-03-06 21:05:31.535 38 ERROR keystone.server.flask.application   File "/var/lib/kolla/venv/lib/python3.9/site-packages/flask/views.py", line 107, in view
2023-03-06 21:05:31.542347 2023-03-06 21:05:31.535 38 ERROR keystone.server.flask.application     return current_app.ensure_sync(self.dispatch_request)(**kwargs)
2023-03-06 21:05:31.542359 2023-03-06 21:05:31.535 38 ERROR keystone.server.flask.application   File "/var/lib/kolla/venv/lib/python3.9/site-packages/flask_restful/__init__.py", line 582, in dispatch_request
2023-03-06 21:05:31.542369 2023-03-06 21:05:31.535 38 ERROR keystone.server.flask.application     resp = meth(*args, **kwargs)
2023-03-06 21:05:31.542379 2023-03-06 21:05:31.535 38 ERROR keystone.server.flask.application   File "/var/lib/kolla/venv/lib/python3.9/site-packages/keystone/api/users.py", line 182, in get
2023-03-06 21:05:31.542388 2023-03-06 21:05:31.535 38 ERROR keystone.server.flask.application     return self._get_user(user_id)
2023-03-06 21:05:31.542398 2023-03-06 21:05:31.535 38 ERROR keystone.server.flask.application   File "/var/lib/kolla/venv/lib/python3.9/site-packages/keystone/api/users.py", line 194, in _get_user
2023-03-06 21:05:31.542408 2023-03-06 21:05:31.535 38 ERROR keystone.server.flask.application     ref = PROVIDERS.identity_api.get_user(user_id)
2023-03-06 21:05:31.542417 2023-03-06 21:05:31.535 38 ERROR keystone.server.flask.application   File "/var/lib/kolla/venv/lib/python3.9/site-packages/keystone/common/manager.py", line 115, in wrapped
2023-03-06 21:05:31.542427 2023-03-06 21:05:31.535 38 ERROR keystone.server.flask.application     __ret_val = __f(*args, **kwargs)
2023-03-06 21:05:31.542437 2023-03-06 21:05:31.535 38 ERROR keystone.server.flask.application   File "/var/lib/kolla/venv/lib/python3.9/site-packages/keystone/identity/core.py", line 414, in wrapper
2023-03-06 21:05:31.542446 2023-03-06 21:05:31.535 38 ERROR keystone.server.flask.application     return f(self, *args, **kwargs)
2023-03-06 21:05:31.542456 2023-03-06 21:05:31.535 38 ERROR keystone.server.flask.application   File "/var/lib/kolla/venv/lib/python3.9/site-packages/keystone/identity/core.py", line 424, in wrapper
2023-03-06 21:05:31.542466 2023-03-06 21:05:31.535 38 ERROR keystone.server.flask.application     return f(self, *args, **kwargs)
2023-03-06 21:05:31.542475 2023-03-06 21:05:31.535 38 ERROR keystone.server.flask.application   File "/var/lib/kolla/venv/lib/python3.9/site-packages/decorator.py", line 232, in fun
2023-03-06 21:05:31.542485 2023-03-06 21:05:31.535 38 ERROR keystone.server.flask.application     return caller(func, *(extras + args), **kw)
2023-03-06 21:05:31.542495 2023-03-06 21:05:31.535 38 ERROR keystone.server.flask.application   File "/var/lib/kolla/venv/lib/python3.9/site-packages/dogpile/cache/region.py", line 1577, in get_or_create_for_user_func
2023-03-06 21:05:31.542504 2023-03-06 21:05:31.535 38 ERROR keystone.server.flask.application     return self.get_or_create(
2023-03-06 21:05:31.542514 2023-03-06 21:05:31.535 38 ERROR keystone.server.flask.application   File "/var/lib/kolla/venv/lib/python3.9/site-packages/dogpile/cache/region.py", line 1042, in get_or_create
2023-03-06 21:05:31.542524 2023-03-06 21:05:31.535 38 ERROR keystone.server.flask.application     with Lock(
2023-03-06 21:05:31.542533 2023-03-06 21:05:31.535 38 ERROR keystone.server.flask.application   File "/var/lib/kolla/venv/lib/python3.9/site-packages/dogpile/lock.py", line 185, in __enter__
2023-03-06 21:05:31.542543 2023-03-06 21:05:31.535 38 ERROR keystone.server.flask.application     return self._enter()
2023-03-06 21:05:31.542553 2023-03-06 21:05:31.535 38 ERROR keystone.server.flask.application   File "/var/lib/kolla/venv/lib/python3.9/site-packages/dogpile/lock.py", line 94, in _enter
2023-03-06 21:05:31.542562 2023-03-06 21:05:31.535 38 ERROR keystone.server.flask.application     generated = self._enter_create(value, createdtime)
2023-03-06 21:05:31.542572 2023-03-06 21:05:31.535 38 ERROR keystone.server.flask.application   File "/var/lib/kolla/venv/lib/python3.9/site-packages/dogpile/lock.py", line 178, in _enter_create
2023-03-06 21:05:31.542599 2023-03-06 21:05:31.535 38 ERROR keystone.server.flask.application     return self.creator()
2023-03-06 21:05:31.542611 2023-03-06 21:05:31.535 38 ERROR keystone.server.flask.application   File "/var/lib/kolla/venv/lib/python3.9/site-packages/dogpile/cache/region.py", line 995, in gen_value
2023-03-06 21:05:31.542620 2023-03-06 21:05:31.535 38 ERROR keystone.server.flask.application     created_value = creator(
2023-03-06 21:05:31.542630 2023-03-06 21:05:31.535 38 ERROR keystone.server.flask.application   File "/var/lib/kolla/venv/lib/python3.9/site-packages/keystone/identity/core.py", line 1011, in get_user
2023-03-06 21:05:31.542640 2023-03-06 21:05:31.535 38 ERROR keystone.server.flask.application     ref = driver.get_user(entity_id)
2023-03-06 21:05:31.542649 2023-03-06 21:05:31.535 38 ERROR keystone.server.flask.application   File "/var/lib/kolla/venv/lib/python3.9/site-packages/keystone/identity/backends/sql.py", line 200, in get_user
2023-03-06 21:05:31.542659 2023-03-06 21:05:31.535 38 ERROR keystone.server.flask.application     self._get_user(session, user_id).to_dict())
2023-03-06 21:05:31.542668 2023-03-06 21:05:31.535 38 ERROR keystone.server.flask.application   File "/var/lib/kolla/venv/lib/python3.9/site-packages/keystone/identity/backends/sql.py", line 194, in _get_user
2023-03-06 21:05:31.542678 2023-03-06 21:05:31.535 38 ERROR keystone.server.flask.application     raise exception.UserNotFound(user_id=user_id)
2023-03-06 21:05:31.542687 2023-03-06 21:05:31.535 38 ERROR keystone.server.flask.application keystone.exception.UserNotFound: Could not find user: ironic-inspector.
2023-03-06 21:05:31.542697 2023-03-06 21:05:31.535 38 ERROR keystone.server.flask.application \x1b[00m
2023-03-06 21:05:32.449876 2023-03-06 21:05:32.445 39 ERROR keystone.server.flask.application [None req-32e54aa8-ee51-4b48-94d9-b0bd6701ba21 0ec98a772fae4111a46b99e8bc573150 - - all default -] Could not find project: service.: keystone.exception.ProjectNotFound: Could not find project: service.
2023-03-06 21:05:32.450026 2023-03-06 21:05:32.445 39 ERROR keystone.server.flask.application Traceback (most recent call last):
2023-03-06 21:05:32.450044 2023-03-06 21:05:32.445 39 ERROR keystone.server.flask.application   File "/var/lib/kolla/venv/lib/python3.9/site-packages/flask/app.py", line 1820, in full_dispatch_request
2023-03-06 21:05:32.452832 2023-03-06 21:05:32.445 39 ERROR keystone.server.flask.application     rv = self.dispatch_request()
2023-03-06 21:05:32.452909 2023-03-06 21:05:32.445 39 ERROR keystone.server.flask.application   File "/var/lib/kolla/venv/lib/python3.9/site-packages/flask/app.py", line 1796, in dispatch_request
2023-03-06 21:05:32.452934 2023-03-06 21:05:32.445 39 ERROR keystone.server.flask.application     return self.ensure_sync(self.view_functions[rule.endpoint])(**view_args)
2023-03-06 21:05:32.452955 2023-03-06 21:05:32.445 39 ERROR keystone.server.flask.application   File "/var/lib/kolla/venv/lib/python3.9/site-packages/flask_restful/__init__.py", line 467, in wrapper
2023-03-06 21:05:32.452976 2023-03-06 21:05:32.445 39 ERROR keystone.server.flask.application     resp = resource(*args, **kwargs)
2023-03-06 21:05:32.453140 2023-03-06 21:05:32.445 39 ERROR keystone.server.flask.application   File "/var/lib/kolla/venv/lib/python3.9/site-packages/flask/views.py", line 107, in view
2023-03-06 21:05:32.453172 2023-03-06 21:05:32.445 39 ERROR keystone.server.flask.application     return current_app.ensure_sync(self.dispatch_request)(**kwargs)
2023-03-06 21:05:32.453189 2023-03-06 21:05:32.445 39 ERROR keystone.server.flask.application   File "/var/lib/kolla/venv/lib/python3.9/site-packages/flask_restful/__init__.py", line 582, in dispatch_request
2023-03-06 21:05:32.453273 2023-03-06 21:05:32.445 39 ERROR keystone.server.flask.application     resp = meth(*args, **kwargs)
2023-03-06 21:05:32.453296 2023-03-06 21:05:32.445 39 ERROR keystone.server.flask.application   File "/var/lib/kolla/venv/lib/python3.9/site-packages/keystone/api/projects.py", line 151, in get
2023-03-06 21:05:32.453362 2023-03-06 21:05:32.445 39 ERROR keystone.server.flask.application     return self._get_project(project_id)
2023-03-06 21:05:32.453382 2023-03-06 21:05:32.445 39 ERROR keystone.server.flask.application   File "/var/lib/kolla/venv/lib/python3.9/site-packages/keystone/api/projects.py", line 107, in _get_project
2023-03-06 21:05:32.453401 2023-03-06 21:05:32.445 39 ERROR keystone.server.flask.application     project = PROVIDERS.resource_api.get_project(project_id)
2023-03-06 21:05:32.453421 2023-03-06 21:05:32.445 39 ERROR keystone.server.flask.application   File "/var/lib/kolla/venv/lib/python3.9/site-packages/keystone/common/manager.py", line 115, in wrapped
2023-03-06 21:05:32.453440 2023-03-06 21:05:32.445 39 ERROR keystone.server.flask.application     __ret_val = __f(*args, **kwargs)
2023-03-06 21:05:32.453472 2023-03-06 21:05:32.445 39 ERROR keystone.server.flask.application   File "/var/lib/kolla/venv/lib/python3.9/site-packages/decorator.py", line 232, in fun
2023-03-06 21:05:32.453492 2023-03-06 21:05:32.445 39 ERROR keystone.server.flask.application     return caller(func, *(extras + args), **kw)
2023-03-06 21:05:32.453542 2023-03-06 21:05:32.445 39 ERROR keystone.server.flask.application   File "/var/lib/kolla/venv/lib/python3.9/site-packages/dogpile/cache/region.py", line 1577, in get_or_create_for_user_func
2023-03-06 21:05:32.453567 2023-03-06 21:05:32.445 39 ERROR keystone.server.flask.application     return self.get_or_create(
2023-03-06 21:05:32.453586 2023-03-06 21:05:32.445 39 ERROR keystone.server.flask.application   File "/var/lib/kolla/venv/lib/python3.9/site-packages/dogpile/cache/region.py", line 1042, in get_or_create
2023-03-06 21:05:32.453606 2023-03-06 21:05:32.445 39 ERROR keystone.server.flask.application     with Lock(
2023-03-06 21:05:32.453627 2023-03-06 21:05:32.445 39 ERROR keystone.server.flask.application   File "/var/lib/kolla/venv/lib/python3.9/site-packages/dogpile/lock.py", line 185, in __enter__
2023-03-06 21:05:32.453648 2023-03-06 21:05:32.445 39 ERROR keystone.server.flask.application     return self._enter()
2023-03-06 21:05:32.453670 2023-03-06 21:05:32.445 39 ERROR keystone.server.flask.application   File "/var/lib/kolla/venv/lib/python3.9/site-packages/dogpile/lock.py", line 94, in _enter
2023-03-06 21:05:32.453691 2023-03-06 21:05:32.445 39 ERROR keystone.server.flask.application     generated = self._enter_create(value, createdtime)
2023-03-06 21:05:32.453731 2023-03-06 21:05:32.445 39 ERROR keystone.server.flask.application   File "/var/lib/kolla/venv/lib/python3.9/site-packages/dogpile/lock.py", line 178, in _enter_create
2023-03-06 21:05:32.453749 2023-03-06 21:05:32.445 39 ERROR keystone.server.flask.application     return self.creator()
2023-03-06 21:05:32.453767 2023-03-06 21:05:32.445 39 ERROR keystone.server.flask.application   File "/var/lib/kolla/venv/lib/python3.9/site-packages/dogpile/cache/region.py", line 995, in gen_value
2023-03-06 21:05:32.453785 2023-03-06 21:05:32.445 39 ERROR keystone.server.flask.application     created_value = creator(
2023-03-06 21:05:32.453805 2023-03-06 21:05:32.445 39 ERROR keystone.server.flask.application   File "/var/lib/kolla/venv/lib/python3.9/site-packages/keystone/resource/core.py", line 903, in get_project
2023-03-06 21:05:32.453824 2023-03-06 21:05:32.445 39 ERROR keystone.server.flask.application     return self.driver.get_project(project_id)
2023-03-06 21:05:32.453839 2023-03-06 21:05:32.445 39 ERROR keystone.server.flask.application   File "/var/lib/kolla/venv/lib/python3.9/site-packages/keystone/resource/backends/sql.py", line 49, in get_project
2023-03-06 21:05:32.453855 2023-03-06 21:05:32.445 39 ERROR keystone.server.flask.application     return self._get_project(session, project_id).to_dict()
2023-03-06 21:05:32.453866 2023-03-06 21:05:32.445 39 ERROR keystone.server.flask.application   File "/var/lib/kolla/venv/lib/python3.9/site-packages/keystone/resource/backends/sql.py", line 44, in _get_project
2023-03-06 21:05:32.453876 2023-03-06 21:05:32.445 39 ERROR keystone.server.flask.application     raise exception.ProjectNotFound(project_id=project_id)
2023-03-06 21:05:32.453901 2023-03-06 21:05:32.445 39 ERROR keystone.server.flask.application keystone.exception.ProjectNotFound: Could not find project: service.
2023-03-06 21:05:32.453912 2023-03-06 21:05:32.445 39 ERROR keystone.server.flask.application \x1b[00m
2023-03-06 21:08:27.009979 2023-03-06 21:08:27.001 40 ERROR keystone.server.flask.application [None req-f2831b2a-0b2b-461a-8723-005466d2e944 0ec98a772fae4111a46b99e8bc573150 - - all default -] Could not find project: service.: keystone.exception.ProjectNotFound: Could not find project: service.
2023-03-06 21:08:27.010102 2023-03-06 21:08:27.001 40 ERROR keystone.server.flask.application Traceback (most recent call last):
2023-03-06 21:08:27.010126 2023-03-06 21:08:27.001 40 ERROR keystone.server.flask.application   File "/var/lib/kolla/venv/lib/python3.9/site-packages/flask/app.py", line 1820, in full_dispatch_request
2023-03-06 21:08:27.010145 2023-03-06 21:08:27.001 40 ERROR keystone.server.flask.application     rv = self.dispatch_request()
2023-03-06 21:08:27.010162 2023-03-06 21:08:27.001 40 ERROR keystone.server.flask.application   File "/var/lib/kolla/venv/lib/python3.9/site-packages/flask/app.py", line 1796, in dispatch_request
2023-03-06 21:08:27.010232 2023-03-06 21:08:27.001 40 ERROR keystone.server.flask.application     return self.ensure_sync(self.view_functions[rule.endpoint])(**view_args)
2023-03-06 21:08:27.010264 2023-03-06 21:08:27.001 40 ERROR keystone.server.flask.application   File "/var/lib/kolla/venv/lib/python3.9/site-packages/flask_restful/__init__.py", line 467, in wrapper
2023-03-06 21:08:27.010283 2023-03-06 21:08:27.001 40 ERROR keystone.server.flask.application     resp = resource(*args, **kwargs)
2023-03-06 21:08:27.010302 2023-03-06 21:08:27.001 40 ERROR keystone.server.flask.application   File "/var/lib/kolla/venv/lib/python3.9/site-packages/flask/views.py", line 107, in view
2023-03-06 21:08:27.010320 2023-03-06 21:08:27.001 40 ERROR keystone.server.flask.application     return current_app.ensure_sync(self.dispatch_request)(**kwargs)
2023-03-06 21:08:27.010339 2023-03-06 21:08:27.001 40 ERROR keystone.server.flask.application   File "/var/lib/kolla/venv/lib/python3.9/site-packages/flask_restful/__init__.py", line 582, in dispatch_request
2023-03-06 21:08:27.010357 2023-03-06 21:08:27.001 40 ERROR keystone.server.flask.application     resp = meth(*args, **kwargs)
2023-03-06 21:08:27.010373 2023-03-06 21:08:27.001 40 ERROR keystone.server.flask.application   File "/var/lib/kolla/venv/lib/python3.9/site-packages/keystone/api/projects.py", line 151, in get
2023-03-06 21:08:27.010406 2023-03-06 21:08:27.001 40 ERROR keystone.server.flask.application     return self._get_project(project_id)
2023-03-06 21:08:27.010423 2023-03-06 21:08:27.001 40 ERROR keystone.server.flask.application   File "/var/lib/kolla/venv/lib/python3.9/site-packages/keystone/api/projects.py", line 107, in _get_project
2023-03-06 21:08:27.010441 2023-03-06 21:08:27.001 40 ERROR keystone.server.flask.application     project = PROVIDERS.resource_api.get_project(project_id)
2023-03-06 21:08:27.010458 2023-03-06 21:08:27.001 40 ERROR keystone.server.flask.application   File "/var/lib/kolla/venv/lib/python3.9/site-packages/keystone/common/manager.py", line 115, in wrapped
2023-03-06 21:08:27.010475 2023-03-06 21:08:27.001 40 ERROR keystone.server.flask.application     __ret_val = __f(*args, **kwargs)
2023-03-06 21:08:27.010491 2023-03-06 21:08:27.001 40 ERROR keystone.server.flask.application   File "/var/lib/kolla/venv/lib/python3.9/site-packages/decorator.py", line 232, in fun
2023-03-06 21:08:27.010510 2023-03-06 21:08:27.001 40 ERROR keystone.server.flask.application     return caller(func, *(extras + args), **kw)
2023-03-06 21:08:27.010540 2023-03-06 21:08:27.001 40 ERROR keystone.server.flask.application   File "/var/lib/kolla/venv/lib/python3.9/site-packages/dogpile/cache/region.py", line 1577, in get_or_create_for_user_func
2023-03-06 21:08:27.010564 2023-03-06 21:08:27.001 40 ERROR keystone.server.flask.application     return self.get_or_create(
2023-03-06 21:08:27.010617 2023-03-06 21:08:27.001 40 ERROR keystone.server.flask.application   File "/var/lib/kolla/venv/lib/python3.9/site-packages/dogpile/cache/region.py", line 1042, in get_or_create
2023-03-06 21:08:27.010638 2023-03-06 21:08:27.001 40 ERROR keystone.server.flask.application     with Lock(
2023-03-06 21:08:27.010655 2023-03-06 21:08:27.001 40 ERROR keystone.server.flask.application   File "/var/lib/kolla/venv/lib/python3.9/site-packages/dogpile/lock.py", line 185, in __enter__
2023-03-06 21:08:27.010677 2023-03-06 21:08:27.001 40 ERROR keystone.server.flask.application     return self._enter()
2023-03-06 21:08:27.010693 2023-03-06 21:08:27.001 40 ERROR keystone.server.flask.application   File "/var/lib/kolla/venv/lib/python3.9/site-packages/dogpile/lock.py", line 94, in _enter
2023-03-06 21:08:27.010710 2023-03-06 21:08:27.001 40 ERROR keystone.server.flask.application     generated = self._enter_create(value, createdtime)
2023-03-06 21:08:27.010728 2023-03-06 21:08:27.001 40 ERROR keystone.server.flask.application   File "/var/lib/kolla/venv/lib/python3.9/site-packages/dogpile/lock.py", line 178, in _enter_create
2023-03-06 21:08:27.010744 2023-03-06 21:08:27.001 40 ERROR keystone.server.flask.application     return self.creator()
2023-03-06 21:08:27.010775 2023-03-06 21:08:27.001 40 ERROR keystone.server.flask.application   File "/var/lib/kolla/venv/lib/python3.9/site-packages/dogpile/cache/region.py", line 995, in gen_value
2023-03-06 21:08:27.010794 2023-03-06 21:08:27.001 40 ERROR keystone.server.flask.application     created_value = creator(
2023-03-06 21:08:27.010810 2023-03-06 21:08:27.001 40 ERROR keystone.server.flask.application   File "/var/lib/kolla/venv/lib/python3.9/site-packages/keystone/resource/core.py", line 903, in get_project
2023-03-06 21:08:27.010826 2023-03-06 21:08:27.001 40 ERROR keystone.server.flask.application     return self.driver.get_project(project_id)
2023-03-06 21:08:27.010843 2023-03-06 21:08:27.001 40 ERROR keystone.server.flask.application   File "/var/lib/kolla/venv/lib/python3.9/site-packages/keystone/resource/backends/sql.py", line 49, in get_project
2023-03-06 21:08:27.010862 2023-03-06 21:08:27.001 40 ERROR keystone.server.flask.application     return self._get_project(session, project_id).to_dict()
2023-03-06 21:08:27.010880 2023-03-06 21:08:27.001 40 ERROR keystone.server.flask.application   File "/var/lib/kolla/venv/lib/python3.9/site-packages/keystone/resource/backends/sql.py", line 44, in _get_project
2023-03-06 21:08:27.010898 2023-03-06 21:08:27.001 40 ERROR keystone.server.flask.application     raise exception.ProjectNotFound(project_id=project_id)
2023-03-06 21:08:27.010915 2023-03-06 21:08:27.001 40 ERROR keystone.server.flask.application keystone.exception.ProjectNotFound: Could not find project: service.
2023-03-06 21:08:27.010944 2023-03-06 21:08:27.001 40 ERROR keystone.server.flask.application \x1b[00m
2023-03-06 21:08:43.348254 2023-03-06 21:08:43.344 38 ERROR keystone.server.flask.application [None req-979ecc13-7df4-4146-955b-2b9bd5015fa4 0ec98a772fae4111a46b99e8bc573150 - - all default -] Could not find role: admin.: keystone.exception.RoleNotFound: Could not find role: admin.
2023-03-06 21:08:43.348310 2023-03-06 21:08:43.344 38 ERROR keystone.server.flask.application Traceback (most recent call last):
2023-03-06 21:08:43.348322 2023-03-06 21:08:43.344 38 ERROR keystone.server.flask.application   File "/var/lib/kolla/venv/lib/python3.9/site-packages/flask/app.py", line 1820, in full_dispatch_request
2023-03-06 21:08:43.348333 2023-03-06 21:08:43.344 38 ERROR keystone.server.flask.application     rv = self.dispatch_request()
2023-03-06 21:08:43.348342 2023-03-06 21:08:43.344 38 ERROR keystone.server.flask.application   File "/var/lib/kolla/venv/lib/python3.9/site-packages/flask/app.py", line 1796, in dispatch_request
2023-03-06 21:08:43.348352 2023-03-06 21:08:43.344 38 ERROR keystone.server.flask.application     return self.ensure_sync(self.view_functions[rule.endpoint])(**view_args)
2023-03-06 21:08:43.348362 2023-03-06 21:08:43.344 38 ERROR keystone.server.flask.application   File "/var/lib/kolla/venv/lib/python3.9/site-packages/flask_restful/__init__.py", line 467, in wrapper
2023-03-06 21:08:43.348390 2023-03-06 21:08:43.344 38 ERROR keystone.server.flask.application     resp = resource(*args, **kwargs)
2023-03-06 21:08:43.348402 2023-03-06 21:08:43.344 38 ERROR keystone.server.flask.application   File "/var/lib/kolla/venv/lib/python3.9/site-packages/flask/views.py", line 107, in view
2023-03-06 21:08:43.348412 2023-03-06 21:08:43.344 38 ERROR keystone.server.flask.application     return current_app.ensure_sync(self.dispatch_request)(**kwargs)
2023-03-06 21:08:43.348422 2023-03-06 21:08:43.344 38 ERROR keystone.server.flask.application   File "/var/lib/kolla/venv/lib/python3.9/site-packages/flask_restful/__init__.py", line 582, in dispatch_request
2023-03-06 21:08:43.348431 2023-03-06 21:08:43.344 38 ERROR keystone.server.flask.application     resp = meth(*args, **kwargs)
2023-03-06 21:08:43.348441 2023-03-06 21:08:43.344 38 ERROR keystone.server.flask.application   File "/var/lib/kolla/venv/lib/python3.9/site-packages/keystone/api/roles.py", line 50, in get
2023-03-06 21:08:43.348451 2023-03-06 21:08:43.344 38 ERROR keystone.server.flask.application     return self._get_role(role_id)
2023-03-06 21:08:43.348460 2023-03-06 21:08:43.344 38 ERROR keystone.server.flask.application   File "/var/lib/kolla/venv/lib/python3.9/site-packages/keystone/api/roles.py", line 70, in _get_role
2023-03-06 21:08:43.348470 2023-03-06 21:08:43.344 38 ERROR keystone.server.flask.application     ENFORCER.enforce_call(action='identity:get_role')
2023-03-06 21:08:43.348479 2023-03-06 21:08:43.344 38 ERROR keystone.server.flask.application   File "/var/lib/kolla/venv/lib/python3.9/site-packages/keystone/common/rbac_enforcer/enforcer.py", line 402, in enforce_call
2023-03-06 21:08:43.348489 2023-03-06 21:08:43.344 38 ERROR keystone.server.flask.application     policy_dict.update(cls._extract_member_target_data(
2023-03-06 21:08:43.348499 2023-03-06 21:08:43.344 38 ERROR keystone.server.flask.application   File "/var/lib/kolla/venv/lib/python3.9/site-packages/keystone/common/rbac_enforcer/enforcer.py", line 234, in _extract_member_target_data
2023-03-06 21:08:43.348509 2023-03-06 21:08:43.344 38 ERROR keystone.server.flask.application     member_name: func(flask.request.view_args[key])
2023-03-06 21:08:43.348519 2023-03-06 21:08:43.344 38 ERROR keystone.server.flask.application   File "/var/lib/kolla/venv/lib/python3.9/site-packages/keystone/common/manager.py", line 115, in wrapped
2023-03-06 21:08:43.348528 2023-03-06 21:08:43.344 38 ERROR keystone.server.flask.application     __ret_val = __f(*args, **kwargs)
2023-03-06 21:08:43.348538 2023-03-06 21:08:43.344 38 ERROR keystone.server.flask.application   File "/var/lib/kolla/venv/lib/python3.9/site-packages/decorator.py", line 232, in fun
2023-03-06 21:08:43.348547 2023-03-06 21:08:43.344 38 ERROR keystone.server.flask.application     return caller(func, *(extras + args), **kw)
2023-03-06 21:08:43.348557 2023-03-06 21:08:43.344 38 ERROR keystone.server.flask.application   File "/var/lib/kolla/venv/lib/python3.9/site-packages/dogpile/cache/region.py", line 1577, in get_or_create_for_user_func
2023-03-06 21:08:43.348567 2023-03-06 21:08:43.344 38 ERROR keystone.server.flask.application     return self.get_or_create(
2023-03-06 21:08:43.348576 2023-03-06 21:08:43.344 38 ERROR keystone.server.flask.application   File "/var/lib/kolla/venv/lib/python3.9/site-packages/dogpile/cache/region.py", line 1042, in get_or_create
2023-03-06 21:08:43.348586 2023-03-06 21:08:43.344 38 ERROR keystone.server.flask.application     with Lock(
2023-03-06 21:08:43.348596 2023-03-06 21:08:43.344 38 ERROR keystone.server.flask.application   File "/var/lib/kolla/venv/lib/python3.9/site-packages/dogpile/lock.py", line 185, in __enter__
2023-03-06 21:08:43.348605 2023-03-06 21:08:43.344 38 ERROR keystone.server.flask.application     return self._enter()
2023-03-06 21:08:43.348615 2023-03-06 21:08:43.344 38 ERROR keystone.server.flask.application   File "/var/lib/kolla/venv/lib/python3.9/site-packages/dogpile/lock.py", line 94, in _enter
2023-03-06 21:08:43.348649 2023-03-06 21:08:43.344 38 ERROR keystone.server.flask.application     generated = self._enter_create(value, createdtime)
2023-03-06 21:08:43.348661 2023-03-06 21:08:43.344 38 ERROR keystone.server.flask.application   File "/var/lib/kolla/venv/lib/python3.9/site-packages/dogpile/lock.py", line 178, in _enter_create
2023-03-06 21:08:43.348671 2023-03-06 21:08:43.344 38 ERROR keystone.server.flask.application     return self.creator()
2023-03-06 21:08:43.348680 2023-03-06 21:08:43.344 38 ERROR keystone.server.flask.application   File "/var/lib/kolla/venv/lib/python3.9/site-packages/dogpile/cache/region.py", line 995, in gen_value
2023-03-06 21:08:43.348690 2023-03-06 21:08:43.344 38 ERROR keystone.server.flask.application     created_value = creator(
2023-03-06 21:08:43.348699 2023-03-06 21:08:43.344 38 ERROR keystone.server.flask.application   File "/var/lib/kolla/venv/lib/python3.9/site-packages/keystone/assignment/core.py", line 1276, in get_role
2023-03-06 21:08:43.348709 2023-03-06 21:08:43.344 38 ERROR keystone.server.flask.application     return self.driver.get_role(role_id)
2023-03-06 21:08:43.348718 2023-03-06 21:08:43.344 38 ERROR keystone.server.flask.application   File "/var/lib/kolla/venv/lib/python3.9/site-packages/keystone/assignment/role_backends/sql.py", line 70, in get_role
2023-03-06 21:08:43.348728 2023-03-06 21:08:43.344 38 ERROR keystone.server.flask.application     return self._get_role(session, role_id).to_dict()
2023-03-06 21:08:43.348738 2023-03-06 21:08:43.344 38 ERROR keystone.server.flask.application   File "/var/lib/kolla/venv/lib/python3.9/site-packages/keystone/assignment/role_backends/sql.py", line 65, in _get_role
2023-03-06 21:08:43.348747 2023-03-06 21:08:43.344 38 ERROR keystone.server.flask.application     raise exception.RoleNotFound(role_id=role_id)
2023-03-06 21:08:43.348757 2023-03-06 21:08:43.344 38 ERROR keystone.server.flask.application keystone.exception.RoleNotFound: Could not find role: admin.
2023-03-06 21:08:43.348766 2023-03-06 21:08:43.344 38 ERROR keystone.server.flask.application \x1b[00m
2023-03-06 21:08:44.641895 2023-03-06 21:08:44.638 38 ERROR keystone.server.flask.application [None req-1b50a878-0fff-4eb4-afe6-f783f4cbca52 0ec98a772fae4111a46b99e8bc573150 - - all default -] Could not find user: neutron.: keystone.exception.UserNotFound: Could not find user: neutron.
2023-03-06 21:08:44.641940 2023-03-06 21:08:44.638 38 ERROR keystone.server.flask.application Traceback (most recent call last):
2023-03-06 21:08:44.641951 2023-03-06 21:08:44.638 38 ERROR keystone.server.flask.application   File "/var/lib/kolla/venv/lib/python3.9/site-packages/flask/app.py", line 1820, in full_dispatch_request
2023-03-06 21:08:44.641962 2023-03-06 21:08:44.638 38 ERROR keystone.server.flask.application     rv = self.dispatch_request()
2023-03-06 21:08:44.641971 2023-03-06 21:08:44.638 38 ERROR keystone.server.flask.application   File "/var/lib/kolla/venv/lib/python3.9/site-packages/flask/app.py", line 1796, in dispatch_request
2023-03-06 21:08:44.641981 2023-03-06 21:08:44.638 38 ERROR keystone.server.flask.application     return self.ensure_sync(self.view_functions[rule.endpoint])(**view_args)
2023-03-06 21:08:44.641990 2023-03-06 21:08:44.638 38 ERROR keystone.server.flask.application   File "/var/lib/kolla/venv/lib/python3.9/site-packages/flask_restful/__init__.py", line 467, in wrapper
2023-03-06 21:08:44.642000 2023-03-06 21:08:44.638 38 ERROR keystone.server.flask.application     resp = resource(*args, **kwargs)
2023-03-06 21:08:44.642009 2023-03-06 21:08:44.638 38 ERROR keystone.server.flask.application   File "/var/lib/kolla/venv/lib/python3.9/site-packages/flask/views.py", line 107, in view
2023-03-06 21:08:44.642020 2023-03-06 21:08:44.638 38 ERROR keystone.server.flask.application     return current_app.ensure_sync(self.dispatch_request)(**kwargs)
2023-03-06 21:08:44.642036 2023-03-06 21:08:44.638 38 ERROR keystone.server.flask.application   File "/var/lib/kolla/venv/lib/python3.9/site-packages/flask_restful/__init__.py", line 582, in dispatch_request
2023-03-06 21:08:44.642101 2023-03-06 21:08:44.638 38 ERROR keystone.server.flask.application     resp = meth(*args, **kwargs)
2023-03-06 21:08:44.642124 2023-03-06 21:08:44.638 38 ERROR keystone.server.flask.application   File "/var/lib/kolla/venv/lib/python3.9/site-packages/keystone/api/users.py", line 182, in get
2023-03-06 21:08:44.642145 2023-03-06 21:08:44.638 38 ERROR keystone.server.flask.application     return self._get_user(user_id)
2023-03-06 21:08:44.642165 2023-03-06 21:08:44.638 38 ERROR keystone.server.flask.application   File "/var/lib/kolla/venv/lib/python3.9/site-packages/keystone/api/users.py", line 194, in _get_user
2023-03-06 21:08:44.642242 2023-03-06 21:08:44.638 38 ERROR keystone.server.flask.application     ref = PROVIDERS.identity_api.get_user(user_id)
2023-03-06 21:08:44.642272 2023-03-06 21:08:44.638 38 ERROR keystone.server.flask.application   File "/var/lib/kolla/venv/lib/python3.9/site-packages/keystone/common/manager.py", line 115, in wrapped
2023-03-06 21:08:44.642291 2023-03-06 21:08:44.638 38 ERROR keystone.server.flask.application     __ret_val = __f(*args, **kwargs)
2023-03-06 21:08:44.642310 2023-03-06 21:08:44.638 38 ERROR keystone.server.flask.application   File "/var/lib/kolla/venv/lib/python3.9/site-packages/keystone/identity/core.py", line 414, in wrapper
2023-03-06 21:08:44.642332 2023-03-06 21:08:44.638 38 ERROR keystone.server.flask.application     return f(self, *args, **kwargs)
2023-03-06 21:08:44.642350 2023-03-06 21:08:44.638 38 ERROR keystone.server.flask.application   File "/var/lib/kolla/venv/lib/python3.9/site-packages/keystone/identity/core.py", line 424, in wrapper
2023-03-06 21:08:44.642368 2023-03-06 21:08:44.638 38 ERROR keystone.server.flask.application     return f(self, *args, **kwargs)
2023-03-06 21:08:44.642384 2023-03-06 21:08:44.638 38 ERROR keystone.server.flask.application   File "/var/lib/kolla/venv/lib/python3.9/site-packages/decorator.py", line 232, in fun
2023-03-06 21:08:44.642396 2023-03-06 21:08:44.638 38 ERROR keystone.server.flask.application     return caller(func, *(extras + args), **kw)
2023-03-06 21:08:44.642406 2023-03-06 21:08:44.638 38 ERROR keystone.server.flask.application   File "/var/lib/kolla/venv/lib/python3.9/site-packages/dogpile/cache/region.py", line 1577, in get_or_create_for_user_func
2023-03-06 21:08:44.642415 2023-03-06 21:08:44.638 38 ERROR keystone.server.flask.application     return self.get_or_create(
2023-03-06 21:08:44.642425 2023-03-06 21:08:44.638 38 ERROR keystone.server.flask.application   File "/var/lib/kolla/venv/lib/python3.9/site-packages/dogpile/cache/region.py", line 1042, in get_or_create
2023-03-06 21:08:44.642442 2023-03-06 21:08:44.638 38 ERROR keystone.server.flask.application     with Lock(
2023-03-06 21:08:44.642451 2023-03-06 21:08:44.638 38 ERROR keystone.server.flask.application   File "/var/lib/kolla/venv/lib/python3.9/site-packages/dogpile/lock.py", line 185, in __enter__
2023-03-06 21:08:44.642461 2023-03-06 21:08:44.638 38 ERROR keystone.server.flask.application     return self._enter()
2023-03-06 21:08:44.642470 2023-03-06 21:08:44.638 38 ERROR keystone.server.flask.application   File "/var/lib/kolla/venv/lib/python3.9/site-packages/dogpile/lock.py", line 94, in _enter
2023-03-06 21:08:44.642480 2023-03-06 21:08:44.638 38 ERROR keystone.server.flask.application     generated = self._enter_create(value, createdtime)
2023-03-06 21:08:44.642489 2023-03-06 21:08:44.638 38 ERROR keystone.server.flask.application   File "/var/lib/kolla/venv/lib/python3.9/site-packages/dogpile/lock.py", line 178, in _enter_create
2023-03-06 21:08:44.642499 2023-03-06 21:08:44.638 38 ERROR keystone.server.flask.application     return self.creator()
2023-03-06 21:08:44.642508 2023-03-06 21:08:44.638 38 ERROR keystone.server.flask.application   File "/var/lib/kolla/venv/lib/python3.9/site-packages/dogpile/cache/region.py", line 995, in gen_value
2023-03-06 21:08:44.642517 2023-03-06 21:08:44.638 38 ERROR keystone.server.flask.application     created_value = creator(
2023-03-06 21:08:44.642542 2023-03-06 21:08:44.638 38 ERROR keystone.server.flask.application   File "/var/lib/kolla/venv/lib/python3.9/site-packages/keystone/identity/core.py", line 1011, in get_user
2023-03-06 21:08:44.642553 2023-03-06 21:08:44.638 38 ERROR keystone.server.flask.application     ref = driver.get_user(entity_id)
2023-03-06 21:08:44.642563 2023-03-06 21:08:44.638 38 ERROR keystone.server.flask.application   File "/var/lib/kolla/venv/lib/python3.9/site-packages/keystone/identity/backends/sql.py", line 200, in get_user
2023-03-06 21:08:44.642572 2023-03-06 21:08:44.638 38 ERROR keystone.server.flask.application     self._get_user(session, user_id).to_dict())
2023-03-06 21:08:44.642582 2023-03-06 21:08:44.638 38 ERROR keystone.server.flask.application   File "/var/lib/kolla/venv/lib/python3.9/site-packages/keystone/identity/backends/sql.py", line 194, in _get_user
2023-03-06 21:08:44.642591 2023-03-06 21:08:44.638 38 ERROR keystone.server.flask.application     raise exception.UserNotFound(user_id=user_id)
2023-03-06 21:08:44.642601 2023-03-06 21:08:44.638 38 ERROR keystone.server.flask.application keystone.exception.UserNotFound: Could not find user: neutron.
2023-03-06 21:08:44.642610 2023-03-06 21:08:44.638 38 ERROR keystone.server.flask.application \x1b[00m
2023-03-06 21:08:45.529032 2023-03-06 21:08:45.526 38 ERROR keystone.server.flask.application [None req-8a9bd2da-0d23-4798-ac35-5cb7493f9892 0ec98a772fae4111a46b99e8bc573150 - - all default -] Could not find project: service.: keystone.exception.ProjectNotFound: Could not find project: service.
2023-03-06 21:08:45.529095 2023-03-06 21:08:45.526 38 ERROR keystone.server.flask.application Traceback (most recent call last):
2023-03-06 21:08:45.529106 2023-03-06 21:08:45.526 38 ERROR keystone.server.flask.application   File "/var/lib/kolla/venv/lib/python3.9/site-packages/flask/app.py", line 1820, in full_dispatch_request
2023-03-06 21:08:45.529116 2023-03-06 21:08:45.526 38 ERROR keystone.server.flask.application     rv = self.dispatch_request()
2023-03-06 21:08:45.529126 2023-03-06 21:08:45.526 38 ERROR keystone.server.flask.application   File "/var/lib/kolla/venv/lib/python3.9/site-packages/flask/app.py", line 1796, in dispatch_request
2023-03-06 21:08:45.529136 2023-03-06 21:08:45.526 38 ERROR keystone.server.flask.application     return self.ensure_sync(self.view_functions[rule.endpoint])(**view_args)
2023-03-06 21:08:45.529146 2023-03-06 21:08:45.526 38 ERROR keystone.server.flask.application   File "/var/lib/kolla/venv/lib/python3.9/site-packages/flask_restful/__init__.py", line 467, in wrapper
2023-03-06 21:08:45.529155 2023-03-06 21:08:45.526 38 ERROR keystone.server.flask.application     resp = resource(*args, **kwargs)
2023-03-06 21:08:45.529182 2023-03-06 21:08:45.526 38 ERROR keystone.server.flask.application   File "/var/lib/kolla/venv/lib/python3.9/site-packages/flask/views.py", line 107, in view
2023-03-06 21:08:45.529253 2023-03-06 21:08:45.526 38 ERROR keystone.server.flask.application     return current_app.ensure_sync(self.dispatch_request)(**kwargs)
2023-03-06 21:08:45.529265 2023-03-06 21:08:45.526 38 ERROR keystone.server.flask.application   File "/var/lib/kolla/venv/lib/python3.9/site-packages/flask_restful/__init__.py", line 582, in dispatch_request
2023-03-06 21:08:45.529275 2023-03-06 21:08:45.526 38 ERROR keystone.server.flask.application     resp = meth(*args, **kwargs)
2023-03-06 21:08:45.529284 2023-03-06 21:08:45.526 38 ERROR keystone.server.flask.application   File "/var/lib/kolla/venv/lib/python3.9/site-packages/keystone/api/projects.py", line 151, in get
2023-03-06 21:08:45.529294 2023-03-06 21:08:45.526 38 ERROR keystone.server.flask.application     return self._get_project(project_id)
2023-03-06 21:08:45.529303 2023-03-06 21:08:45.526 38 ERROR keystone.server.flask.application   File "/var/lib/kolla/venv/lib/python3.9/site-packages/keystone/api/projects.py", line 107, in _get_project
2023-03-06 21:08:45.529313 2023-03-06 21:08:45.526 38 ERROR keystone.server.flask.application     project = PROVIDERS.resource_api.get_project(project_id)
2023-03-06 21:08:45.529341 2023-03-06 21:08:45.526 38 ERROR keystone.server.flask.application   File "/var/lib/kolla/venv/lib/python3.9/site-packages/keystone/common/manager.py", line 115, in wrapped
2023-03-06 21:08:45.529352 2023-03-06 21:08:45.526 38 ERROR keystone.server.flask.application     __ret_val = __f(*args, **kwargs)
2023-03-06 21:08:45.529362 2023-03-06 21:08:45.526 38 ERROR keystone.server.flask.application   File "/var/lib/kolla/venv/lib/python3.9/site-packages/decorator.py", line 232, in fun
2023-03-06 21:08:45.529372 2023-03-06 21:08:45.526 38 ERROR keystone.server.flask.application     return caller(func, *(extras + args), **kw)
2023-03-06 21:08:45.529382 2023-03-06 21:08:45.526 38 ERROR keystone.server.flask.application   File "/var/lib/kolla/venv/lib/python3.9/site-packages/dogpile/cache/region.py", line 1577, in get_or_create_for_user_func
2023-03-06 21:08:45.529392 2023-03-06 21:08:45.526 38 ERROR keystone.server.flask.application     return self.get_or_create(
2023-03-06 21:08:45.529401 2023-03-06 21:08:45.526 38 ERROR keystone.server.flask.application   File "/var/lib/kolla/venv/lib/python3.9/site-packages/dogpile/cache/region.py", line 1042, in get_or_create
2023-03-06 21:08:45.529411 2023-03-06 21:08:45.526 38 ERROR keystone.server.flask.application     with Lock(
2023-03-06 21:08:45.529421 2023-03-06 21:08:45.526 38 ERROR keystone.server.flask.application   File "/var/lib/kolla/venv/lib/python3.9/site-packages/dogpile/lock.py", line 185, in __enter__
2023-03-06 21:08:45.529430 2023-03-06 21:08:45.526 38 ERROR keystone.server.flask.application     return self._enter()
2023-03-06 21:08:45.529440 2023-03-06 21:08:45.526 38 ERROR keystone.server.flask.application   File "/var/lib/kolla/venv/lib/python3.9/site-packages/dogpile/lock.py", line 94, in _enter
2023-03-06 21:08:45.529449 2023-03-06 21:08:45.526 38 ERROR keystone.server.flask.application     generated = self._enter_create(value, createdtime)
2023-03-06 21:08:45.529459 2023-03-06 21:08:45.526 38 ERROR keystone.server.flask.application   File "/var/lib/kolla/venv/lib/python3.9/site-packages/dogpile/lock.py", line 178, in _enter_create
2023-03-06 21:08:45.529468 2023-03-06 21:08:45.526 38 ERROR keystone.server.flask.application     return self.creator()
2023-03-06 21:08:45.529478 2023-03-06 21:08:45.526 38 ERROR keystone.server.flask.application   File "/var/lib/kolla/venv/lib/python3.9/site-packages/dogpile/cache/region.py", line 995, in gen_value
2023-03-06 21:08:45.529487 2023-03-06 21:08:45.526 38 ERROR keystone.server.flask.application     created_value = creator(
2023-03-06 21:08:45.529497 2023-03-06 21:08:45.526 38 ERROR keystone.server.flask.application   File "/var/lib/kolla/venv/lib/python3.9/site-packages/keystone/resource/core.py", line 903, in get_project
2023-03-06 21:08:45.529507 2023-03-06 21:08:45.526 38 ERROR keystone.server.flask.application     return self.driver.get_project(project_id)
2023-03-06 21:08:45.529516 2023-03-06 21:08:45.526 38 ERROR keystone.server.flask.application   File "/var/lib/kolla/venv/lib/python3.9/site-packages/keystone/resource/backends/sql.py", line 49, in get_project
2023-03-06 21:08:45.529526 2023-03-06 21:08:45.526 38 ERROR keystone.server.flask.application     return self._get_project(session, project_id).to_dict()
2023-03-06 21:08:45.529535 2023-03-06 21:08:45.526 38 ERROR keystone.server.flask.application   File "/var/lib/kolla/venv/lib/python3.9/site-packages/keystone/resource/backends/sql.py", line 44, in _get_project
2023-03-06 21:08:45.529545 2023-03-06 21:08:45.526 38 ERROR keystone.server.flask.application     raise exception.ProjectNotFound(project_id=project_id)
2023-03-06 21:08:45.529554 2023-03-06 21:08:45.526 38 ERROR keystone.server.flask.application keystone.exception.ProjectNotFound: Could not find project: service.
2023-03-06 21:08:45.529564 2023-03-06 21:08:45.526 38 ERROR keystone.server.flask.application \x1b[00m
2023-03-06 23:08:03.705513 2023-03-06 23:08:03.703 39 WARNING py.warnings [None req-ba47b1fd-91e9-4623-b30d-f3063ccaf31d 0ec98a772fae4111a46b99e8bc573150 afc0a2857dd84305b3a43c4673f9c8bc - - default default] /var/lib/kolla/venv/lib/python3.9/site-packages/oslo_policy/policy.py:1129: UserWarning: Policy "identity:list_domains": "role:reader and system_scope:all" failed scope check. The token used to make the request was project scoped but the policy requires ['system'] scope. This behavior may change in the future where using the intended scope is required
2023-03-06 23:08:03.705715   warnings.warn(msg)
2023-03-06 23:08:03.705731 \x1b[00m
2023-03-06 23:08:04.062804 2023-03-06 23:08:04.059 38 WARNING py.warnings [None req-1ed59a81-2979-4a8d-9a49-95b35661e923 0ec98a772fae4111a46b99e8bc573150 afc0a2857dd84305b3a43c4673f9c8bc - - default default] /var/lib/kolla/venv/lib/python3.9/site-packages/oslo_policy/policy.py:1129: UserWarning: Policy "identity:create_project": "(role:admin and system_scope:all) or (role:admin and domain_id:%(target.project.domain_id)s)" failed scope check. The token used to make the request was project scoped but the policy requires ['system', 'domain'] scope. This behavior may change in the future where using the intended scope is required
2023-03-06 23:08:04.062851   warnings.warn(msg)
2023-03-06 23:08:04.062863 \x1b[00m
2023-03-06 23:08:04.472450 2023-03-06 23:08:04.469 40 WARNING py.warnings [None req-8e1b4498-3c39-4b15-9910-ce325daccd28 0ec98a772fae4111a46b99e8bc573150 afc0a2857dd84305b3a43c4673f9c8bc - - default default] /var/lib/kolla/venv/lib/python3.9/site-packages/oslo_policy/policy.py:1129: UserWarning: Policy "identity:create_user": "(role:admin and system_scope:all) or (role:admin and token.domain.id:%(target.user.domain_id)s)" failed scope check. The token used to make the request was project scoped but the policy requires ['system', 'domain'] scope. This behavior may change in the future where using the intended scope is required
2023-03-06 23:08:04.472498   warnings.warn(msg)
2023-03-06 23:08:04.472511 \x1b[00m
2023-03-06 23:08:05.439869 2023-03-06 23:08:05.438 39 WARNING py.warnings [None req-cf09d976-c3c0-48b1-a7ee-ddd1292d758f 0ec98a772fae4111a46b99e8bc573150 afc0a2857dd84305b3a43c4673f9c8bc - - default default] /var/lib/kolla/venv/lib/python3.9/site-packages/oslo_policy/policy.py:1129: UserWarning: Policy "identity:list_roles": "role:reader and system_scope:all" failed scope check. The token used to make the request was project scoped but the policy requires ['system'] scope. This behavior may change in the future where using the intended scope is required
2023-03-06 23:08:05.439936   warnings.warn(msg)
2023-03-06 23:08:05.439954 \x1b[00m
2023-03-06 23:08:05.841833 2023-03-06 23:08:05.840 38 WARNING py.warnings [None req-a3b37516-82fe-40eb-9a6e-ad2e6dd195e5 0ec98a772fae4111a46b99e8bc573150 afc0a2857dd84305b3a43c4673f9c8bc - - default default] /var/lib/kolla/venv/lib/python3.9/site-packages/oslo_policy/policy.py:1129: UserWarning: Policy "identity:create_grant": "(role:admin and system_scope:all) or ((role:admin and domain_id:%(target.user.domain_id)s and domain_id:%(target.project.domain_id)s) or (role:admin and domain_id:%(target.user.domain_id)s and domain_id:%(target.domain.id)s) or (role:admin and domain_id:%(target.group.domain_id)s and domain_id:%(target.project.domain_id)s) or (role:admin and domain_id:%(target.group.domain_id)s and domain_id:%(target.domain.id)s)) and (domain_id:%(target.role.domain_id)s or None:%(target.role.domain_id)s)" failed scope check. The token used to make the request was project scoped but the policy requires ['system', 'domain'] scope. This behavior may change in the future where using the intended scope is required
2023-03-06 23:08:05.841882   warnings.warn(msg)
2023-03-06 23:08:05.841893 \x1b[00m
2023-03-06 23:08:07.112645 2023-03-06 23:08:07.111 39 WARNING py.warnings [None req-fd8f03cd-b46f-48b7-94cb-46a243531ccb 0ec98a772fae4111a46b99e8bc573150 afc0a2857dd84305b3a43c4673f9c8bc - - default default] /var/lib/kolla/venv/lib/python3.9/site-packages/oslo_policy/policy.py:1129: UserWarning: Policy "identity:create_project": "(role:admin and system_scope:all) or (role:admin and domain_id:%(target.project.domain_id)s)" failed scope check. The token used to make the request was project scoped but the policy requires ['system', 'domain'] scope. This behavior may change in the future where using the intended scope is required
2023-03-06 23:08:07.112742   warnings.warn(msg)
2023-03-06 23:08:07.112755 \x1b[00m
2023-03-06 23:08:07.625291 2023-03-06 23:08:07.624 38 WARNING py.warnings [None req-2ee6e5f4-bc7e-4643-b3c3-8e54af2fcee7 0ec98a772fae4111a46b99e8bc573150 afc0a2857dd84305b3a43c4673f9c8bc - - default default] /var/lib/kolla/venv/lib/python3.9/site-packages/oslo_policy/policy.py:1129: UserWarning: Policy "identity:create_user": "(role:admin and system_scope:all) or (role:admin and token.domain.id:%(target.user.domain_id)s)" failed scope check. The token used to make the request was project scoped but the policy requires ['system', 'domain'] scope. This behavior may change in the future where using the intended scope is required
2023-03-06 23:08:07.625373   warnings.warn(msg)
2023-03-06 23:08:07.625388 \x1b[00m
2023-03-06 23:08:08.723001 2023-03-06 23:08:08.721 40 WARNING py.warnings [None req-c8728b03-070e-4795-abf8-f897994f35a9 0ec98a772fae4111a46b99e8bc573150 afc0a2857dd84305b3a43c4673f9c8bc - - default default] /var/lib/kolla/venv/lib/python3.9/site-packages/oslo_policy/policy.py:1129: UserWarning: Policy "identity:list_roles": "role:reader and system_scope:all" failed scope check. The token used to make the request was project scoped but the policy requires ['system'] scope. This behavior may change in the future where using the intended scope is required
2023-03-06 23:08:08.723065   warnings.warn(msg)
2023-03-06 23:08:08.723076 \x1b[00m
2023-03-06 23:08:09.111665 2023-03-06 23:08:09.109 39 WARNING py.warnings [None req-d1431a18-25a5-44a4-becf-120dc3e2b067 0ec98a772fae4111a46b99e8bc573150 afc0a2857dd84305b3a43c4673f9c8bc - - default default] /var/lib/kolla/venv/lib/python3.9/site-packages/oslo_policy/policy.py:1129: UserWarning: Policy "identity:create_grant": "(role:admin and system_scope:all) or ((role:admin and domain_id:%(target.user.domain_id)s and domain_id:%(target.project.domain_id)s) or (role:admin and domain_id:%(target.user.domain_id)s and domain_id:%(target.domain.id)s) or (role:admin and domain_id:%(target.group.domain_id)s and domain_id:%(target.project.domain_id)s) or (role:admin and domain_id:%(target.group.domain_id)s and domain_id:%(target.domain.id)s)) and (domain_id:%(target.role.domain_id)s or None:%(target.role.domain_id)s)" failed scope check. The token used to make the request was project scoped but the policy requires ['system', 'domain'] scope. This behavior may change in the future where using the intended scope is required
2023-03-06 23:08:09.111739   warnings.warn(msg)
2023-03-06 23:08:09.111771 \x1b[00m
2023-03-06 23:08:09.346139 2023-03-06 23:08:09.345 38 WARNING py.warnings [None req-83f3a58a-91b8-4ab9-8e2d-faf5031b023a 0ec98a772fae4111a46b99e8bc573150 afc0a2857dd84305b3a43c4673f9c8bc - - default default] /var/lib/kolla/venv/lib/python3.9/site-packages/oslo_policy/policy.py:1129: UserWarning: Policy "identity:list_roles": "role:reader and system_scope:all" failed scope check. The token used to make the request was project scoped but the policy requires ['system'] scope. This behavior may change in the future where using the intended scope is required
2023-03-06 23:08:09.346185   warnings.warn(msg)
2023-03-06 23:08:09.346254 \x1b[00m
2023-03-06 23:08:09.683678 2023-03-06 23:08:09.682 40 WARNING py.warnings [None req-52a059f0-250f-41f3-a09a-6ed1bc703fbd 0ec98a772fae4111a46b99e8bc573150 afc0a2857dd84305b3a43c4673f9c8bc - - default default] /var/lib/kolla/venv/lib/python3.9/site-packages/oslo_policy/policy.py:1129: UserWarning: Policy "identity:create_grant": "(role:admin and system_scope:all) or ((role:admin and domain_id:%(target.user.domain_id)s and domain_id:%(target.project.domain_id)s) or (role:admin and domain_id:%(target.user.domain_id)s and domain_id:%(target.domain.id)s) or (role:admin and domain_id:%(target.group.domain_id)s and domain_id:%(target.project.domain_id)s) or (role:admin and domain_id:%(target.group.domain_id)s and domain_id:%(target.domain.id)s)) and (domain_id:%(target.role.domain_id)s or None:%(target.role.domain_id)s)" failed scope check. The token used to make the request was project scoped but the policy requires ['system', 'domain'] scope. This behavior may change in the future where using the intended scope is required
2023-03-06 23:08:09.683795   warnings.warn(msg)
2023-03-06 23:08:09.683808 \x1b[00m
2023-03-06 23:08:12.126429 2023-03-06 23:08:12.124 39 WARNING py.warnings [None req-7d4dfd86-dc9c-40c9-8550-4e6141a7e1fa 0ec98a772fae4111a46b99e8bc573150 afc0a2857dd84305b3a43c4673f9c8bc - - default default] /var/lib/kolla/venv/lib/python3.9/site-packages/oslo_policy/policy.py:1129: UserWarning: Policy "identity:create_system_grant_for_user": "role:admin and system_scope:all" failed scope check. The token used to make the request was project scoped but the policy requires ['system'] scope. This behavior may change in the future where using the intended scope is required
2023-03-06 23:08:12.126487   warnings.warn(msg)
2023-03-06 23:08:12.126501 \x1b[00m
