2023-04-06 19:00:42.535064 2023-04-06 19:00:42.533 28 WARNING keystone.common.rbac_enforcer.enforcer [None req-ac31fdfb-1179-46db-aa45-a186ce64a5f0 90e9542438684429b47beb5fc0bae2d1 - - all default -] Deprecated policy rules found. Use oslopolicy-policy-generator and oslopolicy-policy-upgrade to detect and resolve deprecated policies in your configuration.\x1b[00m
2023-04-06 19:00:43.385519 2023-04-06 19:00:43.384 27 WARNING keystone.common.rbac_enforcer.enforcer [None req-545bffbb-90d6-4a5f-9806-b16d1975d82c 90e9542438684429b47beb5fc0bae2d1 - - all default -] Deprecated policy rules found. Use oslopolicy-policy-generator and oslopolicy-policy-upgrade to detect and resolve deprecated policies in your configuration.\x1b[00m
2023-04-06 19:00:51.487129 2023-04-06 19:00:51.485 26 WARNING keystone.common.rbac_enforcer.enforcer [None req-0a531bf2-cc6c-493f-b02b-a4e3750b4586 90e9542438684429b47beb5fc0bae2d1 - - all default -] Deprecated policy rules found. Use oslopolicy-policy-generator and oslopolicy-policy-upgrade to detect and resolve deprecated policies in your configuration.\x1b[00m
2023-04-06 19:02:12.716732 2023-04-06 19:02:12.671 28 ERROR keystone.server.flask.application [None req-94941e68-78a5-4cbe-97a5-5d2e298a3b20 90e9542438684429b47beb5fc0bae2d1 - - all default -] Could not find project: service.: keystone.exception.ProjectNotFound: Could not find project: service.
2023-04-06 19:02:12.716793 2023-04-06 19:02:12.671 28 ERROR keystone.server.flask.application Traceback (most recent call last):
2023-04-06 19:02:12.716806 2023-04-06 19:02:12.671 28 ERROR keystone.server.flask.application   File "/var/lib/kolla/venv/lib/python3.9/site-packages/flask/app.py", line 1820, in full_dispatch_request
2023-04-06 19:02:12.716816 2023-04-06 19:02:12.671 28 ERROR keystone.server.flask.application     rv = self.dispatch_request()
2023-04-06 19:02:12.716826 2023-04-06 19:02:12.671 28 ERROR keystone.server.flask.application   File "/var/lib/kolla/venv/lib/python3.9/site-packages/flask/app.py", line 1796, in dispatch_request
2023-04-06 19:02:12.716836 2023-04-06 19:02:12.671 28 ERROR keystone.server.flask.application     return self.ensure_sync(self.view_functions[rule.endpoint])(**view_args)
2023-04-06 19:02:12.716846 2023-04-06 19:02:12.671 28 ERROR keystone.server.flask.application   File "/var/lib/kolla/venv/lib/python3.9/site-packages/flask_restful/__init__.py", line 467, in wrapper
2023-04-06 19:02:12.716855 2023-04-06 19:02:12.671 28 ERROR keystone.server.flask.application     resp = resource(*args, **kwargs)
2023-04-06 19:02:12.716865 2023-04-06 19:02:12.671 28 ERROR keystone.server.flask.application   File "/var/lib/kolla/venv/lib/python3.9/site-packages/flask/views.py", line 107, in view
2023-04-06 19:02:12.716875 2023-04-06 19:02:12.671 28 ERROR keystone.server.flask.application     return current_app.ensure_sync(self.dispatch_request)(**kwargs)
2023-04-06 19:02:12.716884 2023-04-06 19:02:12.671 28 ERROR keystone.server.flask.application   File "/var/lib/kolla/venv/lib/python3.9/site-packages/flask_restful/__init__.py", line 582, in dispatch_request
2023-04-06 19:02:12.716893 2023-04-06 19:02:12.671 28 ERROR keystone.server.flask.application     resp = meth(*args, **kwargs)
2023-04-06 19:02:12.716902 2023-04-06 19:02:12.671 28 ERROR keystone.server.flask.application   File "/var/lib/kolla/venv/lib/python3.9/site-packages/keystone/api/projects.py", line 151, in get
2023-04-06 19:02:12.716912 2023-04-06 19:02:12.671 28 ERROR keystone.server.flask.application     return self._get_project(project_id)
2023-04-06 19:02:12.716921 2023-04-06 19:02:12.671 28 ERROR keystone.server.flask.application   File "/var/lib/kolla/venv/lib/python3.9/site-packages/keystone/api/projects.py", line 107, in _get_project
2023-04-06 19:02:12.716931 2023-04-06 19:02:12.671 28 ERROR keystone.server.flask.application     project = PROVIDERS.resource_api.get_project(project_id)
2023-04-06 19:02:12.716940 2023-04-06 19:02:12.671 28 ERROR keystone.server.flask.application   File "/var/lib/kolla/venv/lib/python3.9/site-packages/keystone/common/manager.py", line 115, in wrapped
2023-04-06 19:02:12.716978 2023-04-06 19:02:12.671 28 ERROR keystone.server.flask.application     __ret_val = __f(*args, **kwargs)
2023-04-06 19:02:12.716990 2023-04-06 19:02:12.671 28 ERROR keystone.server.flask.application   File "/var/lib/kolla/venv/lib/python3.9/site-packages/decorator.py", line 232, in fun
2023-04-06 19:02:12.717000 2023-04-06 19:02:12.671 28 ERROR keystone.server.flask.application     return caller(func, *(extras + args), **kw)
2023-04-06 19:02:12.717010 2023-04-06 19:02:12.671 28 ERROR keystone.server.flask.application   File "/var/lib/kolla/venv/lib/python3.9/site-packages/dogpile/cache/region.py", line 1577, in get_or_create_for_user_func
2023-04-06 19:02:12.717019 2023-04-06 19:02:12.671 28 ERROR keystone.server.flask.application     return self.get_or_create(
2023-04-06 19:02:12.717029 2023-04-06 19:02:12.671 28 ERROR keystone.server.flask.application   File "/var/lib/kolla/venv/lib/python3.9/site-packages/dogpile/cache/region.py", line 1042, in get_or_create
2023-04-06 19:02:12.717038 2023-04-06 19:02:12.671 28 ERROR keystone.server.flask.application     with Lock(
2023-04-06 19:02:12.717050 2023-04-06 19:02:12.671 28 ERROR keystone.server.flask.application   File "/var/lib/kolla/venv/lib/python3.9/site-packages/dogpile/lock.py", line 185, in __enter__
2023-04-06 19:02:12.717060 2023-04-06 19:02:12.671 28 ERROR keystone.server.flask.application     return self._enter()
2023-04-06 19:02:12.717069 2023-04-06 19:02:12.671 28 ERROR keystone.server.flask.application   File "/var/lib/kolla/venv/lib/python3.9/site-packages/dogpile/lock.py", line 94, in _enter
2023-04-06 19:02:12.717078 2023-04-06 19:02:12.671 28 ERROR keystone.server.flask.application     generated = self._enter_create(value, createdtime)
2023-04-06 19:02:12.717087 2023-04-06 19:02:12.671 28 ERROR keystone.server.flask.application   File "/var/lib/kolla/venv/lib/python3.9/site-packages/dogpile/lock.py", line 178, in _enter_create
2023-04-06 19:02:12.717097 2023-04-06 19:02:12.671 28 ERROR keystone.server.flask.application     return self.creator()
2023-04-06 19:02:12.717106 2023-04-06 19:02:12.671 28 ERROR keystone.server.flask.application   File "/var/lib/kolla/venv/lib/python3.9/site-packages/dogpile/cache/region.py", line 995, in gen_value
2023-04-06 19:02:12.717115 2023-04-06 19:02:12.671 28 ERROR keystone.server.flask.application     created_value = creator(
2023-04-06 19:02:12.717124 2023-04-06 19:02:12.671 28 ERROR keystone.server.flask.application   File "/var/lib/kolla/venv/lib/python3.9/site-packages/keystone/resource/core.py", line 903, in get_project
2023-04-06 19:02:12.717134 2023-04-06 19:02:12.671 28 ERROR keystone.server.flask.application     return self.driver.get_project(project_id)
2023-04-06 19:02:12.717143 2023-04-06 19:02:12.671 28 ERROR keystone.server.flask.application   File "/var/lib/kolla/venv/lib/python3.9/site-packages/keystone/resource/backends/sql.py", line 49, in get_project
2023-04-06 19:02:12.717152 2023-04-06 19:02:12.671 28 ERROR keystone.server.flask.application     return self._get_project(session, project_id).to_dict()
2023-04-06 19:02:12.717162 2023-04-06 19:02:12.671 28 ERROR keystone.server.flask.application   File "/var/lib/kolla/venv/lib/python3.9/site-packages/keystone/resource/backends/sql.py", line 44, in _get_project
2023-04-06 19:02:12.717171 2023-04-06 19:02:12.671 28 ERROR keystone.server.flask.application     raise exception.ProjectNotFound(project_id=project_id)
2023-04-06 19:02:12.717180 2023-04-06 19:02:12.671 28 ERROR keystone.server.flask.application keystone.exception.ProjectNotFound: Could not find project: service.
2023-04-06 19:02:12.717189 2023-04-06 19:02:12.671 28 ERROR keystone.server.flask.application \x1b[00m
2023-04-06 19:02:22.528482 2023-04-06 19:02:22.514 26 ERROR keystone.server.flask.application [None req-ded5c87f-f249-4b47-a4ba-bb85cd108cd8 90e9542438684429b47beb5fc0bae2d1 - - all default -] Could not find project: service.: keystone.exception.ProjectNotFound: Could not find project: service.
2023-04-06 19:02:22.528557 2023-04-06 19:02:22.514 26 ERROR keystone.server.flask.application Traceback (most recent call last):
2023-04-06 19:02:22.528586 2023-04-06 19:02:22.514 26 ERROR keystone.server.flask.application   File "/var/lib/kolla/venv/lib/python3.9/site-packages/flask/app.py", line 1820, in full_dispatch_request
2023-04-06 19:02:22.528598 2023-04-06 19:02:22.514 26 ERROR keystone.server.flask.application     rv = self.dispatch_request()
2023-04-06 19:02:22.528607 2023-04-06 19:02:22.514 26 ERROR keystone.server.flask.application   File "/var/lib/kolla/venv/lib/python3.9/site-packages/flask/app.py", line 1796, in dispatch_request
2023-04-06 19:02:22.528617 2023-04-06 19:02:22.514 26 ERROR keystone.server.flask.application     return self.ensure_sync(self.view_functions[rule.endpoint])(**view_args)
2023-04-06 19:02:22.528627 2023-04-06 19:02:22.514 26 ERROR keystone.server.flask.application   File "/var/lib/kolla/venv/lib/python3.9/site-packages/flask_restful/__init__.py", line 467, in wrapper
2023-04-06 19:02:22.528636 2023-04-06 19:02:22.514 26 ERROR keystone.server.flask.application     resp = resource(*args, **kwargs)
2023-04-06 19:02:22.528653 2023-04-06 19:02:22.514 26 ERROR keystone.server.flask.application   File "/var/lib/kolla/venv/lib/python3.9/site-packages/flask/views.py", line 107, in view
2023-04-06 19:02:22.528666 2023-04-06 19:02:22.514 26 ERROR keystone.server.flask.application     return current_app.ensure_sync(self.dispatch_request)(**kwargs)
2023-04-06 19:02:22.528675 2023-04-06 19:02:22.514 26 ERROR keystone.server.flask.application   File "/var/lib/kolla/venv/lib/python3.9/site-packages/flask_restful/__init__.py", line 582, in dispatch_request
2023-04-06 19:02:22.528685 2023-04-06 19:02:22.514 26 ERROR keystone.server.flask.application     resp = meth(*args, **kwargs)
2023-04-06 19:02:22.528694 2023-04-06 19:02:22.514 26 ERROR keystone.server.flask.application   File "/var/lib/kolla/venv/lib/python3.9/site-packages/keystone/api/projects.py", line 151, in get
2023-04-06 19:02:22.528703 2023-04-06 19:02:22.514 26 ERROR keystone.server.flask.application     return self._get_project(project_id)
2023-04-06 19:02:22.528712 2023-04-06 19:02:22.514 26 ERROR keystone.server.flask.application   File "/var/lib/kolla/venv/lib/python3.9/site-packages/keystone/api/projects.py", line 107, in _get_project
2023-04-06 19:02:22.528722 2023-04-06 19:02:22.514 26 ERROR keystone.server.flask.application     project = PROVIDERS.resource_api.get_project(project_id)
2023-04-06 19:02:22.528731 2023-04-06 19:02:22.514 26 ERROR keystone.server.flask.application   File "/var/lib/kolla/venv/lib/python3.9/site-packages/keystone/common/manager.py", line 115, in wrapped
2023-04-06 19:02:22.528740 2023-04-06 19:02:22.514 26 ERROR keystone.server.flask.application     __ret_val = __f(*args, **kwargs)
2023-04-06 19:02:22.528749 2023-04-06 19:02:22.514 26 ERROR keystone.server.flask.application   File "/var/lib/kolla/venv/lib/python3.9/site-packages/decorator.py", line 232, in fun
2023-04-06 19:02:22.528761 2023-04-06 19:02:22.514 26 ERROR keystone.server.flask.application     return caller(func, *(extras + args), **kw)
2023-04-06 19:02:22.528785 2023-04-06 19:02:22.514 26 ERROR keystone.server.flask.application   File "/var/lib/kolla/venv/lib/python3.9/site-packages/dogpile/cache/region.py", line 1577, in get_or_create_for_user_func
2023-04-06 19:02:22.528795 2023-04-06 19:02:22.514 26 ERROR keystone.server.flask.application     return self.get_or_create(
2023-04-06 19:02:22.528804 2023-04-06 19:02:22.514 26 ERROR keystone.server.flask.application   File "/var/lib/kolla/venv/lib/python3.9/site-packages/dogpile/cache/region.py", line 1042, in get_or_create
2023-04-06 19:02:22.528814 2023-04-06 19:02:22.514 26 ERROR keystone.server.flask.application     with Lock(
2023-04-06 19:02:22.528823 2023-04-06 19:02:22.514 26 ERROR keystone.server.flask.application   File "/var/lib/kolla/venv/lib/python3.9/site-packages/dogpile/lock.py", line 185, in __enter__
2023-04-06 19:02:22.528832 2023-04-06 19:02:22.514 26 ERROR keystone.server.flask.application     return self._enter()
2023-04-06 19:02:22.528854 2023-04-06 19:02:22.514 26 ERROR keystone.server.flask.application   File "/var/lib/kolla/venv/lib/python3.9/site-packages/dogpile/lock.py", line 94, in _enter
2023-04-06 19:02:22.528865 2023-04-06 19:02:22.514 26 ERROR keystone.server.flask.application     generated = self._enter_create(value, createdtime)
2023-04-06 19:02:22.528874 2023-04-06 19:02:22.514 26 ERROR keystone.server.flask.application   File "/var/lib/kolla/venv/lib/python3.9/site-packages/dogpile/lock.py", line 178, in _enter_create
2023-04-06 19:02:22.528883 2023-04-06 19:02:22.514 26 ERROR keystone.server.flask.application     return self.creator()
2023-04-06 19:02:22.528892 2023-04-06 19:02:22.514 26 ERROR keystone.server.flask.application   File "/var/lib/kolla/venv/lib/python3.9/site-packages/dogpile/cache/region.py", line 995, in gen_value
2023-04-06 19:02:22.528902 2023-04-06 19:02:22.514 26 ERROR keystone.server.flask.application     created_value = creator(
2023-04-06 19:02:22.528911 2023-04-06 19:02:22.514 26 ERROR keystone.server.flask.application   File "/var/lib/kolla/venv/lib/python3.9/site-packages/keystone/resource/core.py", line 903, in get_project
2023-04-06 19:02:22.528921 2023-04-06 19:02:22.514 26 ERROR keystone.server.flask.application     return self.driver.get_project(project_id)
2023-04-06 19:02:22.528930 2023-04-06 19:02:22.514 26 ERROR keystone.server.flask.application   File "/var/lib/kolla/venv/lib/python3.9/site-packages/keystone/resource/backends/sql.py", line 49, in get_project
2023-04-06 19:02:22.528939 2023-04-06 19:02:22.514 26 ERROR keystone.server.flask.application     return self._get_project(session, project_id).to_dict()
2023-04-06 19:02:22.528948 2023-04-06 19:02:22.514 26 ERROR keystone.server.flask.application   File "/var/lib/kolla/venv/lib/python3.9/site-packages/keystone/resource/backends/sql.py", line 44, in _get_project
2023-04-06 19:02:22.528958 2023-04-06 19:02:22.514 26 ERROR keystone.server.flask.application     raise exception.ProjectNotFound(project_id=project_id)
2023-04-06 19:02:22.528967 2023-04-06 19:02:22.514 26 ERROR keystone.server.flask.application keystone.exception.ProjectNotFound: Could not find project: service.
2023-04-06 19:02:22.528976 2023-04-06 19:02:22.514 26 ERROR keystone.server.flask.application \x1b[00m
2023-04-06 19:02:38.640213 2023-04-06 19:02:38.633 26 ERROR keystone.server.flask.application [None req-6c97cf92-56f1-4694-add0-4f0cc9f789e0 90e9542438684429b47beb5fc0bae2d1 - - all default -] Could not find role: admin.: keystone.exception.RoleNotFound: Could not find role: admin.
2023-04-06 19:02:38.640268 2023-04-06 19:02:38.633 26 ERROR keystone.server.flask.application Traceback (most recent call last):
2023-04-06 19:02:38.640281 2023-04-06 19:02:38.633 26 ERROR keystone.server.flask.application   File "/var/lib/kolla/venv/lib/python3.9/site-packages/flask/app.py", line 1820, in full_dispatch_request
2023-04-06 19:02:38.640291 2023-04-06 19:02:38.633 26 ERROR keystone.server.flask.application     rv = self.dispatch_request()
2023-04-06 19:02:38.640300 2023-04-06 19:02:38.633 26 ERROR keystone.server.flask.application   File "/var/lib/kolla/venv/lib/python3.9/site-packages/flask/app.py", line 1796, in dispatch_request
2023-04-06 19:02:38.640310 2023-04-06 19:02:38.633 26 ERROR keystone.server.flask.application     return self.ensure_sync(self.view_functions[rule.endpoint])(**view_args)
2023-04-06 19:02:38.640319 2023-04-06 19:02:38.633 26 ERROR keystone.server.flask.application   File "/var/lib/kolla/venv/lib/python3.9/site-packages/flask_restful/__init__.py", line 467, in wrapper
2023-04-06 19:02:38.640329 2023-04-06 19:02:38.633 26 ERROR keystone.server.flask.application     resp = resource(*args, **kwargs)
2023-04-06 19:02:38.640344 2023-04-06 19:02:38.633 26 ERROR keystone.server.flask.application   File "/var/lib/kolla/venv/lib/python3.9/site-packages/flask/views.py", line 107, in view
2023-04-06 19:02:38.640356 2023-04-06 19:02:38.633 26 ERROR keystone.server.flask.application     return current_app.ensure_sync(self.dispatch_request)(**kwargs)
2023-04-06 19:02:38.640366 2023-04-06 19:02:38.633 26 ERROR keystone.server.flask.application   File "/var/lib/kolla/venv/lib/python3.9/site-packages/flask_restful/__init__.py", line 582, in dispatch_request
2023-04-06 19:02:38.640398 2023-04-06 19:02:38.633 26 ERROR keystone.server.flask.application     resp = meth(*args, **kwargs)
2023-04-06 19:02:38.640409 2023-04-06 19:02:38.633 26 ERROR keystone.server.flask.application   File "/var/lib/kolla/venv/lib/python3.9/site-packages/keystone/api/roles.py", line 50, in get
2023-04-06 19:02:38.640419 2023-04-06 19:02:38.633 26 ERROR keystone.server.flask.application     return self._get_role(role_id)
2023-04-06 19:02:38.640494 2023-04-06 19:02:38.633 26 ERROR keystone.server.flask.application   File "/var/lib/kolla/venv/lib/python3.9/site-packages/keystone/api/roles.py", line 70, in _get_role
2023-04-06 19:02:38.640505 2023-04-06 19:02:38.633 26 ERROR keystone.server.flask.application     ENFORCER.enforce_call(action='identity:get_role')
2023-04-06 19:02:38.640515 2023-04-06 19:02:38.633 26 ERROR keystone.server.flask.application   File "/var/lib/kolla/venv/lib/python3.9/site-packages/keystone/common/rbac_enforcer/enforcer.py", line 402, in enforce_call
2023-04-06 19:02:38.640524 2023-04-06 19:02:38.633 26 ERROR keystone.server.flask.application     policy_dict.update(cls._extract_member_target_data(
2023-04-06 19:02:38.640541 2023-04-06 19:02:38.633 26 ERROR keystone.server.flask.application   File "/var/lib/kolla/venv/lib/python3.9/site-packages/keystone/common/rbac_enforcer/enforcer.py", line 234, in _extract_member_target_data
2023-04-06 19:02:38.640554 2023-04-06 19:02:38.633 26 ERROR keystone.server.flask.application     member_name: func(flask.request.view_args[key])
2023-04-06 19:02:38.640563 2023-04-06 19:02:38.633 26 ERROR keystone.server.flask.application   File "/var/lib/kolla/venv/lib/python3.9/site-packages/keystone/common/manager.py", line 115, in wrapped
2023-04-06 19:02:38.640572 2023-04-06 19:02:38.633 26 ERROR keystone.server.flask.application     __ret_val = __f(*args, **kwargs)
2023-04-06 19:02:38.640582 2023-04-06 19:02:38.633 26 ERROR keystone.server.flask.application   File "/var/lib/kolla/venv/lib/python3.9/site-packages/decorator.py", line 232, in fun
2023-04-06 19:02:38.640591 2023-04-06 19:02:38.633 26 ERROR keystone.server.flask.application     return caller(func, *(extras + args), **kw)
2023-04-06 19:02:38.640600 2023-04-06 19:02:38.633 26 ERROR keystone.server.flask.application   File "/var/lib/kolla/venv/lib/python3.9/site-packages/dogpile/cache/region.py", line 1577, in get_or_create_for_user_func
2023-04-06 19:02:38.640610 2023-04-06 19:02:38.633 26 ERROR keystone.server.flask.application     return self.get_or_create(
2023-04-06 19:02:38.640619 2023-04-06 19:02:38.633 26 ERROR keystone.server.flask.application   File "/var/lib/kolla/venv/lib/python3.9/site-packages/dogpile/cache/region.py", line 1042, in get_or_create
2023-04-06 19:02:38.640628 2023-04-06 19:02:38.633 26 ERROR keystone.server.flask.application     with Lock(
2023-04-06 19:02:38.640638 2023-04-06 19:02:38.633 26 ERROR keystone.server.flask.application   File "/var/lib/kolla/venv/lib/python3.9/site-packages/dogpile/lock.py", line 185, in __enter__
2023-04-06 19:02:38.640647 2023-04-06 19:02:38.633 26 ERROR keystone.server.flask.application     return self._enter()
2023-04-06 19:02:38.640656 2023-04-06 19:02:38.633 26 ERROR keystone.server.flask.application   File "/var/lib/kolla/venv/lib/python3.9/site-packages/dogpile/lock.py", line 94, in _enter
2023-04-06 19:02:38.640665 2023-04-06 19:02:38.633 26 ERROR keystone.server.flask.application     generated = self._enter_create(value, createdtime)
2023-04-06 19:02:38.640674 2023-04-06 19:02:38.633 26 ERROR keystone.server.flask.application   File "/var/lib/kolla/venv/lib/python3.9/site-packages/dogpile/lock.py", line 178, in _enter_create
2023-04-06 19:02:38.640684 2023-04-06 19:02:38.633 26 ERROR keystone.server.flask.application     return self.creator()
2023-04-06 19:02:38.640692 2023-04-06 19:02:38.633 26 ERROR keystone.server.flask.application   File "/var/lib/kolla/venv/lib/python3.9/site-packages/dogpile/cache/region.py", line 995, in gen_value
2023-04-06 19:02:38.640724 2023-04-06 19:02:38.633 26 ERROR keystone.server.flask.application     created_value = creator(
2023-04-06 19:02:38.640736 2023-04-06 19:02:38.633 26 ERROR keystone.server.flask.application   File "/var/lib/kolla/venv/lib/python3.9/site-packages/keystone/assignment/core.py", line 1276, in get_role
2023-04-06 19:02:38.640746 2023-04-06 19:02:38.633 26 ERROR keystone.server.flask.application     return self.driver.get_role(role_id)
2023-04-06 19:02:38.640755 2023-04-06 19:02:38.633 26 ERROR keystone.server.flask.application   File "/var/lib/kolla/venv/lib/python3.9/site-packages/keystone/assignment/role_backends/sql.py", line 70, in get_role
2023-04-06 19:02:38.640765 2023-04-06 19:02:38.633 26 ERROR keystone.server.flask.application     return self._get_role(session, role_id).to_dict()
2023-04-06 19:02:38.640774 2023-04-06 19:02:38.633 26 ERROR keystone.server.flask.application   File "/var/lib/kolla/venv/lib/python3.9/site-packages/keystone/assignment/role_backends/sql.py", line 65, in _get_role
2023-04-06 19:02:38.640784 2023-04-06 19:02:38.633 26 ERROR keystone.server.flask.application     raise exception.RoleNotFound(role_id=role_id)
2023-04-06 19:02:38.640793 2023-04-06 19:02:38.633 26 ERROR keystone.server.flask.application keystone.exception.RoleNotFound: Could not find role: admin.
2023-04-06 19:02:38.640803 2023-04-06 19:02:38.633 26 ERROR keystone.server.flask.application \x1b[00m
2023-04-06 19:02:39.871590 2023-04-06 19:02:39.865 26 ERROR keystone.server.flask.application [None req-849bbd59-a01b-49c1-a009-ea83ead7446f 90e9542438684429b47beb5fc0bae2d1 - - all default -] Could not find user: ironic.: keystone.exception.UserNotFound: Could not find user: ironic.
2023-04-06 19:02:39.871633 2023-04-06 19:02:39.865 26 ERROR keystone.server.flask.application Traceback (most recent call last):
2023-04-06 19:02:39.871644 2023-04-06 19:02:39.865 26 ERROR keystone.server.flask.application   File "/var/lib/kolla/venv/lib/python3.9/site-packages/flask/app.py", line 1820, in full_dispatch_request
2023-04-06 19:02:39.871654 2023-04-06 19:02:39.865 26 ERROR keystone.server.flask.application     rv = self.dispatch_request()
2023-04-06 19:02:39.871668 2023-04-06 19:02:39.865 26 ERROR keystone.server.flask.application   File "/var/lib/kolla/venv/lib/python3.9/site-packages/flask/app.py", line 1796, in dispatch_request
2023-04-06 19:02:39.871681 2023-04-06 19:02:39.865 26 ERROR keystone.server.flask.application     return self.ensure_sync(self.view_functions[rule.endpoint])(**view_args)
2023-04-06 19:02:39.871690 2023-04-06 19:02:39.865 26 ERROR keystone.server.flask.application   File "/var/lib/kolla/venv/lib/python3.9/site-packages/flask_restful/__init__.py", line 467, in wrapper
2023-04-06 19:02:39.871699 2023-04-06 19:02:39.865 26 ERROR keystone.server.flask.application     resp = resource(*args, **kwargs)
2023-04-06 19:02:39.871709 2023-04-06 19:02:39.865 26 ERROR keystone.server.flask.application   File "/var/lib/kolla/venv/lib/python3.9/site-packages/flask/views.py", line 107, in view
2023-04-06 19:02:39.871719 2023-04-06 19:02:39.865 26 ERROR keystone.server.flask.application     return current_app.ensure_sync(self.dispatch_request)(**kwargs)
2023-04-06 19:02:39.871728 2023-04-06 19:02:39.865 26 ERROR keystone.server.flask.application   File "/var/lib/kolla/venv/lib/python3.9/site-packages/flask_restful/__init__.py", line 582, in dispatch_request
2023-04-06 19:02:39.871737 2023-04-06 19:02:39.865 26 ERROR keystone.server.flask.application     resp = meth(*args, **kwargs)
2023-04-06 19:02:39.871746 2023-04-06 19:02:39.865 26 ERROR keystone.server.flask.application   File "/var/lib/kolla/venv/lib/python3.9/site-packages/keystone/api/users.py", line 182, in get
2023-04-06 19:02:39.871756 2023-04-06 19:02:39.865 26 ERROR keystone.server.flask.application     return self._get_user(user_id)
2023-04-06 19:02:39.871765 2023-04-06 19:02:39.865 26 ERROR keystone.server.flask.application   File "/var/lib/kolla/venv/lib/python3.9/site-packages/keystone/api/users.py", line 194, in _get_user
2023-04-06 19:02:39.871804 2023-04-06 19:02:39.865 26 ERROR keystone.server.flask.application     ref = PROVIDERS.identity_api.get_user(user_id)
2023-04-06 19:02:39.871825 2023-04-06 19:02:39.865 26 ERROR keystone.server.flask.application   File "/var/lib/kolla/venv/lib/python3.9/site-packages/keystone/common/manager.py", line 115, in wrapped
2023-04-06 19:02:39.871835 2023-04-06 19:02:39.865 26 ERROR keystone.server.flask.application     __ret_val = __f(*args, **kwargs)
2023-04-06 19:02:39.871844 2023-04-06 19:02:39.865 26 ERROR keystone.server.flask.application   File "/var/lib/kolla/venv/lib/python3.9/site-packages/keystone/identity/core.py", line 414, in wrapper
2023-04-06 19:02:39.871854 2023-04-06 19:02:39.865 26 ERROR keystone.server.flask.application     return f(self, *args, **kwargs)
2023-04-06 19:02:39.871863 2023-04-06 19:02:39.865 26 ERROR keystone.server.flask.application   File "/var/lib/kolla/venv/lib/python3.9/site-packages/keystone/identity/core.py", line 424, in wrapper
2023-04-06 19:02:39.871872 2023-04-06 19:02:39.865 26 ERROR keystone.server.flask.application     return f(self, *args, **kwargs)
2023-04-06 19:02:39.871882 2023-04-06 19:02:39.865 26 ERROR keystone.server.flask.application   File "/var/lib/kolla/venv/lib/python3.9/site-packages/decorator.py", line 232, in fun
2023-04-06 19:02:39.871891 2023-04-06 19:02:39.865 26 ERROR keystone.server.flask.application     return caller(func, *(extras + args), **kw)
2023-04-06 19:02:39.871901 2023-04-06 19:02:39.865 26 ERROR keystone.server.flask.application   File "/var/lib/kolla/venv/lib/python3.9/site-packages/dogpile/cache/region.py", line 1577, in get_or_create_for_user_func
2023-04-06 19:02:39.871910 2023-04-06 19:02:39.865 26 ERROR keystone.server.flask.application     return self.get_or_create(
2023-04-06 19:02:39.871920 2023-04-06 19:02:39.865 26 ERROR keystone.server.flask.application   File "/var/lib/kolla/venv/lib/python3.9/site-packages/dogpile/cache/region.py", line 1042, in get_or_create
2023-04-06 19:02:39.871929 2023-04-06 19:02:39.865 26 ERROR keystone.server.flask.application     with Lock(
2023-04-06 19:02:39.871938 2023-04-06 19:02:39.865 26 ERROR keystone.server.flask.application   File "/var/lib/kolla/venv/lib/python3.9/site-packages/dogpile/lock.py", line 185, in __enter__
2023-04-06 19:02:39.871948 2023-04-06 19:02:39.865 26 ERROR keystone.server.flask.application     return self._enter()
2023-04-06 19:02:39.871957 2023-04-06 19:02:39.865 26 ERROR keystone.server.flask.application   File "/var/lib/kolla/venv/lib/python3.9/site-packages/dogpile/lock.py", line 94, in _enter
2023-04-06 19:02:39.871967 2023-04-06 19:02:39.865 26 ERROR keystone.server.flask.application     generated = self._enter_create(value, createdtime)
2023-04-06 19:02:39.871976 2023-04-06 19:02:39.865 26 ERROR keystone.server.flask.application   File "/var/lib/kolla/venv/lib/python3.9/site-packages/dogpile/lock.py", line 178, in _enter_create
2023-04-06 19:02:39.871986 2023-04-06 19:02:39.865 26 ERROR keystone.server.flask.application     return self.creator()
2023-04-06 19:02:39.871995 2023-04-06 19:02:39.865 26 ERROR keystone.server.flask.application   File "/var/lib/kolla/venv/lib/python3.9/site-packages/dogpile/cache/region.py", line 995, in gen_value
2023-04-06 19:02:39.872004 2023-04-06 19:02:39.865 26 ERROR keystone.server.flask.application     created_value = creator(
2023-04-06 19:02:39.872013 2023-04-06 19:02:39.865 26 ERROR keystone.server.flask.application   File "/var/lib/kolla/venv/lib/python3.9/site-packages/keystone/identity/core.py", line 1011, in get_user
2023-04-06 19:02:39.872023 2023-04-06 19:02:39.865 26 ERROR keystone.server.flask.application     ref = driver.get_user(entity_id)
2023-04-06 19:02:39.872032 2023-04-06 19:02:39.865 26 ERROR keystone.server.flask.application   File "/var/lib/kolla/venv/lib/python3.9/site-packages/keystone/identity/backends/sql.py", line 200, in get_user
2023-04-06 19:02:39.872042 2023-04-06 19:02:39.865 26 ERROR keystone.server.flask.application     self._get_user(session, user_id).to_dict())
2023-04-06 19:02:39.872061 2023-04-06 19:02:39.865 26 ERROR keystone.server.flask.application   File "/var/lib/kolla/venv/lib/python3.9/site-packages/keystone/identity/backends/sql.py", line 194, in _get_user
2023-04-06 19:02:39.872071 2023-04-06 19:02:39.865 26 ERROR keystone.server.flask.application     raise exception.UserNotFound(user_id=user_id)
2023-04-06 19:02:39.872080 2023-04-06 19:02:39.865 26 ERROR keystone.server.flask.application keystone.exception.UserNotFound: Could not find user: ironic.
2023-04-06 19:02:39.872090 2023-04-06 19:02:39.865 26 ERROR keystone.server.flask.application \x1b[00m
2023-04-06 19:02:40.778929 2023-04-06 19:02:40.763 27 ERROR keystone.server.flask.application [None req-36f5854e-927e-4d39-91de-e72a0888d590 90e9542438684429b47beb5fc0bae2d1 - - all default -] Could not find project: service.: keystone.exception.ProjectNotFound: Could not find project: service.
2023-04-06 19:02:40.779011 2023-04-06 19:02:40.763 27 ERROR keystone.server.flask.application Traceback (most recent call last):
2023-04-06 19:02:40.779022 2023-04-06 19:02:40.763 27 ERROR keystone.server.flask.application   File "/var/lib/kolla/venv/lib/python3.9/site-packages/flask/app.py", line 1820, in full_dispatch_request
2023-04-06 19:02:40.779031 2023-04-06 19:02:40.763 27 ERROR keystone.server.flask.application     rv = self.dispatch_request()
2023-04-06 19:02:40.779040 2023-04-06 19:02:40.763 27 ERROR keystone.server.flask.application   File "/var/lib/kolla/venv/lib/python3.9/site-packages/flask/app.py", line 1796, in dispatch_request
2023-04-06 19:02:40.779050 2023-04-06 19:02:40.763 27 ERROR keystone.server.flask.application     return self.ensure_sync(self.view_functions[rule.endpoint])(**view_args)
2023-04-06 19:02:40.779059 2023-04-06 19:02:40.763 27 ERROR keystone.server.flask.application   File "/var/lib/kolla/venv/lib/python3.9/site-packages/flask_restful/__init__.py", line 467, in wrapper
2023-04-06 19:02:40.779068 2023-04-06 19:02:40.763 27 ERROR keystone.server.flask.application     resp = resource(*args, **kwargs)
2023-04-06 19:02:40.779078 2023-04-06 19:02:40.763 27 ERROR keystone.server.flask.application   File "/var/lib/kolla/venv/lib/python3.9/site-packages/flask/views.py", line 107, in view
2023-04-06 19:02:40.779087 2023-04-06 19:02:40.763 27 ERROR keystone.server.flask.application     return current_app.ensure_sync(self.dispatch_request)(**kwargs)
2023-04-06 19:02:40.779096 2023-04-06 19:02:40.763 27 ERROR keystone.server.flask.application   File "/var/lib/kolla/venv/lib/python3.9/site-packages/flask_restful/__init__.py", line 582, in dispatch_request
2023-04-06 19:02:40.779106 2023-04-06 19:02:40.763 27 ERROR keystone.server.flask.application     resp = meth(*args, **kwargs)
2023-04-06 19:02:40.779115 2023-04-06 19:02:40.763 27 ERROR keystone.server.flask.application   File "/var/lib/kolla/venv/lib/python3.9/site-packages/keystone/api/projects.py", line 151, in get
2023-04-06 19:02:40.779124 2023-04-06 19:02:40.763 27 ERROR keystone.server.flask.application     return self._get_project(project_id)
2023-04-06 19:02:40.779133 2023-04-06 19:02:40.763 27 ERROR keystone.server.flask.application   File "/var/lib/kolla/venv/lib/python3.9/site-packages/keystone/api/projects.py", line 107, in _get_project
2023-04-06 19:02:40.779142 2023-04-06 19:02:40.763 27 ERROR keystone.server.flask.application     project = PROVIDERS.resource_api.get_project(project_id)
2023-04-06 19:02:40.779151 2023-04-06 19:02:40.763 27 ERROR keystone.server.flask.application   File "/var/lib/kolla/venv/lib/python3.9/site-packages/keystone/common/manager.py", line 115, in wrapped
2023-04-06 19:02:40.779161 2023-04-06 19:02:40.763 27 ERROR keystone.server.flask.application     __ret_val = __f(*args, **kwargs)
2023-04-06 19:02:40.779169 2023-04-06 19:02:40.763 27 ERROR keystone.server.flask.application   File "/var/lib/kolla/venv/lib/python3.9/site-packages/decorator.py", line 232, in fun
2023-04-06 19:02:40.779178 2023-04-06 19:02:40.763 27 ERROR keystone.server.flask.application     return caller(func, *(extras + args), **kw)
2023-04-06 19:02:40.779249 2023-04-06 19:02:40.763 27 ERROR keystone.server.flask.application   File "/var/lib/kolla/venv/lib/python3.9/site-packages/dogpile/cache/region.py", line 1577, in get_or_create_for_user_func
2023-04-06 19:02:40.779263 2023-04-06 19:02:40.763 27 ERROR keystone.server.flask.application     return self.get_or_create(
2023-04-06 19:02:40.779273 2023-04-06 19:02:40.763 27 ERROR keystone.server.flask.application   File "/var/lib/kolla/venv/lib/python3.9/site-packages/dogpile/cache/region.py", line 1042, in get_or_create
2023-04-06 19:02:40.779283 2023-04-06 19:02:40.763 27 ERROR keystone.server.flask.application     with Lock(
2023-04-06 19:02:40.779292 2023-04-06 19:02:40.763 27 ERROR keystone.server.flask.application   File "/var/lib/kolla/venv/lib/python3.9/site-packages/dogpile/lock.py", line 185, in __enter__
2023-04-06 19:02:40.779301 2023-04-06 19:02:40.763 27 ERROR keystone.server.flask.application     return self._enter()
2023-04-06 19:02:40.779311 2023-04-06 19:02:40.763 27 ERROR keystone.server.flask.application   File "/var/lib/kolla/venv/lib/python3.9/site-packages/dogpile/lock.py", line 94, in _enter
2023-04-06 19:02:40.779320 2023-04-06 19:02:40.763 27 ERROR keystone.server.flask.application     generated = self._enter_create(value, createdtime)
2023-04-06 19:02:40.779329 2023-04-06 19:02:40.763 27 ERROR keystone.server.flask.application   File "/var/lib/kolla/venv/lib/python3.9/site-packages/dogpile/lock.py", line 178, in _enter_create
2023-04-06 19:02:40.779338 2023-04-06 19:02:40.763 27 ERROR keystone.server.flask.application     return self.creator()
2023-04-06 19:02:40.779347 2023-04-06 19:02:40.763 27 ERROR keystone.server.flask.application   File "/var/lib/kolla/venv/lib/python3.9/site-packages/dogpile/cache/region.py", line 995, in gen_value
2023-04-06 19:02:40.779357 2023-04-06 19:02:40.763 27 ERROR keystone.server.flask.application     created_value = creator(
2023-04-06 19:02:40.779366 2023-04-06 19:02:40.763 27 ERROR keystone.server.flask.application   File "/var/lib/kolla/venv/lib/python3.9/site-packages/keystone/resource/core.py", line 903, in get_project
2023-04-06 19:02:40.779375 2023-04-06 19:02:40.763 27 ERROR keystone.server.flask.application     return self.driver.get_project(project_id)
2023-04-06 19:02:40.779384 2023-04-06 19:02:40.763 27 ERROR keystone.server.flask.application   File "/var/lib/kolla/venv/lib/python3.9/site-packages/keystone/resource/backends/sql.py", line 49, in get_project
2023-04-06 19:02:40.779394 2023-04-06 19:02:40.763 27 ERROR keystone.server.flask.application     return self._get_project(session, project_id).to_dict()
2023-04-06 19:02:40.779403 2023-04-06 19:02:40.763 27 ERROR keystone.server.flask.application   File "/var/lib/kolla/venv/lib/python3.9/site-packages/keystone/resource/backends/sql.py", line 44, in _get_project
2023-04-06 19:02:40.779413 2023-04-06 19:02:40.763 27 ERROR keystone.server.flask.application     raise exception.ProjectNotFound(project_id=project_id)
2023-04-06 19:02:40.779446 2023-04-06 19:02:40.763 27 ERROR keystone.server.flask.application keystone.exception.ProjectNotFound: Could not find project: service.
2023-04-06 19:02:40.779461 2023-04-06 19:02:40.763 27 ERROR keystone.server.flask.application \x1b[00m
2023-04-06 19:02:51.283454 2023-04-06 19:02:51.274 28 ERROR keystone.server.flask.application [None req-39b896d6-d969-4291-87ab-f447e6c8ab88 90e9542438684429b47beb5fc0bae2d1 - - all default -] Could not find role: admin.: keystone.exception.RoleNotFound: Could not find role: admin.
2023-04-06 19:02:51.283514 2023-04-06 19:02:51.274 28 ERROR keystone.server.flask.application Traceback (most recent call last):
2023-04-06 19:02:51.283542 2023-04-06 19:02:51.274 28 ERROR keystone.server.flask.application   File "/var/lib/kolla/venv/lib/python3.9/site-packages/flask/app.py", line 1820, in full_dispatch_request
2023-04-06 19:02:51.283554 2023-04-06 19:02:51.274 28 ERROR keystone.server.flask.application     rv = self.dispatch_request()
2023-04-06 19:02:51.283563 2023-04-06 19:02:51.274 28 ERROR keystone.server.flask.application   File "/var/lib/kolla/venv/lib/python3.9/site-packages/flask/app.py", line 1796, in dispatch_request
2023-04-06 19:02:51.283596 2023-04-06 19:02:51.274 28 ERROR keystone.server.flask.application     return self.ensure_sync(self.view_functions[rule.endpoint])(**view_args)
2023-04-06 19:02:51.283608 2023-04-06 19:02:51.274 28 ERROR keystone.server.flask.application   File "/var/lib/kolla/venv/lib/python3.9/site-packages/flask_restful/__init__.py", line 467, in wrapper
2023-04-06 19:02:51.283618 2023-04-06 19:02:51.274 28 ERROR keystone.server.flask.application     resp = resource(*args, **kwargs)
2023-04-06 19:02:51.283633 2023-04-06 19:02:51.274 28 ERROR keystone.server.flask.application   File "/var/lib/kolla/venv/lib/python3.9/site-packages/flask/views.py", line 107, in view
2023-04-06 19:02:51.283646 2023-04-06 19:02:51.274 28 ERROR keystone.server.flask.application     return current_app.ensure_sync(self.dispatch_request)(**kwargs)
2023-04-06 19:02:51.283655 2023-04-06 19:02:51.274 28 ERROR keystone.server.flask.application   File "/var/lib/kolla/venv/lib/python3.9/site-packages/flask_restful/__init__.py", line 582, in dispatch_request
2023-04-06 19:02:51.283665 2023-04-06 19:02:51.274 28 ERROR keystone.server.flask.application     resp = meth(*args, **kwargs)
2023-04-06 19:02:51.283674 2023-04-06 19:02:51.274 28 ERROR keystone.server.flask.application   File "/var/lib/kolla/venv/lib/python3.9/site-packages/keystone/api/roles.py", line 50, in get
2023-04-06 19:02:51.283683 2023-04-06 19:02:51.274 28 ERROR keystone.server.flask.application     return self._get_role(role_id)
2023-04-06 19:02:51.283692 2023-04-06 19:02:51.274 28 ERROR keystone.server.flask.application   File "/var/lib/kolla/venv/lib/python3.9/site-packages/keystone/api/roles.py", line 70, in _get_role
2023-04-06 19:02:51.283702 2023-04-06 19:02:51.274 28 ERROR keystone.server.flask.application     ENFORCER.enforce_call(action='identity:get_role')
2023-04-06 19:02:51.283712 2023-04-06 19:02:51.274 28 ERROR keystone.server.flask.application   File "/var/lib/kolla/venv/lib/python3.9/site-packages/keystone/common/rbac_enforcer/enforcer.py", line 402, in enforce_call
2023-04-06 19:02:51.283721 2023-04-06 19:02:51.274 28 ERROR keystone.server.flask.application     policy_dict.update(cls._extract_member_target_data(
2023-04-06 19:02:51.283731 2023-04-06 19:02:51.274 28 ERROR keystone.server.flask.application   File "/var/lib/kolla/venv/lib/python3.9/site-packages/keystone/common/rbac_enforcer/enforcer.py", line 234, in _extract_member_target_data
2023-04-06 19:02:51.283741 2023-04-06 19:02:51.274 28 ERROR keystone.server.flask.application     member_name: func(flask.request.view_args[key])
2023-04-06 19:02:51.283752 2023-04-06 19:02:51.274 28 ERROR keystone.server.flask.application   File "/var/lib/kolla/venv/lib/python3.9/site-packages/keystone/common/manager.py", line 115, in wrapped
2023-04-06 19:02:51.283761 2023-04-06 19:02:51.274 28 ERROR keystone.server.flask.application     __ret_val = __f(*args, **kwargs)
2023-04-06 19:02:51.283770 2023-04-06 19:02:51.274 28 ERROR keystone.server.flask.application   File "/var/lib/kolla/venv/lib/python3.9/site-packages/decorator.py", line 232, in fun
2023-04-06 19:02:51.283780 2023-04-06 19:02:51.274 28 ERROR keystone.server.flask.application     return caller(func, *(extras + args), **kw)
2023-04-06 19:02:51.283809 2023-04-06 19:02:51.274 28 ERROR keystone.server.flask.application   File "/var/lib/kolla/venv/lib/python3.9/site-packages/dogpile/cache/region.py", line 1577, in get_or_create_for_user_func
2023-04-06 19:02:51.283820 2023-04-06 19:02:51.274 28 ERROR keystone.server.flask.application     return self.get_or_create(
2023-04-06 19:02:51.283830 2023-04-06 19:02:51.274 28 ERROR keystone.server.flask.application   File "/var/lib/kolla/venv/lib/python3.9/site-packages/dogpile/cache/region.py", line 1042, in get_or_create
2023-04-06 19:02:51.283840 2023-04-06 19:02:51.274 28 ERROR keystone.server.flask.application     with Lock(
2023-04-06 19:02:51.283875 2023-04-06 19:02:51.274 28 ERROR keystone.server.flask.application   File "/var/lib/kolla/venv/lib/python3.9/site-packages/dogpile/lock.py", line 185, in __enter__
2023-04-06 19:02:51.283887 2023-04-06 19:02:51.274 28 ERROR keystone.server.flask.application     return self._enter()
2023-04-06 19:02:51.283897 2023-04-06 19:02:51.274 28 ERROR keystone.server.flask.application   File "/var/lib/kolla/venv/lib/python3.9/site-packages/dogpile/lock.py", line 94, in _enter
2023-04-06 19:02:51.283906 2023-04-06 19:02:51.274 28 ERROR keystone.server.flask.application     generated = self._enter_create(value, createdtime)
2023-04-06 19:02:51.283916 2023-04-06 19:02:51.274 28 ERROR keystone.server.flask.application   File "/var/lib/kolla/venv/lib/python3.9/site-packages/dogpile/lock.py", line 178, in _enter_create
2023-04-06 19:02:51.283925 2023-04-06 19:02:51.274 28 ERROR keystone.server.flask.application     return self.creator()
2023-04-06 19:02:51.283934 2023-04-06 19:02:51.274 28 ERROR keystone.server.flask.application   File "/var/lib/kolla/venv/lib/python3.9/site-packages/dogpile/cache/region.py", line 995, in gen_value
2023-04-06 19:02:51.283944 2023-04-06 19:02:51.274 28 ERROR keystone.server.flask.application     created_value = creator(
2023-04-06 19:02:51.283953 2023-04-06 19:02:51.274 28 ERROR keystone.server.flask.application   File "/var/lib/kolla/venv/lib/python3.9/site-packages/keystone/assignment/core.py", line 1276, in get_role
2023-04-06 19:02:51.284112 2023-04-06 19:02:51.274 28 ERROR keystone.server.flask.application     return self.driver.get_role(role_id)
2023-04-06 19:02:51.284249 2023-04-06 19:02:51.274 28 ERROR keystone.server.flask.application   File "/var/lib/kolla/venv/lib/python3.9/site-packages/keystone/assignment/role_backends/sql.py", line 70, in get_role
2023-04-06 19:02:51.284265 2023-04-06 19:02:51.274 28 ERROR keystone.server.flask.application     return self._get_role(session, role_id).to_dict()
2023-04-06 19:02:51.284276 2023-04-06 19:02:51.274 28 ERROR keystone.server.flask.application   File "/var/lib/kolla/venv/lib/python3.9/site-packages/keystone/assignment/role_backends/sql.py", line 65, in _get_role
2023-04-06 19:02:51.284289 2023-04-06 19:02:51.274 28 ERROR keystone.server.flask.application     raise exception.RoleNotFound(role_id=role_id)
2023-04-06 19:02:51.284303 2023-04-06 19:02:51.274 28 ERROR keystone.server.flask.application keystone.exception.RoleNotFound: Could not find role: admin.
2023-04-06 19:02:51.284314 2023-04-06 19:02:51.274 28 ERROR keystone.server.flask.application \x1b[00m
2023-04-06 19:02:52.511114 2023-04-06 19:02:52.502 28 ERROR keystone.server.flask.application [None req-9efedc24-8f4a-4acc-85b3-56dda0ceca39 90e9542438684429b47beb5fc0bae2d1 - - all default -] Could not find user: ironic-inspector.: keystone.exception.UserNotFound: Could not find user: ironic-inspector.
2023-04-06 19:02:52.511237 2023-04-06 19:02:52.502 28 ERROR keystone.server.flask.application Traceback (most recent call last):
2023-04-06 19:02:52.511254 2023-04-06 19:02:52.502 28 ERROR keystone.server.flask.application   File "/var/lib/kolla/venv/lib/python3.9/site-packages/flask/app.py", line 1820, in full_dispatch_request
2023-04-06 19:02:52.511264 2023-04-06 19:02:52.502 28 ERROR keystone.server.flask.application     rv = self.dispatch_request()
2023-04-06 19:02:52.511274 2023-04-06 19:02:52.502 28 ERROR keystone.server.flask.application   File "/var/lib/kolla/venv/lib/python3.9/site-packages/flask/app.py", line 1796, in dispatch_request
2023-04-06 19:02:52.511284 2023-04-06 19:02:52.502 28 ERROR keystone.server.flask.application     return self.ensure_sync(self.view_functions[rule.endpoint])(**view_args)
2023-04-06 19:02:52.511293 2023-04-06 19:02:52.502 28 ERROR keystone.server.flask.application   File "/var/lib/kolla/venv/lib/python3.9/site-packages/flask_restful/__init__.py", line 467, in wrapper
2023-04-06 19:02:52.511303 2023-04-06 19:02:52.502 28 ERROR keystone.server.flask.application     resp = resource(*args, **kwargs)
2023-04-06 19:02:52.511312 2023-04-06 19:02:52.502 28 ERROR keystone.server.flask.application   File "/var/lib/kolla/venv/lib/python3.9/site-packages/flask/views.py", line 107, in view
2023-04-06 19:02:52.511353 2023-04-06 19:02:52.502 28 ERROR keystone.server.flask.application     return current_app.ensure_sync(self.dispatch_request)(**kwargs)
2023-04-06 19:02:52.511367 2023-04-06 19:02:52.502 28 ERROR keystone.server.flask.application   File "/var/lib/kolla/venv/lib/python3.9/site-packages/flask_restful/__init__.py", line 582, in dispatch_request
2023-04-06 19:02:52.511386 2023-04-06 19:02:52.502 28 ERROR keystone.server.flask.application     resp = meth(*args, **kwargs)
2023-04-06 19:02:52.511402 2023-04-06 19:02:52.502 28 ERROR keystone.server.flask.application   File "/var/lib/kolla/venv/lib/python3.9/site-packages/keystone/api/users.py", line 182, in get
2023-04-06 19:02:52.511413 2023-04-06 19:02:52.502 28 ERROR keystone.server.flask.application     return self._get_user(user_id)
2023-04-06 19:02:52.511459 2023-04-06 19:02:52.502 28 ERROR keystone.server.flask.application   File "/var/lib/kolla/venv/lib/python3.9/site-packages/keystone/api/users.py", line 194, in _get_user
2023-04-06 19:02:52.511495 2023-04-06 19:02:52.502 28 ERROR keystone.server.flask.application     ref = PROVIDERS.identity_api.get_user(user_id)
2023-04-06 19:02:52.511512 2023-04-06 19:02:52.502 28 ERROR keystone.server.flask.application   File "/var/lib/kolla/venv/lib/python3.9/site-packages/keystone/common/manager.py", line 115, in wrapped
2023-04-06 19:02:52.511523 2023-04-06 19:02:52.502 28 ERROR keystone.server.flask.application     __ret_val = __f(*args, **kwargs)
2023-04-06 19:02:52.511532 2023-04-06 19:02:52.502 28 ERROR keystone.server.flask.application   File "/var/lib/kolla/venv/lib/python3.9/site-packages/keystone/identity/core.py", line 414, in wrapper
2023-04-06 19:02:52.511541 2023-04-06 19:02:52.502 28 ERROR keystone.server.flask.application     return f(self, *args, **kwargs)
2023-04-06 19:02:52.511551 2023-04-06 19:02:52.502 28 ERROR keystone.server.flask.application   File "/var/lib/kolla/venv/lib/python3.9/site-packages/keystone/identity/core.py", line 424, in wrapper
2023-04-06 19:02:52.511560 2023-04-06 19:02:52.502 28 ERROR keystone.server.flask.application     return f(self, *args, **kwargs)
2023-04-06 19:02:52.511569 2023-04-06 19:02:52.502 28 ERROR keystone.server.flask.application   File "/var/lib/kolla/venv/lib/python3.9/site-packages/decorator.py", line 232, in fun
2023-04-06 19:02:52.511579 2023-04-06 19:02:52.502 28 ERROR keystone.server.flask.application     return caller(func, *(extras + args), **kw)
2023-04-06 19:02:52.511589 2023-04-06 19:02:52.502 28 ERROR keystone.server.flask.application   File "/var/lib/kolla/venv/lib/python3.9/site-packages/dogpile/cache/region.py", line 1577, in get_or_create_for_user_func
2023-04-06 19:02:52.511598 2023-04-06 19:02:52.502 28 ERROR keystone.server.flask.application     return self.get_or_create(
2023-04-06 19:02:52.511607 2023-04-06 19:02:52.502 28 ERROR keystone.server.flask.application   File "/var/lib/kolla/venv/lib/python3.9/site-packages/dogpile/cache/region.py", line 1042, in get_or_create
2023-04-06 19:02:52.511617 2023-04-06 19:02:52.502 28 ERROR keystone.server.flask.application     with Lock(
2023-04-06 19:02:52.511626 2023-04-06 19:02:52.502 28 ERROR keystone.server.flask.application   File "/var/lib/kolla/venv/lib/python3.9/site-packages/dogpile/lock.py", line 185, in __enter__
2023-04-06 19:02:52.511636 2023-04-06 19:02:52.502 28 ERROR keystone.server.flask.application     return self._enter()
2023-04-06 19:02:52.511645 2023-04-06 19:02:52.502 28 ERROR keystone.server.flask.application   File "/var/lib/kolla/venv/lib/python3.9/site-packages/dogpile/lock.py", line 94, in _enter
2023-04-06 19:02:52.511654 2023-04-06 19:02:52.502 28 ERROR keystone.server.flask.application     generated = self._enter_create(value, createdtime)
2023-04-06 19:02:52.511664 2023-04-06 19:02:52.502 28 ERROR keystone.server.flask.application   File "/var/lib/kolla/venv/lib/python3.9/site-packages/dogpile/lock.py", line 178, in _enter_create
2023-04-06 19:02:52.511763 2023-04-06 19:02:52.502 28 ERROR keystone.server.flask.application     return self.creator()
2023-04-06 19:02:52.511775 2023-04-06 19:02:52.502 28 ERROR keystone.server.flask.application   File "/var/lib/kolla/venv/lib/python3.9/site-packages/dogpile/cache/region.py", line 995, in gen_value
2023-04-06 19:02:52.511785 2023-04-06 19:02:52.502 28 ERROR keystone.server.flask.application     created_value = creator(
2023-04-06 19:02:52.511795 2023-04-06 19:02:52.502 28 ERROR keystone.server.flask.application   File "/var/lib/kolla/venv/lib/python3.9/site-packages/keystone/identity/core.py", line 1011, in get_user
2023-04-06 19:02:52.511804 2023-04-06 19:02:52.502 28 ERROR keystone.server.flask.application     ref = driver.get_user(entity_id)
2023-04-06 19:02:52.511814 2023-04-06 19:02:52.502 28 ERROR keystone.server.flask.application   File "/var/lib/kolla/venv/lib/python3.9/site-packages/keystone/identity/backends/sql.py", line 200, in get_user
2023-04-06 19:02:52.511823 2023-04-06 19:02:52.502 28 ERROR keystone.server.flask.application     self._get_user(session, user_id).to_dict())
2023-04-06 19:02:52.511833 2023-04-06 19:02:52.502 28 ERROR keystone.server.flask.application   File "/var/lib/kolla/venv/lib/python3.9/site-packages/keystone/identity/backends/sql.py", line 194, in _get_user
2023-04-06 19:02:52.511842 2023-04-06 19:02:52.502 28 ERROR keystone.server.flask.application     raise exception.UserNotFound(user_id=user_id)
2023-04-06 19:02:52.511851 2023-04-06 19:02:52.502 28 ERROR keystone.server.flask.application keystone.exception.UserNotFound: Could not find user: ironic-inspector.
2023-04-06 19:02:52.511861 2023-04-06 19:02:52.502 28 ERROR keystone.server.flask.application \x1b[00m
2023-04-06 19:02:53.523136 2023-04-06 19:02:53.518 26 ERROR keystone.server.flask.application [None req-f277cea4-b433-4a00-b7fe-0f4b7b85c56a 90e9542438684429b47beb5fc0bae2d1 - - all default -] Could not find project: service.: keystone.exception.ProjectNotFound: Could not find project: service.
2023-04-06 19:02:53.523212 2023-04-06 19:02:53.518 26 ERROR keystone.server.flask.application Traceback (most recent call last):
2023-04-06 19:02:53.523257 2023-04-06 19:02:53.518 26 ERROR keystone.server.flask.application   File "/var/lib/kolla/venv/lib/python3.9/site-packages/flask/app.py", line 1820, in full_dispatch_request
2023-04-06 19:02:53.523279 2023-04-06 19:02:53.518 26 ERROR keystone.server.flask.application     rv = self.dispatch_request()
2023-04-06 19:02:53.523299 2023-04-06 19:02:53.518 26 ERROR keystone.server.flask.application   File "/var/lib/kolla/venv/lib/python3.9/site-packages/flask/app.py", line 1796, in dispatch_request
2023-04-06 19:02:53.523320 2023-04-06 19:02:53.518 26 ERROR keystone.server.flask.application     return self.ensure_sync(self.view_functions[rule.endpoint])(**view_args)
2023-04-06 19:02:53.523341 2023-04-06 19:02:53.518 26 ERROR keystone.server.flask.application   File "/var/lib/kolla/venv/lib/python3.9/site-packages/flask_restful/__init__.py", line 467, in wrapper
2023-04-06 19:02:53.523360 2023-04-06 19:02:53.518 26 ERROR keystone.server.flask.application     resp = resource(*args, **kwargs)
2023-04-06 19:02:53.523393 2023-04-06 19:02:53.518 26 ERROR keystone.server.flask.application   File "/var/lib/kolla/venv/lib/python3.9/site-packages/flask/views.py", line 107, in view
2023-04-06 19:02:53.523416 2023-04-06 19:02:53.518 26 ERROR keystone.server.flask.application     return current_app.ensure_sync(self.dispatch_request)(**kwargs)
2023-04-06 19:02:53.523498 2023-04-06 19:02:53.518 26 ERROR keystone.server.flask.application   File "/var/lib/kolla/venv/lib/python3.9/site-packages/flask_restful/__init__.py", line 582, in dispatch_request
2023-04-06 19:02:53.523517 2023-04-06 19:02:53.518 26 ERROR keystone.server.flask.application     resp = meth(*args, **kwargs)
2023-04-06 19:02:53.523533 2023-04-06 19:02:53.518 26 ERROR keystone.server.flask.application   File "/var/lib/kolla/venv/lib/python3.9/site-packages/keystone/api/projects.py", line 151, in get
2023-04-06 19:02:53.523576 2023-04-06 19:02:53.518 26 ERROR keystone.server.flask.application     return self._get_project(project_id)
2023-04-06 19:02:53.523598 2023-04-06 19:02:53.518 26 ERROR keystone.server.flask.application   File "/var/lib/kolla/venv/lib/python3.9/site-packages/keystone/api/projects.py", line 107, in _get_project
2023-04-06 19:02:53.523616 2023-04-06 19:02:53.518 26 ERROR keystone.server.flask.application     project = PROVIDERS.resource_api.get_project(project_id)
2023-04-06 19:02:53.523636 2023-04-06 19:02:53.518 26 ERROR keystone.server.flask.application   File "/var/lib/kolla/venv/lib/python3.9/site-packages/keystone/common/manager.py", line 115, in wrapped
2023-04-06 19:02:53.523656 2023-04-06 19:02:53.518 26 ERROR keystone.server.flask.application     __ret_val = __f(*args, **kwargs)
2023-04-06 19:02:53.523676 2023-04-06 19:02:53.518 26 ERROR keystone.server.flask.application   File "/var/lib/kolla/venv/lib/python3.9/site-packages/decorator.py", line 232, in fun
2023-04-06 19:02:53.523697 2023-04-06 19:02:53.518 26 ERROR keystone.server.flask.application     return caller(func, *(extras + args), **kw)
2023-04-06 19:02:53.523717 2023-04-06 19:02:53.518 26 ERROR keystone.server.flask.application   File "/var/lib/kolla/venv/lib/python3.9/site-packages/dogpile/cache/region.py", line 1577, in get_or_create_for_user_func
2023-04-06 19:02:53.523737 2023-04-06 19:02:53.518 26 ERROR keystone.server.flask.application     return self.get_or_create(
2023-04-06 19:02:53.523758 2023-04-06 19:02:53.518 26 ERROR keystone.server.flask.application   File "/var/lib/kolla/venv/lib/python3.9/site-packages/dogpile/cache/region.py", line 1042, in get_or_create
2023-04-06 19:02:53.523779 2023-04-06 19:02:53.518 26 ERROR keystone.server.flask.application     with Lock(
2023-04-06 19:02:53.523796 2023-04-06 19:02:53.518 26 ERROR keystone.server.flask.application   File "/var/lib/kolla/venv/lib/python3.9/site-packages/dogpile/lock.py", line 185, in __enter__
2023-04-06 19:02:53.523815 2023-04-06 19:02:53.518 26 ERROR keystone.server.flask.application     return self._enter()
2023-04-06 19:02:53.523834 2023-04-06 19:02:53.518 26 ERROR keystone.server.flask.application   File "/var/lib/kolla/venv/lib/python3.9/site-packages/dogpile/lock.py", line 94, in _enter
2023-04-06 19:02:53.523852 2023-04-06 19:02:53.518 26 ERROR keystone.server.flask.application     generated = self._enter_create(value, createdtime)
2023-04-06 19:02:53.523873 2023-04-06 19:02:53.518 26 ERROR keystone.server.flask.application   File "/var/lib/kolla/venv/lib/python3.9/site-packages/dogpile/lock.py", line 178, in _enter_create
2023-04-06 19:02:53.523893 2023-04-06 19:02:53.518 26 ERROR keystone.server.flask.application     return self.creator()
2023-04-06 19:02:53.523913 2023-04-06 19:02:53.518 26 ERROR keystone.server.flask.application   File "/var/lib/kolla/venv/lib/python3.9/site-packages/dogpile/cache/region.py", line 995, in gen_value
2023-04-06 19:02:53.523934 2023-04-06 19:02:53.518 26 ERROR keystone.server.flask.application     created_value = creator(
2023-04-06 19:02:53.523952 2023-04-06 19:02:53.518 26 ERROR keystone.server.flask.application   File "/var/lib/kolla/venv/lib/python3.9/site-packages/keystone/resource/core.py", line 903, in get_project
2023-04-06 19:02:53.523973 2023-04-06 19:02:53.518 26 ERROR keystone.server.flask.application     return self.driver.get_project(project_id)
2023-04-06 19:02:53.523990 2023-04-06 19:02:53.518 26 ERROR keystone.server.flask.application   File "/var/lib/kolla/venv/lib/python3.9/site-packages/keystone/resource/backends/sql.py", line 49, in get_project
2023-04-06 19:02:53.524012 2023-04-06 19:02:53.518 26 ERROR keystone.server.flask.application     return self._get_project(session, project_id).to_dict()
2023-04-06 19:02:53.524031 2023-04-06 19:02:53.518 26 ERROR keystone.server.flask.application   File "/var/lib/kolla/venv/lib/python3.9/site-packages/keystone/resource/backends/sql.py", line 44, in _get_project
2023-04-06 19:02:53.524051 2023-04-06 19:02:53.518 26 ERROR keystone.server.flask.application     raise exception.ProjectNotFound(project_id=project_id)
2023-04-06 19:02:53.524097 2023-04-06 19:02:53.518 26 ERROR keystone.server.flask.application keystone.exception.ProjectNotFound: Could not find project: service.
2023-04-06 19:02:53.524121 2023-04-06 19:02:53.518 26 ERROR keystone.server.flask.application \x1b[00m
2023-04-06 19:05:45.267813 2023-04-06 19:05:45.264 28 ERROR keystone.server.flask.application [None req-286198ef-4d49-438e-ba51-22817ad4b572 90e9542438684429b47beb5fc0bae2d1 - - all default -] Could not find project: service.: keystone.exception.ProjectNotFound: Could not find project: service.
2023-04-06 19:05:45.267874 2023-04-06 19:05:45.264 28 ERROR keystone.server.flask.application Traceback (most recent call last):
2023-04-06 19:05:45.267902 2023-04-06 19:05:45.264 28 ERROR keystone.server.flask.application   File "/var/lib/kolla/venv/lib/python3.9/site-packages/flask/app.py", line 1820, in full_dispatch_request
2023-04-06 19:05:45.267912 2023-04-06 19:05:45.264 28 ERROR keystone.server.flask.application     rv = self.dispatch_request()
2023-04-06 19:05:45.267922 2023-04-06 19:05:45.264 28 ERROR keystone.server.flask.application   File "/var/lib/kolla/venv/lib/python3.9/site-packages/flask/app.py", line 1796, in dispatch_request
2023-04-06 19:05:45.267931 2023-04-06 19:05:45.264 28 ERROR keystone.server.flask.application     return self.ensure_sync(self.view_functions[rule.endpoint])(**view_args)
2023-04-06 19:05:45.267941 2023-04-06 19:05:45.264 28 ERROR keystone.server.flask.application   File "/var/lib/kolla/venv/lib/python3.9/site-packages/flask_restful/__init__.py", line 467, in wrapper
2023-04-06 19:05:45.267951 2023-04-06 19:05:45.264 28 ERROR keystone.server.flask.application     resp = resource(*args, **kwargs)
2023-04-06 19:05:45.267966 2023-04-06 19:05:45.264 28 ERROR keystone.server.flask.application   File "/var/lib/kolla/venv/lib/python3.9/site-packages/flask/views.py", line 107, in view
2023-04-06 19:05:45.267978 2023-04-06 19:05:45.264 28 ERROR keystone.server.flask.application     return current_app.ensure_sync(self.dispatch_request)(**kwargs)
2023-04-06 19:05:45.267988 2023-04-06 19:05:45.264 28 ERROR keystone.server.flask.application   File "/var/lib/kolla/venv/lib/python3.9/site-packages/flask_restful/__init__.py", line 582, in dispatch_request
2023-04-06 19:05:45.267998 2023-04-06 19:05:45.264 28 ERROR keystone.server.flask.application     resp = meth(*args, **kwargs)
2023-04-06 19:05:45.268007 2023-04-06 19:05:45.264 28 ERROR keystone.server.flask.application   File "/var/lib/kolla/venv/lib/python3.9/site-packages/keystone/api/projects.py", line 151, in get
2023-04-06 19:05:45.268016 2023-04-06 19:05:45.264 28 ERROR keystone.server.flask.application     return self._get_project(project_id)
2023-04-06 19:05:45.268026 2023-04-06 19:05:45.264 28 ERROR keystone.server.flask.application   File "/var/lib/kolla/venv/lib/python3.9/site-packages/keystone/api/projects.py", line 107, in _get_project
2023-04-06 19:05:45.268035 2023-04-06 19:05:45.264 28 ERROR keystone.server.flask.application     project = PROVIDERS.resource_api.get_project(project_id)
2023-04-06 19:05:45.268044 2023-04-06 19:05:45.264 28 ERROR keystone.server.flask.application   File "/var/lib/kolla/venv/lib/python3.9/site-packages/keystone/common/manager.py", line 115, in wrapped
2023-04-06 19:05:45.268054 2023-04-06 19:05:45.264 28 ERROR keystone.server.flask.application     __ret_val = __f(*args, **kwargs)
2023-04-06 19:05:45.268063 2023-04-06 19:05:45.264 28 ERROR keystone.server.flask.application   File "/var/lib/kolla/venv/lib/python3.9/site-packages/decorator.py", line 232, in fun
2023-04-06 19:05:45.268072 2023-04-06 19:05:45.264 28 ERROR keystone.server.flask.application     return caller(func, *(extras + args), **kw)
2023-04-06 19:05:45.268081 2023-04-06 19:05:45.264 28 ERROR keystone.server.flask.application   File "/var/lib/kolla/venv/lib/python3.9/site-packages/dogpile/cache/region.py", line 1577, in get_or_create_for_user_func
2023-04-06 19:05:45.268091 2023-04-06 19:05:45.264 28 ERROR keystone.server.flask.application     return self.get_or_create(
2023-04-06 19:05:45.268123 2023-04-06 19:05:45.264 28 ERROR keystone.server.flask.application   File "/var/lib/kolla/venv/lib/python3.9/site-packages/dogpile/cache/region.py", line 1042, in get_or_create
2023-04-06 19:05:45.268135 2023-04-06 19:05:45.264 28 ERROR keystone.server.flask.application     with Lock(
2023-04-06 19:05:45.268145 2023-04-06 19:05:45.264 28 ERROR keystone.server.flask.application   File "/var/lib/kolla/venv/lib/python3.9/site-packages/dogpile/lock.py", line 185, in __enter__
2023-04-06 19:05:45.268154 2023-04-06 19:05:45.264 28 ERROR keystone.server.flask.application     return self._enter()
2023-04-06 19:05:45.268164 2023-04-06 19:05:45.264 28 ERROR keystone.server.flask.application   File "/var/lib/kolla/venv/lib/python3.9/site-packages/dogpile/lock.py", line 94, in _enter
2023-04-06 19:05:45.268173 2023-04-06 19:05:45.264 28 ERROR keystone.server.flask.application     generated = self._enter_create(value, createdtime)
2023-04-06 19:05:45.268201 2023-04-06 19:05:45.264 28 ERROR keystone.server.flask.application   File "/var/lib/kolla/venv/lib/python3.9/site-packages/dogpile/lock.py", line 178, in _enter_create
2023-04-06 19:05:45.268210 2023-04-06 19:05:45.264 28 ERROR keystone.server.flask.application     return self.creator()
2023-04-06 19:05:45.268220 2023-04-06 19:05:45.264 28 ERROR keystone.server.flask.application   File "/var/lib/kolla/venv/lib/python3.9/site-packages/dogpile/cache/region.py", line 995, in gen_value
2023-04-06 19:05:45.268229 2023-04-06 19:05:45.264 28 ERROR keystone.server.flask.application     created_value = creator(
2023-04-06 19:05:45.268238 2023-04-06 19:05:45.264 28 ERROR keystone.server.flask.application   File "/var/lib/kolla/venv/lib/python3.9/site-packages/keystone/resource/core.py", line 903, in get_project
2023-04-06 19:05:45.268248 2023-04-06 19:05:45.264 28 ERROR keystone.server.flask.application     return self.driver.get_project(project_id)
2023-04-06 19:05:45.268257 2023-04-06 19:05:45.264 28 ERROR keystone.server.flask.application   File "/var/lib/kolla/venv/lib/python3.9/site-packages/keystone/resource/backends/sql.py", line 49, in get_project
2023-04-06 19:05:45.268267 2023-04-06 19:05:45.264 28 ERROR keystone.server.flask.application     return self._get_project(session, project_id).to_dict()
2023-04-06 19:05:45.268276 2023-04-06 19:05:45.264 28 ERROR keystone.server.flask.application   File "/var/lib/kolla/venv/lib/python3.9/site-packages/keystone/resource/backends/sql.py", line 44, in _get_project
2023-04-06 19:05:45.268285 2023-04-06 19:05:45.264 28 ERROR keystone.server.flask.application     raise exception.ProjectNotFound(project_id=project_id)
2023-04-06 19:05:45.268295 2023-04-06 19:05:45.264 28 ERROR keystone.server.flask.application keystone.exception.ProjectNotFound: Could not find project: service.
2023-04-06 19:05:45.268304 2023-04-06 19:05:45.264 28 ERROR keystone.server.flask.application \x1b[00m
2023-04-06 19:06:00.711632 2023-04-06 19:06:00.706 28 ERROR keystone.server.flask.application [None req-438a72f8-1b70-4e0f-978b-cf6d264e84f7 90e9542438684429b47beb5fc0bae2d1 - - all default -] Could not find role: admin.: keystone.exception.RoleNotFound: Could not find role: admin.
2023-04-06 19:06:00.711721 2023-04-06 19:06:00.706 28 ERROR keystone.server.flask.application Traceback (most recent call last):
2023-04-06 19:06:00.711733 2023-04-06 19:06:00.706 28 ERROR keystone.server.flask.application   File "/var/lib/kolla/venv/lib/python3.9/site-packages/flask/app.py", line 1820, in full_dispatch_request
2023-04-06 19:06:00.711743 2023-04-06 19:06:00.706 28 ERROR keystone.server.flask.application     rv = self.dispatch_request()
2023-04-06 19:06:00.711752 2023-04-06 19:06:00.706 28 ERROR keystone.server.flask.application   File "/var/lib/kolla/venv/lib/python3.9/site-packages/flask/app.py", line 1796, in dispatch_request
2023-04-06 19:06:00.711763 2023-04-06 19:06:00.706 28 ERROR keystone.server.flask.application     return self.ensure_sync(self.view_functions[rule.endpoint])(**view_args)
2023-04-06 19:06:00.711772 2023-04-06 19:06:00.706 28 ERROR keystone.server.flask.application   File "/var/lib/kolla/venv/lib/python3.9/site-packages/flask_restful/__init__.py", line 467, in wrapper
2023-04-06 19:06:00.711797 2023-04-06 19:06:00.706 28 ERROR keystone.server.flask.application     resp = resource(*args, **kwargs)
2023-04-06 19:06:00.711815 2023-04-06 19:06:00.706 28 ERROR keystone.server.flask.application   File "/var/lib/kolla/venv/lib/python3.9/site-packages/flask/views.py", line 107, in view
2023-04-06 19:06:00.711827 2023-04-06 19:06:00.706 28 ERROR keystone.server.flask.application     return current_app.ensure_sync(self.dispatch_request)(**kwargs)
2023-04-06 19:06:00.711837 2023-04-06 19:06:00.706 28 ERROR keystone.server.flask.application   File "/var/lib/kolla/venv/lib/python3.9/site-packages/flask_restful/__init__.py", line 582, in dispatch_request
2023-04-06 19:06:00.711846 2023-04-06 19:06:00.706 28 ERROR keystone.server.flask.application     resp = meth(*args, **kwargs)
2023-04-06 19:06:00.711856 2023-04-06 19:06:00.706 28 ERROR keystone.server.flask.application   File "/var/lib/kolla/venv/lib/python3.9/site-packages/keystone/api/roles.py", line 50, in get
2023-04-06 19:06:00.711865 2023-04-06 19:06:00.706 28 ERROR keystone.server.flask.application     return self._get_role(role_id)
2023-04-06 19:06:00.711874 2023-04-06 19:06:00.706 28 ERROR keystone.server.flask.application   File "/var/lib/kolla/venv/lib/python3.9/site-packages/keystone/api/roles.py", line 70, in _get_role
2023-04-06 19:06:00.711883 2023-04-06 19:06:00.706 28 ERROR keystone.server.flask.application     ENFORCER.enforce_call(action='identity:get_role')
2023-04-06 19:06:00.711893 2023-04-06 19:06:00.706 28 ERROR keystone.server.flask.application   File "/var/lib/kolla/venv/lib/python3.9/site-packages/keystone/common/rbac_enforcer/enforcer.py", line 402, in enforce_call
2023-04-06 19:06:00.711903 2023-04-06 19:06:00.706 28 ERROR keystone.server.flask.application     policy_dict.update(cls._extract_member_target_data(
2023-04-06 19:06:00.711913 2023-04-06 19:06:00.706 28 ERROR keystone.server.flask.application   File "/var/lib/kolla/venv/lib/python3.9/site-packages/keystone/common/rbac_enforcer/enforcer.py", line 234, in _extract_member_target_data
2023-04-06 19:06:00.711923 2023-04-06 19:06:00.706 28 ERROR keystone.server.flask.application     member_name: func(flask.request.view_args[key])
2023-04-06 19:06:00.711932 2023-04-06 19:06:00.706 28 ERROR keystone.server.flask.application   File "/var/lib/kolla/venv/lib/python3.9/site-packages/keystone/common/manager.py", line 115, in wrapped
2023-04-06 19:06:00.711942 2023-04-06 19:06:00.706 28 ERROR keystone.server.flask.application     __ret_val = __f(*args, **kwargs)
2023-04-06 19:06:00.711951 2023-04-06 19:06:00.706 28 ERROR keystone.server.flask.application   File "/var/lib/kolla/venv/lib/python3.9/site-packages/decorator.py", line 232, in fun
2023-04-06 19:06:00.711960 2023-04-06 19:06:00.706 28 ERROR keystone.server.flask.application     return caller(func, *(extras + args), **kw)
2023-04-06 19:06:00.711969 2023-04-06 19:06:00.706 28 ERROR keystone.server.flask.application   File "/var/lib/kolla/venv/lib/python3.9/site-packages/dogpile/cache/region.py", line 1577, in get_or_create_for_user_func
2023-04-06 19:06:00.711979 2023-04-06 19:06:00.706 28 ERROR keystone.server.flask.application     return self.get_or_create(
2023-04-06 19:06:00.711988 2023-04-06 19:06:00.706 28 ERROR keystone.server.flask.application   File "/var/lib/kolla/venv/lib/python3.9/site-packages/dogpile/cache/region.py", line 1042, in get_or_create
2023-04-06 19:06:00.712007 2023-04-06 19:06:00.706 28 ERROR keystone.server.flask.application     with Lock(
2023-04-06 19:06:00.712020 2023-04-06 19:06:00.706 28 ERROR keystone.server.flask.application   File "/var/lib/kolla/venv/lib/python3.9/site-packages/dogpile/lock.py", line 185, in __enter__
2023-04-06 19:06:00.712030 2023-04-06 19:06:00.706 28 ERROR keystone.server.flask.application     return self._enter()
2023-04-06 19:06:00.712039 2023-04-06 19:06:00.706 28 ERROR keystone.server.flask.application   File "/var/lib/kolla/venv/lib/python3.9/site-packages/dogpile/lock.py", line 94, in _enter
2023-04-06 19:06:00.712067 2023-04-06 19:06:00.706 28 ERROR keystone.server.flask.application     generated = self._enter_create(value, createdtime)
2023-04-06 19:06:00.712078 2023-04-06 19:06:00.706 28 ERROR keystone.server.flask.application   File "/var/lib/kolla/venv/lib/python3.9/site-packages/dogpile/lock.py", line 178, in _enter_create
2023-04-06 19:06:00.712087 2023-04-06 19:06:00.706 28 ERROR keystone.server.flask.application     return self.creator()
2023-04-06 19:06:00.712096 2023-04-06 19:06:00.706 28 ERROR keystone.server.flask.application   File "/var/lib/kolla/venv/lib/python3.9/site-packages/dogpile/cache/region.py", line 995, in gen_value
2023-04-06 19:06:00.712106 2023-04-06 19:06:00.706 28 ERROR keystone.server.flask.application     created_value = creator(
2023-04-06 19:06:00.712115 2023-04-06 19:06:00.706 28 ERROR keystone.server.flask.application   File "/var/lib/kolla/venv/lib/python3.9/site-packages/keystone/assignment/core.py", line 1276, in get_role
2023-04-06 19:06:00.712125 2023-04-06 19:06:00.706 28 ERROR keystone.server.flask.application     return self.driver.get_role(role_id)
2023-04-06 19:06:00.712134 2023-04-06 19:06:00.706 28 ERROR keystone.server.flask.application   File "/var/lib/kolla/venv/lib/python3.9/site-packages/keystone/assignment/role_backends/sql.py", line 70, in get_role
2023-04-06 19:06:00.712144 2023-04-06 19:06:00.706 28 ERROR keystone.server.flask.application     return self._get_role(session, role_id).to_dict()
2023-04-06 19:06:00.712153 2023-04-06 19:06:00.706 28 ERROR keystone.server.flask.application   File "/var/lib/kolla/venv/lib/python3.9/site-packages/keystone/assignment/role_backends/sql.py", line 65, in _get_role
2023-04-06 19:06:00.712163 2023-04-06 19:06:00.706 28 ERROR keystone.server.flask.application     raise exception.RoleNotFound(role_id=role_id)
2023-04-06 19:06:00.712191 2023-04-06 19:06:00.706 28 ERROR keystone.server.flask.application keystone.exception.RoleNotFound: Could not find role: admin.
2023-04-06 19:06:00.712204 2023-04-06 19:06:00.706 28 ERROR keystone.server.flask.application \x1b[00m
2023-04-06 19:06:02.107733 2023-04-06 19:06:02.102 28 ERROR keystone.server.flask.application [None req-d29c4052-f634-4470-ba4e-c9589d101b80 90e9542438684429b47beb5fc0bae2d1 - - all default -] Could not find user: neutron.: keystone.exception.UserNotFound: Could not find user: neutron.
2023-04-06 19:06:02.107799 2023-04-06 19:06:02.102 28 ERROR keystone.server.flask.application Traceback (most recent call last):
2023-04-06 19:06:02.107811 2023-04-06 19:06:02.102 28 ERROR keystone.server.flask.application   File "/var/lib/kolla/venv/lib/python3.9/site-packages/flask/app.py", line 1820, in full_dispatch_request
2023-04-06 19:06:02.107821 2023-04-06 19:06:02.102 28 ERROR keystone.server.flask.application     rv = self.dispatch_request()
2023-04-06 19:06:02.107831 2023-04-06 19:06:02.102 28 ERROR keystone.server.flask.application   File "/var/lib/kolla/venv/lib/python3.9/site-packages/flask/app.py", line 1796, in dispatch_request
2023-04-06 19:06:02.107841 2023-04-06 19:06:02.102 28 ERROR keystone.server.flask.application     return self.ensure_sync(self.view_functions[rule.endpoint])(**view_args)
2023-04-06 19:06:02.107850 2023-04-06 19:06:02.102 28 ERROR keystone.server.flask.application   File "/var/lib/kolla/venv/lib/python3.9/site-packages/flask_restful/__init__.py", line 467, in wrapper
2023-04-06 19:06:02.107859 2023-04-06 19:06:02.102 28 ERROR keystone.server.flask.application     resp = resource(*args, **kwargs)
2023-04-06 19:06:02.107869 2023-04-06 19:06:02.102 28 ERROR keystone.server.flask.application   File "/var/lib/kolla/venv/lib/python3.9/site-packages/flask/views.py", line 107, in view
2023-04-06 19:06:02.107879 2023-04-06 19:06:02.102 28 ERROR keystone.server.flask.application     return current_app.ensure_sync(self.dispatch_request)(**kwargs)
2023-04-06 19:06:02.107892 2023-04-06 19:06:02.102 28 ERROR keystone.server.flask.application   File "/var/lib/kolla/venv/lib/python3.9/site-packages/flask_restful/__init__.py", line 582, in dispatch_request
2023-04-06 19:06:02.107949 2023-04-06 19:06:02.102 28 ERROR keystone.server.flask.application     resp = meth(*args, **kwargs)
2023-04-06 19:06:02.107960 2023-04-06 19:06:02.102 28 ERROR keystone.server.flask.application   File "/var/lib/kolla/venv/lib/python3.9/site-packages/keystone/api/users.py", line 182, in get
2023-04-06 19:06:02.107970 2023-04-06 19:06:02.102 28 ERROR keystone.server.flask.application     return self._get_user(user_id)
2023-04-06 19:06:02.107979 2023-04-06 19:06:02.102 28 ERROR keystone.server.flask.application   File "/var/lib/kolla/venv/lib/python3.9/site-packages/keystone/api/users.py", line 194, in _get_user
2023-04-06 19:06:02.107993 2023-04-06 19:06:02.102 28 ERROR keystone.server.flask.application     ref = PROVIDERS.identity_api.get_user(user_id)
2023-04-06 19:06:02.108002 2023-04-06 19:06:02.102 28 ERROR keystone.server.flask.application   File "/var/lib/kolla/venv/lib/python3.9/site-packages/keystone/common/manager.py", line 115, in wrapped
2023-04-06 19:06:02.108018 2023-04-06 19:06:02.102 28 ERROR keystone.server.flask.application     __ret_val = __f(*args, **kwargs)
2023-04-06 19:06:02.108027 2023-04-06 19:06:02.102 28 ERROR keystone.server.flask.application   File "/var/lib/kolla/venv/lib/python3.9/site-packages/keystone/identity/core.py", line 414, in wrapper
2023-04-06 19:06:02.108036 2023-04-06 19:06:02.102 28 ERROR keystone.server.flask.application     return f(self, *args, **kwargs)
2023-04-06 19:06:02.108045 2023-04-06 19:06:02.102 28 ERROR keystone.server.flask.application   File "/var/lib/kolla/venv/lib/python3.9/site-packages/keystone/identity/core.py", line 424, in wrapper
2023-04-06 19:06:02.108055 2023-04-06 19:06:02.102 28 ERROR keystone.server.flask.application     return f(self, *args, **kwargs)
2023-04-06 19:06:02.108064 2023-04-06 19:06:02.102 28 ERROR keystone.server.flask.application   File "/var/lib/kolla/venv/lib/python3.9/site-packages/decorator.py", line 232, in fun
2023-04-06 19:06:02.108073 2023-04-06 19:06:02.102 28 ERROR keystone.server.flask.application     return caller(func, *(extras + args), **kw)
2023-04-06 19:06:02.108098 2023-04-06 19:06:02.102 28 ERROR keystone.server.flask.application   File "/var/lib/kolla/venv/lib/python3.9/site-packages/dogpile/cache/region.py", line 1577, in get_or_create_for_user_func
2023-04-06 19:06:02.108107 2023-04-06 19:06:02.102 28 ERROR keystone.server.flask.application     return self.get_or_create(
2023-04-06 19:06:02.108117 2023-04-06 19:06:02.102 28 ERROR keystone.server.flask.application   File "/var/lib/kolla/venv/lib/python3.9/site-packages/dogpile/cache/region.py", line 1042, in get_or_create
2023-04-06 19:06:02.108126 2023-04-06 19:06:02.102 28 ERROR keystone.server.flask.application     with Lock(
2023-04-06 19:06:02.108135 2023-04-06 19:06:02.102 28 ERROR keystone.server.flask.application   File "/var/lib/kolla/venv/lib/python3.9/site-packages/dogpile/lock.py", line 185, in __enter__
2023-04-06 19:06:02.108145 2023-04-06 19:06:02.102 28 ERROR keystone.server.flask.application     return self._enter()
2023-04-06 19:06:02.108154 2023-04-06 19:06:02.102 28 ERROR keystone.server.flask.application   File "/var/lib/kolla/venv/lib/python3.9/site-packages/dogpile/lock.py", line 94, in _enter
2023-04-06 19:06:02.108163 2023-04-06 19:06:02.102 28 ERROR keystone.server.flask.application     generated = self._enter_create(value, createdtime)
2023-04-06 19:06:02.108190 2023-04-06 19:06:02.102 28 ERROR keystone.server.flask.application   File "/var/lib/kolla/venv/lib/python3.9/site-packages/dogpile/lock.py", line 178, in _enter_create
2023-04-06 19:06:02.108211 2023-04-06 19:06:02.102 28 ERROR keystone.server.flask.application     return self.creator()
2023-04-06 19:06:02.108221 2023-04-06 19:06:02.102 28 ERROR keystone.server.flask.application   File "/var/lib/kolla/venv/lib/python3.9/site-packages/dogpile/cache/region.py", line 995, in gen_value
2023-04-06 19:06:02.108231 2023-04-06 19:06:02.102 28 ERROR keystone.server.flask.application     created_value = creator(
2023-04-06 19:06:02.108254 2023-04-06 19:06:02.102 28 ERROR keystone.server.flask.application   File "/var/lib/kolla/venv/lib/python3.9/site-packages/keystone/identity/core.py", line 1011, in get_user
2023-04-06 19:06:02.108265 2023-04-06 19:06:02.102 28 ERROR keystone.server.flask.application     ref = driver.get_user(entity_id)
2023-04-06 19:06:02.108274 2023-04-06 19:06:02.102 28 ERROR keystone.server.flask.application   File "/var/lib/kolla/venv/lib/python3.9/site-packages/keystone/identity/backends/sql.py", line 200, in get_user
2023-04-06 19:06:02.108284 2023-04-06 19:06:02.102 28 ERROR keystone.server.flask.application     self._get_user(session, user_id).to_dict())
2023-04-06 19:06:02.108293 2023-04-06 19:06:02.102 28 ERROR keystone.server.flask.application   File "/var/lib/kolla/venv/lib/python3.9/site-packages/keystone/identity/backends/sql.py", line 194, in _get_user
2023-04-06 19:06:02.108303 2023-04-06 19:06:02.102 28 ERROR keystone.server.flask.application     raise exception.UserNotFound(user_id=user_id)
2023-04-06 19:06:02.108312 2023-04-06 19:06:02.102 28 ERROR keystone.server.flask.application keystone.exception.UserNotFound: Could not find user: neutron.
2023-04-06 19:06:02.108322 2023-04-06 19:06:02.102 28 ERROR keystone.server.flask.application \x1b[00m
2023-04-06 19:06:03.024564 2023-04-06 19:06:03.019 27 ERROR keystone.server.flask.application [None req-b12d86fb-117f-4e1d-8031-d51dde0ac734 90e9542438684429b47beb5fc0bae2d1 - - all default -] Could not find project: service.: keystone.exception.ProjectNotFound: Could not find project: service.
2023-04-06 19:06:03.024671 2023-04-06 19:06:03.019 27 ERROR keystone.server.flask.application Traceback (most recent call last):
2023-04-06 19:06:03.024684 2023-04-06 19:06:03.019 27 ERROR keystone.server.flask.application   File "/var/lib/kolla/venv/lib/python3.9/site-packages/flask/app.py", line 1820, in full_dispatch_request
2023-04-06 19:06:03.024712 2023-04-06 19:06:03.019 27 ERROR keystone.server.flask.application     rv = self.dispatch_request()
2023-04-06 19:06:03.024723 2023-04-06 19:06:03.019 27 ERROR keystone.server.flask.application   File "/var/lib/kolla/venv/lib/python3.9/site-packages/flask/app.py", line 1796, in dispatch_request
2023-04-06 19:06:03.024734 2023-04-06 19:06:03.019 27 ERROR keystone.server.flask.application     return self.ensure_sync(self.view_functions[rule.endpoint])(**view_args)
2023-04-06 19:06:03.024745 2023-04-06 19:06:03.019 27 ERROR keystone.server.flask.application   File "/var/lib/kolla/venv/lib/python3.9/site-packages/flask_restful/__init__.py", line 467, in wrapper
2023-04-06 19:06:03.024766 2023-04-06 19:06:03.019 27 ERROR keystone.server.flask.application     resp = resource(*args, **kwargs)
2023-04-06 19:06:03.024777 2023-04-06 19:06:03.019 27 ERROR keystone.server.flask.application   File "/var/lib/kolla/venv/lib/python3.9/site-packages/flask/views.py", line 107, in view
2023-04-06 19:06:03.024789 2023-04-06 19:06:03.019 27 ERROR keystone.server.flask.application     return current_app.ensure_sync(self.dispatch_request)(**kwargs)
2023-04-06 19:06:03.024800 2023-04-06 19:06:03.019 27 ERROR keystone.server.flask.application   File "/var/lib/kolla/venv/lib/python3.9/site-packages/flask_restful/__init__.py", line 582, in dispatch_request
2023-04-06 19:06:03.024811 2023-04-06 19:06:03.019 27 ERROR keystone.server.flask.application     resp = meth(*args, **kwargs)
2023-04-06 19:06:03.024822 2023-04-06 19:06:03.019 27 ERROR keystone.server.flask.application   File "/var/lib/kolla/venv/lib/python3.9/site-packages/keystone/api/projects.py", line 151, in get
2023-04-06 19:06:03.024833 2023-04-06 19:06:03.019 27 ERROR keystone.server.flask.application     return self._get_project(project_id)
2023-04-06 19:06:03.024844 2023-04-06 19:06:03.019 27 ERROR keystone.server.flask.application   File "/var/lib/kolla/venv/lib/python3.9/site-packages/keystone/api/projects.py", line 107, in _get_project
2023-04-06 19:06:03.024855 2023-04-06 19:06:03.019 27 ERROR keystone.server.flask.application     project = PROVIDERS.resource_api.get_project(project_id)
2023-04-06 19:06:03.024887 2023-04-06 19:06:03.019 27 ERROR keystone.server.flask.application   File "/var/lib/kolla/venv/lib/python3.9/site-packages/keystone/common/manager.py", line 115, in wrapped
2023-04-06 19:06:03.024900 2023-04-06 19:06:03.019 27 ERROR keystone.server.flask.application     __ret_val = __f(*args, **kwargs)
2023-04-06 19:06:03.024911 2023-04-06 19:06:03.019 27 ERROR keystone.server.flask.application   File "/var/lib/kolla/venv/lib/python3.9/site-packages/decorator.py", line 232, in fun
2023-04-06 19:06:03.024931 2023-04-06 19:06:03.019 27 ERROR keystone.server.flask.application     return caller(func, *(extras + args), **kw)
2023-04-06 19:06:03.024942 2023-04-06 19:06:03.019 27 ERROR keystone.server.flask.application   File "/var/lib/kolla/venv/lib/python3.9/site-packages/dogpile/cache/region.py", line 1577, in get_or_create_for_user_func
2023-04-06 19:06:03.024953 2023-04-06 19:06:03.019 27 ERROR keystone.server.flask.application     return self.get_or_create(
2023-04-06 19:06:03.024964 2023-04-06 19:06:03.019 27 ERROR keystone.server.flask.application   File "/var/lib/kolla/venv/lib/python3.9/site-packages/dogpile/cache/region.py", line 1042, in get_or_create
2023-04-06 19:06:03.024976 2023-04-06 19:06:03.019 27 ERROR keystone.server.flask.application     with Lock(
2023-04-06 19:06:03.024987 2023-04-06 19:06:03.019 27 ERROR keystone.server.flask.application   File "/var/lib/kolla/venv/lib/python3.9/site-packages/dogpile/lock.py", line 185, in __enter__
2023-04-06 19:06:03.024998 2023-04-06 19:06:03.019 27 ERROR keystone.server.flask.application     return self._enter()
2023-04-06 19:06:03.025008 2023-04-06 19:06:03.019 27 ERROR keystone.server.flask.application   File "/var/lib/kolla/venv/lib/python3.9/site-packages/dogpile/lock.py", line 94, in _enter
2023-04-06 19:06:03.025020 2023-04-06 19:06:03.019 27 ERROR keystone.server.flask.application     generated = self._enter_create(value, createdtime)
2023-04-06 19:06:03.025030 2023-04-06 19:06:03.019 27 ERROR keystone.server.flask.application   File "/var/lib/kolla/venv/lib/python3.9/site-packages/dogpile/lock.py", line 178, in _enter_create
2023-04-06 19:06:03.025066 2023-04-06 19:06:03.019 27 ERROR keystone.server.flask.application     return self.creator()
2023-04-06 19:06:03.025079 2023-04-06 19:06:03.019 27 ERROR keystone.server.flask.application   File "/var/lib/kolla/venv/lib/python3.9/site-packages/dogpile/cache/region.py", line 995, in gen_value
2023-04-06 19:06:03.025107 2023-04-06 19:06:03.019 27 ERROR keystone.server.flask.application     created_value = creator(
2023-04-06 19:06:03.025141 2023-04-06 19:06:03.019 27 ERROR keystone.server.flask.application   File "/var/lib/kolla/venv/lib/python3.9/site-packages/keystone/resource/core.py", line 903, in get_project
2023-04-06 19:06:03.025203 2023-04-06 19:06:03.019 27 ERROR keystone.server.flask.application     return self.driver.get_project(project_id)
2023-04-06 19:06:03.025230 2023-04-06 19:06:03.019 27 ERROR keystone.server.flask.application   File "/var/lib/kolla/venv/lib/python3.9/site-packages/keystone/resource/backends/sql.py", line 49, in get_project
2023-04-06 19:06:03.025253 2023-04-06 19:06:03.019 27 ERROR keystone.server.flask.application     return self._get_project(session, project_id).to_dict()
2023-04-06 19:06:03.025292 2023-04-06 19:06:03.019 27 ERROR keystone.server.flask.application   File "/var/lib/kolla/venv/lib/python3.9/site-packages/keystone/resource/backends/sql.py", line 44, in _get_project
2023-04-06 19:06:03.025313 2023-04-06 19:06:03.019 27 ERROR keystone.server.flask.application     raise exception.ProjectNotFound(project_id=project_id)
2023-04-06 19:06:03.025333 2023-04-06 19:06:03.019 27 ERROR keystone.server.flask.application keystone.exception.ProjectNotFound: Could not find project: service.
2023-04-06 19:06:03.025353 2023-04-06 19:06:03.019 27 ERROR keystone.server.flask.application \x1b[00m
2023-04-06 20:02:21.503028 2023-04-06 20:02:21.500 28 WARNING py.warnings [None req-733d0077-ed85-4cf5-9fe4-f81a923ce35a 90e9542438684429b47beb5fc0bae2d1 3cfef37cf9ff4631a6ebfbf1b1390f84 - - default default] /var/lib/kolla/venv/lib/python3.9/site-packages/oslo_policy/policy.py:1129: UserWarning: Policy "identity:list_domains": "role:reader and system_scope:all" failed scope check. The token used to make the request was project scoped but the policy requires ['system'] scope. This behavior may change in the future where using the intended scope is required
2023-04-06 20:02:21.503293   warnings.warn(msg)
2023-04-06 20:02:21.503316 \x1b[00m
2023-04-06 20:02:21.776717 2023-04-06 20:02:21.774 27 WARNING py.warnings [None req-b6a45f36-7b73-430e-bc88-b56745810dc3 90e9542438684429b47beb5fc0bae2d1 3cfef37cf9ff4631a6ebfbf1b1390f84 - - default default] /var/lib/kolla/venv/lib/python3.9/site-packages/oslo_policy/policy.py:1129: UserWarning: Policy "identity:create_project": "(role:admin and system_scope:all) or (role:admin and domain_id:%(target.project.domain_id)s)" failed scope check. The token used to make the request was project scoped but the policy requires ['system', 'domain'] scope. This behavior may change in the future where using the intended scope is required
2023-04-06 20:02:21.776777   warnings.warn(msg)
2023-04-06 20:02:21.776815 \x1b[00m
2023-04-06 20:02:22.187936 2023-04-06 20:02:22.186 28 WARNING py.warnings [None req-47461ee8-cab6-4835-99a3-9154162c0348 90e9542438684429b47beb5fc0bae2d1 3cfef37cf9ff4631a6ebfbf1b1390f84 - - default default] /var/lib/kolla/venv/lib/python3.9/site-packages/oslo_policy/policy.py:1129: UserWarning: Policy "identity:create_user": "(role:admin and system_scope:all) or (role:admin and token.domain.id:%(target.user.domain_id)s)" failed scope check. The token used to make the request was project scoped but the policy requires ['system', 'domain'] scope. This behavior may change in the future where using the intended scope is required
2023-04-06 20:02:22.187994   warnings.warn(msg)
2023-04-06 20:02:22.188010 \x1b[00m
2023-04-06 20:02:23.080575 2023-04-06 20:02:23.079 27 WARNING py.warnings [None req-6cab8e55-2dfd-4446-b4b4-4bc400d9b21b 90e9542438684429b47beb5fc0bae2d1 3cfef37cf9ff4631a6ebfbf1b1390f84 - - default default] /var/lib/kolla/venv/lib/python3.9/site-packages/oslo_policy/policy.py:1129: UserWarning: Policy "identity:list_roles": "role:reader and system_scope:all" failed scope check. The token used to make the request was project scoped but the policy requires ['system'] scope. This behavior may change in the future where using the intended scope is required
2023-04-06 20:02:23.080629   warnings.warn(msg)
2023-04-06 20:02:23.080640 \x1b[00m
2023-04-06 20:02:23.436316 2023-04-06 20:02:23.435 28 WARNING py.warnings [None req-a468007e-7209-481d-8984-da0d15d33af2 90e9542438684429b47beb5fc0bae2d1 3cfef37cf9ff4631a6ebfbf1b1390f84 - - default default] /var/lib/kolla/venv/lib/python3.9/site-packages/oslo_policy/policy.py:1129: UserWarning: Policy "identity:create_grant": "(role:admin and system_scope:all) or ((role:admin and domain_id:%(target.user.domain_id)s and domain_id:%(target.project.domain_id)s) or (role:admin and domain_id:%(target.user.domain_id)s and domain_id:%(target.domain.id)s) or (role:admin and domain_id:%(target.group.domain_id)s and domain_id:%(target.project.domain_id)s) or (role:admin and domain_id:%(target.group.domain_id)s and domain_id:%(target.domain.id)s)) and (domain_id:%(target.role.domain_id)s or None:%(target.role.domain_id)s)" failed scope check. The token used to make the request was project scoped but the policy requires ['system', 'domain'] scope. This behavior may change in the future where using the intended scope is required
2023-04-06 20:02:23.436363   warnings.warn(msg)
2023-04-06 20:02:23.436374 \x1b[00m
2023-04-06 20:02:24.741543 2023-04-06 20:02:24.739 26 WARNING py.warnings [None req-84e21256-b39c-4f52-aa5d-07a39c5d34a3 90e9542438684429b47beb5fc0bae2d1 3cfef37cf9ff4631a6ebfbf1b1390f84 - - default default] /var/lib/kolla/venv/lib/python3.9/site-packages/oslo_policy/policy.py:1129: UserWarning: Policy "identity:create_project": "(role:admin and system_scope:all) or (role:admin and domain_id:%(target.project.domain_id)s)" failed scope check. The token used to make the request was project scoped but the policy requires ['system', 'domain'] scope. This behavior may change in the future where using the intended scope is required
2023-04-06 20:02:24.741634   warnings.warn(msg)
2023-04-06 20:02:24.741647 \x1b[00m
2023-04-06 20:02:26.436625 2023-04-06 20:02:26.435 26 WARNING py.warnings [None req-fbc4e446-5f81-4da6-8037-fe4e9c338fe4 90e9542438684429b47beb5fc0bae2d1 3cfef37cf9ff4631a6ebfbf1b1390f84 - - default default] /var/lib/kolla/venv/lib/python3.9/site-packages/oslo_policy/policy.py:1129: UserWarning: Policy "identity:create_grant": "(role:admin and system_scope:all) or ((role:admin and domain_id:%(target.user.domain_id)s and domain_id:%(target.project.domain_id)s) or (role:admin and domain_id:%(target.user.domain_id)s and domain_id:%(target.domain.id)s) or (role:admin and domain_id:%(target.group.domain_id)s and domain_id:%(target.project.domain_id)s) or (role:admin and domain_id:%(target.group.domain_id)s and domain_id:%(target.domain.id)s)) and (domain_id:%(target.role.domain_id)s or None:%(target.role.domain_id)s)" failed scope check. The token used to make the request was project scoped but the policy requires ['system', 'domain'] scope. This behavior may change in the future where using the intended scope is required
2023-04-06 20:02:26.436746   warnings.warn(msg)
2023-04-06 20:02:26.436758 \x1b[00m
2023-04-06 20:02:26.692228 2023-04-06 20:02:26.691 28 WARNING py.warnings [None req-0afdd35a-33ee-4e74-9660-45c9f9879540 90e9542438684429b47beb5fc0bae2d1 3cfef37cf9ff4631a6ebfbf1b1390f84 - - default default] /var/lib/kolla/venv/lib/python3.9/site-packages/oslo_policy/policy.py:1129: UserWarning: Policy "identity:list_roles": "role:reader and system_scope:all" failed scope check. The token used to make the request was project scoped but the policy requires ['system'] scope. This behavior may change in the future where using the intended scope is required
2023-04-06 20:02:26.692273   warnings.warn(msg)
2023-04-06 20:02:26.692283 \x1b[00m
2023-04-06 20:02:26.998801 2023-04-06 20:02:26.997 27 WARNING py.warnings [None req-52be1b6a-f3c3-443c-b367-db9c58b13bde 90e9542438684429b47beb5fc0bae2d1 3cfef37cf9ff4631a6ebfbf1b1390f84 - - default default] /var/lib/kolla/venv/lib/python3.9/site-packages/oslo_policy/policy.py:1129: UserWarning: Policy "identity:create_grant": "(role:admin and system_scope:all) or ((role:admin and domain_id:%(target.user.domain_id)s and domain_id:%(target.project.domain_id)s) or (role:admin and domain_id:%(target.user.domain_id)s and domain_id:%(target.domain.id)s) or (role:admin and domain_id:%(target.group.domain_id)s and domain_id:%(target.project.domain_id)s) or (role:admin and domain_id:%(target.group.domain_id)s and domain_id:%(target.domain.id)s)) and (domain_id:%(target.role.domain_id)s or None:%(target.role.domain_id)s)" failed scope check. The token used to make the request was project scoped but the policy requires ['system', 'domain'] scope. This behavior may change in the future where using the intended scope is required
2023-04-06 20:02:26.998852   warnings.warn(msg)
2023-04-06 20:02:26.998864 \x1b[00m
2023-04-06 20:02:29.323128 2023-04-06 20:02:29.322 26 WARNING py.warnings [None req-7d6558ee-6b5a-4a76-851c-171174cd66cb 90e9542438684429b47beb5fc0bae2d1 3cfef37cf9ff4631a6ebfbf1b1390f84 - - default default] /var/lib/kolla/venv/lib/python3.9/site-packages/oslo_policy/policy.py:1129: UserWarning: Policy "identity:create_system_grant_for_user": "role:admin and system_scope:all" failed scope check. The token used to make the request was project scoped but the policy requires ['system'] scope. This behavior may change in the future where using the intended scope is required
2023-04-06 20:02:29.323179   warnings.warn(msg)
2023-04-06 20:02:29.323191 \x1b[00m
