2023-04-04 18:19:07.340522 2023-04-04 18:19:07.339 39 WARNING keystone.common.rbac_enforcer.enforcer [None req-9bbe55e6-a866-484d-aae9-05b62a7200d0 5e04de7c8cdd40229d63c638acb175bd - - all default -] Deprecated policy rules found. Use oslopolicy-policy-generator and oslopolicy-policy-upgrade to detect and resolve deprecated policies in your configuration.\x1b[00m
2023-04-04 18:19:08.125942 2023-04-04 18:19:08.124 38 WARNING keystone.common.rbac_enforcer.enforcer [None req-ab1bf32b-2ccd-47a4-bd3e-3800c2b62fdf 5e04de7c8cdd40229d63c638acb175bd - - all default -] Deprecated policy rules found. Use oslopolicy-policy-generator and oslopolicy-policy-upgrade to detect and resolve deprecated policies in your configuration.\x1b[00m
2023-04-04 18:19:14.898874 2023-04-04 18:19:14.895 37 WARNING keystone.common.rbac_enforcer.enforcer [None req-e1797b30-c318-4ca6-93df-d50737dc03d2 5e04de7c8cdd40229d63c638acb175bd - - all default -] Deprecated policy rules found. Use oslopolicy-policy-generator and oslopolicy-policy-upgrade to detect and resolve deprecated policies in your configuration.\x1b[00m
2023-04-04 18:20:27.176658 2023-04-04 18:20:27.166 39 ERROR keystone.server.flask.application [None req-d1d6f33c-184c-41cd-9cac-38a3316ef6f3 5e04de7c8cdd40229d63c638acb175bd - - all default -] Could not find project: service.: keystone.exception.ProjectNotFound: Could not find project: service.
2023-04-04 18:20:27.176704 2023-04-04 18:20:27.166 39 ERROR keystone.server.flask.application Traceback (most recent call last):
2023-04-04 18:20:27.176716 2023-04-04 18:20:27.166 39 ERROR keystone.server.flask.application   File "/var/lib/kolla/venv/lib/python3.9/site-packages/flask/app.py", line 1820, in full_dispatch_request
2023-04-04 18:20:27.176727 2023-04-04 18:20:27.166 39 ERROR keystone.server.flask.application     rv = self.dispatch_request()
2023-04-04 18:20:27.176736 2023-04-04 18:20:27.166 39 ERROR keystone.server.flask.application   File "/var/lib/kolla/venv/lib/python3.9/site-packages/flask/app.py", line 1796, in dispatch_request
2023-04-04 18:20:27.176746 2023-04-04 18:20:27.166 39 ERROR keystone.server.flask.application     return self.ensure_sync(self.view_functions[rule.endpoint])(**view_args)
2023-04-04 18:20:27.176756 2023-04-04 18:20:27.166 39 ERROR keystone.server.flask.application   File "/var/lib/kolla/venv/lib/python3.9/site-packages/flask_restful/__init__.py", line 467, in wrapper
2023-04-04 18:20:27.176765 2023-04-04 18:20:27.166 39 ERROR keystone.server.flask.application     resp = resource(*args, **kwargs)
2023-04-04 18:20:27.176775 2023-04-04 18:20:27.166 39 ERROR keystone.server.flask.application   File "/var/lib/kolla/venv/lib/python3.9/site-packages/flask/views.py", line 107, in view
2023-04-04 18:20:27.176785 2023-04-04 18:20:27.166 39 ERROR keystone.server.flask.application     return current_app.ensure_sync(self.dispatch_request)(**kwargs)
2023-04-04 18:20:27.176794 2023-04-04 18:20:27.166 39 ERROR keystone.server.flask.application   File "/var/lib/kolla/venv/lib/python3.9/site-packages/flask_restful/__init__.py", line 582, in dispatch_request
2023-04-04 18:20:27.176803 2023-04-04 18:20:27.166 39 ERROR keystone.server.flask.application     resp = meth(*args, **kwargs)
2023-04-04 18:20:27.176813 2023-04-04 18:20:27.166 39 ERROR keystone.server.flask.application   File "/var/lib/kolla/venv/lib/python3.9/site-packages/keystone/api/projects.py", line 151, in get
2023-04-04 18:20:27.176829 2023-04-04 18:20:27.166 39 ERROR keystone.server.flask.application     return self._get_project(project_id)
2023-04-04 18:20:27.176838 2023-04-04 18:20:27.166 39 ERROR keystone.server.flask.application   File "/var/lib/kolla/venv/lib/python3.9/site-packages/keystone/api/projects.py", line 107, in _get_project
2023-04-04 18:20:27.176847 2023-04-04 18:20:27.166 39 ERROR keystone.server.flask.application     project = PROVIDERS.resource_api.get_project(project_id)
2023-04-04 18:20:27.176857 2023-04-04 18:20:27.166 39 ERROR keystone.server.flask.application   File "/var/lib/kolla/venv/lib/python3.9/site-packages/keystone/common/manager.py", line 115, in wrapped
2023-04-04 18:20:27.176896 2023-04-04 18:20:27.166 39 ERROR keystone.server.flask.application     __ret_val = __f(*args, **kwargs)
2023-04-04 18:20:27.176909 2023-04-04 18:20:27.166 39 ERROR keystone.server.flask.application   File "/var/lib/kolla/venv/lib/python3.9/site-packages/decorator.py", line 232, in fun
2023-04-04 18:20:27.176918 2023-04-04 18:20:27.166 39 ERROR keystone.server.flask.application     return caller(func, *(extras + args), **kw)
2023-04-04 18:20:27.176928 2023-04-04 18:20:27.166 39 ERROR keystone.server.flask.application   File "/var/lib/kolla/venv/lib/python3.9/site-packages/dogpile/cache/region.py", line 1577, in get_or_create_for_user_func
2023-04-04 18:20:27.176938 2023-04-04 18:20:27.166 39 ERROR keystone.server.flask.application     return self.get_or_create(
2023-04-04 18:20:27.176948 2023-04-04 18:20:27.166 39 ERROR keystone.server.flask.application   File "/var/lib/kolla/venv/lib/python3.9/site-packages/dogpile/cache/region.py", line 1042, in get_or_create
2023-04-04 18:20:27.176958 2023-04-04 18:20:27.166 39 ERROR keystone.server.flask.application     with Lock(
2023-04-04 18:20:27.176967 2023-04-04 18:20:27.166 39 ERROR keystone.server.flask.application   File "/var/lib/kolla/venv/lib/python3.9/site-packages/dogpile/lock.py", line 185, in __enter__
2023-04-04 18:20:27.176976 2023-04-04 18:20:27.166 39 ERROR keystone.server.flask.application     return self._enter()
2023-04-04 18:20:27.176986 2023-04-04 18:20:27.166 39 ERROR keystone.server.flask.application   File "/var/lib/kolla/venv/lib/python3.9/site-packages/dogpile/lock.py", line 94, in _enter
2023-04-04 18:20:27.176996 2023-04-04 18:20:27.166 39 ERROR keystone.server.flask.application     generated = self._enter_create(value, createdtime)
2023-04-04 18:20:27.177005 2023-04-04 18:20:27.166 39 ERROR keystone.server.flask.application   File "/var/lib/kolla/venv/lib/python3.9/site-packages/dogpile/lock.py", line 178, in _enter_create
2023-04-04 18:20:27.177015 2023-04-04 18:20:27.166 39 ERROR keystone.server.flask.application     return self.creator()
2023-04-04 18:20:27.177025 2023-04-04 18:20:27.166 39 ERROR keystone.server.flask.application   File "/var/lib/kolla/venv/lib/python3.9/site-packages/dogpile/cache/region.py", line 995, in gen_value
2023-04-04 18:20:27.177035 2023-04-04 18:20:27.166 39 ERROR keystone.server.flask.application     created_value = creator(
2023-04-04 18:20:27.177044 2023-04-04 18:20:27.166 39 ERROR keystone.server.flask.application   File "/var/lib/kolla/venv/lib/python3.9/site-packages/keystone/resource/core.py", line 903, in get_project
2023-04-04 18:20:27.177054 2023-04-04 18:20:27.166 39 ERROR keystone.server.flask.application     return self.driver.get_project(project_id)
2023-04-04 18:20:27.177063 2023-04-04 18:20:27.166 39 ERROR keystone.server.flask.application   File "/var/lib/kolla/venv/lib/python3.9/site-packages/keystone/resource/backends/sql.py", line 49, in get_project
2023-04-04 18:20:27.177073 2023-04-04 18:20:27.166 39 ERROR keystone.server.flask.application     return self._get_project(session, project_id).to_dict()
2023-04-04 18:20:27.177083 2023-04-04 18:20:27.166 39 ERROR keystone.server.flask.application   File "/var/lib/kolla/venv/lib/python3.9/site-packages/keystone/resource/backends/sql.py", line 44, in _get_project
2023-04-04 18:20:27.177092 2023-04-04 18:20:27.166 39 ERROR keystone.server.flask.application     raise exception.ProjectNotFound(project_id=project_id)
2023-04-04 18:20:27.177102 2023-04-04 18:20:27.166 39 ERROR keystone.server.flask.application keystone.exception.ProjectNotFound: Could not find project: service.
2023-04-04 18:20:27.177111 2023-04-04 18:20:27.166 39 ERROR keystone.server.flask.application \x1b[00m
2023-04-04 18:20:35.820388 2023-04-04 18:20:35.807 37 ERROR keystone.server.flask.application [None req-998fbf43-dad5-43fb-a275-2af1f5e1887d 5e04de7c8cdd40229d63c638acb175bd - - all default -] Could not find project: service.: keystone.exception.ProjectNotFound: Could not find project: service.
2023-04-04 18:20:35.820453 2023-04-04 18:20:35.807 37 ERROR keystone.server.flask.application Traceback (most recent call last):
2023-04-04 18:20:35.820489 2023-04-04 18:20:35.807 37 ERROR keystone.server.flask.application   File "/var/lib/kolla/venv/lib/python3.9/site-packages/flask/app.py", line 1820, in full_dispatch_request
2023-04-04 18:20:35.820505 2023-04-04 18:20:35.807 37 ERROR keystone.server.flask.application     rv = self.dispatch_request()
2023-04-04 18:20:35.820518 2023-04-04 18:20:35.807 37 ERROR keystone.server.flask.application   File "/var/lib/kolla/venv/lib/python3.9/site-packages/flask/app.py", line 1796, in dispatch_request
2023-04-04 18:20:35.820531 2023-04-04 18:20:35.807 37 ERROR keystone.server.flask.application     return self.ensure_sync(self.view_functions[rule.endpoint])(**view_args)
2023-04-04 18:20:35.820544 2023-04-04 18:20:35.807 37 ERROR keystone.server.flask.application   File "/var/lib/kolla/venv/lib/python3.9/site-packages/flask_restful/__init__.py", line 467, in wrapper
2023-04-04 18:20:35.820557 2023-04-04 18:20:35.807 37 ERROR keystone.server.flask.application     resp = resource(*args, **kwargs)
2023-04-04 18:20:35.820615 2023-04-04 18:20:35.807 37 ERROR keystone.server.flask.application   File "/var/lib/kolla/venv/lib/python3.9/site-packages/flask/views.py", line 107, in view
2023-04-04 18:20:35.820637 2023-04-04 18:20:35.807 37 ERROR keystone.server.flask.application     return current_app.ensure_sync(self.dispatch_request)(**kwargs)
2023-04-04 18:20:35.820649 2023-04-04 18:20:35.807 37 ERROR keystone.server.flask.application   File "/var/lib/kolla/venv/lib/python3.9/site-packages/flask_restful/__init__.py", line 582, in dispatch_request
2023-04-04 18:20:35.820662 2023-04-04 18:20:35.807 37 ERROR keystone.server.flask.application     resp = meth(*args, **kwargs)
2023-04-04 18:20:35.820674 2023-04-04 18:20:35.807 37 ERROR keystone.server.flask.application   File "/var/lib/kolla/venv/lib/python3.9/site-packages/keystone/api/projects.py", line 151, in get
2023-04-04 18:20:35.820687 2023-04-04 18:20:35.807 37 ERROR keystone.server.flask.application     return self._get_project(project_id)
2023-04-04 18:20:35.820700 2023-04-04 18:20:35.807 37 ERROR keystone.server.flask.application   File "/var/lib/kolla/venv/lib/python3.9/site-packages/keystone/api/projects.py", line 107, in _get_project
2023-04-04 18:20:35.820712 2023-04-04 18:20:35.807 37 ERROR keystone.server.flask.application     project = PROVIDERS.resource_api.get_project(project_id)
2023-04-04 18:20:35.820725 2023-04-04 18:20:35.807 37 ERROR keystone.server.flask.application   File "/var/lib/kolla/venv/lib/python3.9/site-packages/keystone/common/manager.py", line 115, in wrapped
2023-04-04 18:20:35.820737 2023-04-04 18:20:35.807 37 ERROR keystone.server.flask.application     __ret_val = __f(*args, **kwargs)
2023-04-04 18:20:35.820749 2023-04-04 18:20:35.807 37 ERROR keystone.server.flask.application   File "/var/lib/kolla/venv/lib/python3.9/site-packages/decorator.py", line 232, in fun
2023-04-04 18:20:35.820762 2023-04-04 18:20:35.807 37 ERROR keystone.server.flask.application     return caller(func, *(extras + args), **kw)
2023-04-04 18:20:35.820775 2023-04-04 18:20:35.807 37 ERROR keystone.server.flask.application   File "/var/lib/kolla/venv/lib/python3.9/site-packages/dogpile/cache/region.py", line 1577, in get_or_create_for_user_func
2023-04-04 18:20:35.820787 2023-04-04 18:20:35.807 37 ERROR keystone.server.flask.application     return self.get_or_create(
2023-04-04 18:20:35.820800 2023-04-04 18:20:35.807 37 ERROR keystone.server.flask.application   File "/var/lib/kolla/venv/lib/python3.9/site-packages/dogpile/cache/region.py", line 1042, in get_or_create
2023-04-04 18:20:35.820813 2023-04-04 18:20:35.807 37 ERROR keystone.server.flask.application     with Lock(
2023-04-04 18:20:35.820825 2023-04-04 18:20:35.807 37 ERROR keystone.server.flask.application   File "/var/lib/kolla/venv/lib/python3.9/site-packages/dogpile/lock.py", line 185, in __enter__
2023-04-04 18:20:35.820837 2023-04-04 18:20:35.807 37 ERROR keystone.server.flask.application     return self._enter()
2023-04-04 18:20:35.820865 2023-04-04 18:20:35.807 37 ERROR keystone.server.flask.application   File "/var/lib/kolla/venv/lib/python3.9/site-packages/dogpile/lock.py", line 94, in _enter
2023-04-04 18:20:35.820880 2023-04-04 18:20:35.807 37 ERROR keystone.server.flask.application     generated = self._enter_create(value, createdtime)
2023-04-04 18:20:35.820893 2023-04-04 18:20:35.807 37 ERROR keystone.server.flask.application   File "/var/lib/kolla/venv/lib/python3.9/site-packages/dogpile/lock.py", line 178, in _enter_create
2023-04-04 18:20:35.820906 2023-04-04 18:20:35.807 37 ERROR keystone.server.flask.application     return self.creator()
2023-04-04 18:20:35.820918 2023-04-04 18:20:35.807 37 ERROR keystone.server.flask.application   File "/var/lib/kolla/venv/lib/python3.9/site-packages/dogpile/cache/region.py", line 995, in gen_value
2023-04-04 18:20:35.820931 2023-04-04 18:20:35.807 37 ERROR keystone.server.flask.application     created_value = creator(
2023-04-04 18:20:35.820943 2023-04-04 18:20:35.807 37 ERROR keystone.server.flask.application   File "/var/lib/kolla/venv/lib/python3.9/site-packages/keystone/resource/core.py", line 903, in get_project
2023-04-04 18:20:35.820956 2023-04-04 18:20:35.807 37 ERROR keystone.server.flask.application     return self.driver.get_project(project_id)
2023-04-04 18:20:35.820969 2023-04-04 18:20:35.807 37 ERROR keystone.server.flask.application   File "/var/lib/kolla/venv/lib/python3.9/site-packages/keystone/resource/backends/sql.py", line 49, in get_project
2023-04-04 18:20:35.820982 2023-04-04 18:20:35.807 37 ERROR keystone.server.flask.application     return self._get_project(session, project_id).to_dict()
2023-04-04 18:20:35.820994 2023-04-04 18:20:35.807 37 ERROR keystone.server.flask.application   File "/var/lib/kolla/venv/lib/python3.9/site-packages/keystone/resource/backends/sql.py", line 44, in _get_project
2023-04-04 18:20:35.821007 2023-04-04 18:20:35.807 37 ERROR keystone.server.flask.application     raise exception.ProjectNotFound(project_id=project_id)
2023-04-04 18:20:35.821020 2023-04-04 18:20:35.807 37 ERROR keystone.server.flask.application keystone.exception.ProjectNotFound: Could not find project: service.
2023-04-04 18:20:35.821033 2023-04-04 18:20:35.807 37 ERROR keystone.server.flask.application \x1b[00m
2023-04-04 18:20:50.116068 2023-04-04 18:20:50.110 37 ERROR keystone.server.flask.application [None req-361d49d8-7dbc-48c6-972f-721375233f05 5e04de7c8cdd40229d63c638acb175bd - - all default -] Could not find role: admin.: keystone.exception.RoleNotFound: Could not find role: admin.
2023-04-04 18:20:50.116138 2023-04-04 18:20:50.110 37 ERROR keystone.server.flask.application Traceback (most recent call last):
2023-04-04 18:20:50.116150 2023-04-04 18:20:50.110 37 ERROR keystone.server.flask.application   File "/var/lib/kolla/venv/lib/python3.9/site-packages/flask/app.py", line 1820, in full_dispatch_request
2023-04-04 18:20:50.116160 2023-04-04 18:20:50.110 37 ERROR keystone.server.flask.application     rv = self.dispatch_request()
2023-04-04 18:20:50.116170 2023-04-04 18:20:50.110 37 ERROR keystone.server.flask.application   File "/var/lib/kolla/venv/lib/python3.9/site-packages/flask/app.py", line 1796, in dispatch_request
2023-04-04 18:20:50.116180 2023-04-04 18:20:50.110 37 ERROR keystone.server.flask.application     return self.ensure_sync(self.view_functions[rule.endpoint])(**view_args)
2023-04-04 18:20:50.116189 2023-04-04 18:20:50.110 37 ERROR keystone.server.flask.application   File "/var/lib/kolla/venv/lib/python3.9/site-packages/flask_restful/__init__.py", line 467, in wrapper
2023-04-04 18:20:50.116199 2023-04-04 18:20:50.110 37 ERROR keystone.server.flask.application     resp = resource(*args, **kwargs)
2023-04-04 18:20:50.116216 2023-04-04 18:20:50.110 37 ERROR keystone.server.flask.application   File "/var/lib/kolla/venv/lib/python3.9/site-packages/flask/views.py", line 107, in view
2023-04-04 18:20:50.116228 2023-04-04 18:20:50.110 37 ERROR keystone.server.flask.application     return current_app.ensure_sync(self.dispatch_request)(**kwargs)
2023-04-04 18:20:50.116238 2023-04-04 18:20:50.110 37 ERROR keystone.server.flask.application   File "/var/lib/kolla/venv/lib/python3.9/site-packages/flask_restful/__init__.py", line 582, in dispatch_request
2023-04-04 18:20:50.116262 2023-04-04 18:20:50.110 37 ERROR keystone.server.flask.application     resp = meth(*args, **kwargs)
2023-04-04 18:20:50.116324 2023-04-04 18:20:50.110 37 ERROR keystone.server.flask.application   File "/var/lib/kolla/venv/lib/python3.9/site-packages/keystone/api/roles.py", line 50, in get
2023-04-04 18:20:50.116335 2023-04-04 18:20:50.110 37 ERROR keystone.server.flask.application     return self._get_role(role_id)
2023-04-04 18:20:50.116345 2023-04-04 18:20:50.110 37 ERROR keystone.server.flask.application   File "/var/lib/kolla/venv/lib/python3.9/site-packages/keystone/api/roles.py", line 70, in _get_role
2023-04-04 18:20:50.116360 2023-04-04 18:20:50.110 37 ERROR keystone.server.flask.application     ENFORCER.enforce_call(action='identity:get_role')
2023-04-04 18:20:50.116370 2023-04-04 18:20:50.110 37 ERROR keystone.server.flask.application   File "/var/lib/kolla/venv/lib/python3.9/site-packages/keystone/common/rbac_enforcer/enforcer.py", line 402, in enforce_call
2023-04-04 18:20:50.116380 2023-04-04 18:20:50.110 37 ERROR keystone.server.flask.application     policy_dict.update(cls._extract_member_target_data(
2023-04-04 18:20:50.116399 2023-04-04 18:20:50.110 37 ERROR keystone.server.flask.application   File "/var/lib/kolla/venv/lib/python3.9/site-packages/keystone/common/rbac_enforcer/enforcer.py", line 234, in _extract_member_target_data
2023-04-04 18:20:50.116412 2023-04-04 18:20:50.110 37 ERROR keystone.server.flask.application     member_name: func(flask.request.view_args[key])
2023-04-04 18:20:50.116422 2023-04-04 18:20:50.110 37 ERROR keystone.server.flask.application   File "/var/lib/kolla/venv/lib/python3.9/site-packages/keystone/common/manager.py", line 115, in wrapped
2023-04-04 18:20:50.116431 2023-04-04 18:20:50.110 37 ERROR keystone.server.flask.application     __ret_val = __f(*args, **kwargs)
2023-04-04 18:20:50.116441 2023-04-04 18:20:50.110 37 ERROR keystone.server.flask.application   File "/var/lib/kolla/venv/lib/python3.9/site-packages/decorator.py", line 232, in fun
2023-04-04 18:20:50.116451 2023-04-04 18:20:50.110 37 ERROR keystone.server.flask.application     return caller(func, *(extras + args), **kw)
2023-04-04 18:20:50.116465 2023-04-04 18:20:50.110 37 ERROR keystone.server.flask.application   File "/var/lib/kolla/venv/lib/python3.9/site-packages/dogpile/cache/region.py", line 1577, in get_or_create_for_user_func
2023-04-04 18:20:50.116479 2023-04-04 18:20:50.110 37 ERROR keystone.server.flask.application     return self.get_or_create(
2023-04-04 18:20:50.116489 2023-04-04 18:20:50.110 37 ERROR keystone.server.flask.application   File "/var/lib/kolla/venv/lib/python3.9/site-packages/dogpile/cache/region.py", line 1042, in get_or_create
2023-04-04 18:20:50.116499 2023-04-04 18:20:50.110 37 ERROR keystone.server.flask.application     with Lock(
2023-04-04 18:20:50.116509 2023-04-04 18:20:50.110 37 ERROR keystone.server.flask.application   File "/var/lib/kolla/venv/lib/python3.9/site-packages/dogpile/lock.py", line 185, in __enter__
2023-04-04 18:20:50.116519 2023-04-04 18:20:50.110 37 ERROR keystone.server.flask.application     return self._enter()
2023-04-04 18:20:50.116528 2023-04-04 18:20:50.110 37 ERROR keystone.server.flask.application   File "/var/lib/kolla/venv/lib/python3.9/site-packages/dogpile/lock.py", line 94, in _enter
2023-04-04 18:20:50.116538 2023-04-04 18:20:50.110 37 ERROR keystone.server.flask.application     generated = self._enter_create(value, createdtime)
2023-04-04 18:20:50.116547 2023-04-04 18:20:50.110 37 ERROR keystone.server.flask.application   File "/var/lib/kolla/venv/lib/python3.9/site-packages/dogpile/lock.py", line 178, in _enter_create
2023-04-04 18:20:50.116557 2023-04-04 18:20:50.110 37 ERROR keystone.server.flask.application     return self.creator()
2023-04-04 18:20:50.116567 2023-04-04 18:20:50.110 37 ERROR keystone.server.flask.application   File "/var/lib/kolla/venv/lib/python3.9/site-packages/dogpile/cache/region.py", line 995, in gen_value
2023-04-04 18:20:50.116616 2023-04-04 18:20:50.110 37 ERROR keystone.server.flask.application     created_value = creator(
2023-04-04 18:20:50.116628 2023-04-04 18:20:50.110 37 ERROR keystone.server.flask.application   File "/var/lib/kolla/venv/lib/python3.9/site-packages/keystone/assignment/core.py", line 1276, in get_role
2023-04-04 18:20:50.116638 2023-04-04 18:20:50.110 37 ERROR keystone.server.flask.application     return self.driver.get_role(role_id)
2023-04-04 18:20:50.116648 2023-04-04 18:20:50.110 37 ERROR keystone.server.flask.application   File "/var/lib/kolla/venv/lib/python3.9/site-packages/keystone/assignment/role_backends/sql.py", line 70, in get_role
2023-04-04 18:20:50.116658 2023-04-04 18:20:50.110 37 ERROR keystone.server.flask.application     return self._get_role(session, role_id).to_dict()
2023-04-04 18:20:50.116667 2023-04-04 18:20:50.110 37 ERROR keystone.server.flask.application   File "/var/lib/kolla/venv/lib/python3.9/site-packages/keystone/assignment/role_backends/sql.py", line 65, in _get_role
2023-04-04 18:20:50.116677 2023-04-04 18:20:50.110 37 ERROR keystone.server.flask.application     raise exception.RoleNotFound(role_id=role_id)
2023-04-04 18:20:50.116686 2023-04-04 18:20:50.110 37 ERROR keystone.server.flask.application keystone.exception.RoleNotFound: Could not find role: admin.
2023-04-04 18:20:50.116696 2023-04-04 18:20:50.110 37 ERROR keystone.server.flask.application \x1b[00m
2023-04-04 18:20:51.182542 2023-04-04 18:20:51.176 37 ERROR keystone.server.flask.application [None req-c4bd1e2a-1cd5-4c73-a8fb-09e9edcee069 5e04de7c8cdd40229d63c638acb175bd - - all default -] Could not find user: ironic.: keystone.exception.UserNotFound: Could not find user: ironic.
2023-04-04 18:20:51.182618 2023-04-04 18:20:51.176 37 ERROR keystone.server.flask.application Traceback (most recent call last):
2023-04-04 18:20:51.182631 2023-04-04 18:20:51.176 37 ERROR keystone.server.flask.application   File "/var/lib/kolla/venv/lib/python3.9/site-packages/flask/app.py", line 1820, in full_dispatch_request
2023-04-04 18:20:51.182641 2023-04-04 18:20:51.176 37 ERROR keystone.server.flask.application     rv = self.dispatch_request()
2023-04-04 18:20:51.182651 2023-04-04 18:20:51.176 37 ERROR keystone.server.flask.application   File "/var/lib/kolla/venv/lib/python3.9/site-packages/flask/app.py", line 1796, in dispatch_request
2023-04-04 18:20:51.182661 2023-04-04 18:20:51.176 37 ERROR keystone.server.flask.application     return self.ensure_sync(self.view_functions[rule.endpoint])(**view_args)
2023-04-04 18:20:51.182671 2023-04-04 18:20:51.176 37 ERROR keystone.server.flask.application   File "/var/lib/kolla/venv/lib/python3.9/site-packages/flask_restful/__init__.py", line 467, in wrapper
2023-04-04 18:20:51.182681 2023-04-04 18:20:51.176 37 ERROR keystone.server.flask.application     resp = resource(*args, **kwargs)
2023-04-04 18:20:51.182691 2023-04-04 18:20:51.176 37 ERROR keystone.server.flask.application   File "/var/lib/kolla/venv/lib/python3.9/site-packages/flask/views.py", line 107, in view
2023-04-04 18:20:51.182702 2023-04-04 18:20:51.176 37 ERROR keystone.server.flask.application     return current_app.ensure_sync(self.dispatch_request)(**kwargs)
2023-04-04 18:20:51.182711 2023-04-04 18:20:51.176 37 ERROR keystone.server.flask.application   File "/var/lib/kolla/venv/lib/python3.9/site-packages/flask_restful/__init__.py", line 582, in dispatch_request
2023-04-04 18:20:51.182721 2023-04-04 18:20:51.176 37 ERROR keystone.server.flask.application     resp = meth(*args, **kwargs)
2023-04-04 18:20:51.182731 2023-04-04 18:20:51.176 37 ERROR keystone.server.flask.application   File "/var/lib/kolla/venv/lib/python3.9/site-packages/keystone/api/users.py", line 182, in get
2023-04-04 18:20:51.182741 2023-04-04 18:20:51.176 37 ERROR keystone.server.flask.application     return self._get_user(user_id)
2023-04-04 18:20:51.182750 2023-04-04 18:20:51.176 37 ERROR keystone.server.flask.application   File "/var/lib/kolla/venv/lib/python3.9/site-packages/keystone/api/users.py", line 194, in _get_user
2023-04-04 18:20:51.182775 2023-04-04 18:20:51.176 37 ERROR keystone.server.flask.application     ref = PROVIDERS.identity_api.get_user(user_id)
2023-04-04 18:20:51.182786 2023-04-04 18:20:51.176 37 ERROR keystone.server.flask.application   File "/var/lib/kolla/venv/lib/python3.9/site-packages/keystone/common/manager.py", line 115, in wrapped
2023-04-04 18:20:51.182796 2023-04-04 18:20:51.176 37 ERROR keystone.server.flask.application     __ret_val = __f(*args, **kwargs)
2023-04-04 18:20:51.182806 2023-04-04 18:20:51.176 37 ERROR keystone.server.flask.application   File "/var/lib/kolla/venv/lib/python3.9/site-packages/keystone/identity/core.py", line 414, in wrapper
2023-04-04 18:20:51.182816 2023-04-04 18:20:51.176 37 ERROR keystone.server.flask.application     return f(self, *args, **kwargs)
2023-04-04 18:20:51.182825 2023-04-04 18:20:51.176 37 ERROR keystone.server.flask.application   File "/var/lib/kolla/venv/lib/python3.9/site-packages/keystone/identity/core.py", line 424, in wrapper
2023-04-04 18:20:51.182835 2023-04-04 18:20:51.176 37 ERROR keystone.server.flask.application     return f(self, *args, **kwargs)
2023-04-04 18:20:51.182844 2023-04-04 18:20:51.176 37 ERROR keystone.server.flask.application   File "/var/lib/kolla/venv/lib/python3.9/site-packages/decorator.py", line 232, in fun
2023-04-04 18:20:51.182854 2023-04-04 18:20:51.176 37 ERROR keystone.server.flask.application     return caller(func, *(extras + args), **kw)
2023-04-04 18:20:51.182864 2023-04-04 18:20:51.176 37 ERROR keystone.server.flask.application   File "/var/lib/kolla/venv/lib/python3.9/site-packages/dogpile/cache/region.py", line 1577, in get_or_create_for_user_func
2023-04-04 18:20:51.182874 2023-04-04 18:20:51.176 37 ERROR keystone.server.flask.application     return self.get_or_create(
2023-04-04 18:20:51.182884 2023-04-04 18:20:51.176 37 ERROR keystone.server.flask.application   File "/var/lib/kolla/venv/lib/python3.9/site-packages/dogpile/cache/region.py", line 1042, in get_or_create
2023-04-04 18:20:51.182894 2023-04-04 18:20:51.176 37 ERROR keystone.server.flask.application     with Lock(
2023-04-04 18:20:51.182904 2023-04-04 18:20:51.176 37 ERROR keystone.server.flask.application   File "/var/lib/kolla/venv/lib/python3.9/site-packages/dogpile/lock.py", line 185, in __enter__
2023-04-04 18:20:51.182914 2023-04-04 18:20:51.176 37 ERROR keystone.server.flask.application     return self._enter()
2023-04-04 18:20:51.182923 2023-04-04 18:20:51.176 37 ERROR keystone.server.flask.application   File "/var/lib/kolla/venv/lib/python3.9/site-packages/dogpile/lock.py", line 94, in _enter
2023-04-04 18:20:51.182933 2023-04-04 18:20:51.176 37 ERROR keystone.server.flask.application     generated = self._enter_create(value, createdtime)
2023-04-04 18:20:51.182943 2023-04-04 18:20:51.176 37 ERROR keystone.server.flask.application   File "/var/lib/kolla/venv/lib/python3.9/site-packages/dogpile/lock.py", line 178, in _enter_create
2023-04-04 18:20:51.182954 2023-04-04 18:20:51.176 37 ERROR keystone.server.flask.application     return self.creator()
2023-04-04 18:20:51.182964 2023-04-04 18:20:51.176 37 ERROR keystone.server.flask.application   File "/var/lib/kolla/venv/lib/python3.9/site-packages/dogpile/cache/region.py", line 995, in gen_value
2023-04-04 18:20:51.182974 2023-04-04 18:20:51.176 37 ERROR keystone.server.flask.application     created_value = creator(
2023-04-04 18:20:51.182984 2023-04-04 18:20:51.176 37 ERROR keystone.server.flask.application   File "/var/lib/kolla/venv/lib/python3.9/site-packages/keystone/identity/core.py", line 1011, in get_user
2023-04-04 18:20:51.182994 2023-04-04 18:20:51.176 37 ERROR keystone.server.flask.application     ref = driver.get_user(entity_id)
2023-04-04 18:20:51.183004 2023-04-04 18:20:51.176 37 ERROR keystone.server.flask.application   File "/var/lib/kolla/venv/lib/python3.9/site-packages/keystone/identity/backends/sql.py", line 200, in get_user
2023-04-04 18:20:51.183014 2023-04-04 18:20:51.176 37 ERROR keystone.server.flask.application     self._get_user(session, user_id).to_dict())
2023-04-04 18:20:51.183033 2023-04-04 18:20:51.176 37 ERROR keystone.server.flask.application   File "/var/lib/kolla/venv/lib/python3.9/site-packages/keystone/identity/backends/sql.py", line 194, in _get_user
2023-04-04 18:20:51.183044 2023-04-04 18:20:51.176 37 ERROR keystone.server.flask.application     raise exception.UserNotFound(user_id=user_id)
2023-04-04 18:20:51.183054 2023-04-04 18:20:51.176 37 ERROR keystone.server.flask.application keystone.exception.UserNotFound: Could not find user: ironic.
2023-04-04 18:20:51.183063 2023-04-04 18:20:51.176 37 ERROR keystone.server.flask.application \x1b[00m
2023-04-04 18:20:52.008045 2023-04-04 18:20:51.997 38 ERROR keystone.server.flask.application [None req-90e96408-a244-4276-a7a0-bd97513e34fe 5e04de7c8cdd40229d63c638acb175bd - - all default -] Could not find project: service.: keystone.exception.ProjectNotFound: Could not find project: service.
2023-04-04 18:20:52.008102 2023-04-04 18:20:51.997 38 ERROR keystone.server.flask.application Traceback (most recent call last):
2023-04-04 18:20:52.008114 2023-04-04 18:20:51.997 38 ERROR keystone.server.flask.application   File "/var/lib/kolla/venv/lib/python3.9/site-packages/flask/app.py", line 1820, in full_dispatch_request
2023-04-04 18:20:52.008125 2023-04-04 18:20:51.997 38 ERROR keystone.server.flask.application     rv = self.dispatch_request()
2023-04-04 18:20:52.008134 2023-04-04 18:20:51.997 38 ERROR keystone.server.flask.application   File "/var/lib/kolla/venv/lib/python3.9/site-packages/flask/app.py", line 1796, in dispatch_request
2023-04-04 18:20:52.008145 2023-04-04 18:20:51.997 38 ERROR keystone.server.flask.application     return self.ensure_sync(self.view_functions[rule.endpoint])(**view_args)
2023-04-04 18:20:52.008154 2023-04-04 18:20:51.997 38 ERROR keystone.server.flask.application   File "/var/lib/kolla/venv/lib/python3.9/site-packages/flask_restful/__init__.py", line 467, in wrapper
2023-04-04 18:20:52.008164 2023-04-04 18:20:51.997 38 ERROR keystone.server.flask.application     resp = resource(*args, **kwargs)
2023-04-04 18:20:52.008194 2023-04-04 18:20:51.997 38 ERROR keystone.server.flask.application   File "/var/lib/kolla/venv/lib/python3.9/site-packages/flask/views.py", line 107, in view
2023-04-04 18:20:52.008204 2023-04-04 18:20:51.997 38 ERROR keystone.server.flask.application     return current_app.ensure_sync(self.dispatch_request)(**kwargs)
2023-04-04 18:20:52.008213 2023-04-04 18:20:51.997 38 ERROR keystone.server.flask.application   File "/var/lib/kolla/venv/lib/python3.9/site-packages/flask_restful/__init__.py", line 582, in dispatch_request
2023-04-04 18:20:52.008223 2023-04-04 18:20:51.997 38 ERROR keystone.server.flask.application     resp = meth(*args, **kwargs)
2023-04-04 18:20:52.008232 2023-04-04 18:20:51.997 38 ERROR keystone.server.flask.application   File "/var/lib/kolla/venv/lib/python3.9/site-packages/keystone/api/projects.py", line 151, in get
2023-04-04 18:20:52.008243 2023-04-04 18:20:51.997 38 ERROR keystone.server.flask.application     return self._get_project(project_id)
2023-04-04 18:20:52.008253 2023-04-04 18:20:51.997 38 ERROR keystone.server.flask.application   File "/var/lib/kolla/venv/lib/python3.9/site-packages/keystone/api/projects.py", line 107, in _get_project
2023-04-04 18:20:52.008310 2023-04-04 18:20:51.997 38 ERROR keystone.server.flask.application     project = PROVIDERS.resource_api.get_project(project_id)
2023-04-04 18:20:52.008327 2023-04-04 18:20:51.997 38 ERROR keystone.server.flask.application   File "/var/lib/kolla/venv/lib/python3.9/site-packages/keystone/common/manager.py", line 115, in wrapped
2023-04-04 18:20:52.008338 2023-04-04 18:20:51.997 38 ERROR keystone.server.flask.application     __ret_val = __f(*args, **kwargs)
2023-04-04 18:20:52.008347 2023-04-04 18:20:51.997 38 ERROR keystone.server.flask.application   File "/var/lib/kolla/venv/lib/python3.9/site-packages/decorator.py", line 232, in fun
2023-04-04 18:20:52.008357 2023-04-04 18:20:51.997 38 ERROR keystone.server.flask.application     return caller(func, *(extras + args), **kw)
2023-04-04 18:20:52.008422 2023-04-04 18:20:51.997 38 ERROR keystone.server.flask.application   File "/var/lib/kolla/venv/lib/python3.9/site-packages/dogpile/cache/region.py", line 1577, in get_or_create_for_user_func
2023-04-04 18:20:52.008436 2023-04-04 18:20:51.997 38 ERROR keystone.server.flask.application     return self.get_or_create(
2023-04-04 18:20:52.008446 2023-04-04 18:20:51.997 38 ERROR keystone.server.flask.application   File "/var/lib/kolla/venv/lib/python3.9/site-packages/dogpile/cache/region.py", line 1042, in get_or_create
2023-04-04 18:20:52.008457 2023-04-04 18:20:51.997 38 ERROR keystone.server.flask.application     with Lock(
2023-04-04 18:20:52.008466 2023-04-04 18:20:51.997 38 ERROR keystone.server.flask.application   File "/var/lib/kolla/venv/lib/python3.9/site-packages/dogpile/lock.py", line 185, in __enter__
2023-04-04 18:20:52.008476 2023-04-04 18:20:51.997 38 ERROR keystone.server.flask.application     return self._enter()
2023-04-04 18:20:52.008485 2023-04-04 18:20:51.997 38 ERROR keystone.server.flask.application   File "/var/lib/kolla/venv/lib/python3.9/site-packages/dogpile/lock.py", line 94, in _enter
2023-04-04 18:20:52.008494 2023-04-04 18:20:51.997 38 ERROR keystone.server.flask.application     generated = self._enter_create(value, createdtime)
2023-04-04 18:20:52.008504 2023-04-04 18:20:51.997 38 ERROR keystone.server.flask.application   File "/var/lib/kolla/venv/lib/python3.9/site-packages/dogpile/lock.py", line 178, in _enter_create
2023-04-04 18:20:52.008513 2023-04-04 18:20:51.997 38 ERROR keystone.server.flask.application     return self.creator()
2023-04-04 18:20:52.008523 2023-04-04 18:20:51.997 38 ERROR keystone.server.flask.application   File "/var/lib/kolla/venv/lib/python3.9/site-packages/dogpile/cache/region.py", line 995, in gen_value
2023-04-04 18:20:52.008532 2023-04-04 18:20:51.997 38 ERROR keystone.server.flask.application     created_value = creator(
2023-04-04 18:20:52.008542 2023-04-04 18:20:51.997 38 ERROR keystone.server.flask.application   File "/var/lib/kolla/venv/lib/python3.9/site-packages/keystone/resource/core.py", line 903, in get_project
2023-04-04 18:20:52.008551 2023-04-04 18:20:51.997 38 ERROR keystone.server.flask.application     return self.driver.get_project(project_id)
2023-04-04 18:20:52.008561 2023-04-04 18:20:51.997 38 ERROR keystone.server.flask.application   File "/var/lib/kolla/venv/lib/python3.9/site-packages/keystone/resource/backends/sql.py", line 49, in get_project
2023-04-04 18:20:52.008571 2023-04-04 18:20:51.997 38 ERROR keystone.server.flask.application     return self._get_project(session, project_id).to_dict()
2023-04-04 18:20:52.008597 2023-04-04 18:20:51.997 38 ERROR keystone.server.flask.application   File "/var/lib/kolla/venv/lib/python3.9/site-packages/keystone/resource/backends/sql.py", line 44, in _get_project
2023-04-04 18:20:52.008610 2023-04-04 18:20:51.997 38 ERROR keystone.server.flask.application     raise exception.ProjectNotFound(project_id=project_id)
2023-04-04 18:20:52.008619 2023-04-04 18:20:51.997 38 ERROR keystone.server.flask.application keystone.exception.ProjectNotFound: Could not find project: service.
2023-04-04 18:20:52.008628 2023-04-04 18:20:51.997 38 ERROR keystone.server.flask.application \x1b[00m
2023-04-04 18:21:00.800885 2023-04-04 18:21:00.793 39 ERROR keystone.server.flask.application [None req-5e4ff595-21b2-4f82-b8ed-3d90d4e10cd6 5e04de7c8cdd40229d63c638acb175bd - - all default -] Could not find role: admin.: keystone.exception.RoleNotFound: Could not find role: admin.
2023-04-04 18:21:00.800931 2023-04-04 18:21:00.793 39 ERROR keystone.server.flask.application Traceback (most recent call last):
2023-04-04 18:21:00.800959 2023-04-04 18:21:00.793 39 ERROR keystone.server.flask.application   File "/var/lib/kolla/venv/lib/python3.9/site-packages/flask/app.py", line 1820, in full_dispatch_request
2023-04-04 18:21:00.800969 2023-04-04 18:21:00.793 39 ERROR keystone.server.flask.application     rv = self.dispatch_request()
2023-04-04 18:21:00.800979 2023-04-04 18:21:00.793 39 ERROR keystone.server.flask.application   File "/var/lib/kolla/venv/lib/python3.9/site-packages/flask/app.py", line 1796, in dispatch_request
2023-04-04 18:21:00.801003 2023-04-04 18:21:00.793 39 ERROR keystone.server.flask.application     return self.ensure_sync(self.view_functions[rule.endpoint])(**view_args)
2023-04-04 18:21:00.801015 2023-04-04 18:21:00.793 39 ERROR keystone.server.flask.application   File "/var/lib/kolla/venv/lib/python3.9/site-packages/flask_restful/__init__.py", line 467, in wrapper
2023-04-04 18:21:00.801025 2023-04-04 18:21:00.793 39 ERROR keystone.server.flask.application     resp = resource(*args, **kwargs)
2023-04-04 18:21:00.801036 2023-04-04 18:21:00.793 39 ERROR keystone.server.flask.application   File "/var/lib/kolla/venv/lib/python3.9/site-packages/flask/views.py", line 107, in view
2023-04-04 18:21:00.801046 2023-04-04 18:21:00.793 39 ERROR keystone.server.flask.application     return current_app.ensure_sync(self.dispatch_request)(**kwargs)
2023-04-04 18:21:00.801056 2023-04-04 18:21:00.793 39 ERROR keystone.server.flask.application   File "/var/lib/kolla/venv/lib/python3.9/site-packages/flask_restful/__init__.py", line 582, in dispatch_request
2023-04-04 18:21:00.801067 2023-04-04 18:21:00.793 39 ERROR keystone.server.flask.application     resp = meth(*args, **kwargs)
2023-04-04 18:21:00.801077 2023-04-04 18:21:00.793 39 ERROR keystone.server.flask.application   File "/var/lib/kolla/venv/lib/python3.9/site-packages/keystone/api/roles.py", line 50, in get
2023-04-04 18:21:00.801087 2023-04-04 18:21:00.793 39 ERROR keystone.server.flask.application     return self._get_role(role_id)
2023-04-04 18:21:00.801097 2023-04-04 18:21:00.793 39 ERROR keystone.server.flask.application   File "/var/lib/kolla/venv/lib/python3.9/site-packages/keystone/api/roles.py", line 70, in _get_role
2023-04-04 18:21:00.801107 2023-04-04 18:21:00.793 39 ERROR keystone.server.flask.application     ENFORCER.enforce_call(action='identity:get_role')
2023-04-04 18:21:00.801117 2023-04-04 18:21:00.793 39 ERROR keystone.server.flask.application   File "/var/lib/kolla/venv/lib/python3.9/site-packages/keystone/common/rbac_enforcer/enforcer.py", line 402, in enforce_call
2023-04-04 18:21:00.801128 2023-04-04 18:21:00.793 39 ERROR keystone.server.flask.application     policy_dict.update(cls._extract_member_target_data(
2023-04-04 18:21:00.801138 2023-04-04 18:21:00.793 39 ERROR keystone.server.flask.application   File "/var/lib/kolla/venv/lib/python3.9/site-packages/keystone/common/rbac_enforcer/enforcer.py", line 234, in _extract_member_target_data
2023-04-04 18:21:00.801148 2023-04-04 18:21:00.793 39 ERROR keystone.server.flask.application     member_name: func(flask.request.view_args[key])
2023-04-04 18:21:00.801158 2023-04-04 18:21:00.793 39 ERROR keystone.server.flask.application   File "/var/lib/kolla/venv/lib/python3.9/site-packages/keystone/common/manager.py", line 115, in wrapped
2023-04-04 18:21:00.801169 2023-04-04 18:21:00.793 39 ERROR keystone.server.flask.application     __ret_val = __f(*args, **kwargs)
2023-04-04 18:21:00.801200 2023-04-04 18:21:00.793 39 ERROR keystone.server.flask.application   File "/var/lib/kolla/venv/lib/python3.9/site-packages/decorator.py", line 232, in fun
2023-04-04 18:21:00.801211 2023-04-04 18:21:00.793 39 ERROR keystone.server.flask.application     return caller(func, *(extras + args), **kw)
2023-04-04 18:21:00.801221 2023-04-04 18:21:00.793 39 ERROR keystone.server.flask.application   File "/var/lib/kolla/venv/lib/python3.9/site-packages/dogpile/cache/region.py", line 1577, in get_or_create_for_user_func
2023-04-04 18:21:00.801231 2023-04-04 18:21:00.793 39 ERROR keystone.server.flask.application     return self.get_or_create(
2023-04-04 18:21:00.801240 2023-04-04 18:21:00.793 39 ERROR keystone.server.flask.application   File "/var/lib/kolla/venv/lib/python3.9/site-packages/dogpile/cache/region.py", line 1042, in get_or_create
2023-04-04 18:21:00.801250 2023-04-04 18:21:00.793 39 ERROR keystone.server.flask.application     with Lock(
2023-04-04 18:21:00.801269 2023-04-04 18:21:00.793 39 ERROR keystone.server.flask.application   File "/var/lib/kolla/venv/lib/python3.9/site-packages/dogpile/lock.py", line 185, in __enter__
2023-04-04 18:21:00.801280 2023-04-04 18:21:00.793 39 ERROR keystone.server.flask.application     return self._enter()
2023-04-04 18:21:00.801343 2023-04-04 18:21:00.793 39 ERROR keystone.server.flask.application   File "/var/lib/kolla/venv/lib/python3.9/site-packages/dogpile/lock.py", line 94, in _enter
2023-04-04 18:21:00.801355 2023-04-04 18:21:00.793 39 ERROR keystone.server.flask.application     generated = self._enter_create(value, createdtime)
2023-04-04 18:21:00.801365 2023-04-04 18:21:00.793 39 ERROR keystone.server.flask.application   File "/var/lib/kolla/venv/lib/python3.9/site-packages/dogpile/lock.py", line 178, in _enter_create
2023-04-04 18:21:00.801374 2023-04-04 18:21:00.793 39 ERROR keystone.server.flask.application     return self.creator()
2023-04-04 18:21:00.801384 2023-04-04 18:21:00.793 39 ERROR keystone.server.flask.application   File "/var/lib/kolla/venv/lib/python3.9/site-packages/dogpile/cache/region.py", line 995, in gen_value
2023-04-04 18:21:00.801393 2023-04-04 18:21:00.793 39 ERROR keystone.server.flask.application     created_value = creator(
2023-04-04 18:21:00.801403 2023-04-04 18:21:00.793 39 ERROR keystone.server.flask.application   File "/var/lib/kolla/venv/lib/python3.9/site-packages/keystone/assignment/core.py", line 1276, in get_role
2023-04-04 18:21:00.801412 2023-04-04 18:21:00.793 39 ERROR keystone.server.flask.application     return self.driver.get_role(role_id)
2023-04-04 18:21:00.801422 2023-04-04 18:21:00.793 39 ERROR keystone.server.flask.application   File "/var/lib/kolla/venv/lib/python3.9/site-packages/keystone/assignment/role_backends/sql.py", line 70, in get_role
2023-04-04 18:21:00.801432 2023-04-04 18:21:00.793 39 ERROR keystone.server.flask.application     return self._get_role(session, role_id).to_dict()
2023-04-04 18:21:00.801441 2023-04-04 18:21:00.793 39 ERROR keystone.server.flask.application   File "/var/lib/kolla/venv/lib/python3.9/site-packages/keystone/assignment/role_backends/sql.py", line 65, in _get_role
2023-04-04 18:21:00.801451 2023-04-04 18:21:00.793 39 ERROR keystone.server.flask.application     raise exception.RoleNotFound(role_id=role_id)
2023-04-04 18:21:00.801460 2023-04-04 18:21:00.793 39 ERROR keystone.server.flask.application keystone.exception.RoleNotFound: Could not find role: admin.
2023-04-04 18:21:00.801498 2023-04-04 18:21:00.793 39 ERROR keystone.server.flask.application \x1b[00m
2023-04-04 18:21:02.027895 2023-04-04 18:21:02.021 39 ERROR keystone.server.flask.application [None req-eb140974-fdd0-448c-80e3-7522c6be6c9c 5e04de7c8cdd40229d63c638acb175bd - - all default -] Could not find user: ironic-inspector.: keystone.exception.UserNotFound: Could not find user: ironic-inspector.
2023-04-04 18:21:02.027940 2023-04-04 18:21:02.021 39 ERROR keystone.server.flask.application Traceback (most recent call last):
2023-04-04 18:21:02.027966 2023-04-04 18:21:02.021 39 ERROR keystone.server.flask.application   File "/var/lib/kolla/venv/lib/python3.9/site-packages/flask/app.py", line 1820, in full_dispatch_request
2023-04-04 18:21:02.027976 2023-04-04 18:21:02.021 39 ERROR keystone.server.flask.application     rv = self.dispatch_request()
2023-04-04 18:21:02.027985 2023-04-04 18:21:02.021 39 ERROR keystone.server.flask.application   File "/var/lib/kolla/venv/lib/python3.9/site-packages/flask/app.py", line 1796, in dispatch_request
2023-04-04 18:21:02.027995 2023-04-04 18:21:02.021 39 ERROR keystone.server.flask.application     return self.ensure_sync(self.view_functions[rule.endpoint])(**view_args)
2023-04-04 18:21:02.028005 2023-04-04 18:21:02.021 39 ERROR keystone.server.flask.application   File "/var/lib/kolla/venv/lib/python3.9/site-packages/flask_restful/__init__.py", line 467, in wrapper
2023-04-04 18:21:02.028014 2023-04-04 18:21:02.021 39 ERROR keystone.server.flask.application     resp = resource(*args, **kwargs)
2023-04-04 18:21:02.028024 2023-04-04 18:21:02.021 39 ERROR keystone.server.flask.application   File "/var/lib/kolla/venv/lib/python3.9/site-packages/flask/views.py", line 107, in view
2023-04-04 18:21:02.028052 2023-04-04 18:21:02.021 39 ERROR keystone.server.flask.application     return current_app.ensure_sync(self.dispatch_request)(**kwargs)
2023-04-04 18:21:02.028064 2023-04-04 18:21:02.021 39 ERROR keystone.server.flask.application   File "/var/lib/kolla/venv/lib/python3.9/site-packages/flask_restful/__init__.py", line 582, in dispatch_request
2023-04-04 18:21:02.028073 2023-04-04 18:21:02.021 39 ERROR keystone.server.flask.application     resp = meth(*args, **kwargs)
2023-04-04 18:21:02.028083 2023-04-04 18:21:02.021 39 ERROR keystone.server.flask.application   File "/var/lib/kolla/venv/lib/python3.9/site-packages/keystone/api/users.py", line 182, in get
2023-04-04 18:21:02.028093 2023-04-04 18:21:02.021 39 ERROR keystone.server.flask.application     return self._get_user(user_id)
2023-04-04 18:21:02.028102 2023-04-04 18:21:02.021 39 ERROR keystone.server.flask.application   File "/var/lib/kolla/venv/lib/python3.9/site-packages/keystone/api/users.py", line 194, in _get_user
2023-04-04 18:21:02.028112 2023-04-04 18:21:02.021 39 ERROR keystone.server.flask.application     ref = PROVIDERS.identity_api.get_user(user_id)
2023-04-04 18:21:02.028122 2023-04-04 18:21:02.021 39 ERROR keystone.server.flask.application   File "/var/lib/kolla/venv/lib/python3.9/site-packages/keystone/common/manager.py", line 115, in wrapped
2023-04-04 18:21:02.028132 2023-04-04 18:21:02.021 39 ERROR keystone.server.flask.application     __ret_val = __f(*args, **kwargs)
2023-04-04 18:21:02.028141 2023-04-04 18:21:02.021 39 ERROR keystone.server.flask.application   File "/var/lib/kolla/venv/lib/python3.9/site-packages/keystone/identity/core.py", line 414, in wrapper
2023-04-04 18:21:02.028151 2023-04-04 18:21:02.021 39 ERROR keystone.server.flask.application     return f(self, *args, **kwargs)
2023-04-04 18:21:02.028160 2023-04-04 18:21:02.021 39 ERROR keystone.server.flask.application   File "/var/lib/kolla/venv/lib/python3.9/site-packages/keystone/identity/core.py", line 424, in wrapper
2023-04-04 18:21:02.028170 2023-04-04 18:21:02.021 39 ERROR keystone.server.flask.application     return f(self, *args, **kwargs)
2023-04-04 18:21:02.028180 2023-04-04 18:21:02.021 39 ERROR keystone.server.flask.application   File "/var/lib/kolla/venv/lib/python3.9/site-packages/decorator.py", line 232, in fun
2023-04-04 18:21:02.028189 2023-04-04 18:21:02.021 39 ERROR keystone.server.flask.application     return caller(func, *(extras + args), **kw)
2023-04-04 18:21:02.028199 2023-04-04 18:21:02.021 39 ERROR keystone.server.flask.application   File "/var/lib/kolla/venv/lib/python3.9/site-packages/dogpile/cache/region.py", line 1577, in get_or_create_for_user_func
2023-04-04 18:21:02.028209 2023-04-04 18:21:02.021 39 ERROR keystone.server.flask.application     return self.get_or_create(
2023-04-04 18:21:02.028219 2023-04-04 18:21:02.021 39 ERROR keystone.server.flask.application   File "/var/lib/kolla/venv/lib/python3.9/site-packages/dogpile/cache/region.py", line 1042, in get_or_create
2023-04-04 18:21:02.028229 2023-04-04 18:21:02.021 39 ERROR keystone.server.flask.application     with Lock(
2023-04-04 18:21:02.028238 2023-04-04 18:21:02.021 39 ERROR keystone.server.flask.application   File "/var/lib/kolla/venv/lib/python3.9/site-packages/dogpile/lock.py", line 185, in __enter__
2023-04-04 18:21:02.028248 2023-04-04 18:21:02.021 39 ERROR keystone.server.flask.application     return self._enter()
2023-04-04 18:21:02.028258 2023-04-04 18:21:02.021 39 ERROR keystone.server.flask.application   File "/var/lib/kolla/venv/lib/python3.9/site-packages/dogpile/lock.py", line 94, in _enter
2023-04-04 18:21:02.028311 2023-04-04 18:21:02.021 39 ERROR keystone.server.flask.application     generated = self._enter_create(value, createdtime)
2023-04-04 18:21:02.028327 2023-04-04 18:21:02.021 39 ERROR keystone.server.flask.application   File "/var/lib/kolla/venv/lib/python3.9/site-packages/dogpile/lock.py", line 178, in _enter_create
2023-04-04 18:21:02.028349 2023-04-04 18:21:02.021 39 ERROR keystone.server.flask.application     return self.creator()
2023-04-04 18:21:02.028360 2023-04-04 18:21:02.021 39 ERROR keystone.server.flask.application   File "/var/lib/kolla/venv/lib/python3.9/site-packages/dogpile/cache/region.py", line 995, in gen_value
2023-04-04 18:21:02.028370 2023-04-04 18:21:02.021 39 ERROR keystone.server.flask.application     created_value = creator(
2023-04-04 18:21:02.028379 2023-04-04 18:21:02.021 39 ERROR keystone.server.flask.application   File "/var/lib/kolla/venv/lib/python3.9/site-packages/keystone/identity/core.py", line 1011, in get_user
2023-04-04 18:21:02.028389 2023-04-04 18:21:02.021 39 ERROR keystone.server.flask.application     ref = driver.get_user(entity_id)
2023-04-04 18:21:02.028399 2023-04-04 18:21:02.021 39 ERROR keystone.server.flask.application   File "/var/lib/kolla/venv/lib/python3.9/site-packages/keystone/identity/backends/sql.py", line 200, in get_user
2023-04-04 18:21:02.028408 2023-04-04 18:21:02.021 39 ERROR keystone.server.flask.application     self._get_user(session, user_id).to_dict())
2023-04-04 18:21:02.028418 2023-04-04 18:21:02.021 39 ERROR keystone.server.flask.application   File "/var/lib/kolla/venv/lib/python3.9/site-packages/keystone/identity/backends/sql.py", line 194, in _get_user
2023-04-04 18:21:02.028428 2023-04-04 18:21:02.021 39 ERROR keystone.server.flask.application     raise exception.UserNotFound(user_id=user_id)
2023-04-04 18:21:02.028437 2023-04-04 18:21:02.021 39 ERROR keystone.server.flask.application keystone.exception.UserNotFound: Could not find user: ironic-inspector.
2023-04-04 18:21:02.028447 2023-04-04 18:21:02.021 39 ERROR keystone.server.flask.application \x1b[00m
2023-04-04 18:21:02.853556 2023-04-04 18:21:02.846 37 ERROR keystone.server.flask.application [None req-40b331f5-3194-4d13-b336-a44522003a82 5e04de7c8cdd40229d63c638acb175bd - - all default -] Could not find project: service.: keystone.exception.ProjectNotFound: Could not find project: service.
2023-04-04 18:21:02.853642 2023-04-04 18:21:02.846 37 ERROR keystone.server.flask.application Traceback (most recent call last):
2023-04-04 18:21:02.853662 2023-04-04 18:21:02.846 37 ERROR keystone.server.flask.application   File "/var/lib/kolla/venv/lib/python3.9/site-packages/flask/app.py", line 1820, in full_dispatch_request
2023-04-04 18:21:02.853680 2023-04-04 18:21:02.846 37 ERROR keystone.server.flask.application     rv = self.dispatch_request()
2023-04-04 18:21:02.853700 2023-04-04 18:21:02.846 37 ERROR keystone.server.flask.application   File "/var/lib/kolla/venv/lib/python3.9/site-packages/flask/app.py", line 1796, in dispatch_request
2023-04-04 18:21:02.853720 2023-04-04 18:21:02.846 37 ERROR keystone.server.flask.application     return self.ensure_sync(self.view_functions[rule.endpoint])(**view_args)
2023-04-04 18:21:02.853741 2023-04-04 18:21:02.846 37 ERROR keystone.server.flask.application   File "/var/lib/kolla/venv/lib/python3.9/site-packages/flask_restful/__init__.py", line 467, in wrapper
2023-04-04 18:21:02.853761 2023-04-04 18:21:02.846 37 ERROR keystone.server.flask.application     resp = resource(*args, **kwargs)
2023-04-04 18:21:02.853790 2023-04-04 18:21:02.846 37 ERROR keystone.server.flask.application   File "/var/lib/kolla/venv/lib/python3.9/site-packages/flask/views.py", line 107, in view
2023-04-04 18:21:02.853812 2023-04-04 18:21:02.846 37 ERROR keystone.server.flask.application     return current_app.ensure_sync(self.dispatch_request)(**kwargs)
2023-04-04 18:21:02.853830 2023-04-04 18:21:02.846 37 ERROR keystone.server.flask.application   File "/var/lib/kolla/venv/lib/python3.9/site-packages/flask_restful/__init__.py", line 582, in dispatch_request
2023-04-04 18:21:02.853848 2023-04-04 18:21:02.846 37 ERROR keystone.server.flask.application     resp = meth(*args, **kwargs)
2023-04-04 18:21:02.853866 2023-04-04 18:21:02.846 37 ERROR keystone.server.flask.application   File "/var/lib/kolla/venv/lib/python3.9/site-packages/keystone/api/projects.py", line 151, in get
2023-04-04 18:21:02.853922 2023-04-04 18:21:02.846 37 ERROR keystone.server.flask.application     return self._get_project(project_id)
2023-04-04 18:21:02.853945 2023-04-04 18:21:02.846 37 ERROR keystone.server.flask.application   File "/var/lib/kolla/venv/lib/python3.9/site-packages/keystone/api/projects.py", line 107, in _get_project
2023-04-04 18:21:02.853965 2023-04-04 18:21:02.846 37 ERROR keystone.server.flask.application     project = PROVIDERS.resource_api.get_project(project_id)
2023-04-04 18:21:02.853984 2023-04-04 18:21:02.846 37 ERROR keystone.server.flask.application   File "/var/lib/kolla/venv/lib/python3.9/site-packages/keystone/common/manager.py", line 115, in wrapped
2023-04-04 18:21:02.854004 2023-04-04 18:21:02.846 37 ERROR keystone.server.flask.application     __ret_val = __f(*args, **kwargs)
2023-04-04 18:21:02.854033 2023-04-04 18:21:02.846 37 ERROR keystone.server.flask.application   File "/var/lib/kolla/venv/lib/python3.9/site-packages/decorator.py", line 232, in fun
2023-04-04 18:21:02.854053 2023-04-04 18:21:02.846 37 ERROR keystone.server.flask.application     return caller(func, *(extras + args), **kw)
2023-04-04 18:21:02.854072 2023-04-04 18:21:02.846 37 ERROR keystone.server.flask.application   File "/var/lib/kolla/venv/lib/python3.9/site-packages/dogpile/cache/region.py", line 1577, in get_or_create_for_user_func
2023-04-04 18:21:02.854090 2023-04-04 18:21:02.846 37 ERROR keystone.server.flask.application     return self.get_or_create(
2023-04-04 18:21:02.854108 2023-04-04 18:21:02.846 37 ERROR keystone.server.flask.application   File "/var/lib/kolla/venv/lib/python3.9/site-packages/dogpile/cache/region.py", line 1042, in get_or_create
2023-04-04 18:21:02.854128 2023-04-04 18:21:02.846 37 ERROR keystone.server.flask.application     with Lock(
2023-04-04 18:21:02.854147 2023-04-04 18:21:02.846 37 ERROR keystone.server.flask.application   File "/var/lib/kolla/venv/lib/python3.9/site-packages/dogpile/lock.py", line 185, in __enter__
2023-04-04 18:21:02.854165 2023-04-04 18:21:02.846 37 ERROR keystone.server.flask.application     return self._enter()
2023-04-04 18:21:02.854185 2023-04-04 18:21:02.846 37 ERROR keystone.server.flask.application   File "/var/lib/kolla/venv/lib/python3.9/site-packages/dogpile/lock.py", line 94, in _enter
2023-04-04 18:21:02.854205 2023-04-04 18:21:02.846 37 ERROR keystone.server.flask.application     generated = self._enter_create(value, createdtime)
2023-04-04 18:21:02.854223 2023-04-04 18:21:02.846 37 ERROR keystone.server.flask.application   File "/var/lib/kolla/venv/lib/python3.9/site-packages/dogpile/lock.py", line 178, in _enter_create
2023-04-04 18:21:02.854243 2023-04-04 18:21:02.846 37 ERROR keystone.server.flask.application     return self.creator()
2023-04-04 18:21:02.854260 2023-04-04 18:21:02.846 37 ERROR keystone.server.flask.application   File "/var/lib/kolla/venv/lib/python3.9/site-packages/dogpile/cache/region.py", line 995, in gen_value
2023-04-04 18:21:02.854321 2023-04-04 18:21:02.846 37 ERROR keystone.server.flask.application     created_value = creator(
2023-04-04 18:21:02.854341 2023-04-04 18:21:02.846 37 ERROR keystone.server.flask.application   File "/var/lib/kolla/venv/lib/python3.9/site-packages/keystone/resource/core.py", line 903, in get_project
2023-04-04 18:21:02.854360 2023-04-04 18:21:02.846 37 ERROR keystone.server.flask.application     return self.driver.get_project(project_id)
2023-04-04 18:21:02.854379 2023-04-04 18:21:02.846 37 ERROR keystone.server.flask.application   File "/var/lib/kolla/venv/lib/python3.9/site-packages/keystone/resource/backends/sql.py", line 49, in get_project
2023-04-04 18:21:02.854398 2023-04-04 18:21:02.846 37 ERROR keystone.server.flask.application     return self._get_project(session, project_id).to_dict()
2023-04-04 18:21:02.854417 2023-04-04 18:21:02.846 37 ERROR keystone.server.flask.application   File "/var/lib/kolla/venv/lib/python3.9/site-packages/keystone/resource/backends/sql.py", line 44, in _get_project
2023-04-04 18:21:02.854436 2023-04-04 18:21:02.846 37 ERROR keystone.server.flask.application     raise exception.ProjectNotFound(project_id=project_id)
2023-04-04 18:21:02.854478 2023-04-04 18:21:02.846 37 ERROR keystone.server.flask.application keystone.exception.ProjectNotFound: Could not find project: service.
2023-04-04 18:21:02.854502 2023-04-04 18:21:02.846 37 ERROR keystone.server.flask.application \x1b[00m
2023-04-04 18:23:40.223658 2023-04-04 18:23:40.220 37 ERROR keystone.server.flask.application [None req-f616b4d4-e680-4572-8bbd-fdc71a328a7d 5e04de7c8cdd40229d63c638acb175bd - - all default -] Could not find project: service.: keystone.exception.ProjectNotFound: Could not find project: service.
2023-04-04 18:23:40.223712 2023-04-04 18:23:40.220 37 ERROR keystone.server.flask.application Traceback (most recent call last):
2023-04-04 18:23:40.223724 2023-04-04 18:23:40.220 37 ERROR keystone.server.flask.application   File "/var/lib/kolla/venv/lib/python3.9/site-packages/flask/app.py", line 1820, in full_dispatch_request
2023-04-04 18:23:40.223734 2023-04-04 18:23:40.220 37 ERROR keystone.server.flask.application     rv = self.dispatch_request()
2023-04-04 18:23:40.223744 2023-04-04 18:23:40.220 37 ERROR keystone.server.flask.application   File "/var/lib/kolla/venv/lib/python3.9/site-packages/flask/app.py", line 1796, in dispatch_request
2023-04-04 18:23:40.223754 2023-04-04 18:23:40.220 37 ERROR keystone.server.flask.application     return self.ensure_sync(self.view_functions[rule.endpoint])(**view_args)
2023-04-04 18:23:40.223763 2023-04-04 18:23:40.220 37 ERROR keystone.server.flask.application   File "/var/lib/kolla/venv/lib/python3.9/site-packages/flask_restful/__init__.py", line 467, in wrapper
2023-04-04 18:23:40.223773 2023-04-04 18:23:40.220 37 ERROR keystone.server.flask.application     resp = resource(*args, **kwargs)
2023-04-04 18:23:40.223782 2023-04-04 18:23:40.220 37 ERROR keystone.server.flask.application   File "/var/lib/kolla/venv/lib/python3.9/site-packages/flask/views.py", line 107, in view
2023-04-04 18:23:40.223792 2023-04-04 18:23:40.220 37 ERROR keystone.server.flask.application     return current_app.ensure_sync(self.dispatch_request)(**kwargs)
2023-04-04 18:23:40.223801 2023-04-04 18:23:40.220 37 ERROR keystone.server.flask.application   File "/var/lib/kolla/venv/lib/python3.9/site-packages/flask_restful/__init__.py", line 582, in dispatch_request
2023-04-04 18:23:40.223811 2023-04-04 18:23:40.220 37 ERROR keystone.server.flask.application     resp = meth(*args, **kwargs)
2023-04-04 18:23:40.223820 2023-04-04 18:23:40.220 37 ERROR keystone.server.flask.application   File "/var/lib/kolla/venv/lib/python3.9/site-packages/keystone/api/projects.py", line 151, in get
2023-04-04 18:23:40.223830 2023-04-04 18:23:40.220 37 ERROR keystone.server.flask.application     return self._get_project(project_id)
2023-04-04 18:23:40.223839 2023-04-04 18:23:40.220 37 ERROR keystone.server.flask.application   File "/var/lib/kolla/venv/lib/python3.9/site-packages/keystone/api/projects.py", line 107, in _get_project
2023-04-04 18:23:40.223848 2023-04-04 18:23:40.220 37 ERROR keystone.server.flask.application     project = PROVIDERS.resource_api.get_project(project_id)
2023-04-04 18:23:40.223858 2023-04-04 18:23:40.220 37 ERROR keystone.server.flask.application   File "/var/lib/kolla/venv/lib/python3.9/site-packages/keystone/common/manager.py", line 115, in wrapped
2023-04-04 18:23:40.223867 2023-04-04 18:23:40.220 37 ERROR keystone.server.flask.application     __ret_val = __f(*args, **kwargs)
2023-04-04 18:23:40.223876 2023-04-04 18:23:40.220 37 ERROR keystone.server.flask.application   File "/var/lib/kolla/venv/lib/python3.9/site-packages/decorator.py", line 232, in fun
2023-04-04 18:23:40.223886 2023-04-04 18:23:40.220 37 ERROR keystone.server.flask.application     return caller(func, *(extras + args), **kw)
2023-04-04 18:23:40.223895 2023-04-04 18:23:40.220 37 ERROR keystone.server.flask.application   File "/var/lib/kolla/venv/lib/python3.9/site-packages/dogpile/cache/region.py", line 1577, in get_or_create_for_user_func
2023-04-04 18:23:40.223905 2023-04-04 18:23:40.220 37 ERROR keystone.server.flask.application     return self.get_or_create(
2023-04-04 18:23:40.223929 2023-04-04 18:23:40.220 37 ERROR keystone.server.flask.application   File "/var/lib/kolla/venv/lib/python3.9/site-packages/dogpile/cache/region.py", line 1042, in get_or_create
2023-04-04 18:23:40.223941 2023-04-04 18:23:40.220 37 ERROR keystone.server.flask.application     with Lock(
2023-04-04 18:23:40.223950 2023-04-04 18:23:40.220 37 ERROR keystone.server.flask.application   File "/var/lib/kolla/venv/lib/python3.9/site-packages/dogpile/lock.py", line 185, in __enter__
2023-04-04 18:23:40.223960 2023-04-04 18:23:40.220 37 ERROR keystone.server.flask.application     return self._enter()
2023-04-04 18:23:40.223969 2023-04-04 18:23:40.220 37 ERROR keystone.server.flask.application   File "/var/lib/kolla/venv/lib/python3.9/site-packages/dogpile/lock.py", line 94, in _enter
2023-04-04 18:23:40.223978 2023-04-04 18:23:40.220 37 ERROR keystone.server.flask.application     generated = self._enter_create(value, createdtime)
2023-04-04 18:23:40.223988 2023-04-04 18:23:40.220 37 ERROR keystone.server.flask.application   File "/var/lib/kolla/venv/lib/python3.9/site-packages/dogpile/lock.py", line 178, in _enter_create
2023-04-04 18:23:40.223997 2023-04-04 18:23:40.220 37 ERROR keystone.server.flask.application     return self.creator()
2023-04-04 18:23:40.224006 2023-04-04 18:23:40.220 37 ERROR keystone.server.flask.application   File "/var/lib/kolla/venv/lib/python3.9/site-packages/dogpile/cache/region.py", line 995, in gen_value
2023-04-04 18:23:40.224016 2023-04-04 18:23:40.220 37 ERROR keystone.server.flask.application     created_value = creator(
2023-04-04 18:23:40.224025 2023-04-04 18:23:40.220 37 ERROR keystone.server.flask.application   File "/var/lib/kolla/venv/lib/python3.9/site-packages/keystone/resource/core.py", line 903, in get_project
2023-04-04 18:23:40.224035 2023-04-04 18:23:40.220 37 ERROR keystone.server.flask.application     return self.driver.get_project(project_id)
2023-04-04 18:23:40.224044 2023-04-04 18:23:40.220 37 ERROR keystone.server.flask.application   File "/var/lib/kolla/venv/lib/python3.9/site-packages/keystone/resource/backends/sql.py", line 49, in get_project
2023-04-04 18:23:40.224054 2023-04-04 18:23:40.220 37 ERROR keystone.server.flask.application     return self._get_project(session, project_id).to_dict()
2023-04-04 18:23:40.224063 2023-04-04 18:23:40.220 37 ERROR keystone.server.flask.application   File "/var/lib/kolla/venv/lib/python3.9/site-packages/keystone/resource/backends/sql.py", line 44, in _get_project
2023-04-04 18:23:40.224073 2023-04-04 18:23:40.220 37 ERROR keystone.server.flask.application     raise exception.ProjectNotFound(project_id=project_id)
2023-04-04 18:23:40.224082 2023-04-04 18:23:40.220 37 ERROR keystone.server.flask.application keystone.exception.ProjectNotFound: Could not find project: service.
2023-04-04 18:23:40.224091 2023-04-04 18:23:40.220 37 ERROR keystone.server.flask.application \x1b[00m
2023-04-04 18:23:54.625309 2023-04-04 18:23:54.619 38 ERROR keystone.server.flask.application [None req-f2c34b5a-9331-4972-96a4-0ba935971006 5e04de7c8cdd40229d63c638acb175bd - - all default -] Could not find role: admin.: keystone.exception.RoleNotFound: Could not find role: admin.
2023-04-04 18:23:54.625361 2023-04-04 18:23:54.619 38 ERROR keystone.server.flask.application Traceback (most recent call last):
2023-04-04 18:23:54.625373 2023-04-04 18:23:54.619 38 ERROR keystone.server.flask.application   File "/var/lib/kolla/venv/lib/python3.9/site-packages/flask/app.py", line 1820, in full_dispatch_request
2023-04-04 18:23:54.625384 2023-04-04 18:23:54.619 38 ERROR keystone.server.flask.application     rv = self.dispatch_request()
2023-04-04 18:23:54.625394 2023-04-04 18:23:54.619 38 ERROR keystone.server.flask.application   File "/var/lib/kolla/venv/lib/python3.9/site-packages/flask/app.py", line 1796, in dispatch_request
2023-04-04 18:23:54.625404 2023-04-04 18:23:54.619 38 ERROR keystone.server.flask.application     return self.ensure_sync(self.view_functions[rule.endpoint])(**view_args)
2023-04-04 18:23:54.625414 2023-04-04 18:23:54.619 38 ERROR keystone.server.flask.application   File "/var/lib/kolla/venv/lib/python3.9/site-packages/flask_restful/__init__.py", line 467, in wrapper
2023-04-04 18:23:54.625439 2023-04-04 18:23:54.619 38 ERROR keystone.server.flask.application     resp = resource(*args, **kwargs)
2023-04-04 18:23:54.625451 2023-04-04 18:23:54.619 38 ERROR keystone.server.flask.application   File "/var/lib/kolla/venv/lib/python3.9/site-packages/flask/views.py", line 107, in view
2023-04-04 18:23:54.625461 2023-04-04 18:23:54.619 38 ERROR keystone.server.flask.application     return current_app.ensure_sync(self.dispatch_request)(**kwargs)
2023-04-04 18:23:54.625471 2023-04-04 18:23:54.619 38 ERROR keystone.server.flask.application   File "/var/lib/kolla/venv/lib/python3.9/site-packages/flask_restful/__init__.py", line 582, in dispatch_request
2023-04-04 18:23:54.625481 2023-04-04 18:23:54.619 38 ERROR keystone.server.flask.application     resp = meth(*args, **kwargs)
2023-04-04 18:23:54.625491 2023-04-04 18:23:54.619 38 ERROR keystone.server.flask.application   File "/var/lib/kolla/venv/lib/python3.9/site-packages/keystone/api/roles.py", line 50, in get
2023-04-04 18:23:54.625501 2023-04-04 18:23:54.619 38 ERROR keystone.server.flask.application     return self._get_role(role_id)
2023-04-04 18:23:54.625510 2023-04-04 18:23:54.619 38 ERROR keystone.server.flask.application   File "/var/lib/kolla/venv/lib/python3.9/site-packages/keystone/api/roles.py", line 70, in _get_role
2023-04-04 18:23:54.625520 2023-04-04 18:23:54.619 38 ERROR keystone.server.flask.application     ENFORCER.enforce_call(action='identity:get_role')
2023-04-04 18:23:54.625544 2023-04-04 18:23:54.619 38 ERROR keystone.server.flask.application   File "/var/lib/kolla/venv/lib/python3.9/site-packages/keystone/common/rbac_enforcer/enforcer.py", line 402, in enforce_call
2023-04-04 18:23:54.625571 2023-04-04 18:23:54.619 38 ERROR keystone.server.flask.application     policy_dict.update(cls._extract_member_target_data(
2023-04-04 18:23:54.625585 2023-04-04 18:23:54.619 38 ERROR keystone.server.flask.application   File "/var/lib/kolla/venv/lib/python3.9/site-packages/keystone/common/rbac_enforcer/enforcer.py", line 234, in _extract_member_target_data
2023-04-04 18:23:54.625595 2023-04-04 18:23:54.619 38 ERROR keystone.server.flask.application     member_name: func(flask.request.view_args[key])
2023-04-04 18:23:54.625604 2023-04-04 18:23:54.619 38 ERROR keystone.server.flask.application   File "/var/lib/kolla/venv/lib/python3.9/site-packages/keystone/common/manager.py", line 115, in wrapped
2023-04-04 18:23:54.625614 2023-04-04 18:23:54.619 38 ERROR keystone.server.flask.application     __ret_val = __f(*args, **kwargs)
2023-04-04 18:23:54.625623 2023-04-04 18:23:54.619 38 ERROR keystone.server.flask.application   File "/var/lib/kolla/venv/lib/python3.9/site-packages/decorator.py", line 232, in fun
2023-04-04 18:23:54.625633 2023-04-04 18:23:54.619 38 ERROR keystone.server.flask.application     return caller(func, *(extras + args), **kw)
2023-04-04 18:23:54.625642 2023-04-04 18:23:54.619 38 ERROR keystone.server.flask.application   File "/var/lib/kolla/venv/lib/python3.9/site-packages/dogpile/cache/region.py", line 1577, in get_or_create_for_user_func
2023-04-04 18:23:54.625652 2023-04-04 18:23:54.619 38 ERROR keystone.server.flask.application     return self.get_or_create(
2023-04-04 18:23:54.625661 2023-04-04 18:23:54.619 38 ERROR keystone.server.flask.application   File "/var/lib/kolla/venv/lib/python3.9/site-packages/dogpile/cache/region.py", line 1042, in get_or_create
2023-04-04 18:23:54.625671 2023-04-04 18:23:54.619 38 ERROR keystone.server.flask.application     with Lock(
2023-04-04 18:23:54.625680 2023-04-04 18:23:54.619 38 ERROR keystone.server.flask.application   File "/var/lib/kolla/venv/lib/python3.9/site-packages/dogpile/lock.py", line 185, in __enter__
2023-04-04 18:23:54.625689 2023-04-04 18:23:54.619 38 ERROR keystone.server.flask.application     return self._enter()
2023-04-04 18:23:54.625699 2023-04-04 18:23:54.619 38 ERROR keystone.server.flask.application   File "/var/lib/kolla/venv/lib/python3.9/site-packages/dogpile/lock.py", line 94, in _enter
2023-04-04 18:23:54.625721 2023-04-04 18:23:54.619 38 ERROR keystone.server.flask.application     generated = self._enter_create(value, createdtime)
2023-04-04 18:23:54.625732 2023-04-04 18:23:54.619 38 ERROR keystone.server.flask.application   File "/var/lib/kolla/venv/lib/python3.9/site-packages/dogpile/lock.py", line 178, in _enter_create
2023-04-04 18:23:54.625742 2023-04-04 18:23:54.619 38 ERROR keystone.server.flask.application     return self.creator()
2023-04-04 18:23:54.625751 2023-04-04 18:23:54.619 38 ERROR keystone.server.flask.application   File "/var/lib/kolla/venv/lib/python3.9/site-packages/dogpile/cache/region.py", line 995, in gen_value
2023-04-04 18:23:54.625761 2023-04-04 18:23:54.619 38 ERROR keystone.server.flask.application     created_value = creator(
2023-04-04 18:23:54.625770 2023-04-04 18:23:54.619 38 ERROR keystone.server.flask.application   File "/var/lib/kolla/venv/lib/python3.9/site-packages/keystone/assignment/core.py", line 1276, in get_role
2023-04-04 18:23:54.625780 2023-04-04 18:23:54.619 38 ERROR keystone.server.flask.application     return self.driver.get_role(role_id)
2023-04-04 18:23:54.625789 2023-04-04 18:23:54.619 38 ERROR keystone.server.flask.application   File "/var/lib/kolla/venv/lib/python3.9/site-packages/keystone/assignment/role_backends/sql.py", line 70, in get_role
2023-04-04 18:23:54.625799 2023-04-04 18:23:54.619 38 ERROR keystone.server.flask.application     return self._get_role(session, role_id).to_dict()
2023-04-04 18:23:54.625808 2023-04-04 18:23:54.619 38 ERROR keystone.server.flask.application   File "/var/lib/kolla/venv/lib/python3.9/site-packages/keystone/assignment/role_backends/sql.py", line 65, in _get_role
2023-04-04 18:23:54.625818 2023-04-04 18:23:54.619 38 ERROR keystone.server.flask.application     raise exception.RoleNotFound(role_id=role_id)
2023-04-04 18:23:54.625827 2023-04-04 18:23:54.619 38 ERROR keystone.server.flask.application keystone.exception.RoleNotFound: Could not find role: admin.
2023-04-04 18:23:54.625837 2023-04-04 18:23:54.619 38 ERROR keystone.server.flask.application \x1b[00m
2023-04-04 18:23:55.739157 2023-04-04 18:23:55.734 38 ERROR keystone.server.flask.application [None req-e9be13bf-fab0-404a-97cc-141bdfa9341c 5e04de7c8cdd40229d63c638acb175bd - - all default -] Could not find user: neutron.: keystone.exception.UserNotFound: Could not find user: neutron.
2023-04-04 18:23:55.739215 2023-04-04 18:23:55.734 38 ERROR keystone.server.flask.application Traceback (most recent call last):
2023-04-04 18:23:55.739226 2023-04-04 18:23:55.734 38 ERROR keystone.server.flask.application   File "/var/lib/kolla/venv/lib/python3.9/site-packages/flask/app.py", line 1820, in full_dispatch_request
2023-04-04 18:23:55.739237 2023-04-04 18:23:55.734 38 ERROR keystone.server.flask.application     rv = self.dispatch_request()
2023-04-04 18:23:55.739247 2023-04-04 18:23:55.734 38 ERROR keystone.server.flask.application   File "/var/lib/kolla/venv/lib/python3.9/site-packages/flask/app.py", line 1796, in dispatch_request
2023-04-04 18:23:55.739257 2023-04-04 18:23:55.734 38 ERROR keystone.server.flask.application     return self.ensure_sync(self.view_functions[rule.endpoint])(**view_args)
2023-04-04 18:23:55.739304 2023-04-04 18:23:55.734 38 ERROR keystone.server.flask.application   File "/var/lib/kolla/venv/lib/python3.9/site-packages/flask_restful/__init__.py", line 467, in wrapper
2023-04-04 18:23:55.739319 2023-04-04 18:23:55.734 38 ERROR keystone.server.flask.application     resp = resource(*args, **kwargs)
2023-04-04 18:23:55.739330 2023-04-04 18:23:55.734 38 ERROR keystone.server.flask.application   File "/var/lib/kolla/venv/lib/python3.9/site-packages/flask/views.py", line 107, in view
2023-04-04 18:23:55.739340 2023-04-04 18:23:55.734 38 ERROR keystone.server.flask.application     return current_app.ensure_sync(self.dispatch_request)(**kwargs)
2023-04-04 18:23:55.739349 2023-04-04 18:23:55.734 38 ERROR keystone.server.flask.application   File "/var/lib/kolla/venv/lib/python3.9/site-packages/flask_restful/__init__.py", line 582, in dispatch_request
2023-04-04 18:23:55.739376 2023-04-04 18:23:55.734 38 ERROR keystone.server.flask.application     resp = meth(*args, **kwargs)
2023-04-04 18:23:55.739387 2023-04-04 18:23:55.734 38 ERROR keystone.server.flask.application   File "/var/lib/kolla/venv/lib/python3.9/site-packages/keystone/api/users.py", line 182, in get
2023-04-04 18:23:55.739397 2023-04-04 18:23:55.734 38 ERROR keystone.server.flask.application     return self._get_user(user_id)
2023-04-04 18:23:55.739406 2023-04-04 18:23:55.734 38 ERROR keystone.server.flask.application   File "/var/lib/kolla/venv/lib/python3.9/site-packages/keystone/api/users.py", line 194, in _get_user
2023-04-04 18:23:55.739417 2023-04-04 18:23:55.734 38 ERROR keystone.server.flask.application     ref = PROVIDERS.identity_api.get_user(user_id)
2023-04-04 18:23:55.739426 2023-04-04 18:23:55.734 38 ERROR keystone.server.flask.application   File "/var/lib/kolla/venv/lib/python3.9/site-packages/keystone/common/manager.py", line 115, in wrapped
2023-04-04 18:23:55.739436 2023-04-04 18:23:55.734 38 ERROR keystone.server.flask.application     __ret_val = __f(*args, **kwargs)
2023-04-04 18:23:55.739446 2023-04-04 18:23:55.734 38 ERROR keystone.server.flask.application   File "/var/lib/kolla/venv/lib/python3.9/site-packages/keystone/identity/core.py", line 414, in wrapper
2023-04-04 18:23:55.739455 2023-04-04 18:23:55.734 38 ERROR keystone.server.flask.application     return f(self, *args, **kwargs)
2023-04-04 18:23:55.739465 2023-04-04 18:23:55.734 38 ERROR keystone.server.flask.application   File "/var/lib/kolla/venv/lib/python3.9/site-packages/keystone/identity/core.py", line 424, in wrapper
2023-04-04 18:23:55.739530 2023-04-04 18:23:55.734 38 ERROR keystone.server.flask.application     return f(self, *args, **kwargs)
2023-04-04 18:23:55.739542 2023-04-04 18:23:55.734 38 ERROR keystone.server.flask.application   File "/var/lib/kolla/venv/lib/python3.9/site-packages/decorator.py", line 232, in fun
2023-04-04 18:23:55.739552 2023-04-04 18:23:55.734 38 ERROR keystone.server.flask.application     return caller(func, *(extras + args), **kw)
2023-04-04 18:23:55.739578 2023-04-04 18:23:55.734 38 ERROR keystone.server.flask.application   File "/var/lib/kolla/venv/lib/python3.9/site-packages/dogpile/cache/region.py", line 1577, in get_or_create_for_user_func
2023-04-04 18:23:55.739589 2023-04-04 18:23:55.734 38 ERROR keystone.server.flask.application     return self.get_or_create(
2023-04-04 18:23:55.739599 2023-04-04 18:23:55.734 38 ERROR keystone.server.flask.application   File "/var/lib/kolla/venv/lib/python3.9/site-packages/dogpile/cache/region.py", line 1042, in get_or_create
2023-04-04 18:23:55.739608 2023-04-04 18:23:55.734 38 ERROR keystone.server.flask.application     with Lock(
2023-04-04 18:23:55.739617 2023-04-04 18:23:55.734 38 ERROR keystone.server.flask.application   File "/var/lib/kolla/venv/lib/python3.9/site-packages/dogpile/lock.py", line 185, in __enter__
2023-04-04 18:23:55.739627 2023-04-04 18:23:55.734 38 ERROR keystone.server.flask.application     return self._enter()
2023-04-04 18:23:55.739636 2023-04-04 18:23:55.734 38 ERROR keystone.server.flask.application   File "/var/lib/kolla/venv/lib/python3.9/site-packages/dogpile/lock.py", line 94, in _enter
2023-04-04 18:23:55.739645 2023-04-04 18:23:55.734 38 ERROR keystone.server.flask.application     generated = self._enter_create(value, createdtime)
2023-04-04 18:23:55.739655 2023-04-04 18:23:55.734 38 ERROR keystone.server.flask.application   File "/var/lib/kolla/venv/lib/python3.9/site-packages/dogpile/lock.py", line 178, in _enter_create
2023-04-04 18:23:55.739664 2023-04-04 18:23:55.734 38 ERROR keystone.server.flask.application     return self.creator()
2023-04-04 18:23:55.739673 2023-04-04 18:23:55.734 38 ERROR keystone.server.flask.application   File "/var/lib/kolla/venv/lib/python3.9/site-packages/dogpile/cache/region.py", line 995, in gen_value
2023-04-04 18:23:55.739683 2023-04-04 18:23:55.734 38 ERROR keystone.server.flask.application     created_value = creator(
2023-04-04 18:23:55.739705 2023-04-04 18:23:55.734 38 ERROR keystone.server.flask.application   File "/var/lib/kolla/venv/lib/python3.9/site-packages/keystone/identity/core.py", line 1011, in get_user
2023-04-04 18:23:55.739716 2023-04-04 18:23:55.734 38 ERROR keystone.server.flask.application     ref = driver.get_user(entity_id)
2023-04-04 18:23:55.739725 2023-04-04 18:23:55.734 38 ERROR keystone.server.flask.application   File "/var/lib/kolla/venv/lib/python3.9/site-packages/keystone/identity/backends/sql.py", line 200, in get_user
2023-04-04 18:23:55.739735 2023-04-04 18:23:55.734 38 ERROR keystone.server.flask.application     self._get_user(session, user_id).to_dict())
2023-04-04 18:23:55.739745 2023-04-04 18:23:55.734 38 ERROR keystone.server.flask.application   File "/var/lib/kolla/venv/lib/python3.9/site-packages/keystone/identity/backends/sql.py", line 194, in _get_user
2023-04-04 18:23:55.739755 2023-04-04 18:23:55.734 38 ERROR keystone.server.flask.application     raise exception.UserNotFound(user_id=user_id)
2023-04-04 18:23:55.739765 2023-04-04 18:23:55.734 38 ERROR keystone.server.flask.application keystone.exception.UserNotFound: Could not find user: neutron.
2023-04-04 18:23:55.739774 2023-04-04 18:23:55.734 38 ERROR keystone.server.flask.application \x1b[00m
2023-04-04 18:23:56.460640 2023-04-04 18:23:56.457 37 ERROR keystone.server.flask.application [None req-7b0738e2-bd93-4e56-be47-1cf7fe135af8 5e04de7c8cdd40229d63c638acb175bd - - all default -] Could not find project: service.: keystone.exception.ProjectNotFound: Could not find project: service.
2023-04-04 18:23:56.460679 2023-04-04 18:23:56.457 37 ERROR keystone.server.flask.application Traceback (most recent call last):
2023-04-04 18:23:56.460691 2023-04-04 18:23:56.457 37 ERROR keystone.server.flask.application   File "/var/lib/kolla/venv/lib/python3.9/site-packages/flask/app.py", line 1820, in full_dispatch_request
2023-04-04 18:23:56.460702 2023-04-04 18:23:56.457 37 ERROR keystone.server.flask.application     rv = self.dispatch_request()
2023-04-04 18:23:56.460711 2023-04-04 18:23:56.457 37 ERROR keystone.server.flask.application   File "/var/lib/kolla/venv/lib/python3.9/site-packages/flask/app.py", line 1796, in dispatch_request
2023-04-04 18:23:56.460722 2023-04-04 18:23:56.457 37 ERROR keystone.server.flask.application     return self.ensure_sync(self.view_functions[rule.endpoint])(**view_args)
2023-04-04 18:23:56.460732 2023-04-04 18:23:56.457 37 ERROR keystone.server.flask.application   File "/var/lib/kolla/venv/lib/python3.9/site-packages/flask_restful/__init__.py", line 467, in wrapper
2023-04-04 18:23:56.460742 2023-04-04 18:23:56.457 37 ERROR keystone.server.flask.application     resp = resource(*args, **kwargs)
2023-04-04 18:23:56.460752 2023-04-04 18:23:56.457 37 ERROR keystone.server.flask.application   File "/var/lib/kolla/venv/lib/python3.9/site-packages/flask/views.py", line 107, in view
2023-04-04 18:23:56.460762 2023-04-04 18:23:56.457 37 ERROR keystone.server.flask.application     return current_app.ensure_sync(self.dispatch_request)(**kwargs)
2023-04-04 18:23:56.460772 2023-04-04 18:23:56.457 37 ERROR keystone.server.flask.application   File "/var/lib/kolla/venv/lib/python3.9/site-packages/flask_restful/__init__.py", line 582, in dispatch_request
2023-04-04 18:23:56.460782 2023-04-04 18:23:56.457 37 ERROR keystone.server.flask.application     resp = meth(*args, **kwargs)
2023-04-04 18:23:56.460792 2023-04-04 18:23:56.457 37 ERROR keystone.server.flask.application   File "/var/lib/kolla/venv/lib/python3.9/site-packages/keystone/api/projects.py", line 151, in get
2023-04-04 18:23:56.460807 2023-04-04 18:23:56.457 37 ERROR keystone.server.flask.application     return self._get_project(project_id)
2023-04-04 18:23:56.460816 2023-04-04 18:23:56.457 37 ERROR keystone.server.flask.application   File "/var/lib/kolla/venv/lib/python3.9/site-packages/keystone/api/projects.py", line 107, in _get_project
2023-04-04 18:23:56.460826 2023-04-04 18:23:56.457 37 ERROR keystone.server.flask.application     project = PROVIDERS.resource_api.get_project(project_id)
2023-04-04 18:23:56.460870 2023-04-04 18:23:56.457 37 ERROR keystone.server.flask.application   File "/var/lib/kolla/venv/lib/python3.9/site-packages/keystone/common/manager.py", line 115, in wrapped
2023-04-04 18:23:56.460883 2023-04-04 18:23:56.457 37 ERROR keystone.server.flask.application     __ret_val = __f(*args, **kwargs)
2023-04-04 18:23:56.460893 2023-04-04 18:23:56.457 37 ERROR keystone.server.flask.application   File "/var/lib/kolla/venv/lib/python3.9/site-packages/decorator.py", line 232, in fun
2023-04-04 18:23:56.460903 2023-04-04 18:23:56.457 37 ERROR keystone.server.flask.application     return caller(func, *(extras + args), **kw)
2023-04-04 18:23:56.460913 2023-04-04 18:23:56.457 37 ERROR keystone.server.flask.application   File "/var/lib/kolla/venv/lib/python3.9/site-packages/dogpile/cache/region.py", line 1577, in get_or_create_for_user_func
2023-04-04 18:23:56.460923 2023-04-04 18:23:56.457 37 ERROR keystone.server.flask.application     return self.get_or_create(
2023-04-04 18:23:56.460933 2023-04-04 18:23:56.457 37 ERROR keystone.server.flask.application   File "/var/lib/kolla/venv/lib/python3.9/site-packages/dogpile/cache/region.py", line 1042, in get_or_create
2023-04-04 18:23:56.460943 2023-04-04 18:23:56.457 37 ERROR keystone.server.flask.application     with Lock(
2023-04-04 18:23:56.460953 2023-04-04 18:23:56.457 37 ERROR keystone.server.flask.application   File "/var/lib/kolla/venv/lib/python3.9/site-packages/dogpile/lock.py", line 185, in __enter__
2023-04-04 18:23:56.460963 2023-04-04 18:23:56.457 37 ERROR keystone.server.flask.application     return self._enter()
2023-04-04 18:23:56.460972 2023-04-04 18:23:56.457 37 ERROR keystone.server.flask.application   File "/var/lib/kolla/venv/lib/python3.9/site-packages/dogpile/lock.py", line 94, in _enter
2023-04-04 18:23:56.460982 2023-04-04 18:23:56.457 37 ERROR keystone.server.flask.application     generated = self._enter_create(value, createdtime)
2023-04-04 18:23:56.460992 2023-04-04 18:23:56.457 37 ERROR keystone.server.flask.application   File "/var/lib/kolla/venv/lib/python3.9/site-packages/dogpile/lock.py", line 178, in _enter_create
2023-04-04 18:23:56.461002 2023-04-04 18:23:56.457 37 ERROR keystone.server.flask.application     return self.creator()
2023-04-04 18:23:56.461012 2023-04-04 18:23:56.457 37 ERROR keystone.server.flask.application   File "/var/lib/kolla/venv/lib/python3.9/site-packages/dogpile/cache/region.py", line 995, in gen_value
2023-04-04 18:23:56.461022 2023-04-04 18:23:56.457 37 ERROR keystone.server.flask.application     created_value = creator(
2023-04-04 18:23:56.461031 2023-04-04 18:23:56.457 37 ERROR keystone.server.flask.application   File "/var/lib/kolla/venv/lib/python3.9/site-packages/keystone/resource/core.py", line 903, in get_project
2023-04-04 18:23:56.461041 2023-04-04 18:23:56.457 37 ERROR keystone.server.flask.application     return self.driver.get_project(project_id)
2023-04-04 18:23:56.461051 2023-04-04 18:23:56.457 37 ERROR keystone.server.flask.application   File "/var/lib/kolla/venv/lib/python3.9/site-packages/keystone/resource/backends/sql.py", line 49, in get_project
2023-04-04 18:23:56.461061 2023-04-04 18:23:56.457 37 ERROR keystone.server.flask.application     return self._get_project(session, project_id).to_dict()
2023-04-04 18:23:56.461071 2023-04-04 18:23:56.457 37 ERROR keystone.server.flask.application   File "/var/lib/kolla/venv/lib/python3.9/site-packages/keystone/resource/backends/sql.py", line 44, in _get_project
2023-04-04 18:23:56.461081 2023-04-04 18:23:56.457 37 ERROR keystone.server.flask.application     raise exception.ProjectNotFound(project_id=project_id)
2023-04-04 18:23:56.461091 2023-04-04 18:23:56.457 37 ERROR keystone.server.flask.application keystone.exception.ProjectNotFound: Could not find project: service.
2023-04-04 18:23:56.461100 2023-04-04 18:23:56.457 37 ERROR keystone.server.flask.application \x1b[00m
